Workbook

Sheet Materiali
A1: Caratteristeche dei materiali | J1: Caratteristeche dei materiali | N1: Armatura ordinaria B450C
A2: Calcestruzzo travi C45/55 | J2: Calcestruzzo soletta C35/45 | N2: Staffe e reggistaffe
A3: Rck | B3: 55 | C3: N/mm2 | J3: Rck | K3: 45 | L3: N/mm2 | N3: fyk | O3: 450 | P3: N/mm2
A4: fck | B4: =0.83*B3 -> 45.65 | C4: N/mm2 | J4: fck | K4: =0.83*K3 -> 37.35 | L4: N/mm2 | N4: fyd | O4: =O3/1.15 -> 391.30435 | P4: N/mm2
A5: fcd | B5: =0.85*Materiali!B4/1.5 -> 25.868333 | C5: N/mm2 | J5: fcd | K5: =0.85*Materiali!K4/1.5 -> 21.165 | L5: N/mm2 | N5: fuk | O5: 540 | P5: N/mm2
A6: fcm | B6: =B4+8 -> 53.65 | C6: N/mm2 | J6: fcm | K6: =K4+8 -> 45.35 | L6: N/mm2
A7: fctm | B7: =0.3*B4^(2/3) -> 3.8319083 | C7: N/mm2 | D7: Resistenza a trazione cls | J7: fctm | K7: =0.3*K4^(2/3) -> 3.3520848 | L7: N/mm2
A8: fcfm | B8: =1.2*B7 -> 4.59829 | C8: N/mm2 | D8: Resistenza a trazione per flessione | J8: fcfm | K8: =1.2*K7 -> 4.0225017 | L8: N/mm2
A9: ϭct | B9: =B7/1.2 -> 3.1932569 | C9: N/mm2 | D9: Resistenza a trazione prima delle fessure | J9: ϭct | K9: =K7/1.2 -> 2.793404 | L9: N/mm2
A10: Ecm | B10: =22000*(B6/10)^0.3 -> 36416.114 | C10: N/mm2 | J10: Ecm | K10: =22000*(K6/10)^0.3 -> 34625.485 | L10: N/mm2
A11: Caratteristiche cls al trasferimento della precompressione
A12: t | B12: 9 | C12: giorni | D12: momento di trasferimento della precompressione
A13: s | B13: =0.2 -> 0.2
A14: βcc | B14: =EXP(B13*(1-(28/B12)^(0.5))) -> 0.85832983 | D14: coefficiente d'invecchiamento del calcestruzzo
A15: fcm(t) | B15: =B14*B6 -> 46.049395 | C15: N/mm2
A16: fck(t) | B16: =B14*B4 -> 39.182757 | C16: N/mm2
A17: 0.7 fck(t) | B17: =0.7*B16 -> 27.42793 | C17: N/mm2 | D17: valore limite della tensione di esercizio a cadute avvenute della precompressione ( p. 4.1.8.1.4 )
A18: 0.6 fck(t) | B18: =0.6*B16 -> 23.509654 | C18: N/mm2 | D18: valore limite della tensione all'atto della precompressione ( p. 4.1.8.1.3 )
A19: α | B19: =IF(B12<28,1,2/3) -> 1
A20: fctm(t) | B20: =B7*B14^B19 -> 3.2890412 | C20: N/mm2
A21: k | B21: 1 | D21: valore di riduzione della resistenza a trazione del cls per le verifiche del conglomerato
A22: fctm(t) k | B22: =B20*B21 -> 3.2890412 | C22: N/mm2
A24: trefolo a sette fili ( classe 2 )
A25: Φn | B25: 15.2 | C25: mm | D25: Diametro nominale | G25: area ferri laterali | J25: ferri superiori
A26: Anom | B26: 139 | C26: mm2 | D26: Area nominale | G26: =6*B26 -> 834 | J26: =2*B26 -> 278
A27: Ep | B27: =195000 -> 195000 | C27: N/mm2 | D27: Modulo elastico
A28: fpk | B28: 1860 | C28: N/mm2
A29: fp01,k | B29: =1670 -> 1670 | C29: N/mm2
A31: Limiti tensioni massime iniziali all'atto della tesaturaE
A32: ϭs,pi = 0.9 fpk | B32: =0.9*$B$29 -> 1503 | C32: N/mm2
A33: ϭs,pi = 0.8 fp0k | B33: =0.8*$B$28 -> 1488 | C33: N/mm2 | D33: * si prende la condizione più restrittiva
A34: ϭc,max | B34: =0.7*B4 -> 31.955 | C34: N/mm2 | D34: Tensione massima compressione cls
A38: Lunghezza di trasferimento
A39: ηp1 | B39: =3.2 -> 3.2 | D39: per trefoli a 3 e 7 fili
A40: η1 | B40: 1 | D40: condizioni di buona aderenza
A41: fctd(t) | B41: =B20/1.5 -> 2.1926941 | C41: N/mm2 | D41: tensione di aderenza uniforme
A43: α1 | B43: 1 | D43: rilascio graduale
A44: α2 | B44: 0.19 | D44: per trefoli a 3 o 7 fili
A45: Φn | B45: 15.2 | C45: mm | D45: Diametro nominale
A46: ϭpmo | B46: ='fase 0 '!B22 -> 1064.4391 | C46: N/mm2 | D46: tensione nell'armatura di precompressione subito dopo il rilascio
...

Sheet Caratteristiche trave V185
A1: Caratteristiche trave
A2: L | B2: 32 | C2: m | D2: Luce trave
A3: Caratteristiche statiche sezione solo calcestruzzo
A4: Hsez | B4: 1850 | C4: mm
A5: Acls | B5: 876300 | C5: mm2
A6: xG | B6: 0 | C6: mm
A7: yG | B7: 1049 | C7: mm
A8: H - yG | B8: =B4-B7 -> 801 | C8: mm
A9: Ixg | B9: =331583614407 -> 331583614407 | C9: mm4 | D9: Momento d'inerzia baricentrico in direzione x
A10: Iyg | B10: =356988385000 -> 356988385000 | C10: mm4 | D10: Momento d'inerzia baricentrico in direzione y
A11: Wx | B11: =B9/B7 -> 3.1609496e+08 | C11: mm3 | D11: Modulo di resistenza elastico
A12: Armatura sezione
A13: ntref | B13: =SUM(B51:B53) -> 72 | D13: Numero trefoli utilizzati
A14: Atref | B14: =B13*Materiali!B26 -> 10008 | C14: mm2 | D14: Area totale trefoli
A15: Caratteristiche sezione omogenizzata interamente reagente
A16: n | B16: 6 | D16: coefficiente omogenizzazione
A17: Atot | B17: 933012 | C17: mm2 | D17: Area totale = Acls + n*Atref
A18: yG | B18: 1071 | C18: mm | D18: Ascissa baricentro
A19: H - yG | B19: =B4-B18 -> 779 | C19: mm
A20: Ixg | B20: =357238306267 -> 357238306267 | C20: mm4 | D20: Momento d'inerzia baricentrico in direzione x
A21: Iyg | B21: =367293289000 -> 367293289000 | C21: mm4 | D21: Momento d'inerzia baricentrico in direzione y
A22: Wx, inf | B22: =B20/B18 -> 3.3355584e+08 | C22: mm3 | D22: Modulo di resistenza elastico
A23: Wx, sup | B23: =B20/B19 -> 4.5858576e+08 | C23: mm3 | D23: Modulo di resistenza elastico
A24: yp | B24: =B55 -> 410.55556 | C24: mm | D24: punto di applicazione dello sforzo normale
A25: e | B25: =B18-B24 -> 660.44444 | C25: mm | D25: eccentricità tra il punto di applicazione del tiro e il baricentro della sezione
A27: Caratteristiche sezione omogenizzata interamente reagente con soletta
A29: Caratteristiche soletta
A30: B | B30: 2.5 | C30: m | D30: larghezza soletta
A31: s | B31: 0.25 | C31: m | D31: spessore soletta
A32: Asoletta | B32: =B30*B31*1000^2 -> 625000 | C32: mm2 | D32: Area cls soletta
A33: Φ | B33: =10 -> 10 | C33: mm | D33: diametro armature soletta
A34: As,sup | B34: =10*B33^2*PI()/4 -> 785.39816 | C34: mm2 | D34: area armatura superiore
A35: As,inf | B35: =10*B33^2*PI()/4 -> 785.39816 | C35: mm2 | D35: area armatura inferiore
A36: Caratteristiche sezione omogenizzata
A37: n | B37: 6 | D37: coefficiente omogenizzazione (rapporto tra i due moduli elastici, trefolo e CAP)
A38: n2 | B38: =Materiali!B10/Materiali!K10 -> 1.0517142 | D38: coefficiente omogenizzazione (rapporto tra i due moduli elastici, soletta e CAP)
A39: Acls | B39: =B32+'Caratteristiche trave V185'!B5 -> 1501300 | C39: mm2 | D39: Area cls soletta + trave
A40: Atr | B40: ='Caratteristiche trave V185'!B14 -> 10008 | C40: mm2 | D40: Area trefolo
A41: Atot | B41: =B39+B38*B40+B37*B40 -> 1571873.6 | C41: mm2 | D41: Area totale sezione Atot = Acp + n2*Ac +n*Atr
A42: Hsez | B42: =B31*1000+'Caratteristiche trave V185'!B4 -> 2100 | C42: mm | D42: Altezza totale della sezione
...

Sheet fase 0 
A1: Peso Proprio - fase 0 | I1: Peso Proprio fase 0 | M1: Precompressione fase 0 | Q1: Precompressione fase 0
A2: G1(trave+ traversi) | B2: =(25*'Caratteristiche trave V185'!B5/1000^2)+ (25*1.8*2.5*0.4*2)/'Caratteristiche trave V185'!B2 -> 24.72 | C2: KN/m | I2: X | J2: Y | M2: X | N2: Y | Q2: X | R2: Y
A3: s | B3: =32/2 -> 16 | C3: m | D3: ascissa | I3: 0 | J3: ='Caratteristiche trave V185'!B19 -> 779 | M3: 0 | N3: =J3 -> 779 | Q3: =I3+M3 -> 0 | R3: =N3 -> 779
A4: Mg+ | B4: =B2*0.5*(B3*'Caratteristiche trave V185'!$B$2-B3^2) -> 3164.16 | C4: KNm | D4: Momento in s dovuto al peso proprio della trave | I4: ='fase 0 '!B4*1000^2/'Caratteristiche trave V185'!B23 -> 6.8998218 | J4: ='Caratteristiche trave V185'!B19 -> 779 | M4: =(B13*1000/'Caratteristiche trave V185'!B17) - B13*1000*'Caratteristiche trave V185'!B25/('Caratteristiche trave V185'!B23) -> -3.7949078 | N4: =J4 -> 779 | Q4: =I4+M4 -> 3.1049139 | R4: =N4 -> 779
A5: Tiro iniziale | I5: =- 'fase 0 '!B4*1000^2/'Caratteristiche trave V185'!B22 -> -9.4861478 | J5: =-'Caratteristiche trave V185'!B18 -> -1071 | M5: =(B13*1000/'Caratteristiche trave V185'!B17) + B13*1000*'Caratteristiche trave V185'!B25/('Caratteristiche trave V185'!B22) -> 31.438644 | N5: =J5 -> -1071 | Q5: =I5+M5 -> 21.952496 | R5: =N5 -> -1071
A6: Np0 | B6: =12000*'Caratteristiche trave V185'!B13/(SUM('Caratteristiche trave V185'!B51:B53)) -> 12000 | C6: KN | I6: 0 | J6: =-'Caratteristiche trave V185'!B18 -> -1071 | M6: 0 | N6: =J6 -> -1071 | Q6: =I6+M6 -> 0 | R6: =N6 -> -1071
A7: ϭpi | B7: =B6*1000/'Caratteristiche trave V185'!B14 -> 1199.0408 | C7: N/mm2 | D7: Tensione trefoli | E7: ϭs < min ( 0.9 fpk, 0.8 fp0k) | F7: =IF(B7<MIN(Materiali!B32:B33),"VERIFICA", " NON VERIFICA") -> VERIFICA
A8: Tesnsione cls a livello del cavo al tiro
A9: ϭcc | B9: =B6*1000/'Caratteristiche trave V185'!B17 + B6*1000*'Caratteristiche trave V185'!B25/'Caratteristiche trave V185'!B20*'Caratteristiche trave V185'!B25 -> 27.513534 | C9: N/mm2
A10: Perdite di tensione istantane
A11: ΔNi | B11: ='Perdite di tiro '!B90 -> 1698.3586 | C11: KN
A12: Precompressione dopo le perdite di tensione dovute alla deformazione istantanea del cls
A13: Np0 - Δni | B13: =B6-B11 -> 10301.641 | C13: KN
A14: Tesnsione cls a lembo superiore | G14: D/C
A15: ϭcc,sup | B15: =(B13*1000/'Caratteristiche trave V185'!B17) - B13*1000*'Caratteristiche trave V185'!B25/('Caratteristiche trave V185'!B23) + 'fase 0 '!B4*1000^2/'Caratteristiche trave V185'!B23 -> 3.1049139 | C15: N/mm2 | D15: =IF(B15 < 0,"Trazione","Compressione") -> Compressione | E15: =IF(D15="Trazione","ϭ > fctm(t)/1.2", "ϭ < 0.7fck(t)") -> ϭ < 0.7fck(t) | F15: =IF(D15 = "Trazione", IF(ABS(B15) < Materiali!$B$22/1.2,"VERIFICA", " NON VERIFICA"), IF(B15 < 0.7*Materiali!$B$16,"VERIFICA", " NON VERIFICA")) -> VERIFICA | G15: =ABS(B15/IF(D15 = "Trazione", Materiali!$B$22/1.2, 0.7*Materiali!$B$16)) -> 0.11320264
A16: Tesnsione cls a lembo inferiore
A17: ϭcc,inf | B17: =(B13*1000/'Caratteristiche trave V185'!B17) + B13*1000*'Caratteristiche trave V185'!B25/('Caratteristiche trave V185'!B22) - 'fase 0 '!B4*1000^2/'Caratteristiche trave V185'!B22 -> 21.952496 | C17: N/mm2 | D17: =IF(B17 < 0,"Trazione","Compressione") -> Compressione | E17: ϭ < 0.7 fctk (t) | F17: =IF(D17 = "Trazione", IF(ABS(B17) < Materiali!$B$22/1.2,"VERIFICA", " NON VERIFICA"), IF(B17 < 0.7*Materiali!$B$16,"VERIFICA", " NON VERIFICA")) -> VERIFICA | G17: =ABS(B17/IF(D17 = "Trazione", Materiali!$B$22/1.2, 0.7*Materiali!$B$16)) -> 0.80037016
A18: Tensione cls a livello del cavo
A19: ϭcc0 | B19: =B13*1000/'Caratteristiche trave V185'!B17 + ('fase 0 '!B13*1000*'Caratteristiche trave V185'!B25- 'fase 0 '!B4)/'Caratteristiche trave V185'!B20*'Caratteristiche trave V185'!B25 -> 23.619541 | C19: N/mm2 | D19: =IF(B19 < 0,"Trazione","Compressione") -> Compressione | E19: ϭ < 0.7 fctk (t) | F19: =IF(D19 = "Trazione", IF(ABS(B19) < Materiali!$B$22/1.2,"VERIFICA", " NON VERIFICA"), IF(B19 < 0.7*Materiali!$B$16,"VERIFICA", " NON VERIFICA")) -> VERIFICA | G19: =ABS(B19/IF(D19 = "Trazione", Materiali!$B$22/1.2, 0.7*Materiali!$B$16)) -> 0.86114924
A20: Tensione cls nel cavo
A21: Tensioni del cavo dopo le cadute di tensione dovute al peso proprio
A22: ϭsp0 | B22: =B13*1000/'Caratteristiche trave V185'!B14 + 'Caratteristiche trave V185'!B16*'fase 0 '!B4*1000^2/'Caratteristiche trave V185'!B20*'Caratteristiche trave V185'!B25 -> 1064.4391 | C22: N/mm2 | D22: Tensione trefoli | E22: ϭs < min ( 0.9 fpk, 0.8 fp0k) | F22: =IF(B22<MIN(Materiali!B32:B33),"VERIFICA", " NON VERIFICA") -> VERIFICA | G22: =B22/MIN(Materiali!B32:B33) -> 0.71534887

Sheet fase 1 
A1: GETTO IN OPERA DELLA SOLETTA : fase 1
A2: (Sezione resistente formata dalla sola trave, soletta considerata solo come carico )
A3: Sollecitazioni al getto della soletta
A4: Gsoletta | B4: =25*10*0.25/4 -> 15.625 | C4: KN/m
A5: s | B5: ='fase 0 '!B3 -> 16 | C5: m | D5: ascissa
A6: Mg+ | B6: =B4*0.5*(B5*'Caratteristiche trave V185'!$B$2-B5^2) -> 2000 | C6: KNm | D6: Momento in s dovuto al peso proprio della soletta
A7: Variazioni di tensione dovute a Mmax
A8: Δϭcs1 | B8: =B6*1000^2/'Caratteristiche trave V185'!B23 -> 4.3612344 | C8: N/mm2 | D8: Variazione di tensione nel cls al lembo superiore
A9: Δϭci1 | B9: =-B6*1000^2/'Caratteristiche trave V185'!B22 -> -5.9959975 | C9: N/mm2 | D9: Variazione di tensione nel cls al lembo inferiore
A10: Δϭcc1 | B10: =-B6*1000^2*'Caratteristiche trave V185'!B25/'Caratteristiche trave V185'!B20 -> -3.6975007 | C10: N/mm2 | D10: variazione di tensione nel cls al livello del baricentro dei cavi
A11: A favore di sicurezza si è considerato che il getto della soletta avvenga dopo molto tempo rispetto al tiro delle travi in precompresso, in modo da poter considerare, in questa fase tutte le perdite di tensione lente riguardo la precompressione.
A12: Variazioni di tensione dovute alle perdite di precompressione
A13: ΔNt | B13: ='Perdite di tiro '!B94 -> 2600.556 | C13: KN | D13: Perdita totale di precompressione
A14: Δϭcs1 | B14: =-B13*1000/'Caratteristiche trave V185'!B17 + B13*1000*'Caratteristiche trave V185'!B25/'Caratteristiche trave V185'!B23 -> 0.9579901 | C14: N/mm2 | D14: =IF(B14 < 0,"Trazione","Compressione") -> Compressione | E14: Variazione di tensione nel cls al lembo superiore
A15: Δϭc1 | B15: =-B13*1000/'Caratteristiche trave V185'!B17 - B13*1000*'Caratteristiche trave V185'!B25/'Caratteristiche trave V185'!B22 -> -7.9364009 | C15: N/mm2 | D15: =IF(B15 < 0,"Trazione","Compressione") -> Trazione | E15: Variazione di tensione nel cls al lembo inferiore
A16: Δϭcc1 | B16: =-B13*1000/'Caratteristiche trave V185'!B17 - B13*1000*'Caratteristiche trave V185'!B25^2/'Caratteristiche trave V185'!B20 -> -5.9625405 | C16: N/mm2 | D16: =IF(B16 < 0,"Trazione","Compressione") -> Trazione | E16: variazione di tensione nel cls al livello del baricentro dei cavi
A18: Tensione cls lembo superiore | G18: D/C
A19: ϭcs1 | B19: ='fase 0 '!B15 +'fase 1 '!B8+'fase 1 '!B14 -> 8.4241385 | C19: N/mm2 | D19: =IF(B19 < 0,"Trazione","Compressione") -> Compressione | E19: =IF(D19 = "Trazione", IF(ABS(B19) < Materiali!$B$22/1.2,"VERIFICA", " NON VERIFICA"), IF(B19 < 0.7*Materiali!$B$16,"VERIFICA", " NON VERIFICA")) -> VERIFICA | F19: =IF(D19="Trazione","ϭ > fctm(t)/1.2", "ϭ < 0.6fck(t)") -> ϭ < 0.6fck(t) | G19: =ABS(B19/IF(D19 = "Trazione", Materiali!$B$22/1.2, 0.7*Materiali!$B$16)) -> 0.30713724
A20: Tensione cls lembo inferiore
A21: ϭci1 | B21: ='fase 0 '!B17 +'fase 1 '!B9+'fase 1 '!B15 -> 8.0200979 | C21: N/mm2 | D21: =IF(B21 < 0,"Trazione","Compressione") -> Compressione | E21: =IF(D21 = "Trazione", IF(ABS(B21) < Materiali!$B$22/1.2,"VERIFICA", " NON VERIFICA"), IF(B21 < 0.7*Materiali!$B$16,"VERIFICA", " NON VERIFICA")) -> VERIFICA | F21: =IF(D21="Trazione","ϭ > fctm(t)/1.2", "ϭ < 0.6fck(t)") -> ϭ < 0.6fck(t) | G21: =ABS(B21/IF(D21 = "Trazione", Materiali!$B$22/1.2, 0.7*Materiali!$B$16)) -> 0.29240625
A22: Tensione cls al livello del cavo
A23: ϭct1 | B23: ='fase 0 '!B19+B10+B16 -> 13.959499 | C23: N/mm2 | D23: =IF(B23 < 0,"Trazione","Compressione") -> Compressione | E23: =IF(D23 = "Trazione", IF(ABS(B23) < Materiali!$B$22/1.2,"VERIFICA", " NON VERIFICA"), IF(B23 < 0.7*Materiali!$B$16,"VERIFICA", " NON VERIFICA")) -> VERIFICA | F23: =IF(D23="Trazione","ϭ > fctm(t)/1.2", "ϭ < 0.6fck(t)") -> ϭ < 0.6fck(t) | G23: =ABS(B23/IF(D23 = "Trazione", Materiali!$B$22/1.2, 0.7*Materiali!$B$16)) -> 0.50895199
A24: Tensione nel cavo
A25: Tensione nel cavo dopo le perdite in fase 1 e le cadute di tensione al peso della soletta
A26: ϭsp1 | B26: ='fase 0 '!B22-'Caratteristiche trave V185'!B16*'fase 1 '!B16 + 'Caratteristiche trave V185'!B16*'fase 1 '!B10 -> 1078.0294 | C26: N/mm2 | D26: Tensione trefoli | E26: =IF(B26<MIN(Materiali!B32:B33),"VERIFICA", " NON VERIFICA") -> VERIFICA | F26: ϭs < min ( 0.9 fpk, 0.8 fp0k) | G26: =B26/MIN(Materiali!B32:B33) -> 0.7244821
B29: Tensioni cls fase 0 | F29: Perdite fase 1 | J29: Peso soletta fase 1 | O29: Peso soletta fase 1
B30: X | C30: Y | F30: X | G30: Y | J30: X | K30: Y | O30: X | P30: Y
B31: ='fase 0 '!Q3 -> 0 | C31: ='fase 0 '!R3 -> 779 | F31: 0 | G31: =C31 -> 779 | J31: =B31+F31 -> 0 | K31: =G31 -> 779 | O31: =B31+F31+J31 -> 0 | P31: =G31 -> 779
B32: ='fase 0 '!Q4 -> 3.1049139 | C32: ='fase 0 '!R4 -> 779 | F32: =B14 -> 0.9579901 | G32: =C32 -> 779 | J32: =B8 -> 4.3612344 | K32: =G32 -> 779 | O32: =B32+F32+J32 -> 8.4241385 | P32: =G32 -> 779
B33: ='fase 0 '!Q5 -> 21.952496 | C33: ='fase 0 '!R5 -> -1071 | F33: =B15 -> -7.9364009 | G33: =C33 -> -1071 | J33: =B9 -> -5.9959975 | K33: =G33 -> -1071 | O33: =B33+F33+J33 -> 8.0200979 | P33: =G33 -> -1071
B34: ='fase 0 '!Q6 -> 0 | C34: ='fase 0 '!R6 -> -1071 | F34: 0 | G34: =C34 -> -1071 | J34: =B34+F34 -> 0 | K34: =G34 -> -1071 | O34: =B34+F34+J34 -> 0 | P34: =G34 -> -1071

Sheet fase 2 
A1: SOLETTA COLLABORANTE : fase 2
A2: Calcolo sollecitazione
A3: g2,trave 2 | B3: =(2.7+3.14)*2.5/2 + 0.7*2.5 -> 9.05 | C3: KN/m | D3: g2 trave interna
A4: g2,trave 1 | B4: =(1.01+2.7)*2.5/2 +0.7*(2.5-0.7) +3.8*0.7 -> 8.5575 | C4: KN/m | D4: g2 trave esterna
A5: s | B5: ='fase 0 '!B3 -> 16 | C5: m | D5: ascissa
A6: Mmax | B6: =MAX(B3:B4)*0.5*(B5*'Caratteristiche trave V185'!B2-'fase 2 '!B5^2) -> 1158.4 | C6: KNm | D6: Momento massimo in mezzeria della trave più caricata
A7: Variazioni di tensione dovute a Mmax
A8: Δϭcs,soletta | B8: =B6*1000^2/('Caratteristiche trave V185'!B38*'Caratteristiche trave V185'!B46)*'Caratteristiche trave V185'!B44 -> 1.0359694 | C8: N/mm2 | D8: tensione al lembo superiore della soletta
A9: Δϭci,soletta | B9: =B6*1000^2/('Caratteristiche trave V185'!B38*'Caratteristiche trave V185'!B46)*'Caratteristiche trave V185'!B45 -> 0.72874241 | C9: N/mm2 | D9: tensione al lembo inferiore della soletta
A10: Δϭcs,trave | B10: =B6*1000^2/('Caratteristiche trave V185'!B46)*'Caratteristiche trave V185'!B45 -> 0.76642873 | C10: N/mm2 | D10: tensione al lembo superiore della trave
A11: Δϭci,trave | B11: =-B6*1000^2/('Caratteristiche trave V185'!B46)*'Caratteristiche trave V185'!B43 -> -1.6246221 | C11: N/mm2 | D11: tensione al lembo inferiore della trave
A12: Δϭcp,trave | B12: =-B6*1000^2/('Caratteristiche trave V185'!B46)*'Caratteristiche trave V185'!B48 -> -1.0939955 | C12: N/mm2 | D12: tensione del cls al trefolo
A14: tensione da ritiro soletta
A15: Δϭcs,soletta,ritiro | B15: ='Perdite di tiro '!B98 -> -6.9996134 | C15: N/mm2
A16: Nritiro | B16: =-B15*'Caratteristiche trave V185'!B32/1000 -> 4374.7584 | C16: KN
A17: Mritiro | B17: =B16*('Caratteristiche trave V185'!B44-250)/1000 -> 2594.2317 | C17: KNm
A18: Δϭcs,soletta | B18: =B16*1000/('Caratteristiche trave V185'!B38*'Caratteristiche trave V185'!B41) +B17*1000^2/('Caratteristiche trave V185'!B38*'Caratteristiche trave V185'!B46)*'Caratteristiche trave V185'!B44 + B15 -> -2.0332666 | C18: N/mm2 | D18: =IF(B18 < 0,"Trazione","Compressione") -> Trazione | E18: tensione al lembo superiore della soletta
A19: Δϭci,soletta | B19: =B16*1000/('Caratteristiche trave V185'!B38*'Caratteristiche trave V185'!B41) +B17*1000^2/('Caratteristiche trave V185'!B38*'Caratteristiche trave V185'!B46)*'Caratteristiche trave V185'!B45 + B15 -> -2.7213001 | C19: N/mm2 | D19: =IF(B19 < 0,"Trazione","Compressione") -> Trazione | E19: tensione al lembo inferiore della soletta
A20: Δϭcs,trave | B20: =B16*1000/('Caratteristiche trave V185'!B41) +B17*1000^2/('Caratteristiche trave V185'!B46)*'Caratteristiche trave V185'!B45 -> 4.4995628 | C20: N/mm2 | D20: =IF(B20 < 0,"Trazione","Compressione") -> Compressione | E20: tensione al lembo superiore della trave
A21: Δϭci,trave | B21: =B16*1000/('Caratteristiche trave V185'!B41) -B17*1000^2/('Caratteristiche trave V185'!B46)*'Caratteristiche trave V185'!B43 -> -0.85518504 | C21: N/mm2 | D21: =IF(B21 < 0,"Trazione","Compressione") -> Trazione | E21: tensione al lembo inferiore della trave
A22: Δϭcp | B22: =B16*1000/('Caratteristiche trave V185'!B41) -B17*1000^2/('Caratteristiche trave V185'!B46)*('Caratteristiche trave V185'!B43-'Caratteristiche trave V185'!B24) -> 0.33315089 | C22: N/mm2 | D22: =IF(B22 < 0,"Trazione","Compressione") -> Compressione | E22: tensione del cls al trefolo
A24: Variazioni di tensione dovute alle perdite di precompressione
A25: ΔNt | B25: ='Perdite di tiro '!B112 -> 198.28533 | C25: KN | D25: Perdita totale di precompressione
A26: Δϭcs,soletta | B26: =-B25*1000/('Caratteristiche trave V185'!B38*'Caratteristiche trave V185'!B41) +B25*1000*'Caratteristiche trave V185'!B48/('Caratteristiche trave V185'!B38*'Caratteristiche trave V185'!B46)*'Caratteristiche trave V185'!B44 -> 0.030155775 | C26: N/mm2 | D26: =IF(B26 < 0,"Trazione","Compressione") -> Compressione | E26: variazione tensione al lembo superiore della soletta
A27: Δϭci,soletta | B27: =-B25*1000/('Caratteristiche trave V185'!B38*'Caratteristiche trave V185'!B41) +B25*1000*'Caratteristiche trave V185'!B48/('Caratteristiche trave V185'!B38*'Caratteristiche trave V185'!B46)*'Caratteristiche trave V185'!B45 -> -0.014357531 | C27: N/mm2 | D27: =IF(B27 < 0,"Trazione","Compressione") -> Trazione | E27: tensione al lembo inferiore della soletta
A28: Δϭcs,trave | B28: =-B25*1000/('Caratteristiche trave V185'!B41) +B25*1000*'Caratteristiche trave V185'!B48/('Caratteristiche trave V185'!B46)*'Caratteristiche trave V185'!B45 -> -0.015100019 | C28: N/mm2 | D28: =IF(B28 < 0,"Trazione","Compressione") -> Trazione | E28: variazione tensione al lembo superiore della trave
A29: Δϭci,trave | B29: =-B25*1000/('Caratteristiche trave V185'!B41) -B25*1000*'Caratteristiche trave V185'!B48/('Caratteristiche trave V185'!B46)*'Caratteristiche trave V185'!B43 -> -0.36153305 | C29: N/mm2 | D29: =IF(B29 < 0,"Trazione","Compressione") -> Trazione | E29: variazione tensione al lembo inferiore della trave
A30: Δϭcp,trave | B30: =-B25*1000/('Caratteristiche trave V185'!B41) -B25*1000*'Caratteristiche trave V185'!B48/('Caratteristiche trave V185'!B46)*('Caratteristiche trave V185'!B43-'Caratteristiche trave V185'!B24) -> -0.28465197 | C30: N/mm2 | D30: =IF(B30 < 0,"Trazione","Compressione") -> Trazione | E30: variazione tensione del cls al trefolo
A31: Tensioni totali cls lembo superiore soletta | G31: D/C
A32: ϭcs2,soletta | B32: =G50 -> -0.96714141 | C32: N/mm2 | D32: =IF(B32 < 0,"Trazione","Compressione") -> Trazione | E32: =IF(D32 = "Trazione", IF(ABS(B32) < Materiali!$B$22/1.2,"VERIFICA", " NON VERIFICA"), IF(B32 < 0.7*Materiali!$B$16,"VERIFICA", " NON VERIFICA")) -> VERIFICA | F32: =IF(D32="Trazione","ϭ > fctm(t)/1.2", "ϭ < 0.6fck(t)") -> ϭ > fctm(t)/1.2 | G32: =ABS(B32/IF(D32 = "Trazione", Materiali!$B$22/1.2, 0.7*Materiali!$B$16)) -> 0.35285958
A33: Tensioni totali cls lembo sinferiore soletta
A34: ϭci3,soletta | B34: =G51 -> -2.0069152 | C34: N/mm2 | D34: =IF(B34 < 0,"Trazione","Compressione") -> Trazione | E34: =IF(D34 = "Trazione", IF(ABS(B34) < Materiali!$B$22/1.2,"VERIFICA", " NON VERIFICA"), IF(B34 < 0.7*Materiali!$B$16,"VERIFICA", " NON VERIFICA")) -> VERIFICA | F34: =IF(D34="Trazione","ϭ > fctm(t)/1.2", "ϭ < 0.6fck(t)") -> ϭ > fctm(t)/1.2 | G34: =ABS(B34/IF(D34 = "Trazione", Materiali!$B$22/1.2, 0.7*Materiali!$B$16)) -> 0.73221893
A35: Tensioni totali cls lembo superiore trave
A36: ϭcs2,trave | B36: =G54 -> 13.67503 | C36: N/mm2 | D36: =IF(B36 < 0,"Trazione","Compressione") -> Compressione | E36: =IF(D36 = "Trazione", IF(ABS(B36) < Materiali!$B$22/1.2,"VERIFICA", " NON VERIFICA"), IF(B36 < 0.7*Materiali!$B$16,"VERIFICA", " NON VERIFICA")) -> VERIFICA | F36: =IF(D36="Trazione","ϭ > fctm(t)/1.2", "ϭ < 0.6fck(t)") -> ϭ < 0.6fck(t) | G36: =ABS(B36/IF(D36 = "Trazione", Materiali!$B$22/1.2, 0.7*Materiali!$B$16)) -> 0.49858047
A37: Tensioni totali cls lembo inferiore trave
A38: ϭci2,trave | B38: =G55 -> 5.1787577 | C38: N/mm2 | D38: =IF(B38 < 0,"Trazione","Compressione") -> Compressione | E38: =IF(D38 = "Trazione", IF(ABS(B38) < Materiali!$B$22/1.2,"VERIFICA", " NON VERIFICA"), IF(B38 < 0.7*Materiali!$B$16,"VERIFICA", " NON VERIFICA")) -> VERIFICA | F38: =IF(D38="Trazione","ϭ > fctm(t)/1.2", "ϭ < 0.6fck(t)") -> ϭ < 0.6fck(t) | G38: =ABS(B38/IF(D38 = "Trazione", Materiali!$B$22/1.2, 0.7*Materiali!$B$16)) -> 0.18881329
A39: Tensioni totali cls nel cavo
A40: Tensione nel cavo dopo le perdite in fase 1 e le cadute di tensione al peso dei carichi g2
A41: ϭsp2 | B41: =ABS(B30+B22+B12)*'Caratteristiche trave V185'!B37 +'fase 1 '!B26 -> 1084.3023 | C41: N/mm2 | D41: Tensione trefoli | E41: =IF(B41<MIN(Materiali!B32:B33),"VERIFICA", " NON VERIFICA") -> VERIFICA | F41: ϭs < min ( 0.9 fpk, 0.8 fp0k) | G41: =B41/MIN(Materiali!B32:B33) -> 0.72869781
C47: FASE 1 | D47: G2 -Fase 2 | E47: RITIRO | F47: perdite
...

Sheet fase 3
A1: SOLETTA COLLABORANTE & CARICHI MOBILI : fase 3
A2: Mmax | B2: 9400 | C2: KN/m | D2: g2 trave esterna
A3: s | B3: ='fase 0 '!B3 -> 16 | C3: m | D3: ascissa
A4: Mmax | B4: =B2-'fase 0 '!B4-'fase 1 '!B6-'fase 2 '!B6 -> 3077.44 | C4: KNm | D4: Momento a s della trave più caricata
A5: Variazioni di tensione dovute a Mmax
A6: Δϭcs,soletta | B6: =B4*1000^2/('Caratteristiche trave V185'!B38*'Caratteristiche trave V185'!B46)*'Caratteristiche trave V185'!B44 -> 2.7521872 | C6: N/mm2 | D6: tensione al lembo superiore della soletta
A7: Δϭci,soletta | B7: =B4*1000^2/('Caratteristiche trave V185'!B38*'Caratteristiche trave V185'!B46)*'Caratteristiche trave V185'!B45 -> 1.9359988 | C7: N/mm2 | D7: tensione al lembo inferiore della soletta
A8: Δϭcs,trave | B8: =B4*1000^2/('Caratteristiche trave V185'!B46)*'Caratteristiche trave V185'!B45 -> 2.0361174 | C8: N/mm2 | D8: tensione al lembo superiore della trave
A9: Δϭci,trave | B9: =-B4*1000^2/('Caratteristiche trave V185'!B46)*'Caratteristiche trave V185'!B43 -> -4.3160196 | C9: N/mm2 | D9: tensione al lembo inferiore della trave
A10: Δϭcp,trave | B10: =-B4*1000^2/('Caratteristiche trave V185'!B46)*('Caratteristiche trave V185'!B43-'Caratteristiche trave V185'!B24) -> -2.9063411 | C10: N/mm2 | D10: tensione del cls al trefolo
A11: Δϭcsp | B11: =-B4*1000^2/('Caratteristiche trave V185'!B16*'Caratteristiche trave V185'!B46)*('Caratteristiche trave V185'!B43-'Caratteristiche trave V185'!B24) -> -0.48439019 | C11: N/mm2 | D11: tensione del cls al trefolo
A12: Tensioni totali cls lembo superiore soletta | G12: D/C
A13: ϭcs3,soletta | B13: =E31 -> 1.7850458 | C13: N/mm2 | D13: =IF(B13 < 0,"Trazione","Compressione") -> Compressione | E13: =IF(D13 = "Trazione", IF(ABS(B13) < Materiali!$B$22/1.2,"VERIFICA", " NON VERIFICA"), IF(B13 < 0.7*Materiali!$B$16,"VERIFICA", " NON VERIFICA")) -> VERIFICA | F13: =IF(D13="Trazione","ϭ > fctm(t)/1.2", "ϭ < 0.6fck(t)") -> ϭ < 0.6fck(t) | G13: =ABS(B13/IF(D13 = "Trazione", Materiali!$B$22/1.2, 0.7*Materiali!$B$16)) -> 0.065081317
A14: Tensioni totali cls lembo sinferiore soletta
A15: ϭci3,soletta | B15: =E32 -> -0.070916366 | C15: N/mm2 | D15: =IF(B15 < 0,"Trazione","Compressione") -> Trazione | E15: =IF(D15 = "Trazione", IF(ABS(B15) < Materiali!$B$22/1.2,"VERIFICA", " NON VERIFICA"), IF(B15 < 0.7*Materiali!$B$16,"VERIFICA", " NON VERIFICA")) -> VERIFICA | F15: =IF(D15="Trazione","ϭ > fctm(t)/1.2", "ϭ < 0.6fck(t)") -> ϭ > fctm(t)/1.2 | G15: =ABS(B15/IF(D15 = "Trazione", Materiali!$B$22/1.2, 0.7*Materiali!$B$16)) -> 0.025873692
A16: Tensioni totali cls lembo superiore trave
A17: ϭcs3,trave | B17: =E35 -> 15.711147 | C17: N/mm2 | D17: =IF(B17 < 0,"Trazione","Compressione") -> Compressione | E17: =IF(D17 = "Trazione", IF(ABS(B17) < Materiali!$B$22/1.2,"VERIFICA", " NON VERIFICA"), IF(B17 < 0.7*Materiali!$B$16,"VERIFICA", " NON VERIFICA")) -> VERIFICA | F17: =IF(D17="Trazione","ϭ > fctm(t)/1.2", "ϭ < 0.6fck(t)") -> ϭ < 0.6fck(t) | G17: =ABS(B17/IF(D17 = "Trazione", Materiali!$B$22/1.2, 0.7*Materiali!$B$16)) -> 0.57281565
A18: Tensioni totali cls lembo inferiore trave
A19: ϭci3,trave | B19: =E36 -> 0.86273818 | C19: N/mm2 | D19: =IF(B19 < 0,"Trazione","Compressione") -> Compressione | E19: =IF(D19 = "Trazione", IF(ABS(B19) < Materiali!$B$22/1.2,"VERIFICA", " NON VERIFICA"), IF(B19 < 0.7*Materiali!$B$16,"VERIFICA", " NON VERIFICA")) -> VERIFICA | F19: =IF(D19="Trazione","ϭ > fctm(t)/1.2", "ϭ < 0.6fck(t)") -> ϭ < 0.6fck(t) | G19: =ABS(B19/IF(D19 = "Trazione", Materiali!$B$22/1.2, 0.7*Materiali!$B$16)) -> 0.031454732
A20: Tensioni totali cls nel cav0
A21: Tensione nel cavo dopo le perdite in fase 1 e le cadute di tensione al peso dei carichi g2
A22: ϭsp3 | B22: ='fase 2 '!B41+ABS('fase 3'!B11) -> 1084.7867 | C22: N/mm2 | D22: Tensione trefoli | E22: =IF(B22<MIN(Materiali!B32:B33),"VERIFICA", " NON VERIFICA") -> VERIFICA | F22: ϭs < min ( 0.9 fpk, 0.8 fp0k) | G22: =B22/MIN(Materiali!B32:B33) -> 0.72902334
A23: Tensioni totali cls nel cavo dopo le perdite
A24: Δϭcsp3 | B24: 37.31 | C24: N/mm2
A25: ϭsp3 | B25: =B22+B24 -> 1122.0967 | C25: N/mm2 | D25: Tensione trefoli | E25: =IF(B25<MIN(Materiali!B32:B33),"VERIFICA", " NON VERIFICA") -> VERIFICA | F25: ϭs < min ( 0.9 fpk, 0.8 fp0k) | G25: =B25/MIN(Materiali!B32:B33) -> 0.75409726
C28: FASE 2 | D28: Q -Fase 3
A29: Punto | B29: y | C29: ϭ | D29: ϭ | E29: ϭtot
A30: 1 | B30: ='fase 2 '!B49 -> 1029 | C30: ='fase 2 '!G49 -> 0 | D30: 0 | E30: =SUM(C30:D30) -> 0
A31: 2 | B31: ='fase 2 '!B50 -> 1029 | C31: ='fase 2 '!G50 -> -0.96714141 | D31: =B6 -> 2.7521872 | E31: =SUM(C31:D31) -> 1.7850458
A32: 3 | B32: ='fase 2 '!B51 -> 779 | C32: ='fase 2 '!G51 -> -2.0069152 | D32: =B7 -> 1.9359988 | E32: =SUM(C32:D32) -> -0.070916366
A33: 4 | B33: ='fase 2 '!B52 -> 779 | C33: ='fase 2 '!G52 -> 0.76642873 | D33: 0 | E33: =SUM(C33:D33) -> 0.76642873
A34: 5 | B34: ='fase 2 '!B53 -> 779 | C34: ='fase 2 '!G53 -> 0.76642873 | D34: =B8 -> 2.0361174 | E34: =SUM(C34:D34) -> 2.8025461
A35: 6 | B35: ='fase 2 '!B54 -> 779 | C35: ='fase 2 '!G54 -> 13.67503 | D35: =D34 -> 2.0361174 | E35: =SUM(C35:D35) -> 15.711147
A36: 7 | B36: ='fase 2 '!B55 -> -1071 | C36: ='fase 2 '!G55 -> 5.1787577 | D36: =B9 -> -4.3160196 | E36: =SUM(C36:D36) -> 0.86273818
A37: 8 | B37: ='fase 2 '!B56 -> -1071 | C37: ='fase 2 '!G56 -> 0 | D37: 0 | E37: =SUM(C37:D37) -> 0

Sheet Perdite di tiro 
A1: PERDITE TRAVE V140 | P1: DATI GEOMETRICI SOLETTA | S1: sbalzo soletta
A2: Ac | B2: ='Caratteristiche trave V185'!B5/1000^2 -> 0.8763 | C2: m | D2: Area sezione | P2: L1 | Q2: 0.63 | R2: m | S2: interasse travi
A3: P | B3: =9119.7685/1000 -> 9.1197685 | C3: m | D3: Perimetro disposto al atmosfera | P3: L2 | Q3: 1.24 | R3: m | S3: larghezza totale soletta
A4: yG | B4: ='Caratteristiche trave V185'!B7/1000 -> 1.049 | C4: m | D4: baricentro sezione cls in assenza di ferri | P4: Ltot | Q4: ='Caratteristiche trave V185'!B30*4 -> 10 | R4: m | S4: spessore soletta strutturale
A5: Jx | B5: ='Caratteristiche trave V185'!B9/1000^4 -> 0.33158361 | C5: m4 | D5: Momento d'inerzia sezione | P5: Ss | Q5: ='Caratteristiche trave V185'!B31 -> 0.25 | R5: m | S5: spessore max. soletta di pendenza
A6: L | B6: ='Caratteristiche trave V185'!B2 -> 32 | C6: m | D6: Luce trave | P6: Sspmax | Q6: 0.22 | R6: m | S6: spessore min. soletta di pendenza
A7: CALCESTRUZZO C45/55 | P7: Sspmin | Q7: =(2.3+0.8+1.15)*0.025 -> 0.10625 | R7: m
A8: fck | B8: =Materiali!B4 -> 45.65 | C8: N/mm2 | D8: Resistenza caratteristica cilindrica a compressione | P8: MATERIALI SOLETTA
A9: Rck | B9: =Materiali!B3 -> 55 | C9: N/mm2 | D9: Resistenza caratteristica cubica a compressione | P9: CALCESTRUZZO C35/45 | S9: Resistenza caratteristica cilindrica a compressione
A10: VISCOSITA - RITIRO | P10: fck | Q10: =Materiali!K4 -> 37.35 | R10: N/mm2 | S10: Resistenza caratteristica cubica a compressione
A11: Ac | B11: =B2 -> 0.8763 | C11: m2 | D11: DimArea sezioneensione equivalente per | P11: Rck | Q11: =Materiali!K3 -> 45 | R11: N/mm2 | S11: Classe di esposizione
A12: u | B12: =B3 -> 9.1197685 | C12: m | D12: Perimetro disposto al atmosfera | P12: Cesp. | Q12: XS1 | R12: -
A13: h0 | B13: =B11*2/B12*1000 -> 192.17593 | C13: mm | D13: Altezza equivalente
A14: RH | B14: 80 | C14: % | D14: Umidità relativa
A15: ϕRH | B15: =1+(1-B14/100)/(0.1*(B13)^(1/3)) -> 1.3465748 | C15: - | D15: Coeff. Ridutt. Per ritiro
A16: β(fcm) | B16: =16.8/SQRT(35+8) -> 2.561976 | C16: -
A17: β0 | B17: =1/(0.1+7^0.2) -> 0.63460911 | C17: -
A18: (t-t0) | B18: =50*365-7 -> 18243 | C18: giorni
A19: βH | B19: =MIN(1.5*(1+(0.012*B14)^18)*B13+250,1500) -> 676.51622 | C19: - | P19: VALUTAZIONE EFFETTI VISCOSITA - RITIRO
A20: β(t-t0) | B20: =(B18/(B19+B18))^0.3 -> 0.98913568 | C20: - | P20: Ac | Q20: =Q4*Q5 -> 2.5 | R20: m2 | S20: DimArea sezioneensione equivalente per
A21: ϕ0 | B21: =B15*B16*B17 -> 2.1893331 | C21: - | P21: u | Q21: =2*(Q4+Q5) -> 20.5 | R21: m | S21: Perimetro disposto al atmosfera
A22: ϕvisc. | B22: =B21*B20 -> 2.1655475 | C22: - | D22: Coefficiente viscoso | P22: h0 | Q22: =Q20*2/Q21*1000 -> 243.90244 | R22: mm | S22: Dimensione equivalente per
A23: Ψp | B23: 0.55 | C23: - | D23: Coefficiente di correzione per viscosità | P23: RH | Q23: 80 | R23: % | S23: Umidità relativa
A24: Ψvisc. | B24: 1.1 | C24: - | D24: Coefficiente di correzione per viscosità | P24: ϕRH | Q24: =1+(1-Q23/100)/(0.1*(Q22)^(1/3)) -> 1.3201041 | R24: - | S24: Coeff. Ridutt. Per ritiro
A25: Ecm,cls | B25: =22000*(($B$8+8)/10)^0.3 -> 36416.114 | C25: N/mm2 | D25: Modulo elastico cls a breve termine | P25: β(fcm) | Q25: =16.8/SQRT(35+8) -> 2.561976 | R25: -
A26: ERitiro | B26: =B25/(1+B23+B15) -> 12572.13 | C26: N/mm2 | D26: Modulo elastico cls a ritiro | P26: β0 | Q26: =1/(0.1+7^0.2) -> 0.63460911 | R26: -
A27: Evisc. | B27: =B25/(1+B24*B22) -> 10767.301 | C27: N/mm2 | D27: Modulo elastico cls viscoo | P27: (t-t0) | Q27: =50*365-7 -> 18243 | R27: giorni
A28: Ecm,fissurato | B28: =B25/2 -> 18208.057 | C28: N/mm3 | D28: Modulo elastico cls fissurato | P28: βH | Q28: =MIN(1.5*(1+(0.012*Q23)^18)*Q22+250,1500) -> 791.31829 | R28: -
A29: n0 | B29: =210000/B25 -> 5.7666779 | C29: - | P29: β(t-t0) | Q29: =(Q27/(Q28+Q27))^0.3 -> 0.98734215 | R29: -
A30: nRitiro | B30: =210000/B26 -> 16.703614 | C30: - | P30: ϕ0 | Q30: =Q24*Q25*Q26 -> 2.1462956 | R30: -
A31: nVisc. | B31: =210000/B27 -> 19.503494 | C31: - | H31: fck | I31: εc0 | P31: ϕvisc. | Q31: =Q30*Q29 -> 2.1191282 | R31: -
A32: nfissurato | B32: =210000/B28 -> 11.533356 | C32: - | H32: 20 | I32: 0.3 | P32: Ψp | Q32: 0.55 | R32: -
A33: DEFORMAZIONE PER RITIRO | H33: 40 | I33: 0.24 | P33: Ψvisc. | Q33: 1.1 | R33: -
A34: εca,ꚙ | B34: =-2.5*($B$8-10)*10^-6 -> -8.9125e-05 | C34: - | D34: Ritiro per autogeno | H34: 60 | I34: 0.19 | P34: Ecm,cls | Q34: =22000*((Q10+8)/10)^0.3 -> 34625.485 | R34: N/mm2 | S34: Modulo elastico cls a breve termine
A35: βds | B35: =B18/(B18+0.04*B13^(3/2)) -> 0.99419259 | C35: - | H35: 80 | I35: 0.15 | P35: ERitiro | Q35: =Q34/(1+Q32+Q24) -> 12064.191 | R35: N/mm2 | S35: Modulo elastico cls a ritiro
A36: εc0 | B36: =-40/$B$8*0.24 -> -0.21029573 | C36: - | P36: Evisc. | Q36: =Q34/(1+Q33*Q31) -> 10394.794 | R36: N/mm2 | S36: Modulo elastico cls viscoo
A37: Kh | B37: =3*10^-6*B13^2 - 0.0023*B13 + 1.2 -> 0.86879012 | C37: - | H37: h0 | I37: Kh | P37: Ecm,fissurato | Q37: =Q34/2 -> 17312.743 | R37: N/mm3 | S37: Modulo elastico cls fissurato
A38: εc0 | B38: =-0.3795*EXP(-(0.012*B8)) -> -0.21943468 | C38: - | H38: 100 | I38: 1 | P38: n0 | Q38: =210000/Q34 -> 6.064897 | R38: - | S38: Coefficiente di omogenizzazione iniziale
A39: εcd,ꚙ | B39: =B38*B37/1000 -> -0.00019064268 | C39: - | H39: 200 | I39: 0.85 | P39: nRitiro | Q39: =210000/Q35 -> 17.406886 | R39: - | S39: Coefficiente di omogenizzazione per ritiro
A40: εcd | B40: =B35*B39 -> -0.00018953554 | C40: - | D40: Ritiro per esseccamento | H40: 300 | I40: 0.75 | P40: nVisc. | Q40: =210000/Q36 -> 20.20242 | R40: - | S40: Coefficiente di omogenizzazione per viscosità
...

Sheet verifica sollevamento
A1: Fsollevamento | B1: ='fase 0 '!B2*'Caratteristiche trave V185'!B2 -> 791.04 | C1: KN
A2: nganci | B2: 4 | C2: 2 per testata
A3: Fi | B3: =B1/B2 -> 197.76 | C3: KN
A4: Φl | B4: 12 | C4: mm
A6: Vrd | B6: =(Materiali!O4*(B4^2/4*PI()))/1000 -> 44.255479 | C6: KN

Sheet SLU ( M, V, T )
A1: SOLLECITAZIONI SLU | K1: VERIFICA A TAGLIO | R1: VERIFICA A TORSIONE PURA | U1: nel nostro caso non è pura | AH1: VERIFICA TORSIONE CON TAGLIO E FLESSIONE SOLETTE
A2: N | B2: M | U2: Considero pure la soletta. Ho una sezione chiusa
A3: KN | B3: KNm | K3: SOLLECITAZIONI SLU | R3: SOLLECITAZIONI SLU | AH3: Bsup | AI3: 2500 | AJ3: mm
A4: =-D32 -> -445.696 | B4: =I32 -> 7589.6098 | K4: VED,tot | L4: 1250 | M4: KN | R4: T | S4: 500 | T4: KNm | AH4: Binf | AI4: 900 | AJ4: mm
A5: =-D33 -> -440.102 | B5: =I33 -> 7594.044 | K5: VED,anima | L5: =L4/2 -> 625 | M5: KN | AA5: VERIFICA TORSIONE CON TAGLIO E FLESSIONE PARETI LATERALI | AH5: zsup | AI5: ='Caratteristiche trave V185'!B44 - 'Caratteristiche trave V185'!B31*1000/2 -> 718 | AJ5: mm
A6: =-D34 -> -438.747 | B6: =I34 -> 7639.0112 | R6: PARAMETRI | AH6: zinf | AI6: ='Caratteristiche trave V185'!B44 -AB8/2 -> 693 | AJ6: mm | AL6: N | AM6: 0 | AN6: KN | AO6: sforzo normale di trazione e compressione
A7: =-D35 -> -435.772 | B7: =I35 -> 7639.7309 | K7: Calcolo resistenza a taglio dell'ala | R7: A | S7: 2521211 | T7: mm2 | AA7: H | AB7: ='Caratteristiche trave V185'!B4 -> 1850 | AC7: mm | AD7: altezza complessiva della sezione | AH7: VERIFICA TORSIONE CON TAGLIO E FLESSIONE SOLETTA INFERIORE
A8: =-D36 -> -434.417 | B8: =I36 -> 7614.861 | K8: b | L8: 290 | M8: mm | R8: u | S8: 6575 | T8: mm | U8: area racchiusa dalla linea medea della sezione | AA8: tsinf | AB8: 300 | AC8: mm | AD8: spessore soletta inferiore | AH8: Verifica taglio armatura longitudinale
A9: =-D37 -> -436.842 | B9: =I37 -> 7611.301 | K9: h | L9: 1400 | M9: mm | R9: t | S9: =S7/S8 -> 383.45414 | T9: mm | U9: perimetro medio del nucleo resistente della sezione | AA9: Fti | AB9: =S4*(AB7-AB8)/1000/(2*S7/1000^2)*S18 -> 173.72178 | AC9: KN | AD9: taglio da torsione | AH9: Vsdi (inf) | AI9: =S4*1000*(AI4-S9)/(2*S7) -> 51.220014 | AJ9: KN
A10: =-D38 -> -435.487 | B10: =I38 -> 7506.4073 | K10: Φ | L10: 12 | M10: mm | R10: Φl | S10: 12 | T10: mm | U10: spessore medio della sezione aperta | AA10: Vsdi | AB10: =AB9+L5 -> 798.72178 | AC10: KN | AD10: Taglio totale (taglio puro + taglio da torsione ) | AH10: Ftrd | AI10: =AN14 -> 885.10958 | AJ10: KN | AM10: Verifica trazione armatura longitudinale
A11: =-D39 -> -440.632 | B11: =I39 -> 7499.1525 | K11: passo | L11: 200 | M11: mm | R11: nΦl (soletta) | S11: =18*2 -> 36 | U11: aumentarlo finchè ctgθ non diventa almeno =>1 | AA11: Verifica armatura longitudinale | AH11: D/C | AI11: =AI9/AI10 -> 0.057868557 | AJ11: =IF((AI11 < 1),"VERIFICA", " NON VERIFICA") -> VERIFICA | AM11: Φl | AN11: =S10 -> 12 | AO11: mm
A12: =-D40 -> -439.277 | B12: =I40 -> 7312.4958 | K12: θ | L12: =ASIN(SQRT(2*L10^2/4*PI()*Materiali!$O$4/($L$8*L11*0.5*Materiali!$B$5))) -> 0.3506315 | M12: [rad] | N12: Angolo per cui VRsd = VRcd | R12: nΦl (trave ) | S12: 48 | U12: sopra e sotto la soletta | AA12: nΦl (parete) | AB12: =2*9 -> 18 | AH12: VERIFICA TORSIONE CON TAGLIO E FLESSIONE SOLETTA SUPERIORE | AM12: nΦl (soletta inf) | AN12: 20
A13: =-D41 -> -472.349 | B13: =I41 -> 7301.849 | K13: θ | L13: =DEGREES(L12) -> 20.089705 | M13: [gradi] | R13: Asl | S13: =(S12+S11)*S10^2/4*PI() -> 9500.1762 | T13: mm2 | U13: complessive nella trave | AA13: Asl | AB13: =AB12*S10^2/4*PI() -> 2035.752 | AC13: mm2 | AH13: Verifica taglio armatura longitudinale | AM13: Asl | AN13: =AN12*AN11^2/4*PI() -> 2261.9467 | AO13: mm2
A14: =-D42 -> -470.994 | B14: =I42 -> 7032.2272 | K14: θ | L14: =IF(L13<21.8,21.8,L13) -> 21.8 | M14: [gradi] | N14: Angolo minimo da norma | R14: Ast | S14: =L16*L10^2/4*PI() -> 226.19467 | T14: mm2 | AA14: Ftrd | AB14: =AB13*Materiali!O4/1000 -> 796.59862 | AC14: KN | AH14: Φl | AI14: 12 | AJ14: mm | AM14: Ftrd | AN14: =AN13*Materiali!O4/1000 -> 885.10958 | AO14: KN
A15: =-D43 -> -511.364 | B15: =I43 -> 7017.5675 | K15: θ | L15: =RADIANS(L14) -> 0.38048178 | M15: [rad] | R15: passo Ast | S15: =L11 -> 200 | T15: mm | AA15: D/C | AB15: =AB9/AB14 -> 0.21807944 | AC15: =IF((AB15 < 1),"VERIFICA", " NON VERIFICA") -> VERIFICA | AH15: nΦl (soletta inf) | AI15: 20 | AM15: D/C | AN15: =AM6/AN14 -> 0 | AO15: =IF((AN15 < 1),"VERIFICA", " NON VERIFICA") -> VERIFICA
A16: =-D44 -> -510.008 | B16: =I44 -> 6662.1554 | K16: nbracci | L16: 2 | N16: Taglio resistente armatura d'anima | R16: al | S16: =S13/S8 -> 1.4448937 | T16: mm | AA16: Verifica armatura longitudinale | AH16: Asl | AI16: =AI15*AI14^2/4*PI() -> 2261.9467 | AJ16: mm2
A17: =-D45 -> -555.325 | B17: =I45 -> 6644.4332 | K17: VRsd | L17: =(0.9*($L$9-30)*(L16*PI()*L10^2/4)/L11*Materiali!$O$4)/1000*_xlfn.COT(L15) -> 1364.2725 | M17: KN | N17: taglio resistente biella compressa | R17: as | S17: =S14/S15 -> 1.1309734 | T17: mm | AA17: Ast | AB17: =L16*L10^2/4*PI() -> 226.19467 | AC17: mm2 | AH17: Vsdi (inf) | AI17: =S4*1000*(AI3)/(2*S7) -> 247.89674 | AJ17: KN
A18: =-D46 -> -553.97 | B18: =I46 -> 6200.1124 | K18: VRcd | L18: =(0.9*($L$9-30)*$L$8*0.5*Materiali!$B$5)*(_xlfn.COT(L15))/(1+_xlfn.COT(L15)^2)/1000 -> 1594.7004 | M18: KN | R18: ctgθ | S18: =(S16/S17)^(1/2) -> 1.1302949 | T18: [rad] | U18: =IF(S18<=2.5,"OK","NO") -> OK | AA18: s | AB18: =S15 -> 200 | AC18: mm | AH18: Ftrd | AI18: =AI16*Materiali!O4/1000 -> 885.10958 | AJ18: KN
A19: =-D47 -> -612.882 | B19: =I47 -> 6206.9584 | K19: VRd | L19: =MIN(L17:L18) -> 1364.2725 | M19: KN | R19: θ | S19: =_xlfn.ACOT(S18) -> 0.72431142 | T19: [rad] | AA19: Vrd | AB19: =AB17*Materiali!O4*S18/AB18 -> 500.21742 | AC19: KN | AH19: D/C | AI19: =AI17/AI18 -> 0.28007464 | AJ19: =IF((AI19 < 1),"VERIFICA", " NON VERIFICA") -> VERIFICA
A20: =-D48 -> -611.623 | B20: =I48 -> 5599.0363 | K20: D/C | L20: =L5/L19 -> 0.45811963 | M20: =IF((L20 < 1),"VERIFICA", " NON VERIFICA") -> VERIFICA | R20: RESISTENZE | AA20: D/C | AB20: =AB9/AB19 -> 0.34729255 | AC20: =IF((AB20 < 1),"VERIFICA", " NON VERIFICA") -> VERIFICA
A21: =-D49 -> -665.799 | B21: =I49 -> 5578.0245 | R21: fcd' | S21: =0.85*(1-Materiali!B4/250)*Materiali!B5 -> 17.973059 | T21: N/mm2 | AA21: Verifica bielle compresse
A22: =-D50 -> -664.541 | B22: =I50 -> 4887.0778 | R22: Trcd | S22: =(2*S7*S9*S21*S18/(1+S18^2))/1000^2 -> 17246.276 | T22: KNm | AA22: fcd2 | AB22: =0.7*S21 -> 12.581142 | AC22: N/mm2 | AD22: resistenza calcestruzzo fessurato
A23: =-D51 -> -694.048 | B23: =I51 -> 4874.6495 | R23: Trsd | S23: =(2*S7*S14/S15*Materiali!O4*S18)/1000^2 -> 2522.3073 | T23: KNm | U23: sforzi di compressione sono affidati alle bielle di calcestruzzo. | AA23: ϭRD | AB23: =AB22*COS(S19)*SIN(S19) -> 6.2436815 | AC23: N/mm2 | AD23: controllare
A24: =-D52 -> -692.79 | B24: =I52 -> 4092.3701 | R24: Trld | S24: =(2*S7*S13/S8*Materiali!O4/S18)/1000^2 -> 2522.3073 | T24: KNm | U24: riferimento alle staffe trasversali | AA24: ϭSD | AB24: =AB10*1000/(2*S7) -> 0.15840042 | AC24: N/mm2
A25: =-D53 -> -688.03 | B25: =I53 -> 4093.9777 | R25: TRd | S25: =MIN(S22:S24) -> 2522.3073 | T25: KNm | U25: riferimento all’armatura longitudinale | AA25: D/C | AB25: =AB24/AB23 -> 0.025369716 | AC25: =IF((AB25 < 1),"VERIFICA", " NON VERIFICA") -> VERIFICA
A26: =-D54 -> 0 | B26: =I54 -> 0
B32: 12.01923 | C32: Max | D32: 445.696 | E32: 94.88 | F32: 8.487 | G32: 71.2245 | H32: 414.9879 | I32: 7589.6098
B33: 12.01923 | C33: Max | D33: 440.102 | E33: 119.372 | F33: 18.869 | G33: 73.5877 | H33: 413.3242 | I33: 7594.044
B34: 12.98077 | C34: Max | D34: 438.747 | E34: 163.369 | F34: 18.869 | G34: 73.5877 | H34: 415.2697 | I34: 7639.0112
B35: 12.98077 | C35: Max | D35: 435.772 | E35: 187.9 | F35: 30.978 | G35: 81.4086 | H35: 417.2101 | I35: 7639.7309
B36: 13.94231 | C36: Max | D36: 434.417 | E36: 231.897 | F36: 30.978 | G36: 81.4086 | H36: 407.082 | I36: 7614.861
B37: 13.94231 | C37: Max | D37: 436.842 | E37: 257.422 | F37: 43.449 | G37: 90.6668 | H37: 413.4289 | I37: 7611.301
B38: 14.90385 | C38: Max | D38: 435.487 | E38: 301.419 | F38: 43.449 | G38: 90.6668 | H38: 390.1526 | I38: 7506.4073
B39: 14.90385 | C39: Max | D39: 440.632 | E39: 328.606 | F39: 55.317 | G39: 100.6658 | H39: 401.9683 | I39: 7499.1525
B40: 15.86538 | C40: Max | D40: 439.277 | E40: 372.603 | F40: 55.317 | G40: 100.6658 | H40: 364.9021 | I40: 7312.4958
B41: 15.86538 | C41: Max | D41: 472.349 | E41: 402.452 | F41: 65.39 | G41: 109.6644 | H41: 383.7079 | I41: 7301.849
B42: 16.82692 | C42: Max | D42: 470.994 | E42: 446.448 | F42: 65.39 | G42: 109.6644 | H42: 333.9967 | I42: 7032.2272
B43: 16.82692 | C43: Max | D43: 511.364 | E43: 480.134 | F43: 77.834 | G43: 113.6242 | H43: 362.3468 | I43: 7017.5675
... B53: 21.42857 | C53: Max | D53: 688.03 | E53: 1025.364 | F53: 18.138 | G53: 102.6402 | H53: 7.999 | I53: 4093.9777

Sheet dominio
A1: DOMINIO SEZIONE IN MEZZERIA
A2: Diagramma con barre laterali e sup | C2: Diagramma con solo trefoli inf.
A3: N [KN] | B3: M [KNm] | C3: N [KN] | D3: M [KNm]
A4: -15003 | B4: 12868.2 | C4: -10341.6 | D4: 7394.24
A5: -15003 | B5: 12868.2 | C5: -10341.6 | D5: 7394.24
A6: -15003 | B6: 12868.2 | C6: -10341.6 | D6: 7394.24
A7: -15003 | B7: 12868.2 | C7: -10341.6 | D7: 7394.24
A8: -14104.5 | B8: 13583.9 | C8: -10341.6 | D8: 7394.24
A9: -12328.2 | B9: 14966 | C9: -10341.6 | D9: 7394.24
A10: -10560.9 | B10: 16286.9 | C10: -10341.6 | D10: 7394.24
A11: -8944.32 | B11: 17443 | C11: -10139.4 | D11: 7559.4
A12: -5433.67 | B12: 19790.1 | C12: -9632.11 | D12: 7971.88
A13: 1924.43 | B13: 23908.6 | C13: -8952.63 | D13: 8519
A14: 2977.61 | B14: 24212.3 | C14: -8229.67 | D14: 9093.26
A15: 6863.5 | B15: 21605.2 | C15: -7523.85 | D15: 9644.76
... A41: -15003 | B41: 12868.2 | C41: 24297.9 | D41: 11958.3
C42: 24172.9 | D42: 11549.2
C43: 23328.4 | D43: 10657.4
C44: 21764.4 | D44: 9282.98
C45: 19481 | D45: 7425.97
C46: 16478 | D46: 5086.34
C47: 12755.5 | D47: 2264.09
C48: 8478.87 | D48: -267.653
C49: 6503.09 | D49: -1156.49
C50: 5609.66 | D50: -1403.86
C51: 5058.1 | D51: -1474.86
C52: 4608.9 | D52: -1491.69
C53: 4215.46 | D53: -1480.42
... C77: -10341.6 | D77: 7394.24

Sheet verifica connettori
A1: Verifica connettori trave VH185
A2: Nu,tot | B2: =Materiali!B5*'Caratteristiche trave V185'!B30*'Caratteristiche trave V185'!B31*1000 -> 16167.708 | C2: kN | D2: Sforzo normale ultimo della soletta
A3: passo | B3: 200 | C3: mm | D3: passo connettori
A4: nc | B4: =('Caratteristiche trave V185'!B2*1000)/'verifica connettori'!B3*2 -> 320 | C4: - | D4: Numero dei connettori presenti nella trave nelle 2 file
A5: bc | B5: 2 | C5: - | D5: braccia connettore
A6: Φc | B6: 12 | C6: mm | D6: Diametro del connettore
A7: hc | B7: 200 | C7: mm | D7: Altezza del connettore
A8: α | B8: =IF(B7/B6>4,1,0.2/(B7/B6+1)) -> 1 | C8: -
A9: γv | B9: 1.25 | C9: - | D9: Coefficiente di sicurezza
A10: Nuc | B10: =B2/(B4*B5) -> 25.262044 | C10: kN | D10: Taglio sollecitante
A11: PRd,cls | B11: =0.29*B8*B6^2*SQRT(Materiali!K10*Materiali!K4)/1000 -> 47.49017 | C11: kN | D11: resistenza connettore parte cls
A12: PRd,s | B12: =0.8*Materiali!O5*PI()*B6^2/4/1000 -> 48.858049 | C12: kN | D12: resistenza connettore lato acciaio
A13: PRd | B13: =MIN(B11:B12) -> 47.49017 | C13: kN | D13: minimo tra le resistenze del connettore
A14: D/C | B14: =B10/B13 -> 0.53194259 | C14: =IF((B14 < 1),"VERIFICA", " NON VERIFICA") -> VERIFICA
