Workbook

Sheet Materiali
A1: Caratteristeche dei materiali | J1: Caratteristeche dei materiali | N1: Armatura ordinaria B450C
A2: Calcestruzzo travi C45/55 | J2: Calcestruzzo soletta C35/45 | N2: Staffe e reggistaffe
A3: Rck | B3: 55 | C3: N/mm2 | J3: Rck | K3: 45 | L3: N/mm2 | N3: fyk | O3: 450 | P3: N/mm2
A4: fck | B4: =0.83*B3 -> 45.65 | C4: N/mm2 | J4: fck | K4: =0.83*K3 -> 37.35 | L4: N/mm2 | N4: fyd | O4: =O3/1.15 -> 391.30435 | P4: N/mm2
A5: fcd | B5: =0.85*Materiali!B4/1.5 -> 25.868333 | C5: N/mm2 | J5: fcd | K5: =0.85*Materiali!K4/1.5 -> 21.165 | L5: N/mm2 | N5: fuk | O5: 540 | P5: N/mm2
A6: fcm | B6: =B4+8 -> 53.65 | C6: N/mm2 | J6: fcm | K6: =K4+8 -> 45.35 | L6: N/mm2
A7: fctm | B7: =0.3*B4^(2/3) -> 3.8319083 | C7: N/mm2 | D7: Resistenza a trazione cls | J7: fctm | K7: =0.3*K4^(2/3) -> 3.3520848 | L7: N/mm2
A8: fcfm | B8: =1.2*B7 -> 4.59829 | C8: N/mm2 | D8: Resistenza a trazione per flessione | J8: fcfm | K8: =1.2*K7 -> 4.0225017 | L8: N/mm2
A9: ϭct | B9: =B7/1.2 -> 3.1932569 | C9: N/mm2 | D9: Resistenza a trazione prima delle fessure | J9: ϭct | K9: =K7/1.2 -> 2.793404 | L9: N/mm2
A10: Ecm | B10: =22000*(B6/10)^0.3 -> 36416.114 | C10: N/mm2 | J10: Ecm | K10: =22000*(K6/10)^0.3 -> 34625.485 | L10: N/mm2
A11: Caratteristiche cls al trasferimento della precompressione
A12: t | B12: 9 | C12: giorni | D12: momento di trasferimento della precompressione
A13: s | B13: =0.2 -> 0.2
A14: βcc | B14: =EXP(B13*(1-(28/B12)^(0.5))) -> 0.85832983 | D14: coefficiente d'invecchiamento del calcestruzzo
A15: fcm(t) | B15: =B14*B6 -> 46.049395 | C15: N/mm2
A16: fck(t) | B16: =B14*B4 -> 39.182757 | C16: N/mm2
A17: 0.7 fck(t) | B17: =0.7*B16 -> 27.42793 | C17: N/mm2 | D17: valore limite della tensione di esercizio a cadute avvenute della precompressione ( p. 4.1.8.1.4 )
A18: 0.6 fck(t) | B18: =0.6*B16 -> 23.509654 | C18: N/mm2 | D18: valore limite della tensione all'atto della precompressione ( p. 4.1.8.1.3 )
A19: α | B19: =IF(B12<28,1,2/3) -> 1
A20: fctm(t) | B20: =B7*B14^B19 -> 3.2890412 | C20: N/mm2
A21: k | B21: 1 | D21: valore di riduzione della resistenza a trazione del cls per le verifiche del conglomerato
A22: fctm(t) k | B22: =B20*B21 -> 3.2890412 | C22: N/mm2
A24: trefolo a sette fili ( classe 2 )
A25: Φn | B25: 15.2 | C25: mm | D25: Diametro nominale | G25: area ferri laterali | J25: ferri superiori
A26: Anom | B26: 139 | C26: mm2 | D26: Area nominale | G26: =6*B26 -> 834 | J26: =2*B26 -> 278
A27: Ep | B27: =195000 -> 195000 | C27: N/mm2 | D27: Modulo elastico
A28: fpk | B28: 1860 | C28: N/mm2
A29: fp01,k | B29: =1670 -> 1670 | C29: N/mm2
A31: Limiti tensioni massime iniziali all'atto della tesaturaE
A32: ϭs,pi = 0.9 fpk | B32: =0.9*$B$29 -> 1503 | C32: N/mm2
A33: ϭs,pi = 0.8 fp0k | B33: =0.8*$B$28 -> 1488 | C33: N/mm2 | D33: * si prende la condizione più restrittiva
A34: ϭc,max | B34: =0.7*B4 -> 31.955 | C34: N/mm2 | D34: Tensione massima compressione cls
D52: tensione massima comp. Del cls
A53: TENSIONE LIMITE IN ESERCIZIO
D54: tensione limite acciaio armatura pre -tesa
A55: ϭc,max | B55: =0.6*B4 -> 27.39 | C55: N/mm2 | D55: Rara
A56: ϭc,max | B56: =0.45*B4 -> 20.5425 | C56: N/mm2 | D56: Quasi permanente
A57: ϭs,max | B57: =0.8*450 -> 360 | C57: N/mm2 | D57: Tensione massima armatura ordinaria

Sheet Caratteristiche trave V140
A1: Caratteristiche trave
A2: L | B2: 25 | C2: m | D2: Luce trave
A3: Caratteristiche statiche sezione solo calcestruzzo
A4: Hsez | B4: 1400 | C4: mm | D4: Altezza della sezione
A5: Acls | B5: 694400 | C5: mm2 | D5: Area calcestruzzo della sezione
A6: xG | B6: 0 | C6: mm
A7: yG | B7: =704.7 -> 704.7 | C7: mm | D7: posizione baricentro dal lembo inferiore
A8: H - yG | B8: =B4-B7 -> 695.3 | C8: mm | D8: posizione baricentro rispetto al lembo superiore
A9: Ixg | B9: =175763285357 -> 175763285357 | C9: mm4 | D9: Momento d'inerzia baricentrico in direzione x
A10: Iyg | B10: =235294676667 -> 235294676667 | C10: mm4 | D10: Momento d'inerzia baricentrico in direzione y
A11: Wx | B11: =B9/B7 -> 2.4941576e+08 | C11: mm3 | D11: Modulo di resistenza elastico
A12: Armatura sezione
A13: ntref | B13: =SUM(B51:B53) -> 60 | D13: numero trefoli utilizzati
A14: Atref | B14: =B13*Materiali!B26 -> 8340 | C14: mm2 | D14: Area totale trefoli
A15: Caratteristiche sezione omogenizzata interamente reagente
A16: n | B16: 6 | D16: coefficiente omogenizzazione
A17: Atot | B17: =B5+B16*B14 -> 744440 | C17: mm2 | D17: Area totale = Acls + n*Atref
A18: yG | B18: =677.4 -> 677.4 | C18: mm | D18: posizione baricentro dal lembo inferiore
A19: H - yG | B19: =B4-B18 -> 722.6 | C19: mm | D19: posizione baricentro rispetto al lembo superiore
A20: Ixg | B20: =187020932394 -> 187020932394 | C20: mm4 | D20: Momento d'inerzia baricentrico in direzione x
A21: Iyg | B21: =235294676667 -> 235294676667 | C21: mm4 | D21: Momento d'inerzia baricentrico in direzione y
A22: Wx, inf | B22: =B20/B18 -> 2.7608641e+08 | C22: mm3 | D22: Modulo di resistenza elastico
A23: Wx, sup | B23: =B20/B19 -> 2.5881668e+08 | C23: mm3 | D23: Modulo di resistenza elastico
A24: yp | B24: =B56 -> 350 | C24: mm | D24: punto di applicazione dello sforzo normale
A25: e | B25: =B18-B24 -> 327.4 | C25: mm | D25: eccentricità tra il punto di applicazione del tiro e il baricentro della sezione
A27: Caratteristiche sezione omogenizzata interamente reagente con soletta
A29: Caratteristiche soletta
A30: B | B30: 2.5 | C30: m | D30: larghezza soletta
A31: s | B31: 0.25 | C31: m | D31: spessore soletta
A32: Asoletta | B32: =B30*B31*1000^2 -> 625000 | C32: mm2 | D32: Area cls soletta
A33: Φ | B33: =10 -> 10 | C33: mm | D33: diametro armature soletta
A34: As,sup | B34: =10*B33^2*PI()/4 -> 785.39816 | C34: mm2 | D34: area armatura superiore
A35: As,inf | B35: =10*B33^2*PI()/4 -> 785.39816 | C35: mm2 | D35: area armatura inferiore
A36: Caratteristiche sezione omogenizzata
A37: n | B37: 6 | D37: coefficiente omogenizzazione (rapporto tra i due moduli elastici, trefolo e CAP)
A38: n2 | B38: =Materiali!B10/Materiali!K10 -> 1.0517142 | D38: coefficiente omogenizzazione (rapporto tra i due moduli elastici, soletta e CAP)
A39: Acls | B39: =B32+'Caratteristiche trave V140'!B5 -> 1319400 | C39: mm2 | D39: Area cls soletta + trave
A40: Atr | B40: ='Caratteristiche trave V140'!B14 -> 8340 | C40: mm2 | D40: Area trefolo
A41: Atot | B41: =B39+B38*B40+B37*B40 -> 1378211.3 | C41: mm2 | D41: Area totale sezione Atot = Acp + n2*Ac +n*Atr
A42: Hsez | B42: =B31*1000+'Caratteristiche trave V140'!B4 -> 1650 | C42: mm | D42: Altezza totale della sezione
...

Sheet fase 0 
A1: Peso Proprio trave + traversi - fase 0 | I1: Peso Proprio fase 0 | M1: Precompressione fase 0 | Q1: Precompressione fase 0
A2: G1(trave+ traversi) | B2: =(25*'Caratteristiche trave V140'!B5/1000^2)+ (25*1.4*2.5*0.3*4 - 25 *1*2/4*PI())/'Caratteristiche trave V140'!B2 -> 19.989204 | C2: KN/m | I2: X | J2: Y | M2: X | N2: Y | Q2: X | R2: Y
A3: Mg+ | B3: =B2*'Caratteristiche trave V140'!B2^2/8 -> 1561.6565 | C3: KNm | I3: 0 | J3: ='Caratteristiche trave V140'!B19 -> 722.6 | M3: 0 | N3: =J3 -> 722.6 | Q3: =I3+M3 -> 0 | R3: =N3 -> 722.6
A4: Tiro iniziale | D4: Momento massimo dovuto al peso proprio della trave | I4: ='fase 0 '!B3*1000^2/'Caratteristiche trave V140'!B23 -> 6.0338327 | J4: ='Caratteristiche trave V140'!B19 -> 722.6 | M4: =(B12*1000/'Caratteristiche trave V140'!B17) - B12*1000*'Caratteristiche trave V140'!B25/('Caratteristiche trave V140'!B23) -> 0.7188634 | N4: =J4 -> 722.6 | Q4: =I4+M4 -> 6.7526961 | R4: =N4 -> 722.6
A5: Np0 | B5: 10000 | C5: KN | I5: =- 'fase 0 '!B3*1000^2/'Caratteristiche trave V140'!B22 -> -5.656405 | J5: =-'Caratteristiche trave V140'!B18 -> -677.4 | M5: =(B12*1000/'Caratteristiche trave V140'!B17) + B12*1000*'Caratteristiche trave V140'!B25/('Caratteristiche trave V140'!B22) -> 23.218799 | N5: =J5 -> -677.4 | Q5: =I5+M5 -> 17.562394 | R5: =N5 -> -677.4
A6: ϭpi | B6: =B5*1000/'Caratteristiche trave V140'!B14 -> 1199.0408 | C6: N/mm2 | D6: Tensione trefoli | E6: ϭs < min ( 0.9 fpk, 0.8 fp0k) | F6: =IF(B6<MIN(Materiali!B32:B33),"VERIFICA", " NON VERIFICA") -> VERIFICA | I6: 0 | J6: =-'Caratteristiche trave V140'!B18 -> -677.4 | M6: 0 | N6: =J6 -> -677.4 | Q6: =I6+M6 -> 0 | R6: =N6 -> -677.4
A7: Tesnsione cls a livello del cavo al tiro
A8: ϭcc | B8: =B5*1000/'Caratteristiche trave V140'!B17 + B5*1000*'Caratteristiche trave V140'!B25/'Caratteristiche trave V140'!B20*'Caratteristiche trave V140'!B25 -> 19.164401 | C8: N/mm2
A9: Perdite di tensione istantane
A10: ΔNi | B10: ='Perdite di tiro '!B90 -> 819.53295 | C10: KN
A11: Precompressione dopo le perdite di tensione dovute alla deformazione istantanea del cls
A12: Np0 - Δni | B12: =B5-B10 -> 9180.467 | C12: KN
A13: Tesnsione cls a lembo superiore | G13: D/C
A14: ϭcc,sup | B14: =(B12*1000/'Caratteristiche trave V140'!B17) - B12*1000*'Caratteristiche trave V140'!B25/('Caratteristiche trave V140'!B23) + 'fase 0 '!B3*1000^2/'Caratteristiche trave V140'!B23 -> 6.7526961 | C14: N/mm2 | D14: =IF(B14 < 0,"Trazione","Compressione") -> Compressione | E14: =IF(D14="Trazione","ϭ > fctm(t)/1.2", "ϭ < 0.7fck(t)") -> ϭ < 0.7fck(t) | F14: =IF(D14 = "Trazione", IF(ABS(B14) < Materiali!$B$22/1.2,"VERIFICA", " NON VERIFICA"), IF(B14 < 0.7*Materiali!$B$16,"VERIFICA", " NON VERIFICA")) -> VERIFICA | G14: =ABS(B14/IF(D14 = "Trazione", Materiali!$B$22/1.2, 0.7*Materiali!$B$16)) -> 0.24619781
A15: Tesnsione cls a lembo inferiore
A16: ϭcc,inf | B16: =(B12*1000/'Caratteristiche trave V140'!B17) + B12*1000*'Caratteristiche trave V140'!B25/('Caratteristiche trave V140'!B22) - 'fase 0 '!B3*1000^2/'Caratteristiche trave V140'!B22 -> 17.562394 | C16: N/mm2 | D16: =IF(B16 < 0,"Trazione","Compressione") -> Compressione | E16: ϭ < 0.7 fctk (t) | F16: =IF(D16 = "Trazione", IF(ABS(B16) < Materiali!$B$22/1.2,"VERIFICA", " NON VERIFICA"), IF(B16 < 0.7*Materiali!$B$16,"VERIFICA", " NON VERIFICA")) -> VERIFICA | G16: =ABS(B16/IF(D16 = "Trazione", Materiali!$B$22/1.2, 0.7*Materiali!$B$16)) -> 0.64031059
A17: Tensione cls a livello del cavo
A18: ϭcc0 | B18: =B12*1000/'Caratteristiche trave V140'!B17 + ('fase 0 '!B12*1000*'Caratteristiche trave V140'!B25- 'fase 0 '!B3)/'Caratteristiche trave V140'!B20*'Caratteristiche trave V140'!B25 -> 17.593812 | C18: N/mm2 | D18: =IF(B18 < 0,"Trazione","Compressione") -> Compressione | E18: ϭ < 0.7 fctk (t) | F18: =IF(D18 = "Trazione", IF(ABS(B18) < Materiali!$B$22/1.2,"VERIFICA", " NON VERIFICA"), IF(B18 < 0.7*Materiali!$B$16,"VERIFICA", " NON VERIFICA")) -> VERIFICA | G18: =ABS(B18/IF(D18 = "Trazione", Materiali!$B$22/1.2, 0.7*Materiali!$B$16)) -> 0.64145608
A19: Tensione cls nel cavo
A20: Tensioni del cavo dopo le cadute di tensione dovute al peso proprio
A21: ϭsp0 | B21: =B12*1000/'Caratteristiche trave V140'!B14 + 'Caratteristiche trave V140'!B16*'fase 0 '!B3*1000^2/'Caratteristiche trave V140'!B20*'Caratteristiche trave V140'!B25 -> 1117.1785 | C21: N/mm2 | D21: Tensione trefoli | E21: ϭs < min ( 0.9 fpk, 0.8 fp0k) | F21: =IF(B21<MIN(Materiali!B32:B33),"VERIFICA", " NON VERIFICA") -> VERIFICA | G21: =B21/MIN(Materiali!B32:B33) -> 0.750792

Sheet fase 1 
A1: GETTO IN OPERA DELLA SOLETTA : fase 1
A2: (Sezione resistente formata dalla sola trave, soletta considerata solo come carico )
A3: Sollecitazioni al getto della soletta
A4: Gsoletta | B4: =25*'Caratteristiche trave V140'!B30*'Caratteristiche trave V140'!B31 -> 15.625 | C4: KN/m
A5: Mmax | B5: =B4*'Caratteristiche trave V140'!B2^2/8 -> 1220.7031 | C5: KNm | D5: momento massimo sollecitante dovuto al solo peso proprio della soletta
A6: Variazioni di tensione dovute a Mmax
A7: Δϭcs1 | B7: =B5*1000^2/'Caratteristiche trave V140'!B23 -> 4.7164778 | C7: N/mm2 | D7: Variazione di tensione nel cls al lembo superiore
A8: Δϭci1 | B8: =-B5*1000^2/'Caratteristiche trave V140'!B22 -> -4.4214532 | C8: N/mm2 | D8: Variazione di tensione nel cls al lembo inferiore
A9: Δϭcc1 | B9: =-B5*1000^2*'Caratteristiche trave V140'!B25/'Caratteristiche trave V140'!B20 -> -2.1369704 | C9: N/mm2 | D9: variazione di tensione nel cls al livello del baricentro dei cavi
A11: A favore di sicurezza si è considerato che il getto della soletta avvenga dopo molto tempo rispetto al tiro delle travi in precompresso, in modo da poter considerare, in questa fase tutte le perdite di tensione lente riguardo la precompressione.
A12: Variazioni di tensione dovute alle perdite di precompressione
A13: ΔNt | B13: ='Perdite di tiro '!B94 -> 1939.0143 | C13: KN | D13: Perdita totale di precompressione
A14: Δϭcs1 | B14: =-B13*1000/'Caratteristiche trave V140'!B17 + B13*1000*'Caratteristiche trave V140'!B25/'Caratteristiche trave V140'!B23 -> -0.15183176 | C14: N/mm2 | D14: =IF(B14 < 0,"Trazione","Compressione") -> Trazione | E14: Variazione di tensione nel cls al lembo superiore
A15: Δϭc1 | B15: =-B13*1000/'Caratteristiche trave V140'!B17 - B13*1000*'Caratteristiche trave V140'!B25/'Caratteristiche trave V140'!B22 -> -4.9040624 | C15: N/mm2 | D15: =IF(B15 < 0,"Trazione","Compressione") -> Trazione | E15: Variazione di tensione nel cls al lembo inferiore
A16: Δϭcc1 | B16: =-B13*1000/'Caratteristiche trave V140'!B17 - B13*1000*'Caratteristiche trave V140'!B25^2/'Caratteristiche trave V140'!B20 -> -3.7160047 | C16: N/mm2 | D16: =IF(B16 < 0,"Trazione","Compressione") -> Trazione | E16: variazione di tensione nel cls al livello del baricentro dei cavi
A17: Tensione cls lembo superiore | G17: D/C
A18: ϭcs1 | B18: ='fase 0 '!B14 +'fase 1 '!B7+'fase 1 '!B14 -> 11.317342 | C18: N/mm2 | D18: =IF(B18 < 0,"Trazione","Compressione") -> Compressione | E18: =IF(D18 = "Trazione", IF(ABS(B18) < Materiali!$B$22/1.2,"VERIFICA", " NON VERIFICA"), IF(B18 < 0.7*Materiali!$B$16,"VERIFICA", " NON VERIFICA")) -> VERIFICA | F18: =IF(D18="Trazione","ϭ > fctm(t)/1.2", "ϭ < 0.6fck(t)") -> ϭ < 0.6fck(t) | G18: =ABS(B18/IF(D18 = "Trazione", Materiali!$B$22/1.2, 0.7*Materiali!$B$16)) -> 0.41262109
A19: Tensione cls lembo inferiore
A20: ϭci1 | B20: ='fase 0 '!B16 +'fase 1 '!B8+'fase 1 '!B15 -> 8.2368781 | C20: N/mm2 | D20: =IF(B20 < 0,"Trazione","Compressione") -> Compressione | E20: =IF(D20 = "Trazione", IF(ABS(B20) < Materiali!$B$22/1.2,"VERIFICA", " NON VERIFICA"), IF(B20 < 0.7*Materiali!$B$16,"VERIFICA", " NON VERIFICA")) -> VERIFICA | F20: =IF(D20="Trazione","ϭ > fctm(t)/1.2", "ϭ < 0.6fck(t)") -> ϭ < 0.6fck(t) | G20: =ABS(B20/IF(D20 = "Trazione", Materiali!$B$22/1.2, 0.7*Materiali!$B$16)) -> 0.30030987
A21: Tensione cls al livello del cavo
A22: ϭct1 | B22: ='fase 0 '!B18+B9+B16 -> 11.740837 | C22: N/mm2 | D22: =IF(B22 < 0,"Trazione","Compressione") -> Compressione | E22: =IF(D22 = "Trazione", IF(ABS(B22) < Materiali!$B$22/1.2,"VERIFICA", " NON VERIFICA"), IF(B22 < 0.7*Materiali!$B$16,"VERIFICA", " NON VERIFICA")) -> VERIFICA | F22: =IF(D22="Trazione","ϭ > fctm(t)/1.2", "ϭ < 0.6fck(t)") -> ϭ < 0.6fck(t) | G22: =ABS(B22/IF(D22 = "Trazione", Materiali!$B$22/1.2, 0.7*Materiali!$B$16)) -> 0.42806136
A23: Tensione nel cavo
A24: Tensione nel cavo dopo le perdite in fase 1 e le cadute di tensione al peso della soletta
A25: ϭsp1 | B25: ='fase 0 '!B21-'Caratteristiche trave V140'!B16*'fase 1 '!B16 + 'Caratteristiche trave V140'!B16*'fase 1 '!B9 -> 1126.6527 | C25: N/mm2 | D25: Tensione trefoli | E25: =IF(B25<MIN(Materiali!B32:B33),"VERIFICA", " NON VERIFICA") -> VERIFICA | F25: ϭs < min ( 0.9 fpk, 0.8 fp0k) | G25: =B25/MIN(Materiali!B32:B33) -> 0.75715908
B28: Tensioni cls fase 0 | F28: Perdite fase 1 | J28: Peso soletta fase 1 | O28: Peso soletta fase 1
B29: X | C29: Y | F29: X | G29: Y | J29: X | K29: Y | O29: X | P29: Y
B30: ='fase 0 '!Q3 -> 0 | C30: ='fase 0 '!R3 -> 722.6 | F30: 0 | G30: =C30 -> 722.6 | J30: =B30+F30 -> 0 | K30: =G30 -> 722.6 | O30: =B30+F30+J30 -> 0 | P30: =G30 -> 722.6
B31: ='fase 0 '!Q4 -> 6.7526961 | C31: ='fase 0 '!R4 -> 722.6 | F31: =B14 -> -0.15183176 | G31: =C31 -> 722.6 | J31: =B7 -> 4.7164778 | K31: =G31 -> 722.6 | O31: =B31+F31+J31 -> 11.317342 | P31: =G31 -> 722.6
B32: ='fase 0 '!Q5 -> 17.562394 | C32: ='fase 0 '!R5 -> -677.4 | F32: =B15 -> -4.9040624 | G32: =C32 -> -677.4 | J32: =B8 -> -4.4214532 | K32: =G32 -> -677.4 | O32: =B32+F32+J32 -> 8.2368781 | P32: =G32 -> -677.4
B33: ='fase 0 '!Q6 -> 0 | C33: ='fase 0 '!R6 -> -677.4 | F33: 0 | G33: =C33 -> -677.4 | J33: =B33+F33 -> 0 | K33: =G33 -> -677.4 | O33: =B33+F33+J33 -> 0 | P33: =G33 -> -677.4

Sheet fase 2 
A1: SOLETTA COLLABORANTE : fase 2
A2: Calcolo sollecitazione
A3: g2,trave 2 | B3: =(2.7+3.14)*2.5/2 + 0.7*2.5 -> 9.05 | C3: KN/m | D3: g2 trave interna
A4: Mmax | B4: =MAX(B3:B3)*'Caratteristiche trave V140'!B2^2/8 -> 707.03125 | C4: KNm | D4: Momento massimo in mezzeria della trave più caricata
A5: Variazioni di tensione dovute a Mmax
A6: Δϭcs,soletta | B6: =B4*1000^2/('Caratteristiche trave V140'!B38*'Caratteristiche trave V140'!B46)*'Caratteristiche trave V140'!B44 -> 0.90452327 | C6: N/mm2 | D6: tensione al lembo superiore della soletta
A7: Δϭci,soletta | B7: =B4*1000^2/('Caratteristiche trave V140'!B38*'Caratteristiche trave V140'!B46)*'Caratteristiche trave V140'!B45 -> 0.5153136 | C7: N/mm2 | D7: tensione al lembo inferiore della soletta
A8: Δϭcs,trave | B8: =B4*1000^2/('Caratteristiche trave V140'!B46)*'Caratteristiche trave V140'!B45 -> 0.54196262 | C8: N/mm2 | D8: tensione al lembo superiore della trave
A9: Δϭci,trave | B9: =-B4*1000^2/('Caratteristiche trave V140'!B46)*'Caratteristiche trave V140'!B43 -> -1.7503264 | C9: N/mm2 | D9: tensione al lembo inferiore della trave
A10: Δϭcp,trave | B10: =-B4*1000^2/('Caratteristiche trave V140'!B46)*'Caratteristiche trave V140'!B48 -> -1.1772542 | C10: N/mm2 | D10: tensione del cls al trefolo
A11: tensione da ritiro soletta
A12: Δϭcs,soletta,ritiro | B12: ='Perdite di tiro '!B98 -> -6.9996134 | C12: N/mm2
A13: Nritiro | B13: =-B12*'Caratteristiche trave V140'!B32/1000 -> 4374.7584 | C13: KN
A14: Mritiro | B14: =B13*('Caratteristiche trave V140'!B44-250)/1000 -> 1448.045 | C14: KNm
A15: Δϭcs,soletta | B15: =B13*1000/('Caratteristiche trave V140'!B38*'Caratteristiche trave V140'!B41) +B14*1000^2/('Caratteristiche trave V140'!B38*'Caratteristiche trave V140'!B46)*'Caratteristiche trave V140'!B44 + B12 -> -2.1289441 | C15: N/mm2 | D15: =IF(B15 < 0,"Trazione","Compressione") -> Trazione | E15: tensione al lembo superiore della soletta
A16: Δϭci,soletta | B16: =B13*1000/('Caratteristiche trave V140'!B38*'Caratteristiche trave V140'!B41) +B14*1000^2/('Caratteristiche trave V140'!B38*'Caratteristiche trave V140'!B46)*'Caratteristiche trave V140'!B45 + B12 -> -2.9260703 | C16: N/mm2 | D16: =IF(B16 < 0,"Trazione","Compressione") -> Trazione | E16: tensione al lembo inferiore della soletta
A17: Δϭcs,trave | B17: =B13*1000/('Caratteristiche trave V140'!B41) +B14*1000^2/('Caratteristiche trave V140'!B46)*'Caratteristiche trave V140'!B45 -> 4.284203 | C17: N/mm2 | D17: =IF(B17 < 0,"Trazione","Compressione") -> Compressione | E17: tensione al lembo superiore della trave
A18: Δϭci,trave | B18: =B13*1000/('Caratteristiche trave V140'!B41) -B14*1000^2/('Caratteristiche trave V140'!B46)*'Caratteristiche trave V140'!B43 -> -0.41055088 | C18: N/mm2 | D18: =IF(B18 < 0,"Trazione","Compressione") -> Trazione | E18: tensione al lembo inferiore della trave
A19: Δϭcp | B19: =B13*1000/('Caratteristiche trave V140'!B41) -B14*1000^2/('Caratteristiche trave V140'!B46)*('Caratteristiche trave V140'!B43-'Caratteristiche trave V140'!B24) -> 0.7631376 | C19: N/mm2 | D19: =IF(B19 < 0,"Trazione","Compressione") -> Compressione | E19: tensione del cls al trefolo
A20: Variazioni di tensione dovute alle perdite di precompressione
A21: ΔNt | B21: ='Perdite di tiro '!B112 -> 180.59252 | C21: KN | D21: Perdita totale di precompressione
A22: Δϭcs,soletta | B22: =-B21*1000/('Caratteristiche trave V140'!B38*'Caratteristiche trave V140'!B41) +B21*1000*'Caratteristiche trave V140'!B48/('Caratteristiche trave V140'!B38*'Caratteristiche trave V140'!B46)*'Caratteristiche trave V140'!B44 -> 0.041524485 | C22: N/mm2 | D22: =IF(B22 < 0,"Trazione","Compressione") -> Compressione | E22: variazione tensione al lembo superiore della soletta
A23: Δϭci,soletta | B23: =-B21*1000/('Caratteristiche trave V140'!B38*'Caratteristiche trave V140'!B41) +B21*1000*'Caratteristiche trave V140'!B48/('Caratteristiche trave V140'!B38*'Caratteristiche trave V140'!B46)*'Caratteristiche trave V140'!B45 -> -0.029953722 | C23: N/mm2 | D23: =IF(B23 < 0,"Trazione","Compressione") -> Trazione | E23: tensione al lembo inferiore della soletta
A24: Δϭcs,trave | B24: =-B21*1000/('Caratteristiche trave V140'!B41) +B21*1000*'Caratteristiche trave V140'!B48/('Caratteristiche trave V140'!B46)*'Caratteristiche trave V140'!B45 -> -0.031502755 | C24: N/mm2 | D24: =IF(B24 < 0,"Trazione","Compressione") -> Trazione | E24: variazione tensione al lembo superiore della trave
A25: Δϭci,trave | B25: =-B21*1000/('Caratteristiche trave V140'!B41) -B21*1000*'Caratteristiche trave V140'!B48/('Caratteristiche trave V140'!B46)*'Caratteristiche trave V140'!B43 -> -0.45248076 | C25: N/mm2 | D25: =IF(B25 < 0,"Trazione","Compressione") -> Trazione | E25: variazione tensione al lembo inferiore della trave
A26: Δϭcp,trave | B26: =-B21*1000/('Caratteristiche trave V140'!B41) -B21*1000*'Caratteristiche trave V140'!B48/('Caratteristiche trave V140'!B46)*('Caratteristiche trave V140'!B43-'Caratteristiche trave V140'!B24) -> -0.34723626 | C26: N/mm2 | D26: =IF(B26 < 0,"Trazione","Compressione") -> Trazione | E26: variazione tensione del cls al trefolo
A28: Tensioni totali cls lembo superiore soletta | G28: D/C
A29: ϭcs2,soletta | B29: =G47 -> -1.1828964 | C29: N/mm2 | D29: =IF(B29 < 0,"Trazione","Compressione") -> Trazione | E29: =IF(D29 = "Trazione", IF(ABS(B29) < Materiali!$B$22/1.2,"VERIFICA", " NON VERIFICA"), IF(B29 < 0.7*Materiali!$B$16,"VERIFICA", " NON VERIFICA")) -> VERIFICA | F29: =IF(D29="Trazione","ϭ > fctm(t)/1.2", "ϭ < 0.6fck(t)") -> ϭ > fctm(t)/1.2 | G29: =ABS(B29/IF(D29 = "Trazione", Materiali!$B$22/1.2, 0.7*Materiali!$B$16)) -> 0.43157734
A30: Tensioni totali cls lembo sinferiore soletta
A31: ϭci3,soletta | B31: =G48 -> -2.4407104 | C31: N/mm2 | D31: =IF(B31 < 0,"Trazione","Compressione") -> Trazione | E31: =IF(D31 = "Trazione", IF(ABS(B31) < Materiali!$B$22/1.2,"VERIFICA", " NON VERIFICA"), IF(B31 < 0.7*Materiali!$B$16,"VERIFICA", " NON VERIFICA")) -> VERIFICA | F31: =IF(D31="Trazione","ϭ > fctm(t)/1.2", "ϭ < 0.6fck(t)") -> ϭ > fctm(t)/1.2 | G31: =ABS(B31/IF(D31 = "Trazione", Materiali!$B$22/1.2, 0.7*Materiali!$B$16)) -> 0.89048824
A32: Tensioni totali cls lembo superiore trave
A33: ϭcs2,trave | B33: =G51 -> 16.112005 | C33: N/mm2 | D33: =IF(B33 < 0,"Trazione","Compressione") -> Compressione | E33: =IF(D33 = "Trazione", IF(ABS(B33) < Materiali!$B$22/1.2,"VERIFICA", " NON VERIFICA"), IF(B33 < 0.7*Materiali!$B$16,"VERIFICA", " NON VERIFICA")) -> VERIFICA | F33: =IF(D33="Trazione","ϭ > fctm(t)/1.2", "ϭ < 0.6fck(t)") -> ϭ < 0.6fck(t) | G33: =ABS(B33/IF(D33 = "Trazione", Materiali!$B$22/1.2, 0.7*Materiali!$B$16)) -> 0.5874306
A34: Tensioni totali cls lembo inferiore trave
A35: ϭci2,trave | B35: =G52 -> 5.62352 | C35: N/mm2 | D35: =IF(B35 < 0,"Trazione","Compressione") -> Compressione | E35: =IF(D35 = "Trazione", IF(ABS(B35) < Materiali!$B$22/1.2,"VERIFICA", " NON VERIFICA"), IF(B35 < 0.7*Materiali!$B$16,"VERIFICA", " NON VERIFICA")) -> VERIFICA | F35: =IF(D35="Trazione","ϭ > fctm(t)/1.2", "ϭ < 0.6fck(t)") -> ϭ < 0.6fck(t) | G35: =ABS(B35/IF(D35 = "Trazione", Materiali!$B$22/1.2, 0.7*Materiali!$B$16)) -> 0.20502897
A36: Tensioni totali cls nel cavo
A37: Tensione nel cavo dopo le perdite in fase 1 e le cadute di tensione al peso dei carichi g2
A38: ϭsp2 | B38: =ABS(B26+B19+B10)*'Caratteristiche trave V140'!B37 +'fase 1 '!B25 -> 1131.2208 | C38: N/mm2 | D38: Tensione trefoli | E38: =IF(B38<MIN(Materiali!B32:B33),"VERIFICA", " NON VERIFICA") -> VERIFICA | F38: ϭs < min ( 0.9 fpk, 0.8 fp0k) | G38: =B38/MIN(Materiali!B32:B33) -> 0.76022905
C44: FASE 1 | D44: G2 -Fase 2 | E44: RITIRO | F44: perdite
A45: Punto | B45: y | C45: ϭ | D45: ϭ | E45: ϭ | F45: ϭ | G45: ϭtot
A46: 1 | B46: =B48+250 -> 972.6 | C46: 0 | D46: 0 | E46: 0 | F46: 0 | G46: =SUM(C46:F46) -> 0
...

Sheet Perdite di tiro 
A1: PERDITE TRAVE V140 | P1: DATI GEOMETRICI SOLETTA | S1: sbalzo soletta
A2: Ac | B2: ='Caratteristiche trave V140'!B5/1000^2 -> 0.6944 | C2: m | D2: Area sezione | P2: L1 | Q2: 0.63 | R2: m | S2: interasse travi
A3: P | B3: =9119.7685/1000 -> 9.1197685 | C3: m | D3: Perimetro disposto al atmosfera | P3: L2 | Q3: 1.24 | R3: m | S3: larghezza totale soletta
A4: yG | B4: ='Caratteristiche trave V140'!B7/1000 -> 0.7047 | C4: m | D4: baricentro sezione cls in assenza di ferri | P4: Ltot | Q4: 10 | R4: m | S4: spessore soletta strutturale
A5: Jx | B5: ='Caratteristiche trave V140'!B9/1000^4 -> 0.17576329 | C5: m4 | D5: Momento d'inerzia sezione | P5: Ss | Q5: 0.25 | R5: m | S5: spessore max. soletta di pendenza
A6: L | B6: ='Caratteristiche trave V140'!B2 -> 25 | C6: m | D6: Luce trave | P6: Sspmax | Q6: 0.22 | R6: m | S6: spessore min. soletta di pendenza
A7: CALCESTRUZZO C45/55 | P7: Sspmin | Q7: =(2.3+0.8+1.15)*0.025 -> 0.10625 | R7: m
A8: fck | B8: =Materiali!B4 -> 45.65 | C8: N/mm2 | D8: Resistenza caratteristica cilindrica a compressione | P8: MATERIALI SOLETTA
A9: Rck | B9: =Materiali!B3 -> 55 | C9: N/mm2 | D9: Resistenza caratteristica cubica a compressione | P9: CALCESTRUZZO C35/45 | S9: Resistenza caratteristica cilindrica a compressione
A10: VISCOSITA - RITIRO | P10: fck | Q10: =Materiali!K4 -> 37.35 | R10: N/mm2 | S10: Resistenza caratteristica cubica a compressione
A11: Ac | B11: =B2 -> 0.6944 | C11: m2 | D11: DimArea sezioneensione equivalente per | P11: Rck | Q11: =Materiali!K3 -> 45 | R11: N/mm2 | S11: Classe di esposizione
A12: u | B12: =B3 -> 9.1197685 | C12: m | D12: Perimetro disposto al atmosfera | P12: Cesp. | Q12: XS1 | R12: -
A13: h0 | B13: =B11*2/B12*1000 -> 152.28457 | C13: mm | D13: Altezza equivalente
A14: RH | B14: 80 | C14: % | D14: Umidità relativa
A15: ϕRH | B15: =1+(1-B14/100)/(0.1*(B13)^(1/3)) -> 1.3745226 | C15: - | D15: Coeff. Ridutt. Per ritiro
A16: β(fcm) | B16: =16.8/SQRT(35+8) -> 2.561976 | C16: -
A17: β0 | B17: =1/(0.1+7^0.2) -> 0.63460911 | C17: -
A18: (t-t0) | B18: =50*365-7 -> 18243 | C18: giorni
A19: βH | B19: =MIN(1.5*(1+(0.012*B14)^18)*B13+250,1500) -> 587.98113 | C19: - | P19: VALUTAZIONE EFFETTI VISCOSITA - RITIRO
A20: β(t-t0) | B20: =(B18/(B19+B18))^0.3 -> 0.99052854 | C20: - | P20: Ac | Q20: =Q4*Q5 -> 2.5 | R20: m2 | S20: DimArea sezioneensione equivalente per
A21: ϕ0 | B21: =B15*B16*B17 -> 2.2347721 | C21: - | P21: u | Q21: =2*(Q4+Q5) -> 20.5 | R21: m | S21: Perimetro disposto al atmosfera
A22: ϕvisc. | B22: =B21*B20 -> 2.2136055 | C22: - | D22: Coefficiente viscoso | P22: h0 | Q22: =Q20*2/Q21*1000 -> 243.90244 | R22: mm | S22: Dimensione equivalente per
A23: Ψp | B23: 0.55 | C23: - | D23: Coefficiente di correzione per viscosità | P23: RH | Q23: 80 | R23: % | S23: Umidità relativa
A24: Ψvisc. | B24: 1.1 | C24: - | D24: Coefficiente di correzione per viscosità | P24: ϕRH | Q24: =1+(1-Q23/100)/(0.1*(Q22)^(1/3)) -> 1.3201041 | R24: - | S24: Coeff. Ridutt. Per ritiro
A25: Ecm,cls | B25: =22000*(($B$8+8)/10)^0.3 -> 36416.114 | C25: N/mm2 | D25: Modulo elastico cls a breve termine | P25: β(fcm) | Q25: =16.8/SQRT(35+8) -> 2.561976 | R25: -
A26: ERitiro | B26: =B25/(1+B23+B15) -> 12451.986 | C26: N/mm2 | D26: Modulo elastico cls a ritiro | P26: β0 | Q26: =1/(0.1+7^0.2) -> 0.63460911 | R26: -
A27: Evisc. | B27: =B25/(1+B24*B22) -> 10601.593 | C27: N/mm2 | D27: Modulo elastico cls viscoo | P27: (t-t0) | Q27: =50*365-7 -> 18243 | R27: giorni
A28: Ecm,fissurato | B28: =B25/2 -> 18208.057 | C28: N/mm3 | D28: Modulo elastico cls fissurato | P28: βH | Q28: =MIN(1.5*(1+(0.012*Q23)^18)*Q22+250,1500) -> 791.31829 | R28: -
A29: n0 | B29: =210000/B25 -> 5.7666779 | C29: - | P29: β(t-t0) | Q29: =(Q27/(Q28+Q27))^0.3 -> 0.98734215 | R29: -
A30: nRitiro | B30: =210000/B26 -> 16.86478 | C30: - | P30: ϕ0 | Q30: =Q24*Q25*Q26 -> 2.1462956 | R30: -
A31: nVisc. | B31: =210000/B27 -> 19.808343 | C31: - | H31: fck | I31: εc0 | P31: ϕvisc. | Q31: =Q30*Q29 -> 2.1191282 | R31: -
A32: nfissurato | B32: =210000/B28 -> 11.533356 | C32: - | H32: 20 | I32: 0.3 | P32: Ψp | Q32: 0.55 | R32: -
A33: DEFORMAZIONE PER RITIRO | H33: 40 | I33: 0.24 | P33: Ψvisc. | Q33: 1.1 | R33: -
A34: εca,ꚙ | B34: =-2.5*($B$8-10)*10^-6 -> -8.9125e-05 | C34: - | D34: Ritiro per autogeno | H34: 60 | I34: 0.19 | P34: Ecm,cls | Q34: =22000*((Q10+8)/10)^0.3 -> 34625.485 | R34: N/mm2 | S34: Modulo elastico cls a breve termine
A35: βds | B35: =B18/(B18+0.04*B13^(3/2)) -> 0.99589643 | C35: - | H35: 80 | I35: 0.15 | P35: ERitiro | Q35: =Q34/(1+Q32+Q24) -> 12064.191 | R35: N/mm2 | S35: Modulo elastico cls a ritiro
A36: εc0 | B36: =-40/$B$8*0.24 -> -0.21029573 | C36: - | P36: Evisc. | Q36: =Q34/(1+Q33*Q31) -> 10394.794 | R36: N/mm2 | S36: Modulo elastico cls viscoo
A37: Kh | B37: =3*10^-6*B13^2 - 0.0023*B13 + 1.2 -> 0.91931726 | C37: - | H37: h0 | I37: Kh | P37: Ecm,fissurato | Q37: =Q34/2 -> 17312.743 | R37: N/mm3 | S37: Modulo elastico cls fissurato
A38: εc0 | B38: =-0.3795*EXP(-(0.012*B8)) -> -0.21943468 | C38: - | H38: 100 | I38: 1 | P38: n0 | Q38: =210000/Q34 -> 6.064897 | R38: - | S38: Coefficiente di omogenizzazione iniziale
A39: εcd,ꚙ | B39: =B38*B37/1000 -> -0.00020173009 | C39: - | H39: 200 | I39: 0.85 | P39: nRitiro | Q39: =210000/Q35 -> 17.406886 | R39: - | S39: Coefficiente di omogenizzazione per ritiro
A40: εcd | B40: =B35*B39 -> -0.00020090227 | C40: - | D40: Ritiro per esseccamento | H40: 300 | I40: 0.75 | P40: nVisc. | Q40: =210000/Q36 -> 20.20242 | R40: - | S40: Coefficiente di omogenizzazione per viscosità
...

Sheet fase 3
A1: SOLETTA COLLABORANTE & CARICHI MOBILI : fase 3
A2: Mmax | B2: =3700 -'fase 0 '!$B$3/3 -'fase 1 '!$B$5/3-'fase 2 '!B4/2 -> 2419.0312 | C2: KNm
A3: Variazioni di tensione dovute a Mmax
A4: Δϭcs,soletta | B4: =B2*1000^2/('Caratteristiche trave V140'!B38*'Caratteristiche trave V140'!B46)*'Caratteristiche trave V140'!B44 -> 3.0947288 | C4: N/mm2 | D4: tensione al lembo superiore della soletta
A5: Δϭci,soletta | B5: =B2*1000^2/('Caratteristiche trave V140'!B38*'Caratteristiche trave V140'!B46)*'Caratteristiche trave V140'!B45 -> 1.7630899 | C5: N/mm2 | D5: tensione al lembo inferiore della soletta
A6: Δϭcs,trave | B6: =B2*1000^2/('Caratteristiche trave V140'!B46)*'Caratteristiche trave V140'!B45 -> 1.8542667 | C6: N/mm2 | D6: tensione al lembo superiore della trave
A7: Δϭci,trave | B7: =-B2*1000^2/('Caratteristiche trave V140'!B46)*'Caratteristiche trave V140'!B43 -> -5.988553 | C7: N/mm2 | D7: tensione al lembo inferiore della trave
A8: Δϭcp,trave | B8: =-B2*1000^2/('Caratteristiche trave V140'!B46)*('Caratteristiche trave V140'!B43-'Caratteristiche trave V140'!B24) -> -4.0278481 | C8: N/mm2 | D8: tensione del cls al trefolo
A9: Δϭcsp | B9: =-B2*1000^2/('Caratteristiche trave V140'!B16*'Caratteristiche trave V140'!B46)*('Caratteristiche trave V140'!B43-'Caratteristiche trave V140'!B24) -> -0.67130802 | C9: N/mm2 | D9: tensione del cls al trefolo
A11: Tensioni totali cls lembo superiore soletta | G11: D/C
A12: ϭcs3,soletta | B12: =E30 -> 1.9118324 | C12: N/mm2 | D12: =IF(B12 < 0,"Trazione","Compressione") -> Compressione | E12: =IF(D12 = "Trazione", IF(ABS(B12) < Materiali!$B$22/1.2,"VERIFICA", " NON VERIFICA"), IF(B12 < 0.7*Materiali!$B$16,"VERIFICA", " NON VERIFICA")) -> VERIFICA | F12: =IF(D12="Trazione","ϭ > fctm(t)/1.2", "ϭ < 0.6fck(t)") -> ϭ < 0.6fck(t) | G12: =ABS(B12/IF(D12 = "Trazione", Materiali!$B$22/1.2, 0.7*Materiali!$B$16)) -> 0.069703855
A13: Tensioni totali cls lembo sinferiore soletta
A14: ϭci3,soletta | B14: =E31 -> -0.67762052 | C14: N/mm2 | D14: =IF(B14 < 0,"Trazione","Compressione") -> Trazione | E14: =IF(D14 = "Trazione", IF(ABS(B14) < Materiali!$B$22/1.2,"VERIFICA", " NON VERIFICA"), IF(B14 < 0.7*Materiali!$B$16,"VERIFICA", " NON VERIFICA")) -> VERIFICA | F14: =IF(D14="Trazione","ϭ > fctm(t)/1.2", "ϭ < 0.6fck(t)") -> ϭ > fctm(t)/1.2 | G14: =ABS(B14/IF(D14 = "Trazione", Materiali!$B$22/1.2, 0.7*Materiali!$B$16)) -> 0.24722847
A15: Tensioni totali cls lembo superiore trave
A16: ϭcs3,trave | B16: =E34 -> 17.966272 | C16: N/mm2 | D16: =IF(B16 < 0,"Trazione","Compressione") -> Compressione | E16: =IF(D16 = "Trazione", IF(ABS(B16) < Materiali!$B$22/1.2,"VERIFICA", " NON VERIFICA"), IF(B16 < 0.7*Materiali!$B$16,"VERIFICA", " NON VERIFICA")) -> VERIFICA | F16: =IF(D16="Trazione","ϭ > fctm(t)/1.2", "ϭ < 0.6fck(t)") -> ϭ < 0.6fck(t) | G16: =ABS(B16/IF(D16 = "Trazione", Materiali!$B$22/1.2, 0.7*Materiali!$B$16)) -> 0.65503565
A17: Tensioni totali cls lembo inferiore trave
A18: ϭci3,trave | B18: =E35 -> -0.36503301 | C18: N/mm2 | D18: =IF(B18 < 0,"Trazione","Compressione") -> Trazione | E18: =IF(D18 = "Trazione", IF(ABS(B18) < Materiali!$B$22/1.2,"VERIFICA", " NON VERIFICA"), IF(B18 < 0.7*Materiali!$B$16,"VERIFICA", " NON VERIFICA")) -> VERIFICA | F18: =IF(D18="Trazione","ϭ > fctm(t)/1.2", "ϭ < 0.6fck(t)") -> ϭ > fctm(t)/1.2 | G18: =ABS(B18/IF(D18 = "Trazione", Materiali!$B$22/1.2, 0.7*Materiali!$B$16)) -> 0.13318155
A19: Tensioni totali cls nel cav0
A20: Tensione nel cavo dopo le perdite in fase 1 e le cadute di tensione al peso dei carichi g2
A21: ϭsp3 | B21: ='fase 2 '!B38+ABS('fase 3'!B9) -> 1131.8921 | C21: N/mm2 | D21: Tensione trefoli | E21: =IF(B21<MIN(Materiali!B32:B33),"VERIFICA", " NON VERIFICA") -> VERIFICA | F21: ϭs < min ( 0.9 fpk, 0.8 fp0k) | G21: =B21/MIN(Materiali!B32:B33) -> 0.76068019
A22: Tensioni totali cls nel cavo dopo le perdite
A23: Δϭcsp3 | B23: 37.31 | C23: N/mm2
A24: ϭsp3 | B24: =B21+B23 -> 1169.2021 | C24: N/mm2 | D24: Tensione trefoli | E24: =IF(B24<MIN(Materiali!B32:B33),"VERIFICA", " NON VERIFICA") -> VERIFICA | F24: ϭs < min ( 0.9 fpk, 0.8 fp0k) | G24: =B24/MIN(Materiali!B32:B33) -> 0.78575412
C27: FASE 2 | D27: Q -Fase 3
A28: Punto | B28: y | C28: ϭ | D28: ϭ | E28: ϭtot
A29: 1 | B29: ='fase 2 '!B46 -> 972.6 | C29: ='fase 2 '!G46 -> 0 | D29: 0 | E29: =SUM(C29:D29) -> 0
A30: 2 | B30: ='fase 2 '!B47 -> 972.6 | C30: ='fase 2 '!G47 -> -1.1828964 | D30: =B4 -> 3.0947288 | E30: =SUM(C30:D30) -> 1.9118324
A31: 3 | B31: ='fase 2 '!B48 -> 722.6 | C31: ='fase 2 '!G48 -> -2.4407104 | D31: =B5 -> 1.7630899 | E31: =SUM(C31:D31) -> -0.67762052
A32: 4 | B32: ='fase 2 '!B49 -> 722.6 | C32: ='fase 2 '!G49 -> 0.54196262 | D32: 0 | E32: =SUM(C32:D32) -> 0.54196262
A33: 5 | B33: ='fase 2 '!B50 -> 722.6 | C33: ='fase 2 '!G50 -> 0.54196262 | D33: =B6 -> 1.8542667 | E33: =SUM(C33:D33) -> 2.3962293
A34: 6 | B34: ='fase 2 '!B51 -> 722.6 | C34: ='fase 2 '!G51 -> 16.112005 | D34: =D33 -> 1.8542667 | E34: =SUM(C34:D34) -> 17.966272
A35: 7 | B35: ='fase 2 '!B52 -> -677.4 | C35: ='fase 2 '!G52 -> 5.62352 | D35: =B7 -> -5.988553 | E35: =SUM(C35:D35) -> -0.36503301
A36: 8 | B36: ='fase 2 '!B53 -> -677.4 | C36: ='fase 2 '!G53 -> 0 | D36: 0 | E36: =SUM(C36:D36) -> 0

Sheet dominio
A1: DOMINIO SEZIONE IN MEZZERIA | H1: Dominio 3D
A2: Diagramma con barre laterali e sup | C2: Diagramma con soloarm inf | H2: MxRd | I2: MyRd | L2: Nrd | M2: Ned | N2: ν | O2: α
A3: N [KN] | B3: M [KNm] | C3: N [KN] | D3: M [KNm] | H3: 13572.9 | I3: 0 | L3: =MAX(A4:A77) -> 25945.7 | M3: 1000 | N3: =M3/$L$3 -> 0.038542032
A4: -13070.3 | B4: 4191 | C4: -10341.6 | D4: 7394.24 | H4: 13071.7 | I4: -5482.34
A5: -13070.3 | B5: 4191 | C5: -10341.6 | D5: 7394.24 | H5: 12647.6 | I5: -6478.65
A6: -13070.3 | B6: 4191 | C6: -10341.6 | D6: 7394.24 | H6: 12151.5 | I6: -6976.51
A7: -13070.3 | B7: 4191 | C7: -10341.6 | D7: 7394.24 | H7: 11374.2 | I7: -7557.26
A8: -12331.4 | B8: 4739.62 | C8: -10341.6 | D8: 7394.24 | H8: 10090.8 | I8: -8045.09
A9: -10660.3 | B9: 5980.4 | C9: -10341.6 | D9: 7394.24 | H9: 8837.84 | I9: -7802.48
A10: -8835 | B10: 7335.7 | C10: -10341.6 | D10: 7394.24 | H10: 7407.35 | I10: -7910.26
A11: -6430.83 | B11: 9084.9 | C11: -10139.4 | D11: 7559.4 | H11: 3181.19 | I11: -7287.66
A12: -2000.48 | B12: 12329.7 | C12: -9632.11 | D12: 7971.88 | H12: 84.7856 | I12: -4693.29
A13: 7673.44 | B13: 17978.6 | C13: -8952.63 | D13: 8519 | H13: -2079.4 | I13: -2035.91
A14: 9651.23 | B14: 18965.3 | C14: -8229.67 | D14: 9093.26 | H14: -2983.98 | I14: -648.221
A15: 11210.3 | B15: 19577.1 | C15: -7523.85 | D15: 9644.76 | H15: -3245.15 | I15: -1.50067e-12
... A27: 4102.27 | B27: -2128.13 | C27: 9605.84 | D27: 19852.5 | H27: 13572.9 | I27: 1.70914e-11
A28: 1839.82 | B28: -2865.59 | C28: 11034.3 | D28: 19676.9
A29: 288.675 | B29: -3239.9 | C29: 11806 | D29: 19377.4
A30: -2202.16 | B30: -2817.09 | C30: 12633.7 | D30: 19049.3
A31: -3609.55 | B31: -2341.52 | C31: 13532.4 | D31: 18678.3
A32: -4361.52 | B32: -1946.15 | C32: 14522.2 | D32: 18241.8
A33: -7130.9 | B33: -155.007 | C33: 15680.5 | D33: 17672.2
A34: -9902.57 | B34: 1863.32 | C34: 17626.6 | D34: 16503.3
A35: -11402.3 | B35: 2952.49 | C35: 19392.2 | D35: 15309.7
A36: -12121.1 | B36: 3486.26 | C36: 20896.3 | D36: 14290.5
A37: -12779.3 | B37: 3974.93 | C37: 22139 | D37: 13445.7
A38: -13070.3 | B38: 4191 | C38: 23120.1 | D38: 12775.5
A39: -13070.3 | B39: 4191 | C39: 23839.8 | D39: 12279.7
... A41: -13070.3 | B41: 4191 | C41: 24297.9 | D41: 11958.3
C42: 24172.9 | D42: 11549.2
C43: 23328.4 | D43: 10657.4
C44: 21764.4 | D44: 9282.98
C45: 19481 | D45: 7425.97
C46: 16478 | D46: 5086.34
C47: 12755.5 | D47: 2264.09
C48: 8478.87 | D48: -267.653
C49: 6503.09 | D49: -1156.49
C50: 5609.66 | D50: -1403.86
C51: 5058.1 | D51: -1474.86
C52: 4608.9 | D52: -1491.69
...

Sheet SLU
B1: SOLLECITAZIONI SLU | L1: VERIFICA A TAGLIO | S1: VERIFICA A TORSIONE PURA | AI1: VERIFICA TORSIONE E TAGLIO SOLETTE
A2: s | B2: N | C2: M
A3: m | B3: KN | C3: KNm | L3: SOLLECITAZIONI SLU | S3: SOLLECITAZIONI SLU | AI3: Bsup | AJ3: 2500 | AK3: mm
A4: 7.21154 | B4: -570.434 | C4: 6636.4178 | L4: VED,tot | M4: 1480 | N4: KN | S4: T | T4: 500 | U4: KNm | AI4: Binf | AJ4: 900 | AK4: mm
A5: 7.21154 | B5: -523.251 | C5: 6656.3248 | L5: VED,anima | M5: =M4/2 -> 740 | N5: KN | AB5: VERIFICA TORSIONE CON TAGLIO E FLESSIONE PARETI LATERALI | AI5: zsup | AJ5: ='Caratteristiche trave V140'!B45 - 'Caratteristiche trave V140'!B31*1000/2 -> 206 | AK5: mm
A6: 8.17308 | B6: -523.585 | C6: 7010.6535 | S6: PARAMETRI | AI6: zinf | AJ6: ='Caratteristiche trave V140'!B45 -AC8/2 -> 181 | AK6: mm
A7: 8.17308 | B7: -481.502 | C7: 7027.4468 | L7: Calcolo resistenza a taglio dell'ala | S7: A | T7: 1515893 | U7: mm2 | V7: area racchiusa dalla linea medea della sezione | AB7: H | AC7: ='Caratteristiche trave V140'!B4 -> 1400 | AD7: mm | AE7: altezza complessiva della sezione | AI7: VERIFICA SOLETTA INFERIORE
A8: 9.13462 | B8: -481.836 | C8: 7295.9944 | L8: b | M8: 240 | N8: mm | S8: u | T8: 5012 | U8: mm | V8: perimetro medio del nucleo resistente della sezione | AB8: tsinf | AC8: 300 | AD8: mm | AE8: spessore soletta inferiore | AI8: Verifica taglio armatura longitudinale
A9: 9.13462 | B9: -447.084 | C9: 7308.7129 | L9: h | M9: 1400 | N9: mm | S9: t | T9: =T7/T8 -> 302.45271 | U9: mm | V9: spessore medio della sezione aperta | AB9: Fti | AC9: =T4*(AC7-AC8)/1000/(2*T7/1000^2)*T18 -> 208.17596 | AD9: KN | AE9: taglio da torsione | AI9: Φl | AJ9: =T10 -> 12 | AK9: mm
A10: 10.09615 | B10: -447.419 | C10: 7494.3083 | L10: Φ | M10: 12 | N10: mm | S10: Φl | T10: 12 | U10: mm | AB10: Vsdi | AC10: =AC9+M5 -> 948.17596 | AD10: KN | AE10: Taglio totale (taglio puro + taglio da torsione ) | AI10: nΦl (soletta inf) | AJ10: 20
A11: 10.09615 | B11: -440.84 | C11: 7503.5947 | L11: passo | M11: 200 | N11: mm | S11: nΦl (soletta) | T11: =18*2 -> 36 | V11: sopra e sotto la soletta | AB11: Verifica armatura longitudinale | AI11: Asl | AJ11: =AJ10*AJ9^2/4*PI() -> 2261.9467 | AK11: mm2
A12: 11.05769 | B12: -441.175 | C12: 7607.4867 | L12: nbracci | M12: 2 | S12: nΦl (trave ) | T12: 30 | V12: complessive nella trave | AB12: nΦl (parete) | AC12: =2*8 -> 16 | AE12: ferri di parete al lembo sup. e inf. della parete | AI12: Vsdi (inf) | AJ12: =T4*1000*(AJ4-T9)/(2*T7) -> 98.547075 | AK12: KN
A13: 11.05769 | B13: -437.416 | C13: 7613.0479 | L13: θ | M13: =ASIN(SQRT(2*M10^2/4*PI()*Materiali!$O$4/($M$8*M11*0.5*Materiali!$B$5))) -> 0.38718116 | N13: [rad] | O13: Angolo per cui VRsd = VRcd | S13: Asl | T13: =(T12+T11)*T10^2/4*PI() -> 7464.4241 | U13: mm2 | AB13: Asl | AC13: =AC12*T10^2/4*PI() -> 1809.5574 | AD13: mm2 | AE13: Area armatura lenta long. | AI13: Ftrd | AJ13: =AJ11*Materiali!O4/1000 -> 885.10958 | AK13: KN | AN13: Ftrd | AO13: =AJ11*Materiali!O4/1000 -> 885.10958 | AP13: KN
A14: 12.01923 | B14: -437.75 | C14: 7637.5214 | L14: θ | M14: =DEGREES(M13) -> 22.183846 | N14: [gradi] | S14: Ast | T14: =M12*M10^2/4*PI() -> 226.19467 | U14: mm2 | AB14: Ftrd | AC14: =AC13*Materiali!O4/1000 -> 708.08767 | AD14: KN | AE14: resistenza al taglio da torsione | AI14: D/C | AJ14: =AJ12/AJ13 -> 0.11133884 | AK14: =IF((AJ14 < 1),"VERIFICA", " NON VERIFICA") -> VERIFICA | AN14: D/C | AO14: =#REF!/AO13 -> #REF! | AP14: =IF((AO14 < 1),"VERIFICA", " NON VERIFICA") -> #REF!
A15: 12.01923 | B15: -439.252 | C15: 7639.0194 | L15: θ | M15: =IF(M14<21.8,21.8,M14) -> 22.183846 | N15: [gradi] | O15: Angolo minimo da norma | S15: passo Ast | T15: =M11 -> 200 | U15: mm | AB15: D/C | AC15: =AC9/AC14 -> 0.29399744 | AD15: =IF((AC15 < 1),"VERIFICA", " NON VERIFICA") -> VERIFICA | AI15: VERIFICA SUPERIORE
A16: 12.98077 | B16: -439.586 | C16: 7593.5295 | L16: θ | M16: =RADIANS(M15) -> 0.38718116 | N16: [rad] | S16: al | T16: =T13/T8 -> 1.4893105 | U16: mm | AB16: Verifica armatura trasversale | AI16: Verifica taglio armatura longitudinale
A17: 12.98077 | B17: -443.234 | C17: 7591.0852 | L17: VRsd | M17: =(0.9*($M$9-30)*(M12*PI()*M10^2/4)/M11*Materiali!$O$4)/1000*_xlfn.COT(M16) -> 1338.202 | N17: KN | O17: Taglio resistente armatura d'anima | S17: as | T17: =T14/T15 -> 1.1309734 | U17: mm | AB17: Ast | AC17: =M12*M10^2/4*PI() -> 226.19467 | AD17: mm2 | AI17: Φl | AJ17: 12 | AK17: mm
A18: 13.94231 | B18: -443.568 | C18: 7465.9491 | L18: VRcd | M18: =(0.9*($M$9-30)*$M$8*0.5*Materiali!$B$5)*(_xlfn.COT(M16))/(1+_xlfn.COT(M16)^2)/1000 -> 1338.202 | N18: KN | O18: taglio resistente biella compressa | S18: ctgθ | T18: =(T16/T17)^(1/2) -> 1.1475363 | U18: [rad] | V18: =IF(T18<=2.5,"OK","NO") -> OK | AB18: s | AC18: =T15 -> 200 | AD18: mm | AI18: nΦl (soletta inf) | AJ18: =T11 -> 36
A19: 13.94231 | B19: -448.002 | C19: 7460.1658 | L19: VRd | M19: =MIN(M17:M18) -> 1338.202 | N19: KN | S19: θ | T19: =_xlfn.ACOT(T18) -> 0.71680568 | U19: [rad] | AB19: Vrd | AC19: =AC17*Materiali!O4*T18/AC18 -> 507.84769 | AD19: KN | AI19: Asl | AJ19: =AJ18*AJ17^2/4*PI() -> 4071.5041 | AK19: mm2
A20: 14.90385 | B20: -448.336 | C20: 7254.162 | L20: D/C | M20: =M5/M19 -> 0.55298078 | N20: =IF((M20 < 1),"VERIFICA", " NON VERIFICA") -> VERIFICA | S20: RESISTENZE | AB20: D/C | AC20: =AC9/AC19 -> 0.4099181 | AD20: =IF((AC20 < 1),"VERIFICA", " NON VERIFICA") -> VERIFICA | AI20: Vsdi (inf) | AJ20: =T4*1000*(AJ3)/(2*T7) -> 412.29823 | AK20: KN
A21: 14.90385 | B21: -454.25 | C21: 7245.7948 | S21: fcd' | T21: =0.85*(1-Materiali!B4/250)*Materiali!B5 -> 17.973059 | U21: N/mm2 | AB21: Verifica bielle compresse | AI21: Ftrd | AJ21: =AJ19*Materiali!O4/1000 -> 1593.1972 | AK21: KN
A22: 15.86538 | B22: -454.584 | C22: 6958.9491 | S22: Trcd | T22: =(2*T7*T9*T21*T18/(1+T18^2))/1000^2 -> 8162.9758 | U22: KNm | V22: sforzi di compressione sono affidati alle bielle di calcestruzzo | AB22: fcd2 | AC22: =0.7*T21 -> 12.581142 | AD22: N/mm2 | AE22: resistenza calcestruzzo fessurato | AI22: D/C | AJ22: =AJ20/AJ21 -> 0.25878668 | AK22: =IF((AJ22 < 1),"VERIFICA", " NON VERIFICA") -> VERIFICA
A23: 15.86538 | B23: -460.992 | C23: 6948.1866 | S23: Trsd | T23: =(2*T7*T14/T15*Materiali!O4*T18)/1000^2 -> 1539.6855 | U23: KNm | V23: riferimento alle staffe trasversali | AB23: ϭRD | AC23: =AC22*COS(T19)*SIN(T19) -> 6.2314702 | AD23: N/mm2 | AE23: controllare
A24: 16.82692 | B24: -461.327 | C24: 6577.3704 | S24: Trld | T24: =(2*T7*T13/T8*Materiali!O4/T18)/1000^2 -> 1539.6855 | U24: KNm | V24: riferimento all'armatura longitudinale | AB24: ϭSD | AC24: =AC10*1000/(2*T7) -> 0.31274502 | AD24: N/mm2
A25: 16.82692 | B25: -476.524 | C25: 6566.3613 | S25: TRd | T25: =MIN(T22:T24) -> 1539.6855 | U25: KNm | V25: riferimento all’armatura longitudinale | AB25: D/C | AC25: =AC24/AC23 -> 0.050187999 | AD25: =IF((AC25 < 1),"VERIFICA", " NON VERIFICA") -> VERIFICA
A26: 17.78846 | B26: -476.858 | C26: 6107.3476 | S26: D/C | T26: =T4/T25 -> 0.32474164 | U26: =IF((T26 < 1),"VERIFICA", " NON VERIFICA") -> VERIFICA
A27: 17.78846 | B27: -493.733 | C27: 6098.7228
A28: 18.75 | B28: -494.067 | C28: 5549.6439
A29: 18.75 | B29: -525.272 | C29: 5567.8075
A30: 7.21154 | B30: -274.612 | C30: 4373.9043
A31: 7.21154 | B31: -245.628 | C31: 4384.4012
A32: 8.17308 | B32: -245.963 | C32: 4615.9993
A33: 8.17308 | B33: -204.627 | C33: 4626.0661
A34: 9.13462 | B34: -204.961 | C34: 4801.4658
A35: 9.13462 | B35: -162.725 | C35: 4809.3581
A36: 10.09615 | B36: -163.059 | C36: 4930.8281
A37: 10.09615 | B37: -126.739 | C37: 4936.0411
A38: 11.05769 | B38: -127.073 | C38: 5004.5717
... A55: 18.75 | B55: -262.389 | C55: 3622.8829

Sheet verifica connettori
A1: Verifica connettori VH140
A2: Nu,tot | B2: =Materiali!B5*'Caratteristiche trave V140'!B30*'Caratteristiche trave V140'!B31*1000 -> 16167.708 | C2: kN | D2: Sforzo normale ultimo della soletta
A3: passo | B3: 200 | C3: mm | D3: passo connettori
A4: nc | B4: =('Caratteristiche trave V140'!B2*1000/'verifica connettori'!B3)*2 -> 250 | C4: - | D4: Numero dei connettori presenti nella trave nelle 2 file
A5: bc | B5: 2 | C5: - | D5: braccia connettore
A6: Φc | B6: 12 | C6: mm | D6: Diametro del connettore
A7: hc | B7: 200 | C7: mm | D7: Altezza del connettore
A8: α | B8: =IF(B7/B6>4,1,0.2/(B7/B6+1)) -> 1 | C8: -
A9: γv | B9: 1.25 | C9: - | D9: Coefficiente di sicurezza
A10: Nuc | B10: =B2/B4/B5 -> 32.335417 | C10: kN | D10: Taglio sollecitante
A11: PRd,cls | B11: =0.29*B8*B6^2*SQRT(Materiali!K10*Materiali!K4)/1000 -> 47.49017 | C11: kN | D11: resistenza connettore parte cls
A12: PRd,s | B12: =0.8*Materiali!O5*PI()*B6^2/4/1000 -> 48.858049 | C12: kN | D12: resistenza connettore lato acciaio
A13: PRd | B13: =MIN(B11:B12) -> 47.49017 | C13: kN | D13: minimo tra le resistenze del connettore
A14: D/C | B14: =B10/B13 -> 0.68088652 | C14: =IF((B14 < 1),"VERIFICA", " NON VERIFICA") -> VERIFICA
