Workbook

Sheet Materiali
A1: Caratteristeche dei materiali | J1: Caratteristeche dei materiali | N1: Armatura ordinaria B450C
A2: Calcestruzzo travi C45/55 | J2: Calcestruzzo soletta C35/45 | N2: Staffe e reggistaffe
A3: Rck | B3: 55 | C3: N/mm2 | J3: Rck | K3: 45 | L3: N/mm2 | N3: fyk | O3: 450 | P3: N/mm2
A4: fck | B4: =0.83*B3 -> 45.65 | C4: N/mm2 | J4: fck | K4: =0.83*K3 -> 37.35 | L4: N/mm2 | N4: fyd | O4: =O3/1.15 -> 391.30435 | P4: N/mm2
A5: fcd | B5: =0.85*Materiali!B4/1.5 -> 25.868333 | C5: N/mm2 | J5: fcd | K5: =0.85*Materiali!K4/1.5 -> 21.165 | L5: N/mm2 | N5: fuk | O5: 540 | P5: N/mm2
A6: fcm | B6: =B4+8 -> 53.65 | C6: N/mm2 | J6: fcm | K6: =K4+8 -> 45.35 | L6: N/mm2
A7: fctm | B7: =0.3*B4^(2/3) -> 3.8319083 | C7: N/mm2 | D7: Resistenza a trazione cls | J7: fctm | K7: =0.3*K4^(2/3) -> 3.3520848 | L7: N/mm2
A8: fcfm | B8: =1.2*B7 -> 4.59829 | C8: N/mm2 | D8: Resistenza a trazione per flessione | J8: fcfm | K8: =1.2*K7 -> 4.0225017 | L8: N/mm2
A9: ϭct | B9: =B7/1.2 -> 3.1932569 | C9: N/mm2 | D9: Resistenza a trazione prima delle fessure | J9: ϭct | K9: =K7/1.2 -> 2.793404 | L9: N/mm2
A10: Ecm | B10: =22000*(B6/10)^0.3 -> 36416.114 | C10: N/mm2 | J10: Ecm | K10: =22000*(K6/10)^0.3 -> 34625.485 | L10: N/mm2
A11: Caratteristiche cls al trasferimento della precompressione
A12: t | B12: 9 | C12: giorni | D12: momento di trasferimento della precompressione
A13: s | B13: =0.2 -> 0.2
A14: βcc | B14: =EXP(B13*(1-(28/B12)^(0.5))) -> 0.85832983 | D14: coefficiente d'invecchiamento del calcestruzzo
A15: fcm(t) | B15: =B14*B6 -> 46.049395 | C15: N/mm2
A16: fck(t) | B16: =B14*B4 -> 39.182757 | C16: N/mm2
A17: 0.7 fck(t) | B17: =0.7*B16 -> 27.42793 | C17: N/mm2 | D17: valore limite della tensione di esercizio a cadute avvenute della precompressione ( p. 4.1.8.1.4 )
A18: 0.6 fck(t) | B18: =0.6*B16 -> 23.509654 | C18: N/mm2 | D18: valore limite della tensione all'atto della precompressione ( p. 4.1.8.1.3 )
A19: α | B19: =IF(B12<28,1,2/3) -> 1
A20: fctm(t) | B20: =B7*B14^B19 -> 3.2890412 | C20: N/mm2
A21: k | B21: 1 | D21: valore di riduzione della resistenza a trazione del cls per le verifiche del conglomerato
A22: fctm(t) k | B22: =B20*B21 -> 3.2890412 | C22: N/mm2
A24: trefolo a sette fili ( classe 2 )
A25: Φn | B25: 15.2 | C25: mm | D25: Diametro nominale | G25: area ferri laterali | J25: ferri superiori
A26: Anom | B26: 139 | C26: mm2 | D26: Area nominale | G26: =6*B26 -> 834 | J26: =2*B26 -> 278
A27: Ep | B27: =195000 -> 195000 | C27: N/mm2 | D27: Modulo elastico
A28: fpk | B28: 1860 | C28: N/mm2
A29: fp01,k | B29: =1670 -> 1670 | C29: N/mm2
A31: Limiti tensioni massime iniziali all'atto della tesaturaE
A32: ϭs,pi = 0.9 fpk | B32: =0.9*$B$29 -> 1503 | C32: N/mm2
A33: ϭs,pi = 0.8 fp0k | B33: =0.8*$B$28 -> 1488 | C33: N/mm2 | D33: * si prende la condizione più restrittiva
A34: ϭc,max | B34: =0.7*B4 -> 31.955 | C34: N/mm2 | D34: Tensione massima compressione cls
A38: Lunghezza di trasferimento
A39: ηp1 | B39: =3.2 -> 3.2 | D39: per trefoli a 3 e 7 fili
A40: η1 | B40: 1 | D40: condizioni di buona aderenza
A41: fctd(t) | B41: =B20/1.5 -> 2.1926941 | C41: N/mm2 | D41: tensione di aderenza uniforme
A43: α1 | B43: 1 | D43: rilascio graduale
A44: α2 | B44: 0.19 | D44: per trefoli a 3 o 7 fili
A45: Φn | B45: 15.2 | C45: mm | D45: Diametro nominale
A46: ϭpmo | B46: ='fase 0 '!B22 -> 1223.2157 | C46: N/mm2 | D46: tensione nell'armatura di precompressione subito dopo il rilascio
...

Sheet Caratteristiche trave V185
A1: Caratteristiche trave
A2: L | B2: 33 | C2: m | D2: Luce trave
A3: Caratteristiche statiche sezione solo calcestruzzo
A4: Hsez | B4: 1850 | C4: mm
A5: Acls | B5: 876300 | C5: mm2
A6: xG | B6: 0 | C6: mm
A7: yG | B7: 1049 | C7: mm
A8: H - yG | B8: =B4-B7 -> 801 | C8: mm
A9: Ixg | B9: =331583614407 -> 331583614407 | C9: mm4 | D9: Momento d'inerzia baricentrico in direzione x
A10: Iyg | B10: =356988385000 -> 356988385000 | C10: mm4 | D10: Momento d'inerzia baricentrico in direzione y
A11: Wx | B11: =B9/B7 -> 3.1609496e+08 | C11: mm3 | D11: Modulo di resistenza elastico
A12: Armatura sezione
A13: ntref | B13: =SUM(B54:B56) -> 42 | D13: Numero trefoli utilizzati
A14: Atref | B14: =B13*Materiali!B26 -> 5838 | C14: mm2 | D14: Area totale trefoli
A15: Caratteristiche sezione omogenizzata interamente reagente
A16: n | B16: 6 | D16: coefficiente omogenizzazione
A17: Atot | B17: 933012 | C17: mm2 | D17: Area totale = Acls + n*Atref
A18: yG | B18: 1071 | C18: mm | D18: Ascissa baricentro
A19: H - yG | B19: =B4-B18 -> 779 | C19: mm
A20: Ixg | B20: =357238306267 -> 357238306267 | C20: mm4 | D20: Momento d'inerzia baricentrico in direzione x
A21: Iyg | B21: =367293289000 -> 367293289000 | C21: mm4 | D21: Momento d'inerzia baricentrico in direzione y
A22: Wx, inf | B22: =B20/B18 -> 3.3355584e+08 | C22: mm3 | D22: Modulo di resistenza elastico
A23: Wx, sup | B23: =B20/B19 -> 4.5858576e+08 | C23: mm3 | D23: Modulo di resistenza elastico
A24: yp | B24: =B58 -> 710.95238 | C24: mm | D24: punto di applicazione dello sforzo normale
A25: e | B25: =B18-B24 -> 360.04762 | C25: mm | D25: eccentricità tra il punto di applicazione del tiro e il baricentro della sezione
A27: Caratteristiche sezione omogenizzata interamente reagente con soletta
A30: Caratteristiche soletta
A31: B | B31: 2.5 | C31: m | D31: larghezza soletta
A32: s | B32: 0.25 | C32: m | D32: spessore soletta
A33: Asoletta | B33: =B31*B32*1000^2 -> 625000 | C33: mm2 | D33: Area cls soletta
A34: Φ | B34: =10 -> 10 | C34: mm | D34: diametro armature soletta
A35: As,sup | B35: =10*B34^2*PI()/4 -> 785.39816 | C35: mm2 | D35: area armatura superiore
A36: As,inf | B36: =10*B34^2*PI()/4 -> 785.39816 | C36: mm2 | D36: area armatura inferiore
A38: Caratteristiche sezione omogenizzata
A39: n | B39: 6 | D39: coefficiente omogenizzazione (rapporto tra i due moduli elastici, trefolo e CAP)
A40: n2 | B40: =Materiali!B10/Materiali!K10 -> 1.0517142 | D40: coefficiente omogenizzazione (rapporto tra i due moduli elastici, soletta e CAP)
A41: Acls | B41: =B33+'Caratteristiche trave V185'!B5 -> 1501300 | C41: mm2 | D41: Area cls soletta + trave
A42: Atr | B42: ='Caratteristiche trave V185'!B14 -> 5838 | C42: mm2 | D42: Area trefolo
A43: Atot | B43: =B41+B40*B42+B39*B42 -> 1542467.9 | C43: mm2 | D43: Area totale sezione Atot = Acp + n2*Ac +n*Atr
A44: Hsez | B44: =B32*1000+'Caratteristiche trave V185'!B4 -> 2100 | C44: mm | D44: Altezza totale della sezione
...

Sheet fase 0 
A1: Peso Proprio - fase 0 | I1: Peso Proprio fase 0 | M1: Precompressione fase 0 | Q1: Precompressione fase 0
A2: G1(trave+ traversi) | B2: =(25*'Caratteristiche trave V185'!B5/1000^2)+ (25*1.4*2.5*0.3*3)/'Caratteristiche trave V185'!B2 -> 24.293864 | C2: KN/m | I2: X | J2: Y | M2: X | N2: Y | Q2: X | R2: Y
A3: s | B3: 5.3 | C3: m | D3: ascissa | I3: 0 | J3: ='Caratteristiche trave V185'!B19 -> 779 | M3: 0 | N3: =J3 -> 779 | Q3: =I3+M3 -> 0 | R3: =N3 -> 779
A4: Mg+ | B4: =B2*0.5*(B3*'Caratteristiche trave V185'!$B$2-B3^2) -> 1783.2911 | C4: KNm | D4: Momento in s dovuto al peso proprio della trave | I4: ='fase 0 '!B4*1000^2/'Caratteristiche trave V185'!B23 -> 3.8886752 | J4: ='Caratteristiche trave V185'!B19 -> 779 | M4: =(B13*1000/'Caratteristiche trave V185'!B17) - B13*1000*'Caratteristiche trave V185'!B25/('Caratteristiche trave V185'!B23) -> 2.0291119 | N4: =J4 -> 779 | Q4: =I4+M4 -> 5.917787 | R4: =N4 -> 779
A5: Tiro iniziale | I5: =- 'fase 0 '!B4*1000^2/'Caratteristiche trave V185'!B22 -> -5.3463044 | J5: =-'Caratteristiche trave V185'!B18 -> -1071 | M5: =(B13*1000/'Caratteristiche trave V185'!B17) + B13*1000*'Caratteristiche trave V185'!B25/('Caratteristiche trave V185'!B22) -> 15.226715 | N5: =J5 -> -1071 | Q5: =I5+M5 -> 9.8804105 | R5: =N5 -> -1071
A6: Np0 | B6: =12000*'Caratteristiche trave V185'!B13/(50+10+8) -> 7411.7647 | C6: KN | I6: 0 | J6: =-'Caratteristiche trave V185'!B18 -> -1071 | M6: 0 | N6: =J6 -> -1071 | Q6: =I6+M6 -> 0 | R6: =N6 -> -1071
A7: ϭpi | B7: =B6*1000/'Caratteristiche trave V185'!B14 -> 1269.5726 | C7: N/mm2 | D7: Tensione trefoli | E7: ϭs < min ( 0.9 fpk, 0.8 fp0k) | F7: =IF(B7<MIN(Materiali!B32:B33),"VERIFICA", " NON VERIFICA") -> VERIFICA
A8: Tesnsione cls a livello del cavo al tiro
A9: ϭcc | B9: =B6*1000/'Caratteristiche trave V185'!B17 + B6*1000*'Caratteristiche trave V185'!B25/'Caratteristiche trave V185'!B20*'Caratteristiche trave V185'!B25 -> 10.633485 | C9: N/mm2
A10: Perdite di tensione istantane
A11: ΔNi | B11: ='Perdite di tiro '!B90 -> 333.58784 | C11: KN
A12: Precompressione dopo le perdite di tensione dovute alla deformazione istantanea del cls
A13: Np0 - Δni | B13: =B6-B11 -> 7078.1769 | C13: KN
A14: Tesnsione cls a lembo superiore | G14: D/C
A15: ϭcc,sup | B15: =(B13*1000/'Caratteristiche trave V185'!B17) - B13*1000*'Caratteristiche trave V185'!B25/('Caratteristiche trave V185'!B23) + 'fase 0 '!B4*1000^2/'Caratteristiche trave V185'!B23 -> 5.917787 | C15: N/mm2 | D15: =IF(B15 < 0,"Trazione","Compressione") -> Compressione | E15: =IF(D15="Trazione","ϭ > fctm(t)/1.2", "ϭ < 0.7fck(t)") -> ϭ < 0.7fck(t) | F15: =IF(D15 = "Trazione", IF(ABS(B15) < Materiali!$B$22/1.2,"VERIFICA", " NON VERIFICA"), IF(B15 < 0.7*Materiali!$B$16,"VERIFICA", " NON VERIFICA")) -> VERIFICA | G15: =ABS(B15/IF(D15 = "Trazione", Materiali!$B$22/1.2, 0.7*Materiali!$B$16)) -> 0.2157577
A16: Tesnsione cls a lembo inferiore
A17: ϭcc,inf | B17: =(B13*1000/'Caratteristiche trave V185'!B17) + B13*1000*'Caratteristiche trave V185'!B25/('Caratteristiche trave V185'!B22) - 'fase 0 '!B4*1000^2/'Caratteristiche trave V185'!B22 -> 9.8804105 | C17: N/mm2 | D17: =IF(B17 < 0,"Trazione","Compressione") -> Compressione | E17: ϭ < 0.7 fctk (t) | F17: =IF(D17 = "Trazione", IF(ABS(B17) < Materiali!$B$22/1.2,"VERIFICA", " NON VERIFICA"), IF(B17 < 0.7*Materiali!$B$16,"VERIFICA", " NON VERIFICA")) -> VERIFICA | G17: =ABS(B17/IF(D17 = "Trazione", Materiali!$B$22/1.2, 0.7*Materiali!$B$16)) -> 0.36023173
A18: Tensione cls a livello del cavo
A19: ϭcc0 | B19: =B13*1000/'Caratteristiche trave V185'!B17 + ('fase 0 '!B13*1000*'Caratteristiche trave V185'!B25- 'fase 0 '!B4)/'Caratteristiche trave V185'!B20*'Caratteristiche trave V185'!B25 -> 10.154893 | C19: N/mm2 | D19: =IF(B19 < 0,"Trazione","Compressione") -> Compressione | E19: ϭ < 0.7 fctk (t) | F19: =IF(D19 = "Trazione", IF(ABS(B19) < Materiali!$B$22/1.2,"VERIFICA", " NON VERIFICA"), IF(B19 < 0.7*Materiali!$B$16,"VERIFICA", " NON VERIFICA")) -> VERIFICA | G19: =ABS(B19/IF(D19 = "Trazione", Materiali!$B$22/1.2, 0.7*Materiali!$B$16)) -> 0.37023914
A20: Tensione cls nel cavo
A21: Tensioni del cavo dopo le cadute di tensione dovute al peso proprio
A22: ϭsp0 | B22: =B13*1000/'Caratteristiche trave V185'!B14 + 'Caratteristiche trave V185'!B16*'fase 0 '!B4*1000^2/'Caratteristiche trave V185'!B20*'Caratteristiche trave V185'!B25 -> 1223.2157 | C22: N/mm2 | D22: Tensione trefoli | E22: ϭs < min ( 0.9 fpk, 0.8 fp0k) | F22: =IF(B22<MIN(Materiali!B32:B33),"VERIFICA", " NON VERIFICA") -> VERIFICA | G22: =B22/MIN(Materiali!B32:B33) -> 0.82205356

Sheet fase 1 
A1: GETTO IN OPERA DELLA SOLETTA : fase 1
A2: (Sezione resistente formata dalla sola trave, soletta considerata solo come carico )
A4: Sollecitazioni al getto della soletta
A5: Gsoletta | B5: =25*10*0.25/4 -> 15.625 | C5: KN/m
A6: s | B6: ='fase 0 '!B3 -> 5.3 | C6: m | D6: ascissa
A7: Mg+ | B7: =B5*0.5*(B6*'Caratteristiche trave V185'!$B$2-B6^2) -> 1146.9531 | C7: KNm | D7: Momento in s dovuto al peso proprio della trave
A8: Variazioni di tensione dovute a Mmax
A9: Δϭcs1 | B9: =B7*1000^2/'Caratteristiche trave V185'!B23 -> 2.5010657 | C9: N/mm2 | D9: Variazione di tensione nel cls al lembo superiore
A10: Δϭci1 | B10: =-B7*1000^2/'Caratteristiche trave V185'!B22 -> -3.438564 | C10: N/mm2 | D10: Variazione di tensione nel cls al lembo inferiore
A11: Δϭcc1 | B11: =-B7*1000^2*'Caratteristiche trave V185'!B25/'Caratteristiche trave V185'!B20 -> -1.1559727 | C11: N/mm2 | D11: variazione di tensione nel cls al livello del baricentro dei cavi
A13: A favore di sicurezza si è considerato che il getto della soletta avvenga dopo molto tempo rispetto al tiro delle travi in precompresso, in modo da poter considerare, in questa fase tutte le perdite di tensione lente riguardo la precompressione.
A15: Variazioni di tensione dovute alle perdite di precompressione
A16: ΔNt | B16: ='Perdite di tiro '!B94 -> 926.06163 | C16: KN | D16: Perdita totale di precompressione
A17: Δϭcs1 | B17: =-B16*1000/'Caratteristiche trave V185'!B17 + B16*1000*'Caratteristiche trave V185'!B25/'Caratteristiche trave V185'!B23 -> -0.26547551 | C17: N/mm2 | D17: =IF(B17 < 0,"Trazione","Compressione") -> Trazione | E17: Variazione di tensione nel cls al lembo superiore
A18: Δϭc1 | B18: =-B16*1000/'Caratteristiche trave V185'!B17 - B16*1000*'Caratteristiche trave V185'!B25/'Caratteristiche trave V185'!B22 -> -1.9921622 | C18: N/mm2 | D18: =IF(B18 < 0,"Trazione","Compressione") -> Trazione | E18: Variazione di tensione nel cls al lembo inferiore
A19: Δϭcc1 | B19: =-B16*1000/'Caratteristiche trave V185'!B17 - B16*1000*'Caratteristiche trave V185'!B25^2/'Caratteristiche trave V185'!B20 -> -1.328599 | C19: N/mm2 | D19: =IF(B19 < 0,"Trazione","Compressione") -> Trazione | E19: variazione di tensione nel cls al livello del baricentro dei cavi
A21: Tensione cls lembo superiore | G21: D/C
A22: ϭcs1 | B22: ='fase 0 '!B15 +'fase 1 '!B9+'fase 1 '!B17 -> 8.1533773 | C22: N/mm2 | D22: =IF(B22 < 0,"Trazione","Compressione") -> Compressione | E22: =IF(D22 = "Trazione", IF(ABS(B22) < Materiali!$B$22/1.2,"VERIFICA", " NON VERIFICA"), IF(B22 < 0.7*Materiali!$B$16,"VERIFICA", " NON VERIFICA")) -> VERIFICA | F22: =IF(D22="Trazione","ϭ > fctm(t)/1.2", "ϭ < 0.6fck(t)") -> ϭ < 0.6fck(t) | G22: =ABS(B22/IF(D22 = "Trazione", Materiali!$B$22/1.2, 0.7*Materiali!$B$16)) -> 0.2972655
A23: Tensione cls lembo inferiore
A24: ϭci1 | B24: ='fase 0 '!B17 +'fase 1 '!B10+'fase 1 '!B18 -> 4.4496842 | C24: N/mm2 | D24: =IF(B24 < 0,"Trazione","Compressione") -> Compressione | E24: =IF(D24 = "Trazione", IF(ABS(B24) < Materiali!$B$22/1.2,"VERIFICA", " NON VERIFICA"), IF(B24 < 0.7*Materiali!$B$16,"VERIFICA", " NON VERIFICA")) -> VERIFICA | F24: =IF(D24="Trazione","ϭ > fctm(t)/1.2", "ϭ < 0.6fck(t)") -> ϭ < 0.6fck(t) | G24: =ABS(B24/IF(D24 = "Trazione", Materiali!$B$22/1.2, 0.7*Materiali!$B$16)) -> 0.16223187
A25: Tensione cls al livello del cavo
A26: ϭct1 | B26: ='fase 0 '!B19+B11+B19 -> 7.6703212 | C26: N/mm2 | D26: =IF(B26 < 0,"Trazione","Compressione") -> Compressione | E26: =IF(D26 = "Trazione", IF(ABS(B26) < Materiali!$B$22/1.2,"VERIFICA", " NON VERIFICA"), IF(B26 < 0.7*Materiali!$B$16,"VERIFICA", " NON VERIFICA")) -> VERIFICA | F26: =IF(D26="Trazione","ϭ > fctm(t)/1.2", "ϭ < 0.6fck(t)") -> ϭ < 0.6fck(t) | G26: =ABS(B26/IF(D26 = "Trazione", Materiali!$B$22/1.2, 0.7*Materiali!$B$16)) -> 0.27965367
A27: Tensione nel cavo
A28: Tensione nel cavo dopo le perdite in fase 1 e le cadute di tensione al peso della soletta
A29: ϭsp1 | B29: ='fase 0 '!B22-'Caratteristiche trave V185'!B16*'fase 1 '!B19 + 'Caratteristiche trave V185'!B16*'fase 1 '!B11 -> 1224.2514 | C29: N/mm2 | D29: Tensione trefoli | E29: =IF(B29<MIN(Materiali!B32:B33),"VERIFICA", " NON VERIFICA") -> VERIFICA | F29: ϭs < min ( 0.9 fpk, 0.8 fp0k) | G29: =B29/MIN(Materiali!B32:B33) -> 0.82274963
B32: Tensioni cls fase 0 | F32: Perdite fase 1 | J32: Peso soletta fase 1 | O32: Peso soletta fase 1
B33: X | C33: Y | F33: X | G33: Y | J33: X | K33: Y | O33: X | P33: Y
B34: ='fase 0 '!Q3 -> 0 | C34: ='fase 0 '!R3 -> 779 | F34: 0 | G34: =C34 -> 779 | J34: =B34+F34 -> 0 | K34: =G34 -> 779 | O34: =B34+F34+J34 -> 0 | P34: =G34 -> 779
B35: ='fase 0 '!Q4 -> 5.917787 | C35: ='fase 0 '!R4 -> 779 | F35: =B17 -> -0.26547551 | G35: =C35 -> 779 | J35: =B9 -> 2.5010657 | K35: =G35 -> 779 | O35: =B35+F35+J35 -> 8.1533773 | P35: =G35 -> 779
B36: ='fase 0 '!Q5 -> 9.8804105 | C36: ='fase 0 '!R5 -> -1071 | F36: =B18 -> -1.9921622 | G36: =C36 -> -1071 | J36: =B10 -> -3.438564 | K36: =G36 -> -1071 | O36: =B36+F36+J36 -> 4.4496842 | P36: =G36 -> -1071
B37: ='fase 0 '!Q6 -> 0 | C37: ='fase 0 '!R6 -> -1071 | F37: 0 | G37: =C37 -> -1071 | J37: =B37+F37 -> 0 | K37: =G37 -> -1071 | O37: =B37+F37+J37 -> 0 | P37: =G37 -> -1071

Sheet fase 2 
A1: SOLETTA COLLABORANTE : fase 2
A2: Calcolo sollecitazione
A3: g2,trave 2 | B3: =(2.7+3.14)*2.5/2 + 0.7*2.5 -> 9.05 | C3: KN/m | D3: g2 trave interna
A4: g2,trave 1 | B4: =(1.01+2.7)*2.5/2 +0.7*(2.5-0.7) +3.8*0.7 -> 8.5575 | C4: KN/m | D4: g2 trave esterna
A5: s | B5: ='fase 0 '!B3 -> 5.3 | C5: m | D5: ascissa
A6: Mmax | B6: =MAX(B3:B4)*0.5*(B5*'Caratteristiche trave V185'!B2-'fase 2 '!B5^2) -> 664.31525 | C6: KNm | D6: Momento massimo in mezzeria della trave più caricata
A7: Variazioni di tensione dovute a Mmax
A8: Δϭcs,soletta | B8: =B6*1000^2/('Caratteristiche trave V185'!B40*'Caratteristiche trave V185'!B48)*'Caratteristiche trave V185'!B46 -> 0.59410417 | C8: N/mm2 | D8: tensione al lembo superiore della soletta
A9: Δϭci,soletta | B9: =B6*1000^2/('Caratteristiche trave V185'!B40*'Caratteristiche trave V185'!B48)*'Caratteristiche trave V185'!B47 -> 0.41791669 | C9: N/mm2 | D9: tensione al lembo inferiore della soletta
A10: Δϭcs,trave | B10: =B6*1000^2/('Caratteristiche trave V185'!B48)*'Caratteristiche trave V185'!B47 -> 0.43952891 | C10: N/mm2 | D10: tensione al lembo superiore della trave
A11: Δϭci,trave | B11: =-B6*1000^2/('Caratteristiche trave V185'!B48)*'Caratteristiche trave V185'!B45 -> -0.9316827 | C11: N/mm2 | D11: tensione al lembo inferiore della trave
A12: Δϭcp,trave | B12: =-B6*1000^2/('Caratteristiche trave V185'!B48)*'Caratteristiche trave V185'!B50 -> -0.40472802 | C12: N/mm2 | D12: tensione del cls al trefolo
A14: tensione da ritiro soletta
A15: Δϭcs,soletta,ritiro | B15: ='Perdite di tiro '!B98 -> -6.9996134 | C15: N/mm2
A16: Nritiro | B16: =-B15*'Caratteristiche trave V185'!B33/1000 -> 4374.7584 | C16: KN
A17: Mritiro | B17: =B16*('Caratteristiche trave V185'!B46-250)/1000 -> 2594.2317 | C17: KNm
A18: Δϭcs,soletta | B18: =B16*1000/('Caratteristiche trave V185'!B40*'Caratteristiche trave V185'!B43) +B17*1000^2/('Caratteristiche trave V185'!B40*'Caratteristiche trave V185'!B48)*'Caratteristiche trave V185'!B46 + B15 -> -1.9828175 | C18: N/mm2 | D18: =IF(B18 < 0,"Trazione","Compressione") -> Trazione | E18: tensione al lembo superiore della soletta
A19: Δϭci,soletta | B19: =B16*1000/('Caratteristiche trave V185'!B40*'Caratteristiche trave V185'!B43) +B17*1000^2/('Caratteristiche trave V185'!B40*'Caratteristiche trave V185'!B48)*'Caratteristiche trave V185'!B47 + B15 -> -2.670851 | C19: N/mm2 | D19: =IF(B19 < 0,"Trazione","Compressione") -> Trazione | E19: tensione al lembo inferiore della soletta
A20: Δϭcs,trave | B20: =B16*1000/('Caratteristiche trave V185'!B43) +B17*1000^2/('Caratteristiche trave V185'!B48)*'Caratteristiche trave V185'!B47 -> 4.5526208 | C20: N/mm2 | D20: =IF(B20 < 0,"Trazione","Compressione") -> Compressione | E20: tensione al lembo superiore della trave
A21: Δϭci,trave | B21: =B16*1000/('Caratteristiche trave V185'!B43) -B17*1000^2/('Caratteristiche trave V185'!B48)*'Caratteristiche trave V185'!B45 -> -0.80212701 | C21: N/mm2 | D21: =IF(B21 < 0,"Trazione","Compressione") -> Trazione | E21: tensione al lembo inferiore della trave
A22: Δϭcp | B22: =B16*1000/('Caratteristiche trave V185'!B43) -B17*1000^2/('Caratteristiche trave V185'!B48)*('Caratteristiche trave V185'!B45-'Caratteristiche trave V185'!B24) -> 1.255695 | C22: N/mm2 | D22: =IF(B22 < 0,"Trazione","Compressione") -> Compressione | E22: tensione del cls al trefolo
A24: Variazioni di tensione dovute alle perdite di precompressione
A25: ΔNt | B25: ='Perdite di tiro '!B112 -> 42.791263 | C25: KN | D25: Perdita totale di precompressione
A26: Δϭcs,soletta | B26: =-B25*1000/('Caratteristiche trave V185'!B40*'Caratteristiche trave V185'!B43) +B25*1000*'Caratteristiche trave V185'!B50/('Caratteristiche trave V185'!B40*'Caratteristiche trave V185'!B48)*'Caratteristiche trave V185'!B46 -> -0.0054814404 | C26: N/mm2 | D26: =IF(B26 < 0,"Trazione","Compressione") -> Trazione | E26: variazione tensione al lembo superiore della soletta
A27: Δϭci,soletta | B27: =-B25*1000/('Caratteristiche trave V185'!B40*'Caratteristiche trave V185'!B43) +B25*1000*'Caratteristiche trave V185'!B50/('Caratteristiche trave V185'!B40*'Caratteristiche trave V185'!B48)*'Caratteristiche trave V185'!B47 -> -0.011678511 | C27: N/mm2 | D27: =IF(B27 < 0,"Trazione","Compressione") -> Trazione | E27: tensione al lembo inferiore della soletta
A28: Δϭcs,trave | B28: =-B25*1000/('Caratteristiche trave V185'!B43) +B25*1000*'Caratteristiche trave V185'!B50/('Caratteristiche trave V185'!B48)*'Caratteristiche trave V185'!B47 -> -0.012282456 | C28: N/mm2 | D28: =IF(B28 < 0,"Trazione","Compressione") -> Trazione | E28: variazione tensione al lembo superiore della trave
A29: Δϭci,trave | B29: =-B25*1000/('Caratteristiche trave V185'!B43) -B25*1000*'Caratteristiche trave V185'!B50/('Caratteristiche trave V185'!B48)*'Caratteristiche trave V185'!B45 -> -0.060512303 | C29: N/mm2 | D29: =IF(B29 < 0,"Trazione","Compressione") -> Trazione | E29: variazione tensione al lembo inferiore della trave
A30: Δϭcp,trave | B30: =-B25*1000/('Caratteristiche trave V185'!B43) -B25*1000*'Caratteristiche trave V185'!B50/('Caratteristiche trave V185'!B48)*('Caratteristiche trave V185'!B45-'Caratteristiche trave V185'!B24) -> -0.041977641 | C30: N/mm2 | D30: =IF(B30 < 0,"Trazione","Compressione") -> Trazione | E30: variazione tensione del cls al trefolo
A32: Tensioni totali cls lembo superiore soletta | G32: D/C
A33: ϭcs2,soletta | B33: =G51 -> -1.3941948 | C33: N/mm2 | D33: =IF(B33 < 0,"Trazione","Compressione") -> Trazione | E33: =IF(D33 = "Trazione", IF(ABS(B33) < Materiali!$B$22/1.2,"VERIFICA", " NON VERIFICA"), IF(B33 < 0.7*Materiali!$B$16,"VERIFICA", " NON VERIFICA")) -> VERIFICA | F33: =IF(D33="Trazione","ϭ > fctm(t)/1.2", "ϭ < 0.6fck(t)") -> ϭ > fctm(t)/1.2 | G33: =ABS(B33/IF(D33 = "Trazione", Materiali!$B$22/1.2, 0.7*Materiali!$B$16)) -> 0.50866913
A34: Tensioni totali cls lembo sinferiore soletta
A35: ϭci3,soletta | B35: =G52 -> -2.2646128 | C35: N/mm2 | D35: =IF(B35 < 0,"Trazione","Compressione") -> Trazione | E35: =IF(D35 = "Trazione", IF(ABS(B35) < Materiali!$B$22/1.2,"VERIFICA", " NON VERIFICA"), IF(B35 < 0.7*Materiali!$B$16,"VERIFICA", " NON VERIFICA")) -> VERIFICA | F35: =IF(D35="Trazione","ϭ > fctm(t)/1.2", "ϭ < 0.6fck(t)") -> ϭ > fctm(t)/1.2 | G35: =ABS(B35/IF(D35 = "Trazione", Materiali!$B$22/1.2, 0.7*Materiali!$B$16)) -> 0.82623938
A36: Tensioni totali cls lembo superiore trave
A37: ϭcs2,trave | B37: =G55 -> 13.133245 | C37: N/mm2 | D37: =IF(B37 < 0,"Trazione","Compressione") -> Compressione | E37: =IF(D37 = "Trazione", IF(ABS(B37) < Materiali!$B$22/1.2,"VERIFICA", " NON VERIFICA"), IF(B37 < 0.7*Materiali!$B$16,"VERIFICA", " NON VERIFICA")) -> VERIFICA | F37: =IF(D37="Trazione","ϭ > fctm(t)/1.2", "ϭ < 0.6fck(t)") -> ϭ < 0.6fck(t) | G37: =ABS(B37/IF(D37 = "Trazione", Materiali!$B$22/1.2, 0.7*Materiali!$B$16)) -> 0.47882741
A38: Tensioni totali cls lembo inferiore trave
A39: ϭci2,trave | B39: =G56 -> 2.6553622 | C39: N/mm2 | D39: =IF(B39 < 0,"Trazione","Compressione") -> Compressione | E39: =IF(D39 = "Trazione", IF(ABS(B39) < Materiali!$B$22/1.2,"VERIFICA", " NON VERIFICA"), IF(B39 < 0.7*Materiali!$B$16,"VERIFICA", " NON VERIFICA")) -> VERIFICA | F39: =IF(D39="Trazione","ϭ > fctm(t)/1.2", "ϭ < 0.6fck(t)") -> ϭ < 0.6fck(t) | G39: =ABS(B39/IF(D39 = "Trazione", Materiali!$B$22/1.2, 0.7*Materiali!$B$16)) -> 0.096812346
A40: Tensioni totali cls nel cavo
A41: Tensione nel cavo dopo le perdite in fase 1 e le cadute di tensione al peso dei carichi g2
A42: ϭsp2 | B42: =ABS(B30+B22+B12)*'Caratteristiche trave V185'!B39 +'fase 1 '!B29 -> 1229.1054 | C42: N/mm2 | D42: Tensione trefoli | E42: =IF(B42<MIN(Materiali!B32:B33),"VERIFICA", " NON VERIFICA") -> VERIFICA | F42: ϭs < min ( 0.9 fpk, 0.8 fp0k) | G42: =B42/MIN(Materiali!B32:B33) -> 0.82601168
C48: FASE 1 | D48: G2 -Fase 2 | E48: RITIRO | F48: perdite
...

Sheet fase 3
A1: SOLETTA COLLABORANTE & CARICHI MOBILI : fase 3
A2: Mmax | B2: 3162 | C2: KN/m | D2: g2 trave esterna
A3: s | B3: ='fase 0 '!B3 -> 5.3 | C3: m | D3: ascissa
A4: Mmax | B4: =$B$2/((16.5)^2)*$B$3^2 -> 326.24639 | C4: KNm | D4: Momento a s della trave più caricata
A5: Variazioni di tensione dovute a Mmax
A6: Δϭcs,soletta | B6: =B2*1000^2/('Caratteristiche trave V185'!B40*'Caratteristiche trave V185'!B48)*'Caratteristiche trave V185'!B46 -> 2.8278101 | C6: N/mm2 | D6: tensione al lembo superiore della soletta
A7: Δϭci,soletta | B7: =B2*1000^2/('Caratteristiche trave V185'!B40*'Caratteristiche trave V185'!B48)*'Caratteristiche trave V185'!B47 -> 1.989195 | C7: N/mm2 | D7: tensione al lembo inferiore della soletta
A8: Δϭcs,trave | B8: =B2*1000^2/('Caratteristiche trave V185'!B48)*'Caratteristiche trave V185'!B47 -> 2.0920646 | C8: N/mm2 | D8: tensione al lembo superiore della trave
A9: Δϭci,trave | B9: =-B2*1000^2/('Caratteristiche trave V185'!B48)*'Caratteristiche trave V185'!B45 -> -4.4346125 | C9: N/mm2 | D9: tensione al lembo inferiore della trave
A10: Δϭcp,trave | B10: =-B2*1000^2/('Caratteristiche trave V185'!B48)*('Caratteristiche trave V185'!B45-'Caratteristiche trave V185'!B24) -> -1.9264197 | C10: N/mm2 | D10: tensione del cls al trefolo
A11: Δϭcsp | B11: =-B2*1000^2/('Caratteristiche trave V185'!B16*'Caratteristiche trave V185'!B48)*('Caratteristiche trave V185'!B45-'Caratteristiche trave V185'!B24) -> -0.32106995 | C11: N/mm2 | D11: tensione del cls al trefolo
A13: Tensioni totali cls lembo superiore soletta | G13: D/C
A14: ϭcs3,soletta | B14: =E32 -> 1.4336153 | C14: N/mm2 | D14: =IF(B14 < 0,"Trazione","Compressione") -> Compressione | E14: =IF(D14 = "Trazione", IF(ABS(B14) < Materiali!$B$22/1.2,"VERIFICA", " NON VERIFICA"), IF(B14 < 0.7*Materiali!$B$16,"VERIFICA", " NON VERIFICA")) -> VERIFICA | F14: =IF(D14="Trazione","ϭ > fctm(t)/1.2", "ϭ < 0.6fck(t)") -> ϭ < 0.6fck(t) | G14: =ABS(B14/IF(D14 = "Trazione", Materiali!$B$22/1.2, 0.7*Materiali!$B$16)) -> 0.052268449
A15: Tensioni totali cls lembo sinferiore soletta
A16: ϭci3,soletta | B16: =E33 -> -0.27541779 | C16: N/mm2 | D16: =IF(B16 < 0,"Trazione","Compressione") -> Trazione | E16: =IF(D16 = "Trazione", IF(ABS(B16) < Materiali!$B$22/1.2,"VERIFICA", " NON VERIFICA"), IF(B16 < 0.7*Materiali!$B$16,"VERIFICA", " NON VERIFICA")) -> VERIFICA | F16: =IF(D16="Trazione","ϭ > fctm(t)/1.2", "ϭ < 0.6fck(t)") -> ϭ > fctm(t)/1.2 | G16: =ABS(B16/IF(D16 = "Trazione", Materiali!$B$22/1.2, 0.7*Materiali!$B$16)) -> 0.10048562
A17: Tensioni totali cls lembo superiore trave
A18: ϭcs3,trave | B18: =E36 -> 15.225309 | C18: N/mm2 | D18: =IF(B18 < 0,"Trazione","Compressione") -> Compressione | E18: =IF(D18 = "Trazione", IF(ABS(B18) < Materiali!$B$22/1.2,"VERIFICA", " NON VERIFICA"), IF(B18 < 0.7*Materiali!$B$16,"VERIFICA", " NON VERIFICA")) -> VERIFICA | F18: =IF(D18="Trazione","ϭ > fctm(t)/1.2", "ϭ < 0.6fck(t)") -> ϭ < 0.6fck(t) | G18: =ABS(B18/IF(D18 = "Trazione", Materiali!$B$22/1.2, 0.7*Materiali!$B$16)) -> 0.55510239
A19: Tensioni totali cls lembo inferiore trave
A20: ϭci3,trave | B20: =E37 -> -1.7792503 | C20: N/mm2 | D20: =IF(B20 < 0,"Trazione","Compressione") -> Trazione | E20: =IF(D20 = "Trazione", IF(ABS(B20) < Materiali!$B$22/1.2,"VERIFICA", " NON VERIFICA"), IF(B20 < 0.7*Materiali!$B$16,"VERIFICA", " NON VERIFICA")) -> VERIFICA | F20: =IF(D20="Trazione","ϭ > fctm(t)/1.2", "ϭ < 0.6fck(t)") -> ϭ > fctm(t)/1.2 | G20: =ABS(B20/IF(D20 = "Trazione", Materiali!$B$22/1.2, 0.7*Materiali!$B$16)) -> 0.64915585
A21: Tensioni totali cls nel cav0
A22: Tensione nel cavo dopo le perdite in fase 1 e le cadute di tensione al peso dei carichi g2
A23: ϭsp3 | B23: ='fase 2 '!B42+ABS('fase 3'!B11) -> 1229.4265 | C23: N/mm2 | D23: Tensione trefoli | E23: =IF(B23<MIN(Materiali!B32:B33),"VERIFICA", " NON VERIFICA") -> VERIFICA | F23: ϭs < min ( 0.9 fpk, 0.8 fp0k) | G23: =B23/MIN(Materiali!B32:B33) -> 0.82622746
A24: Tensioni totali cls nel cavo dopo le perdite
A25: Δϭcsp3 | B25: 37.31 | C25: N/mm2
A26: ϭsp3 | B26: =B23+B25 -> 1266.7365 | C26: N/mm2 | D26: Tensione trefoli | E26: =IF(B26<MIN(Materiali!B32:B33),"VERIFICA", " NON VERIFICA") -> VERIFICA | F26: ϭs < min ( 0.9 fpk, 0.8 fp0k) | G26: =B26/MIN(Materiali!B32:B33) -> 0.85130138
C29: FASE 2 | D29: Q -Fase 3
A30: Punto | B30: y | C30: ϭ | D30: ϭ | E30: ϭtot
A31: 1 | B31: ='fase 2 '!B50 -> 1029 | C31: ='fase 2 '!G50 -> 0 | D31: 0 | E31: =SUM(C31:D31) -> 0
A32: 2 | B32: ='fase 2 '!B51 -> 1029 | C32: ='fase 2 '!G51 -> -1.3941948 | D32: =B6 -> 2.8278101 | E32: =SUM(C32:D32) -> 1.4336153
A33: 3 | B33: ='fase 2 '!B52 -> 779 | C33: ='fase 2 '!G52 -> -2.2646128 | D33: =B7 -> 1.989195 | E33: =SUM(C33:D33) -> -0.27541779
A34: 4 | B34: ='fase 2 '!B53 -> 779 | C34: ='fase 2 '!G53 -> 0.43952891 | D34: 0 | E34: =SUM(C34:D34) -> 0.43952891
A35: 5 | B35: ='fase 2 '!B54 -> 779 | C35: ='fase 2 '!G54 -> 0.43952891 | D35: =B8 -> 2.0920646 | E35: =SUM(C35:D35) -> 2.5315935
A36: 6 | B36: ='fase 2 '!B55 -> 779 | C36: ='fase 2 '!G55 -> 13.133245 | D36: =D35 -> 2.0920646 | E36: =SUM(C36:D36) -> 15.225309
A37: 7 | B37: ='fase 2 '!B56 -> -1071 | C37: ='fase 2 '!G56 -> 2.6553622 | D37: =B9 -> -4.4346125 | E37: =SUM(C37:D37) -> -1.7792503
A38: 8 | B38: ='fase 2 '!B57 -> -1071 | C38: ='fase 2 '!G57 -> 0 | D38: 0 | E38: =SUM(C38:D38) -> 0

Sheet Perdite di tiro 
A1: PERDITE TRAVE V140 | P1: DATI GEOMETRICI SOLETTA | S1: sbalzo soletta
A2: Ac | B2: ='Caratteristiche trave V185'!B5/1000^2 -> 0.8763 | C2: m | D2: Area sezione | P2: L1 | Q2: 0.63 | R2: m | S2: interasse travi
A3: P | B3: =9119.7685/1000 -> 9.1197685 | C3: m | D3: Perimetro disposto al atmosfera | P3: L2 | Q3: 1.24 | R3: m | S3: larghezza totale soletta
A4: yG | B4: ='Caratteristiche trave V185'!B7/1000 -> 1.049 | C4: m | D4: baricentro sezione cls in assenza di ferri | P4: Ltot | Q4: ='Caratteristiche trave V185'!B31*4 -> 10 | R4: m | S4: spessore soletta strutturale
A5: Jx | B5: ='Caratteristiche trave V185'!B9/1000^4 -> 0.33158361 | C5: m4 | D5: Momento d'inerzia sezione | P5: Ss | Q5: ='Caratteristiche trave V185'!B32 -> 0.25 | R5: m | S5: spessore max. soletta di pendenza
A6: L | B6: ='Caratteristiche trave V185'!B2 -> 33 | C6: m | D6: Luce trave | P6: Sspmax | Q6: 0.22 | R6: m | S6: spessore min. soletta di pendenza
A7: CALCESTRUZZO C45/55 | P7: Sspmin | Q7: =(2.3+0.8+1.15)*0.025 -> 0.10625 | R7: m
A8: fck | B8: =Materiali!B4 -> 45.65 | C8: N/mm2 | D8: Resistenza caratteristica cilindrica a compressione | P8: MATERIALI SOLETTA
A9: Rck | B9: =Materiali!B3 -> 55 | C9: N/mm2 | D9: Resistenza caratteristica cubica a compressione | P9: CALCESTRUZZO C35/45 | S9: Resistenza caratteristica cilindrica a compressione
A10: VISCOSITA - RITIRO | P10: fck | Q10: =Materiali!K4 -> 37.35 | R10: N/mm2 | S10: Resistenza caratteristica cubica a compressione
A11: Ac | B11: =B2 -> 0.8763 | C11: m2 | D11: DimArea sezioneensione equivalente per | P11: Rck | Q11: =Materiali!K3 -> 45 | R11: N/mm2 | S11: Classe di esposizione
A12: u | B12: =B3 -> 9.1197685 | C12: m | D12: Perimetro disposto al atmosfera | P12: Cesp. | Q12: XS1 | R12: -
A13: h0 | B13: =B11*2/B12*1000 -> 192.17593 | C13: mm | D13: Altezza equivalente
A14: RH | B14: 80 | C14: % | D14: Umidità relativa
A15: ϕRH | B15: =1+(1-B14/100)/(0.1*(B13)^(1/3)) -> 1.3465748 | C15: - | D15: Coeff. Ridutt. Per ritiro
A16: β(fcm) | B16: =16.8/SQRT(35+8) -> 2.561976 | C16: -
A17: β0 | B17: =1/(0.1+7^0.2) -> 0.63460911 | C17: -
A18: (t-t0) | B18: =50*365-7 -> 18243 | C18: giorni
A19: βH | B19: =MIN(1.5*(1+(0.012*B14)^18)*B13+250,1500) -> 676.51622 | C19: - | P19: VALUTAZIONE EFFETTI VISCOSITA - RITIRO
A20: β(t-t0) | B20: =(B18/(B19+B18))^0.3 -> 0.98913568 | C20: - | P20: Ac | Q20: =Q4*Q5 -> 2.5 | R20: m2 | S20: DimArea sezioneensione equivalente per
A21: ϕ0 | B21: =B15*B16*B17 -> 2.1893331 | C21: - | P21: u | Q21: =2*(Q4+Q5) -> 20.5 | R21: m | S21: Perimetro disposto al atmosfera
A22: ϕvisc. | B22: =B21*B20 -> 2.1655475 | C22: - | D22: Coefficiente viscoso | P22: h0 | Q22: =Q20*2/Q21*1000 -> 243.90244 | R22: mm | S22: Dimensione equivalente per
A23: Ψp | B23: 0.55 | C23: - | D23: Coefficiente di correzione per viscosità | P23: RH | Q23: 80 | R23: % | S23: Umidità relativa
A24: Ψvisc. | B24: 1.1 | C24: - | D24: Coefficiente di correzione per viscosità | P24: ϕRH | Q24: =1+(1-Q23/100)/(0.1*(Q22)^(1/3)) -> 1.3201041 | R24: - | S24: Coeff. Ridutt. Per ritiro
A25: Ecm,cls | B25: =22000*(($B$8+8)/10)^0.3 -> 36416.114 | C25: N/mm2 | D25: Modulo elastico cls a breve termine | P25: β(fcm) | Q25: =16.8/SQRT(35+8) -> 2.561976 | R25: -
A26: ERitiro | B26: =B25/(1+B23+B15) -> 12572.13 | C26: N/mm2 | D26: Modulo elastico cls a ritiro | P26: β0 | Q26: =1/(0.1+7^0.2) -> 0.63460911 | R26: -
A27: Evisc. | B27: =B25/(1+B24*B22) -> 10767.301 | C27: N/mm2 | D27: Modulo elastico cls viscoo | P27: (t-t0) | Q27: =50*365-7 -> 18243 | R27: giorni
A28: Ecm,fissurato | B28: =B25/2 -> 18208.057 | C28: N/mm3 | D28: Modulo elastico cls fissurato | P28: βH | Q28: =MIN(1.5*(1+(0.012*Q23)^18)*Q22+250,1500) -> 791.31829 | R28: -
A29: n0 | B29: =210000/B25 -> 5.7666779 | C29: - | P29: β(t-t0) | Q29: =(Q27/(Q28+Q27))^0.3 -> 0.98734215 | R29: -
A30: nRitiro | B30: =210000/B26 -> 16.703614 | C30: - | P30: ϕ0 | Q30: =Q24*Q25*Q26 -> 2.1462956 | R30: -
A31: nVisc. | B31: =210000/B27 -> 19.503494 | C31: - | H31: fck | I31: εc0 | P31: ϕvisc. | Q31: =Q30*Q29 -> 2.1191282 | R31: -
A32: nfissurato | B32: =210000/B28 -> 11.533356 | C32: - | H32: 20 | I32: 0.3 | P32: Ψp | Q32: 0.55 | R32: -
A33: DEFORMAZIONE PER RITIRO | H33: 40 | I33: 0.24 | P33: Ψvisc. | Q33: 1.1 | R33: -
A34: εca,ꚙ | B34: =-2.5*($B$8-10)*10^-6 -> -8.9125e-05 | C34: - | D34: Ritiro per autogeno | H34: 60 | I34: 0.19 | P34: Ecm,cls | Q34: =22000*((Q10+8)/10)^0.3 -> 34625.485 | R34: N/mm2 | S34: Modulo elastico cls a breve termine
A35: βds | B35: =B18/(B18+0.04*B13^(3/2)) -> 0.99419259 | C35: - | H35: 80 | I35: 0.15 | P35: ERitiro | Q35: =Q34/(1+Q32+Q24) -> 12064.191 | R35: N/mm2 | S35: Modulo elastico cls a ritiro
A36: εc0 | B36: =-40/$B$8*0.24 -> -0.21029573 | C36: - | P36: Evisc. | Q36: =Q34/(1+Q33*Q31) -> 10394.794 | R36: N/mm2 | S36: Modulo elastico cls viscoo
A37: Kh | B37: =3*10^-6*B13^2 - 0.0023*B13 + 1.2 -> 0.86879012 | C37: - | H37: h0 | I37: Kh | P37: Ecm,fissurato | Q37: =Q34/2 -> 17312.743 | R37: N/mm3 | S37: Modulo elastico cls fissurato
A38: εc0 | B38: =-0.3795*EXP(-(0.012*B8)) -> -0.21943468 | C38: - | H38: 100 | I38: 1 | P38: n0 | Q38: =210000/Q34 -> 6.064897 | R38: - | S38: Coefficiente di omogenizzazione iniziale
A39: εcd,ꚙ | B39: =B38*B37/1000 -> -0.00019064268 | C39: - | H39: 200 | I39: 0.85 | P39: nRitiro | Q39: =210000/Q35 -> 17.406886 | R39: - | S39: Coefficiente di omogenizzazione per ritiro
A40: εcd | B40: =B35*B39 -> -0.00018953554 | C40: - | D40: Ritiro per esseccamento | H40: 300 | I40: 0.75 | P40: nVisc. | Q40: =210000/Q36 -> 20.20242 | R40: - | S40: Coefficiente di omogenizzazione per viscosità
...

Sheet SLU
A1: SOLLECITAZIONI SLU | K1: VERIFICA A TAGLIO
A2: N | B2: M
A3: KN | B3: KNm | K3: SOLLECITAZIONI SLU
A4: 0 | B4: 8693.03 | K4: VED,tot | L4: 983 | M4: KN
K5: VED,anima | L5: =L4/2 -> 491.5 | M5: KN
K7: Calcolo resistenza a taglio dell'ala
K8: b | L8: 140 | M8: mm
K9: h | L9: 1400 | M9: mm
K10: Φ | L10: 12 | M10: mm
K11: passo | L11: 200 | M11: mm
K12: θ | L12: =ASIN(SQRT(2*L10^2/4*PI()*Materiali!$O$4/($L$8*L11*0.5*Materiali!$B$5))) -> 0.51710753 | M12: [rad] | N12: Angolo per cui VRsd = VRcd
K13: θ | L13: =DEGREES(L12) -> 29.628079 | M13: [gradi]
K14: θ | L14: =IF(L13<21.8,21.8,L13) -> 29.628079 | M14: [gradi] | N14: Angolo minimo da norma
K15: θ | L15: =RADIANS(L14) -> 0.51710753 | M15: [rad]
K16: VRsd | L16: =(0.9*($L$9-30)*(2*PI()*L10^2/4)/L11*Materiali!$O$4)/1000*_xlfn.COT(L15) -> 959.4579 | M16: KN | N16: Taglio resistente armatura d'anima
K17: VRcd | L17: =(0.9*($L$9-30)*$L$8*0.5*Materiali!$B$5)*(_xlfn.COT(L15))/(1+_xlfn.COT(L15)^2)/1000 -> 959.4579 | M17: KN | N17: taglio resistente biella compressa
K18: VRd | L18: =MIN(L16:L17) -> 959.4579 | M18: KN
K19: D/C | L19: =L5/L18 -> 0.51226844 | M19: =IF((L19 < 1),"VERIFICA", " NON VERIFICA") -> VERIFICA

Sheet dominio
A1: DOMINIO SEZIONE IN MEZZERIA
A2: Diagramma con barre laterali e sup | C2: Diagramma con barre laterali
A3: N [KN] | B3: M [KNm] | C3: N [KN] | D3: M [KNm]
A4: -14478.2 | B4: 6856.48 | C4: -10341.6 | D4: 7394.24
A5: -14478.2 | B5: 6856.48 | C5: -10341.6 | D5: 7394.24
A6: -14478.2 | B6: 6856.48 | C6: -10341.6 | D6: 7394.24
A7: -14478.2 | B7: 6856.48 | C7: -10341.6 | D7: 7394.24
A8: -14478.2 | B8: 6856.48 | C8: -10341.6 | D8: 7394.24
A9: -14478.2 | B9: 6856.48 | C9: -10341.6 | D9: 7394.24
A10: -14478.2 | B10: 6856.48 | C10: -10341.6 | D10: 7394.24
A11: -14276 | B11: 7021.63 | C11: -10139.4 | D11: 7559.4
A12: -13768.8 | B12: 7434.12 | C12: -9632.11 | D12: 7971.88
A13: -13089.3 | B13: 7981.23 | C13: -8952.63 | D13: 8519
A14: -12366.3 | B14: 8555.5 | C14: -8229.67 | D14: 9093.26
A15: -11660.5 | B15: 9107 | C15: -7523.85 | D15: 9644.76
... A77: -14478.2 | B77: 6856.48 | C77: -10341.6 | D77: 7394.24

Sheet verifica connettori
A1: Verifica connettori V140
A2: Nu,tot | B2: =Materiali!B5*'Caratteristiche trave V185'!B31*'Caratteristiche trave V185'!B32*1000 -> 16167.708 | C2: kN | D2: Sforzo normale ultimo della soletta
A3: passo | B3: 100 | C3: mm | D3: passo connettori
A4: nc | B4: ='Caratteristiche trave V185'!B2*1000/'verifica connettori'!B3 -> 330 | C4: - | D4: Numero dei connettori presenti nella trave nelle 2 file
A5: bc | B5: 2 | C5: - | D5: braccia connettore
A6: Φc | B6: 12 | C6: mm | D6: Diametro del connettore
A7: hc | B7: 200 | C7: mm | D7: Altezza del connettore
A8: α | B8: =IF(B7/B6>4,1,0.2/(B7/B6+1)) -> 1 | C8: -
A9: γv | B9: 1.25 | C9: - | D9: Coefficiente di sicurezza
A10: Nuc | B10: =B2/B4/B5 -> 24.496528 | C10: kN | D10: Taglio sollecitante
A11: PRd,cls | B11: =0.29*B8*B6^2*SQRT(Materiali!K10*Materiali!K4)/1000 -> 47.49017 | C11: kN | D11: resistenza connettore parte cls
A12: PRd,s | B12: =0.8*Materiali!O5*PI()*B6^2/4/1000 -> 48.858049 | C12: kN | D12: resistenza connettore lato acciaio
A13: PRd | B13: =MIN(B11:B12) -> 47.49017 | C13: kN | D13: minimo tra le resistenze del connettore
A14: D/C | B14: =B10/B13 -> 0.51582312 | C14: =IF((B14 < 1),"VERIFICA", " NON VERIFICA") -> VERIFICA
