Workbook

Sheet Propietà terreno e Gazetas
A1: $Vs_{max}$ | B1: 360 | C1: m/s | E1: Cat B | F1: 360 | G1: ≤Vs≤ | H1: 800
A2: $Vs,_{o}$ | B2: =B1*(0.7-0.15) -> 198 | C2: m/s | E2: Categoria B Rocce tenere e depositi di terreni a grana grossa molto addensati o terreni a grana fina molto consistenti, caratterizzati da un miglioramento delle proprietà meccaniche con la profondità e da valori di velocità equivalente compresi tra 360 m/s e 800 m/s.
A3: $\gamma$ | B3: 19 | C3: KN/m^3
A4: $\rho$ | B4: =B3*1000/9.81 -> 1936.7992 | C4: Kg/m^3
A5: $G_{max}$ | B5: =B4*(B1^2)/1000 -> 251009.17 | C5: KN/m^2
A6: $G_o$ | B6: =0.5*B5 -> 125504.59 | C6: KN/m^2
A7: $\ni$ | B7: 0.4
A8: Eo | B8: =2*B6*(1+B7) -> 351412.84 | C8: KN/m^2
A9: D | B9: 1.2 | C9: m | D9: profondità posa fondazione
A10: $\sigma^'_{vo)$ | B10: =B9*B3 -> 22.8 | C10: KN/m^2 | D10: in assenza di falda
A11: $N_{SPT}$ | B11: =(B2/(55*B10^(0.14)))^(1/0.25) -> 29.158588
A12: $\phi^'$ | B12: =MIN(DEGREES((ATAN(B11/(12.2+20.3*(B10/100)))^(0.34))),27.1+0.3*(3/(2+B10/100))*B11-0.00054*((3/(2+B10/100))*B11)^2) -> 38.046191 | C12: [gradi]
A15: Gazetas in direzione x
A16: B/2 | B16: =1.2/2 -> 0.6 | C16: m | D16: semilarghezza della fondazione
A17: L/2 | B17: =13.5/2 -> 6.75 | C17: m | D17: semilarghezza larghezza fondazione
A18: L/B | B18: =B17/B16 -> 11.25 | C18: -
A19: T1 da SAP | B19: =0.61 -> 0.61 | C19: s
A20: f | B20: =2*PI()/B19 -> 10.300304 | C20: Hz | D20: frequenza
A21: ω | B21: =2*PI()*B20 -> 64.718717 | C21: Hz | D21: frequenza circolare adimensionalizzata
A22: ao | B22: =B21*B16/B2 -> 0.19611733
A23: RIGIDEZZA Z | D23: RIGIDEZZA Y | G23: RIGIDEZZA X
A24: ꭓ | B24: =(B16*2*B17*2)/(4*B17^2) -> 0.088888889 | C24: - | D24: Ky | E24: =2*B6*B17*(2+2.5*B24^0.85)/(2-B7) -> 2456214.6 | F24: KN/m | G24: Ky | H24: =E24-0.2*B6*B17*(1-B16/B17)/(0.75-B7) -> 2015155.7 | I24: KN/m | M24: =B27/17.5 -> 174073.81
A25: Kz | B25: =((2*B6*B17)/(1-B7))*(0.73+1.54*B24^0.75) -> 2769356.1 | C25: KN/m | D25: Ky | E25: 1.2 | F25: - | G25: Ky | H25: 1 | I25: -
A26: Kz | B26: 1.1 | C26: - | D26: Kz | E26: =E24*E25 -> 2947457.6 | F26: KN/m | G26: Kz | H26: =H24*H25 -> 2015155.7 | I26: KN/m
A27: Kz | B27: =B25*B26 -> 3046291.7 | C27: KN/m

Sheet Baricentro sezione e armatura
A1: Propietà della sezione
A2: B | B2: 1.2 | C2: m
A3: b | B3: 0.3 | C3: m
A4: h1 | B4: 0.4 | C4: m
A5: h2 | B5: =B2-B4 -> 0.8 | C5: m
A6: A1 | B6: =B4*B2 -> 0.48 | C6: m^2
A7: A2 | B7: =B5*B3 -> 0.24 | C7: m^2
A8: Atot | B8: =B6+B7 -> 0.72 | C8: m^2
A9: yg1 | B9: =B4/2 -> 0.2 | C9: m
A10: yg2 | B10: =B4+B5/2 -> 0.8 | C10: m
A11: Yg | B11: =(B6*B9+B7*B10)/B8 -> 0.4 | C11: m
A13: Armatura longitudinale trave rovescia
A14: Acls [mm2] | B14: As,min [mm2] | C14: φ [mm] | D14: n (numero barre) | E14: As [mm2]
A15: =B8*1000^2 -> 720000 | B15: =A15*0.002 -> 1440 | C15: 22 | D15: 2 | E15: =D15*PI()*(C15^2)/4+D16*PI()*(C16^2)/4 -> 1520.5308
C16: 22 | D16: 2
A18: Resistenza a taglio
A19: b [mm] | B19: 300
A20: fyd [N/mm^2] | B20: =391.3 -> 391.3
A21: νfcd [N/mm^2] | B21: =0.5*17 -> 8.5
A22: As [mm2] | B22: =E34 -> 157.07963
A23: s [mm] | B23: 250
A24: ϑ [rad] | B24: =_xlfn.ACOT(SQRT(((B23*B19*B21)/(E34*B20))-1)) -> 0.31572889
A25: ϑ [°] | B25: =DEGREES(B24) -> 18.089933
A26: cotϑ | B26: =_xlfn.COT(B24) -> 3.0613253
A27: cotϑ da NTC18 | B27: 2.5
A28: d [mm] | B28: =(B5+B4)*1000-61 -> 1139
A29: VRcd [KN] | B29: =(0.9*$B$28*$B$19*$B$21*($B$27/(1+$B$27^2)))/1000 -> 901.38103
A30: VRsd [KN] | B30: =(0.9*$B$28*($E$34/B23)*$B$20*$B$27)/1000 -> 630.08038
A32: Armatura a taglio
A33: Ast,min [mm^2/m] | B33: φ [mm] | C33: n (numero bracci) | D33: s (passo) [mm] | E33: As [mm2] | F33: Ast [mm2/m]
A34: =1.5*B19 -> 450 | B34: 10 | C34: 2 | D34: 250 | E34: =C34*PI()*(B34^2)/4 -> 157.07963 | F34: =1000/D34*E34 -> 628.31853
A36: Armatura ala
A37: l | B37: =(B2-B3)/2 -> 0.45 | C37: m | D37: lunghezza mensola
A38: qRD | B38: =534.25*1 -> 534.25 | C38: KN/m
A39: MED | B39: =B38*B37^2/2 -> 54.092812 | C39: KNm
A40: VED | B40: =B38*B37 -> 240.4125 | C40: KN
A41: h | B41: =B4 -> 0.4 | C41: m | D41: altezza ala
A42: c | B42: 40 | C42: mm | D42: copriferro
A43: d | B43: =B41*1000-B42 -> 360 | C43: mm
A44: As,min | B44: =B39*1000^2/(0.9*391*B43) -> 426.99009 | C44: mm2 | D44: area di armatura necessaria
...

Sheet Forze totale sisma su fonda
A1: TRAVI IN DIREZIONE Y
A2: n trave | B2: ∑N | C2: ∑T | D2: ∑M | E2: e | F2: R | G2: ∑N | H2: ∑T | I2: ∑M | J2: R | K2: e
A3: - | B3: Max | C3: Max | D3: Max | E3: m | F3: KN | G3: Min | H3: Min | I3: Min | J3: KN | K3: m | N3: fattore amplificazione T e M | P3: fattore ampl N
A4: 1 | B4: ='[1]CDS TRAVI IN Y'!K4*$P$4 -> 1649.3015 | C4: ='[1]CDS TRAVI IN Y'!L4*$N$4 -> 391.9157 | D4: ='[1]CDS TRAVI IN Y'!M4*$N$4 -> 730.99224 | E4: ='[1]CDS TRAVI IN Y'!N4 -> 0.44321323 | F4: ='[1]CDS TRAVI IN Y'!O4 -> 1541.1151 | G4: ='[1]CDS TRAVI IN Y'!P4*$P$4 -> 1340.5953 | H4: ='[1]CDS TRAVI IN Y'!Q4*$N$4 -> -391.9212 | I4: ='[1]CDS TRAVI IN Y'!R4*$N$4 -> 730.98432 | J4: ='[1]CDS TRAVI IN Y'!T4 -> 1964.7701 | K4: ='[1]CDS TRAVI IN Y'!S4 -> 0.54526845 | N4: 1.1 | P4: 1.1
A5: 2 | B5: ='[1]CDS TRAVI IN Y'!K8*$P$4 -> 2138.2949 | C5: ='[1]CDS TRAVI IN Y'!L8*$N$4 -> 372.1311 | D5: ='[1]CDS TRAVI IN Y'!M8*$N$4 -> 694.89277 | E5: ='[1]CDS TRAVI IN Y'!N8 -> 0.32497517 | F5: ='[1]CDS TRAVI IN Y'!O8 -> 1973.1225 | G5: ='[1]CDS TRAVI IN Y'!P8*$P$4 -> 2890.1576 | H5: ='[1]CDS TRAVI IN Y'!Q8*$N$4 -> -372.1289 | I5: ='[1]CDS TRAVI IN Y'!R8*$N$4 -> 694.89464 | J5: ='[1]CDS TRAVI IN Y'!T8 -> 3285.8069 | K5: ='[1]CDS TRAVI IN Y'!S8 -> 0.24043486
A6: 3 | B6: ='[1]CDS TRAVI IN Y'!K12*$P$4 -> 2513.8762 | C6: ='[1]CDS TRAVI IN Y'!L12*$N$4 -> 353.364 | D6: ='[1]CDS TRAVI IN Y'!M12*$N$4 -> 659.91728 | E6: ='[1]CDS TRAVI IN Y'!N12 -> 0.26250986 | F6: ='[1]CDS TRAVI IN Y'!O12 -> 2307.8092 | G6: ='[1]CDS TRAVI IN Y'!P12*$P$4 -> 3519.0738 | H6: ='[1]CDS TRAVI IN Y'!Q12*$N$4 -> -353.364 | I6: ='[1]CDS TRAVI IN Y'!R12*$N$4 -> 659.91508 | J6: ='[1]CDS TRAVI IN Y'!T12 -> 3944.692 | K6: ='[1]CDS TRAVI IN Y'!S12 -> 0.18752522
A7: 4 | B7: ='[1]CDS TRAVI IN Y'!K16*$P$4 -> 2522.2994 | C7: ='[1]CDS TRAVI IN Y'!L16*$N$4 -> 389.9346 | D7: ='[1]CDS TRAVI IN Y'!M16*$N$4 -> 728.24686 | E7: ='[1]CDS TRAVI IN Y'!N16 -> 0.28872339 | F7: ='[1]CDS TRAVI IN Y'!O16 -> 2320.2386 | G7: ='[1]CDS TRAVI IN Y'!P16*$P$4 -> 3444.0505 | H7: ='[1]CDS TRAVI IN Y'!Q16*$N$4 -> -389.9357 | I7: ='[1]CDS TRAVI IN Y'!R16*$N$4 -> 728.24587 | J7: ='[1]CDS TRAVI IN Y'!T16 -> 3896.9714 | K7: ='[1]CDS TRAVI IN Y'!S16 -> 0.2114504
A8: 5 | B8: ='[1]CDS TRAVI IN Y'!K20*$P$4 -> 1656.1694 | C8: ='[1]CDS TRAVI IN Y'!L20*$N$4 -> 423.2129 | D8: ='[1]CDS TRAVI IN Y'!M20*$N$4 -> 789.5085 | E8: ='[1]CDS TRAVI IN Y'!N20 -> 0.47670759 | F8: ='[1]CDS TRAVI IN Y'!O20 -> 1553.9888 | G8: ='[1]CDS TRAVI IN Y'!P20*$P$4 -> 1326.831 | H8: ='[1]CDS TRAVI IN Y'!Q20*$N$4 -> -423.2085 | I8: ='[1]CDS TRAVI IN Y'!R20*$N$4 -> 789.51499 | J8: ='[1]CDS TRAVI IN Y'!T20 -> 1967.1867 | K8: ='[1]CDS TRAVI IN Y'!S20 -> 0.59503809
A9: TRAVI IN DIREZIONE X
A10: n trave | B10: ∑N | C10: ∑T | D10: ∑M | E10: e | F10: R | G10: ∑N | H10: ∑T | I10: ∑M | J10: R | K10: e
A11: - | B11: Max | C11: Max | D11: Max | E11: m | F11: KN | G11: Min | H11: Min | I11: Min | J11: KN | K11: m
A12: 1 | B12: ='[1]CDS TRAVI in X'!K4*$P$4 -> 2158.2742 | C12: ='[1]CDS TRAVI in X'!L4*$N$4 -> 686.9016 | D12: ='[1]CDS TRAVI in X'!M4*$N$4 -> 1367.2352 | E12: ='[1]CDS TRAVI in X'!N4 -> 0.63348539 | F12: ='[1]CDS TRAVI in X'!O4 -> 2059.0421 | G12: ='[1]CDS TRAVI in X'!P4*$P$4 -> 809.87005 | H12: ='[1]CDS TRAVI in X'!Q4*$N$4 -> 686.7509 | I12: ='[1]CDS TRAVI in X'!R4*$N$4 -> 1369.6892 | J12: ='[1]CDS TRAVI in X'!T4 -> 965.31428 | K12: ='[1]CDS TRAVI in X'!S4 -> 1.6912457
A13: 2 | B13: ='[1]CDS TRAVI in X'!K9*$P$4 -> 3081.6979 | C13: ='[1]CDS TRAVI in X'!L9*$N$4 -> 158.6464 | D13: ='[1]CDS TRAVI in X'!M9*$N$4 -> 355.8753 | E13: ='[1]CDS TRAVI in X'!N9 -> 0.11548027 | F13: ='[1]CDS TRAVI in X'!O9 -> 2805.2534 | G13: ='[1]CDS TRAVI in X'!P9*$P$4 -> 2320.3081 | H13: ='[1]CDS TRAVI in X'!Q9*$N$4 -> 158.8026 | I13: ='[1]CDS TRAVI in X'!R9*$N$4 -> 356.80337 | J13: ='[1]CDS TRAVI in X'!T9 -> 2114.3055 | K13: ='[1]CDS TRAVI in X'!S9 -> 0.15377413
A14: 3 | B14: ='[1]CDS TRAVI in X'!K14*$P$4 -> 3081.694 | C14: ='[1]CDS TRAVI in X'!L14*$N$4 -> 158.6464 | D14: ='[1]CDS TRAVI in X'!M14*$N$4 -> 355.87552 | E14: ='[1]CDS TRAVI in X'!N14 -> 0.11548049 | F14: ='[1]CDS TRAVI in X'!O14 -> 2805.2499 | G14: ='[1]CDS TRAVI in X'!P14*$P$4 -> 2320.3054 | H14: ='[1]CDS TRAVI in X'!Q14*$N$4 -> 158.8026 | I14: ='[1]CDS TRAVI in X'!R14*$N$4 -> 356.80304 | J14: ='[1]CDS TRAVI in X'!T14 -> 2114.303 | K14: ='[1]CDS TRAVI in X'!S14 -> 0.15377417
A15: 4 | B15: ='[1]CDS TRAVI in X'!K19*$P$4 -> 2158.2753 | C15: ='[1]CDS TRAVI in X'!L19*$N$4 -> 686.906 | D15: ='[1]CDS TRAVI in X'!M19*$N$4 -> 1367.2377 | E15: ='[1]CDS TRAVI in X'!N19 -> 0.63348624 | F15: ='[1]CDS TRAVI in X'!O19 -> 2059.0442 | G15: ='[1]CDS TRAVI in X'!P19*$P$4 -> 809.8706 | H15: ='[1]CDS TRAVI in X'!Q19*$N$4 -> 686.7465 | I15: ='[1]CDS TRAVI in X'!R19*$N$4 -> 1369.6849 | J15: ='[1]CDS TRAVI in X'!T19 -> 965.31207 | K15: ='[1]CDS TRAVI in X'!S19 -> 1.6912392

Sheet VERIFICHE(DREANATO)X sisma 
A1: Proprietà Fondazione | E1: TRAVE1 X (Comb 1) | G1: TRAVE1 X (Comb 2) | I1: TRAVE2 X (Comb 1) | K1: TRAVE2X (Comb 2) | M1: TRAVE3 X (Comb 1) | O1: TRAVE3X (Comb 2) | Q1: TRAVE4 X (Comb 1) | S1: TRAVE4X (Comb 2)
A2: L | B2: 17.5 | C2: m | E2: Sollecitazioni | G2: Sollecitazioni | I2: Sollecitazioni | K2: Sollecitazioni | M2: Sollecitazioni | O2: Sollecitazioni | Q2: Sollecitazioni | S2: Sollecitazioni
A3: B | B3: 1.2 | C3: m | E3: N | F3: ='Forze totale sisma su fonda'!B12 -> 2158.2742 | G3: N | H3: ='Forze totale sisma su fonda'!G12 -> 809.87005 | I3: N | J3: ='Forze totale sisma su fonda'!B13 -> 3081.6979 | K3: N | L3: ='Forze totale sisma su fonda'!G13 -> 2320.3081 | M3: N | N3: ='Forze totale sisma su fonda'!B14 -> 3081.694 | O3: N | P3: ='Forze totale sisma su fonda'!G14 -> 2320.3054 | Q3: N | R3: ='Forze totale sisma su fonda'!B14 -> 3081.694 | S3: N | T3: ='Forze totale sisma su fonda'!G14 -> 2320.3054
A4: b | B4: 0.3 | C4: m | E4: H | F4: ='Forze totale sisma su fonda'!C12 -> 686.9016 | G4: H | H4: ='Forze totale sisma su fonda'!H12 -> 686.7509 | I4: H | J4: ='Forze totale sisma su fonda'!C13 -> 158.6464 | K4: H | L4: =ABS('Forze totale sisma su fonda'!H13) -> 158.8026 | M4: H | N4: ='Forze totale sisma su fonda'!C14 -> 158.6464 | O4: H | P4: =ABS('Forze totale sisma su fonda'!H14) -> 158.8026 | Q4: H | R4: ='Forze totale sisma su fonda'!C14 -> 158.6464 | S4: H | T4: =ABS('Forze totale sisma su fonda'!H14) -> 158.8026
A5: h1 | B5: 0.4 | C5: m | E5: e | F5: ='Forze totale sisma su fonda'!E12 -> 0.63348539 | G5: e | H5: ='Forze totale sisma su fonda'!K12 -> 1.6912457 | I5: e | J5: ='Forze totale sisma su fonda'!E13 -> 0.11548027 | K5: e | L5: ='Forze totale sisma su fonda'!K13 -> 0.15377413 | M5: e | N5: ='Forze totale sisma su fonda'!E14 -> 0.11548049 | O5: e | P5: ='Forze totale sisma su fonda'!K14 -> 0.15377417 | Q5: e | R5: ='Forze totale sisma su fonda'!E14 -> 0.11548049 | S5: e | T5: ='Forze totale sisma su fonda'!K14 -> 0.15377417
A6: h2 | B6: =B3-B5 -> 0.8 | C6: m | E6: Dimensioni efficaci | G6: Dimensioni efficaci | I6: Dimensioni efficaci | K6: Dimensioni efficaci | M6: Dimensioni efficaci | O6: Dimensioni efficaci | Q6: Dimensioni efficaci | S6: Dimensioni efficaci
A7: A1 | B7: =B5*B3 -> 0.48 | C7: m2 | E7: B' | F7: =$B$3 -> 1.2 | G7: B' | H7: =$B$3 -> 1.2 | I7: B' | J7: =$B$3 -> 1.2 | K7: B' | L7: =$B$3 -> 1.2 | M7: B' | N7: =$B$3 -> 1.2 | O7: B' | P7: =$B$3 -> 1.2 | Q7: B' | R7: =$B$3 -> 1.2 | S7: B' | T7: =$B$3 -> 1.2
A8: A2 | B8: =B6*B4 -> 0.24 | C8: m2 | E8: L' | F8: =$B$2-F5 -> 16.866515 | G8: L' | H8: =$B$2-H5 -> 15.808754 | I8: L' | J8: =$B$2-J5 -> 17.38452 | K8: L' | L8: =$B$2-L5 -> 17.346226 | M8: L' | N8: =$B$2-N5 -> 17.38452 | O8: L' | P8: =$B$2-P5 -> 17.346226 | Q8: L' | R8: =$B$2-R5 -> 17.38452 | S8: L' | T8: =$B$2-T5 -> 17.346226
A9: Atot | B9: =B7+B8 -> 0.72 | C9: m2 | E9: Parametri di calcolo | G9: Parametri di calcolo | I9: Parametri di calcolo | K9: Parametri di calcolo | M9: Parametri di calcolo | O9: Parametri di calcolo | Q9: Parametri di calcolo | S9: Parametri di calcolo
A10: yg1 | B10: =B5/2 -> 0.2 | C10: m | E10: sen(φ' ) | F10: =SIN($B$23) -> 0.62932039 | G10: sen(φ' ) | H10: =SIN($B$23) -> 0.62932039 | I10: sen(φ' ) | J10: =SIN($B$23) -> 0.62932039 | K10: sen(φ' ) | L10: =SIN($B$23) -> 0.62932039 | M10: sen(φ' ) | N10: =SIN($B$23) -> 0.62932039 | O10: sen(φ' ) | P10: =SIN($B$23) -> 0.62932039 | Q10: sen(φ' ) | R10: =SIN($B$23) -> 0.62932039 | S10: sen(φ' ) | T10: =SIN($B$23) -> 0.62932039
A11: yg2 | B11: =B5+B6/2 -> 0.8 | C11: m | E11: e(pi)*tang(φ ') | F11: =EXP(PI()*TAN($B$23)) -> 12.730639 | G11: e(pi)*tang(φ ') | H11: =EXP(PI()*TAN($B$23)) -> 12.730639 | I11: e(pi)*tang(φ ') | J11: =EXP(PI()*TAN($B$23)) -> 12.730639 | K11: e(pi)*tang(φ ') | L11: =EXP(PI()*TAN($B$23)) -> 12.730639 | M11: e(pi)*tang(φ ') | N11: =EXP(PI()*TAN($B$23)) -> 12.730639 | O11: e(pi)*tang(φ ') | P11: =EXP(PI()*TAN($B$23)) -> 12.730639 | Q11: e(pi)*tang(φ ') | R11: =EXP(PI()*TAN($B$23)) -> 12.730639 | S11: e(pi)*tang(φ ') | T11: =EXP(PI()*TAN($B$23)) -> 12.730639
A12: Yg | B12: =(B7*B10+B8*B11)/B9 -> 0.4 | C12: m | E12: tang(φ' ) | F12: =TAN($B$23) -> 0.80978403 | G12: tang(φ' ) | H12: =TAN($B$23) -> 0.80978403 | I12: tang(φ' ) | J12: =TAN($B$23) -> 0.80978403 | K12: tang(φ' ) | L12: =TAN($B$23) -> 0.80978403 | M12: tang(φ' ) | N12: =TAN($B$23) -> 0.80978403 | O12: tang(φ' ) | P12: =TAN($B$23) -> 0.80978403 | Q12: tang(φ' ) | R12: =TAN($B$23) -> 0.80978403 | S12: tang(φ' ) | T12: =TAN($B$23) -> 0.80978403
A13: Peso della fondazione | E13: cotang(φ' ) | F13: =_xlfn.COT($B$23) -> 1.2348972 | G13: cotang(φ' ) | H13: =_xlfn.COT($B$23) -> 1.2348972 | I13: cotang(φ' ) | J13: =_xlfn.COT($B$23) -> 1.2348972 | K13: cotang(φ' ) | L13: =_xlfn.COT($B$23) -> 1.2348972 | M13: cotang(φ' ) | N13: =_xlfn.COT($B$23) -> 1.2348972 | O13: cotang(φ' ) | P13: =_xlfn.COT($B$23) -> 1.2348972 | Q13: cotang(φ' ) | R13: =_xlfn.COT($B$23) -> 1.2348972 | S13: cotang(φ' ) | T13: =_xlfn.COT($B$23) -> 1.2348972
A14: G1 fonda | B14: =(B9*25*1.3*B2)/(B3*B2) -> 19.5 | C14: KN/m2 | D14: =B9*25*1.3 -> 23.4 | E14: tang(45+φ'/2 )2 | F14: =TAN(RADIANS(45)+$B$23/2)^2 -> 4.3954951 | G14: tang(45+φ'/2 )2 | H14: =TAN(RADIANS(45)+$B$23/2)^2 -> 4.3954951 | I14: tang(45+φ'/2 )2 | J14: =TAN(RADIANS(45)+$B$23/2)^2 -> 4.3954951 | K14: tang(45+φ'/2 )2 | L14: =TAN(RADIANS(45)+$B$23/2)^2 -> 4.3954951 | M14: tang(45+φ'/2 )2 | N14: =TAN(RADIANS(45)+$B$23/2)^2 -> 4.3954951 | O14: tang(45+φ'/2 )2 | P14: =TAN(RADIANS(45)+$B$23/2)^2 -> 4.3954951 | Q14: tang(45+φ'/2 )2 | R14: =TAN(RADIANS(45)+$B$23/2)^2 -> 4.3954951 | S14: tang(45+φ'/2 )2 | T14: =TAN(RADIANS(45)+$B$23/2)^2 -> 4.3954951
A15: Proprietà Terreno | E15: Fattori di capacità portante | G15: Fattori di capacità portante | I15: Fattori di capacità portante | K15: Fattori di capacità portante | M15: Fattori di capacità portante | O15: Fattori di capacità portante | Q15: Fattori di capacità portante | S15: Fattori di capacità portante
A16: Y | B16: ='Propietà terreno e Gazetas'!B3 -> 19 | C16: KN/m3 | E16: Nq | F16: =F11*F14 -> 55.957459 | G16: Nq | H16: =H11*H14 -> 55.957459 | I16: Nq | J16: =J11*J14 -> 55.957459 | K16: Nq | L16: =L11*L14 -> 55.957459 | M16: Nq | N16: =N11*N14 -> 55.957459 | O16: Nq | P16: =P11*P14 -> 55.957459 | Q16: Nq | R16: =R11*R14 -> 55.957459 | S16: Nq | T16: =T11*T14 -> 55.957459
A17: Y' | B17: ='Propietà terreno e Gazetas'!B3 -> 19 | C17: KN/m3 | E17: NY | F17: =2*(F16+1)*F12 -> 92.246481 | G17: NY | H17: =2*(H16+1)*H12 -> 92.246481 | I17: NY | J17: =2*(J16+1)*J12 -> 92.246481 | K17: NY | L17: =2*(L16+1)*L12 -> 92.246481 | M17: NY | N17: =2*(N16+1)*N12 -> 92.246481 | O17: NY | P17: =2*(P16+1)*P12 -> 92.246481 | Q17: NY | R17: =2*(R16+1)*R12 -> 92.246481 | S17: NY | T17: =2*(T16+1)*T12 -> 92.246481
A18: D | B18: =B6+B5 -> 1.2 | C18: m | E18: Nc | F18: =(F16-1)*F13 -> 67.86681 | G18: Nc | H18: =(H16-1)*H13 -> 67.86681 | I18: Nc | J18: =(J16-1)*J13 -> 67.86681 | K18: Nc | L18: =(L16-1)*L13 -> 67.86681 | M18: Nc | N18: =(N16-1)*N13 -> 67.86681 | O18: Nc | P18: =(P16-1)*P13 -> 67.86681 | Q18: Nc | R18: =(R16-1)*R13 -> 67.86681 | S18: Nc | T18: =(T16-1)*T13 -> 67.86681
A19: q' | B19: =(B18)*B16 -> 22.8 | C19: KN/m2 | E19: Fattori correttivi | G19: Fattori correttivi | I19: Fattori correttivi | K19: Fattori correttivi | M19: Fattori correttivi | O19: Fattori correttivi | Q19: Fattori correttivi | S19: Fattori correttivi
A20: c' | B20: 0 | E20: Fattori di forma | G20: Fattori di forma | I20: Fattori di forma | K20: Fattori di forma | M20: Fattori di forma | O20: Fattori di forma | Q20: Fattori di forma | S20: Fattori di forma
A21: φ' | B21: =MIN(_xlfn.CEILING.MATH('Propietà terreno e Gazetas'!B12)) -> 39 | C21: [°] | E21: sq | F21: =1+(F7/F8)*$F$10 -> 1.0447742 | G21: sq | H21: =1+(H7/H8)*$F$10 -> 1.04777 | I21: sq | J21: =1+(J7/J8)*$F$10 -> 1.0434401 | K21: sq | L21: =1+(L7/L8)*$F$10 -> 1.043536 | M21: sq | N21: =1+(N7/N8)*$F$10 -> 1.0434401 | O21: sq | P21: =1+(P7/P8)*$F$10 -> 1.043536 | Q21: sq | R21: =1+(R7/R8)*$F$10 -> 1.0434401 | S21: sq | T21: =1+(T7/T8)*$F$10 -> 1.043536
A22: Y RD per phi | B22: 1 | E22: sY | F22: =1-0.3*(F7/F8) -> 0.97865593 | G22: sY | H22: =1-0.3*(H7/H8) -> 0.97722781 | I22: sY | J22: =1-0.3*(J7/J8) -> 0.97929192 | K22: sY | L22: =1-0.3*(L7/L8) -> 0.97924621 | M22: sY | N22: =1-0.3*(N7/N8) -> 0.97929192 | O22: sY | P22: =1-0.3*(P7/P8) -> 0.97924621 | Q22: sY | R22: =1-0.3*(R7/R8) -> 0.97929192 | S22: sY | T22: =1-0.3*(T7/T8) -> 0.97924621
A23: φ'D | B23: =RADIANS(B21)/B22 -> 0.68067841 | C23: [rad] | E23: sc | F23: =(F21*$F$16-1)/($F$16-1) -> 1.0455889 | G23: sc | H23: =(H21*$F$16-1)/($F$16-1) -> 1.0486392 | I23: sc | J23: =(J21*$F$16-1)/($F$16-1) -> 1.0442305 | K23: sc | L23: =(L21*$F$16-1)/($F$16-1) -> 1.0443281 | M23: sc | N23: =(N21*$F$16-1)/($F$16-1) -> 1.0442305 | O23: sc | P23: =(P21*$F$16-1)/($F$16-1) -> 1.0443281 | Q23: sc | R23: =(R21*$F$16-1)/($F$16-1) -> 1.0442305 | S23: sc | T23: =(T21*$F$16-1)/($F$16-1) -> 1.0443281
A24: Parametri sismici | E24: Fattori di approfondimento | G24: Fattori di approfondimento | I24: Fattori di approfondimento | K24: Fattori di approfondimento | M24: Fattori di approfondimento | O24: Fattori di approfondimento | Q24: Fattori di approfondimento | S24: Fattori di approfondimento
A25: ag | B25: 0.19498706 | C25: g | E25: dq | F25: =IF(B18>B3,1+2*$F$12*(1-$F$10)^2*ATAN($B$18/$B$3),1+2*$F$12*(1-$F$10)^2*($B$18/$B$3)) -> 1.2225341 | G25: dq | H25: =IF(D18>D3,1+2*$F$12*(1-$F$10)^2*ATAN($B$18/$B$3),1+2*$F$12*(1-$F$10)^2*($B$18/$B$3)) -> 1.2225341 | I25: dq | J25: =IF(F18>F3,1+2*$F$12*(1-$F$10)^2*ATAN($B$18/$B$3),1+2*$F$12*(1-$F$10)^2*($B$18/$B$3)) -> 1.2225341 | K25: dq | L25: =IF(H18>H3,1+2*$F$12*(1-$F$10)^2*ATAN($B$18/$B$3),1+2*$F$12*(1-$F$10)^2*($B$18/$B$3)) -> 1.2225341 | M25: dq | N25: =IF(J18>J3,1+2*$F$12*(1-$F$10)^2*ATAN($B$18/$B$3),1+2*$F$12*(1-$F$10)^2*($B$18/$B$3)) -> 1.2225341 | O25: dq | P25: =IF(L18>L3,1+2*$F$12*(1-$F$10)^2*ATAN($B$18/$B$3),1+2*$F$12*(1-$F$10)^2*($B$18/$B$3)) -> 1.2225341 | Q25: dq | R25: =IF(N18>N3,1+2*$F$12*(1-$F$10)^2*ATAN($B$18/$B$3),1+2*$F$12*(1-$F$10)^2*($B$18/$B$3)) -> 1.2225341 | S25: dq | T25: =IF(P18>P3,1+2*$F$12*(1-$F$10)^2*ATAN($B$18/$B$3),1+2*$F$12*(1-$F$10)^2*($B$18/$B$3)) -> 1.2225341
A26: SS | B26: 1.2 | E26: dc | F26: =F25-((1-F25)/($F$18*$F$12)) -> 1.2265833 | G26: dc | H26: =H25-((1-H25)/($F$18*$F$12)) -> 1.2265833 | I26: dc | J26: =J25-((1-J25)/($F$18*$F$12)) -> 1.2265833 | K26: dc | L26: =L25-((1-L25)/($F$18*$F$12)) -> 1.2265833 | M26: dc | N26: =N25-((1-N25)/($F$18*$F$12)) -> 1.2265833 | O26: dc | P26: =P25-((1-P25)/($F$18*$F$12)) -> 1.2265833 | Q26: dc | R26: =R25-((1-R25)/($F$18*$F$12)) -> 1.2265833 | S26: dc | T26: =T25-((1-T25)/($F$18*$F$12)) -> 1.2265833
A27: ST | B27: 1 | E27: dY | F27: =1 -> 1 | G27: dY | H27: =1 -> 1 | I27: dY | J27: =1 -> 1 | K27: dY | L27: =1 -> 1 | M27: dY | N27: =1 -> 1 | O27: dY | P27: =1 -> 1 | Q27: dY | R27: =1 -> 1 | S27: dY | T27: =1 -> 1
A28: S | B28: =B26*B27 -> 1.2 | E28: Fattori di inclinazione del carico | G28: Fattori di inclinazione del carico | I28: Fattori di inclinazione del carico | K28: Fattori di inclinazione del carico | M28: Fattori di inclinazione del carico | O28: Fattori di inclinazione del carico | Q28: Fattori di inclinazione del carico | S28: Fattori di inclinazione del carico
A29: Fo | B29: 2.398966 | E29: mL | F29: =(2+(F8/F7))/(1+(F8/F7)) -> 1.0664212 | G29: mL | H29: =(2+(H8/H7))/(1+(H8/H7)) -> 1.0705519 | I29: mL | J29: =(2+(J8/J7))/(1+(J8/J7)) -> 1.0645699 | K29: mL | L29: =(2+(L8/L7))/(1+(L8/L7)) -> 1.0647032 | M29: mL | N29: =(2+(N8/N7))/(1+(N8/N7)) -> 1.0645699 | O29: mL | P29: =(2+(P8/P7))/(1+(P8/P7)) -> 1.0647032 | Q29: mL | R29: =(2+(R8/R7))/(1+(R8/R7)) -> 1.0645699 | S29: mL | T29: =(2+(T8/T7))/(1+(T8/T7)) -> 1.0647032
A30: TC* | B30: 0.2853738 | C30: s | E30: iq | F30: =(1-F4/(F3+F7*F8*$B$20*$F$13))^F29 -> 0.66460656 | G30: iq | H30: =(1-H4/(H3+H7*H8*$B$20*H13))^H29 -> 0.13310442 | I30: iq | J30: =(1-J4/(J3+J7*J8*$B$20*$F$13))^J29 -> 0.94528832 | K30: iq | L30: =(1-L4/(L3+L7*L8*$B$20*$F$13))^L29 -> 0.92729629 | M30: iq | N30: =(1-N4/(N3+N7*N8*$B$20*$F$13))^N29 -> 0.94528826 | O30: iq | P30: =(1-P4/(P3+P7*P8*$B$20*$F$13))^P29 -> 0.9272962 | Q30: iq | R30: =(1-R4/(R3+R7*R8*$B$20*$F$13))^R29 -> 0.94528826 | S30: iq | T30: =(1-T4/(T3+T7*T8*$B$20*$F$13))^T29 -> 0.9272962
E31: ic | F31: =F30-(1-F30)/($F$18*$F$12) -> 0.65850378 | G31: ic | H31: =H30-(1-H30)/($F$18*$F$12) -> 0.11733048 | I31: ic | J31: =J30-(1-J30)/($F$18*$F$12) -> 0.9442928 | K31: ic | L31: =L30-(1-L30)/($F$18*$F$12) -> 0.92597338 | M31: ic | N31: =N30-(1-N30)/($F$18*$F$12) -> 0.94429273 | O31: ic | P31: =P30-(1-P30)/($F$18*$F$12) -> 0.92597329 | Q31: ic | R31: =R30-(1-R30)/($F$18*$F$12) -> 0.94429273 | S31: ic | T31: =T30-(1-T30)/($F$18*$F$12) -> 0.92597329
E32: iY | F32: =(1-F4/(F3+F7*F8*B20*F13))^(F29+1) -> 0.45308603 | G32: iY | H32: =(1-H4/(H3+H7*H8*D20*H13))^(H29+1) -> 0.020234979 | I32: iY | J32: =(1-J4/(J3+J7*J8*F20*J13))^(J29+1) -> 0.8966247 | K32: iY | L32: =(1-L4/(L3+L7*L8*H20*L13))^(L29+1) -> 0.86383185 | M32: iY | N32: =(1-N4/(N3+N7*N8*J20*N13))^(N29+1) -> 0.89662457 | O32: iY | P32: =(1-P4/(P3+P7*P8*L20*P13))^(P29+1) -> 0.86383169 | Q32: iY | R32: =(1-R4/(R3+R7*R8*N20*R13))^(R29+1) -> 0.89662457 | S32: iY | T32: =(1-T4/(T3+T7*T8*P20*T13))^(T29+1) -> 0.86383169
E33: Fattori sismici | G33: Fattori sismici | I33: Fattori sismici | K33: Fattori sismici | M33: Fattori sismici | O33: Fattori sismici | Q33: Fattori sismici | S33: Fattori sismici
E34: Kh | F34: =$B$25*$B$28 -> 0.23398448 | G34: Kh | H34: =$B$25*$B$28 -> 0.23398448 | I34: Kh | J34: =$B$25*$B$28 -> 0.23398448 | K34: Kh | L34: =$B$25*$B$28 -> 0.23398448 | M34: Kh | N34: =$B$25*$B$28 -> 0.23398448 | O34: Kh | P34: =$B$25*$B$28 -> 0.23398448 | Q34: Kh | R34: =$B$25*$B$28 -> 0.23398448 | S34: Kh | T34: =$B$25*$B$28 -> 0.23398448
E35: Kv | F35: =F34/2 -> 0.11699224 | G35: Kv | H35: =H34/2 -> 0.11699224 | I35: Kv | J35: =J34/2 -> 0.11699224 | K35: Kv | L35: =L34/2 -> 0.11699224 | M35: Kv | N35: =N34/2 -> 0.11699224 | O35: Kv | P35: =P34/2 -> 0.11699224 | Q35: Kv | R35: =R34/2 -> 0.11699224 | S35: Kv | T35: =T34/2 -> 0.11699224
E36: ẞs | F36: =0.24 -> 0.24 | G36: ẞs | H36: =0.24 -> 0.24 | I36: ẞs | J36: =0.24 -> 0.24 | K36: ẞs | L36: =0.24 -> 0.24 | M36: ẞs | N36: =0.24 -> 0.24 | O36: ẞs | P36: =0.24 -> 0.24 | Q36: ẞs | R36: =0.24 -> 0.24 | S36: ẞs | T36: =0.24 -> 0.24
E37: zq | F37: =(1-F34/F12)^(0.35) -> 0.88749464 | G37: zq | H37: =(1-H34/H12)^(0.35) -> 0.88749464 | I37: zq | J37: =(1-J34/J12)^(0.35) -> 0.88749464 | K37: zq | L37: =(1-L34/L12)^(0.35) -> 0.88749464 | M37: zq | N37: =(1-N34/N12)^(0.35) -> 0.88749464 | O37: zq | P37: =(1-P34/P12)^(0.35) -> 0.88749464 | Q37: zq | R37: =(1-R34/R12)^(0.35) -> 0.88749464 | S37: zq | T37: =(1-T34/T12)^(0.35) -> 0.88749464
E38: zc | F38: =(1-0.32*F34) -> 0.92512497 | G38: zc | H38: =(1-0.32*H34) -> 0.92512497 | I38: zc | J38: =(1-0.32*J34) -> 0.92512497 | K38: zc | L38: =(1-0.32*L34) -> 0.92512497 | M38: zc | N38: =(1-0.32*N34) -> 0.92512497 | O38: zc | P38: =(1-0.32*P34) -> 0.92512497 | Q38: zc | R38: =(1-0.32*R34) -> 0.92512497 | S38: zc | T38: =(1-0.32*T34) -> 0.92512497
E39: zY | F39: =F37 -> 0.88749464 | G39: zY | H39: =H37 -> 0.88749464 | I39: zY | J39: =J37 -> 0.88749464 | K39: zY | L39: =L37 -> 0.88749464 | M39: zY | N39: =N37 -> 0.88749464 | O39: zY | P39: =P37 -> 0.88749464 | Q39: zY | R39: =R37 -> 0.88749464 | S39: zY | T39: =T37 -> 0.88749464
E40: CAPACITA' PORTANTE | G40: CAPACITA' PORTANTE | I40: CAPACITA' PORTANTE | K40: CAPACITA' PORTANTE | M40: CAPACITA' PORTANTE | O40: CAPACITA' PORTANTE | Q40: CAPACITA' PORTANTE | S40: CAPACITA' PORTANTE
...

Sheet VERIFICHE(DREANATO)Y sisma
A1: Proprietà Fondazione | E1: TRAVE1 Y | G1: TRAVE1 Y | I1: TRAVE2 Y | K1: TRAVE2 Y | M1: TRAVE3 Y | O1: TRAVE3 Y | Q1: TRAVE4 Y | S1: TRAVE4 Y | U1: TRAVE5 Y | W1: TRAVE5 Y
A2: L | B2: 13.5 | C2: m | E2: Sollecitazioni | G2: Sollecitazioni | I2: Sollecitazioni | K2: Sollecitazioni | M2: Sollecitazioni | O2: Sollecitazioni | Q2: Sollecitazioni | S2: Sollecitazioni | U2: Sollecitazioni | W2: Sollecitazioni
A3: B | B3: 1.2 | C3: m | E3: N | F3: ='Forze totale sisma su fonda'!B4 -> 1649.3015 | G3: N | H3: ='Forze totale sisma su fonda'!G4 -> 1340.5953 | I3: N | J3: ='Forze totale sisma su fonda'!B5 -> 2138.2949 | K3: N | L3: ='Forze totale sisma su fonda'!G5 -> 2890.1576 | M3: N | N3: ='Forze totale sisma su fonda'!B6 -> 2513.8762 | O3: N | P3: ='Forze totale sisma su fonda'!G6 -> 3519.0738 | Q3: N | R3: ='Forze totale sisma su fonda'!B7 -> 2522.2994 | S3: N | T3: ='Forze totale sisma su fonda'!G7 -> 3444.0505 | U3: N | V3: ='Forze totale sisma su fonda'!B8 -> 1656.1694 | W3: N | X3: ='Forze totale sisma su fonda'!G8 -> 1326.831
A4: b | B4: 0.3 | C4: m | E4: H | F4: ='Forze totale sisma su fonda'!C4 -> 391.9157 | G4: H | H4: =ABS('Forze totale sisma su fonda'!H4) -> 391.9212 | I4: H | J4: ='Forze totale sisma su fonda'!C5 -> 372.1311 | K4: H | L4: =ABS('Forze totale sisma su fonda'!H5) -> 372.1289 | M4: H | N4: ='Forze totale sisma su fonda'!C6 -> 353.364 | O4: H | P4: =ABS('Forze totale sisma su fonda'!H6) -> 353.364 | Q4: H | R4: ='Forze totale sisma su fonda'!C7 -> 389.9346 | S4: H | T4: =ABS('Forze totale sisma su fonda'!H7) -> 389.9357 | U4: H | V4: ='Forze totale sisma su fonda'!C8 -> 423.2129 | W4: H | X4: =ABS('Forze totale sisma su fonda'!H8) -> 423.2085
A5: h1 | B5: 0.3 | C5: m | E5: e | F5: ='Forze totale sisma su fonda'!E4 -> 0.44321323 | G5: e | H5: ='Forze totale sisma su fonda'!K4 -> 0.54526845 | I5: e | J5: ='Forze totale sisma su fonda'!E5 -> 0.32497517 | K5: e | L5: ='Forze totale sisma su fonda'!K5 -> 0.24043486 | M5: e | N5: ='Forze totale sisma su fonda'!E6 -> 0.26250986 | O5: e | P5: ='Forze totale sisma su fonda'!K6 -> 0.18752522 | Q5: e | R5: ='Forze totale sisma su fonda'!E7 -> 0.28872339 | S5: e | T5: ='Forze totale sisma su fonda'!K7 -> 0.2114504 | U5: e | V5: ='Forze totale sisma su fonda'!E8 -> 0.47670759 | W5: e | X5: ='Forze totale sisma su fonda'!K8 -> 0.59503809
A6: h2 | B6: =B3-B5 -> 0.9 | C6: m | E6: Dimensioni efficaci | G6: Dimensioni efficaci | I6: Dimensioni efficaci | K6: Dimensioni efficaci | M6: Dimensioni efficaci | O6: Dimensioni efficaci | Q6: Dimensioni efficaci | S6: Dimensioni efficaci | U6: Dimensioni efficaci | W6: Dimensioni efficaci
A7: A1 | B7: =B5*B3 -> 0.36 | C7: m2 | E7: B' | F7: =$B$3 -> 1.2 | G7: B' | H7: =$B$3 -> 1.2 | I7: B' | J7: =$B$3 -> 1.2 | K7: B' | L7: =$B$3 -> 1.2 | M7: B' | N7: =$B$3 -> 1.2 | O7: B' | P7: =$B$3 -> 1.2 | Q7: B' | R7: =$B$3 -> 1.2 | S7: B' | T7: =$B$3 -> 1.2 | U7: B' | V7: =$B$3 -> 1.2 | W7: B' | X7: =$B$3 -> 1.2
A8: A2 | B8: =B6*B4 -> 0.27 | C8: m2 | E8: L' | F8: =$B$2-F5 -> 13.056787 | G8: L' | H8: =$B$2-H5 -> 12.954732 | I8: L' | J8: =$B$2-J5 -> 13.175025 | K8: L' | L8: =$B$2-L5 -> 13.259565 | M8: L' | N8: =$B$2-N5 -> 13.23749 | O8: L' | P8: =$B$2-P5 -> 13.312475 | Q8: L' | R8: =$B$2-R5 -> 13.211277 | S8: L' | T8: =$B$2-T5 -> 13.28855 | U8: L' | V8: =$B$2-V5 -> 13.023292 | W8: L' | X8: =$B$2-X5 -> 12.904962
A9: Atot | B9: =B7+B8 -> 0.63 | C9: m2 | E9: Parametri di calcolo | G9: Parametri di calcolo | I9: Parametri di calcolo | K9: Parametri di calcolo | M9: Parametri di calcolo | O9: Parametri di calcolo | Q9: Parametri di calcolo | S9: Parametri di calcolo | U9: Parametri di calcolo | W9: Parametri di calcolo
A10: yg1 | B10: =B5/2 -> 0.15 | C10: m | E10: sen(φ' ) | F10: =SIN($B$23) -> 0.57357644 | G10: sen(φ' ) | H10: =SIN($B$23) -> 0.57357644 | I10: sen(φ' ) | J10: =SIN($B$23) -> 0.57357644 | K10: sen(φ' ) | L10: =SIN($B$23) -> 0.57357644 | M10: sen(φ' ) | N10: =SIN($B$23) -> 0.57357644 | O10: sen(φ' ) | P10: =SIN($B$23) -> 0.57357644 | Q10: sen(φ' ) | R10: =SIN($B$23) -> 0.57357644 | S10: sen(φ' ) | T10: =SIN($B$23) -> 0.57357644 | U10: sen(φ' ) | V10: =SIN($B$23) -> 0.57357644 | W10: sen(φ' ) | X10: =SIN($B$23) -> 0.57357644
A11: yg2 | B11: =B5+B6/2 -> 0.75 | C11: m | E11: e(pi)*tang(φ ') | F11: =EXP(PI()*TAN($B$23)) -> 9.0229096 | G11: e(pi)*tang(φ ') | H11: =EXP(PI()*TAN($B$23)) -> 9.0229096 | I11: e(pi)*tang(φ ') | J11: =EXP(PI()*TAN($B$23)) -> 9.0229096 | K11: e(pi)*tang(φ ') | L11: =EXP(PI()*TAN($B$23)) -> 9.0229096 | M11: e(pi)*tang(φ ') | N11: =EXP(PI()*TAN($B$23)) -> 9.0229096 | O11: e(pi)*tang(φ ') | P11: =EXP(PI()*TAN($B$23)) -> 9.0229096 | Q11: e(pi)*tang(φ ') | R11: =EXP(PI()*TAN($B$23)) -> 9.0229096 | S11: e(pi)*tang(φ ') | T11: =EXP(PI()*TAN($B$23)) -> 9.0229096 | U11: e(pi)*tang(φ ') | V11: =EXP(PI()*TAN($B$23)) -> 9.0229096 | W11: e(pi)*tang(φ ') | X11: =EXP(PI()*TAN($B$23)) -> 9.0229096
A12: Yg | B12: =(B7*B10+B8*B11)/B9 -> 0.40714286 | C12: m | E12: tang(φ' ) | F12: =TAN($B$23) -> 0.70020754 | G12: tang(φ' ) | H12: =TAN($B$23) -> 0.70020754 | I12: tang(φ' ) | J12: =TAN($B$23) -> 0.70020754 | K12: tang(φ' ) | L12: =TAN($B$23) -> 0.70020754 | M12: tang(φ' ) | N12: =TAN($B$23) -> 0.70020754 | O12: tang(φ' ) | P12: =TAN($B$23) -> 0.70020754 | Q12: tang(φ' ) | R12: =TAN($B$23) -> 0.70020754 | S12: tang(φ' ) | T12: =TAN($B$23) -> 0.70020754 | U12: tang(φ' ) | V12: =TAN($B$23) -> 0.70020754 | W12: tang(φ' ) | X12: =TAN($B$23) -> 0.70020754
A13: Peso della fondazione | E13: cotang(φ' ) | F13: =_xlfn.COT($B$23) -> 1.428148 | G13: cotang(φ' ) | H13: =_xlfn.COT($B$23) -> 1.428148 | I13: cotang(φ' ) | J13: =_xlfn.COT($B$23) -> 1.428148 | K13: cotang(φ' ) | L13: =_xlfn.COT($B$23) -> 1.428148 | M13: cotang(φ' ) | N13: =_xlfn.COT($B$23) -> 1.428148 | O13: cotang(φ' ) | P13: =_xlfn.COT($B$23) -> 1.428148 | Q13: cotang(φ' ) | R13: =_xlfn.COT($B$23) -> 1.428148 | S13: cotang(φ' ) | T13: =_xlfn.COT($B$23) -> 1.428148 | U13: cotang(φ' ) | V13: =_xlfn.COT($B$23) -> 1.428148 | W13: cotang(φ' ) | X13: =_xlfn.COT($B$23) -> 1.428148
A14: G1 fonda | B14: =(B9*25*1.3*B2)/(B3*B2) -> 17.0625 | C14: KN/m2 | E14: tang(45+φ'/2 )2 | F14: =TAN(RADIANS(45)+$B$23/2)^2 -> 3.6901723 | G14: tang(45+φ'/2 )2 | H14: =TAN(RADIANS(45)+$B$23/2)^2 -> 3.6901723 | I14: tang(45+φ'/2 )2 | J14: =TAN(RADIANS(45)+$B$23/2)^2 -> 3.6901723 | K14: tang(45+φ'/2 )2 | L14: =TAN(RADIANS(45)+$B$23/2)^2 -> 3.6901723 | M14: tang(45+φ'/2 )2 | N14: =TAN(RADIANS(45)+$B$23/2)^2 -> 3.6901723 | O14: tang(45+φ'/2 )2 | P14: =TAN(RADIANS(45)+$B$23/2)^2 -> 3.6901723 | Q14: tang(45+φ'/2 )2 | R14: =TAN(RADIANS(45)+$B$23/2)^2 -> 3.6901723 | S14: tang(45+φ'/2 )2 | T14: =TAN(RADIANS(45)+$B$23/2)^2 -> 3.6901723 | U14: tang(45+φ'/2 )2 | V14: =TAN(RADIANS(45)+$B$23/2)^2 -> 3.6901723 | W14: tang(45+φ'/2 )2 | X14: =TAN(RADIANS(45)+$B$23/2)^2 -> 3.6901723
A15: Proprietà Terreno | E15: Fattori di capacità portante | G15: Fattori di capacità portante | I15: Fattori di capacità portante | K15: Fattori di capacità portante | M15: Fattori di capacità portante | O15: Fattori di capacità portante | Q15: Fattori di capacità portante | S15: Fattori di capacità portante | U15: Fattori di capacità portante | W15: Fattori di capacità portante
A16: Y | B16: ='Propietà terreno e Gazetas'!B3 -> 19 | C16: KN/m3 | E16: Nq | F16: =F11*F14 -> 33.296091 | G16: Nq | H16: =H11*H14 -> 33.296091 | I16: Nq | J16: =J11*J14 -> 33.296091 | K16: Nq | L16: =L11*L14 -> 33.296091 | M16: Nq | N16: =N11*N14 -> 33.296091 | O16: Nq | P16: =P11*P14 -> 33.296091 | Q16: Nq | R16: =R11*R14 -> 33.296091 | S16: Nq | T16: =T11*T14 -> 33.296091 | U16: Nq | V16: =V11*V14 -> 33.296091 | W16: Nq | X16: =X11*X14 -> 33.296091
A17: Y' | B17: ='Propietà terreno e Gazetas'!B3 -> 19 | C17: KN/m3 | E17: NY | F17: =2*(F16+1)*F12 -> 48.028764 | G17: NY | H17: =2*(H16+1)*H12 -> 48.028764 | I17: NY | J17: =2*(J16+1)*J12 -> 48.028764 | K17: NY | L17: =2*(L16+1)*L12 -> 48.028764 | M17: NY | N17: =2*(N16+1)*N12 -> 48.028764 | O17: NY | P17: =2*(P16+1)*P12 -> 48.028764 | Q17: NY | R17: =2*(R16+1)*R12 -> 48.028764 | S17: NY | T17: =2*(T16+1)*T12 -> 48.028764 | U17: NY | V17: =2*(V16+1)*V12 -> 48.028764 | W17: NY | X17: =2*(X16+1)*X12 -> 48.028764
A18: D | B18: =B6+B5 -> 1.2 | C18: m | E18: Nc | F18: =(F16-1)*F13 -> 46.123599 | G18: Nc | H18: =(H16-1)*H13 -> 46.123599 | I18: Nc | J18: =(J16-1)*J13 -> 46.123599 | K18: Nc | L18: =(L16-1)*L13 -> 46.123599 | M18: Nc | N18: =(N16-1)*N13 -> 46.123599 | O18: Nc | P18: =(P16-1)*P13 -> 46.123599 | Q18: Nc | R18: =(R16-1)*R13 -> 46.123599 | S18: Nc | T18: =(T16-1)*T13 -> 46.123599 | U18: Nc | V18: =(V16-1)*V13 -> 46.123599 | W18: Nc | X18: =(X16-1)*X13 -> 46.123599
A19: q' | B19: =(B18)*B16 -> 22.8 | C19: KN/m2 | E19: Fattori correttivi | G19: Fattori correttivi | I19: Fattori correttivi | K19: Fattori correttivi | M19: Fattori correttivi | O19: Fattori correttivi | Q19: Fattori correttivi | S19: Fattori correttivi | U19: Fattori correttivi | W19: Fattori correttivi
A20: c' | B20: 0 | E20: Fattori di forma | G20: Fattori di forma | I20: Fattori di forma | K20: Fattori di forma | M20: Fattori di forma | O20: Fattori di forma | Q20: Fattori di forma | S20: Fattori di forma | U20: Fattori di forma | W20: Fattori di forma
A21: φ' | B21: =MIN(_xlfn.FLOOR.MATH('Propietà terreno e Gazetas'!B12),35) -> 35 | C21: [°] | E21: sq | F21: =1+(F7/F8)*$F$10 -> 1.0527152 | G21: sq | H21: =1+(H7/H8)*$F$10 -> 1.0531305 | I21: sq | J21: =1+(J7/J8)*$F$10 -> 1.0522422 | K21: sq | L21: =1+(L7/L8)*$F$10 -> 1.0519091 | M21: sq | N21: =1+(N7/N8)*$F$10 -> 1.0519956 | O21: sq | P21: =1+(P7/P8)*$F$10 -> 1.0517028 | Q21: sq | R21: =1+(R7/R8)*$F$10 -> 1.0520988 | S21: sq | T21: =1+(T7/T8)*$F$10 -> 1.0517959 | U21: sq | V21: =1+(V7/V8)*$F$10 -> 1.0528508 | W21: sq | X21: =1+(X7/X8)*$F$10 -> 1.0533354
A22: Y RD per phi | B22: 1 | E22: sY | F22: =1-0.3*(F7/F8) -> 0.97242813 | G22: sY | H22: =1-0.3*(H7/H8) -> 0.97221093 | I22: sY | J22: =1-0.3*(J7/J8) -> 0.97267557 | K22: sY | L22: =1-0.3*(L7/L8) -> 0.97284979 | M22: sY | N22: =1-0.3*(N7/N8) -> 0.97280451 | O22: sY | P22: =1-0.3*(P7/P8) -> 0.9729577 | Q22: sY | R22: =1-0.3*(R7/R8) -> 0.97275055 | S22: sY | T22: =1-0.3*(T7/T8) -> 0.97290901 | U22: sY | V22: =1-0.3*(V7/V8) -> 0.97235722 | W22: sY | X22: =1-0.3*(X7/X8) -> 0.97210375
A23: φ'D | B23: =RADIANS(B21)/B22 -> 0.61086524 | C23: [rad] | E23: sc | F23: =(F21*$F$16-1)/($F$16-1) -> 1.0543475 | G23: sc | H23: =(H21*$F$16-1)/($F$16-1) -> 1.0547756 | I23: sc | J23: =(J21*$F$16-1)/($F$16-1) -> 1.0538598 | K23: sc | L23: =(L21*$F$16-1)/($F$16-1) -> 1.0535164 | M23: sc | N23: =(N21*$F$16-1)/($F$16-1) -> 1.0536056 | O23: sc | P23: =(P21*$F$16-1)/($F$16-1) -> 1.0533037 | Q23: sc | R23: =(R21*$F$16-1)/($F$16-1) -> 1.053712 | S23: sc | T23: =(T21*$F$16-1)/($F$16-1) -> 1.0533996 | U23: sc | V23: =(V21*$F$16-1)/($F$16-1) -> 1.0544873 | W23: sc | X23: =(X21*$F$16-1)/($F$16-1) -> 1.0549869
A24: Parametri sismici | E24: Fattori di approfondimento | G24: Fattori di approfondimento | I24: Fattori di approfondimento | K24: Fattori di approfondimento | M24: Fattori di approfondimento | O24: Fattori di approfondimento | Q24: Fattori di approfondimento | S24: Fattori di approfondimento | U24: Fattori di approfondimento | W24: Fattori di approfondimento
A25: ag | B25: 0.19498706 | C25: g | E25: dq | F25: =IF(B18>B3,1+2*$F$12*(1-$F$10)^2*ATAN($B$18/$B$3),1+2*$F$12*(1-$F$10)^2*($B$18/$B$3)) -> 1.2546474 | G25: dq | H25: =IF(D18>D3,1+2*$F$12*(1-$F$10)^2*ATAN($B$18/$B$3),1+2*$F$12*(1-$F$10)^2*($B$18/$B$3)) -> 1.2546474 | I25: dq | J25: =IF(F18>F3,1+2*$F$12*(1-$F$10)^2*ATAN($B$18/$B$3),1+2*$F$12*(1-$F$10)^2*($B$18/$B$3)) -> 1.2546474 | K25: dq | L25: =IF(H18>H3,1+2*$F$12*(1-$F$10)^2*ATAN($B$18/$B$3),1+2*$F$12*(1-$F$10)^2*($B$18/$B$3)) -> 1.2546474 | M25: dq | N25: =IF(J18>J3,1+2*$F$12*(1-$F$10)^2*ATAN($B$18/$B$3),1+2*$F$12*(1-$F$10)^2*($B$18/$B$3)) -> 1.2546474 | O25: dq | P25: =IF(L18>L3,1+2*$F$12*(1-$F$10)^2*ATAN($B$18/$B$3),1+2*$F$12*(1-$F$10)^2*($B$18/$B$3)) -> 1.2546474 | Q25: dq | R25: =IF(N18>N3,1+2*$F$12*(1-$F$10)^2*ATAN($B$18/$B$3),1+2*$F$12*(1-$F$10)^2*($B$18/$B$3)) -> 1.2546474 | S25: dq | T25: =IF(P18>P3,1+2*$F$12*(1-$F$10)^2*ATAN($B$18/$B$3),1+2*$F$12*(1-$F$10)^2*($B$18/$B$3)) -> 1.2546474 | U25: dq | V25: =IF(R18>R3,1+2*$F$12*(1-$F$10)^2*ATAN($B$18/$B$3),1+2*$F$12*(1-$F$10)^2*($B$18/$B$3)) -> 1.2546474 | W25: dq | X25: =IF(T18>T3,1+2*$F$12*(1-$F$10)^2*ATAN($B$18/$B$3),1+2*$F$12*(1-$F$10)^2*($B$18/$B$3)) -> 1.2546474
A26: SS | B26: 1.2 | E26: dc | F26: =F25-((1-F25)/($F$18*$F$12)) -> 1.2625321 | G26: dc | H26: =H25-((1-H25)/($F$18*$F$12)) -> 1.2625321 | I26: dc | J26: =J25-((1-J25)/($F$18*$F$12)) -> 1.2625321 | K26: dc | L26: =L25-((1-L25)/($F$18*$F$12)) -> 1.2625321 | M26: dc | N26: =N25-((1-N25)/($F$18*$F$12)) -> 1.2625321 | O26: dc | P26: =P25-((1-P25)/($F$18*$F$12)) -> 1.2625321 | Q26: dc | R26: =R25-((1-R25)/($F$18*$F$12)) -> 1.2625321 | S26: dc | T26: =T25-((1-T25)/($F$18*$F$12)) -> 1.2625321 | U26: dc | V26: =V25-((1-V25)/($F$18*$F$12)) -> 1.2625321 | W26: dc | X26: =X25-((1-X25)/($F$18*$F$12)) -> 1.2625321
A27: ST | B27: 1 | E27: dY | F27: =1 -> 1 | G27: dY | H27: =1 -> 1 | I27: dY | J27: =1 -> 1 | K27: dY | L27: =1 -> 1 | M27: dY | N27: =1 -> 1 | O27: dY | P27: =1 -> 1 | Q27: dY | R27: =1 -> 1 | S27: dY | T27: =1 -> 1 | U27: dY | V27: =1 -> 1 | W27: dY | X27: =1 -> 1
A28: S | B28: =B26*B27 -> 1.2 | E28: Fattori di inclinazione del carico | G28: Fattori di inclinazione del carico | I28: Fattori di inclinazione del carico | K28: Fattori di inclinazione del carico | M28: Fattori di inclinazione del carico | O28: Fattori di inclinazione del carico | Q28: Fattori di inclinazione del carico | S28: Fattori di inclinazione del carico | U28: Fattori di inclinazione del carico | W28: Fattori di inclinazione del carico
A29: Fo | B29: 2.398966 | E29: mL | F29: =(2+(F8/F7))/(1+(F8/F7)) -> 1.0841704 | G29: mL | H29: =(2+(H8/H7))/(1+(H8/H7)) -> 1.0847773 | I29: mL | J29: =(2+(J8/J7))/(1+(J8/J7)) -> 1.0834781 | K29: mL | L29: =(2+(L8/L7))/(1+(L8/L7)) -> 1.08299 | M29: mL | N29: =(2+(N8/N7))/(1+(N8/N7)) -> 1.0831169 | O29: mL | P29: =(2+(P8/P7))/(1+(P8/P7)) -> 1.0826875 | Q29: mL | R29: =(2+(R8/R7))/(1+(R8/R7)) -> 1.0832681 | S29: mL | T29: =(2+(T8/T7))/(1+(T8/T7)) -> 1.082824 | U29: mL | V29: =(2+(V8/V7))/(1+(V8/V7)) -> 1.0843687 | W29: mL | X29: =(2+(X8/X7))/(1+(X8/X7)) -> 1.0850764
A30: TC* | B30: 0.2853738 | C30: s | E30: iq | F30: =(1-F4/(F3+F7*F8*$B$20*$F$13))^F29 -> 0.74516177 | G30: iq | H30: =(1-H4/(H3+H7*H8*$B$20*$F$13))^H29 -> 0.68720679 | I30: iq | J30: =(1-J4/(J3+J7*J8*$B$20*$F$13))^J29 -> 0.81288974 | K30: iq | L30: =(1-L4/(L3+L7*L8*$B$20*$F$13))^L29 -> 0.86133341 | M30: iq | N30: =(1-N4/(N3+N7*N8*$B$20*$F$13))^N29 -> 0.84868164 | O30: iq | P30: =(1-P4/(P3+P7*P8*$B$20*$F$13))^P29 -> 0.89174901 | Q30: iq | R30: =(1-R4/(R3+R7*R8*$B$20*$F$13))^R29 -> 0.83366525 | S30: iq | T30: =(1-T4/(T3+T7*T8*$B$20*$F$13))^T29 -> 0.87799844 | U30: iq | V30: =(1-V4/(V3+V7*V8*$B$20*$F$13))^V29 -> 0.72615705 | W30: iq | X30: =(1-X4/(X3+X7*X8*$B$20*$F$13))^X29 -> 0.65914088
E31: ic | F31: =F30-(1-F30)/($F$18*$F$12) -> 0.73727109 | G31: ic | H31: =H30-(1-H30)/($F$18*$F$12) -> 0.67752162 | I31: ic | J31: =J30-(1-J30)/($F$18*$F$12) -> 0.80709615 | K31: ic | L31: =L30-(1-L30)/($F$18*$F$12) -> 0.85703981 | M31: ic | N31: =N30-(1-N30)/($F$18*$F$12) -> 0.8439963 | O31: ic | P31: =P30-(1-P30)/($F$18*$F$12) -> 0.88839718 | Q31: ic | R31: =R30-(1-R30)/($F$18*$F$12) -> 0.82851494 | S31: ic | T31: =T30-(1-T30)/($F$18*$F$12) -> 0.87422085 | U31: ic | V31: =V30-(1-V30)/($F$18*$F$12) -> 0.71767792 | W31: ic | X31: =X30-(1-X30)/($F$18*$F$12) -> 0.64858668
E32: iY | F32: =(1-F4/(F3+F7*F8*B20*F13))^(F29+1) -> 0.56809251 | G32: iY | H32: =(1-H4/(H3+H7*H8*D20*H13))^(H29+1) -> 0.48630282 | I32: iY | J32: =(1-J4/(J3+J7*J8*F20*J13))^(J29+1) -> 0.67142116 | K32: iY | L32: =(1-L4/(L3+L7*L8*H20*L13))^(L29+1) -> 0.75043045 | M32: iY | N32: =(1-N4/(N3+N7*N8*J20*N13))^(N29+1) -> 0.72938637 | O32: iY | P32: =(1-P4/(P3+P7*P8*L20*P13))^(P29+1) -> 0.80220499 | Q32: iY | R32: =(1-R4/(R3+R7*R8*N20*R13))^(R29+1) -> 0.70478486 | S32: iY | T32: =(1-T4/(T3+T7*T8*P20*T13))^(T29+1) -> 0.77859138 | U32: iY | V32: =(1-V4/(V3+V7*V8*R20*V13))^(V29+1) -> 0.5405969 | W32: iY | X32: =(1-X4/(X3+X7*X8*T20*X13))^(X29+1) -> 0.44890007
E33: Fattori sismici | G33: Fattori sismici | I33: Fattori sismici | K33: Fattori sismici | M33: Fattori sismici | O33: Fattori sismici | Q33: Fattori sismici | S33: Fattori sismici | U33: Fattori sismici | W33: Fattori sismici
E34: Kh | F34: =$B$25*$B$28 -> 0.23398448 | G34: Kh | H34: =$B$25*$B$28 -> 0.23398448 | I34: Kh | J34: =$B$25*$B$28 -> 0.23398448 | K34: Kh | L34: =$B$25*$B$28 -> 0.23398448 | M34: Kh | N34: =$B$25*$B$28 -> 0.23398448 | O34: Kh | P34: =$B$25*$B$28 -> 0.23398448 | Q34: Kh | R34: =$B$25*$B$28 -> 0.23398448 | S34: Kh | T34: =$B$25*$B$28 -> 0.23398448 | U34: Kh | V34: =$B$25*$B$28 -> 0.23398448 | W34: Kh | X34: =$B$25*$B$28 -> 0.23398448
E35: Kv | F35: =F34/2 -> 0.11699224 | G35: Kv | H35: =H34/2 -> 0.11699224 | I35: Kv | J35: =J34/2 -> 0.11699224 | K35: Kv | L35: =L34/2 -> 0.11699224 | M35: Kv | N35: =N34/2 -> 0.11699224 | O35: Kv | P35: =P34/2 -> 0.11699224 | Q35: Kv | R35: =R34/2 -> 0.11699224 | S35: Kv | T35: =T34/2 -> 0.11699224 | U35: Kv | V35: =V34/2 -> 0.11699224 | W35: Kv | X35: =X34/2 -> 0.11699224
E36: ẞs | F36: =0.24 -> 0.24 | G36: ẞs | H36: =0.24 -> 0.24 | I36: ẞs | J36: =0.24 -> 0.24 | K36: ẞs | L36: =0.24 -> 0.24 | M36: ẞs | N36: =0.24 -> 0.24 | O36: ẞs | P36: =0.24 -> 0.24 | Q36: ẞs | R36: =0.24 -> 0.24 | S36: ẞs | T36: =0.24 -> 0.24 | U36: ẞs | V36: =0.24 -> 0.24 | W36: ẞs | X36: =0.24 -> 0.24
E37: zq | F37: =(1-F34/F12)^(0.35) -> 0.86731816 | G37: zq | H37: =(1-H34/H12)^(0.35) -> 0.86731816 | I37: zq | J37: =(1-J34/J12)^(0.35) -> 0.86731816 | K37: zq | L37: =(1-L34/L12)^(0.35) -> 0.86731816 | M37: zq | N37: =(1-N34/N12)^(0.35) -> 0.86731816 | O37: zq | P37: =(1-P34/P12)^(0.35) -> 0.86731816 | Q37: zq | R37: =(1-R34/R12)^(0.35) -> 0.86731816 | S37: zq | T37: =(1-T34/T12)^(0.35) -> 0.86731816 | U37: zq | V37: =(1-V34/V12)^(0.35) -> 0.86731816 | W37: zq | X37: =(1-X34/X12)^(0.35) -> 0.86731816
E38: zc | F38: =(1-0.32*F34) -> 0.92512497 | G38: zc | H38: =(1-0.32*H34) -> 0.92512497 | I38: zc | J38: =(1-0.32*J34) -> 0.92512497 | K38: zc | L38: =(1-0.32*L34) -> 0.92512497 | M38: zc | N38: =(1-0.32*N34) -> 0.92512497 | O38: zc | P38: =(1-0.32*P34) -> 0.92512497 | Q38: zc | R38: =(1-0.32*R34) -> 0.92512497 | S38: zc | T38: =(1-0.32*T34) -> 0.92512497 | U38: zc | V38: =(1-0.32*V34) -> 0.92512497 | W38: zc | X38: =(1-0.32*X34) -> 0.92512497
E39: zY | F39: =F37 -> 0.86731816 | G39: zY | H39: =H37 -> 0.86731816 | I39: zY | J39: =J37 -> 0.86731816 | K39: zY | L39: =L37 -> 0.86731816 | M39: zY | N39: =N37 -> 0.86731816 | O39: zY | P39: =P37 -> 0.86731816 | Q39: zY | R39: =R37 -> 0.86731816 | S39: zY | T39: =T37 -> 0.86731816 | U39: zY | V39: =V37 -> 0.86731816 | W39: zY | X39: =X37 -> 0.86731816
E40: CAPACITA' PORTANTE | G40: CAPACITA' PORTANTE | I40: CAPACITA' PORTANTE | K40: CAPACITA' PORTANTE | M40: CAPACITA' PORTANTE | O40: CAPACITA' PORTANTE | Q40: CAPACITA' PORTANTE | S40: CAPACITA' PORTANTE | U40: CAPACITA' PORTANTE | W40: CAPACITA' PORTANTE
...
