Workbook

Sheet PILASTRI
A1: Sez. | B1: fyd | C1: fcd | D1: h | E1: db | F1: Lv | G1: Lpl (Circ) | H1: Lpl (EC8-A.9) | I1: NED | J1: φy | K1: φu | L1: θy (CIR) | M1: θu +(CIR) | N1: 5% θu + | O1: My+ | P1: Mu+ | Q1: 30% Mu +
A2: - | B2: N/mm2 | C2: N/mm2 | D2: mm | E2: mm | F2: mm | G2: mm | H2: mm | I2: KN | J2: mm-1 | K2: mm-1 | L2: rad | M2: rad | N2: rad | O2: KNm | P2: KNm | Q2: KNm
A3: 1 | B3: 391 | C3: 17 | D3: 500 | E3: 18 | F3: 1500 | G3: =0.1*F3+0.17*D3+0.24*(E3*B3/(SQRT(C3))) -> 644.67177 | H3: =F3/30+0.2*D3+0.24*(E3*B3/SQRT(C3)) -> 559.67177 | I3: ='Theta pilastri VCA'!B3 -> 0 | J3: ='Theta pilastri VCA'!F3 -> 6.1e-06 | K3: ='Theta pilastri VCA'!G3 -> 2.6109091e-05 | L3: =J3*F3/3+0.0013*(1+1.5*D3/F3)+0.13*J3*(E3*B3/SQRT(C3)) -> 0.0063536238 | M3: =1/1.5*(L3+(K3-J3)*G3*(1-0.5*G3/F3)) -> 0.010987322 | N3: =M3*5/100+M3 -> 0.011536688 | O3: ='Theta pilastri VCA'!H3 -> 246.2 | P3: ='Theta pilastri VCA'!I3 -> 328.9 | Q3: =30/100*P3 -> 98.67
B4: 391 | C4: 17 | D4: 500 | E4: 18 | F4: 1500 | G4: =0.1*F4+0.17*D4+0.24*(E4*B4/(SQRT(C4))) -> 644.67177 | H4: =F4/30+0.2*D4+0.24*(E4*B4/SQRT(C4)) -> 559.67177 | I4: ='Theta pilastri VCA'!B4 -> 400 | J4: ='Theta pilastri VCA'!F4 -> 7.0109091e-06 | K4: ='Theta pilastri VCA'!G4 -> 1.9309091e-05 | L4: =J4*F4/3+0.0013*(1+1.5*D4/F4)+0.13*J4*(E4*B4/SQRT(C4)) -> 0.0070112141 | M4: =1/1.5*(L4+(K4-J4)*G4*(1-0.5*G4/F4)) -> 0.0088238598 | N4: =M4*5/100+M4 -> 0.0092650528 | O4: ='Theta pilastri VCA'!H4 -> 309 | P4: ='Theta pilastri VCA'!I4 -> 372.6 | Q4: =30/100*P4 -> 111.78
B5: 391 | C5: 17 | D5: 500 | E5: 18 | F5: 1500 | G5: =0.1*F5+0.17*D5+0.24*(E5*B5/(SQRT(C5))) -> 644.67177 | H5: =F5/30+0.2*D5+0.24*(E5*B5/SQRT(C5)) -> 559.67177 | I5: ='Theta pilastri VCA'!B5 -> 600 | J5: ='Theta pilastri VCA'!F5 -> 7.4872727e-06 | K5: ='Theta pilastri VCA'!G5 -> 1.6647273e-05 | L5: =J5*F5/3+0.0013*(1+1.5*D5/F5)+0.13*J5*(E5*B5/SQRT(C5)) -> 0.0073551037 | M5: =1/1.5*(L5+(K5-J5)*G5*(1-0.5*G5/F5)) -> 0.0079942178 | N5: =M5*5/100+M5 -> 0.0083939286 | O5: ='Theta pilastri VCA'!H5 -> 337.6 | P5: ='Theta pilastri VCA'!I5 -> 392.1 | Q5: =30/100*P5 -> 117.63
B6: 391 | C6: 17 | D6: 500 | E6: 18 | F6: 1500 | G6: =0.1*F6+0.17*D6+0.24*(E6*B6/(SQRT(C6))) -> 644.67177 | H6: =F6/30+0.2*D6+0.24*(E6*B6/SQRT(C6)) -> 559.67177 | I6: ='Theta pilastri VCA'!B6 -> 700 | J6: ='Theta pilastri VCA'!F6 -> 7.7345455e-06 | K6: ='Theta pilastri VCA'!G6 -> 1.5503636e-05 | L6: =J6*F6/3+0.0013*(1+1.5*D6/F6)+0.13*J6*(E6*B6/SQRT(C6)) -> 0.0075336112 | M6: =1/1.5*(L6+(K6-J6)*G6*(1-0.5*G6/F6)) -> 0.0076438949 | N6: =M6*5/100+M6 -> 0.0080260897 | O6: ='Theta pilastri VCA'!H6 -> 351.1 | P6: ='Theta pilastri VCA'!I6 -> 400.6 | Q6: =30/100*P6 -> 120.18
B7: 391 | C7: 17 | D7: 500 | E7: 18 | F7: 1500 | G7: =0.1*F7+0.17*D7+0.24*(E7*B7/(SQRT(C7))) -> 644.67177 | H7: =F7/30+0.2*D7+0.24*(E7*B7/SQRT(C7)) -> 559.67177 | I7: ='Theta pilastri VCA'!B7 -> 900 | J7: ='Theta pilastri VCA'!F7 -> 8.2563636e-06 | K7: ='Theta pilastri VCA'!G7 -> 1.4165455e-05 | L7: =J7*F7/3+0.0013*(1+1.5*D7/F7)+0.13*J7*(E7*B7/SQRT(C7)) -> 0.0079103147 | M7: =1/1.5*(L7+(K7-J7)*G7*(1-0.5*G7/F7)) -> 0.0072674196 | N7: =M7*5/100+M7 -> 0.0076307906 | O7: ='Theta pilastri VCA'!H7 -> 376.6 | P7: ='Theta pilastri VCA'!I7 -> 405.1 | Q7: =30/100*P7 -> 121.53
B8: 391 | C8: 17 | D8: 500 | E8: 18 | F8: 1500 | G8: =0.1*F8+0.17*D8+0.24*(E8*B8/(SQRT(C8))) -> 644.67177 | H8: =F8/30+0.2*D8+0.24*(E8*B8/SQRT(C8)) -> 559.67177 | I8: ='Theta pilastri VCA'!B8 -> 1200 | J8: ='Theta pilastri VCA'!F8 -> 9.3690909e-06 | K8: ='Theta pilastri VCA'!G8 -> 1.236e-05 | L8: =J8*F8/3+0.0013*(1+1.5*D8/F8)+0.13*J8*(E8*B8/SQRT(C8)) -> 0.0087135987 | M8: =1/1.5*(L8+(K8-J8)*G8*(1-0.5*G8/F8)) -> 0.006818274 | N8: =M8*5/100+M8 -> 0.0071591877 | O8: ='Theta pilastri VCA'!H8 -> 400.7 | P8: ='Theta pilastri VCA'!I8 -> 410 | Q8: =30/100*P8 -> 123
B9: 391 | C9: 17 | D9: 500 | E9: 18 | F9: 1500 | G9: =0.1*F9+0.17*D9+0.24*(E9*B9/(SQRT(C9))) -> 644.67177 | H9: =F9/30+0.2*D9+0.24*(E9*B9/SQRT(C9)) -> 559.67177 | I9: ='Theta pilastri VCA'!B9 -> 1400 | J9: ='Theta pilastri VCA'!F9 -> 1.0590909e-05 | K9: ='Theta pilastri VCA'!G9 -> 1.104e-05 | L9: =J9*F9/3+0.0013*(1+1.5*D9/F9)+0.13*J9*(E9*B9/SQRT(C9)) -> 0.009595636 | M9: =1/1.5*(L9+(K9-J9)*G9*(1-0.5*G9/F9)) -> 0.0065486253 | N9: =M9*5/100+M9 -> 0.0068760565 | O9: ='Theta pilastri VCA'!H9 -> 410 | P9: ='Theta pilastri VCA'!I9 -> 411.2 | Q9: =30/100*P9 -> 123.36
A10: 2 | B10: 391 | C10: 17 | D10: 500 | E10: 18 | F10: 1500 | G10: =0.1*F10+0.17*D10+0.24*(E10*B10/(SQRT(C10))) -> 644.67177 | H10: =F10/30+0.2*D10+0.24*(E10*B10/SQRT(C10)) -> 559.67177 | I10: ='Theta pilastri VCA'!B10 -> 0 | J10: ='Theta pilastri VCA'!F10 -> 6.916e-06 | K10: ='Theta pilastri VCA'!G10 -> 2.748e-05 | L10: =J10*F10/3+0.0013*(1+1.5*D10/F10)+0.13*J10*(E10*B10/SQRT(C10)) -> 0.0069426987 | M10: =1/1.5*(L10+(K10-J10)*G10*(1-0.5*G10/F10)) -> 0.011567279 | N10: =M10*5/100+M10 -> 0.012145643 | O10: ='Theta pilastri VCA'!H10 -> 219.6 | P10: ='Theta pilastri VCA'!I10 -> 290.3 | Q10: =30/100*P10 -> 87.09
B11: 391 | C11: 17 | D11: 500 | E11: 18 | F11: 1500 | G11: =0.1*F11+0.17*D11+0.24*(E11*B11/(SQRT(C11))) -> 644.67177 | H11: =F11/30+0.2*D11+0.24*(E11*B11/SQRT(C11)) -> 559.67177 | I11: ='Theta pilastri VCA'!B11 -> 200 | J11: ='Theta pilastri VCA'!F11 -> 7.454e-06 | K11: ='Theta pilastri VCA'!G11 -> 2.348e-05 | L11: =J11*F11/3+0.0013*(1+1.5*D11/F11)+0.13*J11*(E11*B11/SQRT(C11)) -> 0.0073310839 | M11: =1/1.5*(L11+(K11-J11)*G11*(1-0.5*G11/F11)) -> 0.010294966 | N11: =M11*5/100+M11 -> 0.010809715 | O11: ='Theta pilastri VCA'!H11 -> 248.2 | P11: ='Theta pilastri VCA'!I11 -> 309.9 | Q11: =30/100*P11 -> 92.97
B12: 391 | C12: 17 | D12: 500 | E12: 18 | F12: 1500 | G12: =0.1*F12+0.17*D12+0.24*(E12*B12/(SQRT(C12))) -> 644.67177 | H12: =F12/30+0.2*D12+0.24*(E12*B12/SQRT(C12)) -> 559.67177 | I12: ='Theta pilastri VCA'!B12 -> 400 | J12: ='Theta pilastri VCA'!F12 -> 8e-06 | K12: ='Theta pilastri VCA'!G12 -> 2.006e-05 | L12: =J12*F12/3+0.0013*(1+1.5*D12/F12)+0.13*J12*(E12*B12/SQRT(C12)) -> 0.0077252444 | M12: =1/1.5*(L12+(K12-J12)*G12*(1-0.5*G12/F12)) -> 0.0092195114 | N12: =M12*5/100+M12 -> 0.009680487 | O12: ='Theta pilastri VCA'!H12 -> 275.2 | P12: ='Theta pilastri VCA'!I12 -> 328.5 | Q12: =30/100*P12 -> 98.55
B13: 391 | C13: 17 | D13: 500 | E13: 18 | F13: 1500 | G13: =0.1*F13+0.17*D13+0.24*(E13*B13/(SQRT(C13))) -> 644.67177 | H13: =F13/30+0.2*D13+0.24*(E13*B13/SQRT(C13)) -> 559.67177 | I13: ='Theta pilastri VCA'!B13 -> 600 | J13: ='Theta pilastri VCA'!F13 -> 8.582e-06 | K13: ='Theta pilastri VCA'!G13 -> 1.7186e-05 | L13: =J13*F13/3+0.0013*(1+1.5*D13/F13)+0.13*J13*(E13*B13/SQRT(C13)) -> 0.0081453934 | M13: =1/1.5*(L13+(K13-J13)*G13*(1-0.5*G13/F13)) -> 0.0083334691 | N13: =M13*5/100+M13 -> 0.0087501426 | O13: ='Theta pilastri VCA'!H13 -> 300.3 | P13: ='Theta pilastri VCA'!I13 -> 345.1 | Q13: =30/100*P13 -> 103.53
B14: 391 | C14: 17 | D14: 500 | E14: 18 | F14: 1500 | G14: =0.1*F14+0.17*D14+0.24*(E14*B14/(SQRT(C14))) -> 644.67177 | H14: =F14/30+0.2*D14+0.24*(E14*B14/SQRT(C14)) -> 559.67177 | I14: ='Theta pilastri VCA'!B14 -> 800 | J14: ='Theta pilastri VCA'!F14 -> 9.198e-06 | K14: ='Theta pilastri VCA'!G14 -> 1.5636e-05 | L14: =J14*F14/3+0.0013*(1+1.5*D14/F14)+0.13*J14*(E14*B14/SQRT(C14)) -> 0.0085900872 | M14: =1/1.5*(L14+(K14-J14)*G14*(1-0.5*G14/F14)) -> 0.0078990686 | N14: =M14*5/100+M14 -> 0.008294022 | O14: ='Theta pilastri VCA'!H14 -> 323.4 | P14: ='Theta pilastri VCA'!I14 -> 349 | Q14: =30/100*P14 -> 104.7
B15: 391 | C15: 17 | D15: 500 | E15: 18 | F15: 1500 | G15: =0.1*F15+0.17*D15+0.24*(E15*B15/(SQRT(C15))) -> 644.67177 | H15: =F15/30+0.2*D15+0.24*(E15*B15/SQRT(C15)) -> 559.67177 | I15: ='Theta pilastri VCA'!B15 -> 1000 | J15: ='Theta pilastri VCA'!F15 -> 9.984e-06 | K15: ='Theta pilastri VCA'!G15 -> 1.4216e-05 | L15: =J15*F15/3+0.0013*(1+1.5*D15/F15)+0.13*J15*(E15*B15/SQRT(C15)) -> 0.009157505 | M15: =1/1.5*(L15+(K15-J15)*G15*(1-0.5*G15/F15)) -> 0.007532987 | N15: =M15*5/100+M15 -> 0.0079096363 | O15: ='Theta pilastri VCA'!H15 -> 341 | P15: ='Theta pilastri VCA'!I15 -> 352.1 | Q15: =30/100*P15 -> 105.63
A16: 3 | B16: 391 | C16: 17 | D16: 500 | E16: 18 | F16: 1500 | G16: =0.1*F16+0.17*D16+0.24*(E16*B16/(SQRT(C16))) -> 644.67177 | H16: =F16/30+0.2*D16+0.24*(E16*B16/SQRT(C16)) -> 559.67177 | I16: ='Theta pilastri VCA'!B16 -> 0 | J16: ='Theta pilastri VCA'!F16 -> 7.9688889e-06 | K16: ='Theta pilastri VCA'!G16 -> 2.9088889e-05 | L16: =J16*F16/3+0.0013*(1+1.5*D16/F16)+0.13*J16*(E16*B16/SQRT(C16)) -> 0.0077027851 | M16: =1/1.5*(L16+(K16-J16)*G16*(1-0.5*G16/F16)) -> 0.012261611 | N16: =M16*5/100+M16 -> 0.012874692 | O16: ='Theta pilastri VCA'!H16 -> 193 | P16: ='Theta pilastri VCA'!I16 -> 252.5 | Q16: =30/100*P16 -> 75.75
B17: 391 | C17: 17 | D17: 500 | E17: 18 | F17: 1500 | G17: =0.1*F17+0.17*D17+0.24*(E17*B17/(SQRT(C17))) -> 644.67177 | H17: =F17/30+0.2*D17+0.24*(E17*B17/SQRT(C17)) -> 559.67177 | I17: ='Theta pilastri VCA'!B17 -> 200 | J17: ='Theta pilastri VCA'!F17 -> 8.6222222e-06 | K17: ='Theta pilastri VCA'!G17 -> 2.4688889e-05 | L17: =J17*F17/3+0.0013*(1+1.5*D17/F17)+0.13*J17*(E17*B17/SQRT(C17)) -> 0.00817443 | M17: =1/1.5*(L17+(K17-J17)*G17*(1-0.5*G17/F17)) -> 0.010870919 | N17: =M17*5/100+M17 -> 0.011414465 | O17: ='Theta pilastri VCA'!H17 -> 218 | P17: ='Theta pilastri VCA'!I17 -> 269.4 | Q17: =30/100*P17 -> 80.82
B18: 391 | C18: 17 | D18: 500 | E18: 18 | F18: 1500 | G18: =0.1*F18+0.17*D18+0.24*(E18*B18/(SQRT(C18))) -> 644.67177 | H18: =F18/30+0.2*D18+0.24*(E18*B18/SQRT(C18)) -> 559.67177 | I18: ='Theta pilastri VCA'!B18 -> 400 | J18: ='Theta pilastri VCA'!F18 -> 9.2977778e-06 | K18: ='Theta pilastri VCA'!G18 -> 2.0913333e-05 | L18: =J18*F18/3+0.0013*(1+1.5*D18/F18)+0.13*J18*(E18*B18/SQRT(C18)) -> 0.0086621173 | M18: =1/1.5*(L18+(K18-J18)*G18*(1-0.5*G18/F18)) -> 0.0096941266 | N18: =M18*5/100+M18 -> 0.010178833 | O18: ='Theta pilastri VCA'!H18 -> 241.5 | P18: ='Theta pilastri VCA'!I18 -> 285.2 | Q18: =30/100*P18 -> 85.56
B19: 391 | C19: 17 | D19: 500 | E19: 18 | F19: 1500 | G19: =0.1*F19+0.17*D19+0.24*(E19*B19/(SQRT(C19))) -> 644.67177 | H19: =F19/30+0.2*D19+0.24*(E19*B19/SQRT(C19)) -> 559.67177 | I19: ='Theta pilastri VCA'!B19 -> 600 | J19: ='Theta pilastri VCA'!F19 -> 1.0015556e-05 | K19: ='Theta pilastri VCA'!G19 -> 1.8317778e-05 | L19: =J19*F19/3+0.0013*(1+1.5*D19/F19)+0.13*J19*(E19*B19/SQRT(C19)) -> 0.0091802851 | M19: =1/1.5*(L19+(K19-J19)*G19*(1-0.5*G19/F19)) -> 0.0089215695 | N19: =M19*5/100+M19 -> 0.0093676479 | O19: ='Theta pilastri VCA'!H19 -> 263.1 | P19: ='Theta pilastri VCA'!I19 -> 294.4 | Q19: =30/100*P19 -> 88.32
B20: 391 | C20: 17 | D20: 500 | E20: 18 | F20: 1500 | G20: =0.1*F20+0.17*D20+0.24*(E20*B20/(SQRT(C20))) -> 644.67177 | H20: =F20/30+0.2*D20+0.24*(E20*B20/SQRT(C20)) -> 559.67177 | I20: ='Theta pilastri VCA'!B20 -> 800 | J20: ='Theta pilastri VCA'!F20 -> 1.0784444e-05 | K20: ='Theta pilastri VCA'!G20 -> 1.6593333e-05 | L20: =J20*F20/3+0.0013*(1+1.5*D20/F20)+0.13*J20*(E20*B20/SQRT(C20)) -> 0.0097353502 | M20: =1/1.5*(L20+(K20-J20)*G20*(1-0.5*G20/F20)) -> 0.0084502993 | N20: =M20*5/100+M20 -> 0.0088728142 | O20: ='Theta pilastri VCA'!H20 -> 283 | P20: ='Theta pilastri VCA'!I20 -> 297.2 | Q20: =30/100*P20 -> 89.16
A21: 4 | B21: 391 | C21: 17 | D21: 500 | E21: 18 | F21: 1500 | G21: =0.1*F21+0.17*D21+0.24*(E21*B21/(SQRT(C21))) -> 644.67177 | H21: =F21/30+0.2*D21+0.24*(E21*B21/SQRT(C21)) -> 559.67177 | I21: ='Theta pilastri VCA'!B21 -> 0 | J21: ='Theta pilastri VCA'!F21 -> 9.035e-06 | K21: ='Theta pilastri VCA'!G21 -> 3.3525e-05 | L21: =J21*F21/3+0.0013*(1+1.5*D21/F21)+0.13*J21*(E21*B21/SQRT(C21)) -> 0.0084724166 | M21: =1/1.5*(L21+(K21-J21)*G21*(1-0.5*G21/F21)) -> 0.013911822 | N21: =M21*5/100+M21 -> 0.014607413 | O21: ='Theta pilastri VCA'!H21 -> 140.6 | P21: ='Theta pilastri VCA'!I21 -> 185 | Q21: =30/100*P21 -> 55.5
B22: 391 | C22: 17 | D22: 500 | E22: 18 | F22: 1500 | G22: =0.1*F22+0.17*D22+0.24*(E22*B22/(SQRT(C22))) -> 644.67177 | H22: =F22/30+0.2*D22+0.24*(E22*B22/SQRT(C22)) -> 559.67177 | I22: ='Theta pilastri VCA'!B22 -> 100 | J22: ='Theta pilastri VCA'!F22 -> 9.47e-06 | K22: ='Theta pilastri VCA'!G22 -> 3.0475e-05 | L22: =J22*F22/3+0.0013*(1+1.5*D22/F22)+0.13*J22*(E22*B22/SQRT(C22)) -> 0.0087864455 | M22: =1/1.5*(L22+(K22-J22)*G22*(1-0.5*G22/F22)) -> 0.012945248 | N22: =M22*5/100+M22 -> 0.01359251 | O22: ='Theta pilastri VCA'!H22 -> 151.9 | P22: ='Theta pilastri VCA'!I22 -> 192.6 | Q22: =30/100*P22 -> 57.78
B23: 391 | C23: 17 | D23: 500 | E23: 18 | F23: 1500 | G23: =0.1*F23+0.17*D23+0.24*(E23*B23/(SQRT(C23))) -> 644.67177 | H23: =F23/30+0.2*D23+0.24*(E23*B23/SQRT(C23)) -> 559.67177 | I23: ='Theta pilastri VCA'!B23 -> 200 | J23: ='Theta pilastri VCA'!F23 -> 9.91e-06 | K23: ='Theta pilastri VCA'!G23 -> 2.7675e-05 | L23: =J23*F23/3+0.0013*(1+1.5*D23/F23)+0.13*J23*(E23*B23/SQRT(C23)) -> 0.0091040839 | M23: =1/1.5*(L23+(K23-J23)*G23*(1-0.5*G23/F23)) -> 0.012063749 | N23: =M23*5/100+M23 -> 0.012666936 | O23: ='Theta pilastri VCA'!H23 -> 162.7 | P23: ='Theta pilastri VCA'!I23 -> 200.1 | Q23: =30/100*P23 -> 60.03
B24: 391 | C24: 17 | D24: 500 | E24: 18 | F24: 1500 | G24: =0.1*F24+0.17*D24+0.24*(E24*B24/(SQRT(C24))) -> 644.67177 | H24: =F24/30+0.2*D24+0.24*(E24*B24/SQRT(C24)) -> 559.67177 | I24: ='Theta pilastri VCA'!B24 -> 300 | J24: ='Theta pilastri VCA'!F24 -> 1.03625e-05 | K24: ='Theta pilastri VCA'!G24 -> 2.515e-05 | L24: =J24*F24/3+0.0013*(1+1.5*D24/F24)+0.13*J24*(E24*B24/SQRT(C24)) -> 0.0094307462 | M24: =1/1.5*(L24+(K24-J24)*G24*(1-0.5*G24/F24)) -> 0.01127684 | N24: =M24*5/100+M24 -> 0.011840682 | O24: ='Theta pilastri VCA'!H24 -> 173.1 | P24: ='Theta pilastri VCA'!I24 -> 207.2 | Q24: =30/100*P24 -> 62.16

Sheet M-Theta pilastri per SAP
C1: A | D1: B | E1: C | F1: D | G1: E | I1: A | J1: B | K1: C | L1: D | M1: E
A2: 0 | B2: Mu/My | C2: 0 | D2: =PILASTRI!O3/PILASTRI!O3 -> 1 | E2: =PILASTRI!P3/PILASTRI!O3 -> 1.3359058 | F2: =PILASTRI!Q3/PILASTRI!O3 -> 0.40077173 | G2: =PILASTRI!Q3/PILASTRI!O3 -> 0.40077173
B3: θ | C3: 0 | D3: =PILASTRI!L3 -> 0.0063536238 | E3: =PILASTRI!M3 -> 0.010987322 | F3: =PILASTRI!M3 -> 0.010987322 | G3: =PILASTRI!N3 -> 0.011536688
A4: 400 | B4: Mu/My | C4: 0 | D4: =PILASTRI!O4/PILASTRI!O4 -> 1 | E4: =PILASTRI!P4/PILASTRI!O4 -> 1.2058252 | F4: =PILASTRI!Q4/PILASTRI!O4 -> 0.36174757 | G4: =PILASTRI!Q4/PILASTRI!O4 -> 0.36174757
B5: θ | C5: 0 | D5: =PILASTRI!L4 -> 0.0070112141 | E5: =PILASTRI!M4 -> 0.0088238598 | F5: =PILASTRI!M4 -> 0.0088238598 | G5: =PILASTRI!N4 -> 0.0092650528
A6: 600 | B6: Mu/My | C6: 0 | D6: =PILASTRI!O5/PILASTRI!O5 -> 1 | E6: =PILASTRI!P5/PILASTRI!O5 -> 1.1614336 | F6: =PILASTRI!Q5/PILASTRI!O5 -> 0.34843009 | G6: =PILASTRI!Q5/PILASTRI!O5 -> 0.34843009
B7: θ | C7: 0 | D7: =PILASTRI!L5 -> 0.0073551037 | E7: =PILASTRI!M5 -> 0.0079942178 | F7: =PILASTRI!M5 -> 0.0079942178 | G7: =PILASTRI!N5 -> 0.0083939286
A8: 700 | B8: Mu/My | C8: 0 | D8: =PILASTRI!O6/PILASTRI!O6 -> 1 | E8: =PILASTRI!P6/PILASTRI!O6 -> 1.1409855 | F8: =PILASTRI!Q6/PILASTRI!O6 -> 0.34229564 | G8: =PILASTRI!Q6/PILASTRI!O6 -> 0.34229564
B9: θ | C9: 0 | D9: =PILASTRI!L6 -> 0.0075336112 | E9: =PILASTRI!M6 -> 0.0076438949 | F9: =PILASTRI!M6 -> 0.0076438949 | G9: =PILASTRI!N6 -> 0.0080260897
A10: 900 | B10: Mu/My | C10: 0 | D10: =PILASTRI!O7/PILASTRI!O7 -> 1 | E10: =PILASTRI!P7/PILASTRI!O7 -> 1.0756771 | F10: =PILASTRI!Q7/PILASTRI!O7 -> 0.32270313 | G10: =PILASTRI!Q7/PILASTRI!O7 -> 0.32270313
B11: θ | C11: 0 | D11: =PILASTRI!L7 -> 0.0079103147 | E11: =PILASTRI!M7 -> 0.0072674196 | F11: =PILASTRI!M7 -> 0.0072674196 | G11: =PILASTRI!N7 -> 0.0076307906
A12: 1200 | B12: Mu/My | C12: 0 | D12: =PILASTRI!O8/PILASTRI!O8 -> 1 | E12: =PILASTRI!P8/PILASTRI!O8 -> 1.0232094 | F12: =PILASTRI!Q8/PILASTRI!O8 -> 0.30696282 | G12: =PILASTRI!Q8/PILASTRI!O8 -> 0.30696282
B13: θ | C13: 0 | D13: =PILASTRI!L8 -> 0.0087135987 | E13: =PILASTRI!M8 -> 0.006818274 | F13: =PILASTRI!M8 -> 0.006818274 | G13: =PILASTRI!N8 -> 0.0071591877
A14: 1400 | B14: Mu/My | C14: 0 | D14: =PILASTRI!O9/PILASTRI!O9 -> 1 | E14: =PILASTRI!P9/PILASTRI!O9 -> 1.0029268 | F14: =PILASTRI!Q9/PILASTRI!O9 -> 0.30087805 | G14: =PILASTRI!Q9/PILASTRI!O9 -> 0.30087805
B15: θ | C15: 0 | D15: =PILASTRI!L9 -> 0.009595636 | E15: =PILASTRI!M9 -> 0.0065486253 | F15: =PILASTRI!M9 -> 0.0065486253 | G15: =PILASTRI!N9 -> 0.0068760565
A16: 0 | B16: Mu/My | C16: 0 | D16: =PILASTRI!O10/PILASTRI!O10 -> 1 | E16: =PILASTRI!P10/PILASTRI!O10 -> 1.321949 | F16: =PILASTRI!Q10/PILASTRI!O10 -> 0.3965847 | G16: =PILASTRI!Q10/PILASTRI!O10 -> 0.3965847
B17: θ | C17: 0 | D17: =PILASTRI!L10 -> 0.0069426987 | E17: =PILASTRI!M10 -> 0.011567279 | F17: =PILASTRI!M10 -> 0.011567279 | G17: =PILASTRI!N10 -> 0.012145643
A18: 200 | B18: Mu/My | C18: 0 | D18: =PILASTRI!O11/PILASTRI!O11 -> 1 | E18: =PILASTRI!P11/PILASTRI!O11 -> 1.2485898 | F18: =PILASTRI!Q11/PILASTRI!O11 -> 0.37457695 | G18: =PILASTRI!Q11/PILASTRI!O11 -> 0.37457695
B19: θ | C19: 0 | D19: =PILASTRI!L11 -> 0.0073310839 | E19: =PILASTRI!M11 -> 0.010294966 | F19: =PILASTRI!M11 -> 0.010294966 | G19: =PILASTRI!N11 -> 0.010809715
A20: 400 | B20: Mu/My | C20: 0 | D20: =PILASTRI!O12/PILASTRI!O12 -> 1 | E20: =PILASTRI!P12/PILASTRI!O12 -> 1.1936773 | F20: =PILASTRI!Q12/PILASTRI!O12 -> 0.3581032 | G20: =PILASTRI!Q12/PILASTRI!O12 -> 0.3581032
B21: θ | C21: 0 | D21: =PILASTRI!L12 -> 0.0077252444 | E21: =PILASTRI!M12 -> 0.0092195114 | F21: =PILASTRI!M12 -> 0.0092195114 | G21: =PILASTRI!N12 -> 0.009680487
A22: 600 | B22: Mu/My | C22: 0 | D22: =PILASTRI!O13/PILASTRI!O13 -> 1 | E22: =PILASTRI!P13/PILASTRI!O13 -> 1.1491841 | F22: =PILASTRI!Q13/PILASTRI!O13 -> 0.34475524 | G22: =PILASTRI!Q13/PILASTRI!O13 -> 0.34475524
B23: θ | C23: 0 | D23: =PILASTRI!L13 -> 0.0081453934 | E23: =PILASTRI!M13 -> 0.0083334691 | F23: =PILASTRI!M13 -> 0.0083334691 | G23: =PILASTRI!N13 -> 0.0087501426
A24: 800 | B24: Mu/My | C24: 0 | D24: =PILASTRI!O14/PILASTRI!O14 -> 1 | E24: =PILASTRI!P14/PILASTRI!O14 -> 1.0791589 | F24: =PILASTRI!Q14/PILASTRI!O14 -> 0.32374768 | G24: =PILASTRI!Q14/PILASTRI!O14 -> 0.32374768
B25: θ | C25: 0 | D25: =PILASTRI!L14 -> 0.0085900872 | E25: =PILASTRI!M14 -> 0.0078990686 | F25: =PILASTRI!M14 -> 0.0078990686 | G25: =PILASTRI!N14 -> 0.008294022
A26: 1000 | B26: Mu/My | C26: 0 | D26: =PILASTRI!O15/PILASTRI!O15 -> 1 | E26: =PILASTRI!P15/PILASTRI!O15 -> 1.0325513 | F26: =PILASTRI!Q15/PILASTRI!O15 -> 0.3097654 | G26: =PILASTRI!Q15/PILASTRI!O15 -> 0.3097654
B27: θ | C27: 0 | D27: =PILASTRI!L15 -> 0.009157505 | E27: =PILASTRI!M15 -> 0.007532987 | F27: =PILASTRI!M15 -> 0.007532987 | G27: =PILASTRI!N15 -> 0.0079096363
A28: 0 | B28: Mu/My | C28: 0 | D28: =PILASTRI!O16/PILASTRI!O16 -> 1 | E28: =PILASTRI!P16/PILASTRI!O16 -> 1.3082902 | F28: =PILASTRI!Q16/PILASTRI!O16 -> 0.39248705 | G28: =PILASTRI!Q16/PILASTRI!O16 -> 0.39248705
B29: θ | C29: 0 | D29: =PILASTRI!L16 -> 0.0077027851 | E29: =PILASTRI!M16 -> 0.012261611 | F29: =PILASTRI!M16 -> 0.012261611 | G29: =PILASTRI!N16 -> 0.012874692
A30: 200 | B30: Mu/My | C30: 0 | D30: =PILASTRI!O17/PILASTRI!O17 -> 1 | E30: =PILASTRI!P17/PILASTRI!O17 -> 1.2357798 | F30: =PILASTRI!Q17/PILASTRI!O17 -> 0.37073394 | G30: =PILASTRI!Q17/PILASTRI!O17 -> 0.37073394
B31: θ | C31: 0 | D31: =PILASTRI!L17 -> 0.00817443 | E31: =PILASTRI!M17 -> 0.010870919 | F31: =PILASTRI!M17 -> 0.010870919 | G31: =PILASTRI!N17 -> 0.011414465
A32: 400 | B32: Mu/My | C32: 0 | D32: =PILASTRI!O18/PILASTRI!O18 -> 1 | E32: =PILASTRI!P18/PILASTRI!O18 -> 1.1809524 | F32: =PILASTRI!Q18/PILASTRI!O18 -> 0.35428571 | G32: =PILASTRI!Q18/PILASTRI!O18 -> 0.35428571
B33: θ | C33: 0 | D33: =PILASTRI!L18 -> 0.0086621173 | E33: =PILASTRI!M18 -> 0.0096941266 | F33: =PILASTRI!M18 -> 0.0096941266 | G33: =PILASTRI!N18 -> 0.010178833
A34: 600 | B34: Mu/My | C34: 0 | D34: =PILASTRI!O19/PILASTRI!O19 -> 1 | E34: =PILASTRI!P19/PILASTRI!O19 -> 1.1189662 | F34: =PILASTRI!Q19/PILASTRI!O19 -> 0.33568985 | G34: =PILASTRI!Q19/PILASTRI!O19 -> 0.33568985
B35: θ | C35: 0 | D35: =PILASTRI!L19 -> 0.0091802851 | E35: =PILASTRI!M19 -> 0.0089215695 | F35: =PILASTRI!M19 -> 0.0089215695 | G35: =PILASTRI!N19 -> 0.0093676479
A36: 800 | B36: Mu/My | C36: 0 | D36: =PILASTRI!O20/PILASTRI!O20 -> 1 | E36: =PILASTRI!P20/PILASTRI!O20 -> 1.0501767 | F36: =PILASTRI!Q20/PILASTRI!O20 -> 0.315053 | G36: =PILASTRI!Q20/PILASTRI!O20 -> 0.315053
B37: θ | C37: 0 | D37: =PILASTRI!L20 -> 0.0097353502 | E37: =PILASTRI!M20 -> 0.0084502993 | F37: =PILASTRI!M20 -> 0.0084502993 | G37: =PILASTRI!N20 -> 0.0088728142
A38: 0 | B38: Mu/My | C38: 0 | D38: =PILASTRI!O21/PILASTRI!O21 -> 1 | E38: =PILASTRI!P21/PILASTRI!O21 -> 1.3157895 | F38: =PILASTRI!Q21/PILASTRI!O21 -> 0.39473684 | G38: =PILASTRI!Q21/PILASTRI!O21 -> 0.39473684
B39: θ | C39: 0 | D39: =PILASTRI!L21 -> 0.0084724166 | E39: =PILASTRI!M21 -> 0.013911822 | F39: =PILASTRI!M21 -> 0.013911822 | G39: =PILASTRI!N21 -> 0.014607413
A40: 100 | B40: Mu/My | C40: 0 | D40: =PILASTRI!O22/PILASTRI!O22 -> 1 | E40: =PILASTRI!P22/PILASTRI!O22 -> 1.2679394 | F40: =PILASTRI!Q22/PILASTRI!O22 -> 0.38038183 | G40: =PILASTRI!Q22/PILASTRI!O22 -> 0.38038183
...

Sheet Theta pilastri VCA
A1: Sez. | B1: NED | C1: h | D1: φy*h | E1: φu*h | F1: φy | G1: φu | H1: My | I1: Mu
A2: - | B2: KN | C2: mm | D2: mm-1 | E2: mm-1 | F2: mm-1 | G2: mm-1 | H2: KNm | I2: KNm
A3: 1 | B3: 0 | C3: 550 | D3: 3.355 | E3: 14.36 | F3: =D3/($C$3*1000) -> 6.1e-06 | G3: =E3/($C$3*1000) -> 2.6109091e-05 | H3: 246.2 | I3: 328.9 | J3: =G3/F3 -> 4.2801788
B4: 400 | D4: 3.856 | E4: 10.62 | F4: =D4/($C$3*1000) -> 7.0109091e-06 | G4: =E4/($C$3*1000) -> 1.9309091e-05 | H4: 309 | I4: 372.6 | J4: =G4/F4 -> 2.7541494
B5: 600 | D5: 4.118 | E5: 9.156 | F5: =D5/($C$3*1000) -> 7.4872727e-06 | G5: =E5/($C$3*1000) -> 1.6647273e-05 | H5: 337.6 | I5: 392.1 | J5: =G5/F5 -> 2.2234094
B6: 700 | D6: 4.254 | E6: 8.527 | F6: =D6/($C$3*1000) -> 7.7345455e-06 | G6: =E6/($C$3*1000) -> 1.5503636e-05 | H6: 351.1 | I6: 400.6 | J6: =G6/F6 -> 2.0044664
B7: 900 | D7: 4.541 | E7: 7.791 | F7: =D7/($C$3*1000) -> 8.2563636e-06 | G7: =E7/($C$3*1000) -> 1.4165455e-05 | H7: 376.6 | I7: 405.1 | J7: =G7/F7 -> 1.7157014
B8: 1200 | D8: 5.153 | E8: 6.798 | F8: =D8/($C$3*1000) -> 9.3690909e-06 | G8: =E8/($C$3*1000) -> 1.236e-05 | H8: 400.7 | I8: 410 | J8: =G8/F8 -> 1.3192315
B9: 1400 | D9: 5.825 | E9: 6.072 | F9: =D9/($C$3*1000) -> 1.0590909e-05 | G9: =E9/($C$3*1000) -> 1.104e-05 | H9: 410 | I9: 411.2 | J9: =G9/F9 -> 1.0424034
A10: 2 | B10: 0 | C10: 500 | D10: 3.458 | E10: 13.74 | F10: =D10/($C$10*1000) -> 6.916e-06 | G10: =E10/($C$10*1000) -> 2.748e-05 | H10: 219.6 | I10: 290.3 | J10: =G10/F10 -> 3.973395
B11: 200 | D11: 3.727 | E11: 11.74 | F11: =D11/($C$10*1000) -> 7.454e-06 | G11: =E11/($C$10*1000) -> 2.348e-05 | H11: 248.2 | I11: 309.9 | J11: =G11/F11 -> 3.1499866
B12: 400 | D12: 4 | E12: 10.03 | F12: =D12/($C$10*1000) -> 8e-06 | G12: =E12/($C$10*1000) -> 2.006e-05 | H12: 275.2 | I12: 328.5 | J12: =G12/F12 -> 2.5075
B13: 600 | D13: 4.291 | E13: 8.593 | F13: =D13/($C$10*1000) -> 8.582e-06 | G13: =E13/($C$10*1000) -> 1.7186e-05 | H13: 300.3 | I13: 345.1 | J13: =G13/F13 -> 2.0025635
B14: 800 | D14: 4.599 | E14: 7.818 | F14: =D14/($C$10*1000) -> 9.198e-06 | G14: =E14/($C$10*1000) -> 1.5636e-05 | H14: 323.4 | I14: 349 | J14: =G14/F14 -> 1.6999348
B15: 1000 | D15: 4.992 | E15: 7.108 | F15: =D15/($C$10*1000) -> 9.984e-06 | G15: =E15/($C$10*1000) -> 1.4216e-05 | H15: 341 | I15: 352.1 | J15: =G15/F15 -> 1.4238782
A16: 3 | B16: 0 | C16: 450 | D16: 3.586 | E16: 13.09 | F16: =D16/($C$16*1000) -> 7.9688889e-06 | G16: =E16/($C$16*1000) -> 2.9088889e-05 | H16: 193 | I16: 252.5 | J16: =G16/F16 -> 3.6503067
B17: 200 | D17: 3.88 | E17: 11.11 | F17: =D17/($C$16*1000) -> 8.6222222e-06 | G17: =E17/($C$16*1000) -> 2.4688889e-05 | H17: 218 | I17: 269.4 | J17: =G17/F17 -> 2.8634021
B18: 400 | D18: 4.184 | E18: 9.411 | F18: =D18/($C$16*1000) -> 9.2977778e-06 | G18: =E18/($C$16*1000) -> 2.0913333e-05 | H18: 241.5 | I18: 285.2 | J18: =G18/F18 -> 2.249283
B19: 600 | D19: 4.507 | E19: 8.243 | F19: =D19/($C$16*1000) -> 1.0015556e-05 | G19: =E19/($C$16*1000) -> 1.8317778e-05 | H19: 263.1 | I19: 294.4 | J19: =G19/F19 -> 1.8289328
B20: 800 | D20: 4.853 | E20: 7.467 | F20: =D20/($C$16*1000) -> 1.0784444e-05 | G20: =E20/($C$16*1000) -> 1.6593333e-05 | H20: 283 | I20: 297.2 | J20: =G20/F20 -> 1.5386359
A21: 4 | B21: 0 | C21: 400 | D21: 3.614 | E21: 13.41 | F21: =D21/($C$21*1000) -> 9.035e-06 | G21: =E21/($C$21*1000) -> 3.3525e-05 | H21: 140.6 | I21: 185 | J21: =G21/F21 -> 3.71057
B22: 100 | D22: 3.788 | E22: 12.19 | F22: =D22/($C$21*1000) -> 9.47e-06 | G22: =E22/($C$21*1000) -> 3.0475e-05 | H22: 151.9 | I22: 192.6 | J22: =G22/F22 -> 3.218057
B23: 200 | D23: 3.964 | E23: 11.07 | F23: =D23/($C$21*1000) -> 9.91e-06 | G23: =E23/($C$21*1000) -> 2.7675e-05 | H23: 162.7 | I23: 200.1 | J23: =G23/F23 -> 2.7926337
B24: 300 | D24: 4.145 | E24: 10.06 | F24: =D24/($C$21*1000) -> 1.03625e-05 | G24: =E24/($C$21*1000) -> 2.515e-05 | H24: 173.1 | I24: 207.2 | J24: =G24/F24 -> 2.4270205

Sheet coeff alpha
A1: i | B1: bi [mm] | C1: bi2 [mm2]
A2: 1 | B2: 150 | C2: =B2^2 -> 22500
A3: 2 | B3: 160 | C3: =B3^2 -> 25600
A4: 3 | B4: 150 | C4: =B4^2 -> 22500
A5: 4 | B5: 150 | C5: =B5^2 -> 22500
A6: 5 | B6: 160 | C6: =B6^2 -> 25600
A7: 6 | B7: 150 | C7: =B7^2 -> 22500
A8: 7 | B8: 200 | C8: =B8^2 -> 40000
A9: 8 | B9: 200 | C9: =B9^2 -> 40000
C10: =SUM(C2:C9) -> 221200

Sheet verifica duttilità
C2: CALCOLO DELLA CAPACITA'
C4: sezione | D4: Nmax | E4: Ast | F4: Lst | G4: Alg | H4: Llg | I4: Vst | J4: s | K4: b | L4: h | M4: bo | N4: ho | O4: Vnc | P4: ωwd
D5: KN | E5: mm | F5: mm | G5: mm | H5: mm | I5: mm2 | J5: mm | K5: mm | L5: mm | M5: mm | N5: mm | O5: mm2 | P5: -
C6: 1 | D6: 520 | E6: =PI()*10^2/4 -> 78.539816 | F6: =2*(50+25+10)*10 -> 1700 | G6: =PI()*10^2/4 -> 78.539816 | H6: =45*10 -> 450 | I6: =E6*F6+2*G6*H6 -> 204203.52 | J6: 150 | K6: 300 | L6: 550 | M6: =(K6-25*2-10) -> 240 | N6: =(L6-25*2-10) -> 490 | O6: =M6*N6*J6 -> 17640000 | P6: =I6/O6*(391/17) -> 0.26625176
C7: 2 | D7: 562 | E7: =PI()*10^2/4 -> 78.539816 | F7: =2*(50+25+10)*10 -> 1700 | G7: =PI()*10^2/4 -> 78.539816 | H7: =45*10 -> 450 | I7: =E7*F7+2*G7*H7 -> 204203.52 | J7: 150 | K7: 300 | L7: 550 | M7: =(K7-25*2-10) -> 240 | N7: =(L7-25*2-10) -> 490 | O7: =M7*N7*J7 -> 17640000 | P7: =I7/O7*(391/17) -> 0.26625176
C8: 3 | D8: 648 | E8: =PI()*10^2/4 -> 78.539816 | F8: =2*(50+25+10)*10 -> 1700 | G8: =PI()*10^2/4 -> 78.539816 | H8: =45*10 -> 450 | I8: =E8*F8+2*G8*H8 -> 204203.52 | J8: 150 | K8: 300 | L8: 550 | M8: =(K8-25*2-10) -> 240 | N8: =(L8-25*2-10) -> 490 | O8: =M8*N8*J8 -> 17640000 | P8: =I8/O8*(391/17) -> 0.26625176
C9: 4 | D9: 660 | E9: =PI()*10^2/4 -> 78.539816 | F9: =2*(50+25+10)*10 -> 1700 | G9: =PI()*10^2/4 -> 78.539816 | H9: =45*10 -> 450 | I9: =E9*F9+2*G9*H9 -> 204203.52 | J9: 150 | K9: 300 | L9: 550 | M9: =(K9-25*2-10) -> 240 | N9: =(L9-25*2-10) -> 490 | O9: =M9*N9*J9 -> 17640000 | P9: =I9/O9*(391/17) -> 0.26625176
C10: 5 | D10: 521 | E10: =PI()*10^2/4 -> 78.539816 | F10: =2*(50+25+10)*10 -> 1700 | G10: =PI()*10^2/4 -> 78.539816 | H10: =45*10 -> 450 | I10: =E10*F10+2*G10*H10 -> 204203.52 | J10: 150 | K10: 300 | L10: 550 | M10: =(K10-25*2-10) -> 240 | N10: =(L10-25*2-10) -> 490 | O10: =M10*N10*J10 -> 17640000 | P10: =I10/O10*(391/17) -> 0.26625176
C11: 6 | D11: 590 | E11: =PI()*10^2/4 -> 78.539816 | F11: =2*(50+25+10)*10 -> 1700 | G11: =PI()*10^2/4 -> 78.539816 | H11: =45*10 -> 450 | I11: =E11*F11+2*G11*H11 -> 204203.52 | J11: 150 | K11: 300 | L11: 550 | M11: =(K11-25*2-10) -> 240 | N11: =(L11-25*2-10) -> 490 | O11: =M11*N11*J11 -> 17640000 | P11: =I11/O11*(391/17) -> 0.26625176
C12: 7 | D12: 765 | E12: =PI()*10^2/4 -> 78.539816 | F12: =2*(50+25+10)*10 -> 1700 | G12: =PI()*10^2/4 -> 78.539816 | H12: =45*10 -> 450 | I12: =E12*F12+2*G12*H12 -> 204203.52 | J12: 150 | K12: 300 | L12: 550 | M12: =(K12-25*2-10) -> 240 | N12: =(L12-25*2-10) -> 490 | O12: =M12*N12*J12 -> 17640000 | P12: =I12/O12*(391/17) -> 0.26625176
C13: 8 | D13: 850 | E13: =PI()*10^2/4 -> 78.539816 | F13: =2*(50+25+10)*10 -> 1700 | G13: =PI()*10^2/4 -> 78.539816 | H13: =45*10 -> 450 | I13: =E13*F13+2*G13*H13 -> 204203.52 | J13: 150 | K13: 300 | L13: 550 | M13: =(K13-25*2-10) -> 240 | N13: =(L13-25*2-10) -> 490 | O13: =M13*N13*J13 -> 17640000 | P13: =I13/O13*(391/17) -> 0.26625176
C14: 9 | D14: 850 | E14: =PI()*10^2/4 -> 78.539816 | F14: =2*(50+25+10)*10 -> 1700 | G14: =PI()*10^2/4 -> 78.539816 | H14: =45*10 -> 450 | I14: =E14*F14+2*G14*H14 -> 204203.52 | J14: 150 | K14: 300 | L14: 550 | M14: =(K14-25*2-10) -> 240 | N14: =(L14-25*2-10) -> 490 | O14: =M14*N14*J14 -> 17640000 | P14: =I14/O14*(391/17) -> 0.26625176
C15: 10 | D15: 595 | E15: =PI()*10^2/4 -> 78.539816 | F15: =2*(50+25+10)*10 -> 1700 | G15: =PI()*10^2/4 -> 78.539816 | H15: =45*10 -> 450 | I15: =E15*F15+2*G15*H15 -> 204203.52 | J15: 150 | K15: 300 | L15: 550 | M15: =(K15-25*2-10) -> 240 | N15: =(L15-25*2-10) -> 490 | O15: =M15*N15*J15 -> 17640000 | P15: =I15/O15*(391/17) -> 0.26625176
E17: CALCOLO DELLA DOMANDA
E19: sezione | F19: Nmax | G19: μφ | H19: νd | I19: εsy,d | J19: αn | K19: αs | L19: α | M19: ωwd,(min)
F20: KN | H20: -
E21: 1 | F21: 520 | G21: =6.28 -> 6.28 | H21: =D6*1000/(K6*L6*17) -> 0.18538324 | I21: =1.957/1000 -> 0.001957 | J21: =1-'coeff alpha'!$C$10/(6*'verifica duttilità'!M6*'verifica duttilità'!N6) -> 0.68650794 | K21: =(1-J6/(2*M6))*(1-J6/(2*N6)) -> 0.58227041 | L21: =J21*K21 -> 0.39973326 | M21: =(30*G21*H21*I21*K6/M6-0.035)/L21 -> 0.12617971 | N21: =IF(M21<P6,"SI","NO") -> SI
E22: 2 | F22: 562 | G22: =6.28 -> 6.28 | H22: =D7*1000/(K7*L7*17) -> 0.20035651 | I22: =1.957/1000 -> 0.001957 | J22: =1-'coeff alpha'!$C$10/(6*'verifica duttilità'!M7*'verifica duttilità'!N7) -> 0.68650794 | K22: =(1-J7/(2*M7))*(1-J7/(2*N7)) -> 0.58227041 | L22: =J22*K22 -> 0.39973326 | M22: =(30*G22*H22*I22*K7/M7-0.035)/L22 -> 0.14344317 | N22: =IF(M22<P7,"SI","NO") -> SI
E23: 3 | F23: 648 | G23: =6.28 -> 6.28 | H23: =D8*1000/(K8*L8*17) -> 0.23101604 | I23: =1.957/1000 -> 0.001957 | J23: =1-'coeff alpha'!$C$10/(6*'verifica duttilità'!M8*'verifica duttilità'!N8) -> 0.68650794 | K23: =(1-J8/(2*M8))*(1-J8/(2*N8)) -> 0.58227041 | L23: =J23*K23 -> 0.39973326 | M23: =(30*G23*H23*I23*K8/M8-0.035)/L23 -> 0.17879216 | N23: =IF(M23<P8,"SI","NO") -> SI
E24: 4 | F24: 660 | G24: =6.28 -> 6.28 | H24: =D9*1000/(K9*L9*17) -> 0.23529412 | I24: =1.957/1000 -> 0.001957 | J24: =1-'coeff alpha'!$C$10/(6*'verifica duttilità'!M9*'verifica duttilità'!N9) -> 0.68650794 | K24: =(1-J9/(2*M9))*(1-J9/(2*N9)) -> 0.58227041 | L24: =J24*K24 -> 0.39973326 | M24: =(30*G24*H24*I24*K9/M9-0.035)/L24 -> 0.18372458 | N24: =IF(M24<P9,"SI","NO") -> SI
E25: 5 | F25: 521 | G25: =6.28 -> 6.28 | H25: =D10*1000/(K10*L10*17) -> 0.18573975 | I25: =1.957/1000 -> 0.001957 | J25: =1-'coeff alpha'!$C$10/(6*'verifica duttilità'!M10*'verifica duttilità'!N10) -> 0.68650794 | K25: =(1-J10/(2*M10))*(1-J10/(2*N10)) -> 0.58227041 | L25: =J25*K25 -> 0.39973326 | M25: =(30*G25*H25*I25*K10/M10-0.035)/L25 -> 0.12659074 | N25: =IF(M25<P10,"SI","NO") -> SI
E26: 6 | F26: 590 | G26: =6.28 -> 6.28 | H26: =D11*1000/(K11*L11*17) -> 0.21033868 | I26: =1.957/1000 -> 0.001957 | J26: =1-'coeff alpha'!$C$10/(6*'verifica duttilità'!M11*'verifica duttilità'!N11) -> 0.68650794 | K26: =(1-J11/(2*M11))*(1-J11/(2*N11)) -> 0.58227041 | L26: =J26*K26 -> 0.39973326 | M26: =(30*G26*H26*I26*K11/M11-0.035)/L26 -> 0.15495214 | N26: =IF(M26<P11,"SI","NO") -> SI
E27: 7 | F27: 765 | G27: =6.28 -> 6.28 | H27: =D12*1000/(K12*L12*17) -> 0.27272727 | I27: =1.957/1000 -> 0.001957 | J27: =1-'coeff alpha'!$C$10/(6*'verifica duttilità'!M12*'verifica duttilità'!N12) -> 0.68650794 | K27: =(1-J12/(2*M12))*(1-J12/(2*N12)) -> 0.58227041 | L27: =J27*K27 -> 0.39973326 | M27: =(30*G27*H27*I27*K12/M12-0.035)/L27 -> 0.22688323 | N27: =IF(M27<P12,"SI","NO") -> SI
E28: 8 | F28: 850 | G28: =6.28 -> 6.28 | H28: =D13*1000/(K13*L13*17) -> 0.3030303 | I28: =1.957/1000 -> 0.001957 | J28: =1-'coeff alpha'!$C$10/(6*'verifica duttilità'!M13*'verifica duttilità'!N13) -> 0.68650794 | K28: =(1-J13/(2*M13))*(1-J13/(2*N13)) -> 0.58227041 | L28: =J28*K28 -> 0.39973326 | M28: =(30*G28*H28*I28*K13/M13-0.035)/L28 -> 0.26182119 | N28: =IF(M28<P13,"SI","NO") -> SI
E29: 9 | F29: 850 | G29: =6.28 -> 6.28 | H29: =D14*1000/(K14*L14*17) -> 0.3030303 | I29: =1.957/1000 -> 0.001957 | J29: =1-'coeff alpha'!$C$10/(6*'verifica duttilità'!M14*'verifica duttilità'!N14) -> 0.68650794 | K29: =(1-J14/(2*M14))*(1-J14/(2*N14)) -> 0.58227041 | L29: =J29*K29 -> 0.39973326 | M29: =(30*G29*H29*I29*K14/M14-0.035)/L29 -> 0.26182119 | N29: =IF(M29<P14,"SI","NO") -> SI
E30: 10 | F30: 595 | G30: =6.28 -> 6.28 | H30: =D15*1000/(K15*L15*17) -> 0.21212121 | I30: =1.957/1000 -> 0.001957 | J30: =1-'coeff alpha'!$C$10/(6*'verifica duttilità'!M15*'verifica duttilità'!N15) -> 0.68650794 | K30: =(1-J15/(2*M15))*(1-J15/(2*N15)) -> 0.58227041 | L30: =J30*K30 -> 0.39973326 | M30: =(30*G30*H30*I30*K15/M15-0.035)/L30 -> 0.15700732 | N30: =IF(M30<P15,"SI","NO") -> SI
A40: μφ
A41: -
A42: 2.45
A43: 2315
A44: 2114
A45: 2087
A46: 2418
A47: 2247
A48: 1906
A49: 1739
A50: 1739
A51: 2235

Sheet TRAVI
A1: Sez. | B1: fyd | C1: fcd | D1: h | E1: db | F1: Lv | G1: Lpl (Circ) | H1: Lpl (EC8-A.9) | I1: φy+ | J1: φu+ | K1: θy +(CIR) | L1: θy +(EC) | M1: θu +(CIR) | N1: θu +(EC) | O1: 5% θu + | P1: My+ | Q1: Mu+ | R1: 30% Mu + | S1: φy- | T1: φu- | U1: θy -(CIR) | V1: θy -(EC) | W1: θu -(CIR) | X1: θu -(EC) | Y1: 5% θu - | Z1: My- | AA1: Mu- | AB1: 30% Mu-
A2: - | B2: N/mm2 | C2: N/mm2 | D2: mm | E2: mm | F2: mm | G2: mm | H2: mm | I2: mm-1 | J2: mm-1 | K2: rad | L2: rad | M2: rad | N2: rad | O2: rad | P2: KNm | Q2: KNm | R2: KNm | S2: mm-1 | T2: mm-1 | U2: rad | V2: rad | W2: rad | X2: rad | Y2: rad | Z2: KNm | AA2: KNm | AB2: KNm
A3: 1 | B3: 391 | C3: 17 | D3: 500 | E3: 18 | F3: 1500 | G3: =0.1*F3+0.17*D3+0.24*(E3*B3/(SQRT(C3))) -> 644.67177 | H3: =F3/30+0.2*D3+0.24*(E3*B3/SQRT(C3)) -> 559.67177 | I3: ='Theta travi VCA'!E3 -> 5.658e-06 | J3: ='Theta travi VCA'!F3 -> 7.826e-05 | K3: =I3*F3/3+0.0013*(1+1.5*D3/F3)+0.13*I3*(E3*B3/SQRT(C3)) -> 0.0060345416 | L3: =I3*F3/3+0.0014*(1+1.5*D3/F3)+I3*E3*B3/(8*SQRT(17)) -> 0.0061362515 | M3: =1/1.5*(K3+(J3-I3)*G3*(1-0.5*G3/F3)) -> 0.028520776 | N3: =1/1.5*(L3+(J3-I3)*H3*(1-0.5*H3/F3)) -> 0.026126071 | O3: =M3*5/100+M3 -> 0.029946815 | P3: =83.06 -> 83.06 | Q3: 86.79 | R3: =30/100*Q3 -> 26.037 | S3: ='Theta travi VCA'!I3 -> 5.658e-06 | T3: ='Theta travi VCA'!J3 -> 7.826e-05 | U3: =S3*F3/3+0.0013*(1+1.5*D3/F3)+0.13*S3*(E3*B3/SQRT(C3)) -> 0.0060345416 | V3: =S3*F3/3+0.0014*(1+1.5*D3/F3)+S3*E3*B3/(8*SQRT(C3)) -> 0.0061362515 | W3: =1/1.5*(U3+(T3-S3)*G3*(1-0.5*G3/F3)) -> 0.028520776 | X3: =1/1.5*(V3+(T3-S3)*H3*(1-0.5*H3/F3)) -> 0.026126071 | Y3: =W3*5/100+W3 -> 0.029946815 | Z3: =83.06 -> 83.06 | AA3: 86.79 | AB3: =30/100*AA3 -> 26.037
A4: 2 | B4: 391 | C4: 17 | D4: 500 | E4: 18 | F4: 1500 | G4: =0.1*F4+0.17*D4+0.24*(E4*B4/(SQRT(C4))) -> 644.67177 | H4: =F4/30+0.2*D4+0.24*(E4*B4/SQRT(C4)) -> 559.67177 | I4: ='Theta travi VCA'!E4 -> 5.754e-06 | J4: ='Theta travi VCA'!F4 -> 7.412e-05 | K4: =I4*F4/3+0.0013*(1+1.5*D4/F4)+0.13*I4*(E4*B4/SQRT(C4)) -> 0.0061038445 | L4: =I4*F4/3+0.0014*(1+1.5*D4/F4)+I4*E4*B4/(8*SQRT(8)) -> 0.0067667161 | M4: =1/1.5*(K4+(J4-I4)*G4*(1-0.5*G4/F4)) -> 0.027137644 | N4: =1/1.5*(L4+(J4-I4)*H4*(1-0.5*H4/F4)) -> 0.025260724 | O4: =M4*5/100+M4 -> 0.028494527 | P4: 101.1 | Q4: 105.1 | R4: =30/100*Q4 -> 31.53 | S4: ='Theta travi VCA'!I4 -> 6.018e-06 | T4: ='Theta travi VCA'!J4 -> 6.638e-05 | U4: =S4*F4/3+0.0013*(1+1.5*D4/F4)+0.13*S4*(E4*B4/SQRT(C4)) -> 0.0062944276 | V4: =S4*F4/3+0.0014*(1+1.5*D4/F4)+S4*E4*B4/(8*SQRT(C4)) -> 0.006393065 | W4: =1/1.5*(U4+(T4-S4)*G4*(1-0.5*G4/F4)) -> 0.024563948 | X4: =1/1.5*(V4+(T4-S4)*H4*(1-0.5*H4/F4)) -> 0.022582351 | Y4: =W4*5/100+W4 -> 0.025792145 | Z4: 122.8 | AA4: 128 | AB4: =30/100*AA4 -> 38.4
A5: 3 | B5: 391 | C5: 17 | D5: 500 | E5: 18 | F5: 1500 | G5: =0.1*F5+0.17*D5+0.24*(E5*B5/(SQRT(C5))) -> 644.67177 | H5: =F5/30+0.2*D5+0.24*(E5*B5/SQRT(C5)) -> 559.67177 | I5: ='Theta travi VCA'!E5 -> 5.608e-06 | J5: ='Theta travi VCA'!F5 -> 7.878e-05 | K5: =I5*F5/3+0.0013*(1+1.5*D5/F5)+0.13*I5*(E5*B5/SQRT(C5)) -> 0.0059984463 | L5: =I5*F5/3+0.0014*(1+1.5*D5/F5)+I5*E5*B5/(8*SQRT(8)) -> 0.0066483044 | M5: =1/1.5*(K5+(J5-I5)*G5*(1-0.5*G5/F5)) -> 0.028689045 | N5: =1/1.5*(L5+(J5-I5)*H5*(1-0.5*H5/F5)) -> 0.026640439 | O5: =M5*5/100+M5 -> 0.030123497 | P5: 83.18 | Q5: 86.79 | R5: =30/100*Q5 -> 26.037 | S5: ='Theta travi VCA'!I5 -> 5.91e-06 | T5: ='Theta travi VCA'!J5 -> 6.966e-05 | U5: =S5*F5/3+0.0013*(1+1.5*D5/F5)+0.13*S5*(E5*B5/SQRT(C5)) -> 0.0062164618 | V5: =S5*F5/3+0.0014*(1+1.5*D5/F5)+S5*E5*B5/(8*SQRT(C5)) -> 0.0063160209 | W5: =1/1.5*(U5+(T5-S5)*G5*(1-0.5*G5/F5)) -> 0.025655168 | X5: =1/1.5*(V5+(T5-S5)*H5*(1-0.5*H5/F5)) -> 0.023559271 | Y5: =W5*5/100+W5 -> 0.026937926 | Z5: 107.1 | AA5: 111.8 | AB5: =30/100*AA5 -> 33.54
A6: 4 | B6: 391 | C6: 17 | D6: 500 | E6: 18 | F6: 1500 | G6: =0.1*F6+0.17*D6+0.24*(E6*B6/(SQRT(C6))) -> 644.67177 | H6: =F6/30+0.2*D6+0.24*(E6*B6/SQRT(C6)) -> 559.67177 | I6: ='Theta travi VCA'!E6 -> 6.164e-06 | J6: ='Theta travi VCA'!F6 -> 6.39e-05 | K6: =I6*F6/3+0.0013*(1+1.5*D6/F6)+0.13*I6*(E6*B6/SQRT(C6)) -> 0.0063998258 | L6: =I6*F6/3+0.0014*(1+1.5*D6/F6)+I6*E6*B6/(8*SQRT(8)) -> 0.0070992419 | M6: =1/1.5*(K6+(J6-I6)*G6*(1-0.5*G6/F6)) -> 0.023748135 | N6: =1/1.5*(L6+(J6-I6)*H6*(1-0.5*H6/F6)) -> 0.022256125 | O6: =M6*5/100+M6 -> 0.024935542 | P6: 163.1 | Q6: 169.2 | R6: =30/100*Q6 -> 50.76 | S6: ='Theta travi VCA'!I6 -> 6.368e-06 | T6: ='Theta travi VCA'!J6 -> 5.87e-05 | U6: =S6*F6/3+0.0013*(1+1.5*D6/F6)+0.13*S6*(E6*B6/SQRT(C6)) -> 0.0065470945 | V6: =S6*F6/3+0.0014*(1+1.5*D6/F6)+S6*E6*B6/(8*SQRT(C6)) -> 0.0066427447 | W6: =1/1.5*(U6+(T6-S6)*G6*(1-0.5*G6/F6)) -> 0.022022868 | X6: =1/1.5*(V6+(T6-S6)*H6*(1-0.5*H6/F6)) -> 0.02031164 | Y6: =W6*5/100+W6 -> 0.023124011 | Z6: 181.2 | AA6: 188.6 | AB6: =30/100*AA6 -> 56.58
A7: 5 | B7: 391 | C7: 17 | D7: 500 | E7: 18 | F7: 1500 | G7: =0.1*F7+0.17*D7+0.24*(E7*B7/(SQRT(C7))) -> 644.67177 | H7: =F7/30+0.2*D7+0.24*(E7*B7/SQRT(C7)) -> 559.67177 | I7: ='Theta travi VCA'!E7 -> 5.946e-06 | J7: ='Theta travi VCA'!F7 -> 6.89e-05 | K7: =I7*F7/3+0.0013*(1+1.5*D7/F7)+0.13*I7*(E7*B7/SQRT(C7)) -> 0.0062424504 | L7: =I7*F7/3+0.0014*(1+1.5*D7/F7)+I7*E7*B7/(8*SQRT(8)) -> 0.0069224355 | M7: =1/1.5*(K7+(J7-I7)*G7*(1-0.5*G7/F7)) -> 0.025403903 | N7: =1/1.5*(L7+(J7-I7)*H7*(1-0.5*H7/F7)) -> 0.023721955 | O7: =M7*5/100+M7 -> 0.026674098 | P7: 131.9 | Q7: 136.8 | R7: =30/100*Q7 -> 41.04 | S7: ='Theta travi VCA'!I7 -> 6.298e-06 | T7: ='Theta travi VCA'!J7 -> 5.944e-05 | U7: =S7*F7/3+0.0013*(1+1.5*D7/F7)+0.13*S7*(E7*B7/SQRT(C7)) -> 0.0064965611 | V7: =S7*F7/3+0.0014*(1+1.5*D7/F7)+S7*E7*B7/(8*SQRT(C7)) -> 0.0065928088 | W7: =1/1.5*(U7+(T7-S7)*G7*(1-0.5*G7/F7)) -> 0.022262493 | X7: =1/1.5*(V7+(T7-S7)*H7*(1-0.5*H7/F7)) -> 0.020524191 | Y7: =W7*5/100+W7 -> 0.023375618 | Z7: 162.2 | AA7: 169.1 | AB7: =30/100*AA7 -> 50.73
A8: 6
A9: 7
A10: 8
A11: 9
A12: 10 | B12: 391 | C12: 17 | D12: 500 | E12: 18 | F12: 1500 | G12: =0.1*F12+0.17*D12+0.24*(E12*B12/(SQRT(C12))) -> 644.67177 | H12: =F12/30+0.2*D12+0.24*(E12*B12/SQRT(C12)) -> 559.67177 | I12: ='Theta travi VCA'!E12 -> 5.512e-06 | J12: ='Theta travi VCA'!F12 -> 7.95e-05 | K12: =I12*F12/3+0.0013*(1+1.5*D12/F12)+0.13*I12*(E12*B12/SQRT(C12)) -> 0.0059291434 | L12: =I12*F12/3+0.0014*(1+1.5*D12/F12)+I12*E12*B12/(8*SQRT(8)) -> 0.0065704447 | M12: =1/1.5*(K12+(J12-I12)*G12*(1-0.5*G12/F12)) -> 0.028918182 | N12: =1/1.5*(L12+(J12-I12)*H12*(1-0.5*H12/F12)) -> 0.026836194 | O12: =M12*5/100+M12 -> 0.030364091 | P12: 83.36 | Q12: 86.78 | R12: =30/100*Q12 -> 26.034 | S12: ='Theta travi VCA'!I12 -> 6.454e-06 | T12: ='Theta travi VCA'!J12 -> 5.294e-05 | U12: =S12*F12/3+0.0013*(1+1.5*D12/F12)+0.13*S12*(E12*B12/SQRT(C12)) -> 0.0066091784 | V12: =S12*F12/3+0.0014*(1+1.5*D12/F12)+S12*E12*B12/(8*SQRT(C12)) -> 0.0067040946 | W12: =1/1.5*(U12+(T12-S12)*G12*(1-0.5*G12/F12)) -> 0.020091669 | X12: =1/1.5*(V12+(T12-S12)*H12*(1-0.5*H12/F12)) -> 0.018578237 | Y12: =W12*5/100+W12 -> 0.021096253 | Z12: 161.1 | AA12: 168.8 | AB12: =30/100*AA12 -> 50.64
A13: 11 | O13: =M13*5/100+M13 -> 0 | R13: =30/100*Q13 -> 0 | Y13: =W13*5/100+W13 -> 0 | AB13: =30/100*AA13 -> 0
A14: 12 | O14: =M14*5/100+M14 -> 0 | R14: =30/100*Q14 -> 0 | Y14: =W14*5/100+W14 -> 0 | AB14: =30/100*AA14 -> 0
A15: 13 | B15: 391 | C15: 17 | D15: 500 | E15: 18 | F15: 1500 | G15: =0.1*F15+0.17*D15+0.24*(E15*B15/(SQRT(C15))) -> 644.67177 | H15: =F15/30+0.2*D15+0.24*(E15*B15/SQRT(C15)) -> 559.67177 | I15: ='Theta travi VCA'!E15 -> 5.484e-06 | J15: ='Theta travi VCA'!F15 -> 7.966e-05 | K15: =I15*F15/3+0.0013*(1+1.5*D15/F15)+0.13*I15*(E15*B15/SQRT(C15)) -> 0.00590893 | L15: =I15*F15/3+0.0014*(1+1.5*D15/F15)+I15*E15*B15/(8*SQRT(8)) -> 0.0065477357 | M15: =1/1.5*(K15+(J15-I15)*G15*(1-0.5*G15/F15)) -> 0.028968142 | N15: =1/1.5*(L15+(J15-I15)*H15*(1-0.5*H15/F15)) -> 0.026878114 | O15: =M15*5/100+M15 -> 0.030416549 | P15: 83.41 | Q15: 86.77 | R15: =30/100*Q15 -> 26.031 | S15: ='Theta travi VCA'!I15 -> 6.632e-06 | T15: ='Theta travi VCA'!J15 -> 4.826e-05 | U15: =S15*F15/3+0.0013*(1+1.5*D15/F15)+0.13*S15*(E15*B15/SQRT(C15)) -> 0.0067376776 | V15: =S15*F15/3+0.0014*(1+1.5*D15/F15)+S15*E15*B15/(8*SQRT(C15)) -> 0.0068310746 | W15: =1/1.5*(U15+(T15-S15)*G15*(1-0.5*G15/F15)) -> 0.018538123 | X15: =1/1.5*(V15+(T15-S15)*H15*(1-0.5*H15/F15)) -> 0.017188451 | Y15: =W15*5/100+W15 -> 0.01946503 | Z15: 178.9 | AA15: 187.9 | AB15: =30/100*AA15 -> 56.37
A16: 14 | O16: =M16*5/100+M16 -> 0 | R16: =30/100*Q16 -> 0 | Y16: =W16*5/100+W16 -> 0 | AB16: =30/100*AA16 -> 0
A17: 15 | B17: 391 | C17: 17 | D17: 500 | E17: 18 | F17: 1500 | G17: =0.1*F17+0.17*D17+0.24*(E17*B17/(SQRT(C17))) -> 644.67177 | H17: =F17/30+0.2*D17+0.24*(E17*B17/SQRT(C17)) -> 559.67177 | I17: ='Theta travi VCA'!E17 -> 5.532e-06 | J17: ='Theta travi VCA'!F17 -> 7.936e-05 | K17: =I17*F17/3+0.0013*(1+1.5*D17/F17)+0.13*I17*(E17*B17/SQRT(C17)) -> 0.0059435815 | L17: =I17*F17/3+0.0014*(1+1.5*D17/F17)+I17*E17*B17/(8*SQRT(8)) -> 0.0065866655 | M17: =1/1.5*(K17+(J17-I17)*G17*(1-0.5*G17/F17)) -> 0.028873819 | N17: =1/1.5*(L17+(J17-I17)*H17*(1-0.5*H17/F17)) -> 0.026798447 | O17: =M17*5/100+M17 -> 0.03031751 | P17: 83.33 | Q17: 86.78 | R17: =30/100*Q17 -> 26.034 | S17: ='Theta travi VCA'!I17 -> 6.332e-06 | T17: ='Theta travi VCA'!J17 -> 5.634e-05 | U17: =S17*F17/3+0.0013*(1+1.5*D17/F17)+0.13*S17*(E17*B17/SQRT(C17)) -> 0.0065211059 | V17: =S17*F17/3+0.0014*(1+1.5*D17/F17)+S17*E17*B17/(8*SQRT(C17)) -> 0.0066170634 | W17: =1/1.5*(U17+(T17-S17)*G17*(1-0.5*G17/F17)) -> 0.021221366 | X17: =1/1.5*(V17+(T17-S17)*H17*(1-0.5*H17/F17)) -> 0.019589168 | Y17: =W17*5/100+W17 -> 0.022282434 | Z17: 149 | AA17: 156 | AB17: =30/100*AA17 -> 46.8
A18: 16 | O18: =M18*5/100+M18 -> 0 | R18: =30/100*Q18 -> 0 | Y18: =W18*5/100+W18 -> 0 | AB18: =30/100*AA18 -> 0
A19: 17 | B19: 391 | C19: 17 | D19: 500 | E19: 18 | F19: 1500 | G19: =0.1*F19+0.17*D19+0.24*(E19*B19/(SQRT(C19))) -> 644.67177 | H19: =F19/30+0.2*D19+0.24*(E19*B19/SQRT(C19)) -> 559.67177 | I19: ='Theta travi VCA'!E19 -> 5.456e-06 | J19: ='Theta travi VCA'!F19 -> 7.98e-05 | K19: =I19*F19/3+0.0013*(1+1.5*D19/F19)+0.13*I19*(E19*B19/SQRT(C19)) -> 0.0058887167 | L19: =I19*F19/3+0.0014*(1+1.5*D19/F19)+I19*E19*B19/(8*SQRT(8)) -> 0.0065250266 | M19: =1/1.5*(K19+(J19-I19)*G19*(1-0.5*G19/F19)) -> 0.029011354 | N19: =1/1.5*(L19+(J19-I19)*H19*(1-0.5*H19/F19)) -> 0.026913964 | O19: =M19*5/100+M19 -> 0.030461922 | P19: 83.44 | Q19: 86.77 | R19: =30/100*Q19 -> 26.031 | S19: ='Theta travi VCA'!I19 -> 6.81e-06 | T19: ='Theta travi VCA'!J19 -> 4.404e-05 | U19: =S19*F19/3+0.0013*(1+1.5*D19/F19)+0.13*S19*(E19*B19/SQRT(C19)) -> 0.0068661768 | V19: =S19*F19/3+0.0014*(1+1.5*D19/F19)+S19*E19*B19/(8*SQRT(C19)) -> 0.0069580546 | W19: =1/1.5*(U19+(T19-S19)*G19*(1-0.5*G19/F19)) -> 0.017139793 | X19: =1/1.5*(V19+(T19-S19)*H19*(1-0.5*H19/F19)) -> 0.01593828 | Y19: =W19*5/100+W19 -> 0.017996783 | Z19: 196.6 | AA19: 206.7 | AB19: =30/100*AA19 -> 62.01

Sheet M-Theta travi per SAP
A1: SEZ | C1: E- | D1: D- | E1: C- | F1: B- | G1: A | H1: B | I1: C | J1: D | K1: E | O1: E- | P1: D- | Q1: C- | R1: B- | S1: A | T1: B | U1: C | V1: D | W1: E
A2: 1 | B2: M | C2: =-TRAVI!AB3 -> -26.037 | D2: =-TRAVI!AB3 -> -26.037 | E2: =-TRAVI!AA3 -> -86.79 | F2: =-TRAVI!Z3 -> -83.06 | G2: 0 | H2: =TRAVI!P3 -> 83.06 | I2: =TRAVI!Q3 -> 86.79 | J2: =TRAVI!R3 -> 26.037 | K2: =TRAVI!R3 -> 26.037
B3: θ | C3: =-TRAVI!Y3 -> -0.029946815 | D3: =-TRAVI!W3 -> -0.028520776 | E3: =-TRAVI!W3 -> -0.028520776 | F3: =-TRAVI!U3 -> -0.0060345416 | G3: 0 | H3: =TRAVI!K3 -> 0.0060345416 | I3: =TRAVI!M3 -> 0.028520776 | J3: =TRAVI!M3 -> 0.028520776 | K3: =TRAVI!O3 -> 0.029946815
A4: 2 | B4: M | C4: =-TRAVI!AB4 -> -38.4 | D4: =-TRAVI!AB4 -> -38.4 | E4: =-TRAVI!AA4 -> -128 | F4: =-TRAVI!Z4 -> -122.8 | G4: 0 | H4: =TRAVI!P4 -> 101.1 | I4: =TRAVI!Q4 -> 105.1 | J4: =TRAVI!R4 -> 31.53 | K4: =TRAVI!R4 -> 31.53
B5: θ | C5: =-TRAVI!Y4 -> -0.025792145 | D5: =-TRAVI!W4 -> -0.024563948 | E5: =-TRAVI!W4 -> -0.024563948 | F5: =-TRAVI!U4 -> -0.0062944276 | G5: 0 | H5: =TRAVI!K4 -> 0.0061038445 | I5: =TRAVI!M4 -> 0.027137644 | J5: =TRAVI!M4 -> 0.027137644 | K5: =TRAVI!O4 -> 0.028494527
A6: 3 | B6: M | C6: =-TRAVI!AB5 -> -33.54 | D6: =-TRAVI!AB5 -> -33.54 | E6: =-TRAVI!AA5 -> -111.8 | F6: =-TRAVI!Z5 -> -107.1 | G6: 0 | H6: =TRAVI!P5 -> 83.18 | I6: =TRAVI!Q5 -> 86.79 | J6: =TRAVI!R5 -> 26.037 | K6: =TRAVI!R5 -> 26.037
B7: θ | C7: =-TRAVI!Y5 -> -0.026937926 | D7: =-TRAVI!W5 -> -0.025655168 | E7: =-TRAVI!W5 -> -0.025655168 | F7: =-TRAVI!U5 -> -0.0062164618 | G7: 0 | H7: =TRAVI!K5 -> 0.0059984463 | I7: =TRAVI!M5 -> 0.028689045 | J7: =TRAVI!M5 -> 0.028689045 | K7: =TRAVI!O5 -> 0.030123497
A8: 4 | B8: M | C8: =-TRAVI!AB6 -> -56.58 | D8: =-TRAVI!AB6 -> -56.58 | E8: =-TRAVI!AA6 -> -188.6 | F8: =-TRAVI!Z6 -> -181.2 | G8: 0 | H8: =TRAVI!P6 -> 163.1 | I8: =TRAVI!Q6 -> 169.2 | J8: =TRAVI!R6 -> 50.76 | K8: =TRAVI!R6 -> 50.76
B9: θ | C9: =-TRAVI!Y6 -> -0.023124011 | D9: =-TRAVI!W6 -> -0.022022868 | E9: =-TRAVI!W6 -> -0.022022868 | F9: =-TRAVI!U6 -> -0.0065470945 | G9: 0 | H9: =TRAVI!K6 -> 0.0063998258 | I9: =TRAVI!M6 -> 0.023748135 | J9: =TRAVI!M6 -> 0.023748135 | K9: =TRAVI!O6 -> 0.024935542
A10: 5 | B10: M | C10: =-TRAVI!AB7 -> -50.73 | D10: =-TRAVI!AB7 -> -50.73 | E10: =-TRAVI!AA7 -> -169.1 | F10: =-TRAVI!Z7 -> -162.2 | G10: 0 | H10: =TRAVI!P7 -> 131.9 | I10: =TRAVI!Q7 -> 136.8 | J10: =TRAVI!R7 -> 41.04 | K10: =TRAVI!R7 -> 41.04
B11: θ | C11: =-TRAVI!Y7 -> -0.023375618 | D11: =-TRAVI!W7 -> -0.022262493 | E11: =-TRAVI!W7 -> -0.022262493 | F11: =-TRAVI!U7 -> -0.0064965611 | G11: 0 | H11: =TRAVI!K7 -> 0.0062424504 | I11: =TRAVI!M7 -> 0.025403903 | J11: =TRAVI!M7 -> 0.025403903 | K11: =TRAVI!O7 -> 0.026674098
A12: 10 | B12: M | C12: =-TRAVI!AB12 -> -50.64 | D12: =-TRAVI!AB12 -> -50.64 | E12: =-TRAVI!AA12 -> -168.8 | F12: =-TRAVI!Z12 -> -161.1 | G12: 0 | H12: =TRAVI!P12 -> 83.36 | I12: =TRAVI!Q12 -> 86.78 | J12: =TRAVI!R12 -> 26.034 | K12: =TRAVI!R12 -> 26.034
B13: θ | C13: =-TRAVI!Y12 -> -0.021096253 | D13: =-TRAVI!W12 -> -0.020091669 | E13: =-TRAVI!W12 -> -0.020091669 | F13: =-TRAVI!U12 -> -0.0066091784 | G13: 0 | H13: =TRAVI!K12 -> 0.0059291434 | I13: =TRAVI!M12 -> 0.028918182 | J13: =TRAVI!M12 -> 0.028918182 | K13: =TRAVI!O12 -> 0.030364091
A14: 13 | B14: M | C14: =-TRAVI!AB15 -> -56.37 | D14: =-TRAVI!AB15 -> -56.37 | E14: =-TRAVI!AA15 -> -187.9 | F14: =-TRAVI!Z15 -> -178.9 | G14: 0 | H14: =TRAVI!P15 -> 83.41 | I14: =TRAVI!Q15 -> 86.77 | J14: =TRAVI!R15 -> 26.031 | K14: =TRAVI!R15 -> 26.031
B15: θ | C15: =-TRAVI!Y15 -> -0.01946503 | D15: =-TRAVI!W15 -> -0.018538123 | E15: =-TRAVI!W15 -> -0.018538123 | F15: =-TRAVI!U15 -> -0.0067376776 | G15: 0 | H15: =TRAVI!K15 -> 0.00590893 | I15: =TRAVI!M15 -> 0.028968142 | J15: =TRAVI!M15 -> 0.028968142 | K15: =TRAVI!O15 -> 0.030416549
A16: 15 | B16: M | C16: =-TRAVI!AB17 -> -46.8 | D16: =-TRAVI!AB17 -> -46.8 | E16: =-TRAVI!AA17 -> -156 | F16: =-TRAVI!Z17 -> -149 | G16: 0 | H16: =TRAVI!P17 -> 83.33 | I16: =TRAVI!Q17 -> 86.78 | J16: =TRAVI!R17 -> 26.034 | K16: =TRAVI!R17 -> 26.034
B17: θ | C17: =-TRAVI!Y17 -> -0.022282434 | D17: =-TRAVI!W17 -> -0.021221366 | E17: =-TRAVI!W17 -> -0.021221366 | F17: =-TRAVI!U17 -> -0.0065211059 | G17: 0 | H17: =TRAVI!K17 -> 0.0059435815 | I17: =TRAVI!M17 -> 0.028873819 | J17: =TRAVI!M17 -> 0.028873819 | K17: =TRAVI!O17 -> 0.03031751
A18: 17 | B18: M | C18: =-TRAVI!AB19 -> -62.01 | D18: =-TRAVI!AB19 -> -62.01 | E18: =-TRAVI!AA19 -> -206.7 | F18: =-TRAVI!Z19 -> -196.6 | G18: 0 | H18: =TRAVI!P19 -> 83.44 | I18: =TRAVI!Q19 -> 86.77 | J18: =TRAVI!R19 -> 26.031 | K18: =TRAVI!R19 -> 26.031
B19: θ | C19: =-TRAVI!Y19 -> -0.017996783 | D19: =-TRAVI!W19 -> -0.017139793 | E19: =-TRAVI!W19 -> -0.017139793 | F19: =-TRAVI!U19 -> -0.0068661768 | G19: 0 | H19: =TRAVI!K19 -> 0.0058887167 | I19: =TRAVI!M19 -> 0.029011354 | J19: =TRAVI!M19 -> 0.029011354 | K19: =TRAVI!O19 -> 0.030461922
B22: SEZ 1 | D22: SEZ 2 | F22: SEZ 3 | H22: SEZ 4 | J22: SEZ 5 | L22: SEZ 10 | N22: SEZ 13 | P22: SEZ 15 | R22: SEZ 17
B23: M | C23: θ | D23: M | E23: θ | F23: M | G23: θ | H23: M | I23: θ | J23: M | K23: θ | L23: M | M23: θ | N23: M | O23: θ | P23: M | Q23: θ | R23: M | S23: θ | AF23: 1 | AG23: 1 | AH23: 1 | AI23: 1 | AJ23: 1 | AK23: 1 | AL23: 1 | AM23: 1 | AN23: 1 | AO23: 1
A24: E- | B24: -26.037 | C24: -0.029946815 | D24: -38.4 | E24: -0.025792145 | F24: -33.54 | G24: -0.026937926 | H24: -56.58 | I24: -0.023124011 | J24: -50.73 | K24: -0.023375618 | L24: -50.64 | M24: -0.021096253 | N24: -56.37 | O24: -0.01946503 | P24: -46.8 | Q24: -0.022282434 | R24: -62.01 | S24: -0.017996783
A25: D- | B25: -26.037 | C25: -0.028520776 | D25: -38.4 | E25: -0.024563948 | F25: -33.54 | G25: -0.025655168 | H25: -56.58 | I25: -0.022022868 | J25: -50.73 | K25: -0.022262493 | L25: -50.64 | M25: -0.020091669 | N25: -56.37 | O25: -0.018538123 | P25: -46.8 | Q25: -0.021221366 | R25: -62.01 | S25: -0.017139793
A26: C- | B26: -86.79 | C26: -0.028520776 | D26: -128 | E26: -0.024563948 | F26: -111.8 | G26: -0.025655168 | H26: -188.6 | I26: -0.022022868 | J26: -169.1 | K26: -0.022262493 | L26: -168.8 | M26: -0.020091669 | N26: -187.9 | O26: -0.018538123 | P26: -156 | Q26: -0.021221366 | R26: -206.7 | S26: -0.017139793
A27: B- | B27: -83.06 | C27: -0.0060345416 | D27: -122.8 | E27: -0.0062944276 | F27: -107.1 | G27: -0.0062164618 | H27: -181.2 | I27: -0.0065470945 | J27: -162.2 | K27: -0.0064965611 | L27: -161.1 | M27: -0.0066091784 | N27: -178.9 | O27: -0.0067376776 | P27: -149 | Q27: -0.0065211059 | R27: -196.6 | S27: -0.0068661768
A28: A | B28: 0 | C28: 0 | D28: 0 | E28: 0 | F28: 0 | G28: 0 | H28: 0 | I28: 0 | J28: 0 | K28: 0 | L28: 0 | M28: 0 | N28: 0 | O28: 0 | P28: 0 | Q28: 0 | R28: 0 | S28: 0
A29: B | B29: 83.06 | C29: 0.0060345416 | D29: 101.1 | E29: 0.0061038445 | F29: 83.18 | G29: 0.0059984463 | H29: 163.1 | I29: 0.0063998258 | J29: 131.9 | K29: 0.0062424504 | L29: 83.36 | M29: 0.0059291434 | N29: 83.41 | O29: 0.00590893 | P29: 83.33 | Q29: 0.0059435815 | R29: 83.44 | S29: 0.0058887167
A30: C | B30: 86.79 | C30: 0.028520776 | D30: 105.1 | E30: 0.027137644 | F30: 86.79 | G30: 0.028689045 | H30: 169.2 | I30: 0.023748135 | J30: 136.8 | K30: 0.025403903 | L30: 86.78 | M30: 0.028918182 | N30: 86.77 | O30: 0.028968142 | P30: 86.78 | Q30: 0.028873819 | R30: 86.77 | S30: 0.029011354
A31: D | B31: 26.037 | C31: 0.028520776 | D31: 31.53 | E31: 0.027137644 | F31: 26.037 | G31: 0.028689045 | H31: 50.76 | I31: 0.023748135 | J31: 41.04 | K31: 0.025403903 | L31: 26.034 | M31: 0.028918182 | N31: 26.031 | O31: 0.028968142 | P31: 26.034 | Q31: 0.028873819 | R31: 26.031 | S31: 0.029011354
A32: E | B32: 26.037 | C32: 0.029946815 | D32: 31.53 | E32: 0.028494527 | F32: 26.037 | G32: 0.030123497 | H32: 50.76 | I32: 0.024935542 | J32: 41.04 | K32: 0.026674098 | L32: 26.034 | M32: 0.030364091 | N32: 26.031 | O32: 0.030416549 | P32: 26.034 | Q32: 0.03031751 | R32: 26.031 | S32: 0.030461922
A35: M | B35: -26.037 | C35: -26.037 | D35: -86.79 | E35: -83.06 | F35: 0 | G35: 83.06 | H35: 86.79 | I35: 26.037 | J35: 26.037
A36: θ | B36: -0.029946815 | C36: -0.028520776 | D36: -0.028520776 | E36: -0.0060345416 | F36: 0 | G36: 0.0060345416 | H36: 0.028520776 | I36: 0.028520776 | J36: 0.029946815
A37: M | B37: -38.4 | C37: -38.4 | D37: -128 | E37: -122.8 | F37: 0 | G37: 101.1 | H37: 105.1 | I37: 31.53 | J37: 31.53
A38: θ | B38: -0.025792145 | C38: -0.024563948 | D38: -0.024563948 | E38: -0.0062944276 | F38: 0 | G38: 0.0061038445 | H38: 0.027137644 | I38: 0.027137644 | J38: 0.028494527
A39: M | B39: -33.54 | C39: -33.54 | D39: -111.8 | E39: -107.1 | F39: 0 | G39: 83.18 | H39: 86.79 | I39: 26.037 | J39: 26.037
A40: θ | B40: -0.026937926 | C40: -0.025655168 | D40: -0.025655168 | E40: -0.0062164618 | F40: 0 | G40: 0.0059984463 | H40: 0.028689045 | I40: 0.028689045 | J40: 0.030123497
A41: M | B41: -56.58 | C41: -56.58 | D41: -188.6 | E41: -181.2 | F41: 0 | G41: 163.1 | H41: 169.2 | I41: 50.76 | J41: 50.76
A42: θ | B42: -0.023124011 | C42: -0.022022868 | D42: -0.022022868 | E42: -0.0065470945 | F42: 0 | G42: 0.0063998258 | H42: 0.023748135 | I42: 0.023748135 | J42: 0.024935542
A43: M | B43: -50.73 | C43: -50.73 | D43: -169.1 | E43: -162.2 | F43: 0 | G43: 131.9 | H43: 136.8 | I43: 41.04 | J43: 41.04
A44: θ | B44: -0.023375618 | C44: -0.022262493 | D44: -0.022262493 | E44: -0.0064965611 | F44: 0 | G44: 0.0062424504 | H44: 0.025403903 | I44: 0.025403903 | J44: 0.026674098
...

Sheet Theta travi VCA
A1: Sez. | B1: h | C1: φy*h+ | D1: φu*h+ | E1: φy+ | F1: φu+ | G1: φy*h- | H1: φu*h- | I1: φy- | J1: φu-
A2: - | B2: mm | C2: mm-1 | D2: mm-1 | E2: mm-1 | F2: mm-1 | G2: mm-1 | H2: mm-1 | I2: mm-1 | J2: mm-1
A3: 1 | B3: 500 | C3: 2.829 | D3: 39.13 | E3: =C3/(B3*1000) -> 5.658e-06 | F3: =D3/(B3*1000) -> 7.826e-05 | G3: =2.829 -> 2.829 | H3: 39.13 | I3: =G3/(B3*1000) -> 5.658e-06 | J3: =H3/(B3*1000) -> 7.826e-05
A4: 2 | B4: 500 | C4: 2.877 | D4: 37.06 | E4: =C4/(B4*1000) -> 5.754e-06 | F4: =D4/(B4*1000) -> 7.412e-05 | G4: 3.009 | H4: 33.19 | I4: =G4/(B4*1000) -> 6.018e-06 | J4: =H4/(B4*1000) -> 6.638e-05
A5: 3 | B5: 500 | C5: 2.804 | D5: 39.39 | E5: =C5/(B5*1000) -> 5.608e-06 | F5: =D5/(B5*1000) -> 7.878e-05 | G5: 2.955 | H5: 34.83 | I5: =G5/(B5*1000) -> 5.91e-06 | J5: =H5/(B5*1000) -> 6.966e-05
A6: 4 | B6: 500 | C6: 3.082 | D6: 31.95 | E6: =C6/(B6*1000) -> 6.164e-06 | F6: =D6/(B6*1000) -> 6.39e-05 | G6: 3.184 | H6: 29.35 | I6: =G6/(B6*1000) -> 6.368e-06 | J6: =H6/(B6*1000) -> 5.87e-05
A7: 5 | B7: 500 | C7: 2.973 | D7: 34.45 | E7: =C7/(B7*1000) -> 5.946e-06 | F7: =D7/(B7*1000) -> 6.89e-05 | G7: 3.149 | H7: 29.72 | I7: =G7/(B7*1000) -> 6.298e-06 | J7: =H7/(B7*1000) -> 5.944e-05
A8: 6 | B8: 500 | E8: =C8/(B8*1000) -> 0 | F8: =D8/(B8*1000) -> 0 | I8: =G8/(B8*1000) -> 0 | J8: =H8/(B8*1000) -> 0
A9: 7 | B9: 500 | E9: =C9/(B9*1000) -> 0 | F9: =D9/(B9*1000) -> 0 | I9: =G9/(B9*1000) -> 0 | J9: =H9/(B9*1000) -> 0
A10: 8 | B10: 500 | E10: =C10/(B10*1000) -> 0 | F10: =D10/(B10*1000) -> 0 | I10: =G10/(B10*1000) -> 0 | J10: =H10/(B10*1000) -> 0
A11: 9 | B11: 500 | E11: =C11/(B11*1000) -> 0 | F11: =D11/(B11*1000) -> 0 | I11: =G11/(B11*1000) -> 0 | J11: =H11/(B11*1000) -> 0
A12: 10 | B12: 500 | C12: 2.756 | D12: 39.75 | E12: =C12/(B12*1000) -> 5.512e-06 | F12: =D12/(B12*1000) -> 7.95e-05 | G12: 3.227 | H12: 26.47 | I12: =G12/(B12*1000) -> 6.454e-06 | J12: =H12/(B12*1000) -> 5.294e-05
A13: 11 | B13: 500 | E13: =C13/(B13*1000) -> 0 | F13: =D13/(B13*1000) -> 0 | I13: =G13/(B13*1000) -> 0 | J13: =H13/(B13*1000) -> 0
A14: 12 | B14: 500 | E14: =C14/(B14*1000) -> 0 | F14: =D14/(B14*1000) -> 0 | I14: =G14/(B14*1000) -> 0 | J14: =H14/(B14*1000) -> 0
A15: 13 | B15: 500 | C15: 2.742 | D15: 39.83 | E15: =C15/(B15*1000) -> 5.484e-06 | F15: =D15/(B15*1000) -> 7.966e-05 | G15: 3.316 | H15: 24.13 | I15: =G15/(B15*1000) -> 6.632e-06 | J15: =H15/(B15*1000) -> 4.826e-05
A16: 14 | B16: 500 | E16: =C16/(B16*1000) -> 0 | F16: =D16/(B16*1000) -> 0 | I16: =G16/(B16*1000) -> 0 | J16: =H16/(B16*1000) -> 0
A17: 15 | B17: 500 | C17: 2.766 | D17: 39.68 | E17: =C17/(B17*1000) -> 5.532e-06 | F17: =D17/(B17*1000) -> 7.936e-05 | G17: 3.166 | H17: 28.17 | I17: =G17/(B17*1000) -> 6.332e-06 | J17: =H17/(B17*1000) -> 5.634e-05
A18: 16 | B18: 500 | E18: =C18/(B18*1000) -> 0 | F18: =D18/(B18*1000) -> 0 | I18: =G18/(B18*1000) -> 0 | J18: =H18/(B18*1000) -> 0
A19: 17 | B19: 500 | C19: 2.728 | D19: 39.9 | E19: =C19/(B19*1000) -> 5.456e-06 | F19: =D19/(B19*1000) -> 7.98e-05 | G19: 3.405 | H19: 22.02 | I19: =G19/(B19*1000) -> 6.81e-06 | J19: =H19/(B19*1000) -> 4.404e-05
