Workbook

Sheet VERIFICHE GENERALI (SAP)
A1: DATI
A2: $E_{cm}$ | B2: =31000 -> 31000 | C2: N/mm^2
A3: Se(SLV) | B3: 0.312 | C3: g
A4: Se(SLV) | B4: 0.37128 | C4: g
A5: q(SLV) | B5: 3.12 | C5: -
A6: q(SLD) | B6: 1.5 | C6: -
A7: Se(SLV) | B7: =B3/B5 -> 0.1 | C7: g
A8: Se(SLV) | B8: =B4/B5 -> 0.119 | C8: g
A9: h | B9: 3000 | C9: mm
A10: fyd | B10: 30 | C10: N/mm^2 | D10: C30/37
A11: fcd | B11: =B10/1.5*0.85 -> 17 | C11: N/mm^3
A14: PESI SISMICI
A16: PIANI | B16: W.solaio | C16: W.tramezzi esterni | D16: W.travi | E16: W.pilastri | F16: $W_{i}$
A17: N.p | B17: [KN] | C17: [KN] | D17: [KN] | E17: [KN] | F17: [KN]
A18: 1 | B18: =[1]COMBINAZIONI!$B$7*'[1]PESO & ANALISI STATICA'!$I$2 -> 1723.9162 | C18: =(13.5*2+17.5*2)*[1]TRAMEZZI!$I$17 -> 464.256 | D18: =(0.3*0.5*25)*(5.5*5+4*2*5+(4+4+5.5+4)*4) -> 515.625 | E18: =0.4*0.4*25*3*4*5 -> 240 | F18: =SUM(B18:E18) -> 2943.7972
A19: 2 | B19: =[1]COMBINAZIONI!$B$7*'[1]PESO & ANALISI STATICA'!$I$2 -> 1723.9162 | C19: =(13.5*2+17.5*2)*[1]TRAMEZZI!$I$17 -> 464.256 | D19: =(0.3*0.5*25)*(5.5*5+4*2*5+(4+4+5.5+4)*4) -> 515.625 | E19: =0.4*0.4*25*3*4*5 -> 240 | F19: =SUM(B19:E19) -> 2943.7972
A20: 3 | B20: =[1]COMBINAZIONI!$B$7*'[1]PESO & ANALISI STATICA'!$I$2 -> 1723.9162 | C20: =(13.5*2+17.5*2)*[1]TRAMEZZI!$I$17 -> 464.256 | D20: =(0.3*0.5*25)*(5.5*5+4*2*5+(4+4+5.5+4)*4) -> 515.625 | E20: =0.4*0.4*25*3*4*5 -> 240 | F20: =SUM(B20:E20) -> 2943.7972
A21: 4 | B21: =[1]COMBINAZIONI!$C$7*'[1]PESO & ANALISI STATICA'!$I$2 -> 1438.0538 | C21: =(13.5*2+17.5*2)*[1]TRAMEZZI!$I$17/2+0.1*C20 -> 278.5536 | D21: =(0.3*0.4*25)*(5.5*5+4*2*5+(4+4+5.5+4)*4) -> 412.5 | E21: =0.4*0.4*25*3*4*5/2 -> 120 | F21: =SUM(B21:E21) -> 2249.1074
E22: $\sum{W_{tot}}$ | F22: =SUM(F18:F21) -> 11080.499
A24: VARIAZIONE DELLA DISTRIBUZIONE IN ELEVAZIONE DELLE MASSE [7.2.2]
A26: PIANI | B26: $W_{i}$ | C26: $M=W/g$ | D26: Riduzione
A27: N.p | B27: [KN] | C27: [t] | D27: [%]
A28: 1 | B28: =F18 -> 2943.7972 | C28: =B28/9.81 -> 300.08127 | E28: =IF(ABS(D28)<=25,"OK","NO") -> OK
A29: 2 | B29: =F19 -> 2943.7972 | C29: =B29/9.81 -> 300.08127 | D29: =(C29-C28)/C28*100 -> 0 | E29: =IF(ABS(D29)<=25,"OK","NO") -> OK
A30: 3 | B30: =F20 -> 2943.7972 | C30: =B30/9.81 -> 300.08127 | D30: =(C30-C29)/C29*100 -> 0 | E30: =IF(ABS(D30)<=25,"OK","NO") -> OK
A31: 4 | B31: =F21 -> 2249.1074 | C31: =B31/9.81 -> 229.2668 | D31: =(C31-C30)/C30*100 -> -23.598429 | E31: =IF(ABS(D31)<=25,"OK","NO") -> OK
A36: ANALISI STATICA LINEARE [7.3.3.2]
E38: direzione X (T = 0.72) | F38: direzione Y (T = 0.61)
E39: Fh (SLV)/3,12 [KN] | F39: Fh (SLV)/3,12 [KN]
E40: =B7*F22*0.85 -> 941.84242 | F40: =B8*F22*0.85 -> 1120.7925
A41: Livello | B41: zi [m] | C41: Wi [KN] | D41: Wi* zi [KNm] | E41: F_i [KN] | F41: Fi [KN]
A42: P1 | B42: 3 | C42: =F18 -> 2943.7972 | D42: =C42*B42 -> 8831.3917 | E42: =$E$40*D42/$D$46 -> 104.00131 | F42: =$F$40*D42/$D$46 -> 123.76156
A43: P2 | B43: 6 | C43: =F19 -> 2943.7972 | D43: =C43*B43 -> 17662.783 | E43: =$E$40*D43/$D$46 -> 208.00263 | F43: =$F$40*D43/$D$46 -> 247.52312
A44: P3 | B44: 9 | C44: =F20 -> 2943.7972 | D44: =C44*B44 -> 26494.175 | E44: =$E$40*D44/$D$46 -> 312.00394 | F44: =$F$40*D44/$D$46 -> 371.28469
A45: P4 | B45: 12 | C45: =F21 -> 2249.1074 | D45: =C45*B45 -> 26989.288 | E45: =$E$40*D45/$D$46 -> 317.83455 | F45: =$F$40*D45/$D$46 -> 378.22311
D46: =SUM(D42:D45) -> 79977.639
A48: ANALISI DINAMICA LINEARE
C51: direzione X (T = 0.72) | D51: direzione Y (T = 0.61)
A52: Livello | B52: zi [m] | C52: ∑Fi [KN] | D52: ∑Fi [KN]
A53: P1 | B53: 3 | C53: =(366.72*2+88.2423*2)-C56-C55-C54 -> 107.6706 | D53: =(202.91*5)-D56-D55-D54 -> 117.3
...

Sheet VERIFICHE GENERALI
A1: DATI
A2: $E_{cm}$ | B2: =31000 -> 31000 | C2: N/mm^2
A3: Se(SLV) | B3: =0.47 -> 0.47 | C3: g
A4: Se(SLV) | B4: =0.18 -> 0.18 | C4: g
A5: q(SLV) | B5: 3.9 | C5: -
A6: q(SLD) | B6: 1.5 | C6: -
A7: Se(SLV) | B7: =B3/B5 -> 0.12051282 | C7: g
A8: Se(SLV) | B8: =B4/B6 -> 0.12 | C8: g
A9: h | B9: 3000 | C9: mm
A10: fyd | B10: 30 | C10: N/mm^2 | D10: C30/37
A11: fcd | B11: =B10/1.5*0.85 -> 17 | C11: N/mm^3
A14: PESI SISMICI
A16: PIANI | B16: W.solaio | C16: W.tramezzi esterni | D16: W.travi | E16: W.pilastri | F16: $W_{i}$
A17: N.p | B17: [KN] | C17: [KN] | D17: [KN] | E17: [KN] | F17: [KN]
A18: 1 | B18: =[1]COMBINAZIONI!$B$7*'[1]PESO & ANALISI STATICA'!$I$2 -> 1723.9162 | C18: =(13.5*2+17.5*2)*[1]TRAMEZZI!$I$17 -> 464.256 | D18: =(0.3*0.5*25)*(5.5*5+4*2*5+(4+4+5.5+4)*4) -> 515.625 | E18: =0.4*0.4*25*3*4*5 -> 240 | F18: =SUM(B18:E18) -> 2943.7972
A19: 2 | B19: =[1]COMBINAZIONI!$B$7*'[1]PESO & ANALISI STATICA'!$I$2 -> 1723.9162 | C19: =(13.5*2+17.5*2)*[1]TRAMEZZI!$I$17 -> 464.256 | D19: =(0.3*0.5*25)*(5.5*5+4*2*5+(4+4+5.5+4)*4) -> 515.625 | E19: =0.4*0.4*25*3*4*5 -> 240 | F19: =SUM(B19:E19) -> 2943.7972
A20: 3 | B20: =[1]COMBINAZIONI!$B$7*'[1]PESO & ANALISI STATICA'!$I$2 -> 1723.9162 | C20: =(13.5*2+17.5*2)*[1]TRAMEZZI!$I$17 -> 464.256 | D20: =(0.3*0.5*25)*(5.5*5+4*2*5+(4+4+5.5+4)*4) -> 515.625 | E20: =0.4*0.4*25*3*4*5 -> 240 | F20: =SUM(B20:E20) -> 2943.7972
A21: 4 | B21: =[1]COMBINAZIONI!$C$7*'[1]PESO & ANALISI STATICA'!$I$2 -> 1438.0538 | C21: =(13.5*2+17.5*2)*[1]TRAMEZZI!$I$17/2+0.1*C20 -> 278.5536 | D21: =(0.3*0.4*25)*(5.5*5+4*2*5+(4+4+5.5+4)*4) -> 412.5 | E21: =0.4*0.4*25*3*4*5/2 -> 120 | F21: =SUM(B21:E21) -> 2249.1074
E22: $\sum{W_{tot}}$ | F22: =SUM(F18:F21) -> 11080.499
A24: VARIAZIONE DELLA DISTRIBUZIONE IN ELEVAZIONE DELLE MASSE [7.2.2]
A26: PIANI | B26: $W_{i}$ | C26: $M=W/g$ | D26: Riduzione
A27: N.p | B27: [KN] | C27: [t] | D27: [%]
A28: 1 | B28: =F18 -> 2943.7972 | C28: =B28/9.81 -> 300.08127 | E28: =IF(ABS(D28)<=25,"OK","NO") -> OK
A29: 2 | B29: =F19 -> 2943.7972 | C29: =B29/9.81 -> 300.08127 | D29: =(C29-C28)/C28*100 -> 0 | E29: =IF(ABS(D29)<=25,"OK","NO") -> OK
A30: 3 | B30: =F20 -> 2943.7972 | C30: =B30/9.81 -> 300.08127 | D30: =(C30-C29)/C29*100 -> 0 | E30: =IF(ABS(D30)<=25,"OK","NO") -> OK
A31: 4 | B31: =F21 -> 2249.1074 | C31: =B31/9.81 -> 229.2668 | D31: =(C31-C30)/C30*100 -> -23.598429 | E31: =IF(ABS(D31)<=25,"OK","NO") -> OK
A33: ANALISI STATICA LINEARE [7.3.3.2]
E35: Fh (SLV)/q=3,12 [KN] | F35: Fh (SLD)/q=1,5 [KN]
E36: =B7*F22*0.85 -> 1135.0409 | F36: =B8*F22*0.85 -> 1130.2109 | H36: $\sum{F_i}$
A37: Livello | B37: zi [m] | C37: Wi [KN] | D37: $Wi\cdot zi$ [KNm] | E37: $F_i \;(SLV)$ | F37: $F_i \; (SLD)$ | H37: N
A38: P1 | B38: 3 | C38: =F18 -> 2943.7972 | D38: =C38*B38 -> 8831.3917 | E38: =$E$36*D38/(SUM($D$38:$D$41)) -> 125.33492 | F38: =$F$36*D38/(SUM($D$38:$D$41)) -> 124.80158 | H38: =F41+F40+F39+F38 -> 1130.2109
A39: P2 | B39: 6 | C39: =F19 -> 2943.7972 | D39: =C39*B39 -> 17662.783 | E39: =$E$36*D39/(SUM($D$38:$D$41)) -> 250.66983 | F39: =$F$36*D39/(SUM($D$38:$D$41)) -> 249.60315 | H39: =F41+F40+F39 -> 1005.4093
A40: P3 | B40: 9 | C40: =F20 -> 2943.7972 | D40: =C40*B40 -> 26494.175 | E40: =$E$36*D40/(SUM($D$38:$D$41)) -> 376.00475 | F40: =$F$36*D40/(SUM($D$38:$D$41)) -> 374.40473 | H40: =F41+F40 -> 755.80618
A41: P4 | B41: 12 | C41: =F21 -> 2249.1074 | D41: =C41*B41 -> 26989.288 | E41: =$E$36*D41/(SUM($D$38:$D$41)) -> 383.03138 | F41: =$F$36*D41/(SUM($D$38:$D$41)) -> 381.40146 | H41: =F41 -> 381.40146
A43: VERIFICA SPOSTAMENTI LATERALI [7.3.7.2]
A45: PIANO | B45: $\sum{k_x}$ | C45: $\sum{k_y}$ | D45: $\sum{F_i}$ | E45: $\delta_x$ | F45: $\delta_y$ | G45: dr [mm] | H45: $w_x$ | I45: $w_y$
A46: n.P | B46: mm/N | C46: mm/N | D46: N | E46: mm | F46: mm | G46: =0.005*B9 -> 15 | H46: mm | I46: mm
A47: 1 | B47: =SUM('PIANO 1'!H5:H24) -> 743569.44 | C47: =SUM('PIANO 1'!I5:I24) -> 743569.44 | D47: =SUM(E38:E41)*1000 -> 1135040.9 | E47: =$D47/B47 -> 1.5264759 | F47: =$D47/C47 -> 1.5264759 | G47: =IF(F47<=$G$46,"OK","NO") -> OK | H47: =SUM(E47) -> 1.5264759 | I47: =SUM(F47) -> 1.5264759
A48: 2 | B48: =SUM('PIANO 2'!H5:H24) -> 585555.56 | C48: =SUM('PIANO 2'!I5:I24) -> 585555.56 | D48: =SUM(E38:E40)*1000 -> 752009.49 | E48: =$D48/B48 -> 1.2842667 | F48: =$D48/C48 -> 1.2842667 | G48: =IF(F48<=$G$46,"OK","NO") -> OK | H48: =SUM(E47:E48) -> 2.8107426 | I48: =SUM(F47:F48) -> 2.8107426
A49: 3 | B49: =SUM('PIANO 3'!H5:H24) -> 453375 | C49: =SUM('PIANO 3'!I5:I24) -> 453375 | D49: =SUM(E38:E39)*1000 -> 376004.75 | E49: =$D49/B49 -> 0.82934601 | F49: =$D49/C49 -> 0.82934601 | G49: =IF(F49<=$G$46,"OK","NO") -> OK | H49: =SUM(E47:E49) -> 3.6400886 | I49: =SUM(F47:F49) -> 3.6400886
...

Sheet PIANO 1
A1: CENTRO DI RIGIDEZZA
A3: PIANO 1 | B3: $b_x$ | C3: $b_y$ | D3: $x_i$ | E3: $y_i$ | F3: $J_x$ | G3: $J_y$ | H3: $k_x$ | I3: $k_y$ | J3: $\k_x_i\cdot x_i$ | K3: $\k_y_i\cdot y_i$ | L3: $Xk$ | M3: $Yk$
A4: n.P | B4: mm | C4: mm | D4: m | E4: m | F4: mm^4 | G4: mm^4 | H4: mm/N | I4: mm/N | J4: mm*m/N | K4: mm*m/N | L4: m | M4: m
A5: 1 | B5: 550 | C5: 300 | D5: 0 | E5: 0 | F5: =B5*C5^3/12 -> 1237500000 | G5: =C5*B5^3/12 -> 4159375000 | H5: =12*'VERIFICHE GENERALI'!$B$2*'PIANO 1'!$G5/'VERIFICHE GENERALI'!$B$9^3 -> 57306.944 | I5: =12*'VERIFICHE GENERALI'!$B$2*'PIANO 1'!F5/'VERIFICHE GENERALI'!$B$9^3 -> 17050 | J5: =H5*D5 -> 0 | K5: =I5*E5 -> 0 | L5: =SUM(J5:J24)/SUM(H5:H24) -> 8.6 | M5: =SUM(K5:K24)/SUM(I5:I24) -> 6.75
A6: 2 | B6: 550 | C6: 300 | D6: 4 | E6: 0 | F6: =B6*C6^3/12 -> 1237500000 | G6: =C6*B6^3/12 -> 4159375000 | H6: =12*'VERIFICHE GENERALI'!$B$2*'PIANO 1'!$G6/'VERIFICHE GENERALI'!$B$9^3 -> 57306.944 | I6: =12*'VERIFICHE GENERALI'!$B$2*'PIANO 1'!F6/'VERIFICHE GENERALI'!$B$9^3 -> 17050 | J6: =H6*D6 -> 229227.78 | K6: =I6*E6 -> 0 | L6: $X_G$ | M6: $Y_G$
A7: 3 | B7: 550 | C7: 300 | D7: 8 | E7: 0 | F7: =B7*C7^3/12 -> 1237500000 | G7: =C7*B7^3/12 -> 4159375000 | H7: =12*'VERIFICHE GENERALI'!$B$2*'PIANO 1'!$G7/'VERIFICHE GENERALI'!$B$9^3 -> 57306.944 | I7: =12*'VERIFICHE GENERALI'!$B$2*'PIANO 1'!F7/'VERIFICHE GENERALI'!$B$9^3 -> 17050 | J7: =H7*D7 -> 458455.56 | K7: =I7*E7 -> 0 | L7: m | M7: m
A8: 4 | B8: 550 | C8: 300 | D8: 13.5 | E8: 0 | F8: =B8*C8^3/12 -> 1237500000 | G8: =C8*B8^3/12 -> 4159375000 | H8: =12*'VERIFICHE GENERALI'!$B$2*'PIANO 1'!$G8/'VERIFICHE GENERALI'!$B$9^3 -> 57306.944 | I8: =12*'VERIFICHE GENERALI'!$B$2*'PIANO 1'!F8/'VERIFICHE GENERALI'!$B$9^3 -> 17050 | J8: =H8*D8 -> 773643.75 | K8: =I8*E8 -> 0 | L8: =17.5/2 -> 8.75 | M8: =13.5/2 -> 6.75
A9: 5 | B9: 550 | C9: 300 | D9: 17.5 | E9: 0 | F9: =B9*C9^3/12 -> 1237500000 | G9: =C9*B9^3/12 -> 4159375000 | H9: =12*'VERIFICHE GENERALI'!$B$2*'PIANO 1'!$G9/'VERIFICHE GENERALI'!$B$9^3 -> 57306.944 | I9: =12*'VERIFICHE GENERALI'!$B$2*'PIANO 1'!F9/'VERIFICHE GENERALI'!$B$9^3 -> 17050 | J9: =H9*D9 -> 1002871.5 | K9: =I9*E9 -> 0
A10: 6 | B10: 300 | C10: 550 | D10: 0 | E10: 4 | F10: =B10*C10^3/12 -> 4159375000 | G10: =C10*B10^3/12 -> 1237500000 | H10: =12*'VERIFICHE GENERALI'!$B$2*'PIANO 1'!$G10/'VERIFICHE GENERALI'!$B$9^3 -> 17050 | I10: =12*'VERIFICHE GENERALI'!$B$2*'PIANO 1'!F10/'VERIFICHE GENERALI'!$B$9^3 -> 57306.944 | J10: =H10*D10 -> 0 | K10: =I10*E10 -> 229227.78
A11: 7 | B11: 300 | C11: 550 | D11: 4 | E11: 4 | F11: =B11*C11^3/12 -> 4159375000 | G11: =C11*B11^3/12 -> 1237500000 | H11: =12*'VERIFICHE GENERALI'!$B$2*'PIANO 1'!$G11/'VERIFICHE GENERALI'!$B$9^3 -> 17050 | I11: =12*'VERIFICHE GENERALI'!$B$2*'PIANO 1'!F11/'VERIFICHE GENERALI'!$B$9^3 -> 57306.944 | J11: =H11*D11 -> 68200 | K11: =I11*E11 -> 229227.78
A12: 8 | B12: 300 | C12: 550 | D12: 8 | E12: 4 | F12: =B12*C12^3/12 -> 4159375000 | G12: =C12*B12^3/12 -> 1237500000 | H12: =12*'VERIFICHE GENERALI'!$B$2*'PIANO 1'!$G12/'VERIFICHE GENERALI'!$B$9^3 -> 17050 | I12: =12*'VERIFICHE GENERALI'!$B$2*'PIANO 1'!F12/'VERIFICHE GENERALI'!$B$9^3 -> 57306.944 | J12: =H12*D12 -> 136400 | K12: =I12*E12 -> 229227.78
A13: 9 | B13: 300 | C13: 550 | D13: 13.5 | E13: 4 | F13: =B13*C13^3/12 -> 4159375000 | G13: =C13*B13^3/12 -> 1237500000 | H13: =12*'VERIFICHE GENERALI'!$B$2*'PIANO 1'!$G13/'VERIFICHE GENERALI'!$B$9^3 -> 17050 | I13: =12*'VERIFICHE GENERALI'!$B$2*'PIANO 1'!F13/'VERIFICHE GENERALI'!$B$9^3 -> 57306.944 | J13: =H13*D13 -> 230175 | K13: =I13*E13 -> 229227.78
A14: 10 | B14: 300 | C14: 550 | D14: 17.5 | E14: 4 | F14: =B14*C14^3/12 -> 4159375000 | G14: =C14*B14^3/12 -> 1237500000 | H14: =12*'VERIFICHE GENERALI'!$B$2*'PIANO 1'!$G14/'VERIFICHE GENERALI'!$B$9^3 -> 17050 | I14: =12*'VERIFICHE GENERALI'!$B$2*'PIANO 1'!F14/'VERIFICHE GENERALI'!$B$9^3 -> 57306.944 | J14: =H14*D14 -> 298375 | K14: =I14*E14 -> 229227.78
A15: 11 | B15: 300 | C15: 550 | D15: 0 | E15: 9.5 | F15: =B15*C15^3/12 -> 4159375000 | G15: =C15*B15^3/12 -> 1237500000 | H15: =12*'VERIFICHE GENERALI'!$B$2*'PIANO 1'!$G15/'VERIFICHE GENERALI'!$B$9^3 -> 17050 | I15: =12*'VERIFICHE GENERALI'!$B$2*'PIANO 1'!F15/'VERIFICHE GENERALI'!$B$9^3 -> 57306.944 | J15: =H15*D15 -> 0 | K15: =I15*E15 -> 544415.97
A16: 12 | B16: 300 | C16: 550 | D16: 4 | E16: 9.5 | F16: =B16*C16^3/12 -> 4159375000 | G16: =C16*B16^3/12 -> 1237500000 | H16: =12*'VERIFICHE GENERALI'!$B$2*'PIANO 1'!$G16/'VERIFICHE GENERALI'!$B$9^3 -> 17050 | I16: =12*'VERIFICHE GENERALI'!$B$2*'PIANO 1'!F16/'VERIFICHE GENERALI'!$B$9^3 -> 57306.944 | J16: =H16*D16 -> 68200 | K16: =I16*E16 -> 544415.97
A17: 13 | B17: 300 | C17: 550 | D17: 8 | E17: 9.5 | F17: =B17*C17^3/12 -> 4159375000 | G17: =C17*B17^3/12 -> 1237500000 | H17: =12*'VERIFICHE GENERALI'!$B$2*'PIANO 1'!$G17/'VERIFICHE GENERALI'!$B$9^3 -> 17050 | I17: =12*'VERIFICHE GENERALI'!$B$2*'PIANO 1'!F17/'VERIFICHE GENERALI'!$B$9^3 -> 57306.944 | J17: =H17*D17 -> 136400 | K17: =I17*E17 -> 544415.97
A18: 14 | B18: 300 | C18: 550 | D18: 13.5 | E18: 9.5 | F18: =B18*C18^3/12 -> 4159375000 | G18: =C18*B18^3/12 -> 1237500000 | H18: =12*'VERIFICHE GENERALI'!$B$2*'PIANO 1'!$G18/'VERIFICHE GENERALI'!$B$9^3 -> 17050 | I18: =12*'VERIFICHE GENERALI'!$B$2*'PIANO 1'!F18/'VERIFICHE GENERALI'!$B$9^3 -> 57306.944 | J18: =H18*D18 -> 230175 | K18: =I18*E18 -> 544415.97
A19: 15 | B19: 300 | C19: 550 | D19: 17.5 | E19: 9.5 | F19: =B19*C19^3/12 -> 4159375000 | G19: =C19*B19^3/12 -> 1237500000 | H19: =12*'VERIFICHE GENERALI'!$B$2*'PIANO 1'!$G19/'VERIFICHE GENERALI'!$B$9^3 -> 17050 | I19: =12*'VERIFICHE GENERALI'!$B$2*'PIANO 1'!F19/'VERIFICHE GENERALI'!$B$9^3 -> 57306.944 | J19: =H19*D19 -> 298375 | K19: =I19*E19 -> 544415.97
A20: 16 | B20: 550 | C20: 300 | D20: 0 | E20: 13.5 | F20: =B20*C20^3/12 -> 1237500000 | G20: =C20*B20^3/12 -> 4159375000 | H20: =12*'VERIFICHE GENERALI'!$B$2*'PIANO 1'!$G20/'VERIFICHE GENERALI'!$B$9^3 -> 57306.944 | I20: =12*'VERIFICHE GENERALI'!$B$2*'PIANO 1'!F20/'VERIFICHE GENERALI'!$B$9^3 -> 17050 | J20: =H20*D20 -> 0 | K20: =I20*E20 -> 230175
... A24: 20 | B24: 550 | C24: 300 | D24: 17.5 | E24: 13.5 | F24: =B24*C24^3/12 -> 1237500000 | G24: =C24*B24^3/12 -> 4159375000 | H24: =12*'VERIFICHE GENERALI'!$B$2*'PIANO 1'!$G24/'VERIFICHE GENERALI'!$B$9^3 -> 57306.944 | I24: =12*'VERIFICHE GENERALI'!$B$2*'PIANO 1'!F24/'VERIFICHE GENERALI'!$B$9^3 -> 17050 | J24: =H24*D24 -> 1002871.5 | K24: =I24*E24 -> 230175
A47: VERIFICA A SFORZO NORMALE [7.4.4.2.2.1]
D50: PIANO 1 | E50: $A_i$ | F50: $N_{ED}$ | G50: $N_{RD}$ | H50: $N_{ED}/N_{RD}$ | K50: DATI
D51: N.P | E51: m^2 | F51: KN | G51: KN | H51: - | I51: < 0.65 | K51: q_{FOND.} | L51: 14.3455 | M51: KN/mm^2
D52: 1 | E52: =2*2 -> 4 | F52: =(25*(B5*C5*'VERIFICHE GENERALI'!$B$9)/1000^3)*1.3+E52*$L$51+E52*$L$54+'PIANO 2'!E48+($L$55/$L$56)*E52 -> 383.97918 | G52: =('VERIFICHE GENERALI'!$B$11*B5*C5)/1000 -> 2805 | H52: =F52/G52 -> 0.13689097 | I52: =IF(H52<=1,"OK","NO") -> OK | K52: PESO TOT. TRAVI | L52: ='VERIFICHE GENERALI'!D18 -> 515.625
D53: 2 | E53: =4*2 -> 8 | F53: =(25*(B6*C6*'VERIFICHE GENERALI'!$B$9)/1000^3)*1.3+E53*$L$51+E53*$L$54+'PIANO 2'!E49+($L$55/$L$56)*E53 -> 712.38337 | G53: =('VERIFICHE GENERALI'!$B$11*B6*C6)/1000 -> 2805 | H53: =F53/G53 -> 0.25396912 | I53: =IF(H53<=1,"OK","NO") -> OK | K53: AREA FABBR. | L53: =(L8*2)*(M8*2) -> 236.25
D54: 3 | E54: =4.75*2 -> 9.5 | F54: =(25*(B7*C7*'VERIFICHE GENERALI'!$B$9)/1000^3)*1.3+E54*$L$51+E54*$L$54+'PIANO 2'!E50+($L$55/$L$56)*E54 -> 835.53494 | G54: =('VERIFICHE GENERALI'!$B$11*B7*C7)/1000 -> 2805 | H54: =F54/G54 -> 0.29787342 | I54: =IF(H54<=1,"OK","NO") -> OK | K54: peso travi al m^2 | L54: =L52/L53*1.3 -> 2.8373016
D55: 4 | E55: =4.75*2 -> 9.5 | F55: =(25*(B8*C8*'VERIFICHE GENERALI'!$B$9)/1000^3)*1.3+E55*$L$51+E55*$L$54+'PIANO 2'!E51+($L$55/$L$56)*E55 -> 835.53494 | G55: =('VERIFICHE GENERALI'!$B$11*B8*C8)/1000 -> 2805 | H55: =F55/G55 -> 0.29787342 | I55: =IF(H55<=1,"OK","NO") -> OK | K55: PESO TRAMEZZI esterni | L55: =[1]TRAMEZZI!$I$17*(L8*4+M8*4)*1.3 -> 603.5328
D56: 5 | E56: =2*2 -> 4 | F56: =(25*(B9*C9*'VERIFICHE GENERALI'!$B$9)/1000^3)*1.3+E56*$L$51+E56*$L$54+'PIANO 2'!E52+($L$55/$L$56)*E56 -> 383.97918 | G56: =('VERIFICHE GENERALI'!$B$11*B9*C9)/1000 -> 2805 | H56: =F56/G56 -> 0.13689097 | I56: =IF(H56<=1,"OK","NO") -> OK | K56: Are comp. Tramezzi esterni | L56: =SUM(E52:E56,E67:E71)+E62+E57+E66+E61 -> 108
D57: 6 | E57: =2*4.75 -> 9.5 | F57: =(25*(B10*C10*'VERIFICHE GENERALI'!$B$9)/1000^3)*1.3+E57*$L$51+E57*$L$54+'PIANO 2'!E53+($L$55/$L$56)*E57 -> 835.53494 | G57: =('VERIFICHE GENERALI'!$B$11*B10*C10)/1000 -> 2805 | H57: =F57/G57 -> 0.29787342 | I57: =IF(H57<=1,"OK","NO") -> OK
D58: 7 | E58: =4*4.75 -> 19 | F58: =(25*(B11*C11*'VERIFICHE GENERALI'!$B$9)/1000^3)*1.3+E58*$L$51+E58*$L$54+'PIANO 2'!E54 -> 1293.9262 | G58: =('VERIFICHE GENERALI'!$B$11*B11*C11)/1000 -> 2805 | H58: =F58/G58 -> 0.46129275 | I58: =IF(H58<=1,"OK","NO") -> OK
D59: 8 | E59: =4.75*4.75 -> 22.5625 | F59: =(25*(B12*C12*'VERIFICHE GENERALI'!$B$9)/1000^3)*1.3+E59*$L$51+E59*$L$54+'PIANO 2'!E55 -> 1526.6866 | G59: =('VERIFICHE GENERALI'!$B$11*B12*C12)/1000 -> 2805 | H59: =F59/G59 -> 0.54427328 | I59: =IF(H59<=1,"OK","NO") -> OK
D60: 9 | E60: =4.75*4.75 -> 22.5625 | F60: =(25*(B13*C13*'VERIFICHE GENERALI'!$B$9)/1000^3)*1.3+E60*$L$51+E60*$L$54+'PIANO 2'!E56 -> 1526.6866 | G60: =('VERIFICHE GENERALI'!$B$11*B13*C13)/1000 -> 2805 | H60: =F60/G60 -> 0.54427328 | I60: =IF(H60<=1,"OK","NO") -> OK
D61: 10 | E61: =4.75*2 -> 9.5 | F61: =(25*(B14*C14*'VERIFICHE GENERALI'!$B$9)/1000^3)*1.3+E61*$L$51+E61*$L$54+'PIANO 2'!E57+($L$55/$L$56)*E61 -> 832.15994 | G61: =('VERIFICHE GENERALI'!$B$11*B14*C14)/1000 -> 2805 | H61: =F61/G61 -> 0.29667021 | I61: =IF(H61<=1,"OK","NO") -> OK
D62: 11 | E62: =2*4.75 -> 9.5 | F62: =(25*(B15*C15*'VERIFICHE GENERALI'!$B$9)/1000^3)*1.3+E62*$L$51+E62*$L$54+'PIANO 2'!E58+($L$55/$L$56)*E62 -> 832.15994 | G62: =('VERIFICHE GENERALI'!$B$11*B15*C15)/1000 -> 2805 | H62: =F62/G62 -> 0.29667021 | I62: =IF(H62<=1,"OK","NO") -> OK
D63: 12 | E63: =4*4.75 -> 19 | F63: =(25*(B16*C16*'VERIFICHE GENERALI'!$B$9)/1000^3)*1.3+E63*$L$51+E63*$L$54+'PIANO 2'!E59 -> 1296.9637 | G63: =('VERIFICHE GENERALI'!$B$11*B16*C16)/1000 -> 2805 | H63: =F63/G63 -> 0.46237564 | I63: =IF(H63<=1,"OK","NO") -> OK
D64: 13 | E64: =4.75*4.75 -> 22.5625 | F64: =(25*(B17*C17*'VERIFICHE GENERALI'!$B$9)/1000^3)*1.3+E64*$L$51+E64*$L$54+'PIANO 2'!E60 -> 1526.3491 | G64: =('VERIFICHE GENERALI'!$B$11*B17*C17)/1000 -> 2805 | H64: =F64/G64 -> 0.54415296 | I64: =IF(H64<=1,"OK","NO") -> OK
D65: 14 | E65: =4.75*4.75 -> 22.5625 | F65: =(25*(B18*C18*'VERIFICHE GENERALI'!$B$9)/1000^3)*1.3+E65*$L$51+E65*$L$54+'PIANO 2'!E61 -> 1526.3491 | G65: =('VERIFICHE GENERALI'!$B$11*B18*C18)/1000 -> 2805 | H65: =F65/G65 -> 0.54415296 | I65: =IF(H65<=1,"OK","NO") -> OK
D66: 15 | E66: =4.75*2 -> 9.5 | F66: =(25*(B19*C19*'VERIFICHE GENERALI'!$B$9)/1000^3)*1.3+E66*$L$51+E66*$L$54+'PIANO 2'!E62+($L$55/$L$56)*E66 -> 835.53494 | G66: =('VERIFICHE GENERALI'!$B$11*B19*C19)/1000 -> 2805 | H66: =F66/G66 -> 0.29787342 | I66: =IF(H66<=1,"OK","NO") -> OK
D67: 16 | E67: =2*2 -> 4 | F67: =(25*(B20*C20*'VERIFICHE GENERALI'!$B$9)/1000^3)*1.3+E67*$L$51+E67*$L$54+'PIANO 2'!E63+($L$55/$L$56)*E67 -> 383.97918 | G67: =('VERIFICHE GENERALI'!$B$11*B20*C20)/1000 -> 2805 | H67: =F67/G67 -> 0.13689097 | I67: =IF(H67<=1,"OK","NO") -> OK
D68: 17 | E68: =4*2 -> 8 | F68: =(25*(B21*C21*'VERIFICHE GENERALI'!$B$9)/1000^3)*1.3+E68*$L$51+E68*$L$54+'PIANO 2'!E64+($L$55/$L$56)*E68 -> 712.38337 | G68: =('VERIFICHE GENERALI'!$B$11*B21*C21)/1000 -> 2805 | H68: =F68/G68 -> 0.25396912 | I68: =IF(H68<=1,"OK","NO") -> OK
...

Sheet PIANO 2
A1: CENTRO DI RIGIDEZZA
A3: PIANO 1 | B3: $b_x$ | C3: $b_y$ | D3: $x_i$ | E3: $y_i$ | F3: $J_x$ | G3: $J_y$ | H3: $k_x$ | I3: $k_y$ | J3: $\k_x_i\cdot x_i$ | K3: $\k_y_i\cdot y_i$ | L3: $Xk$ | M3: $Yk$
A4: n.P | B4: mm | C4: mm | D4: m | E4: m | F4: mm^4 | G4: mm^4 | H4: mm/N | I4: mm/N | J4: mm^2/N | K4: mm^2/N | L4: m | M4: m
A5: 1 | B5: 500 | C5: 300 | D5: 0 | E5: 0 | F5: =B5*C5^3/12 -> 1125000000 | G5: =C5*B5^3/12 -> 3125000000 | H5: =12*'VERIFICHE GENERALI'!$B$2*'PIANO 2'!$G5/'VERIFICHE GENERALI'!$B$9^3 -> 43055.556 | I5: =12*'VERIFICHE GENERALI'!$B$2*'PIANO 2'!F5/'VERIFICHE GENERALI'!$B$9^3 -> 15500 | J5: =H5*D5 -> 0 | K5: =I5*E5 -> 0 | L5: =SUM(J5:J24)/SUM(H5:H24) -> 8.6 | M5: =SUM(K5:K24)/SUM(I5:I24) -> 6.75
A6: 2 | B6: 500 | C6: 300 | D6: 4 | E6: 0 | F6: =B6*C6^3/12 -> 1125000000 | G6: =C6*B6^3/12 -> 3125000000 | H6: =12*'VERIFICHE GENERALI'!$B$2*'PIANO 2'!$G6/'VERIFICHE GENERALI'!$B$9^3 -> 43055.556 | I6: =12*'VERIFICHE GENERALI'!$B$2*'PIANO 2'!F6/'VERIFICHE GENERALI'!$B$9^3 -> 15500 | J6: =H6*D6 -> 172222.22 | K6: =I6*E6 -> 0 | L6: $X_G$ | M6: $Y_G$
A7: 3 | B7: 500 | C7: 300 | D7: 8 | E7: 0 | F7: =B7*C7^3/12 -> 1125000000 | G7: =C7*B7^3/12 -> 3125000000 | H7: =12*'VERIFICHE GENERALI'!$B$2*'PIANO 2'!$G7/'VERIFICHE GENERALI'!$B$9^3 -> 43055.556 | I7: =12*'VERIFICHE GENERALI'!$B$2*'PIANO 2'!F7/'VERIFICHE GENERALI'!$B$9^3 -> 15500 | J7: =H7*D7 -> 344444.44 | K7: =I7*E7 -> 0 | L7: m | M7: m
A8: 4 | B8: 500 | C8: 300 | D8: 13.5 | E8: 0 | F8: =B8*C8^3/12 -> 1125000000 | G8: =C8*B8^3/12 -> 3125000000 | H8: =12*'VERIFICHE GENERALI'!$B$2*'PIANO 2'!$G8/'VERIFICHE GENERALI'!$B$9^3 -> 43055.556 | I8: =12*'VERIFICHE GENERALI'!$B$2*'PIANO 2'!F8/'VERIFICHE GENERALI'!$B$9^3 -> 15500 | J8: =H8*D8 -> 581250 | K8: =I8*E8 -> 0 | L8: =17.5/2 -> 8.75 | M8: =13.5/2 -> 6.75
A9: 5 | B9: 500 | C9: 300 | D9: 17.5 | E9: 0 | F9: =B9*C9^3/12 -> 1125000000 | G9: =C9*B9^3/12 -> 3125000000 | H9: =12*'VERIFICHE GENERALI'!$B$2*'PIANO 2'!$G9/'VERIFICHE GENERALI'!$B$9^3 -> 43055.556 | I9: =12*'VERIFICHE GENERALI'!$B$2*'PIANO 2'!F9/'VERIFICHE GENERALI'!$B$9^3 -> 15500 | J9: =H9*D9 -> 753472.22 | K9: =I9*E9 -> 0
A10: 6 | B10: 300 | C10: 500 | D10: 0 | E10: 4 | F10: =B10*C10^3/12 -> 3125000000 | G10: =C10*B10^3/12 -> 1125000000 | H10: =12*'VERIFICHE GENERALI'!$B$2*'PIANO 2'!$G10/'VERIFICHE GENERALI'!$B$9^3 -> 15500 | I10: =12*'VERIFICHE GENERALI'!$B$2*'PIANO 2'!F10/'VERIFICHE GENERALI'!$B$9^3 -> 43055.556 | J10: =H10*D10 -> 0 | K10: =I10*E10 -> 172222.22
A11: 7 | B11: 300 | C11: 500 | D11: 4 | E11: 4 | F11: =B11*C11^3/12 -> 3125000000 | G11: =C11*B11^3/12 -> 1125000000 | H11: =12*'VERIFICHE GENERALI'!$B$2*'PIANO 2'!$G11/'VERIFICHE GENERALI'!$B$9^3 -> 15500 | I11: =12*'VERIFICHE GENERALI'!$B$2*'PIANO 2'!F11/'VERIFICHE GENERALI'!$B$9^3 -> 43055.556 | J11: =H11*D11 -> 62000 | K11: =I11*E11 -> 172222.22
A12: 8 | B12: 300 | C12: 500 | D12: 8 | E12: 4 | F12: =B12*C12^3/12 -> 3125000000 | G12: =C12*B12^3/12 -> 1125000000 | H12: =12*'VERIFICHE GENERALI'!$B$2*'PIANO 2'!$G12/'VERIFICHE GENERALI'!$B$9^3 -> 15500 | I12: =12*'VERIFICHE GENERALI'!$B$2*'PIANO 2'!F12/'VERIFICHE GENERALI'!$B$9^3 -> 43055.556 | J12: =H12*D12 -> 124000 | K12: =I12*E12 -> 172222.22
A13: 9 | B13: 300 | C13: 500 | D13: 13.5 | E13: 4 | F13: =B13*C13^3/12 -> 3125000000 | G13: =C13*B13^3/12 -> 1125000000 | H13: =12*'VERIFICHE GENERALI'!$B$2*'PIANO 2'!$G13/'VERIFICHE GENERALI'!$B$9^3 -> 15500 | I13: =12*'VERIFICHE GENERALI'!$B$2*'PIANO 2'!F13/'VERIFICHE GENERALI'!$B$9^3 -> 43055.556 | J13: =H13*D13 -> 209250 | K13: =I13*E13 -> 172222.22
A14: 10 | B14: 300 | C14: 500 | D14: 17.5 | E14: 4 | F14: =B14*C14^3/12 -> 3125000000 | G14: =C14*B14^3/12 -> 1125000000 | H14: =12*'VERIFICHE GENERALI'!$B$2*'PIANO 2'!$G14/'VERIFICHE GENERALI'!$B$9^3 -> 15500 | I14: =12*'VERIFICHE GENERALI'!$B$2*'PIANO 2'!F14/'VERIFICHE GENERALI'!$B$9^3 -> 43055.556 | J14: =H14*D14 -> 271250 | K14: =I14*E14 -> 172222.22
A15: 11 | B15: 300 | C15: 500 | D15: 0 | E15: 9.5 | F15: =B15*C15^3/12 -> 3125000000 | G15: =C15*B15^3/12 -> 1125000000 | H15: =12*'VERIFICHE GENERALI'!$B$2*'PIANO 2'!$G15/'VERIFICHE GENERALI'!$B$9^3 -> 15500 | I15: =12*'VERIFICHE GENERALI'!$B$2*'PIANO 2'!F15/'VERIFICHE GENERALI'!$B$9^3 -> 43055.556 | J15: =H15*D15 -> 0 | K15: =I15*E15 -> 409027.78
A16: 12 | B16: 300 | C16: 500 | D16: 4 | E16: 9.5 | F16: =B16*C16^3/12 -> 3125000000 | G16: =C16*B16^3/12 -> 1125000000 | H16: =12*'VERIFICHE GENERALI'!$B$2*'PIANO 2'!$G16/'VERIFICHE GENERALI'!$B$9^3 -> 15500 | I16: =12*'VERIFICHE GENERALI'!$B$2*'PIANO 2'!F16/'VERIFICHE GENERALI'!$B$9^3 -> 43055.556 | J16: =H16*D16 -> 62000 | K16: =I16*E16 -> 409027.78
A17: 13 | B17: 300 | C17: 500 | D17: 8 | E17: 9.5 | F17: =B17*C17^3/12 -> 3125000000 | G17: =C17*B17^3/12 -> 1125000000 | H17: =12*'VERIFICHE GENERALI'!$B$2*'PIANO 2'!$G17/'VERIFICHE GENERALI'!$B$9^3 -> 15500 | I17: =12*'VERIFICHE GENERALI'!$B$2*'PIANO 2'!F17/'VERIFICHE GENERALI'!$B$9^3 -> 43055.556 | J17: =H17*D17 -> 124000 | K17: =I17*E17 -> 409027.78
A18: 14 | B18: 300 | C18: 500 | D18: 13.5 | E18: 9.5 | F18: =B18*C18^3/12 -> 3125000000 | G18: =C18*B18^3/12 -> 1125000000 | H18: =12*'VERIFICHE GENERALI'!$B$2*'PIANO 2'!$G18/'VERIFICHE GENERALI'!$B$9^3 -> 15500 | I18: =12*'VERIFICHE GENERALI'!$B$2*'PIANO 2'!F18/'VERIFICHE GENERALI'!$B$9^3 -> 43055.556 | J18: =H18*D18 -> 209250 | K18: =I18*E18 -> 409027.78
A19: 15 | B19: 300 | C19: 500 | D19: 17.5 | E19: 9.5 | F19: =B19*C19^3/12 -> 3125000000 | G19: =C19*B19^3/12 -> 1125000000 | H19: =12*'VERIFICHE GENERALI'!$B$2*'PIANO 2'!$G19/'VERIFICHE GENERALI'!$B$9^3 -> 15500 | I19: =12*'VERIFICHE GENERALI'!$B$2*'PIANO 2'!F19/'VERIFICHE GENERALI'!$B$9^3 -> 43055.556 | J19: =H19*D19 -> 271250 | K19: =I19*E19 -> 409027.78
A20: 16 | B20: 500 | C20: 300 | D20: 0 | E20: 13.5 | F20: =B20*C20^3/12 -> 1125000000 | G20: =C20*B20^3/12 -> 3125000000 | H20: =12*'VERIFICHE GENERALI'!$B$2*'PIANO 2'!$G20/'VERIFICHE GENERALI'!$B$9^3 -> 43055.556 | I20: =12*'VERIFICHE GENERALI'!$B$2*'PIANO 2'!F20/'VERIFICHE GENERALI'!$B$9^3 -> 15500 | J20: =H20*D20 -> 0 | K20: =I20*E20 -> 209250
... A24: 20 | B24: 500 | C24: 300 | D24: 17.5 | E24: 13.5 | F24: =B24*C24^3/12 -> 1125000000 | G24: =C24*B24^3/12 -> 3125000000 | H24: =12*'VERIFICHE GENERALI'!$B$2*'PIANO 2'!$G24/'VERIFICHE GENERALI'!$B$9^3 -> 43055.556 | I24: =12*'VERIFICHE GENERALI'!$B$2*'PIANO 2'!F24/'VERIFICHE GENERALI'!$B$9^3 -> 15500 | J24: =H24*D24 -> 753472.22 | K24: =I24*E24 -> 209250
A44: VERIFICA A SFORZO NORMALE [7.4.4.2.2.1]
C46: PIANO 2 | D46: $A_i$ | E46: $N_{ED}$ | F46: $N_{RD}$ | G46: $N_{ED}/N_{RD}$ | K46: DATI
C47: N.P | D47: m^2 | E47: KN | F47: KN | G47: - | H47: CD"B" | K47: q_{FOND.} | L47: 14.3455 | M47: KN/mm^2
C48: 1 | D48: =2*2 -> 4 | E48: =(25*(B5*C5*'VERIFICHE GENERALI'!$B$9)/1000^3)*1.3+D48*$L$47+D48*$L$50+'PIANO 3'!E49+($L$51/$L$52)*D48 -> 276.80741 | F48: =(0.65*'VERIFICHE GENERALI'!$B$11*B5*C5)/1000 -> 1657.5 | G48: =E48/F48 -> 0.16700296 | H48: =IF(G48<=1,"OK","NO") -> OK | K48: PESO TOT. TRAVI | L48: ='VERIFICHE GENERALI'!D19 -> 515.625
C49: 2 | D49: =4*2 -> 8 | E49: =(25*(B6*C6*'VERIFICHE GENERALI'!$B$9)/1000^3)*1.3+D49*$L$47+D49*$L$50+'PIANO 3'!E50+($L$51/$L$52)*D49 -> 514.12732 | F49: =(0.65*'VERIFICHE GENERALI'!$B$11*B6*C6)/1000 -> 1657.5 | G49: =E49/F49 -> 0.3101824 | H49: =IF(G49<=1,"OK","NO") -> OK | K49: AREA FABBR. | L49: =(L8*2)*(M8*2) -> 236.25
C50: 3 | D50: =4.75*2 -> 9.5 | E50: =(25*(B7*C7*'VERIFICHE GENERALI'!$B$9)/1000^3)*1.3+D50*$L$47+D50*$L$50+'PIANO 3'!E51+($L$51/$L$52)*D50 -> 603.12229 | F50: =(0.65*'VERIFICHE GENERALI'!$B$11*B7*C7)/1000 -> 1657.5 | G50: =E50/F50 -> 0.36387468 | H50: =IF(G50<=1,"OK","NO") -> OK | K50: peso travi al m^2 | L50: =L48/L49*1.3 -> 2.8373016
C51: 4 | D51: =4.75*2 -> 9.5 | E51: =(25*(B8*C8*'VERIFICHE GENERALI'!$B$9)/1000^3)*1.3+D51*$L$47+D51*$L$50+'PIANO 3'!E52+($L$51/$L$52)*D51 -> 603.12229 | F51: =(0.65*'VERIFICHE GENERALI'!$B$11*B8*C8)/1000 -> 1657.5 | G51: =E51/F51 -> 0.36387468 | H51: =IF(G51<=1,"OK","NO") -> OK | K51: PESO TRAMEZZI esterni | L51: =[1]TRAMEZZI!$I$17*(L8*4+M8*4)*1.3 -> 603.5328
C52: 5 | D52: =2*2 -> 4 | E52: =(25*(B9*C9*'VERIFICHE GENERALI'!$B$9)/1000^3)*1.3+D52*$L$47+D52*$L$50+'PIANO 3'!E53+($L$51/$L$52)*D52 -> 276.80741 | F52: =(0.65*'VERIFICHE GENERALI'!$B$11*B9*C9)/1000 -> 1657.5 | G52: =E52/F52 -> 0.16700296 | H52: =IF(G52<=1,"OK","NO") -> OK | K52: Are comp. Tramezzi esterni | L52: =SUM(D48:D52,D63:D67)+D58+D53+D62+D57 -> 108
C53: 6 | D53: =2*4.75 -> 9.5 | E53: =(25*(B10*C10*'VERIFICHE GENERALI'!$B$9)/1000^3)*1.3+D53*$L$47+D53*$L$50+'PIANO 3'!E54+($L$51/$L$52)*D53 -> 603.12229 | F53: =(0.65*'VERIFICHE GENERALI'!$B$11*B10*C10)/1000 -> 1657.5 | G53: =E53/F53 -> 0.36387468 | H53: =IF(G53<=1,"OK","NO") -> OK
C54: 7 | D54: =4*4.75 -> 19 | E54: =(25*(B11*C11*'VERIFICHE GENERALI'!$B$9)/1000^3)*1.3+D54*$L$47+D54*$L$50+'PIANO 3'!E55 -> 951.36544 | F54: =(0.65*'VERIFICHE GENERALI'!$B$11*B11*C11)/1000 -> 1657.5 | G54: =E54/F54 -> 0.57397614 | H54: =IF(G54<=1,"OK","NO") -> OK
C55: 8 | D55: =4.75*4.75 -> 22.5625 | E55: =(25*(B12*C12*'VERIFICHE GENERALI'!$B$9)/1000^3)*1.3+D55*$L$47+D55*$L$50+'PIANO 3'!E56 -> 1122.9121 | F55: =(0.65*'VERIFICHE GENERALI'!$B$11*B12*C12)/1000 -> 1657.5 | G55: =E55/F55 -> 0.67747336 | H55: =IF(G55<=1,"OK","NO") -> OK
C56: 9 | D56: =4.75*4.75 -> 22.5625 | E56: =(25*(B13*C13*'VERIFICHE GENERALI'!$B$9)/1000^3)*1.3+D56*$L$47+D56*$L$50+'PIANO 3'!E57 -> 1122.9121 | F56: =(0.65*'VERIFICHE GENERALI'!$B$11*B13*C13)/1000 -> 1657.5 | G56: =E56/F56 -> 0.67747336 | H56: =IF(G56<=1,"OK","NO") -> OK
C57: 10 | D57: =4.75*2 -> 9.5 | E57: =(25*(B14*C14*'VERIFICHE GENERALI'!$B$9)/1000^3)+D57*$L$47+D57*$L$50+'PIANO 3'!E58+($L$51/$L$52)*D57 -> 599.74729 | F57: =(0.65*'VERIFICHE GENERALI'!$B$11*B14*C14)/1000 -> 1657.5 | G57: =E57/F57 -> 0.36183849 | H57: =IF(G57<=1,"OK","NO") -> OK
C58: 11 | D58: =2*4.75 -> 9.5 | E58: =(25*(B15*C15*'VERIFICHE GENERALI'!$B$9)/1000^3)+D58*$L$47+D58*$L$50+'PIANO 3'!E59+($L$51/$L$52)*D58 -> 599.74729 | F58: =(0.65*'VERIFICHE GENERALI'!$B$11*B15*C15)/1000 -> 1657.5 | G58: =E58/F58 -> 0.36183849 | H58: =IF(G58<=1,"OK","NO") -> OK
C59: 12 | D59: =4*4.75 -> 19 | E59: =(25*(B16*C16*'VERIFICHE GENERALI'!$B$9)/1000^3)*1.3+D59*$L$47+D59*$L$50+'PIANO 3'!E60 -> 954.40294 | F59: =(0.65*'VERIFICHE GENERALI'!$B$11*B16*C16)/1000 -> 1657.5 | G59: =E59/F59 -> 0.57580871 | H59: =IF(G59<=1,"OK","NO") -> OK
C60: 13 | D60: =4.75*4.75 -> 22.5625 | E60: =(25*(B17*C17*'VERIFICHE GENERALI'!$B$9)/1000^3)+D60*$L$47+D60*$L$50+'PIANO 3'!E61 -> 1122.5746 | F60: =(0.65*'VERIFICHE GENERALI'!$B$11*B17*C17)/1000 -> 1657.5 | G60: =E60/F60 -> 0.67726974 | H60: =IF(G60<=1,"OK","NO") -> OK
C61: 14 | D61: =4.75*4.75 -> 22.5625 | E61: =(25*(B18*C18*'VERIFICHE GENERALI'!$B$9)/1000^3)+D61*$L$47+D61*$L$50+'PIANO 3'!E62 -> 1122.5746 | F61: =(0.65*'VERIFICHE GENERALI'!$B$11*B18*C18)/1000 -> 1657.5 | G61: =E61/F61 -> 0.67726974 | H61: =IF(G61<=1,"OK","NO") -> OK
C62: 15 | D62: =4.75*2 -> 9.5 | E62: =(25*(B19*C19*'VERIFICHE GENERALI'!$B$9)/1000^3)*1.3+D62*$L$47+D62*$L$50+'PIANO 3'!E63+($L$51/$L$52)*D62 -> 603.12229 | F62: =(0.65*'VERIFICHE GENERALI'!$B$11*B19*C19)/1000 -> 1657.5 | G62: =E62/F62 -> 0.36387468 | H62: =IF(G62<=1,"OK","NO") -> OK
C63: 16 | D63: =2*2 -> 4 | E63: =(25*(B20*C20*'VERIFICHE GENERALI'!$B$9)/1000^3)*1.3+D63*$L$47+D63*$L$50+'PIANO 3'!E64+($L$51/$L$52)*D63 -> 276.80741 | F63: =(0.65*'VERIFICHE GENERALI'!$B$11*B20*C20)/1000 -> 1657.5 | G63: =E63/F63 -> 0.16700296 | H63: =IF(G63<=1,"OK","NO") -> OK
C64: 17 | D64: =4*2 -> 8 | E64: =(25*(B21*C21*'VERIFICHE GENERALI'!$B$9)/1000^3)*1.3+D64*$L$47+D64*$L$50+'PIANO 3'!E65+($L$51/$L$52)*D64 -> 514.12732 | F64: =(0.65*'VERIFICHE GENERALI'!$B$11*B21*C21)/1000 -> 1657.5 | G64: =E64/F64 -> 0.3101824 | H64: =IF(G64<=1,"OK","NO") -> OK
...

Sheet PIANO 3
A1: CENTRO DI RIGIDEZZA
A3: PIANO 1 | B3: $b_x$ | C3: $b_y$ | D3: $x_i$ | E3: $y_i$ | F3: $J_x$ | G3: $J_y$ | H3: $k_x$ | I3: $k_y$ | J3: $\k_x_i\cdot x_i$ | K3: $\k_y_i\cdot y_i$ | L3: $Xk$ | M3: $Yk$
A4: n.P | B4: mm | C4: mm | D4: m | E4: m | F4: mm^4 | G4: mm^4 | H4: mm/N | I4: mm/N | J4: mm^2/N | K4: mm^2/N | L4: m | M4: m
A5: 1 | B5: 450 | C5: 300 | D5: 0 | E5: 0 | F5: =B5*C5^3/12 -> 1012500000 | G5: =C5*B5^3/12 -> 2278125000 | H5: =12*'VERIFICHE GENERALI'!$B$2*'PIANO 3'!$G5/'VERIFICHE GENERALI'!$B$9^3 -> 31387.5 | I5: =12*'VERIFICHE GENERALI'!$B$2*'PIANO 3'!F5/'VERIFICHE GENERALI'!$B$9^3 -> 13950 | J5: =H5*D5 -> 0 | K5: =I5*E5 -> 0 | L5: =SUM(J5:J24)/SUM(H5:H24) -> 8.6 | M5: =SUM(K5:K24)/SUM(I5:I24) -> 6.75
A6: 2 | B6: 450 | C6: 300 | D6: 4 | E6: 0 | F6: =B6*C6^3/12 -> 1012500000 | G6: =C6*B6^3/12 -> 2278125000 | H6: =12*'VERIFICHE GENERALI'!$B$2*'PIANO 3'!$G6/'VERIFICHE GENERALI'!$B$9^3 -> 31387.5 | I6: =12*'VERIFICHE GENERALI'!$B$2*'PIANO 3'!F6/'VERIFICHE GENERALI'!$B$9^3 -> 13950 | J6: =H6*D6 -> 125550 | K6: =I6*E6 -> 0 | L6: $X_G$ | M6: $Y_G$
A7: 3 | B7: 450 | C7: 300 | D7: 8 | E7: 0 | F7: =B7*C7^3/12 -> 1012500000 | G7: =C7*B7^3/12 -> 2278125000 | H7: =12*'VERIFICHE GENERALI'!$B$2*'PIANO 3'!$G7/'VERIFICHE GENERALI'!$B$9^3 -> 31387.5 | I7: =12*'VERIFICHE GENERALI'!$B$2*'PIANO 3'!F7/'VERIFICHE GENERALI'!$B$9^3 -> 13950 | J7: =H7*D7 -> 251100 | K7: =I7*E7 -> 0 | L7: m | M7: m
A8: 4 | B8: 450 | C8: 300 | D8: 13.5 | E8: 0 | F8: =B8*C8^3/12 -> 1012500000 | G8: =C8*B8^3/12 -> 2278125000 | H8: =12*'VERIFICHE GENERALI'!$B$2*'PIANO 3'!$G8/'VERIFICHE GENERALI'!$B$9^3 -> 31387.5 | I8: =12*'VERIFICHE GENERALI'!$B$2*'PIANO 3'!F8/'VERIFICHE GENERALI'!$B$9^3 -> 13950 | J8: =H8*D8 -> 423731.25 | K8: =I8*E8 -> 0 | L8: =17.5/2 -> 8.75 | M8: =13.5/2 -> 6.75
A9: 5 | B9: 450 | C9: 300 | D9: 17.5 | E9: 0 | F9: =B9*C9^3/12 -> 1012500000 | G9: =C9*B9^3/12 -> 2278125000 | H9: =12*'VERIFICHE GENERALI'!$B$2*'PIANO 3'!$G9/'VERIFICHE GENERALI'!$B$9^3 -> 31387.5 | I9: =12*'VERIFICHE GENERALI'!$B$2*'PIANO 3'!F9/'VERIFICHE GENERALI'!$B$9^3 -> 13950 | J9: =H9*D9 -> 549281.25 | K9: =I9*E9 -> 0
A10: 6 | B10: 300 | C10: 450 | D10: 0 | E10: 4 | F10: =B10*C10^3/12 -> 2278125000 | G10: =C10*B10^3/12 -> 1012500000 | H10: =12*'VERIFICHE GENERALI'!$B$2*'PIANO 3'!$G10/'VERIFICHE GENERALI'!$B$9^3 -> 13950 | I10: =12*'VERIFICHE GENERALI'!$B$2*'PIANO 3'!F10/'VERIFICHE GENERALI'!$B$9^3 -> 31387.5 | J10: =H10*D10 -> 0 | K10: =I10*E10 -> 125550
A11: 7 | B11: 300 | C11: 450 | D11: 4 | E11: 4 | F11: =B11*C11^3/12 -> 2278125000 | G11: =C11*B11^3/12 -> 1012500000 | H11: =12*'VERIFICHE GENERALI'!$B$2*'PIANO 3'!$G11/'VERIFICHE GENERALI'!$B$9^3 -> 13950 | I11: =12*'VERIFICHE GENERALI'!$B$2*'PIANO 3'!F11/'VERIFICHE GENERALI'!$B$9^3 -> 31387.5 | J11: =H11*D11 -> 55800 | K11: =I11*E11 -> 125550
A12: 8 | B12: 300 | C12: 450 | D12: 8 | E12: 4 | F12: =B12*C12^3/12 -> 2278125000 | G12: =C12*B12^3/12 -> 1012500000 | H12: =12*'VERIFICHE GENERALI'!$B$2*'PIANO 3'!$G12/'VERIFICHE GENERALI'!$B$9^3 -> 13950 | I12: =12*'VERIFICHE GENERALI'!$B$2*'PIANO 3'!F12/'VERIFICHE GENERALI'!$B$9^3 -> 31387.5 | J12: =H12*D12 -> 111600 | K12: =I12*E12 -> 125550
A13: 9 | B13: 300 | C13: 450 | D13: 13.5 | E13: 4 | F13: =B13*C13^3/12 -> 2278125000 | G13: =C13*B13^3/12 -> 1012500000 | H13: =12*'VERIFICHE GENERALI'!$B$2*'PIANO 3'!$G13/'VERIFICHE GENERALI'!$B$9^3 -> 13950 | I13: =12*'VERIFICHE GENERALI'!$B$2*'PIANO 3'!F13/'VERIFICHE GENERALI'!$B$9^3 -> 31387.5 | J13: =H13*D13 -> 188325 | K13: =I13*E13 -> 125550
A14: 10 | B14: 300 | C14: 450 | D14: 17.5 | E14: 4 | F14: =B14*C14^3/12 -> 2278125000 | G14: =C14*B14^3/12 -> 1012500000 | H14: =12*'VERIFICHE GENERALI'!$B$2*'PIANO 3'!$G14/'VERIFICHE GENERALI'!$B$9^3 -> 13950 | I14: =12*'VERIFICHE GENERALI'!$B$2*'PIANO 3'!F14/'VERIFICHE GENERALI'!$B$9^3 -> 31387.5 | J14: =H14*D14 -> 244125 | K14: =I14*E14 -> 125550
A15: 11 | B15: 300 | C15: 450 | D15: 0 | E15: 9.5 | F15: =B15*C15^3/12 -> 2278125000 | G15: =C15*B15^3/12 -> 1012500000 | H15: =12*'VERIFICHE GENERALI'!$B$2*'PIANO 3'!$G15/'VERIFICHE GENERALI'!$B$9^3 -> 13950 | I15: =12*'VERIFICHE GENERALI'!$B$2*'PIANO 3'!F15/'VERIFICHE GENERALI'!$B$9^3 -> 31387.5 | J15: =H15*D15 -> 0 | K15: =I15*E15 -> 298181.25
A16: 12 | B16: 300 | C16: 450 | D16: 4 | E16: 9.5 | F16: =B16*C16^3/12 -> 2278125000 | G16: =C16*B16^3/12 -> 1012500000 | H16: =12*'VERIFICHE GENERALI'!$B$2*'PIANO 3'!$G16/'VERIFICHE GENERALI'!$B$9^3 -> 13950 | I16: =12*'VERIFICHE GENERALI'!$B$2*'PIANO 3'!F16/'VERIFICHE GENERALI'!$B$9^3 -> 31387.5 | J16: =H16*D16 -> 55800 | K16: =I16*E16 -> 298181.25
A17: 13 | B17: 300 | C17: 450 | D17: 8 | E17: 9.5 | F17: =B17*C17^3/12 -> 2278125000 | G17: =C17*B17^3/12 -> 1012500000 | H17: =12*'VERIFICHE GENERALI'!$B$2*'PIANO 3'!$G17/'VERIFICHE GENERALI'!$B$9^3 -> 13950 | I17: =12*'VERIFICHE GENERALI'!$B$2*'PIANO 3'!F17/'VERIFICHE GENERALI'!$B$9^3 -> 31387.5 | J17: =H17*D17 -> 111600 | K17: =I17*E17 -> 298181.25
A18: 14 | B18: 300 | C18: 450 | D18: 13.5 | E18: 9.5 | F18: =B18*C18^3/12 -> 2278125000 | G18: =C18*B18^3/12 -> 1012500000 | H18: =12*'VERIFICHE GENERALI'!$B$2*'PIANO 3'!$G18/'VERIFICHE GENERALI'!$B$9^3 -> 13950 | I18: =12*'VERIFICHE GENERALI'!$B$2*'PIANO 3'!F18/'VERIFICHE GENERALI'!$B$9^3 -> 31387.5 | J18: =H18*D18 -> 188325 | K18: =I18*E18 -> 298181.25
A19: 15 | B19: 300 | C19: 450 | D19: 17.5 | E19: 9.5 | F19: =B19*C19^3/12 -> 2278125000 | G19: =C19*B19^3/12 -> 1012500000 | H19: =12*'VERIFICHE GENERALI'!$B$2*'PIANO 3'!$G19/'VERIFICHE GENERALI'!$B$9^3 -> 13950 | I19: =12*'VERIFICHE GENERALI'!$B$2*'PIANO 3'!F19/'VERIFICHE GENERALI'!$B$9^3 -> 31387.5 | J19: =H19*D19 -> 244125 | K19: =I19*E19 -> 298181.25
A20: 16 | B20: 450 | C20: 300 | D20: 0 | E20: 13.5 | F20: =B20*C20^3/12 -> 1012500000 | G20: =C20*B20^3/12 -> 2278125000 | H20: =12*'VERIFICHE GENERALI'!$B$2*'PIANO 3'!$G20/'VERIFICHE GENERALI'!$B$9^3 -> 31387.5 | I20: =12*'VERIFICHE GENERALI'!$B$2*'PIANO 3'!F20/'VERIFICHE GENERALI'!$B$9^3 -> 13950 | J20: =H20*D20 -> 0 | K20: =I20*E20 -> 188325
... A24: 20 | B24: 450 | C24: 300 | D24: 17.5 | E24: 13.5 | F24: =B24*C24^3/12 -> 1012500000 | G24: =C24*B24^3/12 -> 2278125000 | H24: =12*'VERIFICHE GENERALI'!$B$2*'PIANO 3'!$G24/'VERIFICHE GENERALI'!$B$9^3 -> 31387.5 | I24: =12*'VERIFICHE GENERALI'!$B$2*'PIANO 3'!F24/'VERIFICHE GENERALI'!$B$9^3 -> 13950 | J24: =H24*D24 -> 549281.25 | K24: =I24*E24 -> 188325
A44: VERIFICA A SFORZO NORMALE [7.4.4.2.2.1]
C47: PIANO 3 | D47: $A_i$ | E47: $N_{ED}$ | F47: $N_{RD}$ | G47: $N_{ED}/N_{RD}$
C48: N.P | D48: m^2 | E48: KN | F48: KN | G48: - | H48: CD"B" | K48: DATI
C49: 1 | D49: =2*2 -> 4 | E49: =(25*(B5*C5*'VERIFICHE GENERALI'!$B$9)/1000^3)*1.3+D49*$L$49+D49*$L$52+'PIANO 4'!E48+($L$53/$L$54)*D49 -> 171.09814 | F49: =(0.65*'VERIFICHE GENERALI'!$B$11*B5*C5)/1000 -> 1491.75 | G49: =E49/F49 -> 0.11469625 | H49: =IF(G49<=1,"OK","NO") -> OK | K49: q_{FOND.} | L49: 14.3455 | M49: KN/mm^2
C50: 2 | D50: =4*2 -> 8 | E50: =(25*(B6*C6*'VERIFICHE GENERALI'!$B$9)/1000^3)*1.3+D50*$L$49+D50*$L$52+'PIANO 4'!E49+($L$53/$L$54)*D50 -> 317.33378 | F50: =(0.65*'VERIFICHE GENERALI'!$B$11*B6*C6)/1000 -> 1491.75 | G50: =E50/F50 -> 0.21272584 | H50: =IF(G50<=1,"OK","NO") -> OK | K50: PESO TOT. TRAVI | L50: ='VERIFICHE GENERALI'!D20 -> 515.625
C51: 3 | D51: =4.75*2 -> 9.5 | E51: =(25*(B7*C7*'VERIFICHE GENERALI'!$B$9)/1000^3)*1.3+D51*$L$49+D51*$L$52+'PIANO 4'!E50+($L$53/$L$54)*D51 -> 372.17214 | F51: =(0.65*'VERIFICHE GENERALI'!$B$11*B7*C7)/1000 -> 1491.75 | G51: =E51/F51 -> 0.24948694 | H51: =IF(G51<=1,"OK","NO") -> OK | K51: AREA FABBR. | L51: =(L8*2)*(M8*2) -> 236.25
C52: 4 | D52: =4.75*2 -> 9.5 | E52: =(25*(B8*C8*'VERIFICHE GENERALI'!$B$9)/1000^3)*1.3+D52*$L$49+D52*$L$52+'PIANO 4'!E51+($L$53/$L$54)*D52 -> 372.17214 | F52: =(0.65*'VERIFICHE GENERALI'!$B$11*B8*C8)/1000 -> 1491.75 | G52: =E52/F52 -> 0.24948694 | H52: =IF(G52<=1,"OK","NO") -> OK | K52: peso travi al m^2 | L52: =L50/L51*1.3 -> 2.8373016
C53: 5 | D53: =2*2 -> 4 | E53: =(25*(B9*C9*'VERIFICHE GENERALI'!$B$9)/1000^3)*1.3+D53*$L$49+D53*$L$52+'PIANO 4'!E52+($L$53/$L$54)*D53 -> 171.09814 | F53: =(0.65*'VERIFICHE GENERALI'!$B$11*B9*C9)/1000 -> 1491.75 | G53: =E53/F53 -> 0.11469625 | H53: =IF(G53<=1,"OK","NO") -> OK | K53: PESO TRAMEZZI esterni | L53: =[1]TRAMEZZI!$I$17*(L8*4+M8*4)*1.3 -> 603.5328
C54: 6 | D54: =2*4.75 -> 9.5 | E54: =(25*(B10*C10*'VERIFICHE GENERALI'!$B$9)/1000^3)*1.3+D54*$L$49+D54*$L$52+'PIANO 4'!E53+($L$53/$L$54)*D54 -> 372.17214 | F54: =(0.65*'VERIFICHE GENERALI'!$B$11*B10*C10)/1000 -> 1491.75 | G54: =E54/F54 -> 0.24948694 | H54: =IF(G54<=1,"OK","NO") -> OK | K54: Are comp. Tramezzi esterni | L54: =SUM(D49:D53,D64:D68)+D59+D54+D63+D58 -> 108
C55: 7 | D55: =4*4.75 -> 19 | E55: =(25*(B11*C11*'VERIFICHE GENERALI'!$B$9)/1000^3)+D55*$L$49+D55*$L$52+'PIANO 4'!E54 -> 610.26721 | F55: =(0.65*'VERIFICHE GENERALI'!$B$11*B11*C11)/1000 -> 1491.75 | G55: =E55/F55 -> 0.40909483 | H55: =IF(G55<=1,"OK","NO") -> OK
C56: 8 | D56: =4.75*4.75 -> 22.5625 | E56: =(25*(B12*C12*'VERIFICHE GENERALI'!$B$9)/1000^3)+D56*$L$49+D56*$L$52+'PIANO 4'!E55 -> 720.60013 | F56: =(0.65*'VERIFICHE GENERALI'!$B$11*B12*C12)/1000 -> 1491.75 | G56: =E56/F56 -> 0.4830569 | H56: =IF(G56<=1,"OK","NO") -> OK
C57: 9 | D57: =4.75*4.75 -> 22.5625 | E57: =(25*(B13*C13*'VERIFICHE GENERALI'!$B$9)/1000^3)+D57*$L$49+D57*$L$52+'PIANO 4'!E56 -> 720.60013 | F57: =(0.65*'VERIFICHE GENERALI'!$B$11*B13*C13)/1000 -> 1491.75 | G57: =E57/F57 -> 0.4830569 | H57: =IF(G57<=1,"OK","NO") -> OK
C58: 10 | D58: =4.75*2 -> 9.5 | E58: =(25*(B14*C14*'VERIFICHE GENERALI'!$B$9)/1000^3)*1.3+D58*$L$49+D58*$L$52+'PIANO 4'!E57+($L$53/$L$54)*D58 -> 372.17214 | F58: =(0.65*'VERIFICHE GENERALI'!$B$11*B14*C14)/1000 -> 1491.75 | G58: =E58/F58 -> 0.24948694 | H58: =IF(G58<=1,"OK","NO") -> OK
C59: 11 | D59: =2*4.75 -> 9.5 | E59: =(25*(B15*C15*'VERIFICHE GENERALI'!$B$9)/1000^3)*1.3+D59*$L$49+D59*$L$52+'PIANO 4'!E58+($L$53/$L$54)*D59 -> 372.17214 | F59: =(0.65*'VERIFICHE GENERALI'!$B$11*B15*C15)/1000 -> 1491.75 | G59: =E59/F59 -> 0.24948694 | H59: =IF(G59<=1,"OK","NO") -> OK
C60: 12 | D60: =4*4.75 -> 19 | E60: =(25*(B16*C16*'VERIFICHE GENERALI'!$B$9)/1000^3)*1.3+D60*$L$49+D60*$L$52+'PIANO 4'!E59 -> 613.30471 | F60: =(0.65*'VERIFICHE GENERALI'!$B$11*B16*C16)/1000 -> 1491.75 | G60: =E60/F60 -> 0.41113103 | H60: =IF(G60<=1,"OK","NO") -> OK
C61: 13 | D61: =4.75*4.75 -> 22.5625 | E61: =(25*(B17*C17*'VERIFICHE GENERALI'!$B$9)/1000^3)*1.3+D61*$L$49+D61*$L$52+'PIANO 4'!E60 -> 723.63763 | F61: =(0.65*'VERIFICHE GENERALI'!$B$11*B17*C17)/1000 -> 1491.75 | G61: =E61/F61 -> 0.4850931 | H61: =IF(G61<=1,"OK","NO") -> OK
C62: 14 | D62: =4.75*4.75 -> 22.5625 | E62: =(25*(B18*C18*'VERIFICHE GENERALI'!$B$9)/1000^3)*1.3+D62*$L$49+D62*$L$52+'PIANO 4'!E61 -> 723.63763 | F62: =(0.65*'VERIFICHE GENERALI'!$B$11*B18*C18)/1000 -> 1491.75 | G62: =E62/F62 -> 0.4850931 | H62: =IF(G62<=1,"OK","NO") -> OK
C63: 15 | D63: =4.75*2 -> 9.5 | E63: =(25*(B19*C19*'VERIFICHE GENERALI'!$B$9)/1000^3)*1.3+D63*$L$49+D63*$L$52+'PIANO 4'!E62+($L$53/$L$54)*D63 -> 372.17214 | F63: =(0.65*'VERIFICHE GENERALI'!$B$11*B19*C19)/1000 -> 1491.75 | G63: =E63/F63 -> 0.24948694 | H63: =IF(G63<=1,"OK","NO") -> OK
C64: 16 | D64: =2*2 -> 4 | E64: =(25*(B20*C20*'VERIFICHE GENERALI'!$B$9)/1000^3)*1.3+D64*$L$49+D64*$L$52+'PIANO 4'!E63+($L$53/$L$54)*D64 -> 171.09814 | F64: =(0.65*'VERIFICHE GENERALI'!$B$11*B20*C20)/1000 -> 1491.75 | G64: =E64/F64 -> 0.11469625 | H64: =IF(G64<=1,"OK","NO") -> OK
C65: 17 | D65: =4*2 -> 8 | E65: =(25*(B21*C21*'VERIFICHE GENERALI'!$B$9)/1000^3)*1.3+D65*$L$49+D65*$L$52+'PIANO 4'!E64+($L$53/$L$54)*D65 -> 317.33378 | F65: =(0.65*'VERIFICHE GENERALI'!$B$11*B21*C21)/1000 -> 1491.75 | G65: =E65/F65 -> 0.21272584 | H65: =IF(G65<=1,"OK","NO") -> OK
...

Sheet PIANO 4
A1: CENTRO DI RIGIDEZZA
A3: PIANO 1 | B3: $b_x$ | C3: $b_y$ | D3: $x_i$ | E3: $y_i$ | F3: $J_x$ | G3: $J_y$ | H3: $k_x$ | I3: $k_y$ | J3: $\k_x_i\cdot x_i$ | K3: $\k_y_i\cdot y_i$ | L3: $Xk$ | M3: $Yk$
A4: n.P | B4: mm | C4: mm | D4: m | E4: m | F4: mm^4 | G4: mm^4 | H4: mm/N | I4: mm/N | J4: mm^2/N | K4: mm^2/N | L4: m | M4: m
A5: 1 | B5: 400 | C5: 300 | D5: 0 | E5: 0 | F5: =B5*C5^3/12 -> 900000000 | G5: =C5*B5^3/12 -> 1600000000 | H5: =12*'VERIFICHE GENERALI'!$B$2*'PIANO 4'!$G5/'VERIFICHE GENERALI'!$B$9^3 -> 22044.444 | I5: =12*'VERIFICHE GENERALI'!$B$2*'PIANO 4'!F5/'VERIFICHE GENERALI'!$B$9^3 -> 12400 | J5: =H5*D5 -> 0 | K5: =I5*E5 -> 0 | L5: =SUM(J5:J24)/SUM(H5:H24) -> 8.6 | M5: =SUM(K5:K24)/SUM(I5:I24) -> 6.75
A6: 2 | B6: 400 | C6: 300 | D6: 4 | E6: 0 | F6: =B6*C6^3/12 -> 900000000 | G6: =C6*B6^3/12 -> 1600000000 | H6: =12*'VERIFICHE GENERALI'!$B$2*'PIANO 4'!$G6/'VERIFICHE GENERALI'!$B$9^3 -> 22044.444 | I6: =12*'VERIFICHE GENERALI'!$B$2*'PIANO 4'!F6/'VERIFICHE GENERALI'!$B$9^3 -> 12400 | J6: =H6*D6 -> 88177.778 | K6: =I6*E6 -> 0 | L6: $X_G$ | M6: $Y_G$
A7: 3 | B7: 400 | C7: 300 | D7: 8 | E7: 0 | F7: =B7*C7^3/12 -> 900000000 | G7: =C7*B7^3/12 -> 1600000000 | H7: =12*'VERIFICHE GENERALI'!$B$2*'PIANO 4'!$G7/'VERIFICHE GENERALI'!$B$9^3 -> 22044.444 | I7: =12*'VERIFICHE GENERALI'!$B$2*'PIANO 4'!F7/'VERIFICHE GENERALI'!$B$9^3 -> 12400 | J7: =H7*D7 -> 176355.56 | K7: =I7*E7 -> 0 | L7: m | M7: m
A8: 4 | B8: 400 | C8: 300 | D8: 13.5 | E8: 0 | F8: =B8*C8^3/12 -> 900000000 | G8: =C8*B8^3/12 -> 1600000000 | H8: =12*'VERIFICHE GENERALI'!$B$2*'PIANO 4'!$G8/'VERIFICHE GENERALI'!$B$9^3 -> 22044.444 | I8: =12*'VERIFICHE GENERALI'!$B$2*'PIANO 4'!F8/'VERIFICHE GENERALI'!$B$9^3 -> 12400 | J8: =H8*D8 -> 297600 | K8: =I8*E8 -> 0 | L8: =17.5/2 -> 8.75 | M8: =13.5/2 -> 6.75
A9: 5 | B9: 400 | C9: 300 | D9: 17.5 | E9: 0 | F9: =B9*C9^3/12 -> 900000000 | G9: =C9*B9^3/12 -> 1600000000 | H9: =12*'VERIFICHE GENERALI'!$B$2*'PIANO 4'!$G9/'VERIFICHE GENERALI'!$B$9^3 -> 22044.444 | I9: =12*'VERIFICHE GENERALI'!$B$2*'PIANO 4'!F9/'VERIFICHE GENERALI'!$B$9^3 -> 12400 | J9: =H9*D9 -> 385777.78 | K9: =I9*E9 -> 0
A10: 6 | B10: 300 | C10: 400 | D10: 0 | E10: 4 | F10: =B10*C10^3/12 -> 1600000000 | G10: =C10*B10^3/12 -> 900000000 | H10: =12*'VERIFICHE GENERALI'!$B$2*'PIANO 4'!$G10/'VERIFICHE GENERALI'!$B$9^3 -> 12400 | I10: =12*'VERIFICHE GENERALI'!$B$2*'PIANO 4'!F10/'VERIFICHE GENERALI'!$B$9^3 -> 22044.444 | J10: =H10*D10 -> 0 | K10: =I10*E10 -> 88177.778
A11: 7 | B11: 300 | C11: 400 | D11: 4 | E11: 4 | F11: =B11*C11^3/12 -> 1600000000 | G11: =C11*B11^3/12 -> 900000000 | H11: =12*'VERIFICHE GENERALI'!$B$2*'PIANO 4'!$G11/'VERIFICHE GENERALI'!$B$9^3 -> 12400 | I11: =12*'VERIFICHE GENERALI'!$B$2*'PIANO 4'!F11/'VERIFICHE GENERALI'!$B$9^3 -> 22044.444 | J11: =H11*D11 -> 49600 | K11: =I11*E11 -> 88177.778
A12: 8 | B12: 300 | C12: 400 | D12: 8 | E12: 4 | F12: =B12*C12^3/12 -> 1600000000 | G12: =C12*B12^3/12 -> 900000000 | H12: =12*'VERIFICHE GENERALI'!$B$2*'PIANO 4'!$G12/'VERIFICHE GENERALI'!$B$9^3 -> 12400 | I12: =12*'VERIFICHE GENERALI'!$B$2*'PIANO 4'!F12/'VERIFICHE GENERALI'!$B$9^3 -> 22044.444 | J12: =H12*D12 -> 99200 | K12: =I12*E12 -> 88177.778
A13: 9 | B13: 300 | C13: 400 | D13: 13.5 | E13: 4 | F13: =B13*C13^3/12 -> 1600000000 | G13: =C13*B13^3/12 -> 900000000 | H13: =12*'VERIFICHE GENERALI'!$B$2*'PIANO 4'!$G13/'VERIFICHE GENERALI'!$B$9^3 -> 12400 | I13: =12*'VERIFICHE GENERALI'!$B$2*'PIANO 4'!F13/'VERIFICHE GENERALI'!$B$9^3 -> 22044.444 | J13: =H13*D13 -> 167400 | K13: =I13*E13 -> 88177.778
A14: 10 | B14: 300 | C14: 400 | D14: 17.5 | E14: 4 | F14: =B14*C14^3/12 -> 1600000000 | G14: =C14*B14^3/12 -> 900000000 | H14: =12*'VERIFICHE GENERALI'!$B$2*'PIANO 4'!$G14/'VERIFICHE GENERALI'!$B$9^3 -> 12400 | I14: =12*'VERIFICHE GENERALI'!$B$2*'PIANO 4'!F14/'VERIFICHE GENERALI'!$B$9^3 -> 22044.444 | J14: =H14*D14 -> 217000 | K14: =I14*E14 -> 88177.778
A15: 11 | B15: 300 | C15: 400 | D15: 0 | E15: 9.5 | F15: =B15*C15^3/12 -> 1600000000 | G15: =C15*B15^3/12 -> 900000000 | H15: =12*'VERIFICHE GENERALI'!$B$2*'PIANO 4'!$G15/'VERIFICHE GENERALI'!$B$9^3 -> 12400 | I15: =12*'VERIFICHE GENERALI'!$B$2*'PIANO 4'!F15/'VERIFICHE GENERALI'!$B$9^3 -> 22044.444 | J15: =H15*D15 -> 0 | K15: =I15*E15 -> 209422.22
A16: 12 | B16: 300 | C16: 400 | D16: 4 | E16: 9.5 | F16: =B16*C16^3/12 -> 1600000000 | G16: =C16*B16^3/12 -> 900000000 | H16: =12*'VERIFICHE GENERALI'!$B$2*'PIANO 4'!$G16/'VERIFICHE GENERALI'!$B$9^3 -> 12400 | I16: =12*'VERIFICHE GENERALI'!$B$2*'PIANO 4'!F16/'VERIFICHE GENERALI'!$B$9^3 -> 22044.444 | J16: =H16*D16 -> 49600 | K16: =I16*E16 -> 209422.22
A17: 13 | B17: 300 | C17: 400 | D17: 8 | E17: 9.5 | F17: =B17*C17^3/12 -> 1600000000 | G17: =C17*B17^3/12 -> 900000000 | H17: =12*'VERIFICHE GENERALI'!$B$2*'PIANO 4'!$G17/'VERIFICHE GENERALI'!$B$9^3 -> 12400 | I17: =12*'VERIFICHE GENERALI'!$B$2*'PIANO 4'!F17/'VERIFICHE GENERALI'!$B$9^3 -> 22044.444 | J17: =H17*D17 -> 99200 | K17: =I17*E17 -> 209422.22
A18: 14 | B18: 300 | C18: 400 | D18: 13.5 | E18: 9.5 | F18: =B18*C18^3/12 -> 1600000000 | G18: =C18*B18^3/12 -> 900000000 | H18: =12*'VERIFICHE GENERALI'!$B$2*'PIANO 4'!$G18/'VERIFICHE GENERALI'!$B$9^3 -> 12400 | I18: =12*'VERIFICHE GENERALI'!$B$2*'PIANO 4'!F18/'VERIFICHE GENERALI'!$B$9^3 -> 22044.444 | J18: =H18*D18 -> 167400 | K18: =I18*E18 -> 209422.22
A19: 15 | B19: 300 | C19: 400 | D19: 17.5 | E19: 9.5 | F19: =B19*C19^3/12 -> 1600000000 | G19: =C19*B19^3/12 -> 900000000 | H19: =12*'VERIFICHE GENERALI'!$B$2*'PIANO 4'!$G19/'VERIFICHE GENERALI'!$B$9^3 -> 12400 | I19: =12*'VERIFICHE GENERALI'!$B$2*'PIANO 4'!F19/'VERIFICHE GENERALI'!$B$9^3 -> 22044.444 | J19: =H19*D19 -> 217000 | K19: =I19*E19 -> 209422.22
A20: 16 | B20: 400 | C20: 300 | D20: 0 | E20: 13.5 | F20: =B20*C20^3/12 -> 900000000 | G20: =C20*B20^3/12 -> 1600000000 | H20: =12*'VERIFICHE GENERALI'!$B$2*'PIANO 4'!$G20/'VERIFICHE GENERALI'!$B$9^3 -> 22044.444 | I20: =12*'VERIFICHE GENERALI'!$B$2*'PIANO 4'!F20/'VERIFICHE GENERALI'!$B$9^3 -> 12400 | J20: =H20*D20 -> 0 | K20: =I20*E20 -> 167400
... A24: 20 | B24: 400 | C24: 300 | D24: 17.5 | E24: 13.5 | F24: =B24*C24^3/12 -> 900000000 | G24: =C24*B24^3/12 -> 1600000000 | H24: =12*'VERIFICHE GENERALI'!$B$2*'PIANO 4'!$G24/'VERIFICHE GENERALI'!$B$9^3 -> 22044.444 | I24: =12*'VERIFICHE GENERALI'!$B$2*'PIANO 4'!F24/'VERIFICHE GENERALI'!$B$9^3 -> 12400 | J24: =H24*D24 -> 385777.78 | K24: =I24*E24 -> 167400
A44: VERIFICA A SFORZO NORMALE [7.4.4.2.2.1]
C46: PIANO 4 | D46: $A_i$ | E46: $N_{ED}$ | F46: $N_{RD}$ | G46: $N_{ED}/N_{RD}$ | J46: DATI
C47: N.P | D47: m^2 | E47: KN | F47: KN | G47: - | H47: CD"B" | J47: q_{FOND.} | K47: 11.518 | L47: KN/mm^2
C48: 1 | D48: =2*2 -> 4 | E48: =(25*(B5*C5*'VERIFICHE GENERALI'!$B$9)/1000^3)*1.3+D48*$K$47+$K$50*D48 -> 66.851365 | F48: =(0.65*'VERIFICHE GENERALI'!$B$11*B5*C5)/1000 -> 1326 | G48: =E48/F48 -> 0.050415811 | H48: =IF(G48<=1,"OK","NO") -> OK | J48: PESO TOT. TRAVI | K48: ='VERIFICHE GENERALI'!D21 -> 412.5
C49: 2 | D49: =4*2 -> 8 | E49: =(25*(B6*C6*'VERIFICHE GENERALI'!$B$9)/1000^3)*1.3+D49*$K$47+$K$50*D49 -> 122.00273 | F49: =(0.65*'VERIFICHE GENERALI'!$B$11*B6*C6)/1000 -> 1326 | G49: =E49/F49 -> 0.092008092 | H49: =IF(G49<=1,"OK","NO") -> OK | J49: AREA FABBR. | K49: =(L8*2)*(M8*2) -> 236.25
C50: 3 | D50: =4.75*2 -> 9.5 | E50: =(25*(B7*C7*'VERIFICHE GENERALI'!$B$9)/1000^3)*1.3+D50*$K$47+$K$50*D50 -> 142.68449 | F50: =(0.65*'VERIFICHE GENERALI'!$B$11*B7*C7)/1000 -> 1326 | G50: =E50/F50 -> 0.1076052 | H50: =IF(G50<=1,"OK","NO") -> OK | J50: peso travi al m^2 | K50: =K48/K49*1.3 -> 2.2698413
C51: 4 | D51: =4.75*2 -> 9.5 | E51: =(25*(B8*C8*'VERIFICHE GENERALI'!$B$9)/1000^3)*1.3+D51*$K$47+$K$50*D51 -> 142.68449 | F51: =(0.65*'VERIFICHE GENERALI'!$B$11*B8*C8)/1000 -> 1326 | G51: =E51/F51 -> 0.1076052 | H51: =IF(G51<=1,"OK","NO") -> OK
C52: 5 | D52: =2*2 -> 4 | E52: =(25*(B9*C9*'VERIFICHE GENERALI'!$B$9)/1000^3)*1.3+D52*$K$47+$K$50*D52 -> 66.851365 | F52: =(0.65*'VERIFICHE GENERALI'!$B$11*B9*C9)/1000 -> 1326 | G52: =E52/F52 -> 0.050415811 | H52: =IF(G52<=1,"OK","NO") -> OK
C53: 6 | D53: =2*4.75 -> 9.5 | E53: =(25*(B10*C10*'VERIFICHE GENERALI'!$B$9)/1000^3)*1.3+D53*$K$47+$K$50*D53 -> 142.68449 | F53: =(0.65*'VERIFICHE GENERALI'!$B$11*B10*C10)/1000 -> 1326 | G53: =E53/F53 -> 0.1076052 | H53: =IF(G53<=1,"OK","NO") -> OK
C54: 7 | D54: =4*4.75 -> 19 | E54: =(25*(B11*C11*'VERIFICHE GENERALI'!$B$9)/1000^3)*1.3+D54*$K$47+$K$50*D54 -> 273.66898 | F54: =(0.65*'VERIFICHE GENERALI'!$B$11*B11*C11)/1000 -> 1326 | G54: =E54/F54 -> 0.20638687 | H54: =IF(G54<=1,"OK","NO") -> OK
C55: 8 | D55: =4.75*4.75 -> 22.5625 | E55: =(25*(B12*C12*'VERIFICHE GENERALI'!$B$9)/1000^3)*1.3+D55*$K$47+$K$50*D55 -> 322.78817 | F55: =(0.65*'VERIFICHE GENERALI'!$B$11*B12*C12)/1000 -> 1326 | G55: =E55/F55 -> 0.24342999 | H55: =IF(G55<=1,"OK","NO") -> OK
C56: 9 | D56: =4.75*4.75 -> 22.5625 | E56: =(25*(B13*C13*'VERIFICHE GENERALI'!$B$9)/1000^3)*1.3+D56*$K$47+$K$50*D56 -> 322.78817 | F56: =(0.65*'VERIFICHE GENERALI'!$B$11*B13*C13)/1000 -> 1326 | G56: =E56/F56 -> 0.24342999 | H56: =IF(G56<=1,"OK","NO") -> OK
C57: 10 | D57: =4.75*2 -> 9.5 | E57: =(25*(B14*C14*'VERIFICHE GENERALI'!$B$9)/1000^3)*1.3+D57*$K$47+$K$50*D57 -> 142.68449 | F57: =(0.65*'VERIFICHE GENERALI'!$B$11*B14*C14)/1000 -> 1326 | G57: =E57/F57 -> 0.1076052 | H57: =IF(G57<=1,"OK","NO") -> OK
C58: 11 | D58: =2*4.75 -> 9.5 | E58: =(25*(B15*C15*'VERIFICHE GENERALI'!$B$9)/1000^3)*1.3+D58*$K$47+$K$50*D58 -> 142.68449 | F58: =(0.65*'VERIFICHE GENERALI'!$B$11*B15*C15)/1000 -> 1326 | G58: =E58/F58 -> 0.1076052 | H58: =IF(G58<=1,"OK","NO") -> OK
C59: 12 | D59: =4*4.75 -> 19 | E59: =(25*(B16*C16*'VERIFICHE GENERALI'!$B$9)/1000^3)*1.3+D59*$K$47+$K$50*D59 -> 273.66898 | F59: =(0.65*'VERIFICHE GENERALI'!$B$11*B16*C16)/1000 -> 1326 | G59: =E59/F59 -> 0.20638687 | H59: =IF(G59<=1,"OK","NO") -> OK
C60: 13 | D60: =4.75*4.75 -> 22.5625 | E60: =(25*(B17*C17*'VERIFICHE GENERALI'!$B$9)/1000^3)*1.3+D60*$K$47+$K$50*D60 -> 322.78817 | F60: =(0.65*'VERIFICHE GENERALI'!$B$11*B17*C17)/1000 -> 1326 | G60: =E60/F60 -> 0.24342999 | H60: =IF(G60<=1,"OK","NO") -> OK
C61: 14 | D61: =4.75*4.75 -> 22.5625 | E61: =(25*(B18*C18*'VERIFICHE GENERALI'!$B$9)/1000^3)*1.3+D61*$K$47+$K$50*D61 -> 322.78817 | F61: =(0.65*'VERIFICHE GENERALI'!$B$11*B18*C18)/1000 -> 1326 | G61: =E61/F61 -> 0.24342999 | H61: =IF(G61<=1,"OK","NO") -> OK
C62: 15 | D62: =4.75*2 -> 9.5 | E62: =(25*(B19*C19*'VERIFICHE GENERALI'!$B$9)/1000^3)*1.3+D62*$K$47+$K$50*D62 -> 142.68449 | F62: =(0.65*'VERIFICHE GENERALI'!$B$11*B19*C19)/1000 -> 1326 | G62: =E62/F62 -> 0.1076052 | H62: =IF(G62<=1,"OK","NO") -> OK
C63: 16 | D63: =2*2 -> 4 | E63: =(25*(B20*C20*'VERIFICHE GENERALI'!$B$9)/1000^3)*1.3+D63*$K$47+$K$50*D63 -> 66.851365 | F63: =(0.65*'VERIFICHE GENERALI'!$B$11*B20*C20)/1000 -> 1326 | G63: =E63/F63 -> 0.050415811 | H63: =IF(G63<=1,"OK","NO") -> OK
C64: 17 | D64: =4*2 -> 8 | E64: =(25*(B21*C21*'VERIFICHE GENERALI'!$B$9)/1000^3)*1.3+D64*$K$47+$K$50*D64 -> 122.00273 | F64: =(0.65*'VERIFICHE GENERALI'!$B$11*B21*C21)/1000 -> 1326 | G64: =E64/F64 -> 0.092008092 | H64: =IF(G64<=1,"OK","NO") -> OK
...
