Workbook

Sheet SLU
A1: TRAVI D'INTERPIANO | P1: b | Q1: 300 | R1: mm
A2: TELAIO 1 | B2: $M^+_{max}$ | C2: $As^+_{min}$ | D2: $\phi$ | E2: N$\phi$ | F2: $As^+$ | G2: $M^-_{max}$ | H2: $As^-_{min}$ | I2: $\phi$ | J2: N$\phi$ | K2: $As^-$ | P2: h | Q2: =500 -> 500 | R2: mm
A3: Campata | B3: KNm | C3: mm^2 | D3: mm | E3: - | F3: mm^2 | G3: KNm | H3: mm^2 | I3: mm | J3: - | K3: mm^2 | P3: d | Q3: =Q2-40 -> 460 | R3: mm
A4: 1 | B4: 71.45 | C4: =(B4*1000^2)/(0.9*SLU!$Q$3*SLU!$Q$4) -> 441.04938 | D4: 14 | E4: =ROUNDUP(C4/(PI()*D4^2/4),0) -> 3 | F4: =E4*D4^2*PI()/4 -> 461.81412 | G4: 85.23 | H4: =(G4*1000^2)/(0.9*SLU!$Q$3*SLU!$Q$4) -> 526.11111 | I4: 18 | J4: 4 | K4: =J4*I4^2*PI()/4 -> 1017.876 | P4: fyk | Q4: =450/1.15 -> 391.30435 | R4: N/mm^2
A5: 2 | B5: 130 | C5: =(B5*1000^2)/(0.9*SLU!$Q$3*SLU!$Q$4) -> 802.46914 | D5: 14 | E5: =ROUNDUP(C5/(PI()*D5^2/4),0) -> 6 | F5: =E5*D5^2*PI()/4 -> 923.62824 | G5: 164.7 | H5: =(G5*1000^2)/(0.9*SLU!$Q$3*SLU!$Q$4) -> 1016.6667 | I5: 18 | J5: =ROUNDUP(H5/(PI()*I5^2/4),0) -> 4 | K5: =J5*I5^2*PI()/4 -> 1017.876 | P5: f_ck | Q5: =25 -> 25 | R5: N/mm^2
A6: 3 | B6: 71.44 | C6: =(B6*1000^2)/(0.9*SLU!$Q$3*SLU!$Q$4) -> 440.98765 | D6: 14 | E6: =ROUNDUP(C6/(PI()*D6^2/4),0) -> 3 | F6: =E6*D6^2*PI()/4 -> 461.81412 | G6: 85.27 | H6: =(G6*1000^2)/(0.9*SLU!$Q$3*SLU!$Q$4) -> 526.35802 | I6: 18 | J6: 4 | K6: =J6*I6^2*PI()/4 -> 1017.876 | P6: f_ctm | Q6: =0.3*Q5^(2/3) -> 2.5649639 | R6: N/mm^2
A7: TELAIO 2 | B7: $M^+_{max}$ | C7: $A^+_s$ | D7: $\phi$ | E7: N$\phi$ | F7: $As^+$ | G7: $M^-_{max}$ | H7: $A^-_s$ | I7: $\phi$ | J7: N$\phi$ | K7: $As^-$ | P7: A_S^{min}
A8: Campata | B8: KNm | C8: mm^2 | D8: mm | E8: - | F8: mm^2 | G8: KNm | H8: mm^2 | I8: mm | J8: - | K8: mm^2
A9: 1 | B9: 60.17 | C9: =(B9*1000^2)/(0.9*SLU!$Q$3*SLU!$Q$4) -> 371.41975 | D9: 14 | E9: =ROUNDUP(C9/(PI()*D9^2/4),0) -> 3 | F9: =E9*D9^2*PI()/4 -> 461.81412 | G9: 71.77 | H9: =(G9*1000^2)/(0.9*SLU!$Q$3*SLU!$Q$4) -> 443.02469 | I9: 18 | J9: 4 | K9: =J9*I9^2*PI()/4 -> 1017.876
A10: 2 | B10: 109 | C10: =(B10*1000^2)/(0.9*SLU!$Q$3*SLU!$Q$4) -> 672.83951 | D10: 18 | E10: =ROUNDUP(C10/(PI()*D10^2/4),0) -> 3 | F10: =E10*D10^2*PI()/4 -> 763.40701 | G10: 138.7 | H10: =(G10*1000^2)/(0.9*SLU!$Q$3*SLU!$Q$4) -> 856.17284 | I10: 18 | J10: =ROUNDUP(H10/(PI()*I10^2/4),0) -> 4 | K10: =J10*I10^2*PI()/4 -> 1017.876
A11: 3 | B11: 60.17 | C11: =(B11*1000^2)/(0.9*SLU!$Q$3*SLU!$Q$4) -> 371.41975 | D11: 14 | E11: =ROUNDUP(C11/(PI()*D11^2/4),0) -> 3 | F11: =E11*D11^2*PI()/4 -> 461.81412 | G11: 71.77 | H11: =(G11*1000^2)/(0.9*SLU!$Q$3*SLU!$Q$4) -> 443.02469 | I11: 18 | J11: 4 | K11: =J11*I11^2*PI()/4 -> 1017.876
A12: TELAIO 3 | B12: $M^+_{max}$ | C12: $A^+_s$ | D12: $\phi$ | E12: N$\phi$ | F12: $As^+$ | G12: $M^-_{max}$ | H12: $A^+_s$ | I12: $\phi$ | J12: N$\phi$ | K12: $As^-$
A13: Campata | B13: KNm | C13: mm^2 | D13: mm | E13: - | F13: mm^2 | G13: KNm | H13: mm^2 | I13: mm | J13: - | K13: mm^2
A14: 1 | B14: 71.45 | C14: =(B14*1000^2)/(0.9*SLU!$Q$3*SLU!$Q$4) -> 441.04938 | D14: 14 | E14: =ROUNDUP(C14/(PI()*D14^2/4),0) -> 3 | F14: =E14*D14^2*PI()/4 -> 461.81412 | G14: 85.23 | H14: =(G14*1000^2)/(0.9*SLU!$Q$3*SLU!$Q$4) -> 526.11111 | I14: 18 | J14: 4 | K14: =J14*I14^2*PI()/4 -> 1017.876
A15: 2 | B15: 130.4 | C15: =(B15*1000^2)/(0.9*SLU!$Q$3*SLU!$Q$4) -> 804.93827 | D15: 14 | E15: =ROUNDUP(C15/(PI()*D15^2/4),0) -> 6 | F15: =E15*D15^2*PI()/4 -> 923.62824 | G15: 164.7 | H15: =(G15*1000^2)/(0.9*SLU!$Q$3*SLU!$Q$4) -> 1016.6667 | I15: 18 | J15: =ROUNDUP(H15/(PI()*I15^2/4),0) -> 4 | K15: =J15*I15^2*PI()/4 -> 1017.876
A16: 3 | B16: 71.45 | C16: =(B16*1000^2)/(0.9*SLU!$Q$3*SLU!$Q$4) -> 441.04938 | D16: 14 | E16: =ROUNDUP(C16/(PI()*D16^2/4),0) -> 3 | F16: =E16*D16^2*PI()/4 -> 461.81412 | G16: 85.27 | H16: =(G16*1000^2)/(0.9*SLU!$Q$3*SLU!$Q$4) -> 526.35802 | I16: 18 | J16: 4 | K16: =J16*I16^2*PI()/4 -> 1017.876
A17: TRAVI DI COPERTURA
A18: TELAIO 1 | B18: $M^+_{max}$ | C18: $As^+_{min}$ | D18: $\phi$ | E18: N$\phi$ | F18: $As^+$ | G18: $M^-_{max}$ | H18: $As^-_{min}$ | I18: $\phi$ | J18: N$\phi$ | K18: $As^-$ | O18: b | P18: 300 | Q18: mm
A19: Campata | B19: KNm | C19: mm^2 | D19: mm | E19: - | F19: mm^2 | G19: KNm | H19: mm^2 | I19: mm | J19: - | K19: mm^2 | O19: h | P19: 400 | Q19: mm
A20: 1 | B20: 20.67 | C20: =(B20*1000^2)/(0.9*SLU!$Q$3*SLU!$Q$4) -> 127.59259 | D20: 14 | E20: =ROUNDUP(C20/(PI()*D20^2/4),0) -> 1 | F20: =E20*D20^2*PI()/4 -> 153.93804 | G20: 30.44 | H20: =(G20*1000^2)/(0.9*SLU!$Q$3*SLU!$Q$4) -> 187.90123 | I20: 14 | J20: =ROUNDUP(H20/(PI()*I20^2/4),0) -> 2 | K20: =J20*I20^2*PI()/4 -> 307.87608 | O20: d | P20: =P19-40 -> 360 | Q20: mm
A21: 2 | B21: 40.89 | C21: =(B21*1000^2)/(0.9*SLU!$Q$3*SLU!$Q$4) -> 252.40741 | D21: 14 | E21: =ROUNDUP(C21/(PI()*D21^2/4),0) -> 2 | F21: =E21*D21^2*PI()/4 -> 307.87608 | G21: 51.7 | H21: =(G21*1000^2)/(0.9*SLU!$Q$3*SLU!$Q$4) -> 319.1358 | I21: 14 | J21: =ROUNDUP(H21/(PI()*I21^2/4),0) -> 3 | K21: =J21*I21^2*PI()/4 -> 461.81412 | O21: fyk | P21: =450/1.15 -> 391.30435 | Q21: N/mm^2
A22: 3 | B22: 20.67 | C22: =(B22*1000^2)/(0.9*SLU!$Q$3*SLU!$Q$4) -> 127.59259 | D22: 14 | E22: =ROUNDUP(C22/(PI()*D22^2/4),0) -> 1 | F22: =E22*D22^2*PI()/4 -> 153.93804 | G22: 51.7 | H22: =(G22*1000^2)/(0.9*SLU!$Q$3*SLU!$Q$4) -> 319.1358 | I22: 14 | J22: =ROUNDUP(H22/(PI()*I22^2/4),0) -> 3 | K22: =J22*I22^2*PI()/4 -> 461.81412 | O22: f_ck | P22: =25 -> 25 | Q22: N/mm^2
A23: TELAIO 2 | B23: $M^+_{max}$ | C23: $A^+_s$ | D23: $\phi$ | E23: N$\phi$ | F23: $As^+$ | G23: $M^-_{max}$ | H23: $A^-_s$ | I23: $\phi$ | J23: N$\phi$ | K23: $As^-$ | O23: f_ctm | P23: =0.3*P22^(2/3) -> 2.5649639 | Q23: N/mm^2
A24: Campata | B24: KNm | C24: mm^2 | D24: mm | E24: - | F24: mm^2 | G24: KNm | H24: mm^2 | I24: mm | J24: - | K24: mm^2 | O24: A_S^{min}
A25: 1 | B25: 41.34 | C25: =(B25*1000^2)/(0.9*SLU!$Q$3*SLU!$Q$4) -> 255.18519 | D25: 14 | E25: =ROUNDUP(C25/(PI()*D25^2/4),0) -> 2 | F25: =E25*D25^2*PI()/4 -> 307.87608 | G25: 60.89 | H25: =(G25*1000^2)/(0.9*SLU!$Q$3*SLU!$Q$4) -> 375.8642 | I25: 14 | J25: =ROUNDUP(H25/(PI()*I25^2/4),0) -> 3 | K25: =J25*I25^2*PI()/4 -> 461.81412
A26: 2 | B26: 81.78 | C26: =(B26*1000^2)/(0.9*SLU!$Q$3*SLU!$Q$4) -> 504.81481 | D26: 18 | E26: =ROUNDUP(C26/(PI()*D26^2/4),0) -> 2 | F26: =E26*D26^2*PI()/4 -> 508.93801 | G26: 103.4 | H26: =(G26*1000^2)/(0.9*SLU!$Q$3*SLU!$Q$4) -> 638.2716 | I26: 18 | J26: =ROUNDUP(H26/(PI()*I26^2/4),0) -> 3 | K26: =J26*I26^2*PI()/4 -> 763.40701
A27: 3 | B27: 41.34 | C27: =(B27*1000^2)/(0.9*SLU!$Q$3*SLU!$Q$4) -> 255.18519 | D27: 14 | E27: =ROUNDUP(C27/(PI()*D27^2/4),0) -> 2 | F27: =E27*D27^2*PI()/4 -> 307.87608 | G27: 103.4 | H27: =(G27*1000^2)/(0.9*SLU!$Q$3*SLU!$Q$4) -> 638.2716 | I27: 18 | J27: =ROUNDUP(H27/(PI()*I27^2/4),0) -> 3 | K27: =J27*I27^2*PI()/4 -> 763.40701
A28: TELAIO 3 | B28: $M^+_{max}$ | C28: $A^+_s$ | D28: $\phi$ | E28: N$\phi$ | F28: $As^+$ | G28: $M^-_{max}$ | H28: $A^+_s$ | I28: $\phi$ | J28: N$\phi$ | K28: $As^-$
A29: Campata | B29: KNm | C29: mm^2 | D29: mm | E29: - | F29: mm^2 | G29: KNm | H29: mm^2 | I29: mm | J29: - | K29: mm^2
A30: 1 | B30: 49.08 | C30: =(B30*1000^2)/(0.9*SLU!$Q$3*SLU!$Q$4) -> 302.96296 | D30: 14 | E30: =ROUNDUP(C30/(PI()*D30^2/4),0) -> 2 | F30: =E30*D30^2*PI()/4 -> 307.87608 | G30: 72.3 | H30: =(G30*1000^2)/(0.9*SLU!$Q$3*SLU!$Q$4) -> 446.2963 | I30: 14 | J30: =ROUNDUP(H30/(PI()*I30^2/4),0) -> 3 | K30: =J30*I30^2*PI()/4 -> 461.81412
A31: 2 | B31: 97.11 | C31: =(B31*1000^2)/(0.9*SLU!$Q$3*SLU!$Q$4) -> 599.44444 | D31: 14 | E31: =ROUNDUP(C31/(PI()*D31^2/4),0) -> 4 | F31: =E31*D31^2*PI()/4 -> 615.75216 | G31: 122.8 | H31: =(G31*1000^2)/(0.9*SLU!$Q$3*SLU!$Q$4) -> 758.02469 | I31: 18 | J31: =ROUNDUP(H31/(PI()*I31^2/4),0) -> 3 | K31: =J31*I31^2*PI()/4 -> 763.40701
A32: 3 | B32: 49.08 | C32: =(B32*1000^2)/(0.9*SLU!$Q$3*SLU!$Q$4) -> 302.96296 | D32: 14 | E32: =ROUNDUP(C32/(PI()*D32^2/4),0) -> 2 | F32: =E32*D32^2*PI()/4 -> 307.87608 | G32: 122.8 | H32: =(G32*1000^2)/(0.9*SLU!$Q$3*SLU!$Q$4) -> 758.02469 | I32: 14 | J32: =ROUNDUP(H32/(PI()*I32^2/4),0) -> 5 | K32: =J32*I32^2*PI()/4 -> 769.6902

Sheet TAGLIO SLV (trave spessore) 
A1: P1 | B1: SEZ. | C1: $A_{sup}$ | H1: $A_{inf}$ | M1: $\rho_{sup}$ | O1: $\rho_{inf}$ | Q1: y | T1: $\rho_{min}$ | U1: $\rho_{max}$ | W1: TRAVE ESTERNA
A2: Camp. | C2: $\phi$ | D2: N$\phi$ | E2: $\phi$ | F2: N$\phi$ | G2: A (mm^2) | H2: $\phi$ | I2: N$\phi$ | J2: $\phi$ | K2: N$\phi$ | L2: A (mm^2) | M2: - | O2: - | Q2: mm | T2: - | U2: - | W2: campata 1
A3: 1 | B3: start | C3: 12 | D3: 3 | E3: 12 | F3: 3 | G3: =(C3^2/4*D3+E3^2/4*F3)*PI() -> 678.58401 | H3: 12 | I3: 3 | J3: 12 | K3: 3 | L3: =(H3^2/4*I3+J3^2/4*K3)*PI() -> 678.58401 | M3: =G3/($X$3*$X$4) -> 0.0061689456 | N3: =IF($T$3<=M3,"OK","NO") -> OK | O3: =L3/($X$3*$X$4) -> 0.0061689456 | P3: =IF(O3>$T$3,"OK","NO") -> OK | Q3: =ABS($X$7*(G3-L3)/($X$15*0.8*$X$3)) -> 0 | T3: =1.4/$X$6 -> 0.0031111111 | U3: =3.5/$X$6 -> 0.0077777778 | W3: b | X3: 500 | Y3: mm
B4: end | C4: 12 | D4: 3 | E4: 12 | F4: 3 | G4: =(C4^2/4*D4+E4^2/4*F4)*PI() -> 678.58401 | H4: 12 | I4: 3 | J4: 12 | K4: 3 | L4: =(H4^2/4*I4+J4^2/4*K4)*PI() -> 678.58401 | M4: =G4/($X$3*$X$4) -> 0.0061689456 | N4: =IF($T$3<=M4,"OK","NO") -> OK | O4: =L4/($X$3*$X$4) -> 0.0061689456 | P4: =IF(O4>$T$3,"OK","NO") -> OK | Q4: =ABS($X$7*(G4-L4)/($X$15*0.8*$X$3)) -> 0 | W4: h | X4: 220 | Y4: mm
A5: 2 | B5: start | C5: 12 | D5: 3 | E5: 12 | F5: 3 | G5: =(C5^2/4*D5+E5^2/4*F5)*PI() -> 678.58401 | H5: 12 | I5: 3 | J5: 12 | K5: 3 | L5: =(H5^2/4*I5+J5^2/4*K5)*PI() -> 678.58401 | M5: =G5/($X$3*$X$4) -> 0.0061689456 | N5: =IF($T$3<=M5,"OK","NO") -> OK | O5: =L5/($X$3*$X$4) -> 0.0061689456 | P5: =IF(O5>$T$3,"OK","NO") -> OK | Q5: =ABS($X$7*(G5-L5)/($X$15*0.8*$X$3)) -> 0 | W5: d | X5: =X4-40 -> 180
B6: end | C6: 12 | D6: 3 | E6: 12 | F6: 3 | G6: =(C6^2/4*D6+E6^2/4*F6)*PI() -> 678.58401 | H6: 12 | I6: 3 | J6: 12 | K6: 3 | L6: =(H6^2/4*I6+J6^2/4*K6)*PI() -> 678.58401 | M6: =G6/($X$3*$X$4) -> 0.0061689456 | N6: =IF($T$3<=M6,"OK","NO") -> OK | O6: =L6/($X$3*$X$4) -> 0.0061689456 | P6: =IF(O6>$T$3,"OK","NO") -> OK | Q6: =ABS($X$7*(G6-L6)/($X$15*0.8*$X$3)) -> 0 | W6: $f_{yk}$ | X6: =450 -> 450 | Y6: N/mm^2
A7: 3 | B7: start | C7: 12 | D7: 3 | E7: 12 | F7: 3 | G7: =(C7^2/4*D7+E7^2/4*F7)*PI() -> 678.58401 | H7: 12 | I7: 3 | J7: 12 | K7: 3 | L7: =(H7^2/4*I7+J7^2/4*K7)*PI() -> 678.58401 | M7: =G7/($X$3*$X$4) -> 0.0061689456 | N7: =IF($T$3<=M7,"OK","NO") -> OK | O7: =L7/($X$3*$X$4) -> 0.0061689456 | P7: =IF(O7>$T$3,"OK","NO") -> OK | Q7: =ABS($X$7*(G7-L7)/($X$15*0.8*$X$3)) -> 0 | W7: $f_{yd}$ | X7: =X6/1.15 -> 391.30435
B8: end | C8: 12 | D8: 3 | E8: 12 | F8: 3 | G8: =(C8^2/4*D8+E8^2/4*F8)*PI() -> 678.58401 | H8: 12 | I8: 3 | J8: 12 | K8: 3 | L8: =(H8^2/4*I8+J8^2/4*K8)*PI() -> 678.58401 | M8: =G8/($X$3*$X$4) -> 0.0061689456 | N8: =IF($T$3<=M8,"OK","NO") -> OK | O8: =L8/($X$3*$X$4) -> 0.0061689456 | P8: =IF(O8>$T$3,"OK","NO") -> OK | Q8: =ABS($X$7*(G8-L8)/($X$15*0.8*$X$3)) -> 0 | W8: $A_s$ | X8: =1.4/X6*X3*X4 -> 342.22222 | Y8: mm^2
A9: 4 | B9: start | C9: 12 | D9: 3 | E9: 12 | F9: 3 | G9: =(C9^2/4*D9+E9^2/4*F9)*PI() -> 678.58401 | H9: 12 | I9: 3 | J9: 12 | K9: 3 | L9: =(H9^2/4*I9+J9^2/4*K9)*PI() -> 678.58401 | M9: =G9/($X$3*$X$4) -> 0.0061689456 | N9: =IF($T$3<=M9,"OK","NO") -> OK | O9: =L9/($X$3*$X$4) -> 0.0061689456 | P9: =IF(O9>$T$3,"OK","NO") -> OK | Q9: =ABS($X$7*(G9-L9)/($X$15*0.8*$X$3)) -> 0 | W9: $A_s-A_s^{comp}$ | X9: =3.5/X6*X3*X4 -> 855.55556 | Y9: mm^2
B10: end | C10: 12 | D10: 3 | E10: 12 | F10: 3 | G10: =(C10^2/4*D10+E10^2/4*F10)*PI() -> 678.58401 | H10: 12 | I10: 3 | J10: 12 | K10: 3 | L10: =(H10^2/4*I10+J10^2/4*K10)*PI() -> 678.58401 | M10: =G10/($X$3*$X$4) -> 0.0061689456 | N10: =IF($T$3<=M10,"OK","NO") -> OK | O10: =L10/($X$3*$X$4) -> 0.0061689456 | P10: =IF(O10>$T$3,"OK","NO") -> OK | Q10: =ABS($X$7*(G10-L10)/($X$15*0.8*$X$3)) -> 0 | W10: $\rho_{min}$ | X10: =X8/(X4*X3) -> 0.0031111111
A11: P2 | B11: SEZ. | C11: $A_{sup}$ | H11: $A_{inf}$ | M11: $\rho_{sup}$ | O11: $\rho_{inf}$ | Q11: y | W11: $\rho_{comp}$ | X11: =0.25*X10 -> 0.00077777778
A12: Camp. | C12: $\phi$ | D12: N$\phi$ | E12: $\phi$ | F12: N$\phi$ | G12: A (mm^2) | H12: $\phi$ | I12: N$\phi$ | J12: $\phi$ | K12: N$\phi$ | L12: A (mm^2) | M12: - | O12: - | Q12: mm | W12: $\rho_{comp}$ | X12: =0.5*X10 -> 0.0015555556 | Y12: Nelle zone dissipative
A13: 1 | B13: start | C13: 12 | D13: 3 | E13: 12 | F13: 3 | G13: =(C13^2/4*D13+E13^2/4*F13)*PI() -> 678.58401 | H13: 12 | I13: 3 | J13: 12 | K13: 3 | L13: =(H13^2/4*I13+J13^2/4*K13)*PI() -> 678.58401 | M13: =G13/($X$3*$X$4) -> 0.0061689456 | N13: =IF($T$3<=M13,"OK","NO") -> OK | O13: =L13/($X$3*$X$4) -> 0.0061689456 | P13: =IF(O13>$T$3,"OK","NO") -> OK | Q13: =ABS($X$7*(G13-L13)/($X$15*0.8*$X$3)) -> 0
B14: end | C14: 12 | D14: 3 | E14: 12 | F14: 3 | G14: =(C14^2/4*D14+E14^2/4*F14)*PI() -> 678.58401 | H14: 12 | I14: 3 | J14: 12 | K14: 3 | L14: =(H14^2/4*I14+J14^2/4*K14)*PI() -> 678.58401 | M14: =G14/($X$3*$X$4) -> 0.0061689456 | N14: =IF($T$3<=M14,"OK","NO") -> OK | O14: =L14/($X$3*$X$4) -> 0.0061689456 | P14: =IF(O14>$T$3,"OK","NO") -> OK | Q14: =ABS($X$7*(G14-L14)/($X$15*0.8*$X$3)) -> 0 | X14: =269*1000^2/(0.9*X5*391) -> 4246.7873
A15: 2 | B15: start | C15: 12 | D15: 3 | E15: 12 | F15: 3 | G15: =(C15^2/4*D15+E15^2/4*F15)*PI() -> 678.58401 | H15: 12 | I15: 3 | J15: 12 | K15: 3 | L15: =(H15^2/4*I15+J15^2/4*K15)*PI() -> 678.58401 | M15: =G15/($X$3*$X$4) -> 0.0061689456 | N15: =IF($T$3<=M15,"OK","NO") -> OK | O15: =L15/($X$3*$X$4) -> 0.0061689456 | P15: =IF(O15>$T$3,"OK","NO") -> OK | Q15: =ABS($X$7*(G15-L15)/($X$15*0.8*$X$3)) -> 0 | W15: fcd | X15: =0.85*30/1.5 -> 17
B16: end | C16: 12 | D16: 3 | E16: 12 | F16: 3 | G16: =(C16^2/4*D16+E16^2/4*F16)*PI() -> 678.58401 | H16: 12 | I16: 3 | J16: 12 | K16: 3 | L16: =(H16^2/4*I16+J16^2/4*K16)*PI() -> 678.58401 | M16: =G16/($X$3*$X$4) -> 0.0061689456 | N16: =IF($T$3<=M16,"OK","NO") -> OK | O16: =L16/($X$3*$X$4) -> 0.0061689456 | P16: =IF(O16>$T$3,"OK","NO") -> OK | Q16: =ABS($X$7*(G16-L16)/($X$15*0.8*$X$3)) -> 0 | W16: Es | X16: 210000
A17: 3 | B17: start | C17: 12 | D17: 3 | E17: 12 | F17: 3 | G17: =(C17^2/4*D17+E17^2/4*F17)*PI() -> 678.58401 | H17: 12 | I17: 3 | J17: 12 | K17: 3 | L17: =(H17^2/4*I17+J17^2/4*K17)*PI() -> 678.58401 | M17: =G17/($X$3*$X$4) -> 0.0061689456 | N17: =IF($T$3<=M17,"OK","NO") -> OK | O17: =L17/($X$3*$X$4) -> 0.0061689456 | P17: =IF(O17>$T$3,"OK","NO") -> OK | Q17: =ABS($X$7*(G17-L17)/($X$15*0.8*$X$3)) -> 0
B18: end | C18: 12 | D18: 3 | E18: 12 | F18: 3 | G18: =(C18^2/4*D18+E18^2/4*F18)*PI() -> 678.58401 | H18: 12 | I18: 3 | J18: 12 | K18: 3 | L18: =(H18^2/4*I18+J18^2/4*K18)*PI() -> 678.58401 | M18: =G18/($X$3*$X$4) -> 0.0061689456 | N18: =IF($T$3<=M18,"OK","NO") -> OK | O18: =L18/($X$3*$X$4) -> 0.0061689456 | P18: =IF(O18>$T$3,"OK","NO") -> OK | Q18: =ABS($X$7*(G18-L18)/($X$15*0.8*$X$3)) -> 0
A19: 4 | B19: start | C19: 12 | D19: 3 | E19: 12 | F19: 3 | G19: =(C19^2/4*D19+E19^2/4*F19)*PI() -> 678.58401 | H19: 12 | I19: 3 | J19: 12 | K19: 3 | L19: =(H19^2/4*I19+J19^2/4*K19)*PI() -> 678.58401 | M19: =G19/($X$3*$X$4) -> 0.0061689456 | N19: =IF($T$3<=M19,"OK","NO") -> OK | O19: =L19/($X$3*$X$4) -> 0.0061689456 | P19: =IF(O19>$T$3,"OK","NO") -> OK | Q19: =ABS($X$7*(G19-L19)/($X$15*0.8*$X$3)) -> 0
B20: end | C20: 12 | D20: 3 | E20: 12 | F20: 3 | G20: =(C20^2/4*D20+E20^2/4*F20)*PI() -> 678.58401 | H20: 12 | I20: 3 | J20: 12 | K20: 3 | L20: =(H20^2/4*I20+J20^2/4*K20)*PI() -> 678.58401 | M20: =G20/($X$3*$X$4) -> 0.0061689456 | N20: =IF($T$3<=M20,"OK","NO") -> OK | O20: =L20/($X$3*$X$4) -> 0.0061689456 | P20: =IF(O20>$T$3,"OK","NO") -> OK | Q20: =ABS($X$7*(G20-L20)/($X$15*0.8*$X$3)) -> 0
A21: P3 | B21: SEZ. | C21: $A_{sup}$ | H21: $A_{inf}$ | M21: $\rho_{sup}$ | O21: $\rho_{inf}$ | Q21: y
A22: Camp. | C22: $\phi$ | D22: N$\phi$ | E22: $\phi$ | F22: N$\phi$ | G22: A (mm^2) | H22: $\phi$ | I22: N$\phi$ | J22: $\phi$ | K22: N$\phi$ | L22: A (mm^2) | M22: - | O22: - | Q22: mm
A23: 1 | B23: start | C23: 12 | D23: 3 | E23: 12 | F23: 3 | G23: =(C23^2/4*D23+E23^2/4*F23)*PI() -> 678.58401 | H23: 12 | I23: 3 | J23: 12 | K23: 3 | L23: =(H23^2/4*I23+J23^2/4*K23)*PI() -> 678.58401 | M23: =G23/($X$3*$X$4) -> 0.0061689456 | N23: =IF($T$3<=M23,"OK","NO") -> OK | O23: =L23/($X$3*$X$4) -> 0.0061689456 | P23: =IF(O23>$T$3,"OK","NO") -> OK | Q23: =ABS($X$7*(G23-L23)/($X$15*0.8*$X$3)) -> 0
B24: end | C24: 12 | D24: 3 | E24: 12 | F24: 3 | G24: =(C24^2/4*D24+E24^2/4*F24)*PI() -> 678.58401 | H24: 12 | I24: 3 | J24: 12 | K24: 3 | L24: =(H24^2/4*I24+J24^2/4*K24)*PI() -> 678.58401 | M24: =G24/($X$3*$X$4) -> 0.0061689456 | N24: =IF($T$3<=M24,"OK","NO") -> OK | O24: =L24/($X$3*$X$4) -> 0.0061689456 | P24: =IF(O24>$T$3,"OK","NO") -> OK | Q24: =ABS($X$7*(G24-L24)/($X$15*0.8*$X$3)) -> 0
A25: 2 | B25: start | C25: 12 | D25: 3 | E25: 12 | F25: 3 | G25: =(C25^2/4*D25+E25^2/4*F25)*PI() -> 678.58401 | H25: 12 | I25: 3 | J25: 12 | K25: 3 | L25: =(H25^2/4*I25+J25^2/4*K25)*PI() -> 678.58401 | M25: =G25/($X$3*$X$4) -> 0.0061689456 | N25: =IF($T$3<=M25,"OK","NO") -> OK | O25: =L25/($X$3*$X$4) -> 0.0061689456 | P25: =IF(O25>$T$3,"OK","NO") -> OK | Q25: =ABS($X$7*(G25-L25)/($X$15*0.8*$X$3)) -> 0
B26: end | C26: 12 | D26: 3 | E26: 12 | F26: 3 | G26: =(C26^2/4*D26+E26^2/4*F26)*PI() -> 678.58401 | H26: 12 | I26: 3 | J26: 12 | K26: 3 | L26: =(H26^2/4*I26+J26^2/4*K26)*PI() -> 678.58401 | M26: =G26/($X$3*$X$4) -> 0.0061689456 | N26: =IF($T$3<=M26,"OK","NO") -> OK | O26: =L26/($X$3*$X$4) -> 0.0061689456 | P26: =IF(O26>$T$3,"OK","NO") -> OK | Q26: =ABS($X$7*(G26-L26)/($X$15*0.8*$X$3)) -> 0
A27: 3 | B27: start | C27: 12 | D27: 3 | E27: 12 | F27: 3 | G27: =(C27^2/4*D27+E27^2/4*F27)*PI() -> 678.58401 | H27: 12 | I27: 3 | J27: 12 | K27: 3 | L27: =(H27^2/4*I27+J27^2/4*K27)*PI() -> 678.58401 | M27: =G27/($X$3*$X$4) -> 0.0061689456 | N27: =IF($T$3<=M27,"OK","NO") -> OK | O27: =L27/($X$3*$X$4) -> 0.0061689456 | P27: =IF(O27>$T$3,"OK","NO") -> OK | Q27: =ABS($X$7*(G27-L27)/($X$15*0.8*$X$3)) -> 0
B28: end | C28: 12 | D28: 3 | E28: 12 | F28: 3 | G28: =(C28^2/4*D28+E28^2/4*F28)*PI() -> 678.58401 | H28: 12 | I28: 3 | J28: 12 | K28: 3 | L28: =(H28^2/4*I28+J28^2/4*K28)*PI() -> 678.58401 | M28: =G28/($X$3*$X$4) -> 0.0061689456 | N28: =IF($T$3<=M28,"OK","NO") -> OK | O28: =L28/($X$3*$X$4) -> 0.0061689456 | P28: =IF(O28>$T$3,"OK","NO") -> OK | Q28: =ABS($X$7*(G28-L28)/($X$15*0.8*$X$3)) -> 0
A29: 4 | B29: start | C29: 12 | D29: 3 | E29: 12 | F29: 3 | G29: =(C29^2/4*D29+E29^2/4*F29)*PI() -> 678.58401 | H29: 12 | I29: 3 | J29: 12 | K29: 3 | L29: =(H29^2/4*I29+J29^2/4*K29)*PI() -> 678.58401 | M29: =G29/($X$3*$X$4) -> 0.0061689456 | N29: =IF($T$3<=M29,"OK","NO") -> OK | O29: =L29/($X$3*$X$4) -> 0.0061689456 | P29: =IF(O29>$T$3,"OK","NO") -> OK | Q29: =ABS($X$7*(G29-L29)/($X$15*0.8*$X$3)) -> 0
B30: end | C30: 12 | D30: 3 | E30: 12 | F30: 3 | G30: =(C30^2/4*D30+E30^2/4*F30)*PI() -> 678.58401 | H30: 12 | I30: 3 | J30: 12 | K30: 3 | L30: =(H30^2/4*I30+J30^2/4*K30)*PI() -> 678.58401 | M30: =G30/($X$3*$X$4) -> 0.0061689456 | N30: =IF($T$3<=M30,"OK","NO") -> OK | O30: =L30/($X$3*$X$4) -> 0.0061689456 | P30: =IF(O30>$T$3,"OK","NO") -> OK | Q30: =ABS($X$7*(G30-L30)/($X$15*0.8*$X$3)) -> 0
A31: CALCOLO TAGLIO SOLLECITANTE IN Capacity design
A33: P1 | B33: SEZ. | C33: $M_u^+}$ | D33: $M_u^-$ | E33: p (sisma) | F33: L | G33: V^+ | H33: V^-
A34: Camp. | C34: KNm | D34: KNm | E34: KN/m | F34: m | G34: KN | H34: KN
A35: 1 | B35: start | C35: =(G3*$X$7*($X$4-40-0.8*Q3/2)+L3*$X$7*(0.8*Q3/2-40))/1000^2 -> 37.174602 | D35: =-(L3*$X$7*($X$4-40-0.8*Q3/2)+G3*$X$7*(0.8*Q3/2-40))/1000^2 -> -37.174602 | E35: =7.297*2+7.78 -> 22.374 | F35: 4 | G35: =$E35*$F35/2+($C35+$C36)/$F35*1.1 -> 65.194031 | H35: =$E35*$F35/2+($D35+$D36)/$F35*1.1 -> 24.301969
B36: end | C36: =(L4*$X$7*($X$4-40-0.8*Q4/2)+G4*$X$7*(0.8*Q4/2-40))/1000^2 -> 37.174602 | D36: =-(G4*$X$7*($X$4-40-0.8*Q4/2)+L4*$X$7*(0.8*Q4/2-40))/1000^2 -> -37.174602 | E36: =7.297*2+7.78 -> 22.374 | F36: 4 | G36: =-$E36*$F36/2+($C35+$C36)/$F36*1.1 -> -24.301969 | H36: =-$E36*$F36/2+($D35+$D36)/$F36*1.1 -> -65.194031
A37: 2 | B37: start | C37: =(G5*$X$7*($X$4-40-0.8*Q5/2)+L5*$X$7*(0.8*Q5/2-40))/1000^2 -> 37.174602 | D37: =-(L5*$X$7*($X$4-40-0.8*Q5/2)+G5*$X$7*(0.8*Q5/2-40))/1000^2 -> -37.174602 | E37: =7.297*2+7.78 -> 22.374 | F37: 4 | G37: =$E37*$F37/2+($C37+$C38)/$F37*1.1 -> 65.194031 | H37: =$E37*$F37/2+($D37+$D38)/$F37*1.1 -> 24.301969
B38: end | C38: =(L6*$X$7*($X$4-40-0.8*Q6/2)+G6*$X$7*(0.8*Q6/2-40))/1000^2 -> 37.174602 | D38: =-(G6*$X$7*($X$4-40-0.8*Q6/2)+L6*$X$7*(0.8*Q6/2-40))/1000^2 -> -37.174602 | E38: =7.297*2+7.78 -> 22.374 | F38: 4 | G38: =-$E38*$F38/2+($C37+$C38)/$F38*1.1 -> -24.301969 | H38: =-$E38*$F38/2+($D37+$D38)/$F38*1.1 -> -65.194031
A39: 3 | B39: start | C39: =(G7*$X$7*($X$4-40-0.8*Q7/2)+L7*$X$7*(0.8*Q7/2-40))/1000^2 -> 37.174602 | D39: =-(L7*$X$7*($X$4-40-0.8*Q7/2)+G7*$X$7*(0.8*Q7/2-40))/1000^2 -> -37.174602 | E39: =7.297*2+7.78 -> 22.374 | F39: 4 | G39: =$E39*$F39/2+($C39+$C40)/$F39*1.1 -> 65.194031 | H39: =$E39*$F39/2+($D39+$D40)/$F39*1.1 -> 24.301969
B40: end | C40: =(L8*$X$7*($X$4-40-0.8*Q8/2)+G8*$X$7*(0.8*Q8/2-40))/1000^2 -> 37.174602 | D40: =-(G8*$X$7*($X$4-40-0.8*Q8/2)+L8*$X$7*(0.8*Q8/2-40))/1000^2 -> -37.174602 | E40: =7.297*2+7.78 -> 22.374 | F40: 4 | G40: =-$E40*$F40/2+($C39+$C40)/$F40*1.1 -> -24.301969 | H40: =-$E40*$F40/2+($D39+$D40)/$F40*1.1 -> -65.194031
A41: 4 | B41: start | C41: =(G9*$X$7*($X$4-40-0.8*Q9/2)+L9*$X$7*(0.8*Q9/2-40))/1000^2 -> 37.174602 | D41: =-(L9*$X$7*($X$4-40-0.8*Q9/2)+G9*$X$7*(0.8*Q9/2-40))/1000^2 -> -37.174602 | E41: =7.297*2+7.78 -> 22.374 | F41: 4 | G41: =$E41*$F41/2+($C41+$C42)/$F41*1.1 -> 65.194031 | H41: =$E41*$F41/2+($D41+$D42)/$F41*1.1 -> 24.301969
...

Sheet TAGLIO SLV (trave esterna)
A1: P1 | B1: SEZ. | C1: $A_{sup}$ | H1: $A_{inf}$ | M1: $\rho_{sup}$ | O1: $\rho_{inf}$ | Q1: y | AE1: $\rho_{min}$ | AF1: $\rho_{max}$ | AH1: TRAVE ESTERNA | AL1: b | AM1: h | AN1: d
A2: Camp. | C2: $\phi$ | D2: N$\phi$ | E2: $\phi$ | F2: N$\phi$ | G2: A (mm^2) | H2: $\phi$ | I2: N$\phi$ | J2: $\phi$ | K2: N$\phi$ | L2: A (mm^2) | M2: - | O2: - | Q2: mm | T2: a | U2: b | V2: c | W2: y | X2: $\delta$ | Z2: y1 | AE2: - | AF2: - | AH2: campata 1 | AL2: mm | AM2: mm | AN2: mm
A3: 1 | B3: start | C3: 20 | D3: 2 | E3: 18 | F3: 2 | G3: =(C3^2/4*D3+E3^2/4*F3)*PI() -> 1137.2565 | H3: 18 | I3: 2 | J3: 18 | K3: 2 | L3: =(H3^2/4*I3+J3^2/4*K3)*PI() -> 1017.876 | M3: =G3/($AL$3*$AM$3) -> 0.0075817103 | N3: =IF($AE$3<=M3,"OK","NO") -> OK | O3: =L3/($AL$3*$AM$3) -> 0.0067858401 | P3: =IF(O3>$AE$3,"OK","NO") -> OK | Q3: =ABS($AI$6*(G3-L3)/($AI$14*0.8*$AI$3)) -> 11.449538 | T3: =$AI$3*$AI$14*0.8 -> 4080 | U3: =L3*$AI$15*3.5/1000-G3*$AI$6 -> 303125.45 | V3: =$AI$6,$AI$6,L3*$AI$15*(3.5/1000)*($AI$4-40) -> #VALUE! | W3: =CONCATENATE(T3," y^2 ",IF(U3>0," + "," "),U3," y",IF(V3>0," + "," "),V3, " = 0 ") -> #VALUE! | X3: =U3^2-4*T3*V3 -> #VALUE! | Y3: =IF(X3>0,"2 soluzioni distinte",IF(X3=0,"2 soluzioni coincidenti","nessuna soluzione")) -> #VALUE! | Z3: =IF(X3<0," ",(-U3+SQRT(X3))/(2*T3)) -> #VALUE! | AA3: =IF(X3<0," ",(-U3-SQRT(X3))/(2*T3)) -> #VALUE! | AE3: =1.4/$AI$5 -> 0.0031111111 | AF3: =3.5/$AI$5 -> 0.0077777778 | AH3: b | AI3: =300 -> 300 | AJ3: mm | AL3: 300 | AM3: 500 | AN3: =AM3-40 -> 460
B4: end | C4: 18 | D4: 2 | E4: 18 | F4: 2 | G4: =(C4^2/4*D4+E4^2/4*F4)*PI() -> 1017.876 | H4: 18 | I4: 2 | J4: 18 | K4: 2 | L4: =(H4^2/4*I4+J4^2/4*K4)*PI() -> 1017.876 | M4: =G4/($AL$3*$AM$3) -> 0.0067858401 | N4: =IF($AE$3<=M4,"OK","NO") -> OK | O4: =L4/($AL$3*$AM$3) -> 0.0067858401 | P4: =IF(O4>$AE$3,"OK","NO") -> OK | Q4: =ABS($AI$6*(G4-L4)/($AI$14*0.8*$AI$3)) -> 0 | T4: =$AI$3*$AI$14*0.8 -> 4080 | U4: =G4*$AI$15*3.5/1000-L4*$AI$6 -> 349839.56 | V4: =IF($AI$15*(3.5/1000)*(AA4-40)/(AA4)>$AI$6,$AI$6,L4*$AI$15*(3.5/1000)*($AI$4-40)) -> 0 | W4: =CONCATENATE(T4," y^2 ",IF(U4>0," + "," "),U4," y",IF(V4>0," + "," "),V4, " = 0 ") -> #VALUE! | X4: =U4^2-4*T4*V4 -> #VALUE! | Y4: =IF(X4>0,"2 soluzioni distinte",IF(X4=0,"2 soluzioni coincidenti","nessuna soluzione")) -> #VALUE! | Z4: =IF(X4<0," ",(-U4+SQRT(X4))/(2*T4)) -> #VALUE! | AA4: =IF(X4<0," ",(-U4-SQRT(X4))/(2*T4)) -> #VALUE! | AH4: h | AI4: 500 | AJ4: mm
A5: 2 | B5: start | C5: 18 | D5: 2 | E5: 18 | F5: 2 | G5: =(C5^2/4*D5+E5^2/4*F5)*PI() -> 1017.876 | H5: 18 | I5: 2 | J5: 18 | K5: 2 | L5: =(H5^2/4*I5+J5^2/4*K5)*PI() -> 1017.876 | M5: =G5/($AL$3*$AM$3) -> 0.0067858401 | N5: =IF($AE$3<=M5,"OK","NO") -> OK | O5: =L5/($AL$3*$AM$3) -> 0.0067858401 | P5: =IF(O5>$AE$3,"OK","NO") -> OK | Q5: =ABS($AI$6*(G5-L5)/($AI$14*0.8*$AI$3)) -> 0 | T5: =$AI$3*$AI$14*0.8 -> 4080 | U5: =L5*$AI$15*3.5/1000-G5*$AI$6 -> 349839.56 | V5: =IF($AI$15*(3.5/1000)*(AA5-40)/(AA5)>$AI$6,$AI$6,L5*$AI$15*(3.5/1000)*($AI$4-40)) -> 0 | W5: =CONCATENATE(T5," y^2 ",IF(U5>0," + "," "),U5," y",IF(V5>0," + "," "),V5, " = 0 ") -> #VALUE! | X5: =U5^2-4*T5*V5 -> #VALUE! | Y5: =IF(X5>0,"2 soluzioni distinte",IF(X5=0,"2 soluzioni coincidenti","nessuna soluzione")) -> #VALUE! | Z5: =IF(X5<0," ",(-U5+SQRT(X5))/(2*T5)) -> #VALUE! | AA5: =IF(X5<0," ",(-U5-SQRT(X5))/(2*T5)) -> #VALUE! | AH5: $f_{yk}$ | AI5: =450 -> 450 | AJ5: N/mm^2 | AL5: 300 | AM5: 500 | AN5: =AM5-40 -> 460
B6: end | C6: 18 | D6: 2 | E6: 18 | F6: 2 | G6: =(C6^2/4*D6+E6^2/4*F6)*PI() -> 1017.876 | H6: 18 | I6: 2 | J6: 18 | K6: 2 | L6: =(H6^2/4*I6+J6^2/4*K6)*PI() -> 1017.876 | M6: =G6/($AL$3*$AM$3) -> 0.0067858401 | N6: =IF($AE$3<=M6,"OK","NO") -> OK | O6: =L6/($AL$3*$AM$3) -> 0.0067858401 | P6: =IF(O6>$AE$3,"OK","NO") -> OK | Q6: =ABS($AI$6*(G6-L6)/($AI$14*0.8*$AI$3)) -> 0 | T6: =$AI$3*$AI$14*0.8 -> 4080 | U6: =G6*$AI$15*3.5/1000-L6*$AI$6 -> 349839.56 | V6: =IF($AI$15*(3.5/1000)*(AA6-40)/(AA6)>$AI$6,$AI$6,L6*$AI$15*(3.5/1000)*($AI$4-40)) -> 0 | W6: =CONCATENATE(T6," y^2 ",IF(U6>0," + "," "),U6," y",IF(V6>0," + "," "),V6, " = 0 ") -> #VALUE! | X6: =U6^2-4*T6*V6 -> #VALUE! | Y6: =IF(X6>0,"2 soluzioni distinte",IF(X6=0,"2 soluzioni coincidenti","nessuna soluzione")) -> #VALUE! | Z6: =IF(X6<0," ",(-U6+SQRT(X6))/(2*T6)) -> #VALUE! | AA6: =IF(X6<0," ",(-U6-SQRT(X6))/(2*T6)) -> #VALUE! | AH6: $f_{yd}$ | AI6: =AI5/1.15 -> 391.30435
A7: 3 | B7: start | C7: 18 | D7: 2 | E7: 18 | F7: 2 | G7: =(C7^2/4*D7+E7^2/4*F7)*PI() -> 1017.876 | H7: 18 | I7: 2 | J7: 14 | K7: 2 | L7: =(H7^2/4*I7+J7^2/4*K7)*PI() -> 816.81409 | M7: =G7/($AL$3*$AM$3) -> 0.0067858401 | N7: =IF($AE$3<=M7,"OK","NO") -> OK | O7: =L7/($AL$3*$AM$3) -> 0.0054454273 | P7: =IF(O7>$AE$3,"OK","NO") -> OK | Q7: =ABS($AI$6*(G7-L7)/($AI$14*0.8*$AI$3)) -> 19.283433 | T7: =$AI$3*$AI$14*0.8 -> 4080 | U7: =L7*$AI$15*3.5/1000-G7*$AI$6 -> 202059.04 | V7: =IF($AI$15*(3.5/1000)*(AA7-40)/(AA7)>$AI$6,$AI$6,L7*$AI$15*(3.5/1000)*($AI$4-40)) -> 0 | W7: =CONCATENATE(T7," y^2 ",IF(U7>0," + "," "),U7," y",IF(V7>0," + "," "),V7, " = 0 ") -> #VALUE! | X7: =U7^2-4*T7*V7 -> #VALUE! | Y7: =IF(X7>0,"2 soluzioni distinte",IF(X7=0,"2 soluzioni coincidenti","nessuna soluzione")) -> #VALUE! | Z7: =IF(X7<0," ",(-U7+SQRT(X7))/(2*T7)) -> #VALUE! | AA7: =IF(X7<0," ",(-U7-SQRT(X7))/(2*T7)) -> #VALUE! | AH7: $A_s$ | AI7: =1.4/AI5*AI3*AI4 -> 466.66667 | AJ7: mm^2 | AL7: 300 | AM7: 500 | AN7: =AM7-40 -> 460
B8: end | C8: 20 | D8: 2 | E8: 18 | F8: 2 | G8: =(C8^2/4*D8+E8^2/4*F8)*PI() -> 1137.2565 | H8: 18 | I8: 2 | J8: 14 | K8: 2 | L8: =(H8^2/4*I8+J8^2/4*K8)*PI() -> 816.81409 | M8: =G8/($AL$3*$AM$3) -> 0.0075817103 | N8: =IF($AE$3<=M8,"OK","NO") -> OK | O8: =L8/($AL$3*$AM$3) -> 0.0054454273 | P8: =IF(O8>$AE$3,"OK","NO") -> OK | Q8: =ABS($AI$6*(G8-L8)/($AI$14*0.8*$AI$3)) -> 30.732972 | T8: =$AI$3*$AI$14*0.8 -> 4080 | U8: =G8*$AI$15*3.5/1000-L8*$AI$6 -> 516260.65 | V8: =IF($AI$15*(3.5/1000)*(AA8-40)/(AA8)>$AI$6,$AI$6,L8*$AI$15*(3.5/1000)*($AI$4-40)) -> 0 | W8: =CONCATENATE(T8," y^2 ",IF(U8>0," + "," "),U8," y",IF(V8>0," + "," "),V8, " = 0 ") -> #VALUE! | X8: =U8^2-4*T8*V8 -> #VALUE! | Y8: =IF(X8>0,"2 soluzioni distinte",IF(X8=0,"2 soluzioni coincidenti","nessuna soluzione")) -> #VALUE! | Z8: =IF(X8<0," ",(-U8+SQRT(X8))/(2*T8)) -> #VALUE! | AA8: =IF(X8<0," ",(-U8-SQRT(X8))/(2*T8)) -> #VALUE! | AH8: $A_s-A_s^{comp}$ | AI8: =3.5/AI5*AI3*AI4 -> 1166.6667 | AJ8: mm^2
A9: 4 | B9: start | C9: 20 | D9: 2 | E9: 18 | F9: 2 | G9: =(C9^2/4*D9+E9^2/4*F9)*PI() -> 1137.2565 | H9: 18 | I9: 2 | J9: 18 | K9: 2 | L9: =(H9^2/4*I9+J9^2/4*K9)*PI() -> 1017.876 | M9: =G9/($AL$3*$AM$3) -> 0.0075817103 | N9: =IF($AE$3<=M9,"OK","NO") -> OK | O9: =L9/($AL$3*$AM$3) -> 0.0067858401 | P9: =IF(O9>$AE$3,"OK","NO") -> OK | Q9: =ABS($AI$6*(G9-L9)/($AI$14*0.8*$AI$3)) -> 11.449538 | AH9: $\rho_{min}$ | AI9: =AI7/(AI4*AI3) -> 0.0031111111 | AL9: b | AM9: h | AN9: d
B10: end | C10: 20 | D10: 2 | E10: 18 | F10: 2 | G10: =(C10^2/4*D10+E10^2/4*F10)*PI() -> 1137.2565 | H10: 18 | I10: 2 | J10: 18 | K10: 2 | L10: =(H10^2/4*I10+J10^2/4*K10)*PI() -> 1017.876 | M10: =G10/($AL$3*$AM$3) -> 0.0075817103 | N10: =IF($AE$3<=M10,"OK","NO") -> OK | O10: =L10/($AL$3*$AM$3) -> 0.0067858401 | P10: =IF(O10>$AE$3,"OK","NO") -> OK | Q10: =ABS($AI$6*(G10-L10)/($AI$14*0.8*$AI$3)) -> 11.449538 | AH10: $\rho_{comp}$ | AI10: =0.25*AI9 -> 0.00077777778 | AL10: mm | AM10: mm | AN10: mm
A11: P2 | B11: SEZ. | C11: $A_{sup}$ | H11: $A_{inf}$ | M11: $\rho_{sup}$ | O11: $\rho_{inf}$ | Q11: y | AH11: $\rho_{comp}$ | AI11: =0.5*AI9 -> 0.0015555556 | AJ11: Nelle zone dissipative | AL11: 300 | AM11: 500 | AN11: =AM11-40 -> 460
A12: Camp. | C12: $\phi$ | D12: N$\phi$ | E12: $\phi$ | F12: N$\phi$ | G12: A (mm^2) | H12: $\phi$ | I12: N$\phi$ | J12: $\phi$ | K12: N$\phi$ | L12: A (mm^2) | M12: - | O12: - | Q12: mm
A13: 1 | B13: start | C13: 20 | D13: 2 | E13: 18 | F13: 2 | G13: =(C13^2/4*D13+E13^2/4*F13)*PI() -> 1137.2565 | H13: 18 | I13: 2 | J13: 18 | K13: 2 | L13: =(H13^2/4*I13+J13^2/4*K13)*PI() -> 1017.876 | M13: =G13/($AL$3*$AM$3) -> 0.0075817103 | N13: =IF($AE$3<=M13,"OK","NO") -> OK | O13: =L13/($AL$3*$AM$3) -> 0.0067858401 | P13: =IF(O13>$AE$3,"OK","NO") -> OK | Q13: =ABS($AI$6*(G13-L13)/($AI$14*0.8*$AI$3)) -> 11.449538 | AI13: =269*1000^2/(0.9*AN3*391) -> 1661.7863 | AL13: 300 | AM13: 500 | AN13: =AM13-40 -> 460
B14: end | C14: 18 | D14: 2 | E14: 18 | F14: 2 | G14: =(C14^2/4*D14+E14^2/4*F14)*PI() -> 1017.876 | H14: 18 | I14: 2 | J14: 18 | K14: 2 | L14: =(H14^2/4*I14+J14^2/4*K14)*PI() -> 1017.876 | M14: =G14/($AL$3*$AM$3) -> 0.0067858401 | N14: =IF($AE$3<=M14,"OK","NO") -> OK | O14: =L14/($AL$3*$AM$3) -> 0.0067858401 | P14: =IF(O14>$AE$3,"OK","NO") -> OK | Q14: =ABS($AI$6*(G14-L14)/($AI$14*0.8*$AI$3)) -> 0 | AH14: fcd | AI14: =0.85*30/1.5 -> 17
A15: 2 | B15: start | C15: 18 | D15: 2 | E15: 18 | F15: 2 | G15: =(C15^2/4*D15+E15^2/4*F15)*PI() -> 1017.876 | H15: 18 | I15: 2 | J15: 18 | K15: 2 | L15: =(H15^2/4*I15+J15^2/4*K15)*PI() -> 1017.876 | M15: =G15/($AL$3*$AM$3) -> 0.0067858401 | N15: =IF($AE$3<=M15,"OK","NO") -> OK | O15: =L15/($AL$3*$AM$3) -> 0.0067858401 | P15: =IF(O15>$AE$3,"OK","NO") -> OK | Q15: =ABS($AI$6*(G15-L15)/($AI$14*0.8*$AI$3)) -> 0 | AH15: Es | AI15: 210000 | AL15: 300 | AM15: 500 | AN15: =AM15-40 -> 460
B16: end | C16: 18 | D16: 2 | E16: 18 | F16: 2 | G16: =(C16^2/4*D16+E16^2/4*F16)*PI() -> 1017.876 | H16: 18 | I16: 2 | J16: 18 | K16: 2 | L16: =(H16^2/4*I16+J16^2/4*K16)*PI() -> 1017.876 | M16: =G16/($AL$3*$AM$3) -> 0.0067858401 | N16: =IF($AE$3<=M16,"OK","NO") -> OK | O16: =L16/($AL$3*$AM$3) -> 0.0067858401 | P16: =IF(O16>$AE$3,"OK","NO") -> OK | Q16: =ABS($AI$6*(G16-L16)/($AI$14*0.8*$AI$3)) -> 0
A17: 3 | B17: start | C17: 18 | D17: 2 | E17: 18 | F17: 2 | G17: =(C17^2/4*D17+E17^2/4*F17)*PI() -> 1017.876 | H17: 18 | I17: 2 | J17: 14 | K17: 2 | L17: =(H17^2/4*I17+J17^2/4*K17)*PI() -> 816.81409 | M17: =G17/($AL$3*$AM$3) -> 0.0067858401 | N17: =IF($AE$3<=M17,"OK","NO") -> OK | O17: =L17/($AL$3*$AM$3) -> 0.0054454273 | P17: =IF(O17>$AE$3,"OK","NO") -> OK | Q17: =ABS($AI$6*(G17-L17)/($AI$14*0.8*$AI$3)) -> 19.283433 | AL17: b | AM17: h | AN17: d
B18: end | C18: 18 | D18: 2 | E18: 18 | F18: 2 | G18: =(C18^2/4*D18+E18^2/4*F18)*PI() -> 1017.876 | H18: 18 | I18: 2 | J18: 14 | K18: 2 | L18: =(H18^2/4*I18+J18^2/4*K18)*PI() -> 816.81409 | M18: =G18/($AL$3*$AM$3) -> 0.0067858401 | N18: =IF($AE$3<=M18,"OK","NO") -> OK | O18: =L18/($AL$3*$AM$3) -> 0.0054454273 | P18: =IF(O18>$AE$3,"OK","NO") -> OK | Q18: =ABS($AI$6*(G18-L18)/($AI$14*0.8*$AI$3)) -> 19.283433 | AL18: mm | AM18: mm | AN18: mm
A19: 4 | B19: start | C19: 18 | D19: 2 | E19: 18 | F19: 2 | G19: =(C19^2/4*D19+E19^2/4*F19)*PI() -> 1017.876 | H19: 18 | I19: 2 | J19: 18 | K19: 2 | L19: =(H19^2/4*I19+J19^2/4*K19)*PI() -> 1017.876 | M19: =G19/($AL$3*$AM$3) -> 0.0067858401 | N19: =IF($AE$3<=M19,"OK","NO") -> OK | O19: =L19/($AL$3*$AM$3) -> 0.0067858401 | P19: =IF(O19>$AE$3,"OK","NO") -> OK | Q19: =ABS($AI$6*(G19-L19)/($AI$14*0.8*$AI$3)) -> 0 | AL19: 300 | AM19: 500 | AN19: =AM19-40 -> 460
B20: end | C20: 20 | D20: 2 | E20: 18 | F20: 2 | G20: =(C20^2/4*D20+E20^2/4*F20)*PI() -> 1137.2565 | H20: 18 | I20: 2 | J20: 18 | K20: 2 | L20: =(H20^2/4*I20+J20^2/4*K20)*PI() -> 1017.876 | M20: =G20/($AL$3*$AM$3) -> 0.0075817103 | N20: =IF($AE$3<=M20,"OK","NO") -> OK | O20: =L20/($AL$3*$AM$3) -> 0.0067858401 | P20: =IF(O20>$AE$3,"OK","NO") -> OK | Q20: =ABS($AI$6*(G20-L20)/($AI$14*0.8*$AI$3)) -> 11.449538
A21: P3 | B21: SEZ. | C21: $A_{sup}$ | H21: $A_{inf}$ | M21: $\rho_{sup}$ | O21: $\rho_{inf}$ | Q21: y | AL21: 300 | AM21: 500 | AN21: =AM21-40 -> 460
A22: Camp. | C22: $\phi$ | D22: N$\phi$ | E22: $\phi$ | F22: N$\phi$ | G22: A (mm^2) | H22: $\phi$ | I22: N$\phi$ | J22: $\phi$ | K22: N$\phi$ | L22: A (mm^2) | M22: - | O22: - | Q22: mm
A23: 1 | B23: start | C23: 18 | D23: 2 | E23: 14 | F23: 2 | G23: =(C23^2/4*D23+E23^2/4*F23)*PI() -> 816.81409 | H23: 14 | I23: 2 | J23: 14 | K23: 2 | L23: =(H23^2/4*I23+J23^2/4*K23)*PI() -> 615.75216 | M23: =G23/($AL$3*$AM$3) -> 0.0054454273 | N23: =IF($AE$3<=M23,"OK","NO") -> OK | O23: =L23/($AL$3*$AM$3) -> 0.0041050144 | P23: =IF(O23>$AE$3,"OK","NO") -> OK | Q23: =ABS($AI$6*(G23-L23)/($AI$14*0.8*$AI$3)) -> 19.283433 | AL23: 300 | AM23: 500 | AN23: =AM23-40 -> 460
B24: end | C24: 18 | D24: 2 | E24: 12 | F24: 2 | G24: =(C24^2/4*D24+E24^2/4*F24)*PI() -> 735.13268 | H24: 14 | I24: 2 | J24: 14 | K24: 2 | L24: =(H24^2/4*I24+J24^2/4*K24)*PI() -> 615.75216 | M24: =G24/($AL$3*$AM$3) -> 0.0049008845 | N24: =IF($AE$3<=M24,"OK","NO") -> OK | O24: =L24/($AL$3*$AM$3) -> 0.0041050144 | P24: =IF(O24>$AE$3,"OK","NO") -> OK | Q24: =ABS($AI$6*(G24-L24)/($AI$14*0.8*$AI$3)) -> 11.449538
A25: 2 | B25: start | C25: 18 | D25: 2 | E25: 12 | F25: 2 | G25: =(C25^2/4*D25+E25^2/4*F25)*PI() -> 735.13268 | H25: 14 | I25: 2 | J25: 14 | K25: 2 | L25: =(H25^2/4*I25+J25^2/4*K25)*PI() -> 615.75216 | M25: =G25/($AL$3*$AM$3) -> 0.0049008845 | N25: =IF($AE$3<=M25,"OK","NO") -> OK | O25: =L25/($AL$3*$AM$3) -> 0.0041050144 | P25: =IF(O25>$AE$3,"OK","NO") -> OK | Q25: =ABS($AI$6*(G25-L25)/($AI$14*0.8*$AI$3)) -> 11.449538
B26: end | C26: 18 | D26: 2 | E26: 12 | F26: 2 | G26: =(C26^2/4*D26+E26^2/4*F26)*PI() -> 735.13268 | H26: 14 | I26: 2 | J26: 14 | K26: 2 | L26: =(H26^2/4*I26+J26^2/4*K26)*PI() -> 615.75216 | M26: =G26/($AL$3*$AM$3) -> 0.0049008845 | N26: =IF($AE$3<=M26,"OK","NO") -> OK | O26: =L26/($AL$3*$AM$3) -> 0.0041050144 | P26: =IF(O26>$AE$3,"OK","NO") -> OK | Q26: =ABS($AI$6*(G26-L26)/($AI$14*0.8*$AI$3)) -> 11.449538
A27: 3 | B27: start | C27: 18 | D27: 2 | E27: 12 | F27: 2 | G27: =(C27^2/4*D27+E27^2/4*F27)*PI() -> 735.13268 | H27: 14 | I27: 2 | J27: 14 | K27: 2 | L27: =(H27^2/4*I27+J27^2/4*K27)*PI() -> 615.75216 | M27: =G27/($AL$3*$AM$3) -> 0.0049008845 | N27: =IF($AE$3<=M27,"OK","NO") -> OK | O27: =L27/($AL$3*$AM$3) -> 0.0041050144 | P27: =IF(O27>$AE$3,"OK","NO") -> OK | Q27: =ABS($AI$6*(G27-L27)/($AI$14*0.8*$AI$3)) -> 11.449538
B28: end | C28: 18 | D28: 2 | E28: 12 | F28: 2 | G28: =(C28^2/4*D28+E28^2/4*F28)*PI() -> 735.13268 | H28: 14 | I28: 2 | J28: 14 | K28: 2 | L28: =(H28^2/4*I28+J28^2/4*K28)*PI() -> 615.75216 | M28: =G28/($AL$3*$AM$3) -> 0.0049008845 | N28: =IF($AE$3<=M28,"OK","NO") -> OK | O28: =L28/($AL$3*$AM$3) -> 0.0041050144 | P28: =IF(O28>$AE$3,"OK","NO") -> OK | Q28: =ABS($AI$6*(G28-L28)/($AI$14*0.8*$AI$3)) -> 11.449538
A29: 4 | B29: start | C29: 18 | D29: 2 | E29: 12 | F29: 2 | G29: =(C29^2/4*D29+E29^2/4*F29)*PI() -> 735.13268 | H29: 14 | I29: 2 | J29: 14 | K29: 2 | L29: =(H29^2/4*I29+J29^2/4*K29)*PI() -> 615.75216 | M29: =G29/($AL$3*$AM$3) -> 0.0049008845 | N29: =IF($AE$3<=M29,"OK","NO") -> OK | O29: =L29/($AL$3*$AM$3) -> 0.0041050144 | P29: =IF(O29>$AE$3,"OK","NO") -> OK | Q29: =ABS($AI$6*(G29-L29)/($AI$14*0.8*$AI$3)) -> 11.449538
B30: end | C30: 18 | D30: 2 | E30: 14 | F30: 2 | G30: =(C30^2/4*D30+E30^2/4*F30)*PI() -> 816.81409 | H30: 14 | I30: 2 | J30: 14 | K30: 2 | L30: =(H30^2/4*I30+J30^2/4*K30)*PI() -> 615.75216 | M30: =G30/($AL$3*$AM$3) -> 0.0054454273 | N30: =IF($AE$3<=M30,"OK","NO") -> OK | O30: =L30/($AL$3*$AM$3) -> 0.0041050144 | P30: =IF(O30>$AE$3,"OK","NO") -> OK | Q30: =ABS($AI$6*(G30-L30)/($AI$14*0.8*$AI$3)) -> 19.283433
A31: P4 | B31: SEZ. | C31: $A_{sup}$ | H31: $A_{inf}$ | M31: $\rho_{sup}$ | O31: $\rho_{inf}$ | Q31: y
A32: Camp. | C32: $\phi$ | D32: N$\phi$ | E32: $\phi$ | F32: N$\phi$ | G32: A (mm^2) | H32: $\phi$ | I32: N$\phi$ | J32: $\phi$ | K32: N$\phi$ | L32: A (mm^2) | M32: - | O32: - | Q32: mm
A33: 1 | B33: start | C33: 14 | D33: 2 | E33: 12 | F33: 2 | G33: =(C33^2/4*D33+E33^2/4*F33)*PI() -> 534.07075 | H33: 14 | I33: 2 | J33: 12 | K33: 2 | L33: =(H33^2/4*I33+J33^2/4*K33)*PI() -> 534.07075 | M33: =G33/($AL$3*$AM$3) -> 0.0035604717 | N33: =IF($AE$3<=M33,"OK","NO") -> OK | O33: =L33/($AL$3*$AM$3) -> 0.0035604717 | P33: =IF(O33>$AE$3,"OK","NO") -> OK | Q33: =ABS($AI$6*(G33-L33)/($AI$14*0.8*$AI$3)) -> 0
B34: end | C34: 14 | D34: 2 | E34: 12 | F34: 2 | G34: =(C34^2/4*D34+E34^2/4*F34)*PI() -> 534.07075 | H34: 14 | I34: 2 | J34: 12 | K34: 2 | L34: =(H34^2/4*I34+J34^2/4*K34)*PI() -> 534.07075 | M34: =G34/($AL$3*$AM$3) -> 0.0035604717 | N34: =IF($AE$3<=M34,"OK","NO") -> OK | O34: =L34/($AL$3*$AM$3) -> 0.0035604717 | P34: =IF(O34>$AE$3,"OK","NO") -> OK | Q34: =ABS($AI$6*(G34-L34)/($AI$14*0.8*$AI$3)) -> 0
A35: 2 | B35: start | C35: 14 | D35: 2 | E35: 12 | F35: 2 | G35: =(C35^2/4*D35+E35^2/4*F35)*PI() -> 534.07075 | H35: 14 | I35: 2 | J35: 12 | K35: 2 | L35: =(H35^2/4*I35+J35^2/4*K35)*PI() -> 534.07075 | M35: =G35/($AL$3*$AM$3) -> 0.0035604717 | N35: =IF($AE$3<=M35,"OK","NO") -> OK | O35: =L35/($AL$3*$AM$3) -> 0.0035604717 | P35: =IF(O35>$AE$3,"OK","NO") -> OK | Q35: =ABS($AI$6*(G35-L35)/($AI$14*0.8*$AI$3)) -> 0
B36: end | C36: 14 | D36: 2 | E36: 12 | F36: 2 | G36: =(C36^2/4*D36+E36^2/4*F36)*PI() -> 534.07075 | H36: 14 | I36: 2 | J36: 12 | K36: 2 | L36: =(H36^2/4*I36+J36^2/4*K36)*PI() -> 534.07075 | M36: =G36/($AL$3*$AM$3) -> 0.0035604717 | N36: =IF($AE$3<=M36,"OK","NO") -> OK | O36: =L36/($AL$3*$AM$3) -> 0.0035604717 | P36: =IF(O36>$AE$3,"OK","NO") -> OK | Q36: =ABS($AI$6*(G36-L36)/($AI$14*0.8*$AI$3)) -> 0
A37: 3 | B37: start | C37: 14 | D37: 2 | E37: 12 | F37: 2 | G37: =(C37^2/4*D37+E37^2/4*F37)*PI() -> 534.07075 | H37: 14 | I37: 2 | J37: 12 | K37: 2 | L37: =(H37^2/4*I37+J37^2/4*K37)*PI() -> 534.07075 | M37: =G37/($AL$3*$AM$3) -> 0.0035604717 | N37: =IF($AE$3<=M37,"OK","NO") -> OK | O37: =L37/($AL$3*$AM$3) -> 0.0035604717 | P37: =IF(O37>$AE$3,"OK","NO") -> OK | Q37: =ABS($AI$6*(G37-L37)/($AI$14*0.8*$AI$3)) -> 0
B38: end | C38: 14 | D38: 2 | E38: 12 | F38: 2 | G38: =(C38^2/4*D38+E38^2/4*F38)*PI() -> 534.07075 | H38: 14 | I38: 2 | J38: 12 | K38: 2 | L38: =(H38^2/4*I38+J38^2/4*K38)*PI() -> 534.07075 | M38: =G38/($AL$3*$AM$3) -> 0.0035604717 | N38: =IF($AE$3<=M38,"OK","NO") -> OK | O38: =L38/($AL$3*$AM$3) -> 0.0035604717 | P38: =IF(O38>$AE$3,"OK","NO") -> OK | Q38: =ABS($AI$6*(G38-L38)/($AI$14*0.8*$AI$3)) -> 0
A39: 4 | B39: start | C39: 14 | D39: 2 | E39: 12 | F39: 2 | G39: =(C39^2/4*D39+E39^2/4*F39)*PI() -> 534.07075 | H39: 14 | I39: 2 | J39: 12 | K39: 2 | L39: =(H39^2/4*I39+J39^2/4*K39)*PI() -> 534.07075 | M39: =G39/($AL$3*$AM$3) -> 0.0035604717 | N39: =IF($AE$3<=M39,"OK","NO") -> OK | O39: =L39/($AL$3*$AM$3) -> 0.0035604717 | P39: =IF(O39>$AE$3,"OK","NO") -> OK | Q39: =ABS($AI$6*(G39-L39)/($AI$14*0.8*$AI$3)) -> 0
B40: end | C40: 14 | D40: 2 | E40: 12 | F40: 2 | G40: =(C40^2/4*D40+E40^2/4*F40)*PI() -> 534.07075 | H40: 14 | I40: 2 | J40: 12 | K40: 2 | L40: =(H40^2/4*I40+J40^2/4*K40)*PI() -> 534.07075 | M40: =G40/($AL$3*$AM$3) -> 0.0035604717 | N40: =IF($AE$3<=M40,"OK","NO") -> OK | O40: =L40/($AL$3*$AM$3) -> 0.0035604717 | P40: =IF(O40>$AE$3,"OK","NO") -> OK | Q40: =ABS($AI$6*(G40-L40)/($AI$14*0.8*$AI$3)) -> 0
...

Sheet TAGLIO SLV (P1-P2) 
A1: TEL. 1 | B1: SEZ. | C1: $A_{sup}$ | H1: $A_{inf}$ | M1: $\rho_{sup}$ | O1: $\rho_{inf}$ | Q1: y | AE1: $\rho_{min}$ | AF1: $\rho_{max}$ | AH1: TRAVE ESTERNA | AL1: b | AM1: h | AN1: d
A2: Camp. | C2: $\phi$ | D2: N$\phi$ | E2: $\phi$ | F2: N$\phi$ | G2: A (mm^2) | H2: $\phi$ | I2: N$\phi$ | J2: $\phi$ | K2: N$\phi$ | L2: A (mm^2) | M2: - | O2: - | Q2: mm | T2: a | U2: b | V2: c | W2: y | X2: $\delta$ | Z2: y1 | AE2: - | AF2: - | AH2: campata 1 | AL2: mm | AM2: mm | AN2: mm
A3: 1 | B3: start | C3: 20 | D3: 2 | E3: 14 | F3: 2 | G3: =(C3^2/4*D3+E3^2/4*F3)*PI() -> 936.19461 | H3: 14 | I3: 2 | J3: 14 | K3: 2 | L3: =(H3^2/4*I3+J3^2/4*K3)*PI() -> 615.75216 | M3: =G3/($AL$3*$AM$3) -> 0.0062412974 | N3: =IF($AE$3<=M3,"OK","NO") -> OK | O3: =L3/($AL$3*$AM$3) -> 0.0041050144 | P3: =IF(O3>$AE$3,"OK","NO") -> OK | Q3: =ABS($AI$6*(G3-L3)/($AI$14*0.8*$AI$3)) -> 30.732972 | T3: =$AI$3*$AI$14*0.8 -> 4080 | U3: =L3*$AI$15*3.5/1000-G3*$AI$6 -> 86240.816 | V3: =$AI$6,$AI$6,L3*$AI$15*(3.5/1000)*($AI$4-40) -> #VALUE! | W3: =CONCATENATE(T3," y^2 ",IF(U3>0," + "," "),U3," y",IF(V3>0," + "," "),V3, " = 0 ") -> #VALUE! | X3: =U3^2-4*T3*V3 -> #VALUE! | Y3: =IF(X3>0,"2 soluzioni distinte",IF(X3=0,"2 soluzioni coincidenti","nessuna soluzione")) -> #VALUE! | Z3: =IF(X3<0," ",(-U3+SQRT(X3))/(2*T3)) -> #VALUE! | AA3: =IF(X3<0," ",(-U3-SQRT(X3))/(2*T3)) -> #VALUE! | AE3: =1.4/$AI$5 -> 0.0031111111 | AF3: =3.5/$AI$5 -> 0.0077777778 | AH3: b | AI3: =300 -> 300 | AJ3: mm | AL3: 300 | AM3: 500 | AN3: =AM3-40 -> 460
B4: end | C4: 20 | D4: 2 | E4: 18 | F4: 2 | G4: =(C4^2/4*D4+E4^2/4*F4)*PI() -> 1137.2565 | H4: 14 | I4: 2 | J4: 14 | K4: 2 | L4: =(H4^2/4*I4+J4^2/4*K4)*PI() -> 615.75216 | M4: =G4/($AL$3*$AM$3) -> 0.0075817103 | N4: =IF($AE$3<=M4,"OK","NO") -> OK | O4: =L4/($AL$3*$AM$3) -> 0.0041050144 | P4: =IF(O4>$AE$3,"OK","NO") -> OK | Q4: =ABS($AI$6*(G4-L4)/($AI$14*0.8*$AI$3)) -> 50.016405 | T4: =$AI$3*$AI$14*0.8 -> 4080 | U4: =G4*$AI$15*3.5/1000-L4*$AI$6 -> 594937.06 | V4: =IF($AI$15*(3.5/1000)*(AA4-40)/(AA4)>$AI$6,$AI$6,L4*$AI$15*(3.5/1000)*($AI$4-40)) -> 0 | W4: =CONCATENATE(T4," y^2 ",IF(U4>0," + "," "),U4," y",IF(V4>0," + "," "),V4, " = 0 ") -> #VALUE! | X4: =U4^2-4*T4*V4 -> #VALUE! | Y4: =IF(X4>0,"2 soluzioni distinte",IF(X4=0,"2 soluzioni coincidenti","nessuna soluzione")) -> #VALUE! | Z4: =IF(X4<0," ",(-U4+SQRT(X4))/(2*T4)) -> #VALUE! | AA4: =IF(X4<0," ",(-U4-SQRT(X4))/(2*T4)) -> #VALUE! | AH4: h | AI4: 500 | AJ4: mm
A5: 2 | B5: start | C5: 20 | D5: 2 | E5: 18 | F5: 2 | G5: =(C5^2/4*D5+E5^2/4*F5)*PI() -> 1137.2565 | H5: 14 | I5: 2 | J5: 14 | K5: 2 | L5: =(H5^2/4*I5+J5^2/4*K5)*PI() -> 615.75216 | M5: =G5/($AL$3*$AM$3) -> 0.0075817103 | N5: =IF($AE$3<=M5,"OK","NO") -> OK | O5: =L5/($AL$3*$AM$3) -> 0.0041050144 | P5: =IF(O5>$AE$3,"OK","NO") -> OK | Q5: =ABS($AI$6*(G5-L5)/($AI$14*0.8*$AI$3)) -> 50.016405 | T5: =$AI$3*$AI$14*0.8 -> 4080 | U5: =L5*$AI$15*3.5/1000-G5*$AI$6 -> 7564.4087 | V5: =IF($AI$15*(3.5/1000)*(AA5-40)/(AA5)>$AI$6,$AI$6,L5*$AI$15*(3.5/1000)*($AI$4-40)) -> 0 | W5: =CONCATENATE(T5," y^2 ",IF(U5>0," + "," "),U5," y",IF(V5>0," + "," "),V5, " = 0 ") -> #VALUE! | X5: =U5^2-4*T5*V5 -> #VALUE! | Y5: =IF(X5>0,"2 soluzioni distinte",IF(X5=0,"2 soluzioni coincidenti","nessuna soluzione")) -> #VALUE! | Z5: =IF(X5<0," ",(-U5+SQRT(X5))/(2*T5)) -> #VALUE! | AA5: =IF(X5<0," ",(-U5-SQRT(X5))/(2*T5)) -> #VALUE! | AH5: $f_{yk}$ | AI5: =450 -> 450 | AJ5: N/mm^2 | AL5: 300 | AM5: 500 | AN5: =AM5-40 -> 460
B6: end | C6: 20 | D6: 2 | E6: 18 | F6: 2 | G6: =(C6^2/4*D6+E6^2/4*F6)*PI() -> 1137.2565 | H6: 14 | I6: 2 | J6: 14 | K6: 2 | L6: =(H6^2/4*I6+J6^2/4*K6)*PI() -> 615.75216 | M6: =G6/($AL$3*$AM$3) -> 0.0075817103 | N6: =IF($AE$3<=M6,"OK","NO") -> OK | O6: =L6/($AL$3*$AM$3) -> 0.0041050144 | P6: =IF(O6>$AE$3,"OK","NO") -> OK | Q6: =ABS($AI$6*(G6-L6)/($AI$14*0.8*$AI$3)) -> 50.016405 | T6: =$AI$3*$AI$14*0.8 -> 4080 | U6: =G6*$AI$15*3.5/1000-L6*$AI$6 -> 594937.06 | V6: =IF($AI$15*(3.5/1000)*(AA6-40)/(AA6)>$AI$6,$AI$6,L6*$AI$15*(3.5/1000)*($AI$4-40)) -> 0 | W6: =CONCATENATE(T6," y^2 ",IF(U6>0," + "," "),U6," y",IF(V6>0," + "," "),V6, " = 0 ") -> #VALUE! | X6: =U6^2-4*T6*V6 -> #VALUE! | Y6: =IF(X6>0,"2 soluzioni distinte",IF(X6=0,"2 soluzioni coincidenti","nessuna soluzione")) -> #VALUE! | Z6: =IF(X6<0," ",(-U6+SQRT(X6))/(2*T6)) -> #VALUE! | AA6: =IF(X6<0," ",(-U6-SQRT(X6))/(2*T6)) -> #VALUE! | AH6: $f_{yd}$ | AI6: =AI5/1.15 -> 391.30435
A7: 3 | B7: start | C7: 20 | D7: 2 | E7: 18 | F7: 2 | G7: =(C7^2/4*D7+E7^2/4*F7)*PI() -> 1137.2565 | H7: 14 | I7: 2 | J7: 14 | K7: 2 | L7: =(H7^2/4*I7+J7^2/4*K7)*PI() -> 615.75216 | M7: =G7/($AL$3*$AM$3) -> 0.0075817103 | N7: =IF($AE$3<=M7,"OK","NO") -> OK | O7: =L7/($AL$3*$AM$3) -> 0.0041050144 | P7: =IF(O7>$AE$3,"OK","NO") -> OK | Q7: =ABS($AI$6*(G7-L7)/($AI$14*0.8*$AI$3)) -> 50.016405 | T7: =$AI$3*$AI$14*0.8 -> 4080 | U7: =L7*$AI$15*3.5/1000-G7*$AI$6 -> 7564.4087 | V7: =IF($AI$15*(3.5/1000)*(AA7-40)/(AA7)>$AI$6,$AI$6,L7*$AI$15*(3.5/1000)*($AI$4-40)) -> 0 | W7: =CONCATENATE(T7," y^2 ",IF(U7>0," + "," "),U7," y",IF(V7>0," + "," "),V7, " = 0 ") -> #VALUE! | X7: =U7^2-4*T7*V7 -> #VALUE! | Y7: =IF(X7>0,"2 soluzioni distinte",IF(X7=0,"2 soluzioni coincidenti","nessuna soluzione")) -> #VALUE! | Z7: =IF(X7<0," ",(-U7+SQRT(X7))/(2*T7)) -> #VALUE! | AA7: =IF(X7<0," ",(-U7-SQRT(X7))/(2*T7)) -> #VALUE! | AH7: $A_s$ | AI7: =1.4/AI5*AI3*AI4 -> 466.66667 | AJ7: mm^2 | AL7: 300 | AM7: 500 | AN7: =AM7-40 -> 460
B8: end | C8: 20 | D8: 2 | E8: 14 | F8: 2 | G8: =(C8^2/4*D8+E8^2/4*F8)*PI() -> 936.19461 | H8: 14 | I8: 2 | J8: 14 | K8: 2 | L8: =(H8^2/4*I8+J8^2/4*K8)*PI() -> 615.75216 | M8: =G8/($AL$3*$AM$3) -> 0.0062412974 | N8: =IF($AE$3<=M8,"OK","NO") -> OK | O8: =L8/($AL$3*$AM$3) -> 0.0041050144 | P8: =IF(O8>$AE$3,"OK","NO") -> OK | Q8: =ABS($AI$6*(G8-L8)/($AI$14*0.8*$AI$3)) -> 30.732972 | T8: =$AI$3*$AI$14*0.8 -> 4080 | U8: =G8*$AI$15*3.5/1000-L8*$AI$6 -> 447156.54 | V8: =IF($AI$15*(3.5/1000)*(AA8-40)/(AA8)>$AI$6,$AI$6,L8*$AI$15*(3.5/1000)*($AI$4-40)) -> 0 | W8: =CONCATENATE(T8," y^2 ",IF(U8>0," + "," "),U8," y",IF(V8>0," + "," "),V8, " = 0 ") -> #VALUE! | X8: =U8^2-4*T8*V8 -> #VALUE! | Y8: =IF(X8>0,"2 soluzioni distinte",IF(X8=0,"2 soluzioni coincidenti","nessuna soluzione")) -> #VALUE! | Z8: =IF(X8<0," ",(-U8+SQRT(X8))/(2*T8)) -> #VALUE! | AA8: =IF(X8<0," ",(-U8-SQRT(X8))/(2*T8)) -> #VALUE! | AH8: $A_s-A_s^{comp}$ | AI8: =3.5/AI5*AI3*AI4 -> 1166.6667 | AJ8: mm^2
A9: TEL.2 | B9: sezione | C9: $A_{sup}$ | H9: $A_{inf}$ | M9: $\rho_{sup}$ | O9: $\rho_{inf}$ | Q9: y | AH9: $\rho_{min}$ | AI9: =AI7/(AI4*AI3) -> 0.0031111111 | AL9: b | AM9: h | AN9: d
A10: Camp. | C10: $\phi$ | D10: N$\phi$ | E10: $\phi$ | F10: N$\phi$ | G10: A (mm^2) | H10: $\phi$ | I10: N$\phi$ | J10: $\phi$ | K10: N$\phi$ | L10: A (mm^2) | M10: - | O10: - | Q10: mm | AH10: $\rho_{comp}$ | AI10: =0.25*AI9 -> 0.00077777778 | AL10: mm | AM10: mm | AN10: mm
A11: 1 | B11: start | C11: 20 | D11: 2 | E11: 14 | F11: 2 | G11: =(C11^2/4*D11+E11^2/4*F11)*PI() -> 936.19461 | H11: 14 | I11: 2 | J11: 12 | K11: 2 | L11: =(H11^2/4*I11+J11^2/4*K11)*PI() -> 534.07075 | M11: =G11/($AL$3*$AM$3) -> 0.0062412974 | N11: =IF($AE$3<=M11,"OK","NO") -> OK | O11: =L11/($AL$3*$AM$3) -> 0.0035604717 | P11: =IF(O11>$AE$3,"OK","NO") -> OK | Q11: =ABS($AI$6*(G11-L11)/($AI$14*0.8*$AI$3)) -> 38.566866 | AH11: $\rho_{comp}$ | AI11: =0.5*AI9 -> 0.0015555556 | AJ11: Nelle zone dissipative | AL11: 300 | AM11: 500 | AN11: =AM11-40 -> 460
B12: end | C12: 20 | D12: 2 | E12: 18 | F12: 2 | G12: =(C12^2/4*D12+E12^2/4*F12)*PI() -> 1137.2565 | H12: 14 | I12: 2 | J12: 14 | K12: 2 | L12: =(H12^2/4*I12+J12^2/4*K12)*PI() -> 615.75216 | M12: =G12/($AL$3*$AM$3) -> 0.0075817103 | N12: =IF($AE$3<=M12,"OK","NO") -> OK | O12: =L12/($AL$3*$AM$3) -> 0.0041050144 | P12: =IF(O12>$AE$3,"OK","NO") -> OK | Q12: =ABS($AI$6*(G12-L12)/($AI$14*0.8*$AI$3)) -> 50.016405
A13: 2 | B13: start | C13: 20 | D13: 2 | E13: 18 | F13: 2 | G13: =(C13^2/4*D13+E13^2/4*F13)*PI() -> 1137.2565 | H13: 14 | I13: 2 | J13: 14 | K13: 2 | L13: =(H13^2/4*I13+J13^2/4*K13)*PI() -> 615.75216 | M13: =G13/($AL$3*$AM$3) -> 0.0075817103 | N13: =IF($AE$3<=M13,"OK","NO") -> OK | O13: =L13/($AL$3*$AM$3) -> 0.0041050144 | P13: =IF(O13>$AE$3,"OK","NO") -> OK | Q13: =ABS($AI$6*(G13-L13)/($AI$14*0.8*$AI$3)) -> 50.016405 | AI13: =269*1000^2/(0.9*AN3*391) -> 1661.7863 | AL13: 300 | AM13: 500 | AN13: =AM13-40 -> 460
B14: end | C14: 20 | D14: 2 | E14: 18 | F14: 2 | G14: =(C14^2/4*D14+E14^2/4*F14)*PI() -> 1137.2565 | H14: 14 | I14: 2 | J14: 14 | K14: 2 | L14: =(H14^2/4*I14+J14^2/4*K14)*PI() -> 615.75216 | M14: =G14/($AL$3*$AM$3) -> 0.0075817103 | N14: =IF($AE$3<=M14,"OK","NO") -> OK | O14: =L14/($AL$3*$AM$3) -> 0.0041050144 | P14: =IF(O14>$AE$3,"OK","NO") -> OK | Q14: =ABS($AI$6*(G14-L14)/($AI$14*0.8*$AI$3)) -> 50.016405 | AH14: fcd | AI14: =0.85*30/1.5 -> 17
A15: 3 | B15: start | C15: 20 | D15: 2 | E15: 18 | F15: 2 | G15: =(C15^2/4*D15+E15^2/4*F15)*PI() -> 1137.2565 | H15: 14 | I15: 2 | J15: 14 | K15: 2 | L15: =(H15^2/4*I15+J15^2/4*K15)*PI() -> 615.75216 | M15: =G15/($AL$3*$AM$3) -> 0.0075817103 | N15: =IF($AE$3<=M15,"OK","NO") -> OK | O15: =L15/($AL$3*$AM$3) -> 0.0041050144 | P15: =IF(O15>$AE$3,"OK","NO") -> OK | Q15: =ABS($AI$6*(G15-L15)/($AI$14*0.8*$AI$3)) -> 50.016405 | AH15: Es | AI15: 210000 | AL15: 300 | AM15: 500 | AN15: =AM15-40 -> 460
B16: end | C16: 20 | D16: 2 | E16: 14 | F16: 2 | G16: =(C16^2/4*D16+E16^2/4*F16)*PI() -> 936.19461 | H16: 14 | I16: 2 | J16: 12 | K16: 2 | L16: =(H16^2/4*I16+J16^2/4*K16)*PI() -> 534.07075 | M16: =G16/($AL$3*$AM$3) -> 0.0062412974 | N16: =IF($AE$3<=M16,"OK","NO") -> OK | O16: =L16/($AL$3*$AM$3) -> 0.0035604717 | P16: =IF(O16>$AE$3,"OK","NO") -> OK | Q16: =ABS($AI$6*(G16-L16)/($AI$14*0.8*$AI$3)) -> 38.566866
A17: TEL. 3 | B17: sezione | C17: $A_{sup}$ | H17: $A_{inf}$ | M17: $\rho_{sup}$ | O17: $\rho_{inf}$ | Q17: y | AL17: b | AM17: h | AN17: d
A18: Camp. | C18: $\phi$ | D18: N$\phi$ | E18: $\phi$ | F18: N$\phi$ | G18: A (mm^2) | H18: $\phi$ | I18: N$\phi$ | J18: $\phi$ | K18: N$\phi$ | L18: A (mm^2) | M18: - | O18: - | Q18: mm | AL18: mm | AM18: mm | AN18: mm
A19: 1 | B19: start | C19: 20 | D19: 2 | E19: 14 | F19: 2 | G19: =(C19^2/4*D19+E19^2/4*F19)*PI() -> 936.19461 | H19: 14 | I19: 2 | J19: 12 | K19: 2 | L19: =(H19^2/4*I19+J19^2/4*K19)*PI() -> 534.07075 | M19: =G19/($AL$3*$AM$3) -> 0.0062412974 | N19: =IF($AE$3<=M19,"OK","NO") -> OK | O19: =L19/($AL$3*$AM$3) -> 0.0035604717 | P19: =IF(O19>$AE$3,"OK","NO") -> OK | Q19: =ABS($AI$6*(G19-L19)/($AI$14*0.8*$AI$3)) -> 38.566866 | AL19: 300 | AM19: 500 | AN19: =AM19-40 -> 460
B20: end | C20: 20 | D20: 4 | E20: 0 | F20: 0 | G20: =(C20^2/4*D20+E20^2/4*F20)*PI() -> 1256.6371 | H20: 14 | I20: 2 | J20: 14 | K20: 2 | L20: =(H20^2/4*I20+J20^2/4*K20)*PI() -> 615.75216 | M20: =G20/($AL$3*$AM$3) -> 0.0083775804 | N20: =IF($AE$3<=M20,"OK","NO") -> OK | O20: =L20/($AL$3*$AM$3) -> 0.0041050144 | P20: =IF(O20>$AE$3,"OK","NO") -> OK | Q20: =ABS($AI$6*(G20-L20)/($AI$14*0.8*$AI$3)) -> 61.465943
A21: 2 | B21: start | C21: 20 | D21: 4 | E21: 0 | F21: 0 | G21: =(C21^2/4*D21+E21^2/4*F21)*PI() -> 1256.6371 | H21: 14 | I21: 2 | J21: 14 | K21: 2 | L21: =(H21^2/4*I21+J21^2/4*K21)*PI() -> 615.75216 | M21: =G21/($AL$3*$AM$3) -> 0.0083775804 | N21: =IF($AE$3<=M21,"OK","NO") -> OK | O21: =L21/($AL$3*$AM$3) -> 0.0041050144 | P21: =IF(O21>$AE$3,"OK","NO") -> OK | Q21: =ABS($AI$6*(G21-L21)/($AI$14*0.8*$AI$3)) -> 61.465943 | AL21: 300 | AM21: 500 | AN21: =AM21-40 -> 460
B22: end | C22: 20 | D22: 4 | E22: 0 | F22: 0 | G22: =(C22^2/4*D22+E22^2/4*F22)*PI() -> 1256.6371 | H22: 14 | I22: 2 | J22: 14 | K22: 2 | L22: =(H22^2/4*I22+J22^2/4*K22)*PI() -> 615.75216 | M22: =G22/($AL$3*$AM$3) -> 0.0083775804 | N22: =IF($AE$3<=M22,"OK","NO") -> OK | O22: =L22/($AL$3*$AM$3) -> 0.0041050144 | P22: =IF(O22>$AE$3,"OK","NO") -> OK | Q22: =ABS($AI$6*(G22-L22)/($AI$14*0.8*$AI$3)) -> 61.465943
A23: 3 | B23: start | C23: 20 | D23: 4 | E23: 0 | F23: 0 | G23: =(C23^2/4*D23+E23^2/4*F23)*PI() -> 1256.6371 | H23: 14 | I23: 2 | J23: 14 | K23: 2 | L23: =(H23^2/4*I23+J23^2/4*K23)*PI() -> 615.75216 | M23: =G23/($AL$3*$AM$3) -> 0.0083775804 | N23: =IF($AE$3<=M23,"OK","NO") -> OK | O23: =L23/($AL$3*$AM$3) -> 0.0041050144 | P23: =IF(O23>$AE$3,"OK","NO") -> OK | Q23: =ABS($AI$6*(G23-L23)/($AI$14*0.8*$AI$3)) -> 61.465943 | AL23: 300 | AM23: 500 | AN23: =AM23-40 -> 460
B24: end | C24: 20 | D24: 2 | E24: 14 | F24: 2 | G24: =(C24^2/4*D24+E24^2/4*F24)*PI() -> 936.19461 | H24: 14 | I24: 2 | J24: 12 | K24: 2 | L24: =(H24^2/4*I24+J24^2/4*K24)*PI() -> 534.07075 | M24: =G24/($AL$3*$AM$3) -> 0.0062412974 | N24: =IF($AE$3<=M24,"OK","NO") -> OK | O24: =L24/($AL$3*$AM$3) -> 0.0035604717 | P24: =IF(O24>$AE$3,"OK","NO") -> OK | Q24: =ABS($AI$6*(G24-L24)/($AI$14*0.8*$AI$3)) -> 38.566866
A26: CALCOLO TAGLIO SOLLECITANTE IN Capacity design
A28: TEL. 1 | B28: SEZ. | C28: Mu+ | D28: Mu- | E28: carico distr. (sisma) | F28: L | G28: V+ | H28: V-
A29: Camp. | C29: KNm | D29: KNm | E29: KN/m | F29: m | G29: KN | H29: KN
A30: 1 | B30: start | C30: =(G3*$AI$6*($AI$4-40-0.8*Q3/2)+L3*$AI$6*(0.8*Q3/2-40))/1000^2 -> 157.33572 | D30: =-(L3*$AI$6*($AI$4-40-0.8*Q3/2)+G3*$AI$6*(0.8*Q3/2-40))/1000^2 -> -97.723357 | E30: =7.297*2+7.78 -> 22.374 | F30: 4 | G30: =$E30*$F30/2+($C30+$C31)/$F30*1.1 -> 114.72264 | H30: =$E30*$F30/2+($D30+$D31)/$F30*1.1 -> -34.646974 | I30: 157 | J30: 105.2
B31: end | C31: =(L4*$AI$6*($AI$4-40-0.8*Q4/2)+G4*$AI$6*(0.8*Q4/2-40))/1000^2 -> 97.117529 | D31: =-(G4*$AI$6*($AI$4-40-0.8*Q4/2)+L4*$AI$6*(0.8*Q4/2-40))/1000^2 -> -190.98564 | E31: =7.297*2+7.78 -> 22.374 | F31: 4 | G31: =-$E31*$F31/2+($C30+$C31)/$F31*1.1 -> 25.226644 | H31: =-$E31*$F31/2+($D30+$D31)/$F31*1.1 -> -124.14297 | I31: 105.2 | J31: 190,1
A32: 2 | B32: start | C32: =(G5*$AI$6*($AI$4-40-0.8*Q5/2)+L5*$AI$6*(0.8*Q5/2-40))/1000^2 -> 190.98564 | D32: =-(L5*$AI$6*($AI$4-40-0.8*Q5/2)+G5*$AI$6*(0.8*Q5/2-40))/1000^2 -> -97.117529 | E32: =7.297*2+7.78 -> 22.374 | F32: 5.5 | G32: =$E32*$F32/2+($C32+$C33)/$F32*1.1 -> 119.14913 | H32: =$E32*$F32/2+($D32+$D33)/$F32*1.1 -> 3.9078662 | I32: 190,1 | J32: 105.2
B33: end | C33: =(L6*$AI$6*($AI$4-40-0.8*Q6/2)+G6*$AI$6*(0.8*Q6/2-40))/1000^2 -> 97.117529 | D33: =-(G6*$AI$6*($AI$4-40-0.8*Q6/2)+L6*$AI$6*(0.8*Q6/2-40))/1000^2 -> -190.98564 | E33: =7.297*2+7.78 -> 22.374 | F33: 5.5 | G33: =-$E33*$F33/2+($C32+$C33)/$F33*1.1 -> -3.9078662 | H33: =-$E33*$F33/2+($D32+$D33)/$F33*1.1 -> -119.14913 | I33: 105.2 | J33: 190,1 | L33: -106.01489
A34: 3 | B34: start | C34: =(G7*$AI$6*($AI$4-40-0.8*Q7/2)+L7*$AI$6*(0.8*Q7/2-40))/1000^2 -> 190.98564 | D34: =-(L7*$AI$6*($AI$4-40-0.8*Q7/2)+G7*$AI$6*(0.8*Q7/2-40))/1000^2 -> -97.117529 | E34: =7.297*2+7.78 -> 22.374 | F34: 4 | G34: =$E34*$F34/2+($C34+$C35)/$F34*1.1 -> 124.14297 | H34: =$E34*$F34/2+($D34+$D35)/$F34*1.1 -> -25.226644 | I34: 190,1 | J34: 105.2
B35: end | C35: =(L8*$AI$6*($AI$4-40-0.8*Q8/2)+G8*$AI$6*(0.8*Q8/2-40))/1000^2 -> 97.723357 | D35: =-(G8*$AI$6*($AI$4-40-0.8*Q8/2)+L8*$AI$6*(0.8*Q8/2-40))/1000^2 -> -157.33572 | E35: =7.297*2+7.78 -> 22.374 | F35: 4 | G35: =-$E35*$F35/2+($C34+$C35)/$F35*1.1 -> 34.646974 | H35: =-$E35*$F35/2+($D34+$D35)/$F35*1.1 -> -114.72264 | I35: 105.2 | J35: 157
A36: TEL.2 | B36: SEZ. | C36: Mu+ | D36: Mu- | E36: carico distr. (sisma) | F36: L | G36: V+ | H36: V-
A37: Camp. | C37: KNm | D37: KNm | E37: KN/m | F37: m | G37: KN | H37: KN
A38: 1 | B38: start | C38: =(G11*$AI$6*($AI$4-40-0.8*Q11/2)+L11*$AI$6*(0.8*Q11/2-40))/1000^2 -> 157.72822 | D38: =-(L11*$AI$6*($AI$4-40-0.8*Q11/2)+G11*$AI$6*(0.8*Q11/2-40))/1000^2 -> -83.906696 | E38: =7.297*4 -> 29.188 | F38: 4 | G38: =$E38*$F38/2+($C38+$C39)/$F38*1.1 -> 128.45858 | H38: =$E38*$F38/2+($D38+$D39)/$F38*1.1 -> -17.219392 | I38: 157 | J38: 91.67
B39: end | C39: =(L12*$AI$6*($AI$4-40-0.8*Q12/2)+G12*$AI$6*(0.8*Q12/2-40))/1000^2 -> 97.117529 | D39: =-(G12*$AI$6*($AI$4-40-0.8*Q12/2)+L12*$AI$6*(0.8*Q12/2-40))/1000^2 -> -190.98564 | E39: =7.297*4 -> 29.188 | F39: 4 | G39: =-$E39*$F39/2+($C38+$C39)/$F39*1.1 -> 11.706581 | H39: =-$E39*$F39/2+($D38+$D39)/$F39*1.1 -> -133.97139
A40: 2 | B40: start | C40: =(G13*$AI$6*($AI$4-40-0.8*Q13/2)+L13*$AI$6*(0.8*Q13/2-40))/1000^2 -> 190.98564 | D40: =-(L13*$AI$6*($AI$4-40-0.8*Q13/2)+G13*$AI$6*(0.8*Q13/2-40))/1000^2 -> -97.117529 | E40: =7.297*4 -> 29.188 | F40: 5.5 | G40: =$E40*$F40/2+($C40+$C41)/$F40*1.1 -> 137.88763 | H40: =$E40*$F40/2+($D40+$D41)/$F40*1.1 -> 22.646366
B41: end | C41: =(L14*$AI$6*($AI$4-40-0.8*Q14/2)+G14*$AI$6*(0.8*Q14/2-40))/1000^2 -> 97.117529 | D41: =-(G14*$AI$6*($AI$4-40-0.8*Q14/2)+L14*$AI$6*(0.8*Q14/2-40))/1000^2 -> -190.98564 | E41: =7.297*4 -> 29.188 | F41: 5.5 | G41: =-$E41*$F41/2+($C40+$C41)/$F41*1.1 -> -22.646366 | H41: =-$E41*$F41/2+($D40+$D41)/$F41*1.1 -> -137.88763
A42: 3 | B42: start | C42: =(G15*$AI$6*($AI$4-40-0.8*Q15/2)+L15*$AI$6*(0.8*Q15/2-40))/1000^2 -> 190.98564 | D42: =-(L15*$AI$6*($AI$4-40-0.8*Q15/2)+G15*$AI$6*(0.8*Q15/2-40))/1000^2 -> -97.117529 | E42: =7.297*4 -> 29.188 | F42: 4 | G42: =$E42*$F42/2+($C42+$C43)/$F42*1.1 -> 133.97139 | H42: =$E42*$F42/2+($D42+$D43)/$F42*1.1 -> -11.706581
...

Sheet TAGLIO SLV (P3)
A1: TEL. 1 | B1: SEZ. | C1: $A_{sup}$ | H1: $A_{inf}$ | M1: $\rho_{sup}$ | O1: $\rho_{inf}$ | Q1: y | AE1: $\rho_{min}$ | AF1: $\rho_{max}$ | AH1: TRAVE ESTERNA | AL1: b | AM1: h | AN1: d
A2: Camp. | C2: $\phi$ | D2: N$\phi$ | E2: $\phi$ | F2: N$\phi$ | G2: A (mm^2) | H2: $\phi$ | I2: N$\phi$ | J2: $\phi$ | K2: N$\phi$ | L2: A (mm^2) | M2: - | O2: - | Q2: mm | T2: a | U2: b | V2: c | W2: y | X2: $\delta$ | Z2: y1 | AE2: - | AF2: - | AH2: campata 1 | AL2: mm | AM2: mm | AN2: mm
A3: 1 | B3: start | C3: 14 | D3: 2 | E3: 14 | F3: 2 | G3: =(C3^2/4*D3+E3^2/4*F3)*PI() -> 615.75216 | H3: 14 | I3: 2 | J3: 12 | K3: 2 | L3: =(H3^2/4*I3+J3^2/4*K3)*PI() -> 534.07075 | M3: =G3/($AL$3*$AM$3) -> 0.0041050144 | N3: =IF($AE$3<=M3,"OK","NO") -> OK | O3: =L3/($AL$3*$AM$3) -> 0.0035604717 | P3: =IF(O3>$AE$3,"OK","NO") -> OK | Q3: =ABS($AI$6*(G3-L3)/($AI$14*0.8*$AI$3)) -> 7.8338947 | T3: =$AI$3*$AI$14*0.8 -> 4080 | U3: =L3*$AI$15*3.5/1000-G3*$AI$6 -> 151595.5 | V3: =$AI$6,$AI$6,L3*$AI$15*(3.5/1000)*($AI$4-40) -> #VALUE! | W3: =CONCATENATE(T3," y^2 ",IF(U3>0," + "," "),U3," y",IF(V3>0," + "," "),V3, " = 0 ") -> #VALUE! | X3: =U3^2-4*T3*V3 -> #VALUE! | Y3: =IF(X3>0,"2 soluzioni distinte",IF(X3=0,"2 soluzioni coincidenti","nessuna soluzione")) -> #VALUE! | Z3: =IF(X3<0," ",(-U3+SQRT(X3))/(2*T3)) -> #VALUE! | AA3: =IF(X3<0," ",(-U3-SQRT(X3))/(2*T3)) -> #VALUE! | AE3: =1.4/$AI$5 -> 0.0031111111 | AF3: =3.5/$AI$5 -> 0.0077777778 | AH3: b | AI3: =300 -> 300 | AJ3: mm | AL3: 300 | AM3: 500 | AN3: =AM3-40 -> 460
B4: end | C4: 18 | D4: 2 | E4: 18 | F4: 2 | G4: =(C4^2/4*D4+E4^2/4*F4)*PI() -> 1017.876 | H4: 14 | I4: 2 | J4: 12 | K4: 2 | L4: =(H4^2/4*I4+J4^2/4*K4)*PI() -> 534.07075 | M4: =G4/($AL$3*$AM$3) -> 0.0067858401 | N4: =IF($AE$3<=M4,"OK","NO") -> OK | O4: =L4/($AL$3*$AM$3) -> 0.0035604717 | P4: =IF(O4>$AE$3,"OK","NO") -> OK | Q4: =ABS($AI$6*(G4-L4)/($AI$14*0.8*$AI$3)) -> 46.400761 | T4: =$AI$3*$AI$14*0.8 -> 4080 | U4: =G4*$AI$15*3.5/1000-L4*$AI$6 -> 539154.67 | V4: =IF($AI$15*(3.5/1000)*(AA4-40)/(AA4)>$AI$6,$AI$6,L4*$AI$15*(3.5/1000)*($AI$4-40)) -> 0 | W4: =CONCATENATE(T4," y^2 ",IF(U4>0," + "," "),U4," y",IF(V4>0," + "," "),V4, " = 0 ") -> #VALUE! | X4: =U4^2-4*T4*V4 -> #VALUE! | Y4: =IF(X4>0,"2 soluzioni distinte",IF(X4=0,"2 soluzioni coincidenti","nessuna soluzione")) -> #VALUE! | Z4: =IF(X4<0," ",(-U4+SQRT(X4))/(2*T4)) -> #VALUE! | AA4: =IF(X4<0," ",(-U4-SQRT(X4))/(2*T4)) -> #VALUE! | AH4: h | AI4: 500 | AJ4: mm
