Workbook
Name ca: 'Foglio deposito'!$D$2:$D$4
Name cari: 'Foglio deposito'!$F$2:$F$4
Name clas: 'Foglio deposito'!$M$10:$M$18
Name comb: 'Foglio deposito'!$F$2:$F$3
Name fe: 'Foglio deposito'!$P$10:$P$11
Name fes: 'Foglio deposito'!$O$111:$O$113
Name sigc: 'Foglio deposito'!$E$142:$E$143
Name sigs: 'Foglio deposito'!$F$142:$F$143
Name SN: 'Foglio deposito'!$B$2:$B$3
Name w: '[1]DATI NASCOSTI'!$C$105:$C$107

Sheet Istruzioni
B6: Il foglio di calcolo esegue le verifiche allo stato limite di esercizio per le sezioni a "T" e per le
B7: sezioni rettangolari (per verificare una sezione rettangolare basta inserire bw=b).
B8: Si possono modificare solo le sezioni con il bordo doppio.
B9: Salvando in formato pdf la scheda verifica sle si può ricavare la relazione, la stampa è
B10: stata ottimizzata per un risultato ottimale.
B12: versione 1.1
B13: www.davidecicchini.it
I14: Ing. Davide Cicchini
I15: www.davidecicchini.it

Sheet Verifica SLE
B1: Verifica trave SLE
B3: 1-Geometria, definizione dei carichi e dei materiali utilizzati.
B5: Larghezza della base superiore | D5: b | E5: 500 | F5: mm
B6: Larghezza della base inferiore | D6: bw | E6: 100 | F6: mm
B7: Altezza della sezione | D7: h | E7: 220 | F7: mm
B8: Spessore dell'alla | D8: s | E8: 40 | F8: mm
B9: Spessore copriferro | D9: d' | E9: 30 | F9: mm
B11: Classe di resistenza del calcestruzzo | E11: C25/30
B12: Tipo Acciaio | E12: Fe B450C
B13: Modulo elastico dell'acciaio | D13: Es | E13: 210000 | F13: Mpa
B15: Lunghezza della trave (app-app) | D15: L | E15: 5.5 | F15: m
B17: Carico Permanente strutturale | D17: G1 | E17: =1.9*0.5 -> 0.95 | F17: kN/m2
B18: Carico Permanente non strutturale | D18: G2 | E18: =5.92*0.5 -> 2.96 | F18: kN/m2
B19: Carico folla | D19: Qk | E19: =2*0.5 -> 1 | F19: kN/m2
B21: Med combinazione caratteristica | E21: 12.03 | F21: kN/m2
B22: Med combinazione frequente | E22: 9.82 | F22: kN/m2
B23: Med combinazione quasi permanente | E23: 8.93 | F23: kN/m2
B25: La condizione ambientale è: | D25: ordinaria
B27: 2-Armature utilizzate
B29: Rete elettrosaldata | C29: 0 | D29: 20
B31: Armatura Superiore | C31: 10 | D31: 12 | E31: 14 | F31: As, inserita
D32: 3 | F32: =E32*(E31/2)^2*PI()+C32*(C31/2)^2*PI()+D32*(D31/2)^2*PI()+(C29/2)^2*PI()*E5/(D29*10) -> 339.29201
B34: Armatura Inferiore | C34: 10 | D34: 12 | E34: 14 | F34: As, inserita
D35: 2 | F35: =E35*(E34/2)^2*PI()+C35*(C34/2)^2*PI()+D35*(D34/2)^2*PI() -> 226.19467
B37: 3-Riepilogo
B39: Lunghezza trave: | C39: ='Verifica SLE'!E15 -> 5.5 | D39: Qk | E39: =E19 -> 1 | F39: kN/m
D40: ↓ | E40: ↓ | F40: ↓
D42: G2 | E42: =E18 -> 2.96 | F42: kN/m
D43: ↓ | E43: ↓ | F43: ↓
D45: G1 | E45: =E17 -> 0.95 | F45: kN/m
D46: ↓ | E46: ↓ | F46: ↓
E48: =E5/10 -> 50
B49: =IF(C87="LA SEZIONE SI FESSURA (STADIO 2)",D95,D73) -> 30.878075 | E49: =F32 -> 339.29201 | F49: =IF(E6=E5,"",E8/10) -> 4
E51: =IF(F49="",0,F49)*E48+F52*E55 -> 380
B52: =D140 -> 50.247861 | F52: =(E7-E8)/10 -> 18
E54: =F35 -> 226.19467
E55: =(E6)/10 -> 10
B56: 4-Resistenze dei materiali
B57: Rck | C57: ='Foglio deposito'!S10 -> 30 | D57: N/mm2
B58: fck | C58: ='Foglio deposito'!S10*0.83 -> 24.9 | D58: N/mm2
...

Sheet Foglio1

Sheet fessurazione semplific.
B2: Verifica della fessurazione senza calcolo diretto, in combinazione quasi
B3: permanente
B5: La verifica dell'ampiezza di fesseurazione per via indiretta, può riferirsi ai limiti
B6: di tensione nell'acciaio di armatura definiti nelle tabelle C.4.1.II e C.4.1.III.
B7: La tensione σs è quella nell'acciaio d'armatura prossimo al lembo teso della
B8: sezione calcolata nella sezione parzializzata per la combinazione di carico
B9: pertinente.
B10: Lo stato limite di apertura delle fessure, riferito alla combinazione di azioni
B11: prescelta, è il valore limite di apertura della fessura calcolato al livello
B12: considerato. In particolare si assume pari ad uno dei seguenti valori nominali.
B13: Lo stato limite deve essere fissato in funzione delle condizioni ambientali e della
B14: sensibilità delle armature.
C16: w1 | D16: 0,2 mm
C17: w2 | D17: 0,3 mm
C18: w3 | D18: 0,4 mm
B51: La condizione ambientale è: | E51: ='Verifica SLE'!D25 -> ordinaria
B53: Le armature utilizzate riportano le seguenti caratteristiche:
B55: copriferro laterale: | E55: ='Verifica SLE'!E9 -> 30
B57: Passo medio delle armature: | E57: =('Verifica SLE'!E6-2*E55-'Verifica SLE'!C35*'Verifica SLE'!C34-'Verifica SLE'!D35*'Verifica SLE'!D34-'Verifica SLE'!E35*'Verifica SLE'!E34)/('Verifica SLE'!C35+'Verifica SLE'!D35+'Verifica SLE'!E35) -> 8
B58: Massimo diametro utilizzato: | E58: =MAXA(IF('Verifica SLE'!C35=0,0,'Verifica SLE'!C34),IF('Verifica SLE'!D35=0,0,'Verifica SLE'!D34),IF('Verifica SLE'!E35=0,0,'Verifica SLE'!E34)) -> 12

Sheet Foglio deposito
B2: SI | D2: ordinaria | F2: P,sle carat. | G2: ='Verifica SLE'!E17+'Verifica SLE'!E18+'Verifica SLE'!E19 -> 4.91 | H2: ='Verifica SLE'!E21 -> 12.03
B3: NO | D3: aggressiva | F3: P,sle freq. | G3: ='Verifica SLE'!E17+'Verifica SLE'!E18+0.5*'Verifica SLE'!E19 -> 4.41 | H3: ='Verifica SLE'!E22 -> 9.82 | I3: n,vec | J3: ='Verifica SLE'!D135 -> 24.663593 | M3: Spessore dell'anima equivalente | O3: bW | P3: ='Verifica SLE'!E55*10 -> 100 | Q3: mm
D4: molto aggressiva | F4: P,sle quas. Perm | G4: ='Verifica SLE'!E17+'Verifica SLE'!E18+0.3*'Verifica SLE'!E19 -> 4.21 | H4: ='Verifica SLE'!E23 -> 8.93 | I4: n,gio | J4: ='Verifica SLE'!D90 -> 6.6778682 | M4: Altezza utile della sezione | O4: d | P4: ='Verifica SLE'!E7-'Verifica SLE'!E9 -> 190 | Q4: mm | V4: h0 | W4: =(2*((AB6*AB10)+(AB7*(AB8-AB10))))/(AB6+AB7) -> 126.66667 | Z4: 1 | AA4: As= | AB4: ='Verifica SLE'!F35 -> 226.19467 | AC4: mm2
I5: b | J5: =J29 -> 500 | Z5: =1+Z4 -> 2 | AA5: A's= | AB5: ='Verifica SLE'!F32 -> 339.29201 | AC5: mm2
B6: accsup | I6: b0 | J6: =J30 -> 100 | V6: h0 | W6: kh | Z6: =1+Z5 -> 3 | AA6: b= | AB6: ='Verifica SLE'!E5 -> 500 | AC6: mm
B7: =B24 -> 339.29201 | I7: s | J7: =J31 -> 40 | V7: 10 | W7: 1 | Z7: =1+Z6 -> 4 | AA7: b0= | AB7: ='Verifica SLE'!E6 -> 100 | AC7: mm
B8: accinf | I8: d | J8: =J32 -> 190 | V8: =W4 -> 126.66667 | W8: =-((W7-W9)/(V7-V9)*(V9-V8)-W9) -> 0.90789474 | Z8: =1+Z7 -> 5 | AA8: h= | AB8: ='Verifica SLE'!E7 -> 220 | AC8: mm
B9: =B26 -> 226.19467 | I9: d' | J9: =J33 -> 30 | V9: 200 | W9: 0.85 | Z9: =1+Z8 -> 6 | AA9: d'= | AB9: ='Verifica SLE'!E9 -> 30 | AC9: mm
B10: Atot,equival | M10: C8/10 | N10: =10 -> 10 | P10: Fe B450C | Q10: 450 | S10: =VLOOKUP('Verifica SLE'!E11,'Foglio deposito'!M10:N21,2,) -> 30 | V10: =W4 -> 126.66667 | W10: =-((W9-W11)/(V9-V11)*(V11-V10)-W11) -> 0.92333333 | Z10: =1+Z9 -> 7 | AA10: s= | AB10: ='Verifica SLE'!E8 -> 40 | AC10: mm
B11: =B7+B9 -> 565.48668 | M11: C12/15 | N11: 15 | P11: Fe B44k | Q11: 430 | S11: =VLOOKUP('Verifica SLE'!E12,'Foglio deposito'!P10:Q11,2,) -> 450 | V11: 300 | W11: 0.75 | Z11: =1+Z10 -> 8 | AA11: d= | AB11: ='Foglio deposito'!P4 -> 190 | AC11: mm
M12: C16/20 | N12: 20 | V12: =W4 -> 126.66667 | W12: =-((W11-W13)/(V11-V13)*(V13-V12)-W13) -> 0.79333333 | Z12: =1+Z11 -> 9 | AA12: Ec= | AB12: =22000*(('Foglio deposito'!S10*0.83+8)/10)^0.3 -> 31447.161 | AC12: N/mm2
B13: A | C13: B | D13: C | E13: x | M13: C20/25 | N13: 25 | V13: 500 | W13: 0.7 | Z13: =1+Z12 -> 10 | AA13: Es= | AB13: ='Verifica SLE'!E13 -> 210000 | AC13: N/mm2
B14: =J6/2 -> 50 | C14: =(J5*J7+J6+J4*B7+J4*B9) -> 23876.246 | D14: =-J5*J7^2/2-J6*J8-J4*B7*J9-J4*B9*J8 -> -773967.08 | E14: =(-C14+(C14^2-4*B14*D14)^0.5)/(2*B14) -> 30.471368 | M14: C25/30 | N14: 30 | Z14: =1+Z13 -> 11 | AA14: Ec,eff= | AB14: =AB12/(1+W24) -> 8514.5744 | AC14: N/mm2
M15: C28/35 | N15: 35 | V15: ho | W15: ϕ | Z15: =1+Z14 -> 12 | AA15: fck= | AB15: ='Verifica SLE'!C58 -> 24.9 | AC15: N/mm2
M16: C32/40 | N16: 40 | V16: 75 | W16: 2.9 | Z16: =1+Z15 -> 13 | AA16: fctm= | AB16: ='Verifica SLE'!C60 -> 2.5581194 | AC16: N/mm2
M17: C35/45 | N17: 45 | V17: =W4 -> 126.66667 | W17: =-((W16-W18)/(V16-V18)*(V18-V17)-W18) -> 2.6933333 | Z17: =1+Z16 -> 14 | AA17: fctk= | AB17: ='Verifica SLE'!C61 -> 1.7906836 | AC17: N/mm2
M18: C40/50 | N18: 50 | V18: 150 | W18: 2.6 | Z18: =1+Z17 -> 15 | AA18: n= | AB18: =AB13/AB14 -> 24.663593 | AC18: coeff. di omog. cls vecchio
M19: C45/55 | N19: 55 | V19: =W4 -> 126.66667 | W19: =-((W18-W20)/(V18-V20)*(V20-V19)-W20) -> 2.6466667 | Z19: =1+Z18 -> 16 | AA19: n' | AB19: =AB13/AB12 -> 6.6778682 | AC19: coeff. di omog. cls giovane
V20: 300 | W20: 2.3 | Z20: =1+Z19 -> 17 | AA20: σc-= | AB20: 9.75 | AC20: N/mm2
D21: sol | M21: C50/60 | N21: 60 | V21: =W4 -> 126.66667 | W21: =-((W20-W22)/(V20-V22)*(V22-V21)-W22) -> 2.3577778 | Z21: =1+Z20 -> 18 | AA21: fyk= | AB21: =S11 -> 450 | AC21: N/mm2 | AD21: FeB450c
D22: =('Verifica SLE'!E5-'Foglio deposito'!P3)/'Verifica SLE'!D90*'Verifica SLE'!E8 -> 2395.9742 | V22: 600 | W22: 2.2
B23: accsup | D23: accsup | AA23: STADIO 1 CLS GIOVANE
B24: =D24 -> 339.29201 | D24: ='Verifica SLE'!F32 -> 339.29201 | V24: ϕ | W24: =IF(W4<V18,W17,IF(W4<V20,W19,W21)) -> 2.6933333 | AA24: x | AB24: =(AB19*(AB43+AB4+AB5)*AB45+AB7*AB8^2/2)/(AB19*(AB43+AB4+AB5)+AB7*AB8) -> 74.084376 | AC24: mm
B25: accinf | D25: accinf | AA25: jid1= | AB25: =AB6*AB10^3/12+AB6*AB10*(AB10/2-AB24)^2+AB7*(AB8-AB10)^3/12+AB7*(AB8-AB10)*((AB8-AB10)/2-(AB24-AB10))^2+AB19*AB5*(AB24-AB9)^2+AB19*AB4*(AB11-AB24)^2 -> 1.9074612e+08 | AC25: mm4
B26: =D26 -> 226.19467 | D26: ='Verifica SLE'!F35 -> 226.19467 | AA26: J,solo cls | AB26: =AB6*AB10^3/12+AB6*AB10*(AB10/2-AB27)^2+AB7*(AB8-AB10)^3/12+AB7*(AB8-AB10)*((AB8-AB10)/2-(AB27-AB10))^2 -> 1.6589825e+08 | AC26: mm4
B27: Atot,equival | D27: Atot,equival | AA27: x,solo cls | AB27: =(AB19*AB43*AB10/2+AB7*AB8^2/2)/(AB19*AB43+AB7*AB8) -> 72.105263 | AC27: mm
B28: =B24+B26 -> 565.48668 | D28: =D22+D24+D26 -> 2961.4609 | AA28: σ_c | AC28: N/mm2
I29: b | J29: =J54 -> 500 | AA29: σ_s | AC29: N/mm2
B30: xsoletta | D30: xfuori | F30: xsoletta,approx | I30: b0 | J30: =J55 -> 100
B31: =B39*(-1+(1+2*B33/B39)^0.5) -> 30.878075 | D31: =D39*(-1+(1+2*D33/D39)^0.5) -> 31.604784 | F31: =F39*(-1+(1+2*F33/F39)^0.5) -> 37.211797 | I31: s | J31: =J56 -> 40
B32: d,virt | D32: d,virt | F32: d | I32: d | J32: =J57 -> 190 | AA32: STADIO 1 CLS VECCHIO
B33: =(B24*J33+B26*J32)/(B24+B26) -> 94 | D33: =(D22*J31/2+D24*J33+D26*J32)/D28 -> 34.130193 | F33: ='Foglio deposito'!P4 -> 190 | I33: d' | J33: =J58 -> 30 | AA33: x | AB33: =(AB18*(AB55+AB4+AB5)*AB57+AB7*AB8^2/2)/(AB18*(AB55+AB4+AB5)+AB7*AB8) -> 77.983655 | AC33: mm
AA34: jid1= | AB34: =AB6*AB10^3/12+AB6*AB10*(AB10/2-AB33)^2+AB7*(AB8-AB10)^3/12+AB7*(AB8-AB10)*((AB8-AB10)/2-(AB33-AB10))^2+AB18*AB5*(AB33-AB9)^2+AB18*AB4*(AB11-AB33)^2 -> 2.5647903e+08 | AC34: mm4
B35: As, virtuale | D35: As, virtuale | F35: As | AA35: σ_c | AC35: N/mm2
B36: =((('Verifica SLE'!C29/2)^2*PI()*'Verifica SLE'!E5/200))+'Verifica SLE'!F32 -> 339.29201 | D36: =D22+D24+D26 -> 2961.4609 | F36: ='Verifica SLE'!F32 -> 339.29201 | AA36: σ_s | AC36: N/mm2
B38: f | D38: f | F38: f
B39: ='Verifica SLE'!D90/J29*B28 -> 7.552491 | D39: ='Verifica SLE'!D90*D28/J30 -> 197.76246 | F39: ='Verifica SLE'!D90/J29*F36 -> 4.5314946 | AA39: STADIO 2 CLS GIOVANE
AA40: ηs | AB40: =AB19*(AB4+AB5)/AB6 -> 7.552491 | AC40: mm
B41: j | D41: j | AA41: d0 | AB41: =(AB4*AB11+AB5*AB9)/(AB4+AB5) -> 94 | AC41: mm
B42: =1/3*J29*B31^3+'Verifica SLE'!D90*(B26*(J32-B31)^2+B24*(B31-J33)^2) -> 43154052 | D42: =J30*D31^3/3+(J29-J30)*J31^3/12+(J29-J30)*J31*(D31-J31/2)^2+'Verifica SLE'!D90*D24*(D31-J33)^2+'Verifica SLE'!D90*D26*(J32-D31)^2 -> 43243156 | AA42: x | AB42: =AB40*(-1+SQRT(1+2*AB41/AB40)) -> 30.878075 | AC42: mm | AD42: =IF(AB42<$AB$10,TRUE,FALSE) -> TRUE
...
