Workbook

Sheet PressoflessioneX
B1: DIREZIONE X
B2: Frame | C2: Joint | D2: F3 | E2: Mc | F2: ∑MC,Rd | G2: Mb,sx | H2: Mb,dx | I2: ∑Mb,Rd | J2: Verifica | K2: D/C
B3: Text | C3: Text | D3: KN | E3: KNm | F3: KNm | G3: KNm | H3: KNm | I3: KNm | J3: 1.3∑Mb,Rd<∑MC,Rd | K3: -
A4: PRIMO PIANO | B4: 1 | C4: 2 | D4: 40.211 | E4: 263.3 | F4: =SUM(E4:E5) -> 500.6 | G4: 0 | H4: 203 | I4: =SUM(G4:H5) -> 203 | J4: =IF(F4>1.3*I4,"OK","NO") -> OK | K4: =1.3*I4/F4 -> 0.5271674
B5: 6 | C5: 2 | D5: 54.19 | E5: 237.3
B6: 2 | C6: 4 | D6: 248.76 | E6: 293.3 | F6: =SUM(E6:E7) -> 547.8 | G6: 183 | H6: 183 | I6: =SUM(G6:H7) -> 366 | J6: =IF(F6>1.3*I6,"OK","NO") -> OK | K6: =1.3*I6/F6 -> 0.86856517
B7: 7 | C7: 4 | D7: 201.35 | E7: 254.5
B8: 3 | C8: 6 | D8: 306.071 | E8: 300.3 | F8: =SUM(E8:E9) -> 559.4 | G8: 183 | H8: 145 | I8: =SUM(G8:H9) -> 328 | J8: =IF(F8>1.3*I8,"OK","NO") -> OK | K8: =1.3*I8/F8 -> 0.76224526
B9: 8 | C9: 6 | D9: 244.739 | E9: 259.1
B10: 4 | C10: 8 | D10: 275.856 | E10: 296.7 | F10: =SUM(E10:E11) -> 553.7 | G10: 203 | H10: 145 | I10: =SUM(G10:H11) -> 348 | J10: =IF(F10>1.3*I10,"OK","NO") -> OK | K10: =1.3*I10/F10 -> 0.81704894
B11: 9 | C11: 8 | D11: 224.605 | E11: 257
B12: 5 | C12: 10 | D12: 37.24 | E12: 262.7 | F12: =SUM(E12:E13) -> 499.8 | G12: 203 | H12: 0 | I12: =SUM(G12:H13) -> 203 | J12: =IF(F12>1.3*I12,"OK","NO") -> OK | K12: =1.3*I12/F12 -> 0.5280112
B13: 10 | C13: 10 | D13: 53.019 | E13: 237.1
B14: 42 | C14: 27 | D14: 447.009 | E14: 171.3 | F14: =SUM(E14:E15) -> 331.1 | G14: 0 | H14: 48 | I14: =SUM(G14:H15) -> 48 | J14: =IF(F14>1.3*I14,"OK","NO") -> OK | K14: =1.3*I14/F14 -> 0.1884627
B15: 47 | C15: 27 | D15: 335.932 | E15: 159.8
B16: 43 | C16: 29 | D16: 650.365 | E16: 182.6 | F16: =SUM(E16:E17) -> 354.4 | G16: 48 | H16: 48 | I16: =SUM(G16:H17) -> 96 | J16: =IF(F16>1.3*I16,"OK","NO") -> OK | K16: =1.3*I16/F16 -> 0.35214447
B17: 48 | C17: 29 | D17: 494.517 | E17: 171.8
B18: 44 | C18: 31 | D18: 760.322 | E18: 186.7 | F18: =SUM(E18:E19) -> 361.5 | G18: 48 | H18: 48 | I18: =SUM(G18:H19) -> 96 | J18: =IF(F18>1.3*I18,"OK","NO") -> OK | K18: =1.3*I18/F18 -> 0.34522822
B19: 49 | C19: 31 | D19: 575.796 | E19: 174.8
B20: 45 | C20: 33 | D20: 754.006 | E20: 186 | F20: =SUM(E20:E21) -> 360.7 | G20: 48 | H20: 48 | I20: =SUM(G20:H21) -> 96 | J20: =IF(F20>1.3*I20,"OK","NO") -> OK | K20: =1.3*I20/F20 -> 0.3459939
B21: 50 | C21: 33 | D21: 571.358 | E21: 174.7
B22: 46 | C22: 35 | D22: 441.692 | E22: 170.8 | F22: =SUM(E22:E23) -> 330.4 | G22: 48 | H22: 0 | I22: =SUM(G22:H23) -> 48 | J22: =IF(F22>1.3*I22,"OK","NO") -> OK | K22: =1.3*I22/F22 -> 0.18886199
B23: 51 | C23: 35 | D23: 333.615 | E23: 159.6
A24: SECONDO PIANO | B24: 6 | C24: 11 | D24: 42.943 | E24: 235.5 | F24: =SUM(E24:E25) -> 443.3 | G24: 0 | H24: 203 | I24: =SUM(G24:H25) -> 203 | J24: =IF(F24>1.3*I24,"OK","NO") -> OK | K24: =1.3*I24/F24 -> 0.59530792
B25: 11 | C25: 11 | D25: 51.828 | E25: 207.8
B26: 7 | C26: 12 | D26: 190.104 | E26: 253.3 | F26: =SUM(E26:E27) -> 469.2 | G26: 180 | H26: 180 | I26: =SUM(G26:H27) -> 360 | J26: =IF(F26>1.3*I26,"OK","NO") -> OK | K26: =1.3*I26/F26 -> 0.99744246
B27: 12 | C27: 12 | D27: 137.894 | E27: 215.9
B28: 8 | C28: 13 | D28: 233.492 | E28: 257.9 | F28: =SUM(E28:E29) -> 476.5 | G28: 183 | H28: 145 | I28: =SUM(G28:H29) -> 328 | J28: =IF(F28>1.3*I28,"OK","NO") -> OK | K28: =1.3*I28/F28 -> 0.89485834
B29: 13 | C29: 13 | D29: 166.454 | E29: 218.6
B30: 9 | C30: 14 | D30: 213.358 | E30: 255.8 | F30: =SUM(E30:E31) -> 473.5 | G30: 188 | H30: 145 | I30: =SUM(G30:H31) -> 333 | J30: =IF(F30>1.3*I30,"OK","NO") -> OK | K30: =1.3*I30/F30 -> 0.91425554
B31: 14 | C31: 14 | D31: 156.281 | E31: 217.7
B32: 10 | C32: 15 | D32: 41.773 | E32: 235.3 | F32: =SUM(E32:E33) -> 443.1 | G32: 203 | H32: 0 | I32: =SUM(G32:H33) -> 203 | J32: =IF(F32>1.3*I32,"OK","NO") -> OK | K32: =1.3*I32/F32 -> 0.59557662
B33: 15 | C33: 15 | D33: 51.773 | E33: 207.8
B34: 47 | C34: 36 | D34: 324.685 | E34: 158.8 | F34: =SUM(E34:E35) -> 305.8 | G34: 0 | H34: 48 | I34: =SUM(G34:H35) -> 48 | J34: =IF(F34>1.3*I34,"OK","NO") -> OK | K34: =1.3*I34/F34 -> 0.20405494
B35: 52 | C35: 36 | D35: 213.893 | E35: 147
B36: 48 | C36: 37 | D36: 483.27 | E36: 171.4 | F36: =SUM(E36:E37) -> 329.2 | G36: 48 | H36: 48 | I36: =SUM(G36:H37) -> 96 | J36: =IF(F36>1.3*I36,"OK","NO") -> OK | K36: =1.3*I36/F36 -> 0.37910085
B37: 53 | C37: 37 | D37: 328.632 | E37: 157.8
B38: 49 | C38: 38 | D38: 564.549 | E38: 174.4 | F38: =SUM(E38:E39) -> 336.6 | G38: 48 | H38: 48 | I38: =SUM(G38:H39) -> 96 | J38: =IF(F38>1.3*I38,"OK","NO") -> OK | K38: =1.3*I38/F38 -> 0.37076649
B39: 54 | C39: 38 | D39: 381.7 | E39: 162.2
B40: 50 | C40: 39 | D40: 560.111 | E40: 174.2 | F40: =SUM(E40:E41) -> 336.3 | G40: 48 | H40: 48 | I40: =SUM(G40:H41) -> 96 | J40: =IF(F40>1.3*I40,"OK","NO") -> OK | K40: =1.3*I40/F40 -> 0.37109723
...

Sheet Pressoflessione
B1: DIREZIONE Y
B2: Frame | C2: Joint | D2: F3 | E2: Mc | F2: ∑MC,Rd | G2: Mb,sx | H2: Mb,dx | I2: ∑Mb,Rd | J2: Verifica | K2: D/C
B3: Text | C3: Text | D3: KN | E3: KNm | F3: KNm | G3: KNm | H3: KNm | I3: KNm | J3: 1.3∑Mb,Rd<∑MC,Rd | K3: -
A4: PRIMO PIANO | B4: 1 | C4: 2 | D4: 40.211 | E4: 131.1 | F4: =SUM(E4:E5) -> 262.8 | G4: 164.00683 | H4: 0 | I4: =SUM(G4:G5) -> 164.00683 | J4: =IF(F4>1.3*I4,"OK","NO") -> OK | K4: =1.3*I4/F4 -> 0.81129713
B5: 6 | C5: 2 | D5: 54.19 | E5: 131.7
B6: 2 | C6: 4 | D6: 248.76 | E6: 152.4 | F6: =SUM(E6:E7) -> 299.2 | G6: 162.8612 | H6: 0 | I6: =SUM(G6:H7) -> 162.8612 | J6: =IF(F6>1.3*I6,"OK","NO") -> OK | K6: =1.3*I6/F6 -> 0.70761885
B7: 7 | C7: 4 | D7: 201.35 | E7: 146.8
B8: 3 | C8: 6 | D8: 306.071 | E8: 158.2 | F8: =SUM(E8:E9) -> 309.3 | G8: 162.8612 | H8: 0 | I8: =SUM(G8:H9) -> 162.8612 | J8: =IF(F8>1.3*I8,"OK","NO") -> OK | K8: =1.3*I8/F8 -> 0.68451199
B9: 8 | C9: 6 | D9: 244.739 | E9: 151.1
B10: 4 | C10: 8 | D10: 275.856 | E10: 155.2 | F10: =SUM(E10:E11) -> 304.3 | G10: 162.8612 | H10: 0 | I10: =SUM(G10:H11) -> 162.8612 | J10: =IF(F10>1.3*I10,"OK","NO") -> OK | K10: =1.3*I10/F10 -> 0.69575931
B11: 9 | C11: 8 | D11: 224.605 | E11: 149.1
B12: 5 | C12: 10 | D12: 37.24 | E12: 130.7 | F12: =SUM(E12:E13) -> 262.3 | G12: 164.00683 | H12: 0 | I12: =SUM(G12:H13) -> 164.00683 | J12: =IF(F12>1.3*I12,"OK","NO") -> OK | K12: =1.3*I12/F12 -> 0.81284363
B13: 10 | C13: 10 | D13: 53.019 | E13: 131.6
B14: 42 | C14: 27 | D14: 447.009 | E14: 316.8 | F14: =SUM(E14:E15) -> 585.5 | G14: 195.80299 | H14: 106.01489 | I14: =SUM(G14:H15) -> 301.81788 | J14: =IF(F14>1.3*I14,"OK","NO") -> OK | K14: =1.3*I14/F14 -> 0.67013363
B15: 47 | C15: 27 | D15: 335.932 | E15: 268.7
B16: 43 | C16: 29 | D16: 650.365 | E16: 338.3 | F16: =SUM(E16:E17) -> 623.1 | G16: 195.80299 | H16: 106.01489 | I16: =SUM(G16:H17) -> 301.81788 | J16: =IF(F16>1.3*I16,"OK","NO") -> OK | K16: =1.3*I16/F16 -> 0.62969546
B17: 48 | C17: 29 | D17: 494.517 | E17: 284.8
B18: 44 | C18: 31 | D18: 760.322 | E18: 348.5 | F18: =SUM(E18:E19) -> 640.3 | G18: 214.1077 | H18: 106.01489 | I18: =SUM(G18:H19) -> 320.12258 | J18: =IF(F18>1.3*I18,"OK","NO") -> OK | K18: =1.3*I18/F18 -> 0.64994433
B19: 49 | C19: 31 | D19: 575.796 | E19: 291.8
B20: 45 | C20: 33 | D20: 754.006 | E20: 348 | F20: =SUM(E20:E21) -> 639.4 | G20: 214.1077 | H20: 106.01489 | I20: =SUM(G20:H21) -> 320.12258 | J20: =IF(F20>1.3*I20,"OK","NO") -> OK | K20: =1.3*I20/F20 -> 0.65085917
B21: 50 | C21: 33 | D21: 571.358 | E21: 291.4
B22: 46 | C22: 35 | D22: 441.692 | E22: 316.1 | F22: =SUM(E22:E23) -> 584.5 | G22: 195.80299 | H22: 106.01489 | I22: =SUM(G22:H23) -> 301.81788 | J22: =IF(F22>1.3*I22,"OK","NO") -> OK | K22: =1.3*I22/F22 -> 0.67128014
B23: 51 | C23: 35 | D23: 333.615 | E23: 268.4
A24: SECONDO PIANO | B24: 6 | C24: 11 | D24: 42.943 | E24: 130.6 | F24: =SUM(E24:E25) -> 261.3 | G24: 164.00683 | H24: 0 | I24: =SUM(G24:H25) -> 164.00683 | J24: =IF(F24>1.3*I24,"OK","NO") -> OK | K24: =1.3*I24/F24 -> 0.8159544
B25: 11 | C25: 11 | D25: 51.828 | E25: 130.7
B26: 7 | C26: 12 | D26: 190.104 | E26: 145.7 | F26: =SUM(E26:E27) -> 285.2 | G26: 162.8612 | H26: 0 | I26: =SUM(G26:H27) -> 162.8612 | J26: =IF(F26>1.3*I26,"OK","NO") -> OK | K26: =1.3*I26/F26 -> 0.74235469
B27: 12 | C27: 12 | D27: 137.894 | E27: 139.5
B28: 8 | C28: 13 | D28: 233.492 | E28: 150 | F28: =SUM(E28:E29) -> 291.3 | G28: 162.8612 | H28: 0 | I28: =SUM(G28:H29) -> 162.8612 | J28: =IF(F28>1.3*I28,"OK","NO") -> OK | K28: =1.3*I28/F28 -> 0.72680933
B29: 13 | C29: 13 | D29: 166.454 | E29: 141.3
B30: 9 | C30: 14 | D30: 213.358 | E30: 148 | F30: =SUM(E30:E31) -> 289.3 | G30: 162.8612 | H30: 0 | I30: =SUM(G30:H31) -> 162.8612 | J30: =IF(F30>1.3*I30,"OK","NO") -> OK | K30: =1.3*I30/F30 -> 0.73183394
B31: 14 | C31: 14 | D31: 156.281 | E31: 141.3
B32: 10 | C32: 15 | D32: 41.773 | E32: 130.4 | F32: =SUM(E32:E33) -> 261 | G32: 164.00683 | H32: 0 | I32: =SUM(G32:H33) -> 164.00683 | J32: =IF(F32>1.3*I32,"OK","NO") -> OK | K32: =1.3*I32/F32 -> 0.81689228
B33: 15 | C33: 15 | D33: 51.773 | E33: 130.6
B34: 47 | C34: 36 | D34: 324.685 | E34: 267.5 | F34: =SUM(E34:E35) -> 490.5 | G34: 195.80299 | H34: 106.01489 | I34: =SUM(G34:H35) -> 301.81788 | J34: =IF(F34>1.3*I34,"OK","NO") -> OK | K34: =1.3*I34/F34 -> 0.79992506
B35: 52 | C35: 36 | D35: 213.893 | E35: 223
B36: 48 | C36: 37 | D36: 483.27 | E36: 283.3 | F36: =SUM(E36:E37) -> 516.8 | G36: 195.80299 | H36: 106.01489 | I36: =SUM(G36:H37) -> 301.81788 | J36: =IF(F36>1.3*I36,"OK","NO") -> OK | K36: =1.3*I36/F36 -> 0.7592168
B37: 53 | C37: 37 | D37: 328.632 | E37: 233.5
B38: 49 | C38: 38 | D38: 564.549 | E38: 290.8 | F38: =SUM(E38:E39) -> 528.9 | G38: 214.1077 | H38: 106.01489 | I38: =SUM(G38:H39) -> 320.12258 | J38: =IF(F38>1.3*I38,"OK","NO") -> OK | K38: =1.3*I38/F38 -> 0.78683939
B39: 54 | C39: 38 | D39: 381.7 | E39: 238.1
B40: 50 | C40: 39 | D40: 560.111 | E40: 290.4 | F40: =SUM(E40:E41) -> 528.3 | G40: 214.1077 | H40: 106.01489 | I40: =SUM(G40:H41) -> 320.12258 | J40: =IF(F40>1.3*I40,"OK","NO") -> OK | K40: =1.3*I40/F40 -> 0.78773302
...

Sheet Taglio
B1: Pil. | C1: Zona critica | D1: φ | E1: s | F1: nb | G1: cot(θ) | H1: VR,sd | I1: VR,cd | J1: VR,d | K1: NE,d | L1: MC,Rd | M1: VEd
B2: - | C2: mm | D2: mm | E2: mm | F2: - | G2: - | H2: KN | I2: KN | J2: KN | K2: KN | L2: KNm | M2: KN
A3: PIANO 1 | B3: 1 | C3: =MAX(3000/6,550,450) -> 550 | D3: 10 | E3: 150 | F3: 4 | G3: =MAX(1,M3*1000*E3/(2*D3^2/4*PI()*(550-40)*391)) -> 1.1104212 | H3: =(0.9*(550-30)*(F3*PI()*D3^2/4)/E3*391)*G3/1000 -> 425.568 | I3: =(0.9*(550-30)*300*0.5*17*0.5)*(G3/(1+G3^2))/1000 -> 296.72095 | J3: =MIN(H3:I3) -> 296.72095 | K3: -442.041 | L3: 316.2 | M3: =L3*2/3*1.1 -> 231.88 | N3: =IF(J3>M3,"OK","NO") -> OK
B4: 2 | C4: =MAX(3000/6,550,450) -> 550 | D4: 10 | E4: 150 | F4: 4 | G4: =MAX(1,M4*1000*E4/(2*D4^2/4*PI()*(550-40)*391)) -> 1.1961083 | H4: =(0.9*(550-30)*(F4*PI()*D4^2/4)/E4*391)*G4/1000 -> 458.40753 | I4: =(0.9*(550-30)*300*0.5*17*0.5)*(G4/(1+G4^2))/1000 -> 293.62946 | J4: =MIN(H4:I4) -> 293.62946 | K4: -673.344 | L4: 340.6 | M4: =L4*2/3*1.1 -> 249.77333 | N4: =IF(J4>M4,"OK","NO") -> OK
B5: 3 | C5: =MAX(3000/6,550,450) -> 550 | D5: 10 | E5: 150 | F5: 4 | G5: =MAX(1,M5*1000*E5/(2*D5^2/4*PI()*(550-40)*391)) -> 1.2319284 | H5: =(0.9*(550-30)*((F5*PI()*D5^2/4)/E5)*391)*G5/1000 -> 472.13553 | I5: =(0.9*(550-30)*300*0.5*17*0.5)*(G5/(1+G5^2))/1000 -> 291.97561 | J5: =MIN(H5:I5) -> 291.97561 | K5: -790.545 | L5: 350.8 | M5: =L5*2/3*1.1 -> 257.25333 | N5: =IF(J5>M5,"OK","NO") -> OK
B6: 4 | C6: =MAX(3000/6,550,450) -> 550 | D6: 10 | E6: 150 | F6: 4 | G6: =MAX(1,M6*1000*E6/(2*D6^2/4*PI()*(550-40)*391)) -> 1.2308748 | H6: =(0.9*(550-30)*(F6*PI()*D6^2/4)/E6*391)*G6/1000 -> 471.73176 | I6: =(0.9*(550-30)*300*0.5*17*0.5)*(G6/(1+G6^2))/1000 -> 292.02687 | J6: =MIN(H6:I6) -> 292.02687 | K6: -783.219 | L6: 350.5 | M6: =L6*2/3*1.1 -> 257.03333 | N6: =IF(J6>M6,"OK","NO") -> OK
B7: 5 | C7: =MAX(3000/6,550,450) -> 550 | D7: 10 | E7: 150 | F7: 4 | G7: =MAX(1,M7*1000*E7/(2*D7^2/4*PI()*(550-40)*391)) -> 1.1107724 | H7: =(0.9*(550-30)*(F7*PI()*D7^2/4)/E7*391)*G7/1000 -> 425.70259 | I7: =(0.9*(550-30)*300*0.5*17*0.5)*(G7/(1+G7^2))/1000 -> 296.71114 | J7: =MIN(H7:I7) -> 296.71114 | K7: -442.359 | L7: 316.3 | M7: =L7*2/3*1.1 -> 231.95333 | N7: =IF(J7>M7,"OK","NO") -> OK
B8: 42 | C8: =MAX(3000/6,550,450) -> 550 | D8: 10 | E8: 150 | F8: 4 | G8: =MAX(1,M8*1000*E8/(2*D8^2/4*PI()*(550-40)*391)) -> 1.241059 | H8: =(0.9*(550-30)*(F8*PI()*D8^2/4)/E8*391)*G8/1000 -> 475.63482 | I8: =(0.9*(550-30)*300*0.5*17*0.5)*(G8/(1+G8^2))/1000 -> 291.52504 | J8: =MIN(H8:I8) -> 291.52504 | K8: -868.4 | L8: 353.4 | M8: =L8*2/3*1.1 -> 259.16 | N8: =IF(J8>M8,"OK","NO") -> OK
B9: 43 | C9: =MAX(3000/6,550,450) -> 550 | D9: 10 | E9: 150 | F9: 4 | G9: =MAX(1,M9*1000*E9/(2*D9^2/4*PI()*(550-40)*391)) -> 1.2737184 | H9: =(0.9*(550-30)*(F9*PI()*D9^2/4)/E9*391)*G9/1000 -> 488.15153 | I9: =(0.9*(550-30)*300*0.5*17*0.5)*(G9/(1+G9^2))/1000 -> 289.82603 | J9: =MIN(H9:I9) -> 289.82603 | K9: -1286.674 | L9: 362.7 | M9: =L9*2/3*1.1 -> 265.98 | N9: =IF(J9>M9,"OK","NO") -> OK
B10: 44 | C10: =MAX(3000/6,550,450) -> 550 | D10: 10 | E10: 150 | F10: 4 | G10: =MAX(1,M10*1000*E10/(2*D10^2/4*PI()*(550-40)*391)) -> 1.2645878 | H10: =(0.9*(550-30)*(F10*PI()*D10^2/4)/E10*391)*G10/1000 -> 484.65224 | I10: =(0.9*(550-30)*300*0.5*17*0.5)*(G10/(1+G10^2))/1000 -> 290.3142 | J10: =MIN(H10:I10) -> 290.3142 | K10: -1501.511 | L10: 360.1 | M10: =L10*2/3*1.1 -> 264.07333 | N10: =IF(J10>M10,"OK","NO") -> OK
B11: 45 | C11: =MAX(3000/6,550,450) -> 550 | D11: 10 | E11: 150 | F11: 4 | G11: =MAX(1,M11*1000*E11/(2*D11^2/4*PI()*(550-40)*391)) -> 1.2659925 | H11: =(0.9*(550-30)*(F11*PI()*D11^2/4)/E11*391)*G11/1000 -> 485.19059 | I11: =(0.9*(550-30)*300*0.5*17*0.5)*(G11/(1+G11^2))/1000 -> 290.23974 | J11: =MIN(H11:I11) -> 290.23974 | K11: -1496.55 | L11: 360.5 | M11: =L11*2/3*1.1 -> 264.36667 | N11: =IF(J11>M11,"OK","NO") -> OK
B12: 46 | C12: =MAX(3000/6,550,450) -> 550 | D12: 10 | E12: 150 | F12: 4 | G12: =MAX(1,M12*1000*E12/(2*D12^2/4*PI()*(550-40)*391)) -> 1.241059 | H12: =(0.9*(550-30)*(F12*PI()*D12^2/4)/E12*391)*G12/1000 -> 475.63482 | I12: =(0.9*(550-30)*300*0.5*17*0.5)*(G12/(1+G12^2))/1000 -> 291.52504 | J12: =MIN(H12:I12) -> 291.52504 | K12: -870.166 | L12: 353.4 | M12: =L12*2/3*1.1 -> 259.16 | N12: =IF(J12>M12,"OK","NO") -> OK
A13: PIANO 2 | B13: 6 | C13: =MAX(3000/6,500,450) -> 500 | D13: 10 | E13: 150 | F13: 4 | G13: =MAX(1,M13*1000*E13/(2*D13^2/4*PI()*(550-40)*391)) -> 1 | H13: =(0.9*(500-30)*(F13*PI()*D13^2/4)/E13*391)*G13/1000 -> 346.39829 | I13: =(0.9*(500-30)*300*0.5*17*0.5)*(G13/(1+G13^2))/1000 -> 269.6625 | J13: =MIN(H13:I13) -> 269.6625 | K13: -319.127 | L13: 266.9 | M13: =L13*2/3*1.1 -> 195.72667 | N13: =IF(J13>M13,"OK","NO") -> OK
B14: 7 | C14: =MAX(3000/6,500,450) -> 500 | D14: 10 | E14: 150 | F14: 4 | G14: =MAX(1,M14*1000*E14/(2*D14^2/4*PI()*(550-40)*391)) -> 1 | H14: =(0.9*(500-30)*(F14*PI()*D14^2/4)/E14*391)*G14/1000 -> 346.39829 | I14: =(0.9*(500-30)*300*0.5*17*0.5)*(G14/(1+G14^2))/1000 -> 269.6625 | J14: =MIN(H14:I14) -> 269.6625 | K14: -488.144 | L14: 283.8 | M14: =L14*2/3*1.1 -> 208.12 | N14: =IF(J14>M14,"OK","NO") -> OK
B15: 8 | C15: =MAX(3000/6,500,450) -> 500 | D15: 10 | E15: 150 | F15: 4 | G15: =MAX(1,M15*1000*E15/(2*D15^2/4*PI()*(550-40)*391)) -> 1.0243829 | H15: =(0.9*(500-30)*(F15*PI()*D15^2/4)/E15*391)*G15/1000 -> 354.84447 | I15: =(0.9*(500-30)*300*0.5*17*0.5)*(G15/(1+G15^2))/1000 -> 269.58427 | J15: =MIN(H15:I15) -> 269.58427 | K15: -574.035 | L15: 291.7 | M15: =L15*2/3*1.1 -> 213.91333 | N15: =IF(J15>M15,"OK","NO") -> OK
B16: 9 | C16: =MAX(3000/6,500,450) -> 500 | D16: 10 | E16: 150 | F16: 4 | G16: =MAX(1,M16*1000*E16/(2*D16^2/4*PI()*(550-40)*391)) -> 1.0219246 | H16: =(0.9*(500-30)*(F16*PI()*D16^2/4)/E16*391)*G16/1000 -> 353.99294 | I16: =(0.9*(500-30)*300*0.5*17*0.5)*(G16/(1+G16^2))/1000 -> 269.59909 | J16: =MIN(H16:I16) -> 269.59909 | K16: -567.027 | L16: 291 | M16: =L16*2/3*1.1 -> 213.4 | N16: =IF(J16>M16,"OK","NO") -> OK
B17: 10 | C17: =MAX(3000/6,500,450) -> 500 | D17: 10 | E17: 150 | F17: 4 | G17: =MAX(1,M17*1000*E17/(2*D17^2/4*PI()*(550-40)*391)) -> 1 | H17: =(0.9*(500-30)*(F17*PI()*D17^2/4)/E17*391)*G17/1000 -> 346.39829 | I17: =(0.9*(500-30)*300*0.5*17*0.5)*(G17/(1+G17^2))/1000 -> 269.6625 | J17: =MIN(H17:I17) -> 269.6625 | K17: -319.854 | L17: 274.4 | M17: =L17*2/3*1.1 -> 201.22667 | N17: =IF(J17>M17,"OK","NO") -> OK
B18: 47 | C18: =MAX(3000/6,500,450) -> 500 | D18: 10 | E18: 150 | F18: 4 | G18: =MAX(1,M18*1000*E18/(2*D18^2/4*PI()*(550-40)*391)) -> 1.0408882 | H18: =(0.9*(500-30)*(F18*PI()*D18^2/4)/E18*391)*G18/1000 -> 360.56188 | I18: =(0.9*(500-30)*300*0.5*17*0.5)*(G18/(1+G18^2))/1000 -> 269.44611 | J18: =MIN(H18:I18) -> 269.44611 | K18: -629.762 | L18: 296.4 | M18: =L18*2/3*1.1 -> 217.36 | N18: =IF(J18>M18,"OK","NO") -> OK
B19: 48 | C19: =MAX(3000/6,500,450) -> 500 | D19: 10 | E19: 150 | F19: 4 | G19: =MAX(1,M19*1000*E19/(2*D19^2/4*PI()*(550-40)*391)) -> 1.0816247 | H19: =(0.9*(500-30)*(F19*PI()*D19^2/4)/E19*391)*G19/1000 -> 374.67294 | I19: =(0.9*(500-30)*300*0.5*17*0.5)*(G19/(1+G19^2))/1000 -> 268.83452 | J19: =MIN(H19:I19) -> 268.83452 | K19: -947.713 | L19: 308 | M19: =L19*2/3*1.1 -> 225.86667 | N19: =IF(J19>M19,"OK","NO") -> OK
B20: 49 | C20: =MAX(3000/6,500,450) -> 500 | D20: 10 | E20: 150 | F20: 4 | G20: =MAX(1,M20*1000*E20/(2*D20^2/4*PI()*(550-40)*391)) -> 1.0911065 | H20: =(0.9*(500-30)*(F20*PI()*D20^2/4)/E20*391)*G20/1000 -> 377.95741 | I20: =(0.9*(500-30)*300*0.5*17*0.5)*(G20/(1+G20^2))/1000 -> 268.64068 | J20: =MIN(H20:I20) -> 268.64068 | K20: -1106.299 | L20: 310.7 | M20: =L20*2/3*1.1 -> 227.84667 | N20: =IF(J20>M20,"OK","NO") -> OK
B21: 50 | C21: =MAX(3000/6,500,450) -> 500 | D21: 10 | E21: 150 | F21: 4 | G21: =MAX(1,M21*1000*E21/(2*D21^2/4*PI()*(550-40)*391)) -> 1.0911065 | H21: =(0.9*(500-30)*(F21*PI()*D21^2/4)/E21*391)*G21/1000 -> 377.95741 | I21: =(0.9*(500-30)*300*0.5*17*0.5)*(G21/(1+G21^2))/1000 -> 268.64068 | J21: =MIN(H21:I21) -> 268.64068 | K21: -1101.918 | L21: 310.7 | M21: =L21*2/3*1.1 -> 227.84667 | N21: =IF(J21>M21,"OK","NO") -> OK
B22: 51 | C22: =MAX(3000/6,500,450) -> 500 | D22: 10 | E22: 150 | F22: 4 | G22: =MAX(1,M22*1000*E22/(2*D22^2/4*PI()*(550-40)*391)) -> 1.0412393 | H22: =(0.9*(500-30)*(F22*PI()*D22^2/4)/E22*391)*G22/1000 -> 360.68353 | I22: =(0.9*(500-30)*300*0.5*17*0.5)*(G22/(1+G22^2))/1000 -> 269.44246 | J22: =MIN(H22:I22) -> 269.44246 | K22: -631.32 | L22: 296.5 | M22: =L22*2/3*1.1 -> 217.43333 | N22: =IF(J22>M22,"OK","NO") -> OK
A23: PIANO 3 | B23: 11 | C23: =MAX(3000/6,450,450) -> 500 | D23: 10 | E23: 150 | F23: 4 | G23: =MAX(1,M23*1000*E23/(2*D23^2/4*PI()*(550-40)*391)) -> 1 | H23: =(0.9*(450-30)*(F23*PI()*D23^2/4)/E23*391)*G23/1000 -> 309.54741 | I23: =(0.9*(450-30)*300*0.5*17*0.5)*(G23/(1+G23^2))/1000 -> 240.975 | J23: =MIN(H23:I23) -> 240.975 | K23: -194.287 | L23: 221.2 | M23: =L23*2/3*1.1 -> 162.21333 | N23: =IF(J23>M23,"OK","NO") -> OK
B24: 12 | C24: =MAX(3000/6,450,450) -> 500 | D24: 10 | E24: 150 | F24: 4 | G24: =MAX(1,M24*1000*E24/(2*D24^2/4*PI()*(550-40)*391)) -> 1 | H24: =(0.9*(450-30)*(F24*PI()*D24^2/4)/E24*391)*G24/1000 -> 309.54741 | I24: =(0.9*(450-30)*300*0.5*17*0.5)*(G24/(1+G24^2))/1000 -> 240.975 | J24: =MIN(H24:I24) -> 240.975 | K24: -301.766 | L24: 231.1 | M24: =L24*2/3*1.1 -> 169.47333 | N24: =IF(J24>M24,"OK","NO") -> OK
B25: 13 | C25: =MAX(3000/6,450,450) -> 500 | D25: 10 | E25: 150 | F25: 4 | G25: =MAX(1,M25*1000*E25/(2*D25^2/4*PI()*(550-40)*391)) -> 1 | H25: =(0.9*(450-30)*(F25*PI()*D25^2/4)/E25*391)*G25/1000 -> 309.54741 | I25: =(0.9*(450-30)*300*0.5*17*0.5)*(G25/(1+G25^2))/1000 -> 240.975 | J25: =MIN(H25:I25) -> 240.975 | K25: -355.284 | L25: 235.8 | M25: =L25*2/3*1.1 -> 172.92 | N25: =IF(J25>M25,"OK","NO") -> OK
B26: 14 | C26: =MAX(3000/6,450,450) -> 500 | D26: 10 | E26: 150 | F26: 4 | G26: =MAX(1,M26*1000*E26/(2*D26^2/4*PI()*(550-40)*391)) -> 1 | H26: =(0.9*(450-30)*(F26*PI()*D26^2/4)/E26*391)*G26/1000 -> 309.54741 | I26: =(0.9*(450-30)*300*0.5*17*0.5)*(G26/(1+G26^2))/1000 -> 240.975 | J26: =MIN(H26:I26) -> 240.975 | K26: -350.163 | L26: 235.4 | M26: =L26*2/3*1.1 -> 172.62667 | N26: =IF(J26>M26,"OK","NO") -> OK
B27: 15 | C27: =MAX(3000/6,450,450) -> 500 | D27: 10 | E27: 150 | F27: 4 | G27: =MAX(1,M27*1000*E27/(2*D27^2/4*PI()*(550-40)*391)) -> 1 | H27: =(0.9*(450-30)*(F27*PI()*D27^2/4)/E27*391)*G27/1000 -> 309.54741 | I27: =(0.9*(450-30)*300*0.5*17*0.5)*(G27/(1+G27^2))/1000 -> 240.975 | J27: =MIN(H27:I27) -> 240.975 | K27: -194.841 | L27: 221.3 | M27: =L27*2/3*1.1 -> 162.28667 | N27: =IF(J27>M27,"OK","NO") -> OK
B28: 52 | C28: =MAX(3000/6,450,450) -> 500 | D28: 10 | E28: 150 | F28: 4 | G28: =MAX(1,M28*1000*E28/(2*D28^2/4*PI()*(550-40)*391)) -> 1 | H28: =(0.9*(450-30)*(F28*PI()*D28^2/4)/E28*391)*G28/1000 -> 309.54741 | I28: =(0.9*(450-30)*300*0.5*17*0.5)*(G28/(1+G28^2))/1000 -> 240.975 | J28: =MIN(H28:I28) -> 240.975 | K28: -394.46 | L28: 239.2 | M28: =L28*2/3*1.1 -> 175.41333 | N28: =IF(J28>M28,"OK","NO") -> OK
B29: 53 | C29: =MAX(3000/6,450,450) -> 500 | D29: 10 | E29: 150 | F29: 4 | G29: =MAX(1,M29*1000*E29/(2*D29^2/4*PI()*(550-40)*391)) -> 1 | H29: =(0.9*(450-30)*(F29*PI()*D29^2/4)/E29*391)*G29/1000 -> 309.54741 | I29: =(0.9*(450-30)*300*0.5*17*0.5)*(G29/(1+G29^2))/1000 -> 240.975 | J29: =MIN(H29:I29) -> 240.975 | K29: -613.827 | L29: 255.5 | M29: =L29*2/3*1.1 -> 187.36667 | N29: =IF(J29>M29,"OK","NO") -> OK
B30: 54 | C30: =MAX(3000/6,450,450) -> 500 | D30: 10 | E30: 150 | F30: 4 | G30: =MAX(1,M30*1000*E30/(2*D30^2/4*PI()*(550-40)*391)) -> 1 | H30: =(0.9*(450-30)*(F30*PI()*D30^2/4)/E30*391)*G30/1000 -> 309.54741 | I30: =(0.9*(450-30)*300*0.5*17*0.5)*(G30/(1+G30^2))/1000 -> 240.975 | J30: =MIN(H30:I30) -> 240.975 | K30: -716.634 | L30: 257.9 | M30: =L30*2/3*1.1 -> 189.12667 | N30: =IF(J30>M30,"OK","NO") -> OK
B31: 55 | C31: =MAX(3000/6,450,450) -> 500 | D31: 10 | E31: 150 | F31: 4 | G31: =MAX(1,M31*1000*E31/(2*D31^2/4*PI()*(550-40)*391)) -> 1 | H31: =(0.9*(450-30)*(F31*PI()*D31^2/4)/E31*391)*G31/1000 -> 309.54741 | I31: =(0.9*(450-30)*300*0.5*17*0.5)*(G31/(1+G31^2))/1000 -> 240.975 | J31: =MIN(H31:I31) -> 240.975 | K31: -713.372 | L31: 257.8 | M31: =L31*2/3*1.1 -> 189.05333 | N31: =IF(J31>M31,"OK","NO") -> OK
B32: 56 | C32: =MAX(3000/6,450,450) -> 500 | D32: 10 | E32: 150 | F32: 4 | G32: =MAX(1,M32*1000*E32/(2*D32^2/4*PI()*(550-40)*391)) -> 1 | H32: =(0.9*(450-30)*(F32*PI()*D32^2/4)/E32*391)*G32/1000 -> 309.54741 | I32: =(0.9*(450-30)*300*0.5*17*0.5)*(G32/(1+G32^2))/1000 -> 240.975 | J32: =MIN(H32:I32) -> 240.975 | K32: -395.579 | L32: 239.3 | M32: =L32*2/3*1.1 -> 175.48667 | N32: =IF(J32>M32,"OK","NO") -> OK
A33: PIANO 4 | B33: 37 | C33: =MAX(3000/6,400,450) -> 500 | D33: 10 | E33: 150 | F33: 4 | G33: =MAX(1,M33*1000*E33/(2*D33^2/4*PI()*(550-40)*391)) -> 1 | H33: =(0.9*(400-30)*(F33*PI()*D33^2/4)/E33*391)*G33/1000 -> 272.69653 | I33: =(0.9*(400-30)*300*0.5*17*0.5)*(G33/(1+G33^2))/1000 -> 212.2875 | J33: =MIN(H33:I33) -> 212.2875 | K33: -71.151 | L33: 179.5 | M33: =L33*2/3*1.1 -> 131.63333 | N33: =IF(J33>M33,"OK","NO") -> OK
B34: 38 | C34: =MAX(3000/6,400,450) -> 500 | D34: 10 | E34: 150 | F34: 4 | G34: =MAX(1,M34*1000*E34/(2*D34^2/4*PI()*(550-40)*391)) -> 1 | H34: =(0.9*(400-30)*(F34*PI()*D34^2/4)/E34*391)*G34/1000 -> 272.69653 | I34: =(0.9*(400-30)*300*0.5*17*0.5)*(G34/(1+G34^2))/1000 -> 212.2875 | J34: =MIN(H34:I34) -> 212.2875 | K34: -117.007 | L34: 183.2 | M34: =L34*2/3*1.1 -> 134.34667 | N34: =IF(J34>M34,"OK","NO") -> OK
B35: 39 | C35: =MAX(3000/6,400,450) -> 500 | D35: 10 | E35: 150 | F35: 4 | G35: =MAX(1,M35*1000*E35/(2*D35^2/4*PI()*(550-40)*391)) -> 1 | H35: =(0.9*(400-30)*(F35*PI()*D35^2/4)/E35*391)*G35/1000 -> 272.69653 | I35: =(0.9*(400-30)*300*0.5*17*0.5)*(G35/(1+G35^2))/1000 -> 212.2875 | J35: =MIN(H35:I35) -> 212.2875 | K35: -137.62 | L35: 184.8 | M35: =L35*2/3*1.1 -> 135.52 | N35: =IF(J35>M35,"OK","NO") -> OK
B36: 40 | C36: =MAX(3000/6,400,450) -> 500 | D36: 10 | E36: 150 | F36: 4 | G36: =MAX(1,M36*1000*E36/(2*D36^2/4*PI()*(550-40)*391)) -> 1 | H36: =(0.9*(400-30)*(F36*PI()*D36^2/4)/E36*391)*G36/1000 -> 272.69653 | I36: =(0.9*(400-30)*300*0.5*17*0.5)*(G36/(1+G36^2))/1000 -> 212.2875 | J36: =MIN(H36:I36) -> 212.2875 | K36: -134.691 | L36: 184.6 | M36: =L36*2/3*1.1 -> 135.37333 | N36: =IF(J36>M36,"OK","NO") -> OK
B37: 41 | C37: =MAX(3000/6,400,450) -> 500 | D37: 10 | E37: 150 | F37: 4 | G37: =MAX(1,M37*1000*E37/(2*D37^2/4*PI()*(550-40)*391)) -> 1 | H37: =(0.9*(400-30)*(F37*PI()*D37^2/4)/E37*391)*G37/1000 -> 272.69653 | I37: =(0.9*(400-30)*300*0.5*17*0.5)*(G37/(1+G37^2))/1000 -> 212.2875 | J37: =MIN(H37:I37) -> 212.2875 | K37: -71.657 | L37: 179.5 | M37: =L37*2/3*1.1 -> 131.63333 | N37: =IF(J37>M37,"OK","NO") -> OK
B38: 73 | C38: =MAX(3000/6,400,450) -> 500 | D38: 10 | E38: 150 | F38: 4 | G38: =MAX(1,M38*1000*E38/(2*D38^2/4*PI()*(550-40)*391)) -> 1 | H38: =(0.9*(400-30)*(F38*PI()*D38^2/4)/E38*391)*G38/1000 -> 272.69653 | I38: =(0.9*(400-30)*300*0.5*17*0.5)*(G38/(1+G38^2))/1000 -> 212.2875 | J38: =MIN(H38:I38) -> 212.2875 | K38: -159.883 | L38: 186.6 | M38: =L38*2/3*1.1 -> 136.84 | N38: =IF(J38>M38,"OK","NO") -> OK
B39: 74 | C39: =MAX(3000/6,400,450) -> 500 | D39: 10 | E39: 150 | F39: 4 | G39: =MAX(1,M39*1000*E39/(2*D39^2/4*PI()*(550-40)*391)) -> 1 | H39: =(0.9*(400-30)*(F39*PI()*D39^2/4)/E39*391)*G39/1000 -> 272.69653 | I39: =(0.9*(400-30)*300*0.5*17*0.5)*(G39/(1+G39^2))/1000 -> 212.2875 | J39: =MIN(H39:I39) -> 212.2875 | K39: -281.745 | L39: 196.1 | M39: =L39*2/3*1.1 -> 143.80667 | N39: =IF(J39>M39,"OK","NO") -> OK
B40: 75 | C40: =MAX(3000/6,400,450) -> 500 | D40: 10 | E40: 150 | F40: 4 | G40: =MAX(1,M40*1000*E40/(2*D40^2/4*PI()*(550-40)*391)) -> 1 | H40: =(0.9*(400-30)*(F40*PI()*D40^2/4)/E40*391)*G40/1000 -> 272.69653 | I40: =(0.9*(400-30)*300*0.5*17*0.5)*(G40/(1+G40^2))/1000 -> 212.2875 | J40: =MIN(H40:I40) -> 212.2875 | K40: -328.711 | L40: 199.6 | M40: =L40*2/3*1.1 -> 146.37333 | N40: =IF(J40>M40,"OK","NO") -> OK
...

Sheet Confinamento
B1: DIREZIONE X
B2: Frame | C2: Joint | D2: $N_{ED}_{min}$ | E2: bx | F2: by | G2: s | H2: σl,x | I2: σl,y | J2: σl | K2: αn | L2: αs | M2: α | N2: σ2 | O2: fck,c | P2: fcd,c
B3: Text | C3: Text | D3: KN | O3: N/mm^2 | P3: N/mm^2 | R3: fck
A4: PRIMO PIANO | B4: 1 | C4: 2 | D4: 54.19 | E4: =300-2*25-'NodoX (Taglio Trazione)'!J4:J5 -> 240 | F4: =500-2*25-'NodoY (Taglio Trazione)'!J4:J5 -> 440 | G4: =MIN('NodoX (Taglio Trazione)'!I4,'NodoY (Taglio Trazione)'!I4) -> 50 | H4: =(391*'NodoX (Taglio Trazione)'!L4:L5)/(F4*G4) -> 27.917335 | I4: =(391*'NodoX (Taglio Trazione)'!L4:L5)/(E4*G4) -> 51.18178 | J4: =SQRT(H4*I4) -> 37.80025 | K4: =1-1/(6*E4*F4)*2*(3*(F4/3)^2+(E4-20)^2) -> 0.64351852 | L4: =(1-G4/(2*E4))*(1-G4/(2*F4)) -> 0.84493371 | M4: =K4*L4 -> 0.54373049 | N4: =M4*J4 -> 20.553148 | O4: =IF(N4>0.05*$R$4,$R$4*(1.125+1.5*N4/$R$4),$R$4*(1+5*N4/$R$4)) -> 64.579723 | P4: =0.85*O4/1.5 -> 36.595176 | R4: 30
B5: 6 | C5: 2
B6: 2 | C6: 4 | D6: 201.35 | E6: =300-2*25-'NodoX (Taglio Trazione)'!J6:J7 -> 240 | F6: =500-2*25-'NodoY (Taglio Trazione)'!J6:J7 -> 440 | G6: =MIN('NodoX (Taglio Trazione)'!I6,'NodoY (Taglio Trazione)'!I6) -> 50 | H6: =(391*'NodoX (Taglio Trazione)'!L6:L7)/(F6*G6) -> 27.917335 | I6: =(391*'NodoX (Taglio Trazione)'!L6:L7)/(E6*G6) -> 51.18178 | J6: =SQRT(H6*I6) -> 37.80025 | K6: =1-1/(6*E6*F6)*2*(3*(F6/3)^2+(E6-20)^2) -> 0.64351852 | L6: =(1-G6/(2*E6))*(1-G6/(2*F6)) -> 0.84493371 | M6: =K6*L6 -> 0.54373049 | N6: =M6*J6 -> 20.553148 | O6: =IF(N6>0.05*$R$4,$R$4*(1.125+1.5*N6/$R$4),$R$4*(1+5*N6/$R$4)) -> 64.579723 | P6: =0.85*O6/1.5 -> 36.595176
B7: 7 | C7: 4
B8: 3 | C8: 6 | D8: 244.739 | E8: =300-2*25-'NodoX (Taglio Trazione)'!J8:J9 -> 240 | F8: =500-2*25-'NodoY (Taglio Trazione)'!J8:J9 -> 440 | G8: =MIN('NodoX (Taglio Trazione)'!I8,'NodoY (Taglio Trazione)'!I8) -> 50 | H8: =(391*'NodoX (Taglio Trazione)'!L8:L9)/(F8*G8) -> 27.917335 | I8: =(391*'NodoX (Taglio Trazione)'!L8:L9)/(E8*G8) -> 51.18178 | J8: =SQRT(H8*I8) -> 37.80025 | K8: =1-1/(6*E8*F8)*2*(3*(F8/3)^2+(E8-20)^2) -> 0.64351852 | L8: =(1-G8/(2*E8))*(1-G8/(2*F8)) -> 0.84493371 | M8: =K8*L8 -> 0.54373049 | N8: =M8*J8 -> 20.553148 | O8: =IF(N8>0.05*$R$4,$R$4*(1.125+1.5*N8/$R$4),$R$4*(1+5*N8/$R$4)) -> 64.579723 | P8: =0.85*O8/1.5 -> 36.595176
B9: 8 | C9: 6
B10: 4 | C10: 8 | D10: 224.605 | E10: =300-2*25-'NodoX (Taglio Trazione)'!J10:J11 -> 240 | F10: =500-2*25-'NodoY (Taglio Trazione)'!J10:J11 -> 440 | G10: =MIN('NodoX (Taglio Trazione)'!I10,'NodoY (Taglio Trazione)'!I10) -> 50 | H10: =(391*'NodoX (Taglio Trazione)'!L10:L11)/(F10*G10) -> 27.917335 | I10: =(391*'NodoX (Taglio Trazione)'!L10:L11)/(E10*G10) -> 51.18178 | J10: =SQRT(H10*I10) -> 37.80025 | K10: =1-1/(6*E10*F10)*2*(3*(F10/3)^2+(E10-20)^2) -> 0.64351852 | L10: =(1-G10/(2*E10))*(1-G10/(2*F10)) -> 0.84493371 | M10: =K10*L10 -> 0.54373049 | N10: =M10*J10 -> 20.553148 | O10: =IF(N10>0.05*$R$4,$R$4*(1.125+1.5*N10/$R$4),$R$4*(1+5*N10/$R$4)) -> 64.579723 | P10: =0.85*O10/1.5 -> 36.595176
B11: 9 | C11: 8
B12: 5 | C12: 10 | D12: 53.019 | E12: =300-2*25-'NodoX (Taglio Trazione)'!J12:J13 -> 240 | F12: =500-2*25-'NodoY (Taglio Trazione)'!J12:J13 -> 440 | G12: =MIN('NodoX (Taglio Trazione)'!I12,'NodoY (Taglio Trazione)'!I12) -> 50 | H12: =(391*'NodoX (Taglio Trazione)'!L12:L13)/(F12*G12) -> 27.917335 | I12: =(391*'NodoX (Taglio Trazione)'!L12:L13)/(E12*G12) -> 51.18178 | J12: =SQRT(H12*I12) -> 37.80025 | K12: =1-1/(6*E12*F12)*2*(3*(F12/3)^2+(E12-20)^2) -> 0.64351852 | L12: =(1-G12/(2*E12))*(1-G12/(2*F12)) -> 0.84493371 | M12: =K12*L12 -> 0.54373049 | N12: =M12*J12 -> 20.553148 | O12: =IF(N12>0.05*$R$4,$R$4*(1.125+1.5*N12/$R$4),$R$4*(1+5*N12/$R$4)) -> 64.579723 | P12: =0.85*O12/1.5 -> 36.595176
B13: 10 | C13: 10
B14: 42 | C14: 27 | D14: 335.932 | E14: =500-2*25-'NodoX (Taglio Trazione)'!J14:J15 -> 440 | F14: =300-2*25-'NodoY (Taglio Trazione)'!J14:J15 -> 240 | G14: =MIN('NodoX (Taglio Trazione)'!I14,'NodoY (Taglio Trazione)'!I14) -> 50 | H14: =(391*'NodoX (Taglio Trazione)'!L14:L15)/(F14*G14) -> 102.36356 | I14: =(391*'NodoX (Taglio Trazione)'!L14:L15)/(E14*G14) -> 55.834669 | J14: =SQRT(H14*I14) -> 75.6005 | K14: =1-1/(6*E14*F14)*2*(3*(F14/3)^2+(E14-20)^2) -> 0.38257576 | L14: =(1-G14/(2*E14))*(1-G14/(2*F14)) -> 0.84493371 | M14: =K14*L14 -> 0.32325116 | N14: =M14*J14 -> 24.437949 | O14: =IF(N14>0.05*$R$4,$R$4*(1.125+1.5*N14/$R$4),$R$4*(1+5*N14/$R$4)) -> 70.406923 | P14: =0.85*O14/1.5 -> 39.897257
B15: 47 | C15: 27
B16: 43 | C16: 29 | D16: 494.517 | E16: =500-2*25-'NodoX (Taglio Trazione)'!J16:J17 -> 440 | F16: =300-2*25-'NodoY (Taglio Trazione)'!J16:J17 -> 240 | G16: =MIN('NodoX (Taglio Trazione)'!I16,'NodoY (Taglio Trazione)'!I16) -> 50 | H16: =(391*'NodoX (Taglio Trazione)'!L16:L17)/(F16*G16) -> 102.36356 | I16: =(391*'NodoX (Taglio Trazione)'!L16:L17)/(E16*G16) -> 55.834669 | J16: =SQRT(H16*I16) -> 75.6005 | K16: =1-1/(6*E16*F16)*2*(3*(F16/3)^2+(E16-20)^2) -> 0.38257576 | L16: =(1-G16/(2*E16))*(1-G16/(2*F16)) -> 0.84493371 | M16: =K16*L16 -> 0.32325116 | N16: =M16*J16 -> 24.437949 | O16: =IF(N16>0.05*$R$4,$R$4*(1.125+1.5*N16/$R$4),$R$4*(1+5*N16/$R$4)) -> 70.406923 | P16: =0.85*O16/1.5 -> 39.897257
B17: 48 | C17: 29
B18: 44 | C18: 31 | D18: 575.796 | E18: =500-2*25-'NodoX (Taglio Trazione)'!J18:J19 -> 440 | F18: =300-2*25-'NodoY (Taglio Trazione)'!J18:J19 -> 240 | G18: =MIN('NodoX (Taglio Trazione)'!I18,'NodoY (Taglio Trazione)'!I18) -> 50 | H18: =(391*'NodoX (Taglio Trazione)'!L18:L19)/(F18*G18) -> 102.36356 | I18: =(391*'NodoX (Taglio Trazione)'!L18:L19)/(E18*G18) -> 55.834669 | J18: =SQRT(H18*I18) -> 75.6005 | K18: =1-1/(6*E18*F18)*2*(3*(F18/3)^2+(E18-20)^2) -> 0.38257576 | L18: =(1-G18/(2*E18))*(1-G18/(2*F18)) -> 0.84493371 | M18: =K18*L18 -> 0.32325116 | N18: =M18*J18 -> 24.437949 | O18: =IF(N18>0.05*$R$4,$R$4*(1.125+1.5*N18/$R$4),$R$4*(1+5*N18/$R$4)) -> 70.406923 | P18: =0.85*O18/1.5 -> 39.897257
B19: 49 | C19: 31
B20: 45 | C20: 33 | D20: 571.358 | E20: =500-2*25-'NodoX (Taglio Trazione)'!J20:J21 -> 440 | F20: =300-2*25-'NodoY (Taglio Trazione)'!J20:J21 -> 240 | G20: =MIN('NodoX (Taglio Trazione)'!I20,'NodoY (Taglio Trazione)'!I20) -> 50 | H20: =(391*'NodoX (Taglio Trazione)'!L20:L21)/(F20*G20) -> 102.36356 | I20: =(391*'NodoX (Taglio Trazione)'!L20:L21)/(E20*G20) -> 55.834669 | J20: =SQRT(H20*I20) -> 75.6005 | K20: =1-1/(6*E20*F20)*2*(3*(F20/3)^2+(E20-20)^2) -> 0.38257576 | L20: =(1-G20/(2*E20))*(1-G20/(2*F20)) -> 0.84493371 | M20: =K20*L20 -> 0.32325116 | N20: =M20*J20 -> 24.437949 | O20: =IF(N20>0.05*$R$4,$R$4*(1.125+1.5*N20/$R$4),$R$4*(1+5*N20/$R$4)) -> 70.406923 | P20: =0.85*O20/1.5 -> 39.897257
B21: 50 | C21: 33
B22: 46 | C22: 35 | D22: 333.615 | E22: =500-2*25-'NodoX (Taglio Trazione)'!J22:J23 -> 440 | F22: =300-2*25-'NodoY (Taglio Trazione)'!J22:J23 -> 240 | G22: =MIN('NodoX (Taglio Trazione)'!I22,'NodoY (Taglio Trazione)'!I22) -> 50 | H22: =(391*'NodoX (Taglio Trazione)'!L22:L23)/(F22*G22) -> 102.36356 | I22: =(391*'NodoX (Taglio Trazione)'!L22:L23)/(E22*G22) -> 55.834669 | J22: =SQRT(H22*I22) -> 75.6005 | K22: =1-1/(6*E22*F22)*2*(3*(F22/3)^2+(E22-20)^2) -> 0.38257576 | L22: =(1-G22/(2*E22))*(1-G22/(2*F22)) -> 0.84493371 | M22: =K22*L22 -> 0.32325116 | N22: =M22*J22 -> 24.437949 | O22: =IF(N22>0.05*$R$4,$R$4*(1.125+1.5*N22/$R$4),$R$4*(1+5*N22/$R$4)) -> 70.406923 | P22: =0.85*O22/1.5 -> 39.897257
B23: 51 | C23: 35
A24: SECONDO PIANO | B24: 6 | C24: 11 | D24: 51.828 | E24: =300-2*25-'NodoX (Taglio Trazione)'!J24:J25 -> 240 | F24: =450-2*25-'NodoY (Taglio Trazione)'!J24:J25 -> 390 | G24: =MIN('NodoX (Taglio Trazione)'!I24,'NodoY (Taglio Trazione)'!I24) -> 50 | H24: =(391*'NodoX (Taglio Trazione)'!L24:L25)/(F24*G24) -> 31.49648 | I24: =(391*'NodoX (Taglio Trazione)'!L24:L25)/(E24*G24) -> 51.18178 | J24: =SQRT(H24*I24) -> 40.150292 | K24: =1-1/(6*E24*F24)*2*(3*(F24/3)^2+(E24-20)^2) -> 0.64707977 | L24: =(1-G24/(2*E24))*(1-G24/(2*F24)) -> 0.83840812 | M24: =K24*L24 -> 0.54251693 | N24: =M24*J24 -> 21.782213 | O24: =IF(N24>0.05*$R$4,$R$4*(1.125+1.5*N24/$R$4),$R$4*(1+5*N24/$R$4)) -> 66.42332 | P24: =0.85*O24/1.5 -> 37.639881
B25: 11 | C25: 11
B26: 7 | C26: 12 | D26: 137.894 | E26: =300-2*25-'NodoX (Taglio Trazione)'!J26:J27 -> 240 | F26: =450-2*25-'NodoY (Taglio Trazione)'!J26:J27 -> 390 | G26: =MIN('NodoX (Taglio Trazione)'!I26,'NodoY (Taglio Trazione)'!I26) -> 50 | H26: =(391*'NodoX (Taglio Trazione)'!L26:L27)/(F26*G26) -> 31.49648 | I26: =(391*'NodoX (Taglio Trazione)'!L26:L27)/(E26*G26) -> 51.18178 | J26: =SQRT(H26*I26) -> 40.150292 | K26: =1-1/(6*E26*F26)*2*(3*(F26/3)^2+(E26-20)^2) -> 0.64707977 | L26: =(1-G26/(2*E26))*(1-G26/(2*F26)) -> 0.83840812 | M26: =K26*L26 -> 0.54251693 | N26: =M26*J26 -> 21.782213 | O26: =IF(N26>0.05*$R$4,$R$4*(1.125+1.5*N26/$R$4),$R$4*(1+5*N26/$R$4)) -> 66.42332 | P26: =0.85*O26/1.5 -> 37.639881
B27: 12 | C27: 12
B28: 8 | C28: 13 | D28: 166.454 | E28: =300-2*25-'NodoX (Taglio Trazione)'!J28:J29 -> 240 | F28: =450-2*25-'NodoY (Taglio Trazione)'!J28:J29 -> 390 | G28: =MIN('NodoX (Taglio Trazione)'!I28,'NodoY (Taglio Trazione)'!I28) -> 50 | H28: =(391*'NodoX (Taglio Trazione)'!L28:L29)/(F28*G28) -> 31.49648 | I28: =(391*'NodoX (Taglio Trazione)'!L28:L29)/(E28*G28) -> 51.18178 | J28: =SQRT(H28*I28) -> 40.150292 | K28: =1-1/(6*E28*F28)*2*(3*(F28/3)^2+(E28-20)^2) -> 0.64707977 | L28: =(1-G28/(2*E28))*(1-G28/(2*F28)) -> 0.83840812 | M28: =K28*L28 -> 0.54251693 | N28: =M28*J28 -> 21.782213 | O28: =IF(N28>0.05*$R$4,$R$4*(1.125+1.5*N28/$R$4),$R$4*(1+5*N28/$R$4)) -> 66.42332 | P28: =0.85*O28/1.5 -> 37.639881
B29: 13 | C29: 13
B30: 9 | C30: 14 | D30: 156.281 | E30: =300-2*25-'NodoX (Taglio Trazione)'!J30:J31 -> 240 | F30: =450-2*25-'NodoY (Taglio Trazione)'!J30:J31 -> 390 | G30: =MIN('NodoX (Taglio Trazione)'!I30,'NodoY (Taglio Trazione)'!I30) -> 50 | H30: =(391*'NodoX (Taglio Trazione)'!L30:L31)/(F30*G30) -> 31.49648 | I30: =(391*'NodoX (Taglio Trazione)'!L30:L31)/(E30*G30) -> 51.18178 | J30: =SQRT(H30*I30) -> 40.150292 | K30: =1-1/(6*E30*F30)*2*(3*(F30/3)^2+(E30-20)^2) -> 0.64707977 | L30: =(1-G30/(2*E30))*(1-G30/(2*F30)) -> 0.83840812 | M30: =K30*L30 -> 0.54251693 | N30: =M30*J30 -> 21.782213 | O30: =IF(N30>0.05*$R$4,$R$4*(1.125+1.5*N30/$R$4),$R$4*(1+5*N30/$R$4)) -> 66.42332 | P30: =0.85*O30/1.5 -> 37.639881
B31: 14 | C31: 14
B32: 10 | C32: 15 | D32: 51.773 | E32: =300-2*25-'NodoX (Taglio Trazione)'!J32:J33 -> 240 | F32: =450-2*25-'NodoY (Taglio Trazione)'!J32:J33 -> 390 | G32: =MIN('NodoX (Taglio Trazione)'!I32,'NodoY (Taglio Trazione)'!I32) -> 50 | H32: =(391*'NodoX (Taglio Trazione)'!L32:L33)/(F32*G32) -> 31.49648 | I32: =(391*'NodoX (Taglio Trazione)'!L32:L33)/(E32*G32) -> 51.18178 | J32: =SQRT(H32*I32) -> 40.150292 | K32: =1-1/(6*E32*F32)*2*(3*(F32/3)^2+(E32-20)^2) -> 0.64707977 | L32: =(1-G32/(2*E32))*(1-G32/(2*F32)) -> 0.83840812 | M32: =K32*L32 -> 0.54251693 | N32: =M32*J32 -> 21.782213 | O32: =IF(N32>0.05*$R$4,$R$4*(1.125+1.5*N32/$R$4),$R$4*(1+5*N32/$R$4)) -> 66.42332 | P32: =0.85*O32/1.5 -> 37.639881
B33: 15 | C33: 15
B34: 47 | C34: 36 | D34: 213.893 | E34: =450-2*25-'NodoX (Taglio Trazione)'!J34:J35 -> 390 | F34: =300-2*25-'NodoY (Taglio Trazione)'!J34:J35 -> 240 | G34: =MIN('NodoX (Taglio Trazione)'!I34,'NodoY (Taglio Trazione)'!I34) -> 50 | H34: =(391*'NodoX (Taglio Trazione)'!L34:L35)/(F34*G34) -> 102.36356 | I34: =(391*'NodoX (Taglio Trazione)'!L34:L35)/(E34*G34) -> 62.99296 | J34: =SQRT(H34*I34) -> 80.300584 | K34: =1-1/(6*E34*F34)*2*(3*(F34/3)^2+(E34-20)^2) -> 0.44408832 | L34: =(1-G34/(2*E34))*(1-G34/(2*F34)) -> 0.83840812 | M34: =K34*L34 -> 0.37232725 | N34: =M34*J34 -> 29.898096 | O34: =IF(N34>0.05*$R$4,$R$4*(1.125+1.5*N34/$R$4),$R$4*(1+5*N34/$R$4)) -> 78.597143 | P34: =0.85*O34/1.5 -> 44.538381
B35: 52 | C35: 36
B36: 48 | C36: 37 | D36: 328.632 | E36: =450-2*25-'NodoX (Taglio Trazione)'!J36:J37 -> 390 | F36: =300-2*25-'NodoY (Taglio Trazione)'!J36:J37 -> 240 | G36: =MIN('NodoX (Taglio Trazione)'!I36,'NodoY (Taglio Trazione)'!I36) -> 50 | H36: =(391*'NodoX (Taglio Trazione)'!L36:L37)/(F36*G36) -> 102.36356 | I36: =(391*'NodoX (Taglio Trazione)'!L36:L37)/(E36*G36) -> 62.99296 | J36: =SQRT(H36*I36) -> 80.300584 | K36: =1-1/(6*E36*F36)*2*(3*(F36/3)^2+(E36-20)^2) -> 0.44408832 | L36: =(1-G36/(2*E36))*(1-G36/(2*F36)) -> 0.83840812 | M36: =K36*L36 -> 0.37232725 | N36: =M36*J36 -> 29.898096 | O36: =IF(N36>0.05*$R$4,$R$4*(1.125+1.5*N36/$R$4),$R$4*(1+5*N36/$R$4)) -> 78.597143 | P36: =0.85*O36/1.5 -> 44.538381
B37: 53 | C37: 37
B38: 49 | C38: 38 | D38: 381.7 | E38: =450-2*25-'NodoX (Taglio Trazione)'!J38:J39 -> 390 | F38: =300-2*25-'NodoY (Taglio Trazione)'!J38:J39 -> 240 | G38: =MIN('NodoX (Taglio Trazione)'!I38,'NodoY (Taglio Trazione)'!I38) -> 50 | H38: =(391*'NodoX (Taglio Trazione)'!L38:L39)/(F38*G38) -> 102.36356 | I38: =(391*'NodoX (Taglio Trazione)'!L38:L39)/(E38*G38) -> 62.99296 | J38: =SQRT(H38*I38) -> 80.300584 | K38: =1-1/(6*E38*F38)*2*(3*(F38/3)^2+(E38-20)^2) -> 0.44408832 | L38: =(1-G38/(2*E38))*(1-G38/(2*F38)) -> 0.83840812 | M38: =K38*L38 -> 0.37232725 | N38: =M38*J38 -> 29.898096 | O38: =IF(N38>0.05*$R$4,$R$4*(1.125+1.5*N38/$R$4),$R$4*(1+5*N38/$R$4)) -> 78.597143 | P38: =0.85*O38/1.5 -> 44.538381
B39: 54 | C39: 38
B40: 50 | C40: 39 | D40: 379.269 | E40: =450-2*25-'NodoX (Taglio Trazione)'!J40:J41 -> 390 | F40: =300-2*25-'NodoY (Taglio Trazione)'!J40:J41 -> 240 | G40: =MIN('NodoX (Taglio Trazione)'!I40,'NodoY (Taglio Trazione)'!I40) -> 50 | H40: =(391*'NodoX (Taglio Trazione)'!L40:L41)/(F40*G40) -> 102.36356 | I40: =(391*'NodoX (Taglio Trazione)'!L40:L41)/(E40*G40) -> 62.99296 | J40: =SQRT(H40*I40) -> 80.300584 | K40: =1-1/(6*E40*F40)*2*(3*(F40/3)^2+(E40-20)^2) -> 0.44408832 | L40: =(1-G40/(2*E40))*(1-G40/(2*F40)) -> 0.83840812 | M40: =K40*L40 -> 0.37232725 | N40: =M40*J40 -> 29.898096 | O40: =IF(N40>0.05*$R$4,$R$4*(1.125+1.5*N40/$R$4),$R$4*(1+5*N40/$R$4)) -> 78.597143 | P40: =0.85*O40/1.5 -> 44.538381
...

Sheet NodoX (Taglio Compressione)
B1: DIREZIONE X
B2: Frame | C2: Joint | D2: NED | E2: As,sup | F2: Asinf | G2: VED,sup | H2: Vjbd | I2: η | J2: bj | K2: hjc | L2: ν | M2: VRd | N2: Verifica
B3: Text | C3: Text | D3: KN | E3: mm^2 | F3: mm^2 | G3: KN | H3: KN | I3: - | J3: mm | K3: mm | L3: - | M3: KN | N3: -
A4: PRIMO PIANO | B4: 1 | C4: 2 | D4: 358.839 | E4: 936.19461 | F4: 0 | G4: 32.432 | H4: =(1.1*(E4+F4)*391)/1000-G4 -> 370.2253 | I4: =IF(F4=0,0.48*(1-30/250),0.6*(1-30/250)) -> 0.4224 | J4: 500 | K4: =300-80 -> 220 | L4: =D4*1000/(500*300*17) -> 0.14072118 | M4: =(I4*17*J4*K4*SQRT(1-L4/I4))/1000 -> 645.03111 | N4: =IF(M4>H4,"OK","NO") -> OK
B5: 6 | C5: 2
B6: 2 | C6: 4 | D6: 402.063 | E6: 936.19461 | F6: 0 | G6: 28.281 | H6: =(1.1*(E6+F6)*391)/1000-G6 -> 374.3763 | I6: =IF(F6=0,0.48*(1-30/250),0.6*(1-30/250)) -> 0.4224 | J6: 500 | K6: =300-80 -> 220 | L6: =D6*1000/(500*300*17) -> 0.15767176 | M6: =(I6*17*J6*K6*SQRT(1-L6/I6))/1000 -> 625.32198 | N6: =IF(M6>H6,"OK","NO") -> OK
B7: 7 | C7: 4
B8: 3 | C8: 6 | D8: 460.431 | E8: 936.19461 | F8: 0 | G8: 24.966 | H8: =(1.1*(E8+F8)*391)/1000-G8 -> 377.6913 | I8: =IF(F8=0,0.48*(1-30/250),0.6*(1-30/250)) -> 0.4224 | J8: 500 | K8: =300-80 -> 220 | L8: =D8*1000/(500*300*17) -> 0.18056118 | M8: =(I8*17*J8*K8*SQRT(1-L8/I8))/1000 -> 597.67704 | N8: =IF(M8>H8,"OK","NO") -> OK
B9: 8 | C9: 6
B10: 4 | C10: 8 | D10: 474.403 | E10: 936.19461 | F10: 0 | G10: 28.747 | H10: =(1.1*(E10+F10)*391)/1000-G10 -> 373.9103 | I10: =IF(F10=0,0.48*(1-30/250),0.6*(1-30/250)) -> 0.4224 | J10: 500 | K10: =300-80 -> 220 | L10: =D10*1000/(500*300*17) -> 0.18604039 | M10: =(I10*17*J10*K10*SQRT(1-L10/I10))/1000 -> 590.86762 | N10: =IF(M10>H10,"OK","NO") -> OK
B11: 9 | C11: 8
B12: 5 | C12: 10 | D12: 359.865 | E12: 936.19461 | F12: 0 | G12: 35.912 | H12: =(1.1*(E12+F12)*391)/1000-G12 -> 366.7453 | I12: =IF(F12=0,0.48*(1-30/250),0.6*(1-30/250)) -> 0.4224 | J12: 500 | K12: =300-80 -> 220 | L12: =D12*1000/(500*300*17) -> 0.14112353 | M12: =(I12*17*J12*K12*SQRT(1-L12/I12))/1000 -> 644.57026 | N12: =IF(M12>H12,"OK","NO") -> OK
B13: 10 | C13: 10
B14: 42 | C14: 27 | D14: 428.39 | E14: =1137.25654059951 -> 1137.2565 | F14: 615.75216 | G14: 74.137 | H14: =(1.1*(E14+F14)*391)/1000-G14 -> 679.83204 | I14: =IF(F14=0,0.48*(1-30/250),0.6*(1-30/250)) -> 0.528 | J14: 300 | K14: 420 | L14: =D14*1000/(500*300*17) -> 0.16799608 | M14: =(I14*17*J14*K14*SQRT(1-L14/I14))/1000 -> 933.87778 | N14: =IF(M14>H14,"OK","NO") -> OK
B15: 47 | C15: 27
B16: 43 | C16: 29 | D16: 561.845 | E16: =1137.25654059951 -> 1137.2565 | F16: 615.75216 | G16: 68.141 | H16: =(1.1*(E16+F16)*391)/1000-G16 -> 685.82804 | I16: =IF(F16=0,0.48*(1-30/250),0.6*(1-30/250)) -> 0.528 | J16: 300 | K16: 420 | L16: =D16*1000/(500*300*17) -> 0.22033137 | M16: =(I16*17*J16*K16*SQRT(1-L16/I16))/1000 -> 863.33239 | N16: =IF(M16>H16,"OK","NO") -> OK
B17: 48 | C17: 29
B18: 44 | C18: 31 | D18: 647.766 | E18: =1256.63706143592 -> 1256.6371 | F18: 615.75216 | G18: 63.067 | H18: =(1.1*(E18+F18)*391)/1000-G18 -> 742.2476 | I18: =IF(F18=0,0.48*(1-30/250),0.6*(1-30/250)) -> 0.528 | J18: 300 | K18: 420 | L18: =D18*1000/(500*300*17) -> 0.25402588 | M18: =(I18*17*J18*K18*SQRT(1-L18/I18))/1000 -> 814.68777 | N18: =IF(M18>H18,"OK","NO") -> OK
B19: 49 | C19: 31
B20: 45 | C20: 33 | D20: 648.669 | E20: =1256.63706143592 -> 1256.6371 | F20: 615.75216 | G20: 70.576 | H20: =(1.1*(E20+F20)*391)/1000-G20 -> 734.7386 | I20: =IF(F20=0,0.48*(1-30/250),0.6*(1-30/250)) -> 0.528 | J20: 300 | K20: 420 | L20: =D20*1000/(500*300*17) -> 0.25438 | M20: =(I20*17*J20*K20*SQRT(1-L20/I20))/1000 -> 814.1611 | N20: =IF(M20>H20,"OK","NO") -> OK
B21: 50 | C21: 33
B22: 46 | C22: 35 | D22: 432.025 | E22: =1137.25654059951 -> 1137.2565 | F22: 615.75216 | G22: 81.248 | H22: =(1.1*(E22+F22)*391)/1000-G22 -> 672.72104 | I22: =IF(F22=0,0.48*(1-30/250),0.6*(1-30/250)) -> 0.528 | J22: 300 | K22: 420 | L22: =D22*1000/(500*300*17) -> 0.16942157 | M22: =(I22*17*J22*K22*SQRT(1-L22/I22))/1000 -> 932.02703 | N22: =IF(M22>H22,"OK","NO") -> OK
B23: 51 | C23: 35
A24: SECONDO PIANO | B24: 6 | C24: 11 | D24: 197.98 | E24: 936.19461 | F24: 0 | G24: 23.262 | H24: =(1.1*(E24+F24)*391)/1000-G24 -> 379.3953 | I24: =IF(F24=0,0.48*(1-30/250),0.6*(1-30/250)) -> 0.4224 | J24: 450 | K24: =300-80 -> 220 | L24: =D24*1000/(450*300*17) -> 0.086265795 | M24: =(I24*17*J24*K24*SQRT(1-L24/I24))/1000 -> 634.16523 | N24: =IF(M24>H24,"OK","NO") -> OK
B25: 11 | C25: 11
B26: 7 | C26: 12 | D26: 233.681 | E26: 936.19461 | F26: 0 | G26: 19.71 | H26: =(1.1*(E26+F26)*391)/1000-G26 -> 382.9473 | I26: =IF(F26=0,0.48*(1-30/250),0.6*(1-30/250)) -> 0.4224 | J26: 450 | K26: =300-80 -> 220 | L26: =D26*1000/(450*300*17) -> 0.10182179 | M26: =(I26*17*J26*K26*SQRT(1-L26/I26))/1000 -> 619.3171 | N26: =IF(M26>H26,"OK","NO") -> OK
B27: 12 | C27: 12
B28: 8 | C28: 13 | D28: 268.032 | E28: 936.19461 | F28: 0 | G28: 16.999 | H28: =(1.1*(E28+F28)*391)/1000-G28 -> 385.6583 | I28: =IF(F28=0,0.48*(1-30/250),0.6*(1-30/250)) -> 0.4224 | J28: 450 | K28: =300-80 -> 220 | L28: =D28*1000/(450*300*17) -> 0.11678954 | M28: =(I28*17*J28*K28*SQRT(1-L28/I28))/1000 -> 604.68637 | N28: =IF(M28>H28,"OK","NO") -> OK
B29: 13 | C29: 13
B30: 9 | C30: 14 | D30: 273.614 | E30: 936.19461 | F30: 0 | G30: 19.786 | H30: =(1.1*(E30+F30)*391)/1000-G30 -> 382.8713 | I30: =IF(F30=0,0.48*(1-30/250),0.6*(1-30/250)) -> 0.4224 | J30: 450 | K30: =300-80 -> 220 | L30: =D30*1000/(450*300*17) -> 0.11922179 | M30: =(I30*17*J30*K30*SQRT(1-L30/I30))/1000 -> 602.27532 | N30: =IF(M30>H30,"OK","NO") -> OK
B31: 14 | C31: 14
B32: 10 | C32: 15 | D32: 198.042 | E32: 936.19461 | F32: 0 | G32: 25.958 | H32: =(1.1*(E32+F32)*391)/1000-G32 -> 376.6993 | I32: =IF(F32=0,0.48*(1-30/250),0.6*(1-30/250)) -> 0.4224 | J32: 450 | K32: =300-80 -> 220 | L32: =D32*1000/(450*300*17) -> 0.08629281 | M32: =(I32*17*J32*K32*SQRT(1-L32/I32))/1000 -> 634.13974 | N32: =IF(M32>H32,"OK","NO") -> OK
B33: 15 | C33: 15
B34: 47 | C34: 36 | D34: 262.309 | E34: =1137.25654059951 -> 1137.2565 | F34: 615.75216 | G34: 52.169 | H34: =(1.1*(E34+F34)*391)/1000-G34 -> 701.80004 | I34: =IF(F34=0,0.48*(1-30/250),0.6*(1-30/250)) -> 0.528 | J34: 300 | K34: =450-80 -> 370 | L34: =D34*1000/(450*300*17) -> 0.11429586 | M34: =(I34*17*J34*K34*SQRT(1-L34/I34))/1000 -> 881.92935 | N34: =IF(M34>H34,"OK","NO") -> OK
B35: 52 | C35: 36
B36: 48 | C36: 37 | D36: 359.797 | E36: =1137.25654059951 -> 1137.2565 | F36: 615.75216 | G36: 47.495 | H36: =(1.1*(E36+F36)*391)/1000-G36 -> 706.47404 | I36: =IF(F36=0,0.48*(1-30/250),0.6*(1-30/250)) -> 0.528 | J36: 300 | K36: =450-80 -> 370 | L36: =D36*1000/(450*300*17) -> 0.15677429 | M36: =(I36*17*J36*K36*SQRT(1-L36/I36))/1000 -> 835.4258 | N36: =IF(M36>H36,"OK","NO") -> OK
B37: 53 | C37: 37
B38: 49 | C38: 38 | D38: 415.809 | E38: =1256.63706143592 -> 1256.6371 | F38: 615.75216 | G38: 43.7 | H38: =(1.1*(E38+F38)*391)/1000-G38 -> 761.6146 | I38: =IF(F38=0,0.48*(1-30/250),0.6*(1-30/250)) -> 0.528 | J38: 300 | K38: =450-80 -> 370 | L38: =D38*1000/(450*300*17) -> 0.18118039 | M38: =(I38*17*J38*K38*SQRT(1-L38/I38))/1000 -> 807.49656 | N38: =IF(M38>H38,"OK","NO") -> OK
B39: 54 | C39: 38
B40: 50 | C40: 39 | D40: 415.576 | E40: =1256.63706143592 -> 1256.6371 | F40: 615.75216 | G40: 48.945 | H40: =(1.1*(E40+F40)*391)/1000-G40 -> 756.3696 | I40: =IF(F40=0,0.48*(1-30/250),0.6*(1-30/250)) -> 0.528 | J40: 300 | K40: =450-80 -> 370 | L40: =D40*1000/(450*300*17) -> 0.18107887 | M40: =(I40*17*J40*K40*SQRT(1-L40/I40))/1000 -> 807.61474 | N40: =IF(M40>H40,"OK","NO") -> OK
...

Sheet NodoX (Taglio Trazione)
B1: DIREZIONE X
B2: Frame | C2: Joint | D2: NED,min | E2: As,sup | F2: As,inf | G2: VED,sup | H2: Hnodo | I2: s (passo) | J2: φ | K2: nbracci | L2: Ash | M2: ν | N2: Domanda | O2: Verifica | P2: bj | Q2: hjc | R2: Vjbd | S2: D/C
B3: Text | C3: Text | D3: KN | E3: mm^2 | F3: mm^2 | G3: KN | H3: mm | I3: mm | J3: mm | L3: mm^2 | M3: - | O3: - | P3: mm | Q3: mm | R3: KN | S3: <1
A4: PRIMO PIANO | B4: 1 | C4: 2 | D4: 54.19 | E4: 0 | F4: 615.75216 | G4: 32.432 | H4: 500 | I4: 50 | J4: 10 | K4: 2 | L4: =J4^2*PI()/4*K4*(H4/I4) -> 1570.7963 | M4: =D4*1000/(500*300*Confinamento!P4) -> 0.0098719751 | N4: =1.1*(E4+F4)*391*(1-0.8*M4) -> 262743.45 | O4: =IF(L4*391>N4,"OK","NO") -> OK | P4: 500 | Q4: =300-80 -> 220 | R4: =(1.1*(E4+F4)*391)/1000-G4 -> 232.403 | S4: =N4/(L4*391) -> 0.42779456
B5: 6 | C5: 2
B6: 2 | C6: 4 | D6: 201.35 | E6: 0 | F6: 534.07075 | G6: 28.281 | H6: 500 | I6: 50 | J6: 10 | K6: 2 | L6: =J6^2*PI()/4*K6*(H6/I6) -> 1570.7963 | M6: =D6*1000/(500*300*Confinamento!P6) -> 0.036680609 | N6: =1.1*(E6+F6)*391*(1-0.8*M6) -> 222963.29 | O6: =IF(L6*391>N6,"OK","NO") -> OK | P6: 500 | Q6: =300-80 -> 220 | R6: =(1.1*(E6+F6)*391)/1000-G6 -> 201.42283 | S6: =N6/(L6*391) -> 0.36302516
B7: 7 | C7: 4
B8: 3 | C8: 6 | D8: 244.739 | E8: 0 | F8: 534.07075 | G8: 24.966 | H8: 500 | I8: 50 | J8: 10 | K8: 2 | L8: =J8^2*PI()/4*K8*(H8/I8) -> 1570.7963 | M8: =D8*1000/(500*300*Confinamento!P8) -> 0.044584929 | N8: =1.1*(E8+F8)*391*(1-0.8*M8) -> 221510.77 | O8: =IF(L8*391>N8,"OK","NO") -> OK | P8: 500 | Q8: =300-80 -> 220 | R8: =(1.1*(E8+F8)*391)/1000-G8 -> 204.73783 | S8: =N8/(L8*391) -> 0.36066019
B9: 8 | C9: 6
B10: 4 | C10: 8 | D10: 224.605 | E10: 0 | F10: 534.07075 | G10: 28.747 | H10: 500 | I10: 50 | J10: 10 | K10: 2 | L10: =J10^2*PI()/4*K10*(H10/I10) -> 1570.7963 | M10: =D10*1000/(500*300*Confinamento!P10) -> 0.04091705 | N10: =1.1*(E10+F10)*391*(1-0.8*M10) -> 222184.79 | O10: =IF(L10*391>N10,"OK","NO") -> OK | P10: 500 | Q10: =300-80 -> 220 | R10: =(1.1*(E10+F10)*391)/1000-G10 -> 200.95683 | S10: =N10/(L10*391) -> 0.36175762
B11: 9 | C11: 8
B12: 5 | C12: 10 | D12: 53.019 | E12: 0 | F12: 615.75216 | G12: 35.912 | H12: 500 | I12: 50 | J12: 10 | K12: 2 | L12: =J12^2*PI()/4*K12*(H12/I12) -> 1570.7963 | M12: =D12*1000/(500*300*Confinamento!P12) -> 0.00965865 | N12: =1.1*(E12+F12)*391*(1-0.8*M12) -> 262788.65 | O12: =IF(L12*391>N12,"OK","NO") -> OK | P12: 500 | Q12: =300-80 -> 220 | R12: =(1.1*(E12+F12)*391)/1000-G12 -> 228.923 | S12: =N12/(L12*391) -> 0.42786815
B13: 10 | C13: 10
B14: 42 | C14: 27 | D14: 335.932 | E14: =1137.25654059951 -> 1137.2565 | F14: 615.75216 | G14: 74.137 | H14: 500 | I14: 50 | J14: 10 | K14: 4 | L14: =J14^2*PI()/4*K14*(H14/I14) -> 3141.5927 | M14: =D14*1000/(500*300*Confinamento!P14) -> 0.056132849 | N14: =1.1*(E14+F14)*391*(1-0.8*M14) -> 720111.1 | O14: =IF(L14*391>N14,"OK","NO") -> OK | P14: 300 | Q14: 420 | R14: =(1.1*(E14+F14)*391)/1000-G14 -> 679.83204 | S14: =N14/(L14*391) -> 0.58623653
B15: 47 | C15: 27
B16: 43 | C16: 29 | D16: 494.517 | E16: =1137.25654059951 -> 1137.2565 | F16: 615.75216 | G16: 68.141 | H16: 500 | I16: 50 | J16: 10 | K16: 4 | L16: =J16^2*PI()/4*K16*(H16/I16) -> 3141.5927 | M16: =D16*1000/(500*300*Confinamento!P16) -> 0.082631747 | N16: =1.1*(E16+F16)*391*(1-0.8*M16) -> 704127.62 | O16: =IF(L16*391>N16,"OK","NO") -> OK | P16: 300 | Q16: 420 | R16: =(1.1*(E16+F16)*391)/1000-G16 -> 685.82804 | S16: =N16/(L16*391) -> 0.57322451
B17: 48 | C17: 29
B18: 44 | C18: 31 | D18: 575.796 | E18: =1256.63706143592 -> 1256.6371 | F18: 615.75216 | G18: 63.067 | H18: 500 | I18: 50 | J18: 10 | K18: 4 | L18: =J18^2*PI()/4*K18*(H18/I18) -> 3141.5927 | M18: =D18*1000/(500*300*Confinamento!P18) -> 0.096213132 | N18: =1.1*(E18+F18)*391*(1-0.8*M18) -> 743329.13 | O18: =IF(L18*391>N18,"OK","NO") -> OK | P18: 300 | Q18: 420 | R18: =(1.1*(E18+F18)*391)/1000-G18 -> 742.2476 | S18: =N18/(L18*391) -> 0.60513814
B19: 49 | C19: 31
B20: 45 | C20: 33 | D20: 571.358 | E20: =1256.63706143592 -> 1256.6371 | F20: 615.75216 | G20: 70.576 | H20: 500 | I20: 50 | J20: 10 | K20: 4 | L20: =J20^2*PI()/4*K20*(H20/I20) -> 3141.5927 | M20: =D20*1000/(500*300*Confinamento!P20) -> 0.09547156 | N20: =1.1*(E20+F20)*391*(1-0.8*M20) -> 743806.89 | O20: =IF(L20*391>N20,"OK","NO") -> OK | P20: 300 | Q20: 420 | R20: =(1.1*(E20+F20)*391)/1000-G20 -> 734.7386 | S20: =N20/(L20*391) -> 0.60552708
B21: 50 | C21: 33
B22: 46 | C22: 35 | D22: 333.615 | E22: =1137.25654059951 -> 1137.2565 | F22: 615.75216 | G22: 81.248 | H22: 500 | I22: 50 | J22: 10 | K22: 4 | L22: =J22^2*PI()/4*K22*(H22/I22) -> 3141.5927 | M22: =D22*1000/(500*300*Confinamento!P22) -> 0.055745688 | N22: =1.1*(E22+F22)*391*(1-0.8*M22) -> 720344.62 | O22: =IF(L22*391>N22,"OK","NO") -> OK | P22: 300 | Q22: 420 | R22: =(1.1*(E22+F22)*391)/1000-G22 -> 672.72104 | S22: =N22/(L22*391) -> 0.58642664
B23: 51 | C23: 35
A24: SECONDO PIANO | B24: 6 | C24: 11 | D24: 51.828 | E24: 0 | F24: 615.75216 | G24: 23.262 | H24: 500 | I24: 50 | J24: 10 | K24: 2 | L24: =J24^2*PI()/4*K24*(H24/I24) -> 1570.7963 | M24: =D24*1000/(500*300*Confinamento!P24) -> 0.0091796251 | N24: =1.1*(E24+F24)*391*(1-0.8*M24) -> 262890.14 | O24: =IF(L24*391>N24,"OK","NO") -> OK | P24: 450 | Q24: =300-80 -> 220 | R24: =(1.1*(E24+F24)*391)/1000-G24 -> 241.573 | S24: =N24/(L24*391) -> 0.4280334
B25: 11 | C25: 11
B26: 7 | C26: 12 | D26: 137.894 | E26: 0 | F26: 534.07075 | G26: 19.71 | H26: 500 | I26: 50 | J26: 10 | K26: 2 | L26: =J26^2*PI()/4*K26*(H26/I26) -> 1570.7963 | M26: =D26*1000/(500*300*Confinamento!P26) -> 0.024423386 | N26: =1.1*(E26+F26)*391*(1-0.8*M26) -> 225215.71 | O26: =IF(L26*391>N26,"OK","NO") -> OK | P26: 450 | Q26: =300-80 -> 220 | R26: =(1.1*(E26+F26)*391)/1000-G26 -> 209.99383 | S26: =N26/(L26*391) -> 0.36669252
B27: 12 | C27: 12
B28: 8 | C28: 13 | D28: 166.454 | E28: 0 | F28: 534.07075 | G28: 16.999 | H28: 500 | I28: 50 | J28: 10 | K28: 2 | L28: =J28^2*PI()/4*K28*(H28/I28) -> 1570.7963 | M28: =D28*1000/(500*300*Confinamento!P28) -> 0.02948185 | N28: =1.1*(E28+F28)*391*(1-0.8*M28) -> 224286.15 | O28: =IF(L28*391>N28,"OK","NO") -> OK | P28: 450 | Q28: =300-80 -> 220 | R28: =(1.1*(E28+F28)*391)/1000-G28 -> 212.70483 | S28: =N28/(L28*391) -> 0.36517903
B29: 13 | C29: 13
B30: 9 | C30: 14 | D30: 156.281 | E30: 0 | F30: 534.07075 | G30: 19.786 | H30: 500 | I30: 50 | J30: 10 | K30: 2 | L30: =J30^2*PI()/4*K30*(H30/I30) -> 1570.7963 | M30: =D30*1000/(500*300*Confinamento!P30) -> 0.027680038 | N30: =1.1*(E30+F30)*391*(1-0.8*M30) -> 224617.26 | O30: =IF(L30*391>N30,"OK","NO") -> OK | P30: 450 | Q30: =300-80 -> 220 | R30: =(1.1*(E30+F30)*391)/1000-G30 -> 209.91783 | S30: =N30/(L30*391) -> 0.36571813
B31: 14 | C31: 14
B32: 10 | C32: 15 | D32: 51.773 | E32: 0 | F32: 615.75216 | G32: 25.958 | H32: 500 | I32: 50 | J32: 10 | K32: 2 | L32: =J32^2*PI()/4*K32*(H32/I32) -> 1570.7963 | M32: =D32*1000/(500*300*Confinamento!P32) -> 0.0091698837 | N32: =1.1*(E32+F32)*391*(1-0.8*M32) -> 262892.2 | O32: =IF(L32*391>N32,"OK","NO") -> OK | P32: 450 | Q32: =300-80 -> 220 | R32: =(1.1*(E32+F32)*391)/1000-G32 -> 238.877 | S32: =N32/(L32*391) -> 0.42803676
B33: 15 | C33: 15
B34: 47 | C34: 36 | D34: 213.893 | E34: =1137.25654059951 -> 1137.2565 | F34: 615.75216 | G34: 52.169 | H34: 500 | I34: 50 | J34: 10 | K34: 4 | L34: =J34^2*PI()/4*K34*(H34/I34) -> 3141.5927 | M34: =D34*1000/(500*300*Confinamento!P34) -> 0.032016281 | N34: =1.1*(E34+F34)*391*(1-0.8*M34) -> 734657.61 | O34: =IF(L34*391>N34,"OK","NO") -> OK | P34: 300 | Q34: =450-80 -> 370 | R34: =(1.1*(E34+F34)*391)/1000-G34 -> 701.80004 | S34: =N34/(L34*391) -> 0.59807873
B35: 52 | C35: 36
B36: 48 | C36: 37 | D36: 328.632 | E36: =1137.25654059951 -> 1137.2565 | F36: 615.75216 | G36: 47.495 | H36: 500 | I36: 50 | J36: 10 | K36: 4 | L36: =J36^2*PI()/4*K36*(H36/I36) -> 3141.5927 | M36: =D36*1000/(500*300*Confinamento!P36) -> 0.049190831 | N36: =1.1*(E36+F36)*391*(1-0.8*M36) -> 724298.35 | O36: =IF(L36*391>N36,"OK","NO") -> OK | P36: 300 | Q36: =450-80 -> 370 | R36: =(1.1*(E36+F36)*391)/1000-G36 -> 706.47404 | S36: =N36/(L36*391) -> 0.58964533
B37: 53 | C37: 37
B38: 49 | C38: 38 | D38: 381.7 | E38: =1256.63706143592 -> 1256.6371 | F38: 615.75216 | G38: 43.7 | H38: 500 | I38: 50 | J38: 10 | K38: 4 | L38: =J38^2*PI()/4*K38*(H38/I38) -> 3141.5927 | M38: =D38*1000/(500*300*Confinamento!P38) -> 0.057134242 | N38: =1.1*(E38+F38)*391*(1-0.8*M38) -> 768505.77 | O38: =IF(L38*391>N38,"OK","NO") -> OK | P38: 300 | Q38: =450-80 -> 370 | R38: =(1.1*(E38+F38)*391)/1000-G38 -> 761.6146 | S38: =N38/(L38*391) -> 0.62563423
B39: 54 | C39: 38
B40: 50 | C40: 39 | D40: 379.269 | E40: =1256.63706143592 -> 1256.6371 | F40: 615.75216 | G40: 48.945 | H40: 500 | I40: 50 | J40: 10 | K40: 4 | L40: =J40^2*PI()/4*K40*(H40/I40) -> 3141.5927 | M40: =D40*1000/(500*300*Confinamento!P40) -> 0.056770361 | N40: =1.1*(E40+F40)*391*(1-0.8*M40) -> 768740.2 | O40: =IF(L40*391>N40,"OK","NO") -> OK | P40: 300 | Q40: =450-80 -> 370 | R40: =(1.1*(E40+F40)*391)/1000-G40 -> 756.3696 | S40: =N40/(L40*391) -> 0.62582508
...

Sheet NodoY (Taglio Compressione)
B1: DIREZIONE Y
B2: Frame | C2: Joint | D2: NED | E2: As,sup | F2: Asinf | G2: VED,sup | H2: Vjbd | I2: η | J2: bj | K2: hjc | L2: ν | M2: VRd | N2: Verifica
B3: Text | C3: Text | D3: KN | E3: mm^2 | F3: mm^2 | G3: KN | H3: KN | I3: - | J3: mm | K3: mm | L3: - | M3: KN | N3: -
A4: PRIMO PIANO | B4: 1 | C4: 2 | D4: 358.839 | E4: 1137.2565 | F4: 0 | G4: 59.099 | H4: =(1.1*(E4+F4)*391)/1000-G4 -> 430.03504 | I4: =IF(F4=0,0.48*(1-30/250),0.6*(1-30/250)) -> 0.4224 | J4: 300 | K4: 420 | L4: =D4*1000/(500*300*17) -> 0.14072118 | M4: =(I4*17*J4*K4*SQRT(1-L4/I4))/1000 -> 738.85382 | N4: =IF(M4>H4,"OK","NO") -> OK
B5: 6 | C5: 2
B6: 2 | C6: 4 | D6: 402.063 | E6: 1017.876 | F6: 1017.876 | G6: 106.607 | H6: =(1.1*(E6+F6)*391)/1000-G6 -> 768.96995 | I6: =IF(F6=0,0.48*(1-30/250),0.6*(1-30/250)) -> 0.528 | J6: 300 | K6: 420 | L6: =D6*1000/(500*300*17) -> 0.15767176 | M6: =(I6*17*J6*K6*SQRT(1-L6/I6))/1000 -> 947.17416 | N6: =IF(M6>H6,"OK","NO") -> OK
B7: 7 | C7: 4
B8: 3 | C8: 6 | D8: 460.431 | E8: 1017.876 | F8: 816.81409 | G8: 92.63 | H8: =(1.1*(E8+F8)*391)/1000-G8 -> 696.47022 | I8: =IF(F8=0,0.48*(1-30/250),0.6*(1-30/250)) -> 0.528 | J8: 300 | K8: 420 | L8: =D8*1000/(500*300*17) -> 0.18056118 | M8: =(I8*17*J8*K8*SQRT(1-L8/I8))/1000 -> 917.43563 | N8: =IF(M8>H8,"OK","NO") -> OK
B9: 8 | C9: 6
B10: 4 | C10: 8 | D10: 474.403 | E10: 1017.876 | F10: 816.81409 | G10: 94.667 | H10: =(1.1*(E10+F10)*391)/1000-G10 -> 694.43322 | I10: =IF(F10=0,0.48*(1-30/250),0.6*(1-30/250)) -> 0.528 | J10: 300 | K10: 420 | L10: =D10*1000/(500*300*17) -> 0.18604039 | M10: =(I10*17*J10*K10*SQRT(1-L10/I10))/1000 -> 910.17276 | N10: =IF(M10>H10,"OK","NO") -> OK
B11: 9 | C11: 8
B12: 5 | C12: 10 | D12: 359.865 | E12: 1137.2565 | F12: 0 | G12: 59.244 | H12: =(1.1*(E12+F12)*391)/1000-G12 -> 429.89004 | I12: =IF(F12=0,0.48*(1-30/250),0.6*(1-30/250)) -> 0.4224 | J12: 300 | K12: 420 | L12: =D12*1000/(500*300*17) -> 0.14112353 | M12: =(I12*17*J12*K12*SQRT(1-L12/I12))/1000 -> 738.32593 | N12: =IF(M12>H12,"OK","NO") -> OK
B13: 10 | C13: 10
B14: 42 | C14: 27 | D14: 428.39 | E14: 678.58401 | F14: 0 | G14: 11.586 | H14: =(1.1*(E14+F14)*391)/1000-G14 -> 280.27298 | I14: =IF(F14=0,0.48*(1-30/250),0.6*(1-30/250)) -> 0.4224 | J14: 500 | K14: 220 | L14: =D14*1000/(500*300*17) -> 0.16799608 | M14: =(I14*17*J14*K14*SQRT(1-L14/I14))/1000 -> 613.00704 | N14: =IF(M14>H14,"OK","NO") -> OK
B15: 47 | C15: 27
B16: 43 | C16: 29 | D16: 561.845 | E16: 678.58401 | F16: 678.58401 | G16: 22.344 | H16: =(1.1*(E16+F16)*391)/1000-G16 -> 561.37397 | I16: =IF(F16=0,0.48*(1-30/250),0.6*(1-30/250)) -> 0.528 | J16: 500 | K16: 220 | L16: =D16*1000/(500*300*17) -> 0.22033137 | M16: =(I16*17*J16*K16*SQRT(1-L16/I16))/1000 -> 753.70288 | N16: =IF(M16>H16,"OK","NO") -> OK
B17: 48 | C17: 29
B18: 44 | C18: 31 | D18: 647.766 | E18: 678.58401 | F18: 678.58401 | G18: 18.762 | H18: =(1.1*(E18+F18)*391)/1000-G18 -> 564.95597 | I18: =IF(F18=0,0.48*(1-30/250),0.6*(1-30/250)) -> 0.528 | J18: 500 | K18: 220 | L18: =D18*1000/(500*300*17) -> 0.25402588 | M18: =(I18*17*J18*K18*SQRT(1-L18/I18))/1000 -> 711.23535 | N18: =IF(M18>H18,"OK","NO") -> OK
B19: 49 | C19: 31
B20: 45 | C20: 33 | D20: 648.669 | E20: 678.58401 | F20: 678.58401 | G20: 19.025 | H20: =(1.1*(E20+F20)*391)/1000-G20 -> 564.69297 | I20: =IF(F20=0,0.48*(1-30/250),0.6*(1-30/250)) -> 0.528 | J20: 500 | K20: 220 | L20: =D20*1000/(500*300*17) -> 0.25438 | M20: =(I20*17*J20*K20*SQRT(1-L20/I20))/1000 -> 710.77556 | N20: =IF(M20>H20,"OK","NO") -> OK
B21: 50 | C21: 33
B22: 46 | C22: 35 | D22: 432.025 | E22: 678.58401 | F22: 0 | G22: 11.583 | H22: =(1.1*(E22+F22)*391)/1000-G22 -> 280.27598 | I22: =IF(F22=0,0.48*(1-30/250),0.6*(1-30/250)) -> 0.4224 | J22: 500 | K22: 220 | L22: =D22*1000/(500*300*17) -> 0.16942157 | M22: =(I22*17*J22*K22*SQRT(1-L22/I22))/1000 -> 611.28721 | N22: =IF(M22>H22,"OK","NO") -> OK
B23: 51 | C23: 35
