Workbook

Sheet Pesi elementi
B2: Peso tramezzi interni | F2: Tamponature esterne | J2: Pilastri
J3: a | K3: 0.3 | L3: m
J4: b | K4: 0.6 | L4: m
J5: 𝛾c.a | K5: 25 | L5: kN/m3
J6: Altezza Interpiano | K6: 3.5 | L6: m
J7: G1 | K7: =K5*K4*K3 -> 4.5 | L7: kN/m
J9: Trave Principale (Ricalata)
J10: a | K10: 0.3 | L10: m
J11: b | K11: 0.7 | L11: m
J12: 𝛾c.a | K12: 25 | L12: kN/m3
J13: G1 | K13: =K12*K11*K10 -> 5.25 | L13: kN/m
J15: Trave Secondaria (A Spessore)
J16: a | K16: 0.6 | L16: m
B17: үlaterizio | C17: 9 | D17: KN/m3 | F17: үlaterizio | G17: 9 | H17: KN/m3 | J17: b | K17: 0.22 | L17: m
B18: slaterizio | C18: 0.06 | D18: m | F18: slaterizio | G18: 0.06 | H18: m | J18: 𝛾c.a | K18: 25 | L18: kN/m3
B19: үmalta | C19: 18 | D19: KN/m3 | F19: sparete in laterizio | G19: 0.12 | H19: m | J19: G1 | K19: =K18*K17*K16 -> 3.3 | L19: kN/m
B20: sintonaco | C20: 0.015 | D20: m | F20: үmalta | G20: 18 | H20: KN/m3
B21: Altezza tramezzi | C21: =3.5-0.3 -> 3.2 | D21: m | F21: sintonaco | G21: 0.015 | H21: m
B22: P.Platerizio | C22: =C17*C18 -> 0.54 | D22: KN/m2 | F22: үmalta-cementizia | G22: 22 | H22: KN/m3
B23: P.Pintonaco | C23: =2*C19*C20 -> 0.54 | D23: KN/m2 | F23: sintonaco esterno | G23: 0.025 | H23: m
B24: Ptot | C24: =SUM(C22:C23) -> 1.08 | D24: KN/m2 | F24: Altezza tramezzi | G24: =3.5-0.7 -> 2.8 | H24: m
B25: G2 | C25: =C24*C21 -> 3.456 | D25: KN/m | F25: P.Platerizi forati | G25: =G17*(G19+G18) -> 1.62 | H25: KN/m2
B26: g2 | C26: 1.6 | D26: KN/m2 | F26: P.Pintonaco interno | G26: =G20*G21 -> 0.27 | H26: KN/m2
F27: P.Pintonaco esterno | G27: =G22*G23 -> 0.55 | H27: KN/m2
F28: P.Pisolante termico | G28: 0.09 | H28: KN/m2
F29: P.Pcortina di laterizio | G29: 0.35 | H29: KN/m2
F30: Ptot | G30: =SUM(G25:G29) -> 2.88 | H30: KN/m2
F31: Ptot al m | G31: =G30*G24 -> 8.064 | H31: KN/m
F32: G2 | G32: =G31 -> 8.064 | H32: KN/m
C37: Solaio latero cemento H=22 cm (Carichi riferiti ad una striscia di 1 m)
C39: (Altezza Solaio) H [m] | D39: 0.22
C40: (Altezza Soletta) s [m] | D40: 0.04
C41: (Altezza Pignatta) h [m] | D41: 0.18
C42: (Interasse Travetto) i [m] | D42: 0.5
D44: h [m] | E44: L [m] | F44: 𝛾 [kN/m3] | G44: 𝛾 [kN/m]
C45: Travetto | D45: 0.18 | E45: 0.1 | F45: 25 | G45: =2*D45*E45*F45 -> 0.9
C46: Soletta | D46: 0.04 | E46: 1 | F46: 25 | G46: =D46*E46*F46 -> 1
D48: G1 [KN/m]= | G48: =SUM(G45:G46) -> 1.9
D50: h [m] | E50: L [m] | F50: 𝛾 [kN/m3] | G50: 𝛾 [kN/m]
C51: Intonaco Interno | D51: 0.02 | E51: 1 | F51: 20 | G51: =D51*E51*F51 -> 0.4
...

Sheet Azione del vento & Neve
B2: CALCOLO AZIONE DEL VENTO | I2: CALCOLO AZIONE DELLA NEVE
J3: qsk (Lucca) | K3: 1.94 | L3: KN/m2
C4: Velocità base di riferimento | J4: μi | K4: 0.8
C5: vb=vb,0*ca | J5: CE | K5: 1
J6: Ct | K6: 1
D7: a0 [m]= | E7: 500 | J7: qs (Carico Neve) | K7: =K3*K4*K5*K6 -> 1.552 | L7: KN/m2
C8: Zona 3 | D8: Ka = | E8: 0.37
D9: Vb,0 [m/s] = | E9: 27
C11: Per Lucca | D11: as [m] = | E11: 19
C13: poiché as <a0 | D13: ca= | E13: 1
C15: vb= | D15: =E9*E13 -> 27 | E15: m/s
C17: Velocità di riferimento
C18: vr=vb*cr
C20: Tr= | D20: 50 | E20: anni
C21: per 5<=Tr=>50
C22: cr= | D22: 1 | E22: anni
C23: per Tr>50
C24: cr= | D24: =0.65*SQRT(1-0.138*LN(-LN(1-(1/$D$20)))) -> 0.80622735 | E24: anni
C26: vr= | D26: =D15*D22 -> 27 | E26: m/s
C28: Pressione cinetica di riferimento
C29: qr=(1/2)*ρ*(vr)^2
C31: ρ= | D31: 1.25 | E31: Kg/m^3
C33: qr= | D33: =(1/2)*D31*(D26^2) -> 455.625 | E33: N/m^2
C37: Coefficiente di pressione [cp]
C39: Coefficiente di topografia [ct]
C40: 1
C42: cpe= | D42: 0.8
C44: cpe= | D44: -0.4
C46: Coefficiente di esposizione [ce]
C48: Toscana Zona 3
C49: distanza Lucca- mare 25 Km
C50: classe di rugosità D
C53: Categoria di esposizione del sito II
C54: Kr | D54: z0 [m] | E54: zmin [m]
C55: 0.23 | D55: 0.7 | E55: =12 -> 12
C57: fino a 4 m [ce] sarà : | D57: ce(<=4)= | E57: =$C$55^2*$C$40*LN($E$55/$D$55)*(7+$C$40*LN($E$55/$D$55)) -> 1.4793833
C59: Z [m]> zmin [m]
C60: 7 | D60: ce(7)= | E60: =$C$55^2*$C$40*LN(C60/$D$55)*(7+$C$40*LN(C60/$D$55)) -> 1.1331177
C62: Coefficiente dinamico [cd]
D63: 1
...

Sheet Analisi statica lineare
B2: CALCOLO MASSE DI PIANO
E4: COMB: | G4: G1 + G2 + Ψ2iQk | I4: Ψ2i=0,3
E6: Peso al m [KN/m] | F6: Peso al m^2 [KN/m^2] | G6: Caratteristiche | K6: PESO [KN]
D7: Pilastri | E7: ='Pesi elementi'!K7 -> 4.5 | F7: - | G7: del | K7: =12*E7*J10 -> 189
D8: travi principali | E8: ='Pesi elementi'!K13 -> 5.25 | F8: - | G8: fabbricato | K8: =(E8*G10)*6+(E8*H10)*3+(E8*I10)*4 -> 363.5625
D9: travi secondarie | E9: ='Pesi elementi'!K19 -> 3.3 | F9: - | G9: X1 [m] | H9: X2 [m] | I9: Y1 [m] | J9: h [m] | K9: =4*(E9*I10) -> 62.7
D10: solaio | E10: - | F10: ='Pesi elementi'!G48+'Pesi elementi'!G57+0.3*'Pesi elementi'!J55 -> 5.656 | G10: =5.5 -> 5.5 | H10: 5.75 | I10: 4.75 | J10: 3.5 | K10: =F10*J12 -> 781.5885
D11: tramezzi interni | E11: - | F11: ='Pesi elementi'!C26 -> 1.6 | G11: Perimetro [m] | J11: =(2*G10+H10)*2+I10*2*2 -> 52.5 | K11: =F11*J12 -> 221.1
D12: tramezzi esterni | E12: ='Pesi elementi'!G32 -> 8.064 | F12: - | G12: Area [m^2] | J12: =(2*G10+H10)*(I10+J10) -> 138.1875 | K12: =E12*J11 -> 423.36
D13: W1 (peso totale) [KN] | K13: =SUM(K7:K12) -> 2041.311
E16: Peso al m [KN/m] | F16: Peso al m^2 [KN/m^2] | G16: Caratteristiche | K16: PESO [KN]
D17: Pilastri | E17: ='Pesi elementi'!K7 -> 4.5 | F17: - | G17: del | K17: =12*E17*J20/2 -> 94.5
D18: travi principali | E18: ='Pesi elementi'!K13 -> 5.25 | F18: - | G18: fabbricato | K18: =(E18*G20)*6+(E18*H20)*3+(E18*I20)*4 -> 363.5625
D19: travi secondarie | E19: ='Pesi elementi'!K19 -> 3.3 | F19: - | G19: X1 [m] | H19: X2 [m] | I19: Y1 [m] | J19: h [m] | K19: =4*(E19*I20) -> 62.7
D20: solaio | E20: - | F20: 6.93 | G20: =5.5 -> 5.5 | H20: 5.75 | I20: 4.75 | J20: =3.5 -> 3.5 | K20: =F20*J22 -> 957.63937
D21: tramezzi interni | E21: - | F21: 1.6 | G21: Perimetro [m] | J21: =(2*G20+H20)*2+I20*2*2 -> 52.5 | K21: =F21*J22/2 -> 110.55
D22: tramezzi esterni | E22: ='Pesi elementi'!G32 -> 8.064 | F22: - | G22: Area [m^2] | J22: =(2*G20+H20)*(I20+J20) -> 138.1875 | K22: =E22*J21/2 -> 211.68
D23: W2 (peso totale) [KN] | K23: =SUM(K17:K22) -> 1800.6319
B29: ANALISI STATICA LINEARE NTC 08
B31: Calcolo q [fattore di struttura]
B32: qo= | C32: 3 | D32: valore base del fattore di comportamento per strutture a telaio in calcestruzzo in CD''B''
B33: αu/α1= | C33: 1.3 | D33: coefficiente amplificativo del fattore di comportamento per strutture a più piani e più campate
B34: q= | C34: =C32*C33 -> 3.9 | D34: fattore di comportamento
B36: Parametri indipendenti
B37: STATO LIMITE | C37: SLV | E37: Parametri dipendenti
B38: ag | C38: 0.2037607 | D38: g | E38: S | F38: 1.406
B39: Fo | C39: 2.4012106 | E39: η | F39: 0.256
B40: Tc | C40: 0.28102577 | D40: s | E40: TB | F40: 0.15 | G40: s
B41: Ss | C41: 1.4064366 | E41: TC | F41: 0.449 | G41: s
B42: Cc | C42: 1.5962579 | E42: TD | F42: 2.415 | G42: s
B43: ST | C43: 1
B44: q | C44: =C34 -> 3.9
B46: C1= | C46: 0.075
B47: H= | C47: 7
B48: T1= | C48: =C46*C47^(3/4) -> 0.32276378 | D48: mi trovo tra TB e TC | F48: Sd(T1)= | G48: =C38*F38*F39*C39 -> 0.17610673
B49: λ= | C49: 1
B52: T1= | C52: =0.26 -> 0.26
B53: q= | C53: =3.12 -> 3.12
B54: Sd(T1x)SLV= | C54: =0.688 -> 0.688 | E54: Sd(T1y)SLV= | F54: =0.61872 -> 0.61872
B55: Sd(T1x)= | C55: =C54/C53 -> 0.22051282 | E55: Sd(T1y)= | F55: =F54/C53 -> 0.19830769
...

Sheet parametri geotecnici
A1: CPT 1
A3: NATURA COESIVA | N3: NATURA GRANULARE | Y3: media | AA3: calcolata da me con la curva 1 di shmertaman
A4: Prof. Rp Rp/Rl | D4: Natura Y' p'vo Cu OCR | J4: Eu50 Eu25 | L4: Mo | M4: Dr | N4: ø1s | O4: ø2s | P4: ø3s | Q4: ø4s | R4: ødm | T4: ømy | U4: Amax/g | V4: E'50 E'25 Mo | Y4: øs | AA4: øs | AB4: øsmedia
A5: m kg/cm² (-) | D5: Litol. t/m³ kg/cm² kg/cm² (-) | J5: kg/cm² | L5: kg/cm² | M5: % | N5: (°) | O5: (°) | P5: (°) | Q5: (°) | R5: (°) | T5: (°) | U5: (-) | V5: kg/cm² kg/cm² | Y5: (°) | AA5: (°) | AB5: (°) | AD5: z [m] | AE5: qc [Kpa] | AF5: fs [Kpa] | BE5: 0 | BF5: -1.8
A6: 0.2 | B6: 16 | C6: -- | D6: 4/:/: | E6: 1.85 | F6: 0.04 | G6: 0.7 | I6: 99.9 | J6: 118 | K6: 177 | L6: 52 | M6: 89 | N6: 41 | O6: 42 | P6: 44 | Q6: 45 | R6: 43 | T6: 27 | U6: 0.221 | V6: 27 | W6: 40 | X6: 48 | Y6: =(AVERAGE(K6:K19)) -> 167 | AA6: =28+0.14*M6 -> 40.46 | AB6: =AVERAGE(AA6:AA19) -> 36.624 | AD6: =-A6 -> -0.2 | AE6: =B6*100 -> 1600 | AF6: =AE6/C6 -> #VALUE! | BE6: 1 | BF6: -1.8
A7: 0.4 | B7: 26 | C7: 26 | D7: 4/:/: | E7: 1.85 | F7: 0.07 | G7: 0.93 | I7: 99.9 | J7: 158 | K7: 237 | L7: 78 | M7: 89 | N7: 40 | O7: 42 | P7: 44 | Q7: 45 | R7: 42 | T7: 28 | U7: 0.22 | V7: 43 | W7: 65 | X7: 78 | AA7: =28+0.14*M7 -> 40.46 | AD7: =-A7 -> -0.4 | AE7: =B7*100 -> 2600 | AF7: =AE7/C7 -> 100 | BE7: 2 | BF7: -1.8
A8: 0.6 | B8: 30 | C8: 45 | D8: 3:::: | E8: 1.85 | F8: 0.11 | G8: -- | I8: -- | J8: -- | K8: -- | L8: -- | M8: 84 | N8: 40 | O8: 41 | P8: 43 | Q8: 45 | R8: 41 | T8: 29 | U8: 0.204 | V8: 50 | W8: 75 | X8: 90 | AA8: =28+0.14*M8 -> 39.76 | AD8: =-A8 -> -0.6 | AE8: =B8*100 -> 3000 | AF8: =AE8/C8 -> 66.666667 | BE8: 3 | BF8: -1.8
A9: 0.8 | B9: 25 | C9: 34 | D9: 3:::: | E9: 1.85 | F9: 0.15 | G9: -- | I9: -- | J9: -- | K9: -- | L9: -- | M9: 71 | N9: 38 | O9: 40 | P9: 42 | Q9: 44 | R9: 39 | T9: 28 | U9: 0.162 | V9: 42 | W9: 63 | X9: 75 | AA9: =28+0.14*M9 -> 37.94 | AD9: =-A9 -> -0.8 | AE9: =B9*100 -> 2500 | AF9: =AE9/C9 -> 73.529412 | BE9: 4 | BF9: -1.8
A10: 1 | B10: 17 | C10: 32 | D10: 4/:/: | E10: 1.85 | F10: 0.19 | G10: 0.72 | I10: 34.5 | J10: 123 | K10: 184 | L10: 54 | M10: 52 | N10: 35 | O10: 38 | P10: 40 | Q10: 42 | R10: 37 | T10: 27 | U10: 0.11 | V10: 28 | W10: 43 | X10: 51 | AA10: =28+0.14*M10 -> 35.28 | AD10: =-A10 -> -1 | AE10: =B10*100 -> 1700 | AF10: =AE10/C10 -> 53.125 | BE10: 5 | BF10: -1.8
A11: 1.2 | B11: 12 | C11: 22 | D11: 2//// | E11: 1.85 | F11: 0.22 | G11: 0.57 | I11: 20.5 | J11: 97 | K11: 146 | L11: 45 | M11: -- | N11: -- | O11: -- | P11: -- | Q11: -- | R11: -- | T11: -- | U11: -- | V11: -- | W11: -- | X11: -- | AA11: - | AD11: =-A11 -> -1.2 | AE11: =B11*100 -> 1200 | AF11: =AE11/C11 -> 54.545455 | BE11: 6 | BF11: -1.8
A12: 1.4 | B12: 24 | C12: 45 | D12: 3:::: | E12: 1.85 | F12: 0.26 | G12: -- | I12: -- | J12: -- | K12: -- | L12: -- | M12: 56 | N12: 36 | O12: 38 | P12: 40 | Q12: 42 | R12: 37 | T12: 28 | U12: 0.119 | V12: 40 | W12: 60 | X12: 72 | AA12: =28+0.14*M12 -> 35.84 | AD12: =-A12 -> -1.4 | AE12: =B12*100 -> 2400 | AF12: =AE12/C12 -> 53.333333 | BE12: 7 | BF12: -1.8
A13: 1.6 | B13: 20 | C13: 60 | D13: 4/:/: | E13: 1.85 | F13: 0.3 | G13: 0.8 | I13: 21.8 | J13: 136 | K13: 204 | L13: 60 | M13: 46 | N13: 34 | O13: 37 | P13: 39 | Q13: 42 | R13: 35 | T13: 27 | U13: 0.095 | V13: 33 | W13: 50 | X13: 60 | AA13: =28+0.14*M13 -> 34.44 | AD13: =-A13 -> -1.6 | AE13: =B13*100 -> 2000 | AF13: =AE13/C13 -> 33.333333 | BE13: 8 | BF13: -1.8
A14: 1.8 | B14: 9 | C14: 34 | D14: 4/:/: | E14: 0.85 | F14: 0.31 | G14: 0.45 | I14: 9.9 | J14: 77 | K14: 115 | L14: 38 | M14: 18 | N14: 30 | O14: 33 | P14: 36 | Q14: 39 | R14: 30 | T14: 26 | U14: 0.034 | V14: 15 | W14: 23 | X14: 27 | AA14: =28+0.14*M14 -> 30.52 | AD14: =-A14 -> -1.8 | AE14: =B14*100 -> 900 | AF14: =AE14/C14 -> 26.470588 | BE14: 9 | BF14: -1.8
A15: 2 | B15: 76 | C15: 104 | D15: 3:::: | E15: 0.96 | F15: 0.33 | G15: -- | I15: -- | J15: -- | K15: -- | L15: -- | M15: 89 | N15: 41 | O15: 42 | P15: 44 | Q15: 45 | R15: 41 | T15: 33 | U15: 0.221 | V15: 127 | W15: 190 | X15: 228 | AA15: =28+0.14*M15 -> 40.46 | AD15: =-A15 -> -2 | AE15: =B15*100 -> 7600 | AF15: =AE15/C15 -> 73.076923 | BE15: 10 | BF15: -1.8
A16: 2.2 | B16: 11 | C16: 82 | D16: 4/:/: | E16: 0.87 | F16: 0.35 | G16: 0.54 | I16: 10.7 | J16: 91 | K16: 137 | L16: 42 | M16: 22 | N16: 31 | O16: 34 | P16: 37 | Q16: 40 | R16: 31 | T16: 26 | U16: 0.041 | V16: 18 | W16: 28 | X16: 33 | AA16: =28+0.14*M16 -> 31.08 | AD16: =-A16 -> -2.2 | AE16: =B16*100 -> 1100 | AF16: =AE16/C16 -> 13.414634 | BE16: 11 | BF16: -1.8
A17: 2.4 | B17: 6 | C17: 90 | D17: 4/:/: | E17: 0.82 | F17: 0.37 | G17: 0.3 | I17: 4.9 | J17: 101 | K17: 152 | L17: 29 | M17: -- | N17: 28 | O17: 31 | P17: 35 | Q17: 38 | R17: 27 | T17: 26 | U17: -- | V17: 10 | W17: 15 | X17: 18 | AA17: - | AD17: =-A17 -> -2.4 | AE17: =B17*100 -> 600 | AF17: =AE17/C17 -> 6.6666667 | BE17: 12 | BF17: -1.8
A18: 2.6 | B18: 5 | C18: 19 | D18: 2//// | E18: 0.8 | F18: 0.38 | G18: 0.25 | I18: 3.7 | J18: 108 | K18: 162 | L18: 25 | M18: -- | N18: -- | O18: 0 | P18: 0 | Q18: 0 | R18: 0 | T18: 0 | U18: -- | V18: -- | W18: -- | X18: -- | AA18: - | AD18: =-A18 -> -2.6 | AE18: =B18*100 -> 500 | AF18: =AE18/C18 -> 26.315789 | BE18: 13 | BF18: -1.8
A19: 2.8 | B19: 8 | C19: 13 | D19: 2//// | E19: 0.86 | F19: 0.4 | G19: 0.4 | I19: 6.3 | J19: 104 | K19: 156 | L19: 35 | M19: -- | N19: -- | O19: 0 | P19: 0 | Q19: 0 | R19: 0 | T19: 0 | U19: -- | V19: -- | W19: -- | X19: -- | AA19: - | AD19: =-A19 -> -2.8 | AE19: =B19*100 -> 800 | AF19: =AE19/C19 -> 61.538462 | BE19: 14 | BF19: -1.8
A20: 3 | B20: 36 | C20: 34 | D20: 3:::: | E20: 0.89 | F20: 0.42 | G20: -- | I20: -- | J20: -- | K20: -- | L20: -- | M20: 58 | N20: 36 | O20: 38 | P20: 40 | Q20: 43 | R20: 36 | T20: 30 | U20: 0.126 | V20: 60 | W20: 90 | X20: 108 | Y20: =(AVERAGE(V20:V40)+AVERAGE(V42:V53))/2 -> 72.190476 | AA20: =28+0.14*M20 -> 36.12 | AB20: =AVERAGE(AA20:AA53) -> 34.787879 | AD20: =-A20 -> -3 | AE20: =B20*100 -> 3600 | AF20: =AE20/C20 -> 105.88235 | BE20: 15 | BF20: -1.8
A21: 3.2 | B21: 38 | C21: 71 | D21: 3:::: | E21: 0.9 | F21: 0.43 | G21: -- | I21: -- | J21: -- | K21: -- | L21: -- | M21: 59 | N21: 36 | O21: 38 | P21: 40 | Q21: 43 | R21: 36 | T21: 30 | U21: 0.128 | V21: 63 | W21: 95 | X21: 114 | AA21: =28+0.14*M21 -> 36.26 | AD21: =-A21 -> -3.2 | AE21: =B21*100 -> 3800 | AF21: =AE21/C21 -> 53.521127 | BE21: 100 | BF21: -1.8
A22: 3.4 | B22: 52 | C22: 32 | D22: 3:::: | E22: 0.92 | F22: 0.45 | G22: -- | I22: -- | J22: -- | K22: -- | L22: -- | M22: 69 | N22: 38 | O22: 40 | P22: 41 | Q22: 44 | R22: 38 | T22: 31 | U22: 0.156 | V22: 87 | W22: 130 | X22: 156 | AA22: =28+0.14*M22 -> 37.66 | AD22: =-A22 -> -3.4 | AE22: =B22*100 -> 5200 | AF22: =AE22/C22 -> 162.5 | BE22: 200 | BF22: -1.8
A23: 3.6 | B23: 36 | C23: 39 | D23: 3:::: | E23: 0.89 | F23: 0.47 | G23: -- | I23: -- | J23: -- | K23: -- | L23: -- | M23: 55 | N23: 36 | O23: 38 | P23: 40 | Q23: 42 | R23: 35 | T23: 30 | U23: 0.118 | V23: 60 | W23: 90 | X23: 108 | AA23: =28+0.14*M23 -> 35.7 | AD23: =-A23 -> -3.6 | AE23: =B23*100 -> 3600 | AF23: =AE23/C23 -> 92.307692 | BE23: 300 | BF23: -1.8
A24: 3.8 | B24: 32 | C24: 37 | D24: 3:::: | E24: 0.88 | F24: 0.49 | G24: -- | I24: -- | J24: -- | K24: -- | L24: -- | M24: 50 | N24: 35 | O24: 37 | P24: 40 | Q24: 42 | R24: 35 | T24: 29 | U24: 0.105 | V24: 53 | W24: 80 | X24: 96 | AA24: =28+0.14*M24 -> 35 | AD24: =-A24 -> -3.8 | AE24: =B24*100 -> 3200 | AF24: =AE24/C24 -> 86.486486 | BE24: 400 | BF24: -1.8
A25: 4 | B25: 37 | C25: 40 | D25: 3:::: | E25: 0.89 | F25: 0.51 | G25: -- | I25: -- | J25: -- | K25: -- | L25: -- | M25: 54 | N25: 36 | O25: 38 | P25: 40 | Q25: 42 | R25: 35 | T25: 30 | U25: 0.115 | V25: 62 | W25: 93 | X25: 111 | AA25: =28+0.14*M25 -> 35.56 | AD25: =-A25 -> -4 | AE25: =B25*100 -> 3700 | AF25: =AE25/C25 -> 92.5 | BE25: 500 | BF25: -1.8
A26: 4.2 | B26: 22 | C26: 33 | D26: 3:::: | E26: 0.86 | F26: 0.52 | G26: -- | I26: -- | J26: -- | K26: -- | L26: -- | M26: 36 | N26: 33 | O26: 36 | P26: 38 | Q26: 41 | R26: 32 | T26: 28 | U26: 0.07 | V26: 37 | W26: 55 | X26: 66 | AA26: =28+0.14*M26 -> 33.04 | AD26: =-A26 -> -4.2 | AE26: =B26*100 -> 2200 | AF26: =AE26/C26 -> 66.666667 | BE26: 600 | BF26: -1.8
A27: 4.4 | B27: 26 | C27: 43 | D27: 3:::: | E27: 0.87 | F27: 0.54 | G27: -- | I27: -- | J27: -- | K27: -- | L27: -- | M27: 41 | N27: 34 | O27: 36 | P27: 39 | Q27: 41 | R27: 33 | T27: 28 | U27: 0.081 | V27: 43 | W27: 65 | X27: 78 | AA27: =28+0.14*M27 -> 33.74 | AD27: =-A27 -> -4.4 | AE27: =B27*100 -> 2600 | AF27: =AE27/C27 -> 60.465116 | BE27: 700 | BF27: -1.8
A28: 4.6 | B28: 27 | C28: 45 | D28: 3:::: | E28: 0.87 | F28: 0.56 | G28: -- | I28: -- | J28: -- | K28: -- | L28: -- | M28: 41 | N28: 34 | O28: 36 | P28: 39 | Q28: 41 | R28: 33 | T28: 28 | U28: 0.083 | V28: 45 | W28: 68 | X28: 81 | AA28: =28+0.14*M28 -> 33.74 | AD28: =-A28 -> -4.6 | AE28: =B28*100 -> 2700 | AF28: =AE28/C28 -> 60 | BE28: 800 | BF28: -1.8
A29: 4.8 | B29: 28 | C29: 42 | D29: 3:::: | E29: 0.87 | F29: 0.58 | G29: -- | I29: -- | J29: -- | K29: -- | L29: -- | M29: 42 | N29: 34 | O29: 36 | P29: 39 | Q29: 41 | R29: 33 | T29: 28 | U29: 0.084 | V29: 47 | W29: 70 | X29: 84 | AA29: =28+0.14*M29 -> 33.88 | AD29: =-A29 -> -4.8 | AE29: =B29*100 -> 2800 | AF29: =AE29/C29 -> 66.666667 | BE29: 900 | BF29: -1.8
A30: 5 | B30: 26 | C30: 24 | D30: 4/:/: | E30: 0.95 | F30: 0.59 | G30: 0.93 | I30: 11 | J30: 158 | K30: 237 | L30: 78 | M30: 38 | N30: 33 | O30: 36 | P30: 38 | Q30: 41 | R30: 32 | T30: 28 | U30: 0.076 | V30: 43 | W30: 65 | X30: 78 | AA30: =28+0.14*M30 -> 33.32 | AD30: =-A30 -> -5 | AE30: =B30*100 -> 2600 | AF30: =AE30/C30 -> 108.33333 | BE30: 1000 | BF30: -1.8
A31: 5.2 | B31: 38 | C31: 57 | D31: 3:::: | E31: 0.9 | F31: 0.61 | G31: -- | I31: -- | J31: -- | K31: -- | L31: -- | M31: 51 | N31: 35 | O31: 37 | P31: 40 | Q31: 42 | R31: 34 | T31: 30 | U31: 0.106 | V31: 63 | W31: 95 | X31: 114 | AA31: =28+0.14*M31 -> 35.14 | AD31: =-A31 -> -5.2 | AE31: =B31*100 -> 3800 | AF31: =AE31/C31 -> 66.666667 | BE31: 2000 | BF31: -1.8
A32: 5.4 | B32: 48 | C32: 60 | D32: 3:::: | E32: 0.91 | F32: 0.63 | G32: -- | I32: -- | J32: -- | K32: -- | L32: -- | M32: 58 | N32: 36 | O32: 38 | P32: 40 | Q32: 43 | R32: 35 | T32: 31 | U32: 0.125 | V32: 80 | W32: 120 | X32: 144 | AA32: =28+0.14*M32 -> 36.12 | AD32: =-A32 -> -5.4 | AE32: =B32*100 -> 4800 | AF32: =AE32/C32 -> 80 | BE32: 3000 | BF32: -1.8
A33: 5.6 | B33: 42 | C33: 42 | D33: 3:::: | E33: 0.9 | F33: 0.65 | G33: -- | I33: -- | J33: -- | K33: -- | L33: -- | M33: 53 | N33: 35 | O33: 38 | P33: 40 | Q33: 42 | R33: 35 | T33: 30 | U33: 0.111 | V33: 70 | W33: 105 | X33: 126 | AA33: =28+0.14*M33 -> 35.42 | AD33: =-A33 -> -5.6 | AE33: =B33*100 -> 4200 | AF33: =AE33/C33 -> 100 | BE33: 4000 | BF33: -1.8
A34: 5.8 | B34: 30 | C34: 56 | D34: 3:::: | E34: 0.88 | F34: 0.67 | G34: -- | I34: -- | J34: -- | K34: -- | L34: -- | M34: 41 | N34: 34 | O34: 36 | P34: 39 | Q34: 41 | R34: 33 | T34: 29 | U34: 0.081 | V34: 50 | W34: 75 | X34: 90 | AA34: =28+0.14*M34 -> 33.74 | AD34: =-A34 -> -5.8 | AE34: =B34*100 -> 3000 | AF34: =AE34/C34 -> 53.571429 | BE34: 5000 | BF34: -1.8
A35: 6 | B35: 32 | C35: 53 | D35: 3:::: | E35: 0.88 | F35: 0.68 | G35: -- | I35: -- | J35: -- | K35: -- | L35: -- | M35: 42 | N35: 34 | O35: 36 | P35: 39 | Q35: 41 | R35: 33 | T35: 29 | U35: 0.085 | V35: 53 | W35: 80 | X35: 96 | AA35: =28+0.14*M35 -> 33.88 | AD35: =-A35 -> -6 | AE35: =B35*100 -> 3200 | AF35: =AE35/C35 -> 60.377358 | BE35: 6000 | BF35: -1.8
A36: 6.2 | B36: 37 | C36: 37 | D36: 3:::: | E36: 0.89 | F36: 0.7 | G36: -- | I36: -- | J36: -- | K36: -- | L36: -- | M36: 46 | N36: 35 | O36: 37 | P36: 39 | Q36: 42 | R36: 33 | T36: 30 | U36: 0.095 | V36: 62 | W36: 93 | X36: 111 | AA36: =28+0.14*M36 -> 34.44 | AD36: =-A36 -> -6.2 | AE36: =B36*100 -> 3700 | AF36: =AE36/C36 -> 100 | BE36: 7000 | BF36: -1.8
A37: 6.4 | B37: 41 | C37: 56 | D37: 3:::: | E37: 0.9 | F37: 0.72 | G37: -- | I37: -- | J37: -- | K37: -- | L37: -- | M37: 49 | N37: 35 | O37: 37 | P37: 39 | Q37: 42 | R37: 34 | T37: 30 | U37: 0.102 | V37: 68 | W37: 103 | X37: 123 | AA37: =28+0.14*M37 -> 34.86 | AD37: =-A37 -> -6.4 | AE37: =B37*100 -> 4100 | AF37: =AE37/C37 -> 73.214286 | BE37: 8000 | BF37: -1.8
A38: 6.6 | B38: 33 | C38: 45 | D38: 3:::: | E38: 0.88 | F38: 0.74 | G38: -- | I38: -- | J38: -- | K38: -- | L38: -- | M38: 41 | N38: 34 | O38: 36 | P38: 39 | Q38: 41 | R38: 32 | T38: 29 | U38: 0.083 | V38: 55 | W38: 83 | X38: 99 | AA38: =28+0.14*M38 -> 33.74 | AD38: =-A38 -> -6.6 | AE38: =B38*100 -> 3300 | AF38: =AE38/C38 -> 73.333333 | BE38: 9000 | BF38: -1.8
A39: 6.8 | B39: 26 | C39: 65 | D39: 3:::: | E39: 0.87 | F39: 0.75 | G39: -- | I39: -- | J39: -- | K39: -- | L39: -- | M39: 33 | N39: 33 | O39: 35 | P39: 38 | Q39: 41 | R39: 31 | T39: 28 | U39: 0.063 | V39: 43 | W39: 65 | X39: 78 | AA39: =28+0.14*M39 -> 32.62 | AD39: =-A39 -> -6.8 | AE39: =B39*100 -> 2600 | AF39: =AE39/C39 -> 40 | BE39: 10000 | BF39: -1.8
A40: 7 | B40: 20 | C40: 25 | D40: 4/:/: | E40: 0.93 | F40: 0.77 | G40: 0.8 | I40: 6.6 | J40: 199 | K40: 298 | L40: 60 | M40: 23 | N40: 31 | O40: 34 | P40: 37 | Q40: 40 | R40: 29 | T40: 27 | U40: 0.044 | V40: 33 | W40: 50 | X40: 60 | AA40: =28+0.14*M40 -> 31.22 | AD40: =-A40 -> -7 | AE40: =B40*100 -> 2000 | AF40: =AE40/C40 -> 80
A41: 7.2 | B41: 10 | C41: 25 | D41: 2//// | E41: 0.9 | F41: 0.79 | G41: 0.5 | I41: 3.5 | J41: 223 | K41: 335 | L41: 40 | M41: -- | N41: -- | O41: 0 | P41: 0 | Q41: 0 | R41: 0 | T41: 0 | U41: -- | V41: -- | W41: -- | X41: -- | AA41: - | AD41: =-A41 -> -7.2 | AE41: =B41*100 -> 1000 | AF41: =AE41/C41 -> 40
...

Sheet verifica a liquefazione CPT (5)
A1: CPT 1 | AD1: DOMANDA | AF1: CAPACITA' | AH1: DOMANDA
A2: z | B2: qc | C2: qc/fs | D2: γ' | E2: σ'vo | F2: Dr | G2: φ's | H2: amax/g | K2: z | L2: qc | M2: fs | N2: γ | O2: γ' | P2: σvo | Q2: σ'vo | R2: Pa | S2: F | T2: n | U2: Q | V2: Ic | W2: qc1N | X2: kc | Y2: (qc1N)cs | Z2: Dr | AA2: f | AB2: kσ | AC2: rd | AD2: CSR7,5 | AE2: CSRM | AF2: CRR7,5 (Y-R) | AG2: FS | AH2: CRR7,5 (I-B) | AI2: FS
A3: [m] | B3: [Kg/cm^2] | C3: [Kg/cm^2] | D3: [t/m^3] | E3: [Kg/cm^2] | F3: % | G3: (°) | H3: (-) | K3: [m] | L3: [KPa] | M3: [KPa] | N3: [KN/m^3] | O3: [KN/m^3] | P3: [KPa] | Q3: [KPa] | R3: [KPa] | S3: (-) | T3: (-) | U3: (-) | V3: (-) | W3: (-) | X3: (-) | Y3: (-) | Z3: % | AA3: (-) | AB3: (-) | AC3: (-) | AD3: (-) | AE3: (-) | AF3: (-) | AG3: (-) | AH3: (-) | AI3: (-) | AN3: sabbia ghiaiosa | AO3: sabbie da pulite a limose | AP3: miscele di sabbie (da sabbia limosa a limo sabbioso) | AQ3: Mscele di limo (da limo argilloso a argilla limosa | AR3: Argilla (da argilla limosa a argilla) | AS3: Terreni organici (torbe)
A4: 0.2 | B4: 7 | C4: -- | D4: 1.85 | E4: 0.04 | F4: 89 | G4: 41 | H4: 0.221 | K4: 0.2 | L4: =B4*100 -> 700 | M4: -- | N4: =18.5 -> 18.5 | O4: =N4 -> 18.5 | P4: =N4*K4 -> 3.7 | Q4: =O4*K4 -> 3.7 | R4: =100 -> 100 | S4: =(M4/(L4-P4))*100 -> #VALUE! | T4: =((AJ59-1.64)*0.3)+0.5 -> #VALUE! | U4: =(($L4-$P4)/$R$4)*(($R$4/$Q4)^T4) -> #VALUE! | W4: =(L4/$R$4)*($R$4/Q4)^T4 -> #VALUE! | X4: =IF(V4<2.5,-(0.403*V4^4)+(5.581*V4^3)-(21.63*V4^2)+(33.75*V4)-17.88,(6*10^(-7))*V4^(16.76)) -> -17.88 | Y4: =X4*W4 -> #VALUE! | Z4: =-98+66*LOG(10*B4/(SQRT(10*(Q4/100)))) -> 38.025814 | AA4: =IF(Z4<40,1,0.75) -> 1 | AB4: =IF(P4/$R$4<=1,1,(P4/$R$4)^(AA4-1)) -> 1 | AC4: =IF(K4<9.15,1-0.00765*K4,1.174-0.0267*K4) -> 0.99847 | AD4: =0.65*AC4*($R$7)*(P4/Q4) -> 0.13239712 | AE4: =AD4/($R$22*AB4) -> 0.10814868 | AF4: =93*(Y4/1000)^3+0.08 -> #VALUE! | AH4: =EXP((Y4/540)+(Y4/67)^2-(Y4/80)^3+(Y4/114)^4-3) -> #VALUE! | AI4: =AH4/AE4 -> #VALUE! | AL4: 1.25 | AM4: -0.2 | AN4: 1.31 | AO4: 2.05 | AP4: 2.6 | AQ4: 2.95 | AR4: 3.6 | AS4: 4
A5: 0.4 | B5: 14 | C5: 35 | D5: 1.85 | E5: 0.07 | F5: 89 | G5: 40 | H5: 0.22 | K5: 0.4 | L5: =B5*100 -> 1400 | M5: =L5/C5 -> 40 | N5: =18.5 -> 18.5 | O5: =N5 -> 18.5 | P5: =N5*K5 -> 7.4 | Q5: =O5*K5 -> 7.4 | R5: amax/g | S5: =(M5/(L5-P5))*100 -> 2.8723251 | T5: =((AJ60-1.64)*0.3)+0.5 -> 0.69205416 | U5: =(($L5-$P5)/$R$4)*(($R$4/$Q5)^$T$5) -> 84.40716 | V5: =((3.47-LOG(U5))^2+(LOG($S5)+1.22)^2)^0.5 -> 2.2801827 | W5: =(L5/$R$4)*($R$4/Q5)^T5 -> 84.855682 | X5: =-(0.403*V5^4)+(5.581*V5^3)-(21.63*V5^2)+(33.75*V5)-17.88 -> 1.8867263 | Y5: =X5*W5 -> 160.09944 | Z5: =-98+66*LOG(10*B5/(SQRT(10*(Q5/100)))) -> 47.959804 | AA5: =IF(Z5<40,1,0.75) -> 0.75 | AB5: =IF(P5/$R$4<=1,1,(P5/$R$4)^(AA5-1)) -> 1 | AC5: =IF(K5<9.15,1-0.00765*K5,1.174-0.0267*K5) -> 0.99694 | AD5: =0.65*AC5*($R$7)*(P5/Q5) -> 0.13219424 | AE5: =AD5/($R$22*AB5) -> 0.10798296 | AF5: =93*(Y5/1000)^3+0.08 -> 0.46163871 | AH5: =EXP((Y5/540)+(Y5/67)^2-(Y5/80)^3+(Y5/114)^4-3) -> 0.32673293 | AL5: 1.25 | AM5: -0.4 | AN5: 1.31 | AO5: 2.05 | AP5: 2.6 | AQ5: 2.95 | AR5: 3.6
A6: 0.6 | B6: 24 | C6: 40 | D6: 1.85 | E6: 0.11 | F6: 84 | G6: 40 | H6: 0.204 | K6: 0.6 | L6: =B6*100 -> 2400 | M6: =L6/C6 -> 60 | N6: =18.5 -> 18.5 | O6: =N6 -> 18.5 | P6: =N6*K6 -> 11.1 | Q6: =O6*K6 -> 11.1 | R6: (-) | S6: =(M6/(L6-P6))*100 -> 2.5116162 | T6: =((AJ61-1.64)*0.3)+0.5 -> 0.66216625 | U6: =(($L6-$P6)/$R$4)*(($R$4/$Q6)^T6) -> 102.41248 | V6: =((3.47-LOG(U6))^2+(LOG($S6)+1.22)^2)^0.5 -> 2.1805546 | W6: =(L6/$R$4)*($R$4/Q6)^T6 -> 102.88834 | X6: =-(0.403*V6^4)+(5.581*V6^3)-(21.63*V6^2)+(33.75*V6)-17.88 -> 1.6204478 | Y6: =X6*W6 -> 166.72518 | Z6: =-98+66*LOG(10*B6/(SQRT(10*(Q6/100)))) -> 57.598284 | AA6: =IF(Z6<40,1,0.75) -> 0.75 | AB6: =IF(P6/$R$4<=1,1,(P6/$R$4)^(AA6-1)) -> 1 | AC6: =IF(K6<9.15,1-0.00765*K6,1.174-0.0267*K6) -> 0.99541 | AD6: =0.65*AC6*($R$7)*(P6/Q6) -> 0.13199137 | AE6: =AD6/($R$22*AB6) -> 0.10781724 | AF6: =93*(Y6/1000)^3+0.08 -> 0.51100918 | AG6: =AF6/AE6 -> 4.7395871 | AH6: =EXP((Y6/540)+(Y6/67)^2-(Y6/80)^3+(Y6/114)^4-3) -> 0.37690165 | AI6: =AH6/AE6 -> 3.4957457 | AL6: 1.25 | AM6: -0.6 | AN6: 1.31 | AO6: 2.05 | AP6: 2.6 | AQ6: 2.95 | AR6: 3.6
A7: 0.8 | B7: 50 | C7: 62 | D7: 1.85 | E7: 0.15 | F7: 71 | G7: 38 | H7: 0.162 | K7: 0.8 | L7: =B7*100 -> 5000 | M7: =L7/C7 -> 80.645161 | N7: =18.5 -> 18.5 | O7: =N7 -> 18.5 | P7: =N7*K7 -> 14.8 | Q7: =O7*K7 -> 14.8 | R7: 0.204 | S7: =(M7/(L7-P7))*100 -> 1.6176916 | T7: =((AJ62-1.64)*0.3)+0.5 -> 0.5849128 | U7: =(($L7-$P7)/$R$4)*(($R$4/$Q7)^T7) -> 152.40778 | V7: =((3.47-LOG(U7))^2+(LOG($S7)+1.22)^2)^0.5 -> 1.9230428 | W7: =(L7/$R$4)*($R$4/Q7)^T7 -> 152.86024 | X7: =-(0.403*V7^4)+(5.581*V7^3)-(21.63*V7^2)+(33.75*V7)-17.88 -> 1.2113401 | Y7: =X7*W7 -> 185.16574 | Z7: =-98+66*LOG(10*B7/(SQRT(10*(Q7/100)))) -> 74.513384 | AA7: =IF(Z7<40,1,0.75) -> 0.75 | AB7: =IF(P7/$R$4<=1,1,(P7/$R$4)^(AA7-1)) -> 1 | AC7: =IF(K7<9.15,1-0.00765*K7,1.174-0.0267*K7) -> 0.99388 | AD7: =0.65*AC7*($R$7)*(P7/Q7) -> 0.13178849 | AE7: =AD7/($R$22*AB7) -> 0.10765152 | AF7: =93*(Y7/1000)^3+0.08 -> 0.67042513 | AG7: =AF7/AE7 -> 6.2277351 | AH7: =EXP((Y7/540)+(Y7/67)^2-(Y7/80)^3+(Y7/114)^4-3) -> 0.63207938 | AI7: =AH7/AE7 -> 5.8715326 | AL7: 1.25 | AM7: -0.8 | AN7: 1.31 | AO7: 2.05 | AP7: 2.6 | AQ7: 2.95 | AR7: 3.6
A8: 1,00 | B8: 40 | C8: 37 | D8: 1.85 | E8: 0.19 | F8: 52 | G8: 35 | H8: 0.11 | K8: 1 | L8: =B8*100 -> 4000 | M8: =L8/C8 -> 108.10811 | N8: =18.5 -> 18.5 | O8: =N8 -> 18.5 | P8: =N8*K8 -> 18.5 | Q8: =O8*K8 -> 18.5 | R8: n | S8: =(M8/(L8-P8))*100 -> 2.7152608 | T8: =((AJ63-1.64)*0.3)+0.5 -> 0.65596465 | U8: =(($L8-$P8)/$R$4)*(($R$4/$Q8)^T8) -> 120.43595 | V8: =((3.47-LOG(U8))^2+(LOG($S8)+1.22)^2)^0.5 -> 2.1598822 | W8: =(L8/$R$4)*($R$4/Q8)^T8 -> 120.99556 | X8: =-(0.403*V8^4)+(5.581*V8^3)-(21.63*V8^2)+(33.75*V8)-17.88 -> 1.5740039 | Y8: =X8*W8 -> 190.44748 | Z8: =-98+66*LOG(10*B8/(SQRT(10*(Q8/100)))) -> 64.919292 | AA8: =IF(Z8<40,1,0.75) -> 0.75 | AB8: =IF(P8/$R$4<=1,1,(P8/$R$4)^(AA8-1)) -> 1 | AC8: =IF(K8<9.15,1-0.00765*K8,1.174-0.0267*K8) -> 0.99235 | AD8: =0.65*AC8*($R$7)*(P8/Q8) -> 0.13158561 | AE8: =AD8/($R$22*AB8) -> 0.1074858 | AF8: =93*(Y8/1000)^3+0.08 -> 0.72240458 | AG8: =AF8/AE8 -> 6.7209307 | AH8: =EXP((Y8/540)+(Y8/67)^2-(Y8/80)^3+(Y8/114)^4-3) -> 0.76347238 | AI8: =AH8/AE8 -> 7.1030072 | AL8: 1.25 | AM8: -1 | AN8: 1.31 | AO8: 2.05 | AP8: 2.6 | AQ8: 2.95 | AR8: 3.6
A9: 1.2 | B9: 24 | C9: 28 | D9: 1.85 | E9: 0.22 | F9: -- | G9: -- | H9: -- | K9: 1.2 | L9: =B9*100 -> 2400 | M9: =L9/C9 -> 85.714286 | N9: =18.5 -> 18.5 | O9: =N9 -> 18.5 | P9: =N9*K9 -> 22.2 | Q9: =O9*K9 -> 22.2 | R9: (-) | S9: =(M9/(L9-P9))*100 -> 3.6047727 | T9: =((AJ64-1.64)*0.3)+0.5 -> 0.72883429 | U9: =(($L9-$P9)/$R$4)*(($R$4/$Q9)^T9) -> 71.21569 | V9: =((3.47-LOG(U9))^2+(LOG($S9)+1.22)^2)^0.5 -> 2.402781 | W9: =(L9/$R$4)*($R$4/Q9)^T9 -> 71.880586 | X9: =-(0.403*V9^4)+(5.581*V9^3)-(21.63*V9^2)+(33.75*V9)-17.88 -> 2.3237573 | Y9: =X9*W9 -> 167.03303 | Z9: =-98+66*LOG(10*B9/(SQRT(10*(Q9/100)))) -> 47.664294 | AA9: =IF(Z9<40,1,0.75) -> 0.75 | AB9: =IF(P9/$R$4<=1,1,(P9/$R$4)^(AA9-1)) -> 1 | AC9: =IF(K9<9.15,1-0.00765*K9,1.174-0.0267*K9) -> 0.99082 | AD9: =0.65*AC9*($R$7)*(P9/Q9) -> 0.13138273 | AE9: =AD9/($R$22*AB9) -> 0.10732007 | AF9: =93*(Y9/1000)^3+0.08 -> 0.51340115 | AG9: =AF9/AE9 -> 4.7838315 | AH9: =EXP((Y9/540)+(Y9/67)^2-(Y9/80)^3+(Y9/114)^4-3) -> 0.37959045 | AI9: =AH9/AE9 -> 3.5369939 | AL9: 1.25 | AM9: -1.2 | AN9: 1.31 | AO9: 2.05 | AP9: 2.6 | AQ9: 2.95 | AR9: 3.6
A10: 1.4 | B10: 27 | C10: 31 | D10: 1.85 | E10: 0.26 | F10: 56 | G10: 36 | H10: 0.119 | K10: 1.4 | L10: =B10*100 -> 2700 | M10: =L10/C10 -> 87.096774 | N10: =18.5 -> 18.5 | O10: =N10 -> 18.5 | P10: =N10*K10 -> 25.9 | Q10: =O10*K10 -> 25.9 | R10: 1 | S10: =(M10/(L10-P10))*100 -> 3.25705 | T10: =((AJ65-1.64)*0.3)+0.5 -> 0.71975507 | U10: =(($L10-$P10)/$R$4)*(($R$4/$Q10)^T10) -> 70.7063 | V10: =((3.47-LOG(U10))^2+(LOG($S10)+1.22)^2)^0.5 -> 2.3725169 | W10: =(L10/$R$4)*($R$4/Q10)^T10 -> 71.391126 | X10: =-(0.403*V10^4)+(5.581*V10^3)-(21.63*V10^2)+(33.75*V10)-17.88 -> 2.2036599 | Y10: =X10*W10 -> 157.32176 | Z10: =-98+66*LOG(10*B10/(SQRT(10*(Q10/100)))) -> 48.831116 | AA10: =IF(Z10<40,1,0.75) -> 0.75 | AB10: =IF(P10/$R$4<=1,1,(P10/$R$4)^(AA10-1)) -> 1 | AC10: =IF(K10<9.15,1-0.00765*K10,1.174-0.0267*K10) -> 0.98929 | AD10: =0.65*AC10*($R$7)*(P10/Q10) -> 0.13117985 | AE10: =AD10/($R$22*AB10) -> 0.10715435 | AF10: =93*(Y10/1000)^3+0.08 -> 0.44211738 | AG10: =AF10/AE10 -> 4.1259862 | AH10: =EXP((Y10/540)+(Y10/67)^2-(Y10/80)^3+(Y10/114)^4-3) -> 0.30937378 | AI10: =AH10/AE10 -> 2.8871788 | AL10: 1.25 | AM10: -1.4 | AN10: 1.31 | AO10: 2.05 | AP10: 2.6 | AQ10: 2.95 | AR10: 3.6
A11: 1.6 | B11: 31 | C11: 36 | D11: 1.85 | E11: 0.3 | F11: 46 | G11: 34 | H11: 0.095 | K11: 1.6 | L11: =B11*100 -> 3100 | M11: =L11/C11 -> 86.111111 | N11: =18.5 -> 18.5 | O11: =N11 -> 18.5 | P11: =N11*K11 -> 29.6 | Q11: =O11*K11 -> 29.6 | R11: M | S11: =(M11/(L11-P11))*100 -> 2.8045568 | T11: =((AJ66-1.64)*0.3)+0.5 -> 0.70361466 | U11: =(($L11-$P11)/$R$4)*(($R$4/$Q11)^T11) -> 72.310583 | V11: =((3.47-LOG(U11))^2+(LOG($S11)+1.22)^2)^0.5 -> 2.3187155 | W11: =(L11/$R$4)*($R$4/Q11)^T11 -> 73.007688 | X11: =-(0.403*V11^4)+(5.581*V11^3)-(21.63*V11^2)+(33.75*V11)-17.88 -> 2.0102419 | Y11: =X11*W11 -> 146.76311 | Z11: =-98+66*LOG(10*B11/(SQRT(10*(Q11/100)))) -> 50.877245 | AA11: =IF(Z11<40,1,0.75) -> 0.75 | AB11: =IF(P11/$R$4<=1,1,(P11/$R$4)^(AA11-1)) -> 1 | AC11: =IF(K11<9.15,1-0.00765*K11,1.174-0.0267*K11) -> 0.98776 | AD11: =0.65*AC11*($R$7)*(P11/Q11) -> 0.13097698 | AE11: =AD11/($R$22*AB11) -> 0.10698863 | AF11: =93*(Y11/1000)^3+0.08 -> 0.37399076 | AG11: =AF11/AE11 -> 3.4956122 | AH11: =EXP((Y11/540)+(Y11/67)^2-(Y11/80)^3+(Y11/114)^4-3) -> 0.25737564 | AI11: =AH11/AE11 -> 2.4056354 | AL11: 1.25 | AM11: -1.6 | AN11: 1.31 | AO11: 2.05 | AP11: 2.6 | AQ11: 2.95 | AR11: 3.6
A12: 1.8 | B12: 31 | C12: 29 | D12: 0.85 | E12: 0.31 | F12: 18 | G12: 30 | H12: 0.034 | K12: 1.8 | L12: =B12*100 -> 3100 | M12: =L12/C12 -> 106.89655 | N12: =18.5 -> 18.5 | O12: =N12 -> 18.5 | P12: =N12*K12 -> 33.3 | Q12: =O12*K12 -> 33.3 | R12: (-) | S12: =(M12/(L12-P12))*100 -> 3.4857192 | T12: =((AJ67-1.64)*0.3)+0.5 -> 0.72919968 | U12: =(($L12-$P12)/$R$4)*(($R$4/$Q12)^T12) -> 68.376175 | V12: =((3.47-LOG(U12))^2+(LOG($S12)+1.22)^2)^0.5 -> 2.4039989 | W12: =(L12/$R$4)*($R$4/Q12)^T12 -> 69.118643 | X12: =-(0.403*V12^4)+(5.581*V12^3)-(21.63*V12^2)+(33.75*V12)-17.88 -> 2.3287664 | Y12: =X12*W12 -> 160.96118 | Z12: =-98+66*LOG(10*B12/(SQRT(10*(Q12/100)))) -> 49.189212 | AA12: =IF(Z12<40,1,0.75) -> 0.75 | AB12: =IF(P12/$R$4<=1,1,(P12/$R$4)^(AA12-1)) -> 1 | AC12: =IF(K12<9.15,1-0.00765*K12,1.174-0.0267*K12) -> 0.98623 | AD12: =0.65*AC12*($R$7)*(P12/Q12) -> 0.1307741 | AE12: =AD12/($R$22*AB12) -> 0.10682291 | AF12: =93*(Y12/1000)^3+0.08 -> 0.46783443 | AG12: =AF12/AE12 -> 4.3795327 | AH12: =EXP((Y12/540)+(Y12/67)^2-(Y12/80)^3+(Y12/114)^4-3) -> 0.33251373 | AI12: =AH12/AE12 -> 3.1127566 | AL12: 1.25 | AM12: -1.8 | AN12: 1.31 | AO12: 2.05 | AP12: 2.6 | AQ12: 2.95 | AR12: 3.6
A13: 2,00 | B13: 28 | C13: 38 | D13: 0.96 | E13: 0.33 | F13: 89 | G13: 41 | H13: 0.221 | K13: 2 | L13: =B13*100 -> 2800 | M13: =L13/C13 -> 73.684211 | N13: =18.5 -> 18.5 | O13: =N13 -> 18.5 | P13: =N13*K13 -> 37 | Q13: =O13*K13 -> 37 | R13: 7 | S13: =(M13/(L13-P13))*100 -> 2.6668191 | T13: =((AJ68-1.64)*0.3)+0.5 -> 0.72156791 | U13: =(($L13-$P13)/$R$4)*(($R$4/$Q13)^T13) -> 56.617758 | V13: =((3.47-LOG(U13))^2+(LOG($S13)+1.22)^2)^0.5 -> 2.3785597 | W13: =(L13/$R$4)*($R$4/Q13)^T13 -> 57.37594 | X13: =-(0.403*V13^4)+(5.581*V13^3)-(21.63*V13^2)+(33.75*V13)-17.88 -> 2.2269743 | Y13: =X13*W13 -> 127.77474 | Z13: =-98+66*LOG(10*B13/(SQRT(10*(Q13/100)))) -> 44.761773 | AA13: =IF(Z13<40,1,0.75) -> 0.75 | AB13: =IF(P13/$R$4<=1,1,(P13/$R$4)^(AA13-1)) -> 1 | AC13: =IF(K13<9.15,1-0.00765*K13,1.174-0.0267*K13) -> 0.9847 | AD13: =0.65*AC13*($R$7)*(P13/Q13) -> 0.13057122 | AE13: =AD13/($R$22*AB13) -> 0.10665719 | AF13: =93*(Y13/1000)^3+0.08 -> 0.27400727 | AG13: =AF13/AE13 -> 2.5690464 | AH13: =EXP((Y13/540)+(Y13/67)^2-(Y13/80)^3+(Y13/114)^4-3) -> 0.19738038 | AI13: =AH13/AE13 -> 1.8506055 | AL13: 1.25 | AM13: -2 | AN13: 1.31 | AO13: 2.05 | AP13: 2.6 | AQ13: 2.95 | AR13: 3.6
A14: 2.2 | B14: 35 | C14: 33 | D14: 0.87 | E14: 0.35 | F14: 22 | G14: 31 | H14: 0.041 | K14: 2.2 | L14: =B14*100 -> 3500 | M14: =L14/C14 -> 106.06061 | N14: =18.5 -> 18.5 | O14: =N14 -> 18.5 | P14: =N14*K14 -> 40.7 | Q14: =O14*K14 -> 40.7 | R14: MFS(Idriss) | S14: =(M14/(L14-P14))*100 -> 3.0659557 | T14: =((AJ69-1.64)*0.3)+0.5 -> 0.72011052 | U14: =(($L14-$P14)/$R$4)*(($R$4/$Q14)^T14) -> 66.08812 | V14: =((3.47-LOG(U14))^2+(LOG($S14)+1.22)^2)^0.5 -> 2.3737017 | W14: =(L14/$R$4)*($R$4/Q14)^T14 -> 66.865672 | X14: =-(0.403*V14^4)+(5.581*V14^3)-(21.63*V14^2)+(33.75*V14)-17.88 -> 2.2082053 | Y14: =X14*W14 -> 147.65313 | Z14: =-98+66*LOG(10*B14/(SQRT(10*(Q14/100)))) -> 49.791875 | AA14: =IF(Z14<40,1,0.75) -> 0.75 | AB14: =IF(P14/$R$4<=1,1,(P14/$R$4)^(AA14-1)) -> 1 | AC14: =IF(K14<9.15,1-0.00765*K14,1.174-0.0267*K14) -> 0.98317 | AD14: =0.65*AC14*($R$7)*(P14/Q14) -> 0.13036834 | AE14: =AD14/($R$22*AB14) -> 0.10649147 | AF14: =93*(Y14/1000)^3+0.08 -> 0.37937184 | AG14: =AF14/AE14 -> 3.5624623 | AH14: =EXP((Y14/540)+(Y14/67)^2-(Y14/80)^3+(Y14/114)^4-3) -> 0.26107036 | AI14: =AH14/AE14 -> 2.4515612 | AL14: 1.25 | AM14: -2.2 | AN14: 1.31 | AO14: 2.05 | AP14: 2.6 | AQ14: 2.95 | AR14: 3.6
A15: 2.4 | B15: 32 | C15: 48 | D15: 0.82 | E15: 0.37 | F15: -- | G15: 28 | H15: -- | K15: 2.4 | L15: =B15*100 -> 3200 | M15: =L15/C15 -> 66.666667 | N15: =18.5 -> 18.5 | O15: =N15 -> 18.5 | P15: =N15*K15 -> 44.4 | Q15: =O15*K15 -> 44.4 | R15: (-) | S15: =(M15/(L15-P15))*100 -> 2.1126463 | T15: =((AJ70-1.64)*0.3)+0.5 -> 0.70230169 | U15: =(($L15-$P15)/$R$4)*(($R$4/$Q15)^T15) -> 55.81173 | V15: =((3.47-LOG(U15))^2+(LOG($S15)+1.22)^2)^0.5 -> 2.314339 | W15: =(L15/$R$4)*($R$4/Q15)^T15 -> 56.597013 | X15: =-(0.403*V15^4)+(5.581*V15^3)-(21.63*V15^2)+(33.75*V15)-17.88 -> 1.9955982 | Y15: =X15*W15 -> 112.9449 | Z15: =-98+66*LOG(10*B15/(SQRT(10*(Q15/100)))) -> 45.976261 | AA15: =IF(Z15<40,1,0.75) -> 0.75 | AB15: =IF(P15/$R$4<=1,1,(P15/$R$4)^(AA15-1)) -> 1 | AC15: =IF(K15<9.15,1-0.00765*K15,1.174-0.0267*K15) -> 0.98164 | AD15: =0.65*AC15*($R$7)*(P15/Q15) -> 0.13016546 | AE15: =AD15/($R$22*AB15) -> 0.10632575 | AF15: =93*(Y15/1000)^3+0.08 -> 0.21399322 | AG15: =AF15/AE15 -> 2.012619 | AH15: =EXP((Y15/540)+(Y15/67)^2-(Y15/80)^3+(Y15/114)^4-3) -> 0.16535588 | AI15: =AH15/AE15 -> 1.5551819 | AL15: 1.25 | AM15: -2.4 | AN15: 1.31 | AO15: 2.05 | AP15: 2.6 | AQ15: 2.95 | AR15: 3.6
A16: 2.6 | B16: 64 | C16: 48 | D16: 0.8 | E16: 0.38 | F16: -- | G16: -- | H16: -- | K16: 2.6 | L16: =B16*100 -> 6400 | M16: =L16/C16 -> 133.33333 | N16: =18.5 -> 18.5 | O16: =N16 -> 18.5 | P16: =N16*K16 -> 48.1 | Q16: =O16*K16 -> 48.1 | R16: =(10^2.24)/($R$13^2.56) -> 1.1927489 | S16: =(M16/(L16-P16))*100 -> 2.0991095 | T16: =((AJ71-1.64)*0.3)+0.5 -> 0.64546424 | U16: =(($L16-$P16)/$R$4)*(($R$4/$Q16)^T16) -> 101.875 | V16: =((3.47-LOG(U16))^2+(LOG($S16)+1.22)^2)^0.5 -> 2.1248808 | W16: =(L16/$R$4)*($R$4/Q16)^T16 -> 102.64646 | X16: =-(0.403*V16^4)+(5.581*V16^3)-(21.63*V16^2)+(33.75*V16)-17.88 -> 1.5016466 | Y16: =X16*W16 -> 154.1387 | Z16: =-98+66*LOG(10*B16/(SQRT(10*(Q16/100)))) -> 64.697091 | AA16: =IF(Z16<40,1,0.75) -> 0.75 | AB16: =IF(P16/$R$4<=1,1,(P16/$R$4)^(AA16-1)) -> 1 | AC16: =IF(K16<9.15,1-0.00765*K16,1.174-0.0267*K16) -> 0.98011 | AD16: =0.65*AC16*($R$7)*(P16/Q16) -> 0.12996259 | AE16: =AD16/($R$22*AB16) -> 0.10616003 | AF16: =93*(Y16/1000)^3+0.08 -> 0.42057916 | AG16: =AF16/AE16 -> 3.9617469 | AH16: =EXP((Y16/540)+(Y16/67)^2-(Y16/80)^3+(Y16/114)^4-3) -> 0.29160389 | AI16: =AH16/AE16 -> 2.7468332 | AL16: 1.25 | AM16: -2.6 | AN16: 1.31 | AO16: 2.05 | AP16: 2.6 | AQ16: 2.95 | AR16: 3.6
A17: 2.8 | B17: 60 | C17: 45 | D17: 0.86 | E17: 0.4 | F17: -- | G17: -- | H17: -- | K17: 2.8 | L17: =B17*100 -> 6000 | M17: =L17/C17 -> 133.33333 | N17: =18.5 -> 18.5 | O17: =N17 -> 18.5 | P17: =N17*K17 -> 51.8 | Q17: =O17*K17 -> 51.8 | R17: MFS(A&S) | S17: =(M17/(L17-P17))*100 -> 2.2415745 | T17: =((AJ72-1.64)*0.3)+0.5 -> 0.66094566 | U17: =(($L17-$P17)/$R$4)*(($R$4/$Q17)^T17) -> 91.875152 | V17: =((3.47-LOG(U17))^2+(LOG($S17)+1.22)^2)^0.5 -> 2.1764855 | W17: =(L17/$R$4)*($R$4/Q17)^T17 -> 92.675248 | X17: =-(0.403*V17^4)+(5.581*V17^3)-(21.63*V17^2)+(33.75*V17)-17.88 -> 1.611081 | Y17: =X17*W17 -> 149.30733 | Z17: =-98+66*LOG(10*B17/(SQRT(10*(Q17/100)))) -> 61.7851 | AA17: =IF(Z17<40,1,0.75) -> 0.75 | AB17: =IF(P17/$R$4<=1,1,(P17/$R$4)^(AA17-1)) -> 1 | AC17: =IF(K17<9.15,1-0.00765*K17,1.174-0.0267*K17) -> 0.97858 | AD17: =0.65*AC17*($R$7)*(P17/Q17) -> 0.12975971 | AE17: =AD17/($R$22*AB17) -> 0.10599431 | AF17: =93*(Y17/1000)^3+0.08 -> 0.38954682 | AG17: =AF17/AE17 -> 3.6751674 | AH17: =EXP((Y17/540)+(Y17/67)^2-(Y17/80)^3+(Y17/114)^4-3) -> 0.26822929 | AI17: =AH17/AE17 -> 2.5306009 | AL17: 1.25 | AM17: -2.8 | AN17: 1.31 | AO17: 2.05 | AP17: 2.6 | AQ17: 2.95 | AR17: 3.6
A18: 3,00 | B18: 80 | C18: 46 | D18: 0.89 | E18: 0.42 | F18: 58 | G18: 36 | H18: 0.126 | K18: 3 | L18: =B18*100 -> 8000 | M18: =L18/C18 -> 173.91304 | N18: =18.5 -> 18.5 | O18: =N18 -> 18.5 | P18: =N18*K18 -> 55.5 | Q18: =O18*K18 -> 55.5 | R18: (-) | S18: =(M18/(L18-P18))*100 -> 2.1890999 | T18: =((AJ73-1.64)*0.3)+0.5 -> 0.63823729 | U18: =(($L18-$P18)/$R$4)*(($R$4/$Q18)^T18) -> 115.68268 | V18: =((3.47-LOG(U18))^2+(LOG($S18)+1.22)^2)^0.5 -> 2.100791 | W18: =(L18/$R$4)*($R$4/Q18)^T18 -> 116.49083 | X18: =-(0.403*V18^4)+(5.581*V18^3)-(21.63*V18^2)+(33.75*V18)-17.88 -> 1.4561917 | Y18: =X18*W18 -> 169.63298 | Z18: =-98+66*LOG(10*B18/(SQRT(10*(Q18/100)))) -> 69.042271 | AA18: =IF(Z18<40,1,0.75) -> 0.75 | AB18: =IF(P18/$R$4<=1,1,(P18/$R$4)^(AA18-1)) -> 1 | AC18: =IF(K18<9.15,1-0.00765*K18,1.174-0.0267*K18) -> 0.97705 | AD18: =0.65*AC18*($R$7)*(P18/Q18) -> 0.12955683 | AE18: =AD18/($R$22*AB18) -> 0.10582859 | AF18: =93*(Y18/1000)^3+0.08 -> 0.53395603 | AG18: =AF18/AE18 -> 5.0454802 | AH18: =EXP((Y18/540)+(Y18/67)^2-(Y18/80)^3+(Y18/114)^4-3) -> 0.40380853 | AI18: =AH18/AE18 -> 3.8156849 | AL18: 1.25 | AM18: -3 | AN18: 1.31 | AO18: 2.05 | AP18: 2.6 | AQ18: 2.95 | AR18: 3.6
A19: 3.2 | B19: 80 | C19: 43 | D19: 0.9 | E19: 0.43 | F19: 59 | G19: 36 | H19: 0.128 | K19: 3.2 | L19: =B19*100 -> 8000 | M19: =L19/C19 -> 186.04651 | N19: =18.5 -> 18.5 | O19: =N19 -> 18.5 | P19: =N19*K19 -> 59.2 | Q19: =O19*K19 -> 59.2 | R19: =($R$13/7.5)^(-3.3) -> 1.255679 | S19: =(M19/(L19-P19))*100 -> 2.342919 | T19: =((AJ74-1.64)*0.3)+0.5 -> 0.64800057 | U19: =(($L19-$P19)/$R$4)*(($R$4/$Q19)^T19) -> 111.53211 | V19: =((3.47-LOG(U19))^2+(LOG($S19)+1.22)^2)^0.5 -> 2.1333352 | W19: =(L19/$R$4)*($R$4/Q19)^T19 -> 112.3636 | X19: =-(0.403*V19^4)+(5.581*V19^3)-(21.63*V19^2)+(33.75*V19)-17.88 -> 1.5184234 | Y19: =X19*W19 -> 170.61552 | Z19: =-98+66*LOG(10*B19/(SQRT(10*(Q19/100)))) -> 68.117323 | AA19: =IF(Z19<40,1,0.75) -> 0.75 | AB19: =IF(P19/$R$4<=1,1,(P19/$R$4)^(AA19-1)) -> 1 | AC19: =IF(K19<9.15,1-0.00765*K19,1.174-0.0267*K19) -> 0.97552 | AD19: =0.65*AC19*($R$7)*(P19/Q19) -> 0.12935395 | AE19: =AD19/($R$22*AB19) -> 0.10566286 | AF19: =93*(Y19/1000)^3+0.08 -> 0.54189 | AG19: =AF19/AE19 -> 5.1284811 | AH19: =EXP((Y19/540)+(Y19/67)^2-(Y19/80)^3+(Y19/114)^4-3) -> 0.41371855 | AI19: =AH19/AE19 -> 3.9154584 | AL19: 1.25 | AM19: -3.2 | AN19: 1.31 | AO19: 2.05 | AP19: 2.6 | AQ19: 2.95 | AR19: 3.6
A20: 3.4 | B20: 52 | C20: 43 | D20: 0.92 | E20: 0.45 | F20: 69 | G20: 38 | H20: 0.156 | K20: 3.4 | L20: =B20*100 -> 5200 | M20: =L20/C20 -> 120.93023 | N20: =18.5 -> 18.5 | O20: =N20 -> 18.5 | P20: =N20*K20 -> 62.9 | Q20: =O20*K20 -> 62.9 | R20: MFS | S20: =(M20/(L20-P20))*100 -> 2.3540564 | T20: =((AJ75-1.64)*0.3)+0.5 -> 0.6894541 | U20: =(($L20-$P20)/$R$4)*(($R$4/$Q20)^T20) -> 70.719496 | V20: =((3.47-LOG(U20))^2+(LOG($S20)+1.22)^2)^0.5 -> 2.2715137 | W20: =(L20/$R$4)*($R$4/Q20)^T20 -> 71.585404 | X20: =-(0.403*V20^4)+(5.581*V20^3)-(21.63*V20^2)+(33.75*V20)-17.88 -> 1.8605879 | Y20: =X20*W20 -> 133.19094 | Z20: =-98+66*LOG(10*B20/(SQRT(10*(Q20/100)))) -> 54.900749 | AA20: =IF(Z20<40,1,0.75) -> 0.75 | AB20: =IF(P20/$R$4<=1,1,(P20/$R$4)^(AA20-1)) -> 1 | AC20: =IF(K20<9.15,1-0.00765*K20,1.174-0.0267*K20) -> 0.97399 | AD20: =0.65*AC20*($R$7)*(P20/Q20) -> 0.12915107 | AE20: =AD20/($R$22*AB20) -> 0.10549714 | AF20: =93*(Y20/1000)^3+0.08 -> 0.29973891 | AG20: =AF20/AE20 -> 2.8412041 | AH20: =EXP((Y20/540)+(Y20/67)^2-(Y20/80)^3+(Y20/114)^4-3) -> 0.21160498 | AI20: =AH20/AE20 -> 2.0057887 | AL20: 1.25 | AM20: -3.4 | AN20: 1.31 | AO20: 2.05 | AP20: 2.6 | AQ20: 2.95 | AR20: 3.6
A21: 3.6 | B21: 44 | C21: 37 | D21: 0.89 | E21: 0.47 | F21: 55 | G21: 36 | H21: 0.118 | K21: 3.6 | L21: =B21*100 -> 4400 | M21: =L21/C21 -> 118.91892 | N21: =18.5 -> 18.5 | O21: =N21 -> 18.5 | P21: =N21*K21 -> 66.6 | Q21: =O21*K21 -> 66.6 | R21: (-) | S21: =(M21/(L21-P21))*100 -> 2.7442405 | T21: =((AJ76-1.64)*0.3)+0.5 -> 0.72172328 | U21: =(($L21-$P21)/$R$4)*(($R$4/$Q21)^T21) -> 58.107412 | V21: =((3.47-LOG(U21))^2+(LOG($S21)+1.22)^2)^0.5 -> 2.3790776 | W21: =(L21/$R$4)*($R$4/Q21)^T21 -> 59.000465 | X21: =-(0.403*V21^4)+(5.581*V21^3)-(21.63*V21^2)+(33.75*V21)-17.88 -> 2.2289877 | Y21: =X21*W21 -> 131.51131 | Z21: =-98+66*LOG(10*B21/(SQRT(10*(Q21/100)))) -> 49.293227 | AA21: =IF(Z21<40,1,0.75) -> 0.75 | AB21: =IF(P21/$R$4<=1,1,(P21/$R$4)^(AA21-1)) -> 1 | AC21: =IF(K21<9.15,1-0.00765*K21,1.174-0.0267*K21) -> 0.97246 | AD21: =0.65*AC21*($R$7)*(P21/Q21) -> 0.1289482 | AE21: =AD21/($R$22*AB21) -> 0.10533142 | AF21: =93*(Y21/1000)^3+0.08 -> 0.29153014 | AG21: =AF21/AE21 -> 2.7677414 | AH21: =EXP((Y21/540)+(Y21/67)^2-(Y21/80)^3+(Y21/114)^4-3) -> 0.20700389 | AI21: =AH21/AE21 -> 1.9652625 | AL21: 1.25 | AM21: -3.6 | AN21: 1.31 | AO21: 2.05 | AP21: 2.6 | AQ21: 2.95 | AR21: 3.6
A22: 3.8 | B22: 29 | C22: 29 | D22: 0.88 | E22: 0.49 | F22: 50 | G22: 35 | H22: 0.105 | K22: 3.8 | L22: =B22*100 -> 2900 | M22: =L22/C22 -> 100 | N22: =18.5 -> 18.5 | O22: =N22 -> 18.5 | P22: =N22*K22 -> 70.3 | Q22: =O22*K22 -> 70.3 | R22: =(R16+R19)/2 -> 1.2242139 | S22: =(M22/(L22-P22))*100 -> 3.5339435 | T22: =((AJ77-1.64)*0.3)+0.5 -> 0.78620373 | U22: =(($L22-$P22)/$R$4)*(($R$4/$Q22)^T22) -> 37.330576 | V22: =((3.47-LOG(U22))^2+(LOG($S22)+1.22)^2)^0.5 -> 2.5940124 | W22: =(L22/$R$4)*($R$4/Q22)^T22 -> 38.258003 | X22: =-(0.403*V22^4)+(5.581*V22^3)-(21.63*V22^2)+(33.75*V22)-17.88 -> 3.2902532 | Y22: =X22*W22 -> 125.87852 | Z22: =-98+66*LOG(10*B22/(SQRT(10*(Q22/100)))) -> 36.568742 | AA22: =IF(Z22<40,1,0.75) -> 1 | AB22: =IF(P22/$R$4<=1,1,(P22/$R$4)^(AA22-1)) -> 1 | AC22: =IF(K22<9.15,1-0.00765*K22,1.174-0.0267*K22) -> 0.97093 | AD22: =0.65*AC22*($R$7)*(P22/Q22) -> 0.12874532 | AE22: =AD22/($R$22*AB22) -> 0.1051657 | AF22: =93*(Y22/1000)^3+0.08 -> 0.26549738 | AG22: =AF22/AE22 -> 2.5245625 | AH22: =EXP((Y22/540)+(Y22/67)^2-(Y22/80)^3+(Y22/114)^4-3) -> 0.19278463 | AI22: =AH22/AE22 -> 1.8331512 | AL22: 1.25 | AM22: -3.8 | AN22: 1.31 | AO22: 2.05 | AP22: 2.6 | AQ22: 2.95 | AR22: 3.6
A23: 4,00 | B23: 29 | C23: 48 | D23: 0.89 | E23: 0.51 | F23: 54 | G23: 36 | H23: 0.115 | K23: 4 | L23: =B23*100 -> 2900 | M23: =L23/C23 -> 60.416667 | N23: =18.5 -> 18.5 | O23: =N23 -> 18.5 | P23: =N23*K23 -> 74 | Q23: =O23*K23 -> 74 | R23: MFS | S23: =(M23/(L23-P23))*100 -> 2.1378863 | T23: =((AJ78-1.64)*0.3)+0.5 -> 0.74848958 | U23: =(($L23-$P23)/$R$4)*(($R$4/$Q23)^T23) -> 35.403879 | V23: =((3.47-LOG(U23))^2+(LOG($S23)+1.22)^2)^0.5 -> 2.4682986 | W23: =(L23/$R$4)*($R$4/Q23)^T23 -> 36.330945 | X23: =-(0.403*V23^4)+(5.581*V23^3)-(21.63*V23^2)+(33.75*V23)-17.88 -> 2.6132379 | Y23: =X23*W23 -> 94.941401 | Z23: =-98+66*LOG(10*B23/(SQRT(10*(Q23/100)))) -> 35.833621 | AA23: =IF(Z23<40,1,0.75) -> 1 | AB23: =IF(P23/$R$4<=1,1,(P23/$R$4)^(AA23-1)) -> 1 | AC23: =IF(K23<9.15,1-0.00765*K23,1.174-0.0267*K23) -> 0.9694 | AD23: =0.65*AC23*($R$7)*(P23/Q23) -> 0.12854244 | AE23: =AD23/($R$22*AB23) -> 0.10499998 | AF23: =93*(Y23/1000)^3+0.08 -> 0.15958841 | AG23: =AF23/AE23 -> 1.51989 | AH23: =EXP((Y23/540)+(Y23/67)^2-(Y23/80)^3+(Y23/114)^4-3) -> 0.13444617 | AI23: =AH23/AE23 -> 1.2804399 | AL23: 1.25 | AM23: -4 | AN23: 1.31 | AO23: 2.05 | AP23: 2.6 | AQ23: 2.95 | AR23: 3.6
A24: 4.2 | B24: 35 | C24: 44 | D24: 0.86 | E24: 0.52 | F24: 36 | G24: 33 | H24: 0.07 | K24: 4.2 | L24: =B24*100 -> 3500 | M24: =L24/C24 -> 79.545455 | N24: =18.5 -> 18.5 | O24: =N24 -> 18.5 | P24: =N24*K24 -> 77.7 | Q24: =O24*K24 -> 77.7 | R24: (-) | S24: =(M24/(L24-P24))*100 -> 2.3243273 | T24: =((AJ79-1.64)*0.3)+0.5 -> 0.7401353 | U24: =(($L24-$P24)/$R$4)*(($R$4/$Q24)^T24) -> 41.249753 | V24: =((3.47-LOG(U24))^2+(LOG($S24)+1.22)^2)^0.5 -> 2.440451 | W24: =(L24/$R$4)*($R$4/Q24)^T24 -> 42.186288 | X24: =-(0.403*V24^4)+(5.581*V24^3)-(21.63*V24^2)+(33.75*V24)-17.88 -> 2.4851485 | Y24: =X24*W24 -> 104.83919 | Z24: =-98+66*LOG(10*B24/(SQRT(10*(Q24/100)))) -> 40.524597 | AA24: =IF(Z24<40,1,0.75) -> 0.75 | AB24: =IF(P24/$R$4<=1,1,(P24/$R$4)^(AA24-1)) -> 1 | AC24: =IF(K24<9.15,1-0.00765*K24,1.174-0.0267*K24) -> 0.96787 | AD24: =0.65*AC24*($R$7)*(P24/Q24) -> 0.12833956 | AE24: =AD24/($R$22*AB24) -> 0.10483426 | AF24: =93*(Y24/1000)^3+0.08 -> 0.18716524 | AG24: =AF24/AE24 -> 1.7853442 | AH24: =EXP((Y24/540)+(Y24/67)^2-(Y24/80)^3+(Y24/114)^4-3) -> 0.15066412 | AI24: =AH24/AE24 -> 1.437165 | AL24: 1.25 | AM24: -4.2 | AN24: 1.31 | AO24: 2.05 | AP24: 2.6 | AQ24: 2.95 | AR24: 3.6
A25: 4.4 | B25: 31 | C25: 58 | D25: 0.87 | E25: 0.54 | F25: 41 | G25: 34 | H25: 0.081 | K25: 4.4 | L25: =B25*100 -> 3100 | M25: =L25/C25 -> 53.448276 | N25: =18.5 -> 18.5 | O25: =N25 -> 18.5 | P25: =N25*K25 -> 81.4 | Q25: =O25*K25 -> 81.4 | R25: =6.9*EXP(-R13/4)-0.058 -> 1.1410402 | S25: =(M25/(L25-P25))*100 -> 1.7706313 | T25: =((AJ80-1.64)*0.3)+0.5 -> 0.73418553 | U25: =(($L25-$P25)/$R$4)*(($R$4/$Q25)^T25) -> 35.109435 | V25: =((3.47-LOG(U25))^2+(LOG($S25)+1.22)^2)^0.5 -> 2.4206184 | W25: =(L25/$R$4)*($R$4/Q25)^T25 -> 36.056201 | X25: =-(0.403*V25^4)+(5.581*V25^3)-(21.63*V25^2)+(33.75*V25)-17.88 -> 2.3985045 | Y25: =X25*W25 -> 86.480958 | Z25: =-98+66*LOG(10*B25/(SQRT(10*(Q25/100)))) -> 36.379266 | AA25: =IF(Z25<40,1,0.75) -> 1 | AB25: =IF(P25/$R$4<=1,1,(P25/$R$4)^(AA25-1)) -> 1 | AC25: =IF(K25<9.15,1-0.00765*K25,1.174-0.0267*K25) -> 0.96634 | AD25: =0.65*AC25*($R$7)*(P25/Q25) -> 0.12813668 | AE25: =AD25/($R$22*AB25) -> 0.10466854 | AF25: =93*(Y25/1000)^3+0.08 -> 0.14015122 | AG25: =AF25/AE25 -> 1.3390004 | AH25: =EXP((Y25/540)+(Y25/67)^2-(Y25/80)^3+(Y25/114)^4-3) -> 0.12174034 | AI25: =AH25/AE25 -> 1.1631035 | AL25: 1.25 | AM25: -4.4 | AN25: 1.31 | AO25: 2.05 | AP25: 2.6 | AQ25: 2.95 | AR25: 3.6
A26: 4.6 | B26: 28 | C26: 42 | D26: 0.87 | E26: 0.56 | F26: 41 | G26: 34 | H26: 0.083 | K26: 4.6 | L26: =B26*100 -> 2800 | M26: =L26/C26 -> 66.666667 | N26: =18.5 -> 18.5 | O26: =N26 -> 18.5 | P26: =N26*K26 -> 85.1 | Q26: =O26*K26 -> 85.1 | S26: =(M26/(L26-P26))*100 -> 2.4555846 | T26: =((AJ81-1.64)*0.3)+0.5 -> 0.77408426 | U26: =(($L26-$P26)/$R$4)*(($R$4/$Q26)^T26) -> 30.760562 | V26: =((3.47-LOG(U26))^2+(LOG($S26)+1.22)^2)^0.5 -> 2.5536142 | W26: =(L26/$R$4)*($R$4/Q26)^T26 -> 31.724768 | X26: =-(0.403*V26^4)+(5.581*V26^3)-(21.63*V26^2)+(33.75*V26)-17.88 -> 3.0544631 | Y26: =X26*W26 -> 96.902132 | Z26: =-98+66*LOG(10*B26/(SQRT(10*(Q26/100)))) -> 32.824755 | AA26: =IF(Z26<40,1,0.75) -> 1 | AB26: =IF(P26/$R$4<=1,1,(P26/$R$4)^(AA26-1)) -> 1 | AC26: =IF(K26<9.15,1-0.00765*K26,1.174-0.0267*K26) -> 0.96481 | AD26: =0.65*AC26*($R$7)*(P26/Q26) -> 0.12793381 | AE26: =AD26/($R$22*AB26) -> 0.10450282 | AF26: =93*(Y26/1000)^3+0.08 -> 0.16462193 | AG26: =AF26/AE26 -> 1.5752871 | AH26: =EXP((Y26/540)+(Y26/67)^2-(Y26/80)^3+(Y26/114)^4-3) -> 0.13753337 | AI26: =AH26/AE26 -> 1.3160733 | AL26: 1.25 | AM26: -4.6 | AN26: 1.31 | AO26: 2.05 | AP26: 2.6 | AQ26: 2.95 | AR26: 3.6
A27: 4.8 | B27: 31 | C27: 77 | D27: 0.87 | E27: 0.58 | F27: 42 | G27: 34 | H27: 0.084 | K27: 4.8 | L27: =B27*100 -> 3100 | M27: =L27/C27 -> 40.25974 | N27: =18.5 -> 18.5 | O27: =N27 -> 18.5 | P27: =N27*K27 -> 88.8 | Q27: =O27*K27 -> 88.8 | S27: =(M27/(L27-P27))*100 -> 1.3369999 | T27: =((AJ82-1.64)*0.3)+0.5 -> 0.7198711 | U27: =(($L27-$P27)/$R$4)*(($R$4/$Q27)^T27) -> 32.800134 | V27: =((3.47-LOG(U27))^2+(LOG($S27)+1.22)^2)^0.5 -> 2.3729037 | W27: =(L27/$R$4)*($R$4/Q27)^T27 -> 33.767407 | X27: =-(0.403*V27^4)+(5.581*V27^3)-(21.63*V27^2)+(33.75*V27)-17.88 -> 2.2051422 | Y27: =X27*W27 -> 74.461935 | Z27: =-98+66*LOG(10*B27/(SQRT(10*(Q27/100)))) -> 35.132244 | AA27: =IF(Z27<40,1,0.75) -> 1 | AB27: =IF(P27/$R$4<=1,1,(P27/$R$4)^(AA27-1)) -> 1 | AC27: =IF(K27<9.15,1-0.00765*K27,1.174-0.0267*K27) -> 0.96328 | AD27: =0.65*AC27*($R$7)*(P27/Q27) -> 0.12773093 | AE27: =AD27/($R$22*AB27) -> 0.1043371 | AF27: =93*(Y27/1000)^3+0.08 -> 0.11839599 | AG27: =AF27/AE27 -> 1.1347449 | AH27: =EXP((Y27/540)+(Y27/67)^2-(Y27/80)^3+(Y27/114)^4-3) -> 0.10526151 | AI27: =AH27/AE27 -> 1.0088599 | AL27: 1.25 | AM27: -4.8 | AN27: 1.31 | AO27: 2.05 | AP27: 2.6 | AQ27: 2.95 | AR27: 3.6
A28: 5,00 | B28: 48 | C28: 55 | D28: 0.95 | E28: 0.59 | F28: 38 | G28: 33 | H28: 0.076 | K28: 5 | L28: =B28*100 -> 4800 | M28: =L28/C28 -> 87.272727 | N28: =18.5 -> 18.5 | O28: =N28 -> 18.5 | P28: =N28*K28 -> 92.5 | Q28: =O28*K28 -> 92.5 | S28: =(M28/(L28-P28))*100 -> 1.8539082 | T28: =((AJ83-1.64)*0.3)+0.5 -> 0.70251383 | U28: =(($L28-$P28)/$R$4)*(($R$4/$Q28)^T28) -> 49.725165 | V28: =((3.47-LOG(U28))^2+(LOG($S28)+1.22)^2)^0.5 -> 2.3150461 | W28: =(L28/$R$4)*($R$4/Q28)^T28 -> 50.702239 | X28: =-(0.403*V28^4)+(5.581*V28^3)-(21.63*V28^2)+(33.75*V28)-17.88 -> 1.9979534 | Y28: =X28*W28 -> 101.30071 | Z28: =-98+66*LOG(10*B28/(SQRT(10*(Q28/100)))) -> 47.079244 | AA28: =IF(Z28<40,1,0.75) -> 0.75 | AB28: =IF(P28/$R$4<=1,1,(P28/$R$4)^(AA28-1)) -> 1 | AC28: =IF(K28<9.15,1-0.00765*K28,1.174-0.0267*K28) -> 0.96175 | AD28: =0.65*AC28*($R$7)*(P28/Q28) -> 0.12752805 | AE28: =AD28/($R$22*AB28) -> 0.10417137 | AF28: =93*(Y28/1000)^3+0.08 -> 0.17667639 | AG28: =AF28/AE28 -> 1.6960166 | AH28: =EXP((Y28/540)+(Y28/67)^2-(Y28/80)^3+(Y28/114)^4-3) -> 0.14467678 | AI28: =AH28/AE28 -> 1.3888343 | AL28: 1.25 | AM28: -5 | AN28: 1.31 | AO28: 2.05 | AP28: 2.6 | AQ28: 2.95 | AR28: 3.6
A29: 5.2 | B29: 43 | C29: 64 | D29: 0.9 | E29: 0.61 | F29: 51 | G29: 35 | H29: 0.106 | K29: 5.2 | L29: =B29*100 -> 4300 | M29: =L29/C29 -> 67.1875 | N29: =18.5 -> 18.5 | O29: =N29 -> 18.5 | P29: =N29*K29 -> 96.2 | Q29: =O29*K29 -> 96.2 | S29: =(M29/(L29-P29))*100 -> 1.5982563 | T29: =((AJ84-1.64)*0.3)+0.5 -> 0.70463132 | U29: =(($L29-$P29)/$R$4)*(($R$4/$Q29)^T29) -> 43.20136 | V29: =((3.47-LOG(U29))^2+(LOG($S29)+1.22)^2)^0.5 -> 2.3221044 | W29: =(L29/$R$4)*($R$4/Q29)^T29 -> 44.189982 | X29: =-(0.403*V29^4)+(5.581*V29^3)-(21.63*V29^2)+(33.75*V29)-17.88 -> 2.021691 | Y29: =X29*W29 -> 89.338491 | Z29: =-98+66*LOG(10*B29/(SQRT(10*(Q29/100)))) -> 43.364141 | AA29: =IF(Z29<40,1,0.75) -> 0.75 | AB29: =IF(P29/$R$4<=1,1,(P29/$R$4)^(AA29-1)) -> 1 | AC29: =IF(K29<9.15,1-0.00765*K29,1.174-0.0267*K29) -> 0.96022 | AD29: =0.65*AC29*($R$7)*(P29/Q29) -> 0.12732517 | AE29: =AD29/($R$22*AB29) -> 0.10400565 | AF29: =93*(Y29/1000)^3+0.08 -> 0.14631302 | AG29: =AF29/AE29 -> 1.4067795 | AH29: =EXP((Y29/540)+(Y29/67)^2-(Y29/80)^3+(Y29/114)^4-3) -> 0.1259249 | AI29: =AH29/AE29 -> 1.2107505 | AL29: 1.25 | AM29: -5.2 | AN29: 1.31 | AO29: 2.05 | AP29: 2.6 | AQ29: 2.95 | AR29: 3.6
A30: 5.4 | B30: 48 | C30: 60 | D30: 0.91 | E30: 0.63 | F30: 58 | G30: 36 | H30: 0.125 | K30: 5.4 | L30: =B30*100 -> 4800 | M30: =L30/C30 -> 80 | N30: =18.5 -> 18.5 | O30: =N30 -> 18.5 | P30: =N30*K30 -> 99.9 | Q30: =O30*K30 -> 99.9 | S30: =(M30/(L30-P30))*100 -> 1.7020914 | T30: =((AJ85-1.64)*0.3)+0.5 -> 0.70103734 | U30: =(($L30-$P30)/$R$4)*(($R$4/$Q30)^T30) -> 47.033978 | V30: =((3.47-LOG(U30))^2+(LOG($S30)+1.22)^2)^0.5 -> 2.3101245 | W30: =(L30/$R$4)*($R$4/Q30)^T30 -> 48.033678 | X30: =-(0.403*V30^4)+(5.581*V30^3)-(21.63*V30^2)+(33.75*V30)-17.88 -> 1.9816477 | Y30: =X30*W30 -> 95.18583 | Z30: =-98+66*LOG(10*B30/(SQRT(10*(Q30/100)))) -> 45.976261 | AA30: =IF(Z30<40,1,0.75) -> 0.75 | AB30: =IF(P30/$R$4<=1,1,(P30/$R$4)^(AA30-1)) -> 1 | AC30: =IF(K30<9.15,1-0.00765*K30,1.174-0.0267*K30) -> 0.95869 | AD30: =0.65*AC30*($R$7)*(P30/Q30) -> 0.12712229 | AE30: =AD30/($R$22*AB30) -> 0.10383993 | AF30: =93*(Y30/1000)^3+0.08 -> 0.16020471 | AG30: =AF30/AE30 -> 1.5428044 | AH30: =EXP((Y30/540)+(Y30/67)^2-(Y30/80)^3+(Y30/114)^4-3) -> 0.13482792 | AI30: =AH30/AE30 -> 1.2984208 | AL30: 1.25 | AM30: -5.4 | AN30: 1.31 | AO30: 2.05 | AP30: 2.6 | AQ30: 2.95 | AR30: 3.6
A31: 5.6 | B31: 52 | C31: 49 | D31: 0.9 | E31: 0.65 | F31: 53 | G31: 35 | H31: 0.111 | K31: 5.6 | L31: =B31*100 -> 5200 | M31: =L31/C31 -> 106.12245 | N31: =18.5 -> 18.5 | O31: =N31 -> 18.5 | P31: =N31*K31 -> 103.6 | Q31: =O31*K31 -> 103.6 | S31: =(M31/(L31-P31))*100 -> 2.0823022 | T31: =((AJ86-1.64)*0.3)+0.5 -> 0.71239675 | U31: =(($L31-$P31)/$R$4)*(($R$4/$Q31)^T31) -> 49.695981 | V31: =((3.47-LOG(U31))^2+(LOG($S31)+1.22)^2)^0.5 -> 2.3479892 | W31: =(L31/$R$4)*($R$4/Q31)^T31 -> 50.706205 | X31: =-(0.403*V31^4)+(5.581*V31^3)-(21.63*V31^2)+(33.75*V31)-17.88 -> 2.1123634 | Y31: =X31*W31 -> 107.10993 | Z31: =-98+66*LOG(10*B31/(SQRT(10*(Q31/100)))) -> 47.749349 | AA31: =IF(Z31<40,1,0.75) -> 0.75 | AB31: =IF(P31/$R$4<=1,1,(P31/$R$4)^(AA31-1)) -> 0.99119719 | AC31: =IF(K31<9.15,1-0.00765*K31,1.174-0.0267*K31) -> 0.95716 | AD31: =0.65*AC31*($R$7)*(P31/Q31) -> 0.12691942 | AE31: =AD31/($R$22*AB31) -> 0.10459494 | AF31: =93*(Y31/1000)^3+0.08 -> 0.1942805 | AG31: =AF31/AE31 -> 1.857456 | AH31: =EXP((Y31/540)+(Y31/67)^2-(Y31/80)^3+(Y31/114)^4-3) -> 0.15463283 | AI31: =AH31/AE31 -> 1.4783969 | AL31: 1.25 | AM31: -5.6 | AN31: 1.31 | AO31: 2.05 | AP31: 2.6 | AQ31: 2.95 | AR31: 3.6
A32: 5.8 | B32: 38 | C32: 71 | D32: 0.88 | E32: 0.67 | F32: 41 | G32: 34 | H32: 0.081 | K32: 5.8 | L32: =B32*100 -> 3800 | M32: =L32/C32 -> 53.521127 | N32: =18.5 -> 18.5 | O32: =N32 -> 18.5 | P32: =N32*K32 -> 107.3 | Q32: =O32*K32 -> 107.3 | S32: =(M32/(L32-P32))*100 -> 1.4493765 | T32: =((AJ87-1.64)*0.3)+0.5 -> 0.71868536 | U32: =(($L32-$P32)/$R$4)*(($R$4/$Q32)^T32) -> 35.103664 | V32: =((3.47-LOG(U32))^2+(LOG($S32)+1.22)^2)^0.5 -> 2.3689512 | W32: =(L32/$R$4)*($R$4/Q32)^T32 -> 36.123683 | X32: =-(0.403*V32^4)+(5.581*V32^3)-(21.63*V32^2)+(33.75*V32)-17.88 -> 2.1900563 | Y32: =X32*W32 -> 79.112902 | Z32: =-98+66*LOG(10*B32/(SQRT(10*(Q32/100)))) -> 38.255927 | AA32: =IF(Z32<40,1,0.75) -> 1 | AB32: =IF(P32/$R$4<=1,1,(P32/$R$4)^(AA32-1)) -> 1 | AC32: =IF(K32<9.15,1-0.00765*K32,1.174-0.0267*K32) -> 0.95563 | AD32: =0.65*AC32*($R$7)*(P32/Q32) -> 0.12671654 | AE32: =AD32/($R$22*AB32) -> 0.10350849 | AF32: =93*(Y32/1000)^3+0.08 -> 0.1260495 | AG32: =AF32/AE32 -> 1.2177696 | AH32: =EXP((Y32/540)+(Y32/67)^2-(Y32/80)^3+(Y32/114)^4-3) -> 0.11142595 | AI32: =AH32/AE32 -> 1.0764909 | AL32: 1.25 | AM32: -5.8 | AN32: 1.31 | AO32: 2.05 | AP32: 2.6 | AQ32: 2.95 | AR32: 3.6
A33: 6,00 | B33: 49 | C33: 82 | D33: 0.88 | E33: 0.68 | F33: 42 | G33: 34 | H33: 0.085 | K33: 6 | L33: =B33*100 -> 4900 | M33: =L33/C33 -> 59.756098 | N33: =18.5 -> 18.5 | O33: =N33 -> 18.5 | P33: =N33*K33 -> 111 | Q33: =O33*K33 -> 111 | S33: =(M33/(L33-P33))*100 -> 1.2477782 | T33: =((AJ88-1.64)*0.3)+0.5 -> 0.68196821 | U33: =(($L33-$P33)/$R$4)*(($R$4/$Q33)^T33) -> 44.600118 | V33: =((3.47-LOG(U33))^2+(LOG($S33)+1.22)^2)^0.5 -> 2.2465607 | W33: =(L33/$R$4)*($R$4/Q33)^T33 -> 45.633865 | X33: =-(0.403*V33^4)+(5.581*V33^3)-(21.63*V33^2)+(33.75*V33)-17.88 -> 1.788618 | Y33: =X33*W33 -> 81.621553 | Z33: =-98+66*LOG(10*B33/(SQRT(10*(Q33/100)))) -> 45.057283 | AA33: =IF(Z33<40,1,0.75) -> 0.75 | AB33: =IF(P33/$R$4<=1,1,(P33/$R$4)^(AA33-1)) -> 0.9742474 | AC33: =IF(K33<9.15,1-0.00765*K33,1.174-0.0267*K33) -> 0.9541 | AD33: =0.65*AC33*($R$7)*(P33/Q33) -> 0.12651366 | AE33: =AD33/($R$22*AB33) -> 0.10607446 | AF33: =93*(Y33/1000)^3+0.08 -> 0.13057053 | AG33: =AF33/AE33 -> 1.2309328 | AH33: =EXP((Y33/540)+(Y33/67)^2-(Y33/80)^3+(Y33/114)^4-3) -> 0.114862 | AI33: =AH33/AE33 -> 1.0828431 | AL33: 1.25 | AM33: -6 | AN33: 1.31 | AO33: 2.05 | AP33: 2.6 | AQ33: 2.95 | AR33: 3.6
A34: 6.2 | B34: 55 | C34: 46 | D34: 0.89 | E34: 0.7 | F34: 46 | G34: 35 | H34: 0.095 | K34: 6.2 | L34: =B34*100 -> 5500 | M34: =L34/C34 -> 119.56522 | N34: =18.5 -> 18.5 | O34: =N34 -> 18.5 | P34: =N34*K34 -> 114.7 | Q34: =O34*K34 -> 114.7 | S34: =(M34/(L34-P34))*100 -> 2.2202146 | T34: =((AJ89-1.64)*0.3)+0.5 -> 0.71969568 | U34: =(($L34-$P34)/$R$4)*(($R$4/$Q34)^T34) -> 48.791297 | V34: =((3.47-LOG(U34))^2+(LOG($S34)+1.22)^2)^0.5 -> 2.3723189 | W34: =(L34/$R$4)*($R$4/Q34)^T34 -> 49.83049 | X34: =-(0.403*V34^4)+(5.581*V34^3)-(21.63*V34^2)+(33.75*V34)-17.88 -> 2.2029016 | Y34: =X34*W34 -> 109.77167 | Z34: =-98+66*LOG(10*B34/(SQRT(10*(Q34/100)))) -> 47.898345 | AA34: =IF(Z34<40,1,0.75) -> 0.75 | AB34: =IF(P34/$R$4<=1,1,(P34/$R$4)^(AA34-1)) -> 0.96629369 | AC34: =IF(K34<9.15,1-0.00765*K34,1.174-0.0267*K34) -> 0.95257 | AD34: =0.65*AC34*($R$7)*(P34/Q34) -> 0.12631078 | AE34: =AD34/($R$22*AB34) -> 0.10677608 | AF34: =93*(Y34/1000)^3+0.08 -> 0.20301376 | AG34: =AF34/AE34 -> 1.9013038 | AH34: =EXP((Y34/540)+(Y34/67)^2-(Y34/80)^3+(Y34/114)^4-3) -> 0.15942447 | AI34: =AH34/AE34 -> 1.493073 | AL34: 1.25 | AM34: -6.2 | AN34: 1.31 | AO34: 2.05 | AP34: 2.6 | AQ34: 2.95 | AR34: 3.6
A35: 6.4 | B35: 50 | C35: 37 | D35: 0.9 | E35: 0.72 | F35: 49 | G35: 35 | H35: 0.102 | K35: 6.4 | L35: =B35*100 -> 5000 | M35: =L35/C35 -> 135.13514 | N35: =18.5 -> 18.5 | O35: =N35 -> 18.5 | P35: =N35*K35 -> 118.4 | Q35: =O35*K35 -> 118.4 | S35: =(M35/(L35-P35))*100 -> 2.768255 | T35: =((AJ90-1.64)*0.3)+0.5 -> 0.75111544 | U35: =(($L35-$P35)/$R$4)*(($R$4/$Q35)^T35) -> 42.999816 | V35: =((3.47-LOG(U35))^2+(LOG($S35)+1.22)^2)^0.5 -> 2.4770515 | W35: =(L35/$R$4)*($R$4/Q35)^T35 -> 44.042748 | X35: =-(0.403*V35^4)+(5.581*V35^3)-(21.63*V35^2)+(33.75*V35)-17.88 -> 2.6550789 | Y35: =X35*W35 -> 116.93697 | Z35: =-98+66*LOG(10*B35/(SQRT(10*(Q35/100)))) -> 44.711414 | AA35: =IF(Z35<40,1,0.75) -> 0.75 | AB35: =IF(P35/$R$4<=1,1,(P35/$R$4)^(AA35-1)) -> 0.95865441 | AC35: =IF(K35<9.15,1-0.00765*K35,1.174-0.0267*K35) -> 0.95104 | AD35: =0.65*AC35*($R$7)*(P35/Q35) -> 0.1261079 | AE35: =AD35/($R$22*AB35) -> 0.10745408 | AF35: =93*(Y35/1000)^3+0.08 -> 0.22870942 | AG35: =AF35/AE35 -> 2.1284387 | AH35: =EXP((Y35/540)+(Y35/67)^2-(Y35/80)^3+(Y35/114)^4-3) -> 0.17320572 | AI35: =AH35/AE35 -> 1.6119045 | AL35: 1.25 | AM35: -6.4 | AN35: 1.31 | AO35: 2.05 | AP35: 2.6 | AQ35: 2.95 | AR35: 3.6
