Workbook

Sheet CPT1
A1: prf | B1: LP | C1: LL | D1: Rp | E1: RL | F1: Rp/Rl | G1: prf | H1: LP | I1: LL | J1: Rp | K1: RL | L1: Rp/Rl
A2: m | B2: - | C2: - | D2: Kg/cm² | E2: Kg/cm² | F2: - | G2: m | H2: - | I2: - | J2: Kg/cm² | K2: Kg/cm² | L2: -
A3: 0.2 | B3: 8 | C3: ---- | D3: 16 | E3: ------ | F3: ---- | G3: 5 | H3: 13 | I3: 18 | J3: 26 | K3: 1.07 | L3: 24
A4: 0.4 | B4: 13 | C4: ---- | D4: 26 | E4: 1 | F4: 26 | G4: 5.2 | H4: 19 | I4: 27 | J4: 38 | K4: 0.67 | L4: 57
A5: 0.6 | B5: 15 | C5: 22.5 | D5: 30 | E5: 0.67 | F5: 45 | G5: 5.4 | H5: 24 | I5: 29 | J5: 48 | K5: 0.8 | L5: 60
A6: 0.8 | B6: 12.5 | C6: 17.5 | D6: 25 | E6: 0.73 | F6: 34 | G6: 5.6 | H6: 21 | I6: 27 | J6: 42 | K6: 1 | L6: 42
A7: 1 | B7: 8.5 | C7: 14 | D7: 17 | E7: 0.53 | F7: 32 | G7: 5.8 | H7: 15 | I7: 22.5 | J7: 30 | K7: 0.53 | L7: 56
A8: 1.2 | B8: 6 | C8: 10 | D8: 12 | E8: 0.53 | F8: 22 | G8: 6 | H8: 16 | I8: 20 | J8: 32 | K8: 0.6 | L8: 53
A9: 1.4 | B9: 12 | C9: 16 | D9: 24 | E9: 0.53 | F9: 45 | G9: 6.2 | H9: 18.5 | I9: 23 | J9: 37 | K9: 1 | L9: 37
A10: 1.6 | B10: 10 | C10: 14 | D10: 20 | E10: 0.33 | F10: 60 | G10: 6.4 | H10: 20.5 | I10: 28 | J10: 41 | K10: 0.73 | L10: 56
A11: 1.8 | B11: 4.5 | C11: 7 | D11: 9 | E11: 0.27 | F11: 34 | G11: 6.6 | H11: 16.5 | I11: 22 | J11: 33 | K11: 0.73 | L11: 45
A12: 2 | B12: 38 | C12: 40 | D12: 76 | E12: 0.73 | F12: 104 | G12: 6.8 | H12: 13 | I12: 18.5 | J12: 26 | K12: 0.4 | L12: 65
A13: 2.2 | B13: 5.5 | C13: 11 | D13: 11 | E13: 0.13 | F13: 82 | G13: 7 | H13: 10 | I13: 13 | J13: 20 | K13: 0.8 | L13: 25
A14: 2.4 | B14: 3 | C14: 4 | D14: 6 | E14: 0.07 | F14: 90 | G14: 7.2 | H14: 5 | I14: 11 | J14: 10 | K14: 0.4 | L14: 25
A15: 2.6 | B15: 2.5 | C15: 3 | D15: 5 | E15: 0.27 | F15: 19 | G15: 7.4 | H15: 20 | I15: 23 | J15: 40 | K15: 0.87 | L15: 46
A16: 2.8 | B16: 4 | C16: 6 | D16: 8 | E16: 0.6 | F16: 13 | G16: 7.6 | H16: 17.5 | I16: 24 | J16: 35 | K16: 0.67 | L16: 52
... A25: 4.6 | B25: 13.5 | C25: 18 | D25: 27 | E25: 0.6 | F25: 45 | G25: 9.4 | H25: 34 | I25: 45 | J25: 68 | K25: 1.6 | L25: 42
A26: 4.8 | B26: 14 | C26: 18.5 | D26: 28 | E26: 0.67 | F26: 42 | G26: 9.6 | H26: 36 | I26: 48 | J26: 72 | K26: ----- | L26: ----

Sheet CPT2
A1: prf | B1: LP | D1: LL | E1: Rp | F1: RL | G1: Rp/Rl | H1: prf | I1: LP | J1: LL | K1: Rp | L1: RL | M1: Rp/Rl
A2: m | B2: - | D2: - | E2: Kg/cm² | F2: Kg/cm² | G2: - | H2: m | I2: - | J2: - | K2: Kg/cm² | L2: Kg/cm² | M2: -
A3: 0.2 | B3: 3.5 | D3: ---- | E3: 7 | F3: ------ | G3: ---- | H3: 5.2 | I3: 21.5 | J3: 28 | K3: 43 | L3: 0.67 | M3: 64
A4: 0.4 | B4: 7 | D4: ---- | E4: 14 | F4: 0.4 | G4: 35 | H4: 5.4 | I4: 24 | J4: 29 | K4: 48 | L4: 0.8 | M4: 60
A5: 0.6 | B5: 12 | D5: 15 | E5: 24 | F5: 0.6 | G5: 40 | H5: 5.6 | I5: 26 | J5: 32 | K5: 52 | L5: 1.07 | M5: 49
A6: 0.8 | B6: 25 | D6: 29.5 | E6: 50 | F6: 0.8 | G6: 62 | H6: 5.8 | I6: 19 | J6: 27 | K6: 38 | L6: 0.53 | M6: 71
A7: 1 | B7: 20 | D7: 26 | E7: 40 | F7: 1.07 | G7: 37 | H7: 6 | I7: 24.5 | J7: 28.5 | K7: 49 | L7: 0.6 | M7: 82
A8: 1.2 | B8: 12 | D8: 20 | E8: 24 | F8: 0.87 | G8: 28 | H8: 6.2 | I8: 27.5 | J8: 32 | K8: 55 | L8: 1.2 | M8: 46
A9: 1.4 | B9: 13.5 | D9: 20 | E9: 27 | F9: 0.87 | G9: 31 | H9: 6.4 | I9: 25 | J9: 34 | K9: 50 | L9: 1.33 | M9: 37
A10: 1.6 | B10: 15.5 | D10: 22 | E10: 31 | F10: 0.87 | G10: 36 | H10: 6.6 | I10: 25 | J10: 35 | K10: 50 | L10: 0.8 | M10: 62
A11: 1.8 | B11: 15.5 | D11: 22 | E11: 31 | F11: 1.07 | G11: 29 | H11: 6.8 | I11: 30 | J11: 36 | K11: 60 | L11: 1 | M11: 60
A12: 2 | B12: 14 | D12: 22 | E12: 28 | F12: 0.73 | G12: 38 | H12: 7 | I12: 20.5 | J12: 28 | K12: 41 | L12: 0.47 | M12: 88
A13: 2.2 | B13: 17.5 | D13: 23 | E13: 35 | F13: 1.07 | G13: 33 | H13: 7.2 | I13: 26.5 | J13: 30 | K13: 53 | L13: 1.07 | M13: 50
A14: 2.4 | B14: 16 | D14: 24 | E14: 32 | F14: 0.67 | G14: 48 | H14: 7.4 | I14: 16 | J14: 24 | K14: 32 | L14: 1 | M14: 32
A15: 2.6 | B15: 32 | D15: 37 | E15: 64 | F15: 1.33 | G15: 48 | H15: 7.6 | I15: 21.5 | J15: 29 | K15: 43 | L15: 1.07 | M15: 40
A16: 2.8 | B16: 30 | D16: 40 | E16: 60 | F16: 1.33 | G16: 45 | H16: 7.8 | I16: 19.5 | J16: 27.5 | K16: 39 | L16: 0.73 | M16: 53
... A26: 4.8 | B26: 15.5 | D26: 20.5 | E26: 31 | F26: 0.4 | G26: 77 | H26: 9.8 | I26: 34 | J26: 45 | K26: 68 | L26: 1.6 | M26: 42
A27: 5 | B27: 24 | D27: 27 | E27: 48 | F27: 0.87 | G27: 55 | H27: 10 | I27: 30 | J27: 42 | K27: 60 | L27: ----- | M27: ----

Sheet CPT1_1
A1: NATURA COESIVA | N1: NATURA GRANULARE
A2: Prof. Rp Rp/Rl | D2: Natura Y' p'vo Cu OCR | J2: Eu50 Eu25 | L2: Mo | M2: Dr | N2: ø1s | O2: ø2s | P2: ø3s | Q2: ø4s | R2: ødm | T2: ømy | U2: Amax/g | V2: E'50 E'25 Mo
A3: m kg/cm² (-) | D3: Litol. t/m³ kg/cm² kg/cm² (-) | J3: kg/cm² | L3: kg/cm² | M3: % | N3: (°) | O3: (°) | P3: (°) | Q3: (°) | R3: (°) | T3: (°) | U3: (-) | V3: kg/cm² kg/cm²
A4: 0.2 | B4: 16 | C4: -- | D4: 4/:/: | E4: 1.85 | F4: 0.04 | G4: 0.7 | I4: 99.9 | J4: 118 | K4: 177 | L4: 52 | M4: 89 | N4: 41 | O4: 42 | P4: 44 | Q4: 45 | R4: 43 | T4: 27 | U4: 0.221 | V4: 27 | W4: 40 | X4: 48
A5: 0.4 | B5: 26 | C5: 26 | D5: 4/:/: | E5: 1.85 | F5: 0.07 | G5: 0.93 | I5: 99.9 | J5: 158 | K5: 237 | L5: 78 | M5: 89 | N5: 40 | O5: 42 | P5: 44 | Q5: 45 | R5: 42 | T5: 28 | U5: 0.22 | V5: 43 | W5: 65 | X5: 78
A6: 0.6 | B6: 30 | C6: 45 | D6: 3:::: | E6: 1.85 | F6: 0.11 | G6: -- | I6: -- | J6: -- | K6: -- | L6: -- | M6: 84 | N6: 40 | O6: 41 | P6: 43 | Q6: 45 | R6: 41 | T6: 29 | U6: 0.204 | V6: 50 | W6: 75 | X6: 90
A7: 0.8 | B7: 25 | C7: 34 | D7: 3:::: | E7: 1.85 | F7: 0.15 | G7: -- | I7: -- | J7: -- | K7: -- | L7: -- | M7: 71 | N7: 38 | O7: 40 | P7: 42 | Q7: 44 | R7: 39 | T7: 28 | U7: 0.162 | V7: 42 | W7: 63 | X7: 75
A8: 1,00 | B8: 17 | C8: 32 | D8: 4/:/: | E8: 1.85 | F8: 0.19 | G8: 0.72 | I8: 34.5 | J8: 123 | K8: 184 | L8: 54 | M8: 52 | N8: 35 | O8: 38 | P8: 40 | Q8: 42 | R8: 37 | T8: 27 | U8: 0.11 | V8: 28 | W8: 43 | X8: 51
A9: 1.2 | B9: 12 | C9: 22 | D9: 2//// | E9: 1.85 | F9: 0.22 | G9: 0.57 | I9: 20.5 | J9: 97 | K9: 146 | L9: 45 | M9: -- | N9: 0 | O9: 0 | P9: 0 | Q9: 0 | R9: 0 | T9: 0 | U9: -- | V9: -- | W9: -- | X9: --
A10: 1.4 | B10: 24 | C10: 45 | D10: 3:::: | E10: 1.85 | F10: 0.26 | G10: -- | I10: -- | J10: -- | K10: -- | L10: -- | M10: 56 | N10: 36 | O10: 38 | P10: 40 | Q10: 42 | R10: 37 | T10: 28 | U10: 0.119 | V10: 40 | W10: 60 | X10: 72
A11: 1.6 | B11: 20 | C11: 60 | D11: 4/:/: | E11: 1.85 | F11: 0.3 | G11: 0.8 | I11: 21.8 | J11: 136 | K11: 204 | L11: 60 | M11: 46 | N11: 34 | O11: 37 | P11: 39 | Q11: 42 | R11: 35 | T11: 27 | U11: 0.095 | V11: 33 | W11: 50 | X11: 60
A12: 1.8 | B12: 9 | C12: 34 | D12: 4/:/: | E12: 0.85 | F12: 0.31 | G12: 0.45 | I12: 9.9 | J12: 77 | K12: 115 | L12: 38 | M12: 18 | N12: 30 | O12: 33 | P12: 36 | Q12: 39 | R12: 30 | T12: 26 | U12: 0.034 | V12: 15 | W12: 23 | X12: 27
A13: 2,00 | B13: 76 | C13: 104 | D13: 3:::: | E13: 0.96 | F13: 0.33 | G13: -- | I13: -- | J13: -- | K13: -- | L13: -- | M13: 89 | N13: 41 | O13: 42 | P13: 44 | Q13: 45 | R13: 41 | T13: 33 | U13: 0.221 | V13: 127 | W13: 190 | X13: 228
A14: 2.2 | B14: 11 | C14: 82 | D14: 4/:/: | E14: 0.87 | F14: 0.35 | G14: 0.54 | I14: 10.7 | J14: 91 | K14: 137 | L14: 42 | M14: 22 | N14: 31 | O14: 34 | P14: 37 | Q14: 40 | R14: 31 | T14: 26 | U14: 0.041 | V14: 18 | W14: 28 | X14: 33
A15: 2.4 | B15: 6 | C15: 90 | D15: 4/:/: | E15: 0.82 | F15: 0.37 | G15: 0.3 | I15: 4.9 | J15: 101 | K15: 152 | L15: 29 | M15: -- | N15: 28 | O15: 31 | P15: 35 | Q15: 38 | R15: 27 | T15: 26 | U15: -- | V15: 10 | W15: 15 | X15: 18
A16: 2.6 | B16: 5 | C16: 19 | D16: 2//// | E16: 0.8 | F16: 0.38 | G16: 0.25 | I16: 3.7 | J16: 108 | K16: 162 | L16: 25 | M16: -- | N16: 0 | O16: 0 | P16: 0 | Q16: 0 | R16: 0 | T16: 0 | U16: -- | V16: -- | W16: -- | X16: --
A17: 2.8 | B17: 8 | C17: 13 | D17: 2//// | E17: 0.86 | F17: 0.4 | G17: 0.4 | I17: 6.3 | J17: 104 | K17: 156 | L17: 35 | M17: -- | N17: 0 | O17: 0 | P17: 0 | Q17: 0 | R17: 0 | T17: 0 | U17: -- | V17: -- | W17: -- | X17: --
A18: 3,00 | B18: 36 | C18: 34 | D18: 3:::: | E18: 0.89 | F18: 0.42 | G18: -- | I18: -- | J18: -- | K18: -- | L18: -- | M18: 58 | N18: 36 | O18: 38 | P18: 40 | Q18: 43 | R18: 36 | T18: 30 | U18: 0.126 | V18: 60 | W18: 90 | X18: 108
A19: 3.2 | B19: 38 | C19: 71 | D19: 3:::: | E19: 0.9 | F19: 0.43 | G19: -- | I19: -- | J19: -- | K19: -- | L19: -- | M19: 59 | N19: 36 | O19: 38 | P19: 40 | Q19: 43 | R19: 36 | T19: 30 | U19: 0.128 | V19: 63 | W19: 95 | X19: 114
A20: 3.4 | B20: 52 | C20: 32 | D20: 3:::: | E20: 0.92 | F20: 0.45 | G20: -- | I20: -- | J20: -- | K20: -- | L20: -- | M20: 69 | N20: 38 | O20: 40 | P20: 41 | Q20: 44 | R20: 38 | T20: 31 | U20: 0.156 | V20: 87 | W20: 130 | X20: 156
A21: 3.6 | B21: 36 | C21: 39 | D21: 3:::: | E21: 0.89 | F21: 0.47 | G21: -- | I21: -- | J21: -- | K21: -- | L21: -- | M21: 55 | N21: 36 | O21: 38 | P21: 40 | Q21: 42 | R21: 35 | T21: 30 | U21: 0.118 | V21: 60 | W21: 90 | X21: 108
A22: 3.8 | B22: 32 | C22: 37 | D22: 3:::: | E22: 0.88 | F22: 0.49 | G22: -- | I22: -- | J22: -- | K22: -- | L22: -- | M22: 50 | N22: 35 | O22: 37 | P22: 40 | Q22: 42 | R22: 35 | T22: 29 | U22: 0.105 | V22: 53 | W22: 80 | X22: 96
A23: 4,00 | B23: 37 | C23: 40 | D23: 3:::: | E23: 0.89 | F23: 0.51 | G23: -- | I23: -- | J23: -- | K23: -- | L23: -- | M23: 54 | N23: 36 | O23: 38 | P23: 40 | Q23: 42 | R23: 35 | T23: 30 | U23: 0.115 | V23: 62 | W23: 93 | X23: 111
A24: 4.2 | B24: 22 | C24: 33 | D24: 3:::: | E24: 0.86 | F24: 0.52 | G24: -- | I24: -- | J24: -- | K24: -- | L24: -- | M24: 36 | N24: 33 | O24: 36 | P24: 38 | Q24: 41 | R24: 32 | T24: 28 | U24: 0.07 | V24: 37 | W24: 55 | X24: 66
A25: 4.4 | B25: 26 | C25: 43 | D25: 3:::: | E25: 0.87 | F25: 0.54 | G25: -- | I25: -- | J25: -- | K25: -- | L25: -- | M25: 41 | N25: 34 | O25: 36 | P25: 39 | Q25: 41 | R25: 33 | T25: 28 | U25: 0.081 | V25: 43 | W25: 65 | X25: 78
A26: 4.6 | B26: 27 | C26: 45 | D26: 3:::: | E26: 0.87 | F26: 0.56 | G26: -- | I26: -- | J26: -- | K26: -- | L26: -- | M26: 41 | N26: 34 | O26: 36 | P26: 39 | Q26: 41 | R26: 33 | T26: 28 | U26: 0.083 | V26: 45 | W26: 68 | X26: 81
A27: 4.8 | B27: 28 | C27: 42 | D27: 3:::: | E27: 0.87 | F27: 0.58 | G27: -- | I27: -- | J27: -- | K27: -- | L27: -- | M27: 42 | N27: 34 | O27: 36 | P27: 39 | Q27: 41 | R27: 33 | T27: 28 | U27: 0.084 | V27: 47 | W27: 70 | X27: 84
A28: 5,00 | B28: 26 | C28: 24 | D28: 4/:/: | E28: 0.95 | F28: 0.59 | G28: 0.93 | I28: 11 | J28: 158 | K28: 237 | L28: 78 | M28: 38 | N28: 33 | O28: 36 | P28: 38 | Q28: 41 | R28: 32 | T28: 28 | U28: 0.076 | V28: 43 | W28: 65 | X28: 78
A29: 5.2 | B29: 38 | C29: 57 | D29: 3:::: | E29: 0.9 | F29: 0.61 | G29: -- | I29: -- | J29: -- | K29: -- | L29: -- | M29: 51 | N29: 35 | O29: 37 | P29: 40 | Q29: 42 | R29: 34 | T29: 30 | U29: 0.106 | V29: 63 | W29: 95 | X29: 114
A30: 5.4 | B30: 48 | C30: 60 | D30: 3:::: | E30: 0.91 | F30: 0.63 | G30: -- | I30: -- | J30: -- | K30: -- | L30: -- | M30: 58 | N30: 36 | O30: 38 | P30: 40 | Q30: 43 | R30: 35 | T30: 31 | U30: 0.125 | V30: 80 | W30: 120 | X30: 144
A31: 5.6 | B31: 42 | C31: 42 | D31: 3:::: | E31: 0.9 | F31: 0.65 | G31: -- | I31: -- | J31: -- | K31: -- | L31: -- | M31: 53 | N31: 35 | O31: 38 | P31: 40 | Q31: 42 | R31: 35 | T31: 30 | U31: 0.111 | V31: 70 | W31: 105 | X31: 126
A32: 5.8 | B32: 30 | C32: 56 | D32: 3:::: | E32: 0.88 | F32: 0.67 | G32: -- | I32: -- | J32: -- | K32: -- | L32: -- | M32: 41 | N32: 34 | O32: 36 | P32: 39 | Q32: 41 | R32: 33 | T32: 29 | U32: 0.081 | V32: 50 | W32: 75 | X32: 90
A33: 6,00 | B33: 32 | C33: 53 | D33: 3:::: | E33: 0.88 | F33: 0.68 | G33: -- | I33: -- | J33: -- | K33: -- | L33: -- | M33: 42 | N33: 34 | O33: 36 | P33: 39 | Q33: 41 | R33: 33 | T33: 29 | U33: 0.085 | V33: 53 | W33: 80 | X33: 96
A34: 6.2 | B34: 37 | C34: 37 | D34: 3:::: | E34: 0.89 | F34: 0.7 | G34: -- | I34: -- | J34: -- | K34: -- | L34: -- | M34: 46 | N34: 35 | O34: 37 | P34: 39 | Q34: 42 | R34: 33 | T34: 30 | U34: 0.095 | V34: 62 | W34: 93 | X34: 111
A35: 6.4 | B35: 41 | C35: 56 | D35: 3:::: | E35: 0.9 | F35: 0.72 | G35: -- | I35: -- | J35: -- | K35: -- | L35: -- | M35: 49 | N35: 35 | O35: 37 | P35: 39 | Q35: 42 | R35: 34 | T35: 30 | U35: 0.102 | V35: 68 | W35: 103 | X35: 123
A36: 6.6 | B36: 33 | C36: 45 | D36: 3:::: | E36: 0.88 | F36: 0.74 | G36: -- | I36: -- | J36: -- | K36: -- | L36: -- | M36: 41 | N36: 34 | O36: 36 | P36: 39 | Q36: 41 | R36: 32 | T36: 29 | U36: 0.083 | V36: 55 | W36: 83 | X36: 99
A37: 6.8 | B37: 26 | C37: 65 | D37: 3:::: | E37: 0.87 | F37: 0.75 | G37: -- | I37: -- | J37: -- | K37: -- | L37: -- | M37: 33 | N37: 33 | O37: 35 | P37: 38 | Q37: 41 | R37: 31 | T37: 28 | U37: 0.063 | V37: 43 | W37: 65 | X37: 78
A38: 7,00 | B38: 20 | C38: 25 | D38: 4/:/: | E38: 0.93 | F38: 0.77 | G38: 0.8 | I38: 6.6 | J38: 199 | K38: 298 | L38: 60 | M38: 23 | N38: 31 | O38: 34 | P38: 37 | Q38: 40 | R38: 29 | T38: 27 | U38: 0.044 | V38: 33 | W38: 50 | X38: 60
A39: 7.2 | B39: 10 | C39: 25 | D39: 2//// | E39: 0.9 | F39: 0.79 | G39: 0.5 | I39: 3.5 | J39: 223 | K39: 335 | L39: 40 | M39: -- | N39: 0 | O39: 0 | P39: 0 | Q39: 0 | R39: 0 | T39: 0 | U39: -- | V39: -- | W39: -- | X39: --
A40: 7.4 | B40: 40 | C40: 46 | D40: 3:::: | E40: 0.9 | F40: 0.81 | G40: -- | I40: -- | J40: -- | K40: -- | L40: -- | M40: 46 | N40: 34 | O40: 37 | P40: 39 | Q40: 42 | R40: 33 | T40: 30 | U40: 0.093 | V40: 67 | W40: 100 | X40: 120
...

Sheet CPT2_2
A1: NATURA COESIVA | H1: NATURA GRANULARE
A2: Prof. Rp Rp/Rl | D2: Natura Y' p'vo Cu OCR | J2: Eu50 Eu25 | L2: Mo | M2: Dr | N2: ø1s | O2: ø2s | P2: ø3s | Q2: ø4s | R2: ødm | T2: ømy | U2: Amax/g | V2: E'50 E'25 Mo
A3: m kg/cm² (-) | D3: Litol. t/m³ kg/cm² kg/cm² (-) | J3: kg/cm² | L3: kg/cm² | M3: % | N3: (°) | O3: (°) | P3: (°) | Q3: (°) | R3: (°) | T3: (°) | U3: (-) | V3: kg/cm² kg/cm²
A4: 0,20 7 -- | D4: 2//// 1,85 0,04 0,35 99,9 | J4: 59 89 | L4: 32 | M4: -- | N4: -- | O4: -- | P4: -- | Q4: -- | R4: -- | T4: -- | U4: -- | V4: -- -- --
A5: 0.4 | B5: 14 | C5: 35 | D5: 4/:/: | E5: 1.85 | F5: 0.07 | G5: 0.64 | I5: 92.5 | J5: 108 | K5: 162 | L5: 48 | M5: 68 | N5: 38 | O5: 39 | P5: 41 | Q5: 43 | R5: 40 | T5: 26 | U5: 0.153 | V5: 23 | W5: 35 | X5: 42
A6: 0.6 | B6: 24 | C6: 40 | D6: 3:::: | E6: 1.85 | F6: 0.11 | G6: -- | I6: -- | J6: -- | K6: -- | L6: -- | M6: 77 | N6: 39 | O6: 40 | P6: 42 | Q6: 44 | R6: 40 | T6: 28 | U6: 0.179 | V6: 40 | W6: 60 | X6: 72
A7: 0.8 | B7: 50 | C7: 62 | D7: 3:::: | E7: 1.85 | F7: 0.15 | G7: -- | I7: -- | J7: -- | K7: -- | L7: -- | M7: 95 | N7: 41 | O7: 43 | P7: 44 | Q7: 46 | R7: 42 | T7: 31 | U7: 0.24 | V7: 83 | W7: 125 | X7: 150
A8: 1,00 | B8: 40 | C8: 37 | D8: 3:::: | E8: 1.85 | F8: 0.19 | G8: -- | I8: -- | J8: -- | K8: -- | L8: -- | M8: 82 | N8: 39 | O8: 41 | P8: 43 | Q8: 45 | R8: 40 | T8: 30 | U8: 0.195 | V8: 67 | W8: 100 | X8: 120
A9: 1.2 | B9: 24 | C9: 28 | D9: 4/:/: | E9: 1.85 | F9: 0.22 | G9: 0.89 | I9: 35.6 | J9: 151 | K9: 227 | L9: 72 | M9: 60 | N9: 36 | O9: 38 | P9: 41 | Q9: 43 | R9: 37 | T9: 28 | U9: 0.13 | V9: 40 | W9: 60 | X9: 72
A10: 1.4 | B10: 27 | C10: 31 | D10: 3:::: | E10: 1.85 | F10: 0.26 | G10: -- | I10: -- | J10: -- | K10: -- | L10: -- | M10: 60 | N10: 36 | O10: 38 | P10: 41 | Q10: 43 | R10: 37 | T10: 28 | U10: 0.13 | V10: 45 | W10: 68 | X10: 81
A11: 1.6 | B11: 31 | C11: 36 | D11: 3:::: | E11: 1.85 | F11: 0.3 | G11: -- | I11: -- | J11: -- | K11: -- | L11: -- | M11: 61 | N11: 37 | O11: 39 | P11: 41 | Q11: 43 | R11: 37 | T11: 29 | U11: 0.134 | V11: 52 | W11: 78 | X11: 93
A12: 1.8 | B12: 31 | C12: 29 | D12: 4/:/: | E12: 1.85 | F12: 0.33 | G12: 1.03 | I12: 25.9 | J12: 176 | K12: 264 | L12: 93 | M12: 59 | N12: 36 | O12: 38 | P12: 40 | Q12: 43 | R12: 37 | T12: 29 | U12: 0.127 | V12: 52 | W12: 78 | X12: 93
A13: 2,00 | B13: 28 | C13: 38 | D13: 3:::: | E13: 1.85 | F13: 0.37 | G13: -- | I13: -- | J13: -- | K13: -- | L13: -- | M13: 52 | N13: 35 | O13: 38 | P13: 40 | Q13: 42 | R13: 35 | T13: 28 | U13: 0.11 | V13: 47 | W13: 70 | X13: 84
A14: 2.2 | B14: 35 | C14: 33 | D14: 3:::: | E14: 1.85 | F14: 0.41 | G14: -- | I14: -- | J14: -- | K14: -- | L14: -- | M14: 58 | N14: 36 | O14: 38 | P14: 40 | Q14: 43 | R14: 36 | T14: 29 | U14: 0.125 | V14: 58 | W14: 88 | X14: 105
A15: 2.4 | B15: 32 | C15: 48 | D15: 3:::: | E15: 1.85 | F15: 0.44 | G15: -- | I15: -- | J15: -- | K15: -- | L15: -- | M15: 53 | N15: 35 | O15: 38 | P15: 40 | Q15: 42 | R15: 35 | T15: 29 | U15: 0.111 | V15: 53 | W15: 80 | X15: 96
A16: 2.6 | B16: 64 | C16: 48 | D16: 3:::: | E16: 1.85 | F16: 0.48 | G16: -- | I16: -- | J16: -- | K16: -- | L16: -- | M16: 75 | N16: 38 | O16: 40 | P16: 42 | Q16: 44 | R16: 38 | T16: 32 | U16: 0.173 | V16: 107 | W16: 160 | X16: 192
A17: 2.8 | B17: 60 | C17: 45 | D17: 3:::: | E17: 1.85 | F17: 0.52 | G17: -- | I17: -- | J17: -- | K17: -- | L17: -- | M17: 70 | N17: 38 | O17: 40 | P17: 42 | Q17: 44 | R17: 38 | T17: 32 | U17: 0.161 | V17: 100 | W17: 150 | X17: 180
A18: 3,00 | B18: 80 | C18: 46 | D18: 3:::: | E18: 1.85 | F18: 0.55 | G18: -- | I18: -- | J18: -- | K18: -- | L18: -- | M18: 79 | N18: 39 | O18: 41 | P18: 42 | Q18: 44 | R18: 39 | T18: 33 | U18: 0.186 | V18: 133 | W18: 200 | X18: 240
A19: 3.2 | B19: 80 | C19: 43 | D19: 3:::: | E19: 1.85 | F19: 0.59 | G19: -- | I19: -- | J19: -- | K19: -- | L19: -- | M19: 77 | N19: 39 | O19: 41 | P19: 42 | Q19: 44 | R19: 38 | T19: 33 | U19: 0.181 | V19: 133 | W19: 200 | X19: 240
A20: 3.4 | B20: 52 | C20: 43 | D20: 3:::: | E20: 1.85 | F20: 0.63 | G20: -- | I20: -- | J20: -- | K20: -- | L20: -- | M20: 61 | N20: 37 | O20: 39 | P20: 41 | Q20: 43 | R20: 36 | T20: 31 | U20: 0.133 | V20: 87 | W20: 130 | X20: 156
A21: 3.6 | B21: 44 | C21: 37 | D21: 3:::: | E21: 1.85 | F21: 0.67 | G21: -- | I21: -- | J21: -- | K21: -- | L21: -- | M21: 54 | N21: 36 | O21: 38 | P21: 40 | Q21: 42 | R21: 35 | T21: 31 | U21: 0.113 | V21: 73 | W21: 110 | X21: 132
A22: 3.8 | B22: 29 | C22: 29 | D22: 4/:/: | E22: 1.85 | F22: 0.7 | G22: 0.98 | I22: 9.5 | J22: 169 | K22: 254 | L22: 87 | M22: 38 | N22: 33 | O22: 36 | P22: 38 | Q22: 41 | R22: 32 | T22: 29 | U22: 0.075 | V22: 48 | W22: 73 | X22: 87
A23: 4,00 | B23: 29 | C23: 48 | D23: 3:::: | E23: 1.85 | F23: 0.74 | G23: -- | I23: -- | J23: -- | K23: -- | L23: -- | M23: 37 | N23: 33 | O23: 36 | P23: 38 | Q23: 41 | R23: 32 | T23: 29 | U23: 0.072 | V23: 48 | W23: 73 | X23: 87
A24: 4.2 | B24: 35 | C24: 44 | D24: 3:::: | E24: 1.85 | F24: 0.78 | G24: -- | I24: -- | J24: -- | K24: -- | L24: -- | M24: 42 | N24: 34 | O24: 36 | P24: 39 | Q24: 41 | R24: 33 | T24: 29 | U24: 0.085 | V24: 58 | W24: 88 | X24: 105
A25: 4.4 | B25: 31 | C25: 58 | D25: 3:::: | E25: 1.85 | F25: 0.81 | G25: -- | I25: -- | J25: -- | K25: -- | L25: -- | M25: 37 | N25: 33 | O25: 36 | P25: 38 | Q25: 41 | R25: 32 | T25: 29 | U25: 0.072 | V25: 52 | W25: 78 | X25: 93
A26: 4.6 | B26: 28 | C26: 42 | D26: 3:::: | E26: 1.85 | F26: 0.85 | G26: -- | I26: -- | J26: -- | K26: -- | L26: -- | M26: 32 | N26: 33 | O26: 35 | P26: 38 | Q26: 41 | R26: 31 | T26: 28 | U26: 0.062 | V26: 47 | W26: 70 | X26: 84
A27: 4.8 | B27: 31 | C27: 77 | D27: 3:::: | E27: 1.85 | F27: 0.89 | G27: -- | I27: -- | J27: -- | K27: -- | L27: -- | M27: 35 | N27: 33 | O27: 35 | P27: 38 | Q27: 41 | R27: 31 | T27: 29 | U27: 0.068 | V27: 52 | W27: 78 | X27: 93
A28: 5,00 | B28: 48 | C28: 55 | D28: 3:::: | E28: 1.85 | F28: 0.93 | G28: -- | I28: -- | J28: -- | K28: -- | L28: -- | M28: 49 | N28: 35 | O28: 37 | P28: 39 | Q28: 42 | R28: 33 | T28: 31 | U28: 0.101 | V28: 80 | W28: 120 | X28: 144
A29: 5.2 | B29: 43 | C29: 64 | D29: 3:::: | E29: 1.85 | F29: 0.96 | G29: -- | I29: -- | J29: -- | K29: -- | L29: -- | M29: 44 | N29: 34 | O29: 37 | P29: 39 | Q29: 42 | R29: 32 | T29: 30 | U29: 0.089 | V29: 72 | W29: 108 | X29: 129
A30: 5.4 | B30: 48 | C30: 60 | D30: 3:::: | E30: 1.85 | F30: 1 | G30: -- | I30: -- | J30: -- | K30: -- | L30: -- | M30: 47 | N30: 35 | O30: 37 | P30: 39 | Q30: 42 | R30: 33 | T30: 31 | U30: 0.096 | V30: 80 | W30: 120 | X30: 144
A31: 5.6 | B31: 52 | C31: 49 | D31: 3:::: | E31: 1.85 | F31: 1.04 | G31: -- | I31: -- | J31: -- | K31: -- | L31: -- | M31: 49 | N31: 35 | O31: 37 | P31: 39 | Q31: 42 | R31: 33 | T31: 31 | U31: 0.101 | V31: 87 | W31: 130 | X31: 156
A32: 5.8 | B32: 38 | C32: 71 | D32: 3:::: | E32: 1.85 | F32: 1.07 | G32: -- | I32: -- | J32: -- | K32: -- | L32: -- | M32: 37 | N32: 33 | O32: 36 | P32: 38 | Q32: 41 | R32: 31 | T32: 30 | U32: 0.073 | V32: 63 | W32: 95 | X32: 114
A33: 6,00 | B33: 49 | C33: 82 | D33: 3:::: | E33: 1.85 | F33: 1.11 | G33: -- | I33: -- | J33: -- | K33: -- | L33: -- | M33: 45 | N33: 34 | O33: 37 | P33: 39 | Q33: 42 | R33: 32 | T33: 31 | U33: 0.091 | V33: 82 | W33: 123 | X33: 147
A34: 6.2 | B34: 55 | C34: 46 | D34: 3:::: | E34: 1.85 | F34: 1.15 | G34: -- | I34: -- | J34: -- | K34: -- | L34: -- | M34: 48 | N34: 35 | O34: 37 | P34: 39 | Q34: 42 | R34: 33 | T34: 31 | U34: 0.099 | V34: 92 | W34: 138 | X34: 165
A35: 6.4 | B35: 50 | C35: 37 | D35: 3:::: | E35: 1.85 | F35: 1.18 | G35: -- | I35: -- | J35: -- | K35: -- | L35: -- | M35: 44 | N35: 34 | O35: 37 | P35: 39 | Q35: 42 | R35: 32 | T35: 31 | U35: 0.089 | V35: 83 | W35: 125 | X35: 150
A36: 6.6 | B36: 50 | C36: 62 | D36: 3:::: | E36: 1.85 | F36: 1.22 | G36: -- | I36: -- | J36: -- | K36: -- | L36: -- | M36: 43 | N36: 34 | O36: 36 | P36: 39 | Q36: 41 | R36: 32 | T36: 31 | U36: 0.088 | V36: 83 | W36: 125 | X36: 150
A37: 6.8 | B37: 60 | C37: 60 | D37: 3:::: | E37: 1.85 | F37: 1.26 | G37: -- | I37: -- | J37: -- | K37: -- | L37: -- | M37: 49 | N37: 35 | O37: 37 | P37: 39 | Q37: 42 | R37: 33 | T37: 32 | U37: 0.101 | V37: 100 | W37: 150 | X37: 180
A38: 7,00 | B38: 41 | C38: 88 | D38: 3:::: | E38: 1.85 | F38: 1.3 | G38: -- | I38: -- | J38: -- | K38: -- | L38: -- | M38: 35 | N38: 33 | O38: 35 | P38: 38 | Q38: 41 | R38: 31 | T38: 30 | U38: 0.069 | V38: 68 | W38: 103 | X38: 123
A39: 7.2 | B39: 53 | C39: 50 | D39: 3:::: | E39: 1.85 | F39: 1.33 | G39: -- | I39: -- | J39: -- | K39: -- | L39: -- | M39: 43 | N39: 34 | O39: 36 | P39: 39 | Q39: 41 | R39: 32 | T39: 31 | U39: 0.087 | V39: 88 | W39: 133 | X39: 159
A40: 7.4 | B40: 32 | C40: 32 | D40: 3:::: | E40: 1.85 | F40: 1.37 | G40: -- | I40: -- | J40: -- | K40: -- | L40: -- | M40: 25 | N40: 32 | O40: 34 | P40: 37 | Q40: 40 | R40: 29 | T40: 29 | U40: 0.048 | V40: 53 | W40: 80 | X40: 96
...

Sheet Vs30
C2: Spessore h [m] | D2: Velocità onde SH [m/s] | E2: hi/Vi [s]
B3: sismostrato 1 | C3: 2.8 | D3: 142 | E3: =C3/D3 -> 0.01971831
B4: sismostrato 2 | C4: 6.3 | D4: 184 | E4: =C4/D4 -> 0.03423913
B5: sismostrato 3 | C5: 6.1 | D5: 172 | E5: =C5/D5 -> 0.035465116
B6: sismostrato 4 | C6: =30-(C5+C4+C3) -> 14.8 | D6: 269 | E6: =C6/D6 -> 0.055018587
C9: ∑ hi/Vi [s] | D9: VS30 [m/s]
C10: =SUM(E3:E6) -> 0.14444114 | D10: =30/C10 -> 207.69705 | E10: terreno C
A15: profondità | B15: gamma saturo CPT 1 | C15: gamma saturo CPT 2 | D15: acc. Gravità | E15: rho CPT 1 | F15: rho CPT 2 | G15: G CPT1 | H15: G CPT2
A16: =CPT2_2!A4 -> 0,20 7 -- | B16: =CPT1_1!E4 -> 1.85 | C16: =CPT2_2!E5 -> 1.85 | D16: =9.81 -> 9.81 | E16: =B16/$D$16 -> 0.18858308 | F16: =C16/$D$16 -> 0.18858308 | G16: =E16*$D$3^2 -> 3802.5892 | H16: =F16*$D$3^2 -> 3802.5892
A17: =CPT2_2!A5 -> 0.4 | B17: =CPT1_1!E5 -> 1.85 | C17: =CPT2_2!E5 -> 1.85 | E17: =B17/$D$16 -> 0.18858308 | F17: =C17/$D$16 -> 0.18858308 | G17: =E17*$D$3^2 -> 3802.5892 | H17: =F17*$D$3^2 -> 3802.5892
A18: =CPT2_2!A6 -> 0.6 | B18: =CPT1_1!E6 -> 1.85 | C18: =CPT2_2!E6 -> 1.85 | E18: =B18/$D$16 -> 0.18858308 | F18: =C18/$D$16 -> 0.18858308 | G18: =E18*$D$3^2 -> 3802.5892 | H18: =F18*$D$3^2 -> 3802.5892
A19: =CPT2_2!A7 -> 0.8 | B19: =CPT1_1!E7 -> 1.85 | C19: =CPT2_2!E7 -> 1.85 | E19: =B19/$D$16 -> 0.18858308 | F19: =C19/$D$16 -> 0.18858308 | G19: =E19*$D$3^2 -> 3802.5892 | H19: =F19*$D$3^2 -> 3802.5892
A20: =CPT2_2!A8 -> 1,00 | B20: =CPT1_1!E8 -> 1.85 | C20: =CPT2_2!E8 -> 1.85 | E20: =B20/$D$16 -> 0.18858308 | F20: =C20/$D$16 -> 0.18858308 | G20: =E20*$D$3^2 -> 3802.5892 | H20: =F20*$D$3^2 -> 3802.5892
A21: =CPT2_2!A9 -> 1.2 | B21: =CPT1_1!E9 -> 1.85 | C21: =CPT2_2!E9 -> 1.85 | E21: =B21/$D$16 -> 0.18858308 | F21: =C21/$D$16 -> 0.18858308 | G21: =E21*$D$3^2 -> 3802.5892 | H21: =F21*$D$3^2 -> 3802.5892
A22: =CPT2_2!A10 -> 1.4 | B22: =CPT1_1!E10 -> 1.85 | C22: =CPT2_2!E10 -> 1.85 | E22: =B22/$D$16 -> 0.18858308 | F22: =C22/$D$16 -> 0.18858308 | G22: =E22*$D$3^2 -> 3802.5892 | H22: =F22*$D$3^2 -> 3802.5892
A23: =CPT2_2!A11 -> 1.6 | B23: =CPT1_1!E11 -> 1.85 | C23: =CPT2_2!E11 -> 1.85 | E23: =B23/$D$16 -> 0.18858308 | F23: =C23/$D$16 -> 0.18858308 | G23: =E23*$D$3^2 -> 3802.5892 | H23: =F23*$D$3^2 -> 3802.5892
A24: =CPT2_2!A12 -> 1.8 | B24: =CPT1_1!E12 -> 0.85 | C24: =CPT2_2!E12 -> 1.85 | E24: =B24/$D$16 -> 0.086646279 | F24: =C24/$D$16 -> 0.18858308 | G24: =E24*$D$3^2 -> 1747.1356 | H24: =F24*$D$3^2 -> 3802.5892
A25: =CPT2_2!A13 -> 2,00 | B25: =CPT1_1!E13 -> 0.96 | C25: =CPT2_2!E13 -> 1.85 | E25: =B25/$D$16 -> 0.097859327 | F25: =C25/$D$16 -> 0.18858308 | G25: =E25*$D$3^2 -> 1973.2355 | H25: =F25*$D$3^2 -> 3802.5892
A26: =CPT2_2!A14 -> 2.2 | B26: =CPT1_1!E14 -> 0.87 | C26: =CPT2_2!E14 -> 1.85 | E26: =B26/$D$16 -> 0.088685015 | F26: =C26/$D$16 -> 0.18858308 | G26: =E26*$D$3^2 -> 1788.2446 | H26: =F26*$D$3^2 -> 3802.5892
A27: =CPT2_2!A15 -> 2.4 | B27: =CPT1_1!E15 -> 0.82 | C27: =CPT2_2!E15 -> 1.85 | E27: =B27/$D$16 -> 0.083588175 | F27: =C27/$D$16 -> 0.18858308 | G27: =E27*$D$3^2 -> 1685.472 | H27: =F27*$D$3^2 -> 3802.5892
A28: =CPT2_2!A16 -> 2.6 | B28: =CPT1_1!E16 -> 0.8 | C28: =CPT2_2!E16 -> 1.85 | E28: =B28/$D$16 -> 0.081549439 | F28: =C28/$D$16 -> 0.18858308 | G28: =E28*$D$3^2 -> 1644.3629 | H28: =F28*$D$3^2 -> 3802.5892
A29: =CPT2_2!A17 -> 2.8 | B29: =CPT1_1!E17 -> 0.86 | C29: =CPT2_2!E17 -> 1.85 | E29: =B29/$D$16 -> 0.087665647 | F29: =C29/$D$16 -> 0.18858308 | G29: =E29*$D$3^2 -> 1767.6901 | H29: =F29*$D$3^2 -> 3802.5892
A30: =CPT2_2!A18 -> 3,00 | B30: =CPT1_1!E18 -> 0.89 | C30: =CPT2_2!E18 -> 1.85 | E30: =B30/$D$16 -> 0.090723751 | F30: =C30/$D$16 -> 0.18858308 | G30: =E30*$D$4^2 -> 3071.5433 | H30: =F30*$D$4^2 -> 6384.6687
A31: =CPT2_2!A19 -> 3.2 | B31: =CPT1_1!E19 -> 0.9 | C31: =CPT2_2!E19 -> 1.85 | E31: =B31/$D$16 -> 0.091743119 | F31: =C31/$D$16 -> 0.18858308 | G31: =E31*$D$4^2 -> 3106.055 | H31: =F31*$D$4^2 -> 6384.6687
A32: =CPT2_2!A20 -> 3.4 | B32: =CPT1_1!E20 -> 0.92 | C32: =CPT2_2!E20 -> 1.85 | E32: =B32/$D$16 -> 0.093781855 | F32: =C32/$D$16 -> 0.18858308 | G32: =E32*$D$4^2 -> 3175.0785 | H32: =F32*$D$4^2 -> 6384.6687
A33: =CPT2_2!A21 -> 3.6 | B33: =CPT1_1!E21 -> 0.89 | C33: =CPT2_2!E21 -> 1.85 | E33: =B33/$D$16 -> 0.090723751 | F33: =C33/$D$16 -> 0.18858308 | G33: =E33*$D$4^2 -> 3071.5433 | H33: =F33*$D$4^2 -> 6384.6687
A34: =CPT2_2!A22 -> 3.8 | B34: =CPT1_1!E22 -> 0.88 | C34: =CPT2_2!E22 -> 1.85 | E34: =B34/$D$16 -> 0.089704383 | F34: =C34/$D$16 -> 0.18858308 | G34: =E34*$D$4^2 -> 3037.0316 | H34: =F34*$D$4^2 -> 6384.6687
A35: =CPT2_2!A23 -> 4,00 | B35: =CPT1_1!E23 -> 0.89 | C35: =CPT2_2!E23 -> 1.85 | E35: =B35/$D$16 -> 0.090723751 | F35: =C35/$D$16 -> 0.18858308 | G35: =E35*$D$4^2 -> 3071.5433 | H35: =F35*$D$4^2 -> 6384.6687
A36: =CPT2_2!A24 -> 4.2 | B36: =CPT1_1!E24 -> 0.86 | C36: =CPT2_2!E24 -> 1.85 | E36: =B36/$D$16 -> 0.087665647 | F36: =C36/$D$16 -> 0.18858308 | G36: =E36*$D$4^2 -> 2968.0082 | H36: =F36*$D$4^2 -> 6384.6687
A37: =CPT2_2!A25 -> 4.4 | B37: =CPT1_1!E25 -> 0.87 | C37: =CPT2_2!E25 -> 1.85 | E37: =B37/$D$16 -> 0.088685015 | F37: =C37/$D$16 -> 0.18858308 | G37: =E37*$D$4^2 -> 3002.5199 | H37: =F37*$D$4^2 -> 6384.6687
A38: =CPT2_2!A26 -> 4.6 | B38: =CPT1_1!E26 -> 0.87 | C38: =CPT2_2!E26 -> 1.85 | E38: =B38/$D$16 -> 0.088685015 | F38: =C38/$D$16 -> 0.18858308 | G38: =E38*$D$4^2 -> 3002.5199 | H38: =F38*$D$4^2 -> 6384.6687
A39: =CPT2_2!A27 -> 4.8 | B39: =CPT1_1!E27 -> 0.87 | C39: =CPT2_2!E27 -> 1.85 | E39: =B39/$D$16 -> 0.088685015 | F39: =C39/$D$16 -> 0.18858308 | G39: =E39*$D$4^2 -> 3002.5199 | H39: =F39*$D$4^2 -> 6384.6687
A40: =CPT2_2!A28 -> 5,00 | B40: =CPT1_1!E28 -> 0.95 | C40: =CPT2_2!E28 -> 1.85 | E40: =B40/$D$16 -> 0.096839959 | F40: =C40/$D$16 -> 0.18858308 | G40: =E40*$D$4^2 -> 3278.6137 | H40: =F40*$D$4^2 -> 6384.6687
A41: =CPT2_2!A29 -> 5.2 | B41: =CPT1_1!E29 -> 0.9 | C41: =CPT2_2!E29 -> 1.85 | E41: =B41/$D$16 -> 0.091743119 | F41: =C41/$D$16 -> 0.18858308 | G41: =E41*$D$4^2 -> 3106.055 | H41: =F41*$D$4^2 -> 6384.6687
... A60: =CPT2_2!A48 -> 9,00 | B60: =CPT1_1!E48 -> 0.92 | C60: =CPT2_2!E48 -> 1.85 | E60: =B60/$D$16 -> 0.093781855 | F60: =C60/$D$16 -> 0.18858308 | G60: =E60*$D$4^2 -> 3175.0785 | H60: =F60*$D$4^2 -> 6384.6687
A61: =CPT2_2!A49 -> 9.2 | B61: =CPT1_1!E49 -> 0.94 | C61: =CPT2_2!E49 -> 1.85 | E61: =B61/$D$16 -> 0.095820591 | F61: =C61/$D$16 -> 0.18858308
A62: =CPT2_2!A50 -> 9.4 | B62: =CPT1_1!E50 -> 0.95 | C62: =CPT2_2!E50 -> 1.85 | E62: =B62/$D$16 -> 0.096839959 | F62: =C62/$D$16 -> 0.18858308
A63: =CPT2_2!A51 -> 9.6 | B63: =CPT1_1!E51 -> 0.95 | C63: =CPT2_2!E51 -> 1.85 | E63: =B63/$D$16 -> 0.096839959 | F63: =C63/$D$16 -> 0.18858308
A64: =CPT2_2!A52 -> 9.8 | C64: =CPT2_2!E52 -> 1.85 | F64: =C64/$D$16 -> 0.18858308
A65: =CPT2_2!A53 -> 10,00 | C65: =CPT2_2!E53 -> 1.85 | F65: =C65/$D$16 -> 0.18858308
